/scratch/cnt0024/hmg2840/albert7a/anaconda3/lib/python3.7/site-packages/dask/config.py:168: YAMLLoadWarning: calling yaml.load() without Loader=... is deprecated, as the default Loader is unsafe. Please read https://msg.pyyaml.org/load for full details.
  data = yaml.load(f.read()) or {}
/scratch/cnt0024/hmg2840/albert7a/anaconda3/lib/python3.7/site-packages/distributed/utils.py:136: RuntimeWarning: Couldn't detect a suitable IP address for reaching '8.8.8.8', defaulting to '127.0.0.1': [Errno 101] Network is unreachable
  RuntimeWarning,
distributed.nanny - INFO -         Start Nanny at: 'tcp://172.30.6.48:42952'
distributed.nanny - INFO -         Start Nanny at: 'tcp://172.30.6.48:34373'
distributed.nanny - INFO -         Start Nanny at: 'tcp://172.30.6.48:34469'
distributed.nanny - INFO -         Start Nanny at: 'tcp://172.30.6.48:43980'
distributed.nanny - INFO -         Start Nanny at: 'tcp://172.30.6.48:41500'
distributed.nanny - INFO -         Start Nanny at: 'tcp://172.30.6.48:43239'
distributed.nanny - INFO -         Start Nanny at: 'tcp://172.30.6.48:37747'
distributed.nanny - INFO -         Start Nanny at: 'tcp://172.30.6.48:42358'
distributed.nanny - INFO -         Start Nanny at: 'tcp://172.30.6.48:38482'
distributed.nanny - INFO -         Start Nanny at: 'tcp://172.30.6.48:44432'
distributed.nanny - INFO -         Start Nanny at: 'tcp://172.30.6.48:41005'
distributed.nanny - INFO -         Start Nanny at: 'tcp://172.30.6.48:38455'
distributed.nanny - INFO -         Start Nanny at: 'tcp://172.30.6.48:36261'
distributed.nanny - INFO -         Start Nanny at: 'tcp://172.30.6.48:33842'
distributed.nanny - INFO -         Start Nanny at: 'tcp://172.30.6.48:40111'
distributed.nanny - INFO -         Start Nanny at: 'tcp://172.30.6.48:39632'
distributed.nanny - INFO -         Start Nanny at: 'tcp://172.30.6.48:42560'
distributed.nanny - INFO -         Start Nanny at: 'tcp://172.30.6.48:39052'
distributed.nanny - INFO -         Start Nanny at: 'tcp://172.30.6.48:40453'
distributed.nanny - INFO -         Start Nanny at: 'tcp://172.30.6.48:38624'
distributed.nanny - INFO -         Start Nanny at: 'tcp://172.30.6.48:39160'
distributed.nanny - INFO -         Start Nanny at: 'tcp://172.30.6.48:37919'
distributed.nanny - INFO -         Start Nanny at: 'tcp://172.30.6.48:45122'
distributed.nanny - INFO -         Start Nanny at: 'tcp://172.30.6.48:40181'
distributed.nanny - INFO -         Start Nanny at: 'tcp://172.30.6.48:46593'
distributed.nanny - INFO -         Start Nanny at: 'tcp://172.30.6.48:38538'
distributed.nanny - INFO -         Start Nanny at: 'tcp://172.30.6.48:42577'
distributed.nanny - INFO -         Start Nanny at: 'tcp://172.30.6.48:41776'
/scratch/cnt0024/hmg2840/albert7a/anaconda3/lib/python3.7/site-packages/dask/config.py:168: YAMLLoadWarning: calling yaml.load() without Loader=... is deprecated, as the default Loader is unsafe. Please read https://msg.pyyaml.org/load for full details.
  data = yaml.load(f.read()) or {}
/scratch/cnt0024/hmg2840/albert7a/anaconda3/lib/python3.7/site-packages/distributed/utils.py:136: RuntimeWarning: Couldn't detect a suitable IP address for reaching '8.8.8.8', defaulting to '127.0.0.1': [Errno 101] Network is unreachable
  RuntimeWarning,
distributed.worker - INFO -       Start worker at:    tcp://172.30.6.48:45168
distributed.worker - INFO -          Listening to:    tcp://172.30.6.48:45168
distributed.worker - INFO -              nanny at:          172.30.6.48:46593
distributed.worker - INFO -              bokeh at:          172.30.6.48:36992
distributed.worker - INFO - Waiting to connect to:   tcp://172.30.100.3:40056
distributed.worker - INFO - -------------------------------------------------
distributed.worker - INFO -               Threads:                          1
distributed.worker - INFO -                Memory:                    4.29 GB
distributed.worker - INFO -       Local Directory: /scratch/cnt0024/hmg2840/albert7a/daskjobqueue/worker-zwbuqntz
distributed.worker - INFO - -------------------------------------------------
/scratch/cnt0024/hmg2840/albert7a/anaconda3/lib/python3.7/site-packages/dask/config.py:168: YAMLLoadWarning: calling yaml.load() without Loader=... is deprecated, as the default Loader is unsafe. Please read https://msg.pyyaml.org/load for full details.
  data = yaml.load(f.read()) or {}
/scratch/cnt0024/hmg2840/albert7a/anaconda3/lib/python3.7/site-packages/distributed/utils.py:136: RuntimeWarning: Couldn't detect a suitable IP address for reaching '8.8.8.8', defaulting to '127.0.0.1': [Errno 101] Network is unreachable
  RuntimeWarning,
distributed.worker - INFO -       Start worker at:    tcp://172.30.6.48:38700
distributed.worker - INFO -          Listening to:    tcp://172.30.6.48:38700
distributed.worker - INFO -              nanny at:          172.30.6.48:34373
distributed.worker - INFO -              bokeh at:          172.30.6.48:38139
distributed.worker - INFO - Waiting to connect to:   tcp://172.30.100.3:40056
distributed.worker - INFO - -------------------------------------------------
distributed.worker - INFO -               Threads:                          1
distributed.worker - INFO -                Memory:                    4.29 GB
distributed.worker - INFO -       Local Directory: /scratch/cnt0024/hmg2840/albert7a/daskjobqueue/worker-v4ad5amq
distributed.worker - INFO - -------------------------------------------------
distributed.worker - INFO -         Registered to:   tcp://172.30.100.3:40056
distributed.worker - INFO - -------------------------------------------------
distributed.worker - INFO -         Registered to:   tcp://172.30.100.3:40056
distributed.core - INFO - Starting established connection
distributed.worker - INFO - -------------------------------------------------
distributed.core - INFO - Starting established connection
/scratch/cnt0024/hmg2840/albert7a/anaconda3/lib/python3.7/site-packages/dask/config.py:168: YAMLLoadWarning: calling yaml.load() without Loader=... is deprecated, as the default Loader is unsafe. Please read https://msg.pyyaml.org/load for full details.
  data = yaml.load(f.read()) or {}
/scratch/cnt0024/hmg2840/albert7a/anaconda3/lib/python3.7/site-packages/distributed/utils.py:136: RuntimeWarning: Couldn't detect a suitable IP address for reaching '8.8.8.8', defaulting to '127.0.0.1': [Errno 101] Network is unreachable
  RuntimeWarning,
distributed.worker - INFO -       Start worker at:    tcp://172.30.6.48:35837
distributed.worker - INFO -          Listening to:    tcp://172.30.6.48:35837
/scratch/cnt0024/hmg2840/albert7a/anaconda3/lib/python3.7/site-packages/dask/config.py:168: YAMLLoadWarning: calling yaml.load() without Loader=... is deprecated, as the default Loader is unsafe. Please read https://msg.pyyaml.org/load for full details.
  data = yaml.load(f.read()) or {}
/scratch/cnt0024/hmg2840/albert7a/anaconda3/lib/python3.7/site-packages/distributed/utils.py:136: RuntimeWarning: Couldn't detect a suitable IP address for reaching '8.8.8.8', defaulting to '127.0.0.1': [Errno 101] Network is unreachable
  RuntimeWarning,
distributed.worker - INFO -       Start worker at:    tcp://172.30.6.48:41537
distributed.worker - INFO -              nanny at:          172.30.6.48:33842
distributed.worker - INFO -          Listening to:    tcp://172.30.6.48:41537
distributed.worker - INFO -              bokeh at:          172.30.6.48:36352
distributed.worker - INFO -              nanny at:          172.30.6.48:41005
distributed.worker - INFO - Waiting to connect to:   tcp://172.30.100.3:40056
distributed.worker - INFO -              bokeh at:          172.30.6.48:43145
distributed.worker - INFO - -------------------------------------------------
distributed.worker - INFO - Waiting to connect to:   tcp://172.30.100.3:40056
distributed.worker - INFO - -------------------------------------------------
distributed.worker - INFO -               Threads:                          1
distributed.worker - INFO -                Memory:                    4.29 GB
distributed.worker - INFO -               Threads:                          1
distributed.worker - INFO -       Local Directory: /scratch/cnt0024/hmg2840/albert7a/daskjobqueue/worker-hjuwks2m
distributed.worker - INFO -                Memory:                    4.29 GB
distributed.worker - INFO -       Local Directory: /scratch/cnt0024/hmg2840/albert7a/daskjobqueue/worker-uryr2qxb
distributed.worker - INFO - -------------------------------------------------
distributed.worker - INFO - -------------------------------------------------
distributed.worker - INFO -         Registered to:   tcp://172.30.100.3:40056
distributed.worker - INFO - -------------------------------------------------
distributed.core - INFO - Starting established connection
distributed.worker - INFO -         Registered to:   tcp://172.30.100.3:40056
distributed.worker - INFO - -------------------------------------------------
distributed.core - INFO - Starting established connection
/scratch/cnt0024/hmg2840/albert7a/anaconda3/lib/python3.7/site-packages/dask/config.py:168: YAMLLoadWarning: calling yaml.load() without Loader=... is deprecated, as the default Loader is unsafe. Please read https://msg.pyyaml.org/load for full details.
  data = yaml.load(f.read()) or {}
/scratch/cnt0024/hmg2840/albert7a/anaconda3/lib/python3.7/site-packages/distributed/utils.py:136: RuntimeWarning: Couldn't detect a suitable IP address for reaching '8.8.8.8', defaulting to '127.0.0.1': [Errno 101] Network is unreachable
  RuntimeWarning,
distributed.worker - INFO -       Start worker at:    tcp://172.30.6.48:34807
distributed.worker - INFO -          Listening to:    tcp://172.30.6.48:34807
distributed.worker - INFO -              nanny at:          172.30.6.48:36261
distributed.worker - INFO -              bokeh at:          172.30.6.48:33985
distributed.worker - INFO - Waiting to connect to:   tcp://172.30.100.3:40056
distributed.worker - INFO - -------------------------------------------------
distributed.worker - INFO -               Threads:                          1
distributed.worker - INFO -                Memory:                    4.29 GB
distributed.worker - INFO -       Local Directory: /scratch/cnt0024/hmg2840/albert7a/daskjobqueue/worker-2p4vbbqk
distributed.worker - INFO - -------------------------------------------------
/scratch/cnt0024/hmg2840/albert7a/anaconda3/lib/python3.7/site-packages/dask/config.py:168: YAMLLoadWarning: calling yaml.load() without Loader=... is deprecated, as the default Loader is unsafe. Please read https://msg.pyyaml.org/load for full details.
  data = yaml.load(f.read()) or {}
/scratch/cnt0024/hmg2840/albert7a/anaconda3/lib/python3.7/site-packages/distributed/utils.py:136: RuntimeWarning: Couldn't detect a suitable IP address for reaching '8.8.8.8', defaulting to '127.0.0.1': [Errno 101] Network is unreachable
  RuntimeWarning,
distributed.worker - INFO -       Start worker at:    tcp://172.30.6.48:41497
distributed.worker - INFO -          Listening to:    tcp://172.30.6.48:41497
distributed.worker - INFO -              nanny at:          172.30.6.48:39632
distributed.worker - INFO -              bokeh at:          172.30.6.48:38822
distributed.worker - INFO - Waiting to connect to:   tcp://172.30.100.3:40056
distributed.worker - INFO - -------------------------------------------------
/scratch/cnt0024/hmg2840/albert7a/anaconda3/lib/python3.7/site-packages/dask/config.py:168: YAMLLoadWarning: calling yaml.load() without Loader=... is deprecated, as the default Loader is unsafe. Please read https://msg.pyyaml.org/load for full details.
  data = yaml.load(f.read()) or {}
/scratch/cnt0024/hmg2840/albert7a/anaconda3/lib/python3.7/site-packages/distributed/utils.py:136: RuntimeWarning: Couldn't detect a suitable IP address for reaching '8.8.8.8', defaulting to '127.0.0.1': [Errno 101] Network is unreachable
  RuntimeWarning,
distributed.worker - INFO -       Start worker at:    tcp://172.30.6.48:36488
distributed.worker - INFO -               Threads:                          1
distributed.worker - INFO -          Listening to:    tcp://172.30.6.48:36488
distributed.worker - INFO -                Memory:                    4.29 GB
distributed.worker - INFO -              nanny at:          172.30.6.48:43980
distributed.worker - INFO -       Local Directory: /scratch/cnt0024/hmg2840/albert7a/daskjobqueue/worker-b67snlaj
distributed.worker - INFO -              bokeh at:          172.30.6.48:41858
distributed.worker - INFO - -------------------------------------------------
distributed.worker - INFO - Waiting to connect to:   tcp://172.30.100.3:40056
distributed.worker - INFO - -------------------------------------------------
distributed.worker - INFO -               Threads:                          1
distributed.worker - INFO -                Memory:                    4.29 GB
distributed.worker - INFO -       Local Directory: /scratch/cnt0024/hmg2840/albert7a/daskjobqueue/worker-auvil0bh
distributed.worker - INFO - -------------------------------------------------
/scratch/cnt0024/hmg2840/albert7a/anaconda3/lib/python3.7/site-packages/dask/config.py:168: YAMLLoadWarning: calling yaml.load() without Loader=... is deprecated, as the default Loader is unsafe. Please read https://msg.pyyaml.org/load for full details.
  data = yaml.load(f.read()) or {}
/scratch/cnt0024/hmg2840/albert7a/anaconda3/lib/python3.7/site-packages/distributed/utils.py:136: RuntimeWarning: Couldn't detect a suitable IP address for reaching '8.8.8.8', defaulting to '127.0.0.1': [Errno 101] Network is unreachable
  RuntimeWarning,
distributed.worker - INFO -       Start worker at:    tcp://172.30.6.48:36396
distributed.worker - INFO -          Listening to:    tcp://172.30.6.48:36396
distributed.worker - INFO -              nanny at:          172.30.6.48:38624
distributed.worker - INFO -              bokeh at:          172.30.6.48:38084
distributed.worker - INFO - Waiting to connect to:   tcp://172.30.100.3:40056
distributed.worker - INFO - -------------------------------------------------
distributed.worker - INFO -               Threads:                          1
distributed.worker - INFO -                Memory:                    4.29 GB
distributed.worker - INFO -       Local Directory: /scratch/cnt0024/hmg2840/albert7a/daskjobqueue/worker-wlfzosx_
distributed.worker - INFO - -------------------------------------------------
/scratch/cnt0024/hmg2840/albert7a/anaconda3/lib/python3.7/site-packages/dask/config.py:168: YAMLLoadWarning: calling yaml.load() without Loader=... is deprecated, as the default Loader is unsafe. Please read https://msg.pyyaml.org/load for full details.
  data = yaml.load(f.read()) or {}
/scratch/cnt0024/hmg2840/albert7a/anaconda3/lib/python3.7/site-packages/distributed/utils.py:136: RuntimeWarning: Couldn't detect a suitable IP address for reaching '8.8.8.8', defaulting to '127.0.0.1': [Errno 101] Network is unreachable
  RuntimeWarning,
distributed.worker - INFO -       Start worker at:    tcp://172.30.6.48:33723
distributed.worker - INFO -          Listening to:    tcp://172.30.6.48:33723
distributed.worker - INFO -              nanny at:          172.30.6.48:37747
distributed.worker - INFO -              bokeh at:          172.30.6.48:43466
distributed.worker - INFO - Waiting to connect to:   tcp://172.30.100.3:40056
distributed.worker - INFO - -------------------------------------------------
distributed.worker - INFO -               Threads:                          1
distributed.worker - INFO -                Memory:                    4.29 GB
distributed.worker - INFO -       Local Directory: /scratch/cnt0024/hmg2840/albert7a/daskjobqueue/worker-0iiux_ik
distributed.worker - INFO - -------------------------------------------------
distributed.worker - INFO -         Registered to:   tcp://172.30.100.3:40056
distributed.worker - INFO - -------------------------------------------------
distributed.core - INFO - Starting established connection
distributed.worker - INFO -         Registered to:   tcp://172.30.100.3:40056
distributed.worker - INFO -         Registered to:   tcp://172.30.100.3:40056
distributed.worker - INFO - -------------------------------------------------
distributed.worker - INFO - -------------------------------------------------
distributed.worker - INFO -         Registered to:   tcp://172.30.100.3:40056
distributed.core - INFO - Starting established connection
distributed.worker - INFO - -------------------------------------------------
distributed.core - INFO - Starting established connection
distributed.core - INFO - Starting established connection
/scratch/cnt0024/hmg2840/albert7a/anaconda3/lib/python3.7/site-packages/dask/config.py:168: YAMLLoadWarning: calling yaml.load() without Loader=... is deprecated, as the default Loader is unsafe. Please read https://msg.pyyaml.org/load for full details.
  data = yaml.load(f.read()) or {}
/scratch/cnt0024/hmg2840/albert7a/anaconda3/lib/python3.7/site-packages/distributed/utils.py:136: RuntimeWarning: Couldn't detect a suitable IP address for reaching '8.8.8.8', defaulting to '127.0.0.1': [Errno 101] Network is unreachable
  RuntimeWarning,
distributed.worker - INFO -       Start worker at:    tcp://172.30.6.48:44537
distributed.worker - INFO -          Listening to:    tcp://172.30.6.48:44537
distributed.worker - INFO -              nanny at:          172.30.6.48:38482
distributed.worker - INFO -              bokeh at:          172.30.6.48:36635
distributed.worker - INFO - Waiting to connect to:   tcp://172.30.100.3:40056
distributed.worker - INFO - -------------------------------------------------
distributed.worker - INFO -               Threads:                          1
distributed.worker - INFO -                Memory:                    4.29 GB
distributed.worker - INFO -       Local Directory: /scratch/cnt0024/hmg2840/albert7a/daskjobqueue/worker-yyju30qu
distributed.worker - INFO - -------------------------------------------------
/scratch/cnt0024/hmg2840/albert7a/anaconda3/lib/python3.7/site-packages/dask/config.py:168: YAMLLoadWarning: calling yaml.load() without Loader=... is deprecated, as the default Loader is unsafe. Please read https://msg.pyyaml.org/load for full details.
  data = yaml.load(f.read()) or {}
/scratch/cnt0024/hmg2840/albert7a/anaconda3/lib/python3.7/site-packages/distributed/utils.py:136: RuntimeWarning: Couldn't detect a suitable IP address for reaching '8.8.8.8', defaulting to '127.0.0.1': [Errno 101] Network is unreachable
  RuntimeWarning,
distributed.worker - INFO -       Start worker at:    tcp://172.30.6.48:41010
distributed.worker - INFO -          Listening to:    tcp://172.30.6.48:41010
distributed.worker - INFO -              nanny at:          172.30.6.48:42577
distributed.worker - INFO -              bokeh at:          172.30.6.48:43963
distributed.worker - INFO - Waiting to connect to:   tcp://172.30.100.3:40056
distributed.worker - INFO - -------------------------------------------------
distributed.worker - INFO -               Threads:                          1
distributed.worker - INFO -                Memory:                    4.29 GB
distributed.worker - INFO -       Local Directory: /scratch/cnt0024/hmg2840/albert7a/daskjobqueue/worker-_dyzp7ot
distributed.worker - INFO - -------------------------------------------------
/scratch/cnt0024/hmg2840/albert7a/anaconda3/lib/python3.7/site-packages/dask/config.py:168: YAMLLoadWarning: calling yaml.load() without Loader=... is deprecated, as the default Loader is unsafe. Please read https://msg.pyyaml.org/load for full details.
  data = yaml.load(f.read()) or {}
/scratch/cnt0024/hmg2840/albert7a/anaconda3/lib/python3.7/site-packages/distributed/utils.py:136: RuntimeWarning: Couldn't detect a suitable IP address for reaching '8.8.8.8', defaulting to '127.0.0.1': [Errno 101] Network is unreachable
  RuntimeWarning,
distributed.worker - INFO -       Start worker at:    tcp://172.30.6.48:38777
distributed.worker - INFO -          Listening to:    tcp://172.30.6.48:38777
distributed.worker - INFO -              nanny at:          172.30.6.48:42952
distributed.worker - INFO -              bokeh at:          172.30.6.48:33397
distributed.worker - INFO - Waiting to connect to:   tcp://172.30.100.3:40056
/scratch/cnt0024/hmg2840/albert7a/anaconda3/lib/python3.7/site-packages/dask/config.py:168: YAMLLoadWarning: calling yaml.load() without Loader=... is deprecated, as the default Loader is unsafe. Please read https://msg.pyyaml.org/load for full details.
  data = yaml.load(f.read()) or {}
/scratch/cnt0024/hmg2840/albert7a/anaconda3/lib/python3.7/site-packages/distributed/utils.py:136: RuntimeWarning: Couldn't detect a suitable IP address for reaching '8.8.8.8', defaulting to '127.0.0.1': [Errno 101] Network is unreachable
  RuntimeWarning,
distributed.worker - INFO -       Start worker at:    tcp://172.30.6.48:36008
distributed.worker - INFO - -------------------------------------------------
distributed.worker - INFO -          Listening to:    tcp://172.30.6.48:36008
distributed.worker - INFO -              nanny at:          172.30.6.48:45122
distributed.worker - INFO -               Threads:                          1
distributed.worker - INFO -              bokeh at:          172.30.6.48:46655
distributed.worker - INFO -                Memory:                    4.29 GB
distributed.worker - INFO - Waiting to connect to:   tcp://172.30.100.3:40056
distributed.worker - INFO -       Local Directory: /scratch/cnt0024/hmg2840/albert7a/daskjobqueue/worker-lvku81u2
distributed.worker - INFO - -------------------------------------------------
distributed.worker - INFO - -------------------------------------------------
distributed.worker - INFO -               Threads:                          1
distributed.worker - INFO -                Memory:                    4.29 GB
distributed.worker - INFO -       Local Directory: /scratch/cnt0024/hmg2840/albert7a/daskjobqueue/worker-yhui71ts
distributed.worker - INFO - -------------------------------------------------
distributed.worker - INFO -         Registered to:   tcp://172.30.100.3:40056
distributed.worker - INFO - -------------------------------------------------
distributed.worker - INFO -         Registered to:   tcp://172.30.100.3:40056
distributed.core - INFO - Starting established connection
distributed.worker - INFO - -------------------------------------------------
distributed.core - INFO - Starting established connection
distributed.worker - INFO -         Registered to:   tcp://172.30.100.3:40056
distributed.worker - INFO - -------------------------------------------------
distributed.core - INFO - Starting established connection
distributed.worker - INFO -         Registered to:   tcp://172.30.100.3:40056
distributed.worker - INFO - -------------------------------------------------
distributed.worker - INFO -         Registered to:   tcp://172.30.100.3:40056
distributed.worker - INFO - -------------------------------------------------
distributed.core - INFO - Starting established connection
distributed.core - INFO - Starting established connection
/scratch/cnt0024/hmg2840/albert7a/anaconda3/lib/python3.7/site-packages/dask/config.py:168: YAMLLoadWarning: calling yaml.load() without Loader=... is deprecated, as the default Loader is unsafe. Please read https://msg.pyyaml.org/load for full details.
  data = yaml.load(f.read()) or {}
/scratch/cnt0024/hmg2840/albert7a/anaconda3/lib/python3.7/site-packages/distributed/utils.py:136: RuntimeWarning: Couldn't detect a suitable IP address for reaching '8.8.8.8', defaulting to '127.0.0.1': [Errno 101] Network is unreachable
  RuntimeWarning,
distributed.worker - INFO -       Start worker at:    tcp://172.30.6.48:38715
distributed.worker - INFO -          Listening to:    tcp://172.30.6.48:38715
distributed.worker - INFO -              nanny at:          172.30.6.48:41500
distributed.worker - INFO -              bokeh at:          172.30.6.48:46559
distributed.worker - INFO - Waiting to connect to:   tcp://172.30.100.3:40056
distributed.worker - INFO - -------------------------------------------------
distributed.worker - INFO -               Threads:                          1
distributed.worker - INFO -                Memory:                    4.29 GB
distributed.worker - INFO -       Local Directory: /scratch/cnt0024/hmg2840/albert7a/daskjobqueue/worker-7322f88l
distributed.worker - INFO - -------------------------------------------------
distributed.worker - INFO -         Registered to:   tcp://172.30.100.3:40056
distributed.worker - INFO - -------------------------------------------------
distributed.core - INFO - Starting established connection
/scratch/cnt0024/hmg2840/albert7a/anaconda3/lib/python3.7/site-packages/dask/config.py:168: YAMLLoadWarning: calling yaml.load() without Loader=... is deprecated, as the default Loader is unsafe. Please read https://msg.pyyaml.org/load for full details.
  data = yaml.load(f.read()) or {}
/scratch/cnt0024/hmg2840/albert7a/anaconda3/lib/python3.7/site-packages/distributed/utils.py:136: RuntimeWarning: Couldn't detect a suitable IP address for reaching '8.8.8.8', defaulting to '127.0.0.1': [Errno 101] Network is unreachable
  RuntimeWarning,
distributed.worker - INFO -       Start worker at:    tcp://172.30.6.48:35469
distributed.worker - INFO -          Listening to:    tcp://172.30.6.48:35469
distributed.worker - INFO -              nanny at:          172.30.6.48:44432
distributed.worker - INFO -              bokeh at:          172.30.6.48:39667
distributed.worker - INFO - Waiting to connect to:   tcp://172.30.100.3:40056
distributed.worker - INFO - -------------------------------------------------
distributed.worker - INFO -               Threads:                          1
distributed.worker - INFO -                Memory:                    4.29 GB
distributed.worker - INFO -       Local Directory: /scratch/cnt0024/hmg2840/albert7a/daskjobqueue/worker-z27_1d7q
distributed.worker - INFO - -------------------------------------------------
/scratch/cnt0024/hmg2840/albert7a/anaconda3/lib/python3.7/site-packages/dask/config.py:168: YAMLLoadWarning: calling yaml.load() without Loader=... is deprecated, as the default Loader is unsafe. Please read https://msg.pyyaml.org/load for full details.
  data = yaml.load(f.read()) or {}
/scratch/cnt0024/hmg2840/albert7a/anaconda3/lib/python3.7/site-packages/distributed/utils.py:136: RuntimeWarning: Couldn't detect a suitable IP address for reaching '8.8.8.8', defaulting to '127.0.0.1': [Errno 101] Network is unreachable
  RuntimeWarning,
distributed.worker - INFO -       Start worker at:    tcp://172.30.6.48:45317
distributed.worker - INFO -          Listening to:    tcp://172.30.6.48:45317
distributed.worker - INFO -              nanny at:          172.30.6.48:34469
distributed.worker - INFO -              bokeh at:          172.30.6.48:38501
distributed.worker - INFO - Waiting to connect to:   tcp://172.30.100.3:40056
distributed.worker - INFO - -------------------------------------------------
distributed.worker - INFO -               Threads:                          1
/scratch/cnt0024/hmg2840/albert7a/anaconda3/lib/python3.7/site-packages/dask/config.py:168: YAMLLoadWarning: calling yaml.load() without Loader=... is deprecated, as the default Loader is unsafe. Please read https://msg.pyyaml.org/load for full details.
  data = yaml.load(f.read()) or {}
/scratch/cnt0024/hmg2840/albert7a/anaconda3/lib/python3.7/site-packages/distributed/utils.py:136: RuntimeWarning: Couldn't detect a suitable IP address for reaching '8.8.8.8', defaulting to '127.0.0.1': [Errno 101] Network is unreachable
  RuntimeWarning,
distributed.worker - INFO -       Start worker at:    tcp://172.30.6.48:35839
distributed.worker - INFO -                Memory:                    4.29 GB
distributed.worker - INFO -          Listening to:    tcp://172.30.6.48:35839
distributed.worker - INFO -       Local Directory: /scratch/cnt0024/hmg2840/albert7a/daskjobqueue/worker-iff91cal
distributed.worker - INFO -              nanny at:          172.30.6.48:40181
distributed.worker - INFO - -------------------------------------------------
distributed.worker - INFO -              bokeh at:          172.30.6.48:38981
distributed.worker - INFO - Waiting to connect to:   tcp://172.30.100.3:40056
distributed.worker - INFO - -------------------------------------------------
distributed.worker - INFO -               Threads:                          1
distributed.worker - INFO -                Memory:                    4.29 GB
distributed.worker - INFO -       Local Directory: /scratch/cnt0024/hmg2840/albert7a/daskjobqueue/worker-qo6yzimn
distributed.worker - INFO - -------------------------------------------------
/scratch/cnt0024/hmg2840/albert7a/anaconda3/lib/python3.7/site-packages/dask/config.py:168: YAMLLoadWarning: calling yaml.load() without Loader=... is deprecated, as the default Loader is unsafe. Please read https://msg.pyyaml.org/load for full details.
  data = yaml.load(f.read()) or {}
/scratch/cnt0024/hmg2840/albert7a/anaconda3/lib/python3.7/site-packages/distributed/utils.py:136: RuntimeWarning: Couldn't detect a suitable IP address for reaching '8.8.8.8', defaulting to '127.0.0.1': [Errno 101] Network is unreachable
  RuntimeWarning,
distributed.worker - INFO -       Start worker at:    tcp://172.30.6.48:39355
distributed.worker - INFO -          Listening to:    tcp://172.30.6.48:39355
distributed.worker - INFO -              nanny at:          172.30.6.48:40111
distributed.worker - INFO -              bokeh at:          172.30.6.48:46268
distributed.worker - INFO - Waiting to connect to:   tcp://172.30.100.3:40056
distributed.worker - INFO - -------------------------------------------------
distributed.worker - INFO -               Threads:                          1
distributed.worker - INFO -                Memory:                    4.29 GB
distributed.worker - INFO -       Local Directory: /scratch/cnt0024/hmg2840/albert7a/daskjobqueue/worker-ympeg16u
distributed.worker - INFO - -------------------------------------------------
/scratch/cnt0024/hmg2840/albert7a/anaconda3/lib/python3.7/site-packages/dask/config.py:168: YAMLLoadWarning: calling yaml.load() without Loader=... is deprecated, as the default Loader is unsafe. Please read https://msg.pyyaml.org/load for full details.
  data = yaml.load(f.read()) or {}
/scratch/cnt0024/hmg2840/albert7a/anaconda3/lib/python3.7/site-packages/distributed/utils.py:136: RuntimeWarning: Couldn't detect a suitable IP address for reaching '8.8.8.8', defaulting to '127.0.0.1': [Errno 101] Network is unreachable
  RuntimeWarning,
distributed.worker - INFO -       Start worker at:    tcp://172.30.6.48:36502
distributed.worker - INFO -          Listening to:    tcp://172.30.6.48:36502
distributed.worker - INFO -              nanny at:          172.30.6.48:38455
distributed.worker - INFO -              bokeh at:          172.30.6.48:39509
distributed.worker - INFO - Waiting to connect to:   tcp://172.30.100.3:40056
distributed.worker - INFO - -------------------------------------------------
distributed.worker - INFO -               Threads:                          1
distributed.worker - INFO -                Memory:                    4.29 GB
distributed.worker - INFO -       Local Directory: /scratch/cnt0024/hmg2840/albert7a/daskjobqueue/worker-t7mfgxvw
distributed.worker - INFO - -------------------------------------------------
/scratch/cnt0024/hmg2840/albert7a/anaconda3/lib/python3.7/site-packages/dask/config.py:168: YAMLLoadWarning: calling yaml.load() without Loader=... is deprecated, as the default Loader is unsafe. Please read https://msg.pyyaml.org/load for full details.
  data = yaml.load(f.read()) or {}
/scratch/cnt0024/hmg2840/albert7a/anaconda3/lib/python3.7/site-packages/distributed/utils.py:136: RuntimeWarning: Couldn't detect a suitable IP address for reaching '8.8.8.8', defaulting to '127.0.0.1': [Errno 101] Network is unreachable
  RuntimeWarning,
distributed.worker - INFO -       Start worker at:    tcp://172.30.6.48:42524
distributed.worker - INFO -         Registered to:   tcp://172.30.100.3:40056
distributed.worker - INFO -          Listening to:    tcp://172.30.6.48:42524
distributed.worker - INFO -         Registered to:   tcp://172.30.100.3:40056
distributed.worker - INFO -         Registered to:   tcp://172.30.100.3:40056
distributed.worker - INFO -         Registered to:   tcp://172.30.100.3:40056
distributed.worker - INFO - -------------------------------------------------
distributed.worker - INFO -              nanny at:          172.30.6.48:40453
distributed.worker - INFO - -------------------------------------------------
distributed.worker - INFO - -------------------------------------------------
distributed.worker - INFO -              bokeh at:          172.30.6.48:40486
distributed.worker - INFO - -------------------------------------------------
distributed.worker - INFO - Waiting to connect to:   tcp://172.30.100.3:40056
distributed.worker - INFO - -------------------------------------------------
distributed.core - INFO - Starting established connection
distributed.worker - INFO -               Threads:                          1
distributed.core - INFO - Starting established connection
distributed.worker - INFO -                Memory:                    4.29 GB
distributed.core - INFO - Starting established connection
distributed.worker - INFO -       Local Directory: /scratch/cnt0024/hmg2840/albert7a/daskjobqueue/worker-lvv1y20h
distributed.core - INFO - Starting established connection
distributed.worker - INFO - -------------------------------------------------
distributed.worker - INFO -         Registered to:   tcp://172.30.100.3:40056
distributed.worker - INFO - -------------------------------------------------
distributed.core - INFO - Starting established connection
distributed.worker - INFO -         Registered to:   tcp://172.30.100.3:40056
distributed.worker - INFO - -------------------------------------------------
distributed.core - INFO - Starting established connection
/scratch/cnt0024/hmg2840/albert7a/anaconda3/lib/python3.7/site-packages/dask/config.py:168: YAMLLoadWarning: calling yaml.load() without Loader=... is deprecated, as the default Loader is unsafe. Please read https://msg.pyyaml.org/load for full details.
  data = yaml.load(f.read()) or {}
/scratch/cnt0024/hmg2840/albert7a/anaconda3/lib/python3.7/site-packages/distributed/utils.py:136: RuntimeWarning: Couldn't detect a suitable IP address for reaching '8.8.8.8', defaulting to '127.0.0.1': [Errno 101] Network is unreachable
  RuntimeWarning,
distributed.worker - INFO -       Start worker at:    tcp://172.30.6.48:35878
distributed.worker - INFO -          Listening to:    tcp://172.30.6.48:35878
distributed.worker - INFO -              nanny at:          172.30.6.48:42560
distributed.worker - INFO -              bokeh at:          172.30.6.48:36039
distributed.worker - INFO - Waiting to connect to:   tcp://172.30.100.3:40056
distributed.worker - INFO - -------------------------------------------------
distributed.worker - INFO -               Threads:                          1
distributed.worker - INFO -                Memory:                    4.29 GB
/scratch/cnt0024/hmg2840/albert7a/anaconda3/lib/python3.7/site-packages/dask/config.py:168: YAMLLoadWarning: calling yaml.load() without Loader=... is deprecated, as the default Loader is unsafe. Please read https://msg.pyyaml.org/load for full details.
  data = yaml.load(f.read()) or {}
/scratch/cnt0024/hmg2840/albert7a/anaconda3/lib/python3.7/site-packages/distributed/utils.py:136: RuntimeWarning: Couldn't detect a suitable IP address for reaching '8.8.8.8', defaulting to '127.0.0.1': [Errno 101] Network is unreachable
  RuntimeWarning,
distributed.worker - INFO -       Start worker at:    tcp://172.30.6.48:43622
distributed.worker - INFO -       Local Directory: /scratch/cnt0024/hmg2840/albert7a/daskjobqueue/worker-4s597giv
distributed.worker - INFO -          Listening to:    tcp://172.30.6.48:43622
distributed.worker - INFO - -------------------------------------------------
distributed.worker - INFO -              nanny at:          172.30.6.48:38538
distributed.worker - INFO -              bokeh at:          172.30.6.48:34481
distributed.worker - INFO - Waiting to connect to:   tcp://172.30.100.3:40056
distributed.worker - INFO - -------------------------------------------------
distributed.worker - INFO -               Threads:                          1
distributed.worker - INFO -                Memory:                    4.29 GB
distributed.worker - INFO -       Local Directory: /scratch/cnt0024/hmg2840/albert7a/daskjobqueue/worker-_pwfb57_
distributed.worker - INFO - -------------------------------------------------
distributed.worker - INFO -         Registered to:   tcp://172.30.100.3:40056
distributed.worker - INFO - -------------------------------------------------
distributed.core - INFO - Starting established connection
distributed.worker - INFO -         Registered to:   tcp://172.30.100.3:40056
distributed.worker - INFO - -------------------------------------------------
distributed.core - INFO - Starting established connection
/scratch/cnt0024/hmg2840/albert7a/anaconda3/lib/python3.7/site-packages/dask/config.py:168: YAMLLoadWarning: calling yaml.load() without Loader=... is deprecated, as the default Loader is unsafe. Please read https://msg.pyyaml.org/load for full details.
  data = yaml.load(f.read()) or {}
/scratch/cnt0024/hmg2840/albert7a/anaconda3/lib/python3.7/site-packages/distributed/utils.py:136: RuntimeWarning: Couldn't detect a suitable IP address for reaching '8.8.8.8', defaulting to '127.0.0.1': [Errno 101] Network is unreachable
  RuntimeWarning,
distributed.worker - INFO -       Start worker at:    tcp://172.30.6.48:39323
distributed.worker - INFO -          Listening to:    tcp://172.30.6.48:39323
distributed.worker - INFO -              nanny at:          172.30.6.48:43239
distributed.worker - INFO -              bokeh at:          172.30.6.48:34537
distributed.worker - INFO - Waiting to connect to:   tcp://172.30.100.3:40056
distributed.worker - INFO - -------------------------------------------------
distributed.worker - INFO -               Threads:                          1
distributed.worker - INFO -                Memory:                    4.29 GB
distributed.worker - INFO -       Local Directory: /scratch/cnt0024/hmg2840/albert7a/daskjobqueue/worker-1buvg5fl
distributed.worker - INFO - -------------------------------------------------
distributed.worker - INFO -         Registered to:   tcp://172.30.100.3:40056
distributed.worker - INFO - -------------------------------------------------
distributed.core - INFO - Starting established connection
/scratch/cnt0024/hmg2840/albert7a/anaconda3/lib/python3.7/site-packages/dask/config.py:168: YAMLLoadWarning: calling yaml.load() without Loader=... is deprecated, as the default Loader is unsafe. Please read https://msg.pyyaml.org/load for full details.
  data = yaml.load(f.read()) or {}
/scratch/cnt0024/hmg2840/albert7a/anaconda3/lib/python3.7/site-packages/distributed/utils.py:136: RuntimeWarning: Couldn't detect a suitable IP address for reaching '8.8.8.8', defaulting to '127.0.0.1': [Errno 101] Network is unreachable
  RuntimeWarning,
distributed.worker - INFO -       Start worker at:    tcp://172.30.6.48:41100
distributed.worker - INFO -          Listening to:    tcp://172.30.6.48:41100
distributed.worker - INFO -              nanny at:          172.30.6.48:42358
distributed.worker - INFO -              bokeh at:          172.30.6.48:33676
distributed.worker - INFO - Waiting to connect to:   tcp://172.30.100.3:40056
distributed.worker - INFO - -------------------------------------------------
distributed.worker - INFO -               Threads:                          1
distributed.worker - INFO -                Memory:                    4.29 GB
distributed.worker - INFO -       Local Directory: /scratch/cnt0024/hmg2840/albert7a/daskjobqueue/worker-rxfwy3c_
distributed.worker - INFO - -------------------------------------------------
distributed.worker - INFO -         Registered to:   tcp://172.30.100.3:40056
distributed.worker - INFO - -------------------------------------------------
distributed.core - INFO - Starting established connection
/scratch/cnt0024/hmg2840/albert7a/anaconda3/lib/python3.7/site-packages/dask/config.py:168: YAMLLoadWarning: calling yaml.load() without Loader=... is deprecated, as the default Loader is unsafe. Please read https://msg.pyyaml.org/load for full details.
  data = yaml.load(f.read()) or {}
/scratch/cnt0024/hmg2840/albert7a/anaconda3/lib/python3.7/site-packages/distributed/utils.py:136: RuntimeWarning: Couldn't detect a suitable IP address for reaching '8.8.8.8', defaulting to '127.0.0.1': [Errno 101] Network is unreachable
  RuntimeWarning,
distributed.worker - INFO -       Start worker at:    tcp://172.30.6.48:39139
distributed.worker - INFO -          Listening to:    tcp://172.30.6.48:39139
distributed.worker - INFO -              nanny at:          172.30.6.48:39160
distributed.worker - INFO -              bokeh at:          172.30.6.48:34699
distributed.worker - INFO - Waiting to connect to:   tcp://172.30.100.3:40056
distributed.worker - INFO - -------------------------------------------------
distributed.worker - INFO -               Threads:                          1
distributed.worker - INFO -                Memory:                    4.29 GB
distributed.worker - INFO -       Local Directory: /scratch/cnt0024/hmg2840/albert7a/daskjobqueue/worker-parejdm1
distributed.worker - INFO - -------------------------------------------------
distributed.worker - INFO -         Registered to:   tcp://172.30.100.3:40056
distributed.worker - INFO - -------------------------------------------------
distributed.core - INFO - Starting established connection
/scratch/cnt0024/hmg2840/albert7a/anaconda3/lib/python3.7/site-packages/dask/config.py:168: YAMLLoadWarning: calling yaml.load() without Loader=... is deprecated, as the default Loader is unsafe. Please read https://msg.pyyaml.org/load for full details.
  data = yaml.load(f.read()) or {}
/scratch/cnt0024/hmg2840/albert7a/anaconda3/lib/python3.7/site-packages/distributed/utils.py:136: RuntimeWarning: Couldn't detect a suitable IP address for reaching '8.8.8.8', defaulting to '127.0.0.1': [Errno 101] Network is unreachable
  RuntimeWarning,
distributed.worker - INFO -       Start worker at:    tcp://172.30.6.48:46861
distributed.worker - INFO -          Listening to:    tcp://172.30.6.48:46861
distributed.worker - INFO -              nanny at:          172.30.6.48:37919
distributed.worker - INFO -              bokeh at:          172.30.6.48:45420
distributed.worker - INFO - Waiting to connect to:   tcp://172.30.100.3:40056
distributed.worker - INFO - -------------------------------------------------
distributed.worker - INFO -               Threads:                          1
distributed.worker - INFO -                Memory:                    4.29 GB
distributed.worker - INFO -       Local Directory: /scratch/cnt0024/hmg2840/albert7a/daskjobqueue/worker-vx9vegs2
distributed.worker - INFO - -------------------------------------------------
distributed.worker - INFO -         Registered to:   tcp://172.30.100.3:40056
distributed.worker - INFO - -------------------------------------------------
distributed.core - INFO - Starting established connection
/scratch/cnt0024/hmg2840/albert7a/anaconda3/lib/python3.7/site-packages/dask/config.py:168: YAMLLoadWarning: calling yaml.load() without Loader=... is deprecated, as the default Loader is unsafe. Please read https://msg.pyyaml.org/load for full details.
  data = yaml.load(f.read()) or {}
/scratch/cnt0024/hmg2840/albert7a/anaconda3/lib/python3.7/site-packages/distributed/utils.py:136: RuntimeWarning: Couldn't detect a suitable IP address for reaching '8.8.8.8', defaulting to '127.0.0.1': [Errno 101] Network is unreachable
  RuntimeWarning,
distributed.worker - INFO -       Start worker at:    tcp://172.30.6.48:44600
distributed.worker - INFO -          Listening to:    tcp://172.30.6.48:44600
distributed.worker - INFO -              nanny at:          172.30.6.48:39052
distributed.worker - INFO -              bokeh at:          172.30.6.48:35531
distributed.worker - INFO - Waiting to connect to:   tcp://172.30.100.3:40056
distributed.worker - INFO - -------------------------------------------------
distributed.worker - INFO -               Threads:                          1
distributed.worker - INFO -                Memory:                    4.29 GB
distributed.worker - INFO -       Local Directory: /scratch/cnt0024/hmg2840/albert7a/daskjobqueue/worker-2l2lwtgd
distributed.worker - INFO - -------------------------------------------------
distributed.worker - INFO -         Registered to:   tcp://172.30.100.3:40056
distributed.worker - INFO - -------------------------------------------------
distributed.core - INFO - Starting established connection
/scratch/cnt0024/hmg2840/albert7a/anaconda3/lib/python3.7/site-packages/dask/config.py:168: YAMLLoadWarning: calling yaml.load() without Loader=... is deprecated, as the default Loader is unsafe. Please read https://msg.pyyaml.org/load for full details.
  data = yaml.load(f.read()) or {}
/scratch/cnt0024/hmg2840/albert7a/anaconda3/lib/python3.7/site-packages/distributed/utils.py:136: RuntimeWarning: Couldn't detect a suitable IP address for reaching '8.8.8.8', defaulting to '127.0.0.1': [Errno 101] Network is unreachable
  RuntimeWarning,
distributed.worker - INFO -       Start worker at:    tcp://172.30.6.48:46001
distributed.worker - INFO -          Listening to:    tcp://172.30.6.48:46001
distributed.worker - INFO -              nanny at:          172.30.6.48:41776
distributed.worker - INFO -              bokeh at:          172.30.6.48:34197
distributed.worker - INFO - Waiting to connect to:   tcp://172.30.100.3:40056
distributed.worker - INFO - -------------------------------------------------
distributed.worker - INFO -               Threads:                          1
distributed.worker - INFO -                Memory:                    4.29 GB
distributed.worker - INFO -       Local Directory: /scratch/cnt0024/hmg2840/albert7a/daskjobqueue/worker-aximrc9s
distributed.worker - INFO - -------------------------------------------------
distributed.worker - INFO -         Registered to:   tcp://172.30.100.3:40056
distributed.worker - INFO - -------------------------------------------------
distributed.core - INFO - Starting established connection
distributed.utils - ERROR - Timed out trying to connect to 'tcp://172.30.100.3:40056' after 10 s: connect() didn't finish in time
Traceback (most recent call last):
  File "/scratch/cnt0024/hmg2840/albert7a/anaconda3/lib/python3.7/site-packages/distributed/comm/core.py", line 218, in connect
    quiet_exceptions=EnvironmentError,
  File "/scratch/cnt0024/hmg2840/albert7a/anaconda3/lib/python3.7/site-packages/tornado/gen.py", line 735, in run
    value = future.result()
tornado.util.TimeoutError: Timeout

During handling of the above exception, another exception occurred:

Traceback (most recent call last):
  File "/scratch/cnt0024/hmg2840/albert7a/anaconda3/lib/python3.7/site-packages/distributed/utils.py", line 713, in log_errors
    yield
  File "/scratch/cnt0024/hmg2840/albert7a/anaconda3/lib/python3.7/site-packages/distributed/worker.py", line 1994, in query_who_has
    response = yield self.scheduler.who_has(keys=deps)
  File "/scratch/cnt0024/hmg2840/albert7a/anaconda3/lib/python3.7/site-packages/tornado/gen.py", line 735, in run
    value = future.result()
  File "/scratch/cnt0024/hmg2840/albert7a/anaconda3/lib/python3.7/site-packages/tornado/gen.py", line 742, in run
    yielded = self.gen.throw(*exc_info)  # type: ignore
  File "/scratch/cnt0024/hmg2840/albert7a/anaconda3/lib/python3.7/site-packages/distributed/core.py", line 736, in send_recv_from_rpc
    comm = yield self.pool.connect(self.addr)
  File "/scratch/cnt0024/hmg2840/albert7a/anaconda3/lib/python3.7/site-packages/tornado/gen.py", line 735, in run
    value = future.result()
  File "/scratch/cnt0024/hmg2840/albert7a/anaconda3/lib/python3.7/site-packages/tornado/gen.py", line 742, in run
    yielded = self.gen.throw(*exc_info)  # type: ignore
  File "/scratch/cnt0024/hmg2840/albert7a/anaconda3/lib/python3.7/site-packages/distributed/core.py", line 864, in connect
    connection_args=self.connection_args,
  File "/scratch/cnt0024/hmg2840/albert7a/anaconda3/lib/python3.7/site-packages/tornado/gen.py", line 735, in run
    value = future.result()
  File "/scratch/cnt0024/hmg2840/albert7a/anaconda3/lib/python3.7/site-packages/tornado/gen.py", line 742, in run
    yielded = self.gen.throw(*exc_info)  # type: ignore
  File "/scratch/cnt0024/hmg2840/albert7a/anaconda3/lib/python3.7/site-packages/distributed/comm/core.py", line 230, in connect
    _raise(error)
  File "/scratch/cnt0024/hmg2840/albert7a/anaconda3/lib/python3.7/site-packages/distributed/comm/core.py", line 207, in _raise
    raise IOError(msg)
OSError: Timed out trying to connect to 'tcp://172.30.100.3:40056' after 10 s: connect() didn't finish in time
distributed.utils - ERROR - Timed out trying to connect to 'tcp://172.30.100.3:40056' after 10 s: connect() didn't finish in time
Traceback (most recent call last):
  File "/scratch/cnt0024/hmg2840/albert7a/anaconda3/lib/python3.7/site-packages/distributed/comm/core.py", line 218, in connect
    quiet_exceptions=EnvironmentError,
  File "/scratch/cnt0024/hmg2840/albert7a/anaconda3/lib/python3.7/site-packages/tornado/gen.py", line 735, in run
    value = future.result()
tornado.util.TimeoutError: Timeout

During handling of the above exception, another exception occurred:

Traceback (most recent call last):
  File "/scratch/cnt0024/hmg2840/albert7a/anaconda3/lib/python3.7/site-packages/distributed/utils.py", line 713, in log_errors
    yield
  File "/scratch/cnt0024/hmg2840/albert7a/anaconda3/lib/python3.7/site-packages/distributed/worker.py", line 1994, in query_who_has
    response = yield self.scheduler.who_has(keys=deps)
  File "/scratch/cnt0024/hmg2840/albert7a/anaconda3/lib/python3.7/site-packages/tornado/gen.py", line 735, in run
    value = future.result()
  File "/scratch/cnt0024/hmg2840/albert7a/anaconda3/lib/python3.7/site-packages/tornado/gen.py", line 742, in run
    yielded = self.gen.throw(*exc_info)  # type: ignore
  File "/scratch/cnt0024/hmg2840/albert7a/anaconda3/lib/python3.7/site-packages/distributed/core.py", line 736, in send_recv_from_rpc
    comm = yield self.pool.connect(self.addr)
  File "/scratch/cnt0024/hmg2840/albert7a/anaconda3/lib/python3.7/site-packages/tornado/gen.py", line 735, in run
    value = future.result()
  File "/scratch/cnt0024/hmg2840/albert7a/anaconda3/lib/python3.7/site-packages/tornado/gen.py", line 742, in run
    yielded = self.gen.throw(*exc_info)  # type: ignore
  File "/scratch/cnt0024/hmg2840/albert7a/anaconda3/lib/python3.7/site-packages/distributed/core.py", line 864, in connect
    connection_args=self.connection_args,
  File "/scratch/cnt0024/hmg2840/albert7a/anaconda3/lib/python3.7/site-packages/tornado/gen.py", line 735, in run
    value = future.result()
  File "/scratch/cnt0024/hmg2840/albert7a/anaconda3/lib/python3.7/site-packages/tornado/gen.py", line 742, in run
    yielded = self.gen.throw(*exc_info)  # type: ignore
  File "/scratch/cnt0024/hmg2840/albert7a/anaconda3/lib/python3.7/site-packages/distributed/comm/core.py", line 230, in connect
    _raise(error)
  File "/scratch/cnt0024/hmg2840/albert7a/anaconda3/lib/python3.7/site-packages/distributed/comm/core.py", line 207, in _raise
    raise IOError(msg)
OSError: Timed out trying to connect to 'tcp://172.30.100.3:40056' after 10 s: connect() didn't finish in time
distributed.utils - ERROR - Timed out trying to connect to 'tcp://172.30.100.3:40056' after 10 s: connect() didn't finish in time
Traceback (most recent call last):
  File "/scratch/cnt0024/hmg2840/albert7a/anaconda3/lib/python3.7/site-packages/distributed/comm/core.py", line 218, in connect
    quiet_exceptions=EnvironmentError,
  File "/scratch/cnt0024/hmg2840/albert7a/anaconda3/lib/python3.7/site-packages/tornado/gen.py", line 735, in run
    value = future.result()
tornado.util.TimeoutError: Timeout

During handling of the above exception, another exception occurred:

Traceback (most recent call last):
  File "/scratch/cnt0024/hmg2840/albert7a/anaconda3/lib/python3.7/site-packages/distributed/utils.py", line 713, in log_errors
    yield
  File "/scratch/cnt0024/hmg2840/albert7a/anaconda3/lib/python3.7/site-packages/distributed/worker.py", line 1923, in gather_dep
    yield self.query_who_has(dep)
  File "/scratch/cnt0024/hmg2840/albert7a/anaconda3/lib/python3.7/site-packages/tornado/gen.py", line 735, in run
    value = future.result()
  File "/scratch/cnt0024/hmg2840/albert7a/anaconda3/lib/python3.7/site-packages/tornado/gen.py", line 742, in run
    yielded = self.gen.throw(*exc_info)  # type: ignore
  File "/scratch/cnt0024/hmg2840/albert7a/anaconda3/lib/python3.7/site-packages/distributed/worker.py", line 1994, in query_who_has
    response = yield self.scheduler.who_has(keys=deps)
  File "/scratch/cnt0024/hmg2840/albert7a/anaconda3/lib/python3.7/site-packages/tornado/gen.py", line 735, in run
    value = future.result()
  File "/scratch/cnt0024/hmg2840/albert7a/anaconda3/lib/python3.7/site-packages/tornado/gen.py", line 742, in run
    yielded = self.gen.throw(*exc_info)  # type: ignore
  File "/scratch/cnt0024/hmg2840/albert7a/anaconda3/lib/python3.7/site-packages/distributed/core.py", line 736, in send_recv_from_rpc
    comm = yield self.pool.connect(self.addr)
  File "/scratch/cnt0024/hmg2840/albert7a/anaconda3/lib/python3.7/site-packages/tornado/gen.py", line 735, in run
    value = future.result()
  File "/scratch/cnt0024/hmg2840/albert7a/anaconda3/lib/python3.7/site-packages/tornado/gen.py", line 742, in run
    yielded = self.gen.throw(*exc_info)  # type: ignore
  File "/scratch/cnt0024/hmg2840/albert7a/anaconda3/lib/python3.7/site-packages/distributed/core.py", line 864, in connect
    connection_args=self.connection_args,
  File "/scratch/cnt0024/hmg2840/albert7a/anaconda3/lib/python3.7/site-packages/tornado/gen.py", line 735, in run
    value = future.result()
  File "/scratch/cnt0024/hmg2840/albert7a/anaconda3/lib/python3.7/site-packages/tornado/gen.py", line 742, in run
    yielded = self.gen.throw(*exc_info)  # type: ignore
  File "/scratch/cnt0024/hmg2840/albert7a/anaconda3/lib/python3.7/site-packages/distributed/comm/core.py", line 230, in connect
    _raise(error)
  File "/scratch/cnt0024/hmg2840/albert7a/anaconda3/lib/python3.7/site-packages/distributed/comm/core.py", line 207, in _raise
    raise IOError(msg)
OSError: Timed out trying to connect to 'tcp://172.30.100.3:40056' after 10 s: connect() didn't finish in time
distributed.utils - ERROR - Timed out trying to connect to 'tcp://172.30.100.3:40056' after 10 s: connect() didn't finish in time
Traceback (most recent call last):
  File "/scratch/cnt0024/hmg2840/albert7a/anaconda3/lib/python3.7/site-packages/distributed/comm/core.py", line 218, in connect
    quiet_exceptions=EnvironmentError,
  File "/scratch/cnt0024/hmg2840/albert7a/anaconda3/lib/python3.7/site-packages/tornado/gen.py", line 735, in run
    value = future.result()
tornado.util.TimeoutError: Timeout

During handling of the above exception, another exception occurred:

Traceback (most recent call last):
  File "/scratch/cnt0024/hmg2840/albert7a/anaconda3/lib/python3.7/site-packages/distributed/utils.py", line 713, in log_errors
    yield
  File "/scratch/cnt0024/hmg2840/albert7a/anaconda3/lib/python3.7/site-packages/distributed/worker.py", line 1923, in gather_dep
    yield self.query_who_has(dep)
  File "/scratch/cnt0024/hmg2840/albert7a/anaconda3/lib/python3.7/site-packages/tornado/gen.py", line 735, in run
    value = future.result()
  File "/scratch/cnt0024/hmg2840/albert7a/anaconda3/lib/python3.7/site-packages/tornado/gen.py", line 742, in run
    yielded = self.gen.throw(*exc_info)  # type: ignore
  File "/scratch/cnt0024/hmg2840/albert7a/anaconda3/lib/python3.7/site-packages/distributed/worker.py", line 1994, in query_who_has
    response = yield self.scheduler.who_has(keys=deps)
  File "/scratch/cnt0024/hmg2840/albert7a/anaconda3/lib/python3.7/site-packages/tornado/gen.py", line 735, in run
    value = future.result()
  File "/scratch/cnt0024/hmg2840/albert7a/anaconda3/lib/python3.7/site-packages/tornado/gen.py", line 742, in run
    yielded = self.gen.throw(*exc_info)  # type: ignore
  File "/scratch/cnt0024/hmg2840/albert7a/anaconda3/lib/python3.7/site-packages/distributed/core.py", line 736, in send_recv_from_rpc
    comm = yield self.pool.connect(self.addr)
  File "/scratch/cnt0024/hmg2840/albert7a/anaconda3/lib/python3.7/site-packages/tornado/gen.py", line 735, in run
    value = future.result()
  File "/scratch/cnt0024/hmg2840/albert7a/anaconda3/lib/python3.7/site-packages/tornado/gen.py", line 742, in run
    yielded = self.gen.throw(*exc_info)  # type: ignore
  File "/scratch/cnt0024/hmg2840/albert7a/anaconda3/lib/python3.7/site-packages/distributed/core.py", line 864, in connect
    connection_args=self.connection_args,
  File "/scratch/cnt0024/hmg2840/albert7a/anaconda3/lib/python3.7/site-packages/tornado/gen.py", line 735, in run
    value = future.result()
  File "/scratch/cnt0024/hmg2840/albert7a/anaconda3/lib/python3.7/site-packages/tornado/gen.py", line 742, in run
    yielded = self.gen.throw(*exc_info)  # type: ignore
  File "/scratch/cnt0024/hmg2840/albert7a/anaconda3/lib/python3.7/site-packages/distributed/comm/core.py", line 230, in connect
    _raise(error)
  File "/scratch/cnt0024/hmg2840/albert7a/anaconda3/lib/python3.7/site-packages/distributed/comm/core.py", line 207, in _raise
    raise IOError(msg)
OSError: Timed out trying to connect to 'tcp://172.30.100.3:40056' after 10 s: connect() didn't finish in time
tornado.application - ERROR - Exception in callback functools.partial(<bound method IOLoop._discard_future_result of <tornado.platform.asyncio.AsyncIOLoop object at 0x2ae469514160>>, <Future finished exception=OSError("Timed out trying to connect to 'tcp://172.30.100.3:40056' after 10 s: connect() didn't finish in time")>)
Traceback (most recent call last):
  File "/scratch/cnt0024/hmg2840/albert7a/anaconda3/lib/python3.7/site-packages/distributed/comm/core.py", line 218, in connect
    quiet_exceptions=EnvironmentError,
  File "/scratch/cnt0024/hmg2840/albert7a/anaconda3/lib/python3.7/site-packages/tornado/gen.py", line 735, in run
    value = future.result()
tornado.util.TimeoutError: Timeout

During handling of the above exception, another exception occurred:

Traceback (most recent call last):
  File "/scratch/cnt0024/hmg2840/albert7a/anaconda3/lib/python3.7/site-packages/tornado/ioloop.py", line 743, in _run_callback
    ret = callback()
  File "/scratch/cnt0024/hmg2840/albert7a/anaconda3/lib/python3.7/site-packages/tornado/ioloop.py", line 767, in _discard_future_result
    future.result()
  File "/scratch/cnt0024/hmg2840/albert7a/anaconda3/lib/python3.7/site-packages/tornado/gen.py", line 742, in run
    yielded = self.gen.throw(*exc_info)  # type: ignore
  File "/scratch/cnt0024/hmg2840/albert7a/anaconda3/lib/python3.7/site-packages/distributed/worker.py", line 1923, in gather_dep
    yield self.query_who_has(dep)
  File "/scratch/cnt0024/hmg2840/albert7a/anaconda3/lib/python3.7/site-packages/tornado/gen.py", line 735, in run
    value = future.result()
  File "/scratch/cnt0024/hmg2840/albert7a/anaconda3/lib/python3.7/site-packages/tornado/gen.py", line 742, in run
    yielded = self.gen.throw(*exc_info)  # type: ignore
  File "/scratch/cnt0024/hmg2840/albert7a/anaconda3/lib/python3.7/site-packages/distributed/worker.py", line 1994, in query_who_has
    response = yield self.scheduler.who_has(keys=deps)
  File "/scratch/cnt0024/hmg2840/albert7a/anaconda3/lib/python3.7/site-packages/tornado/gen.py", line 735, in run
    value = future.result()
  File "/scratch/cnt0024/hmg2840/albert7a/anaconda3/lib/python3.7/site-packages/tornado/gen.py", line 742, in run
    yielded = self.gen.throw(*exc_info)  # type: ignore
  File "/scratch/cnt0024/hmg2840/albert7a/anaconda3/lib/python3.7/site-packages/distributed/core.py", line 736, in send_recv_from_rpc
    comm = yield self.pool.connect(self.addr)
  File "/scratch/cnt0024/hmg2840/albert7a/anaconda3/lib/python3.7/site-packages/tornado/gen.py", line 735, in run
    value = future.result()
  File "/scratch/cnt0024/hmg2840/albert7a/anaconda3/lib/python3.7/site-packages/tornado/gen.py", line 742, in run
    yielded = self.gen.throw(*exc_info)  # type: ignore
  File "/scratch/cnt0024/hmg2840/albert7a/anaconda3/lib/python3.7/site-packages/distributed/core.py", line 864, in connect
    connection_args=self.connection_args,
  File "/scratch/cnt0024/hmg2840/albert7a/anaconda3/lib/python3.7/site-packages/tornado/gen.py", line 735, in run
    value = future.result()
  File "/scratch/cnt0024/hmg2840/albert7a/anaconda3/lib/python3.7/site-packages/tornado/gen.py", line 742, in run
    yielded = self.gen.throw(*exc_info)  # type: ignore
  File "/scratch/cnt0024/hmg2840/albert7a/anaconda3/lib/python3.7/site-packages/distributed/comm/core.py", line 230, in connect
    _raise(error)
  File "/scratch/cnt0024/hmg2840/albert7a/anaconda3/lib/python3.7/site-packages/distributed/comm/core.py", line 207, in _raise
    raise IOError(msg)
OSError: Timed out trying to connect to 'tcp://172.30.100.3:40056' after 10 s: connect() didn't finish in time
tornado.application - ERROR - Exception in callback functools.partial(<bound method IOLoop._discard_future_result of <tornado.platform.asyncio.AsyncIOLoop object at 0x2ae469514160>>, <Future finished exception=OSError("Timed out trying to connect to 'tcp://172.30.100.3:40056' after 10 s: connect() didn't finish in time")>)
Traceback (most recent call last):
  File "/scratch/cnt0024/hmg2840/albert7a/anaconda3/lib/python3.7/site-packages/distributed/comm/core.py", line 218, in connect
    quiet_exceptions=EnvironmentError,
  File "/scratch/cnt0024/hmg2840/albert7a/anaconda3/lib/python3.7/site-packages/tornado/gen.py", line 735, in run
    value = future.result()
tornado.util.TimeoutError: Timeout

During handling of the above exception, another exception occurred:

Traceback (most recent call last):
  File "/scratch/cnt0024/hmg2840/albert7a/anaconda3/lib/python3.7/site-packages/tornado/ioloop.py", line 743, in _run_callback
    ret = callback()
  File "/scratch/cnt0024/hmg2840/albert7a/anaconda3/lib/python3.7/site-packages/tornado/ioloop.py", line 767, in _discard_future_result
    future.result()
  File "/scratch/cnt0024/hmg2840/albert7a/anaconda3/lib/python3.7/site-packages/tornado/gen.py", line 742, in run
    yielded = self.gen.throw(*exc_info)  # type: ignore
  File "/scratch/cnt0024/hmg2840/albert7a/anaconda3/lib/python3.7/site-packages/distributed/worker.py", line 1923, in gather_dep
    yield self.query_who_has(dep)
  File "/scratch/cnt0024/hmg2840/albert7a/anaconda3/lib/python3.7/site-packages/tornado/gen.py", line 735, in run
    value = future.result()
  File "/scratch/cnt0024/hmg2840/albert7a/anaconda3/lib/python3.7/site-packages/tornado/gen.py", line 742, in run
    yielded = self.gen.throw(*exc_info)  # type: ignore
  File "/scratch/cnt0024/hmg2840/albert7a/anaconda3/lib/python3.7/site-packages/distributed/worker.py", line 1994, in query_who_has
    response = yield self.scheduler.who_has(keys=deps)
  File "/scratch/cnt0024/hmg2840/albert7a/anaconda3/lib/python3.7/site-packages/tornado/gen.py", line 735, in run
    value = future.result()
  File "/scratch/cnt0024/hmg2840/albert7a/anaconda3/lib/python3.7/site-packages/tornado/gen.py", line 742, in run
    yielded = self.gen.throw(*exc_info)  # type: ignore
  File "/scratch/cnt0024/hmg2840/albert7a/anaconda3/lib/python3.7/site-packages/distributed/core.py", line 736, in send_recv_from_rpc
    comm = yield self.pool.connect(self.addr)
  File "/scratch/cnt0024/hmg2840/albert7a/anaconda3/lib/python3.7/site-packages/tornado/gen.py", line 735, in run
    value = future.result()
  File "/scratch/cnt0024/hmg2840/albert7a/anaconda3/lib/python3.7/site-packages/tornado/gen.py", line 742, in run
    yielded = self.gen.throw(*exc_info)  # type: ignore
  File "/scratch/cnt0024/hmg2840/albert7a/anaconda3/lib/python3.7/site-packages/distributed/core.py", line 864, in connect
    connection_args=self.connection_args,
  File "/scratch/cnt0024/hmg2840/albert7a/anaconda3/lib/python3.7/site-packages/tornado/gen.py", line 735, in run
    value = future.result()
  File "/scratch/cnt0024/hmg2840/albert7a/anaconda3/lib/python3.7/site-packages/tornado/gen.py", line 742, in run
    yielded = self.gen.throw(*exc_info)  # type: ignore
  File "/scratch/cnt0024/hmg2840/albert7a/anaconda3/lib/python3.7/site-packages/distributed/comm/core.py", line 230, in connect
    _raise(error)
  File "/scratch/cnt0024/hmg2840/albert7a/anaconda3/lib/python3.7/site-packages/distributed/comm/core.py", line 207, in _raise
    raise IOError(msg)
OSError: Timed out trying to connect to 'tcp://172.30.100.3:40056' after 10 s: connect() didn't finish in time
distributed.utils - ERROR - Timed out trying to connect to 'tcp://172.30.100.3:40056' after 10 s: connect() didn't finish in time
Traceback (most recent call last):
  File "/scratch/cnt0024/hmg2840/albert7a/anaconda3/lib/python3.7/site-packages/distributed/comm/core.py", line 218, in connect
    quiet_exceptions=EnvironmentError,
  File "/scratch/cnt0024/hmg2840/albert7a/anaconda3/lib/python3.7/site-packages/tornado/gen.py", line 735, in run
    value = future.result()
tornado.util.TimeoutError: Timeout

During handling of the above exception, another exception occurred:

Traceback (most recent call last):
  File "/scratch/cnt0024/hmg2840/albert7a/anaconda3/lib/python3.7/site-packages/distributed/utils.py", line 713, in log_errors
    yield
  File "/scratch/cnt0024/hmg2840/albert7a/anaconda3/lib/python3.7/site-packages/distributed/worker.py", line 1994, in query_who_has
    response = yield self.scheduler.who_has(keys=deps)
  File "/scratch/cnt0024/hmg2840/albert7a/anaconda3/lib/python3.7/site-packages/tornado/gen.py", line 735, in run
    value = future.result()
  File "/scratch/cnt0024/hmg2840/albert7a/anaconda3/lib/python3.7/site-packages/tornado/gen.py", line 742, in run
    yielded = self.gen.throw(*exc_info)  # type: ignore
  File "/scratch/cnt0024/hmg2840/albert7a/anaconda3/lib/python3.7/site-packages/distributed/core.py", line 736, in send_recv_from_rpc
    comm = yield self.pool.connect(self.addr)
  File "/scratch/cnt0024/hmg2840/albert7a/anaconda3/lib/python3.7/site-packages/tornado/gen.py", line 735, in run
    value = future.result()
  File "/scratch/cnt0024/hmg2840/albert7a/anaconda3/lib/python3.7/site-packages/tornado/gen.py", line 742, in run
    yielded = self.gen.throw(*exc_info)  # type: ignore
  File "/scratch/cnt0024/hmg2840/albert7a/anaconda3/lib/python3.7/site-packages/distributed/core.py", line 864, in connect
    connection_args=self.connection_args,
  File "/scratch/cnt0024/hmg2840/albert7a/anaconda3/lib/python3.7/site-packages/tornado/gen.py", line 735, in run
    value = future.result()
  File "/scratch/cnt0024/hmg2840/albert7a/anaconda3/lib/python3.7/site-packages/tornado/gen.py", line 742, in run
    yielded = self.gen.throw(*exc_info)  # type: ignore
  File "/scratch/cnt0024/hmg2840/albert7a/anaconda3/lib/python3.7/site-packages/distributed/comm/core.py", line 230, in connect
    _raise(error)
  File "/scratch/cnt0024/hmg2840/albert7a/anaconda3/lib/python3.7/site-packages/distributed/comm/core.py", line 207, in _raise
    raise IOError(msg)
OSError: Timed out trying to connect to 'tcp://172.30.100.3:40056' after 10 s: connect() didn't finish in time
distributed.utils - ERROR - Timed out trying to connect to 'tcp://172.30.100.3:40056' after 10 s: connect() didn't finish in time
Traceback (most recent call last):
  File "/scratch/cnt0024/hmg2840/albert7a/anaconda3/lib/python3.7/site-packages/distributed/comm/core.py", line 218, in connect
    quiet_exceptions=EnvironmentError,
  File "/scratch/cnt0024/hmg2840/albert7a/anaconda3/lib/python3.7/site-packages/tornado/gen.py", line 735, in run
    value = future.result()
tornado.util.TimeoutError: Timeout

During handling of the above exception, another exception occurred:

Traceback (most recent call last):
  File "/scratch/cnt0024/hmg2840/albert7a/anaconda3/lib/python3.7/site-packages/distributed/utils.py", line 713, in log_errors
    yield
  File "/scratch/cnt0024/hmg2840/albert7a/anaconda3/lib/python3.7/site-packages/distributed/worker.py", line 1923, in gather_dep
    yield self.query_who_has(dep)
  File "/scratch/cnt0024/hmg2840/albert7a/anaconda3/lib/python3.7/site-packages/tornado/gen.py", line 735, in run
    value = future.result()
  File "/scratch/cnt0024/hmg2840/albert7a/anaconda3/lib/python3.7/site-packages/tornado/gen.py", line 742, in run
    yielded = self.gen.throw(*exc_info)  # type: ignore
  File "/scratch/cnt0024/hmg2840/albert7a/anaconda3/lib/python3.7/site-packages/distributed/worker.py", line 1994, in query_who_has
    response = yield self.scheduler.who_has(keys=deps)
  File "/scratch/cnt0024/hmg2840/albert7a/anaconda3/lib/python3.7/site-packages/tornado/gen.py", line 735, in run
    value = future.result()
  File "/scratch/cnt0024/hmg2840/albert7a/anaconda3/lib/python3.7/site-packages/tornado/gen.py", line 742, in run
    yielded = self.gen.throw(*exc_info)  # type: ignore
  File "/scratch/cnt0024/hmg2840/albert7a/anaconda3/lib/python3.7/site-packages/distributed/core.py", line 736, in send_recv_from_rpc
    comm = yield self.pool.connect(self.addr)
  File "/scratch/cnt0024/hmg2840/albert7a/anaconda3/lib/python3.7/site-packages/tornado/gen.py", line 735, in run
    value = future.result()
  File "/scratch/cnt0024/hmg2840/albert7a/anaconda3/lib/python3.7/site-packages/tornado/gen.py", line 742, in run
    yielded = self.gen.throw(*exc_info)  # type: ignore
  File "/scratch/cnt0024/hmg2840/albert7a/anaconda3/lib/python3.7/site-packages/distributed/core.py", line 864, in connect
    connection_args=self.connection_args,
  File "/scratch/cnt0024/hmg2840/albert7a/anaconda3/lib/python3.7/site-packages/tornado/gen.py", line 735, in run
    value = future.result()
  File "/scratch/cnt0024/hmg2840/albert7a/anaconda3/lib/python3.7/site-packages/tornado/gen.py", line 742, in run
    yielded = self.gen.throw(*exc_info)  # type: ignore
  File "/scratch/cnt0024/hmg2840/albert7a/anaconda3/lib/python3.7/site-packages/distributed/comm/core.py", line 230, in connect
    _raise(error)
  File "/scratch/cnt0024/hmg2840/albert7a/anaconda3/lib/python3.7/site-packages/distributed/comm/core.py", line 207, in _raise
    raise IOError(msg)
OSError: Timed out trying to connect to 'tcp://172.30.100.3:40056' after 10 s: connect() didn't finish in time
tornado.application - ERROR - Exception in callback functools.partial(<bound method IOLoop._discard_future_result of <tornado.platform.asyncio.AsyncIOLoop object at 0x2ae469514160>>, <Future finished exception=OSError("Timed out trying to connect to 'tcp://172.30.100.3:40056' after 10 s: connect() didn't finish in time")>)
Traceback (most recent call last):
  File "/scratch/cnt0024/hmg2840/albert7a/anaconda3/lib/python3.7/site-packages/distributed/comm/core.py", line 218, in connect
    quiet_exceptions=EnvironmentError,
  File "/scratch/cnt0024/hmg2840/albert7a/anaconda3/lib/python3.7/site-packages/tornado/gen.py", line 735, in run
    value = future.result()
tornado.util.TimeoutError: Timeout

During handling of the above exception, another exception occurred:

Traceback (most recent call last):
  File "/scratch/cnt0024/hmg2840/albert7a/anaconda3/lib/python3.7/site-packages/tornado/ioloop.py", line 743, in _run_callback
    ret = callback()
  File "/scratch/cnt0024/hmg2840/albert7a/anaconda3/lib/python3.7/site-packages/tornado/ioloop.py", line 767, in _discard_future_result
    future.result()
  File "/scratch/cnt0024/hmg2840/albert7a/anaconda3/lib/python3.7/site-packages/tornado/gen.py", line 742, in run
    yielded = self.gen.throw(*exc_info)  # type: ignore
  File "/scratch/cnt0024/hmg2840/albert7a/anaconda3/lib/python3.7/site-packages/distributed/worker.py", line 1923, in gather_dep
    yield self.query_who_has(dep)
  File "/scratch/cnt0024/hmg2840/albert7a/anaconda3/lib/python3.7/site-packages/tornado/gen.py", line 735, in run
    value = future.result()
  File "/scratch/cnt0024/hmg2840/albert7a/anaconda3/lib/python3.7/site-packages/tornado/gen.py", line 742, in run
    yielded = self.gen.throw(*exc_info)  # type: ignore
  File "/scratch/cnt0024/hmg2840/albert7a/anaconda3/lib/python3.7/site-packages/distributed/worker.py", line 1994, in query_who_has
    response = yield self.scheduler.who_has(keys=deps)
  File "/scratch/cnt0024/hmg2840/albert7a/anaconda3/lib/python3.7/site-packages/tornado/gen.py", line 735, in run
    value = future.result()
  File "/scratch/cnt0024/hmg2840/albert7a/anaconda3/lib/python3.7/site-packages/tornado/gen.py", line 742, in run
    yielded = self.gen.throw(*exc_info)  # type: ignore
  File "/scratch/cnt0024/hmg2840/albert7a/anaconda3/lib/python3.7/site-packages/distributed/core.py", line 736, in send_recv_from_rpc
    comm = yield self.pool.connect(self.addr)
  File "/scratch/cnt0024/hmg2840/albert7a/anaconda3/lib/python3.7/site-packages/tornado/gen.py", line 735, in run
    value = future.result()
  File "/scratch/cnt0024/hmg2840/albert7a/anaconda3/lib/python3.7/site-packages/tornado/gen.py", line 742, in run
    yielded = self.gen.throw(*exc_info)  # type: ignore
  File "/scratch/cnt0024/hmg2840/albert7a/anaconda3/lib/python3.7/site-packages/distributed/core.py", line 864, in connect
    connection_args=self.connection_args,
  File "/scratch/cnt0024/hmg2840/albert7a/anaconda3/lib/python3.7/site-packages/tornado/gen.py", line 735, in run
    value = future.result()
  File "/scratch/cnt0024/hmg2840/albert7a/anaconda3/lib/python3.7/site-packages/tornado/gen.py", line 742, in run
    yielded = self.gen.throw(*exc_info)  # type: ignore
  File "/scratch/cnt0024/hmg2840/albert7a/anaconda3/lib/python3.7/site-packages/distributed/comm/core.py", line 230, in connect
    _raise(error)
  File "/scratch/cnt0024/hmg2840/albert7a/anaconda3/lib/python3.7/site-packages/distributed/comm/core.py", line 207, in _raise
    raise IOError(msg)
OSError: Timed out trying to connect to 'tcp://172.30.100.3:40056' after 10 s: connect() didn't finish in time
distributed.utils - ERROR - Timed out trying to connect to 'tcp://172.30.100.3:40056' after 10 s: connect() didn't finish in time
Traceback (most recent call last):
  File "/scratch/cnt0024/hmg2840/albert7a/anaconda3/lib/python3.7/site-packages/distributed/comm/core.py", line 218, in connect
    quiet_exceptions=EnvironmentError,
  File "/scratch/cnt0024/hmg2840/albert7a/anaconda3/lib/python3.7/site-packages/tornado/gen.py", line 735, in run
    value = future.result()
tornado.util.TimeoutError: Timeout

During handling of the above exception, another exception occurred:

Traceback (most recent call last):
  File "/scratch/cnt0024/hmg2840/albert7a/anaconda3/lib/python3.7/site-packages/distributed/utils.py", line 713, in log_errors
    yield
  File "/scratch/cnt0024/hmg2840/albert7a/anaconda3/lib/python3.7/site-packages/distributed/worker.py", line 1994, in query_who_has
    response = yield self.scheduler.who_has(keys=deps)
  File "/scratch/cnt0024/hmg2840/albert7a/anaconda3/lib/python3.7/site-packages/tornado/gen.py", line 735, in run
    value = future.result()
  File "/scratch/cnt0024/hmg2840/albert7a/anaconda3/lib/python3.7/site-packages/tornado/gen.py", line 742, in run
    yielded = self.gen.throw(*exc_info)  # type: ignore
  File "/scratch/cnt0024/hmg2840/albert7a/anaconda3/lib/python3.7/site-packages/distributed/core.py", line 736, in send_recv_from_rpc
    comm = yield self.pool.connect(self.addr)
  File "/scratch/cnt0024/hmg2840/albert7a/anaconda3/lib/python3.7/site-packages/tornado/gen.py", line 735, in run
    value = future.result()
  File "/scratch/cnt0024/hmg2840/albert7a/anaconda3/lib/python3.7/site-packages/tornado/gen.py", line 742, in run
    yielded = self.gen.throw(*exc_info)  # type: ignore
  File "/scratch/cnt0024/hmg2840/albert7a/anaconda3/lib/python3.7/site-packages/distributed/core.py", line 864, in connect
    connection_args=self.connection_args,
  File "/scratch/cnt0024/hmg2840/albert7a/anaconda3/lib/python3.7/site-packages/tornado/gen.py", line 735, in run
    value = future.result()
  File "/scratch/cnt0024/hmg2840/albert7a/anaconda3/lib/python3.7/site-packages/tornado/gen.py", line 742, in run
    yielded = self.gen.throw(*exc_info)  # type: ignore
  File "/scratch/cnt0024/hmg2840/albert7a/anaconda3/lib/python3.7/site-packages/distributed/comm/core.py", line 230, in connect
    _raise(error)
  File "/scratch/cnt0024/hmg2840/albert7a/anaconda3/lib/python3.7/site-packages/distributed/comm/core.py", line 207, in _raise
    raise IOError(msg)
OSError: Timed out trying to connect to 'tcp://172.30.100.3:40056' after 10 s: connect() didn't finish in time
distributed.utils - ERROR - Timed out trying to connect to 'tcp://172.30.100.3:40056' after 10 s: connect() didn't finish in time
Traceback (most recent call last):
  File "/scratch/cnt0024/hmg2840/albert7a/anaconda3/lib/python3.7/site-packages/distributed/comm/core.py", line 218, in connect
    quiet_exceptions=EnvironmentError,
  File "/scratch/cnt0024/hmg2840/albert7a/anaconda3/lib/python3.7/site-packages/tornado/gen.py", line 735, in run
    value = future.result()
tornado.util.TimeoutError: Timeout

During handling of the above exception, another exception occurred:

Traceback (most recent call last):
  File "/scratch/cnt0024/hmg2840/albert7a/anaconda3/lib/python3.7/site-packages/distributed/utils.py", line 713, in log_errors
    yield
  File "/scratch/cnt0024/hmg2840/albert7a/anaconda3/lib/python3.7/site-packages/distributed/worker.py", line 1923, in gather_dep
    yield self.query_who_has(dep)
  File "/scratch/cnt0024/hmg2840/albert7a/anaconda3/lib/python3.7/site-packages/tornado/gen.py", line 735, in run
    value = future.result()
  File "/scratch/cnt0024/hmg2840/albert7a/anaconda3/lib/python3.7/site-packages/tornado/gen.py", line 742, in run
    yielded = self.gen.throw(*exc_info)  # type: ignore
  File "/scratch/cnt0024/hmg2840/albert7a/anaconda3/lib/python3.7/site-packages/distributed/worker.py", line 1994, in query_who_has
    response = yield self.scheduler.who_has(keys=deps)
  File "/scratch/cnt0024/hmg2840/albert7a/anaconda3/lib/python3.7/site-packages/tornado/gen.py", line 735, in run
    value = future.result()
  File "/scratch/cnt0024/hmg2840/albert7a/anaconda3/lib/python3.7/site-packages/tornado/gen.py", line 742, in run
    yielded = self.gen.throw(*exc_info)  # type: ignore
  File "/scratch/cnt0024/hmg2840/albert7a/anaconda3/lib/python3.7/site-packages/distributed/core.py", line 736, in send_recv_from_rpc
    comm = yield self.pool.connect(self.addr)
  File "/scratch/cnt0024/hmg2840/albert7a/anaconda3/lib/python3.7/site-packages/tornado/gen.py", line 735, in run
    value = future.result()
  File "/scratch/cnt0024/hmg2840/albert7a/anaconda3/lib/python3.7/site-packages/tornado/gen.py", line 742, in run
    yielded = self.gen.throw(*exc_info)  # type: ignore
  File "/scratch/cnt0024/hmg2840/albert7a/anaconda3/lib/python3.7/site-packages/distributed/core.py", line 864, in connect
    connection_args=self.connection_args,
  File "/scratch/cnt0024/hmg2840/albert7a/anaconda3/lib/python3.7/site-packages/tornado/gen.py", line 735, in run
    value = future.result()
  File "/scratch/cnt0024/hmg2840/albert7a/anaconda3/lib/python3.7/site-packages/tornado/gen.py", line 742, in run
    yielded = self.gen.throw(*exc_info)  # type: ignore
  File "/scratch/cnt0024/hmg2840/albert7a/anaconda3/lib/python3.7/site-packages/distributed/comm/core.py", line 230, in connect
    _raise(error)
  File "/scratch/cnt0024/hmg2840/albert7a/anaconda3/lib/python3.7/site-packages/distributed/comm/core.py", line 207, in _raise
    raise IOError(msg)
OSError: Timed out trying to connect to 'tcp://172.30.100.3:40056' after 10 s: connect() didn't finish in time
tornado.application - ERROR - Exception in callback functools.partial(<bound method IOLoop._discard_future_result of <tornado.platform.asyncio.AsyncIOLoop object at 0x2ae469514160>>, <Future finished exception=OSError("Timed out trying to connect to 'tcp://172.30.100.3:40056' after 10 s: connect() didn't finish in time")>)
Traceback (most recent call last):
  File "/scratch/cnt0024/hmg2840/albert7a/anaconda3/lib/python3.7/site-packages/distributed/comm/core.py", line 218, in connect
    quiet_exceptions=EnvironmentError,
  File "/scratch/cnt0024/hmg2840/albert7a/anaconda3/lib/python3.7/site-packages/tornado/gen.py", line 735, in run
    value = future.result()
tornado.util.TimeoutError: Timeout

During handling of the above exception, another exception occurred:

Traceback (most recent call last):
  File "/scratch/cnt0024/hmg2840/albert7a/anaconda3/lib/python3.7/site-packages/tornado/ioloop.py", line 743, in _run_callback
    ret = callback()
  File "/scratch/cnt0024/hmg2840/albert7a/anaconda3/lib/python3.7/site-packages/tornado/ioloop.py", line 767, in _discard_future_result
    future.result()
  File "/scratch/cnt0024/hmg2840/albert7a/anaconda3/lib/python3.7/site-packages/tornado/gen.py", line 742, in run
    yielded = self.gen.throw(*exc_info)  # type: ignore
  File "/scratch/cnt0024/hmg2840/albert7a/anaconda3/lib/python3.7/site-packages/distributed/worker.py", line 1923, in gather_dep
    yield self.query_who_has(dep)
  File "/scratch/cnt0024/hmg2840/albert7a/anaconda3/lib/python3.7/site-packages/tornado/gen.py", line 735, in run
    value = future.result()
  File "/scratch/cnt0024/hmg2840/albert7a/anaconda3/lib/python3.7/site-packages/tornado/gen.py", line 742, in run
    yielded = self.gen.throw(*exc_info)  # type: ignore
  File "/scratch/cnt0024/hmg2840/albert7a/anaconda3/lib/python3.7/site-packages/distributed/worker.py", line 1994, in query_who_has
    response = yield self.scheduler.who_has(keys=deps)
  File "/scratch/cnt0024/hmg2840/albert7a/anaconda3/lib/python3.7/site-packages/tornado/gen.py", line 735, in run
    value = future.result()
  File "/scratch/cnt0024/hmg2840/albert7a/anaconda3/lib/python3.7/site-packages/tornado/gen.py", line 742, in run
    yielded = self.gen.throw(*exc_info)  # type: ignore
  File "/scratch/cnt0024/hmg2840/albert7a/anaconda3/lib/python3.7/site-packages/distributed/core.py", line 736, in send_recv_from_rpc
    comm = yield self.pool.connect(self.addr)
  File "/scratch/cnt0024/hmg2840/albert7a/anaconda3/lib/python3.7/site-packages/tornado/gen.py", line 735, in run
    value = future.result()
  File "/scratch/cnt0024/hmg2840/albert7a/anaconda3/lib/python3.7/site-packages/tornado/gen.py", line 742, in run
    yielded = self.gen.throw(*exc_info)  # type: ignore
  File "/scratch/cnt0024/hmg2840/albert7a/anaconda3/lib/python3.7/site-packages/distributed/core.py", line 864, in connect
    connection_args=self.connection_args,
  File "/scratch/cnt0024/hmg2840/albert7a/anaconda3/lib/python3.7/site-packages/tornado/gen.py", line 735, in run
    value = future.result()
  File "/scratch/cnt0024/hmg2840/albert7a/anaconda3/lib/python3.7/site-packages/tornado/gen.py", line 742, in run
    yielded = self.gen.throw(*exc_info)  # type: ignore
  File "/scratch/cnt0024/hmg2840/albert7a/anaconda3/lib/python3.7/site-packages/distributed/comm/core.py", line 230, in connect
    _raise(error)
  File "/scratch/cnt0024/hmg2840/albert7a/anaconda3/lib/python3.7/site-packages/distributed/comm/core.py", line 207, in _raise
    raise IOError(msg)
OSError: Timed out trying to connect to 'tcp://172.30.100.3:40056' after 10 s: connect() didn't finish in time
distributed.utils - ERROR - Timed out trying to connect to 'tcp://172.30.100.3:40056' after 10 s: connect() didn't finish in time
Traceback (most recent call last):
  File "/scratch/cnt0024/hmg2840/albert7a/anaconda3/lib/python3.7/site-packages/distributed/comm/core.py", line 218, in connect
    quiet_exceptions=EnvironmentError,
  File "/scratch/cnt0024/hmg2840/albert7a/anaconda3/lib/python3.7/site-packages/tornado/gen.py", line 735, in run
    value = future.result()
tornado.util.TimeoutError: Timeout

During handling of the above exception, another exception occurred:

Traceback (most recent call last):
  File "/scratch/cnt0024/hmg2840/albert7a/anaconda3/lib/python3.7/site-packages/distributed/utils.py", line 713, in log_errors
    yield
  File "/scratch/cnt0024/hmg2840/albert7a/anaconda3/lib/python3.7/site-packages/distributed/worker.py", line 1994, in query_who_has
    response = yield self.scheduler.who_has(keys=deps)
  File "/scratch/cnt0024/hmg2840/albert7a/anaconda3/lib/python3.7/site-packages/tornado/gen.py", line 735, in run
    value = future.result()
  File "/scratch/cnt0024/hmg2840/albert7a/anaconda3/lib/python3.7/site-packages/tornado/gen.py", line 742, in run
    yielded = self.gen.throw(*exc_info)  # type: ignore
  File "/scratch/cnt0024/hmg2840/albert7a/anaconda3/lib/python3.7/site-packages/distributed/core.py", line 736, in send_recv_from_rpc
    comm = yield self.pool.connect(self.addr)
  File "/scratch/cnt0024/hmg2840/albert7a/anaconda3/lib/python3.7/site-packages/tornado/gen.py", line 735, in run
    value = future.result()
  File "/scratch/cnt0024/hmg2840/albert7a/anaconda3/lib/python3.7/site-packages/tornado/gen.py", line 742, in run
    yielded = self.gen.throw(*exc_info)  # type: ignore
  File "/scratch/cnt0024/hmg2840/albert7a/anaconda3/lib/python3.7/site-packages/distributed/core.py", line 864, in connect
    connection_args=self.connection_args,
  File "/scratch/cnt0024/hmg2840/albert7a/anaconda3/lib/python3.7/site-packages/tornado/gen.py", line 735, in run
    value = future.result()
  File "/scratch/cnt0024/hmg2840/albert7a/anaconda3/lib/python3.7/site-packages/tornado/gen.py", line 742, in run
    yielded = self.gen.throw(*exc_info)  # type: ignore
  File "/scratch/cnt0024/hmg2840/albert7a/anaconda3/lib/python3.7/site-packages/distributed/comm/core.py", line 230, in connect
    _raise(error)
  File "/scratch/cnt0024/hmg2840/albert7a/anaconda3/lib/python3.7/site-packages/distributed/comm/core.py", line 207, in _raise
    raise IOError(msg)
OSError: Timed out trying to connect to 'tcp://172.30.100.3:40056' after 10 s: connect() didn't finish in time
distributed.utils - ERROR - Timed out trying to connect to 'tcp://172.30.100.3:40056' after 10 s: connect() didn't finish in time
Traceback (most recent call last):
  File "/scratch/cnt0024/hmg2840/albert7a/anaconda3/lib/python3.7/site-packages/distributed/comm/core.py", line 218, in connect
    quiet_exceptions=EnvironmentError,
  File "/scratch/cnt0024/hmg2840/albert7a/anaconda3/lib/python3.7/site-packages/tornado/gen.py", line 735, in run
    value = future.result()
tornado.util.TimeoutError: Timeout

During handling of the above exception, another exception occurred:

Traceback (most recent call last):
  File "/scratch/cnt0024/hmg2840/albert7a/anaconda3/lib/python3.7/site-packages/distributed/utils.py", line 713, in log_errors
    yield
  File "/scratch/cnt0024/hmg2840/albert7a/anaconda3/lib/python3.7/site-packages/distributed/worker.py", line 1923, in gather_dep
    yield self.query_who_has(dep)
  File "/scratch/cnt0024/hmg2840/albert7a/anaconda3/lib/python3.7/site-packages/tornado/gen.py", line 735, in run
    value = future.result()
  File "/scratch/cnt0024/hmg2840/albert7a/anaconda3/lib/python3.7/site-packages/tornado/gen.py", line 742, in run
    yielded = self.gen.throw(*exc_info)  # type: ignore
  File "/scratch/cnt0024/hmg2840/albert7a/anaconda3/lib/python3.7/site-packages/distributed/worker.py", line 1994, in query_who_has
    response = yield self.scheduler.who_has(keys=deps)
  File "/scratch/cnt0024/hmg2840/albert7a/anaconda3/lib/python3.7/site-packages/tornado/gen.py", line 735, in run
    value = future.result()
  File "/scratch/cnt0024/hmg2840/albert7a/anaconda3/lib/python3.7/site-packages/tornado/gen.py", line 742, in run
    yielded = self.gen.throw(*exc_info)  # type: ignore
  File "/scratch/cnt0024/hmg2840/albert7a/anaconda3/lib/python3.7/site-packages/distributed/core.py", line 736, in send_recv_from_rpc
    comm = yield self.pool.connect(self.addr)
  File "/scratch/cnt0024/hmg2840/albert7a/anaconda3/lib/python3.7/site-packages/tornado/gen.py", line 735, in run
    value = future.result()
  File "/scratch/cnt0024/hmg2840/albert7a/anaconda3/lib/python3.7/site-packages/tornado/gen.py", line 742, in run
    yielded = self.gen.throw(*exc_info)  # type: ignore
  File "/scratch/cnt0024/hmg2840/albert7a/anaconda3/lib/python3.7/site-packages/distributed/core.py", line 864, in connect
    connection_args=self.connection_args,
  File "/scratch/cnt0024/hmg2840/albert7a/anaconda3/lib/python3.7/site-packages/tornado/gen.py", line 735, in run
    value = future.result()
  File "/scratch/cnt0024/hmg2840/albert7a/anaconda3/lib/python3.7/site-packages/tornado/gen.py", line 742, in run
    yielded = self.gen.throw(*exc_info)  # type: ignore
  File "/scratch/cnt0024/hmg2840/albert7a/anaconda3/lib/python3.7/site-packages/distributed/comm/core.py", line 230, in connect
    _raise(error)
  File "/scratch/cnt0024/hmg2840/albert7a/anaconda3/lib/python3.7/site-packages/distributed/comm/core.py", line 207, in _raise
    raise IOError(msg)
OSError: Timed out trying to connect to 'tcp://172.30.100.3:40056' after 10 s: connect() didn't finish in time
tornado.application - ERROR - Exception in callback functools.partial(<bound method IOLoop._discard_future_result of <tornado.platform.asyncio.AsyncIOLoop object at 0x2ae469514160>>, <Future finished exception=OSError("Timed out trying to connect to 'tcp://172.30.100.3:40056' after 10 s: connect() didn't finish in time")>)
Traceback (most recent call last):
  File "/scratch/cnt0024/hmg2840/albert7a/anaconda3/lib/python3.7/site-packages/distributed/comm/core.py", line 218, in connect
    quiet_exceptions=EnvironmentError,
  File "/scratch/cnt0024/hmg2840/albert7a/anaconda3/lib/python3.7/site-packages/tornado/gen.py", line 735, in run
    value = future.result()
tornado.util.TimeoutError: Timeout

During handling of the above exception, another exception occurred:

Traceback (most recent call last):
  File "/scratch/cnt0024/hmg2840/albert7a/anaconda3/lib/python3.7/site-packages/tornado/ioloop.py", line 743, in _run_callback
    ret = callback()
  File "/scratch/cnt0024/hmg2840/albert7a/anaconda3/lib/python3.7/site-packages/tornado/ioloop.py", line 767, in _discard_future_result
    future.result()
  File "/scratch/cnt0024/hmg2840/albert7a/anaconda3/lib/python3.7/site-packages/tornado/gen.py", line 742, in run
    yielded = self.gen.throw(*exc_info)  # type: ignore
  File "/scratch/cnt0024/hmg2840/albert7a/anaconda3/lib/python3.7/site-packages/distributed/worker.py", line 1923, in gather_dep
    yield self.query_who_has(dep)
  File "/scratch/cnt0024/hmg2840/albert7a/anaconda3/lib/python3.7/site-packages/tornado/gen.py", line 735, in run
    value = future.result()
  File "/scratch/cnt0024/hmg2840/albert7a/anaconda3/lib/python3.7/site-packages/tornado/gen.py", line 742, in run
    yielded = self.gen.throw(*exc_info)  # type: ignore
  File "/scratch/cnt0024/hmg2840/albert7a/anaconda3/lib/python3.7/site-packages/distributed/worker.py", line 1994, in query_who_has
    response = yield self.scheduler.who_has(keys=deps)
  File "/scratch/cnt0024/hmg2840/albert7a/anaconda3/lib/python3.7/site-packages/tornado/gen.py", line 735, in run
    value = future.result()
  File "/scratch/cnt0024/hmg2840/albert7a/anaconda3/lib/python3.7/site-packages/tornado/gen.py", line 742, in run
    yielded = self.gen.throw(*exc_info)  # type: ignore
  File "/scratch/cnt0024/hmg2840/albert7a/anaconda3/lib/python3.7/site-packages/distributed/core.py", line 736, in send_recv_from_rpc
    comm = yield self.pool.connect(self.addr)
  File "/scratch/cnt0024/hmg2840/albert7a/anaconda3/lib/python3.7/site-packages/tornado/gen.py", line 735, in run
    value = future.result()
  File "/scratch/cnt0024/hmg2840/albert7a/anaconda3/lib/python3.7/site-packages/tornado/gen.py", line 742, in run
    yielded = self.gen.throw(*exc_info)  # type: ignore
  File "/scratch/cnt0024/hmg2840/albert7a/anaconda3/lib/python3.7/site-packages/distributed/core.py", line 864, in connect
    connection_args=self.connection_args,
  File "/scratch/cnt0024/hmg2840/albert7a/anaconda3/lib/python3.7/site-packages/tornado/gen.py", line 735, in run
    value = future.result()
  File "/scratch/cnt0024/hmg2840/albert7a/anaconda3/lib/python3.7/site-packages/tornado/gen.py", line 742, in run
    yielded = self.gen.throw(*exc_info)  # type: ignore
  File "/scratch/cnt0024/hmg2840/albert7a/anaconda3/lib/python3.7/site-packages/distributed/comm/core.py", line 230, in connect
    _raise(error)
  File "/scratch/cnt0024/hmg2840/albert7a/anaconda3/lib/python3.7/site-packages/distributed/comm/core.py", line 207, in _raise
    raise IOError(msg)
OSError: Timed out trying to connect to 'tcp://172.30.100.3:40056' after 10 s: connect() didn't finish in time
distributed.utils - ERROR - Timed out trying to connect to 'tcp://172.30.100.3:40056' after 10 s: connect() didn't finish in time
Traceback (most recent call last):
  File "/scratch/cnt0024/hmg2840/albert7a/anaconda3/lib/python3.7/site-packages/distributed/comm/core.py", line 218, in connect
    quiet_exceptions=EnvironmentError,
  File "/scratch/cnt0024/hmg2840/albert7a/anaconda3/lib/python3.7/site-packages/tornado/gen.py", line 735, in run
    value = future.result()
tornado.util.TimeoutError: Timeout

During handling of the above exception, another exception occurred:

Traceback (most recent call last):
  File "/scratch/cnt0024/hmg2840/albert7a/anaconda3/lib/python3.7/site-packages/distributed/utils.py", line 713, in log_errors
    yield
  File "/scratch/cnt0024/hmg2840/albert7a/anaconda3/lib/python3.7/site-packages/distributed/worker.py", line 1994, in query_who_has
    response = yield self.scheduler.who_has(keys=deps)
  File "/scratch/cnt0024/hmg2840/albert7a/anaconda3/lib/python3.7/site-packages/tornado/gen.py", line 735, in run
    value = future.result()
  File "/scratch/cnt0024/hmg2840/albert7a/anaconda3/lib/python3.7/site-packages/tornado/gen.py", line 742, in run
    yielded = self.gen.throw(*exc_info)  # type: ignore
  File "/scratch/cnt0024/hmg2840/albert7a/anaconda3/lib/python3.7/site-packages/distributed/core.py", line 736, in send_recv_from_rpc
    comm = yield self.pool.connect(self.addr)
  File "/scratch/cnt0024/hmg2840/albert7a/anaconda3/lib/python3.7/site-packages/tornado/gen.py", line 735, in run
    value = future.result()
  File "/scratch/cnt0024/hmg2840/albert7a/anaconda3/lib/python3.7/site-packages/tornado/gen.py", line 742, in run
    yielded = self.gen.throw(*exc_info)  # type: ignore
  File "/scratch/cnt0024/hmg2840/albert7a/anaconda3/lib/python3.7/site-packages/distributed/core.py", line 864, in connect
    connection_args=self.connection_args,
  File "/scratch/cnt0024/hmg2840/albert7a/anaconda3/lib/python3.7/site-packages/tornado/gen.py", line 735, in run
    value = future.result()
  File "/scratch/cnt0024/hmg2840/albert7a/anaconda3/lib/python3.7/site-packages/tornado/gen.py", line 742, in run
    yielded = self.gen.throw(*exc_info)  # type: ignore
  File "/scratch/cnt0024/hmg2840/albert7a/anaconda3/lib/python3.7/site-packages/distributed/comm/core.py", line 230, in connect
    _raise(error)
  File "/scratch/cnt0024/hmg2840/albert7a/anaconda3/lib/python3.7/site-packages/distributed/comm/core.py", line 207, in _raise
    raise IOError(msg)
OSError: Timed out trying to connect to 'tcp://172.30.100.3:40056' after 10 s: connect() didn't finish in time
distributed.utils - ERROR - Timed out trying to connect to 'tcp://172.30.100.3:40056' after 10 s: connect() didn't finish in time
Traceback (most recent call last):
  File "/scratch/cnt0024/hmg2840/albert7a/anaconda3/lib/python3.7/site-packages/distributed/comm/core.py", line 218, in connect
    quiet_exceptions=EnvironmentError,
  File "/scratch/cnt0024/hmg2840/albert7a/anaconda3/lib/python3.7/site-packages/tornado/gen.py", line 735, in run
    value = future.result()
tornado.util.TimeoutError: Timeout

During handling of the above exception, another exception occurred:

Traceback (most recent call last):
  File "/scratch/cnt0024/hmg2840/albert7a/anaconda3/lib/python3.7/site-packages/distributed/utils.py", line 713, in log_errors
    yield
  File "/scratch/cnt0024/hmg2840/albert7a/anaconda3/lib/python3.7/site-packages/distributed/worker.py", line 1923, in gather_dep
    yield self.query_who_has(dep)
  File "/scratch/cnt0024/hmg2840/albert7a/anaconda3/lib/python3.7/site-packages/tornado/gen.py", line 735, in run
    value = future.result()
  File "/scratch/cnt0024/hmg2840/albert7a/anaconda3/lib/python3.7/site-packages/tornado/gen.py", line 742, in run
    yielded = self.gen.throw(*exc_info)  # type: ignore
  File "/scratch/cnt0024/hmg2840/albert7a/anaconda3/lib/python3.7/site-packages/distributed/worker.py", line 1994, in query_who_has
    response = yield self.scheduler.who_has(keys=deps)
  File "/scratch/cnt0024/hmg2840/albert7a/anaconda3/lib/python3.7/site-packages/tornado/gen.py", line 735, in run
    value = future.result()
  File "/scratch/cnt0024/hmg2840/albert7a/anaconda3/lib/python3.7/site-packages/tornado/gen.py", line 742, in run
    yielded = self.gen.throw(*exc_info)  # type: ignore
  File "/scratch/cnt0024/hmg2840/albert7a/anaconda3/lib/python3.7/site-packages/distributed/core.py", line 736, in send_recv_from_rpc
    comm = yield self.pool.connect(self.addr)
  File "/scratch/cnt0024/hmg2840/albert7a/anaconda3/lib/python3.7/site-packages/tornado/gen.py", line 735, in run
    value = future.result()
  File "/scratch/cnt0024/hmg2840/albert7a/anaconda3/lib/python3.7/site-packages/tornado/gen.py", line 742, in run
    yielded = self.gen.throw(*exc_info)  # type: ignore
  File "/scratch/cnt0024/hmg2840/albert7a/anaconda3/lib/python3.7/site-packages/distributed/core.py", line 864, in connect
    connection_args=self.connection_args,
  File "/scratch/cnt0024/hmg2840/albert7a/anaconda3/lib/python3.7/site-packages/tornado/gen.py", line 735, in run
    value = future.result()
  File "/scratch/cnt0024/hmg2840/albert7a/anaconda3/lib/python3.7/site-packages/tornado/gen.py", line 742, in run
    yielded = self.gen.throw(*exc_info)  # type: ignore
  File "/scratch/cnt0024/hmg2840/albert7a/anaconda3/lib/python3.7/site-packages/distributed/comm/core.py", line 230, in connect
    _raise(error)
  File "/scratch/cnt0024/hmg2840/albert7a/anaconda3/lib/python3.7/site-packages/distributed/comm/core.py", line 207, in _raise
    raise IOError(msg)
OSError: Timed out trying to connect to 'tcp://172.30.100.3:40056' after 10 s: connect() didn't finish in time
tornado.application - ERROR - Exception in callback functools.partial(<bound method IOLoop._discard_future_result of <tornado.platform.asyncio.AsyncIOLoop object at 0x2ae469514160>>, <Future finished exception=OSError("Timed out trying to connect to 'tcp://172.30.100.3:40056' after 10 s: connect() didn't finish in time")>)
Traceback (most recent call last):
  File "/scratch/cnt0024/hmg2840/albert7a/anaconda3/lib/python3.7/site-packages/distributed/comm/core.py", line 218, in connect
    quiet_exceptions=EnvironmentError,
  File "/scratch/cnt0024/hmg2840/albert7a/anaconda3/lib/python3.7/site-packages/tornado/gen.py", line 735, in run
    value = future.result()
tornado.util.TimeoutError: Timeout

During handling of the above exception, another exception occurred:

Traceback (most recent call last):
  File "/scratch/cnt0024/hmg2840/albert7a/anaconda3/lib/python3.7/site-packages/tornado/ioloop.py", line 743, in _run_callback
    ret = callback()
  File "/scratch/cnt0024/hmg2840/albert7a/anaconda3/lib/python3.7/site-packages/tornado/ioloop.py", line 767, in _discard_future_result
    future.result()
  File "/scratch/cnt0024/hmg2840/albert7a/anaconda3/lib/python3.7/site-packages/tornado/gen.py", line 742, in run
    yielded = self.gen.throw(*exc_info)  # type: ignore
  File "/scratch/cnt0024/hmg2840/albert7a/anaconda3/lib/python3.7/site-packages/distributed/worker.py", line 1923, in gather_dep
    yield self.query_who_has(dep)
  File "/scratch/cnt0024/hmg2840/albert7a/anaconda3/lib/python3.7/site-packages/tornado/gen.py", line 735, in run
    value = future.result()
  File "/scratch/cnt0024/hmg2840/albert7a/anaconda3/lib/python3.7/site-packages/tornado/gen.py", line 742, in run
    yielded = self.gen.throw(*exc_info)  # type: ignore
  File "/scratch/cnt0024/hmg2840/albert7a/anaconda3/lib/python3.7/site-packages/distributed/worker.py", line 1994, in query_who_has
    response = yield self.scheduler.who_has(keys=deps)
  File "/scratch/cnt0024/hmg2840/albert7a/anaconda3/lib/python3.7/site-packages/tornado/gen.py", line 735, in run
    value = future.result()
  File "/scratch/cnt0024/hmg2840/albert7a/anaconda3/lib/python3.7/site-packages/tornado/gen.py", line 742, in run
    yielded = self.gen.throw(*exc_info)  # type: ignore
  File "/scratch/cnt0024/hmg2840/albert7a/anaconda3/lib/python3.7/site-packages/distributed/core.py", line 736, in send_recv_from_rpc
    comm = yield self.pool.connect(self.addr)
  File "/scratch/cnt0024/hmg2840/albert7a/anaconda3/lib/python3.7/site-packages/tornado/gen.py", line 735, in run
    value = future.result()
  File "/scratch/cnt0024/hmg2840/albert7a/anaconda3/lib/python3.7/site-packages/tornado/gen.py", line 742, in run
    yielded = self.gen.throw(*exc_info)  # type: ignore
  File "/scratch/cnt0024/hmg2840/albert7a/anaconda3/lib/python3.7/site-packages/distributed/core.py", line 864, in connect
    connection_args=self.connection_args,
  File "/scratch/cnt0024/hmg2840/albert7a/anaconda3/lib/python3.7/site-packages/tornado/gen.py", line 735, in run
    value = future.result()
  File "/scratch/cnt0024/hmg2840/albert7a/anaconda3/lib/python3.7/site-packages/tornado/gen.py", line 742, in run
    yielded = self.gen.throw(*exc_info)  # type: ignore
  File "/scratch/cnt0024/hmg2840/albert7a/anaconda3/lib/python3.7/site-packages/distributed/comm/core.py", line 230, in connect
    _raise(error)
  File "/scratch/cnt0024/hmg2840/albert7a/anaconda3/lib/python3.7/site-packages/distributed/comm/core.py", line 207, in _raise
    raise IOError(msg)
OSError: Timed out trying to connect to 'tcp://172.30.100.3:40056' after 10 s: connect() didn't finish in time
distributed.utils - ERROR - Timed out trying to connect to 'tcp://172.30.100.3:40056' after 10 s: connect() didn't finish in time
Traceback (most recent call last):
  File "/scratch/cnt0024/hmg2840/albert7a/anaconda3/lib/python3.7/site-packages/distributed/comm/core.py", line 218, in connect
    quiet_exceptions=EnvironmentError,
  File "/scratch/cnt0024/hmg2840/albert7a/anaconda3/lib/python3.7/site-packages/tornado/gen.py", line 735, in run
    value = future.result()
tornado.util.TimeoutError: Timeout

During handling of the above exception, another exception occurred:

Traceback (most recent call last):
  File "/scratch/cnt0024/hmg2840/albert7a/anaconda3/lib/python3.7/site-packages/distributed/utils.py", line 713, in log_errors
    yield
  File "/scratch/cnt0024/hmg2840/albert7a/anaconda3/lib/python3.7/site-packages/distributed/worker.py", line 1994, in query_who_has
    response = yield self.scheduler.who_has(keys=deps)
  File "/scratch/cnt0024/hmg2840/albert7a/anaconda3/lib/python3.7/site-packages/tornado/gen.py", line 735, in run
    value = future.result()
  File "/scratch/cnt0024/hmg2840/albert7a/anaconda3/lib/python3.7/site-packages/tornado/gen.py", line 742, in run
    yielded = self.gen.throw(*exc_info)  # type: ignore
  File "/scratch/cnt0024/hmg2840/albert7a/anaconda3/lib/python3.7/site-packages/distributed/core.py", line 736, in send_recv_from_rpc
    comm = yield self.pool.connect(self.addr)
  File "/scratch/cnt0024/hmg2840/albert7a/anaconda3/lib/python3.7/site-packages/tornado/gen.py", line 735, in run
    value = future.result()
  File "/scratch/cnt0024/hmg2840/albert7a/anaconda3/lib/python3.7/site-packages/tornado/gen.py", line 742, in run
    yielded = self.gen.throw(*exc_info)  # type: ignore
  File "/scratch/cnt0024/hmg2840/albert7a/anaconda3/lib/python3.7/site-packages/distributed/core.py", line 864, in connect
    connection_args=self.connection_args,
  File "/scratch/cnt0024/hmg2840/albert7a/anaconda3/lib/python3.7/site-packages/tornado/gen.py", line 735, in run
    value = future.result()
  File "/scratch/cnt0024/hmg2840/albert7a/anaconda3/lib/python3.7/site-packages/tornado/gen.py", line 742, in run
    yielded = self.gen.throw(*exc_info)  # type: ignore
  File "/scratch/cnt0024/hmg2840/albert7a/anaconda3/lib/python3.7/site-packages/distributed/comm/core.py", line 230, in connect
    _raise(error)
  File "/scratch/cnt0024/hmg2840/albert7a/anaconda3/lib/python3.7/site-packages/distributed/comm/core.py", line 207, in _raise
    raise IOError(msg)
OSError: Timed out trying to connect to 'tcp://172.30.100.3:40056' after 10 s: connect() didn't finish in time
distributed.utils - ERROR - Timed out trying to connect to 'tcp://172.30.100.3:40056' after 10 s: connect() didn't finish in time
Traceback (most recent call last):
  File "/scratch/cnt0024/hmg2840/albert7a/anaconda3/lib/python3.7/site-packages/distributed/comm/core.py", line 218, in connect
    quiet_exceptions=EnvironmentError,
  File "/scratch/cnt0024/hmg2840/albert7a/anaconda3/lib/python3.7/site-packages/tornado/gen.py", line 735, in run
    value = future.result()
tornado.util.TimeoutError: Timeout

During handling of the above exception, another exception occurred:

Traceback (most recent call last):
  File "/scratch/cnt0024/hmg2840/albert7a/anaconda3/lib/python3.7/site-packages/distributed/utils.py", line 713, in log_errors
    yield
  File "/scratch/cnt0024/hmg2840/albert7a/anaconda3/lib/python3.7/site-packages/distributed/worker.py", line 1923, in gather_dep
    yield self.query_who_has(dep)
  File "/scratch/cnt0024/hmg2840/albert7a/anaconda3/lib/python3.7/site-packages/tornado/gen.py", line 735, in run
    value = future.result()
  File "/scratch/cnt0024/hmg2840/albert7a/anaconda3/lib/python3.7/site-packages/tornado/gen.py", line 742, in run
    yielded = self.gen.throw(*exc_info)  # type: ignore
  File "/scratch/cnt0024/hmg2840/albert7a/anaconda3/lib/python3.7/site-packages/distributed/worker.py", line 1994, in query_who_has
    response = yield self.scheduler.who_has(keys=deps)
  File "/scratch/cnt0024/hmg2840/albert7a/anaconda3/lib/python3.7/site-packages/tornado/gen.py", line 735, in run
    value = future.result()
  File "/scratch/cnt0024/hmg2840/albert7a/anaconda3/lib/python3.7/site-packages/tornado/gen.py", line 742, in run
    yielded = self.gen.throw(*exc_info)  # type: ignore
  File "/scratch/cnt0024/hmg2840/albert7a/anaconda3/lib/python3.7/site-packages/distributed/core.py", line 736, in send_recv_from_rpc
    comm = yield self.pool.connect(self.addr)
  File "/scratch/cnt0024/hmg2840/albert7a/anaconda3/lib/python3.7/site-packages/tornado/gen.py", line 735, in run
    value = future.result()
  File "/scratch/cnt0024/hmg2840/albert7a/anaconda3/lib/python3.7/site-packages/tornado/gen.py", line 742, in run
    yielded = self.gen.throw(*exc_info)  # type: ignore
  File "/scratch/cnt0024/hmg2840/albert7a/anaconda3/lib/python3.7/site-packages/distributed/core.py", line 864, in connect
    connection_args=self.connection_args,
  File "/scratch/cnt0024/hmg2840/albert7a/anaconda3/lib/python3.7/site-packages/tornado/gen.py", line 735, in run
    value = future.result()
  File "/scratch/cnt0024/hmg2840/albert7a/anaconda3/lib/python3.7/site-packages/tornado/gen.py", line 742, in run
    yielded = self.gen.throw(*exc_info)  # type: ignore
  File "/scratch/cnt0024/hmg2840/albert7a/anaconda3/lib/python3.7/site-packages/distributed/comm/core.py", line 230, in connect
    _raise(error)
  File "/scratch/cnt0024/hmg2840/albert7a/anaconda3/lib/python3.7/site-packages/distributed/comm/core.py", line 207, in _raise
    raise IOError(msg)
OSError: Timed out trying to connect to 'tcp://172.30.100.3:40056' after 10 s: connect() didn't finish in time
tornado.application - ERROR - Exception in callback functools.partial(<bound method IOLoop._discard_future_result of <tornado.platform.asyncio.AsyncIOLoop object at 0x2ae469514160>>, <Future finished exception=OSError("Timed out trying to connect to 'tcp://172.30.100.3:40056' after 10 s: connect() didn't finish in time")>)
Traceback (most recent call last):
  File "/scratch/cnt0024/hmg2840/albert7a/anaconda3/lib/python3.7/site-packages/distributed/comm/core.py", line 218, in connect
    quiet_exceptions=EnvironmentError,
  File "/scratch/cnt0024/hmg2840/albert7a/anaconda3/lib/python3.7/site-packages/tornado/gen.py", line 735, in run
    value = future.result()
tornado.util.TimeoutError: Timeout

During handling of the above exception, another exception occurred:

Traceback (most recent call last):
  File "/scratch/cnt0024/hmg2840/albert7a/anaconda3/lib/python3.7/site-packages/tornado/ioloop.py", line 743, in _run_callback
    ret = callback()
  File "/scratch/cnt0024/hmg2840/albert7a/anaconda3/lib/python3.7/site-packages/tornado/ioloop.py", line 767, in _discard_future_result
    future.result()
  File "/scratch/cnt0024/hmg2840/albert7a/anaconda3/lib/python3.7/site-packages/tornado/gen.py", line 742, in run
    yielded = self.gen.throw(*exc_info)  # type: ignore
  File "/scratch/cnt0024/hmg2840/albert7a/anaconda3/lib/python3.7/site-packages/distributed/worker.py", line 1923, in gather_dep
    yield self.query_who_has(dep)
  File "/scratch/cnt0024/hmg2840/albert7a/anaconda3/lib/python3.7/site-packages/tornado/gen.py", line 735, in run
    value = future.result()
  File "/scratch/cnt0024/hmg2840/albert7a/anaconda3/lib/python3.7/site-packages/tornado/gen.py", line 742, in run
    yielded = self.gen.throw(*exc_info)  # type: ignore
  File "/scratch/cnt0024/hmg2840/albert7a/anaconda3/lib/python3.7/site-packages/distributed/worker.py", line 1994, in query_who_has
    response = yield self.scheduler.who_has(keys=deps)
  File "/scratch/cnt0024/hmg2840/albert7a/anaconda3/lib/python3.7/site-packages/tornado/gen.py", line 735, in run
    value = future.result()
  File "/scratch/cnt0024/hmg2840/albert7a/anaconda3/lib/python3.7/site-packages/tornado/gen.py", line 742, in run
    yielded = self.gen.throw(*exc_info)  # type: ignore
  File "/scratch/cnt0024/hmg2840/albert7a/anaconda3/lib/python3.7/site-packages/distributed/core.py", line 736, in send_recv_from_rpc
    comm = yield self.pool.connect(self.addr)
  File "/scratch/cnt0024/hmg2840/albert7a/anaconda3/lib/python3.7/site-packages/tornado/gen.py", line 735, in run
    value = future.result()
  File "/scratch/cnt0024/hmg2840/albert7a/anaconda3/lib/python3.7/site-packages/tornado/gen.py", line 742, in run
    yielded = self.gen.throw(*exc_info)  # type: ignore
  File "/scratch/cnt0024/hmg2840/albert7a/anaconda3/lib/python3.7/site-packages/distributed/core.py", line 864, in connect
    connection_args=self.connection_args,
  File "/scratch/cnt0024/hmg2840/albert7a/anaconda3/lib/python3.7/site-packages/tornado/gen.py", line 735, in run
    value = future.result()
  File "/scratch/cnt0024/hmg2840/albert7a/anaconda3/lib/python3.7/site-packages/tornado/gen.py", line 742, in run
    yielded = self.gen.throw(*exc_info)  # type: ignore
  File "/scratch/cnt0024/hmg2840/albert7a/anaconda3/lib/python3.7/site-packages/distributed/comm/core.py", line 230, in connect
    _raise(error)
  File "/scratch/cnt0024/hmg2840/albert7a/anaconda3/lib/python3.7/site-packages/distributed/comm/core.py", line 207, in _raise
    raise IOError(msg)
OSError: Timed out trying to connect to 'tcp://172.30.100.3:40056' after 10 s: connect() didn't finish in time
distributed.utils - ERROR - Timed out trying to connect to 'tcp://172.30.100.3:40056' after 10 s: connect() didn't finish in time
Traceback (most recent call last):
  File "/scratch/cnt0024/hmg2840/albert7a/anaconda3/lib/python3.7/site-packages/distributed/comm/core.py", line 218, in connect
    quiet_exceptions=EnvironmentError,
  File "/scratch/cnt0024/hmg2840/albert7a/anaconda3/lib/python3.7/site-packages/tornado/gen.py", line 735, in run
    value = future.result()
tornado.util.TimeoutError: Timeout

During handling of the above exception, another exception occurred:

Traceback (most recent call last):
  File "/scratch/cnt0024/hmg2840/albert7a/anaconda3/lib/python3.7/site-packages/distributed/utils.py", line 713, in log_errors
    yield
  File "/scratch/cnt0024/hmg2840/albert7a/anaconda3/lib/python3.7/site-packages/distributed/worker.py", line 1994, in query_who_has
    response = yield self.scheduler.who_has(keys=deps)
  File "/scratch/cnt0024/hmg2840/albert7a/anaconda3/lib/python3.7/site-packages/tornado/gen.py", line 735, in run
    value = future.result()
  File "/scratch/cnt0024/hmg2840/albert7a/anaconda3/lib/python3.7/site-packages/tornado/gen.py", line 742, in run
    yielded = self.gen.throw(*exc_info)  # type: ignore
  File "/scratch/cnt0024/hmg2840/albert7a/anaconda3/lib/python3.7/site-packages/distributed/core.py", line 736, in send_recv_from_rpc
    comm = yield self.pool.connect(self.addr)
  File "/scratch/cnt0024/hmg2840/albert7a/anaconda3/lib/python3.7/site-packages/tornado/gen.py", line 735, in run
    value = future.result()
  File "/scratch/cnt0024/hmg2840/albert7a/anaconda3/lib/python3.7/site-packages/tornado/gen.py", line 742, in run
    yielded = self.gen.throw(*exc_info)  # type: ignore
  File "/scratch/cnt0024/hmg2840/albert7a/anaconda3/lib/python3.7/site-packages/distributed/core.py", line 864, in connect
    connection_args=self.connection_args,
  File "/scratch/cnt0024/hmg2840/albert7a/anaconda3/lib/python3.7/site-packages/tornado/gen.py", line 735, in run
    value = future.result()
  File "/scratch/cnt0024/hmg2840/albert7a/anaconda3/lib/python3.7/site-packages/tornado/gen.py", line 742, in run
    yielded = self.gen.throw(*exc_info)  # type: ignore
  File "/scratch/cnt0024/hmg2840/albert7a/anaconda3/lib/python3.7/site-packages/distributed/comm/core.py", line 230, in connect
    _raise(error)
  File "/scratch/cnt0024/hmg2840/albert7a/anaconda3/lib/python3.7/site-packages/distributed/comm/core.py", line 207, in _raise
    raise IOError(msg)
OSError: Timed out trying to connect to 'tcp://172.30.100.3:40056' after 10 s: connect() didn't finish in time
distributed.utils - ERROR - Timed out trying to connect to 'tcp://172.30.100.3:40056' after 10 s: connect() didn't finish in time
Traceback (most recent call last):
  File "/scratch/cnt0024/hmg2840/albert7a/anaconda3/lib/python3.7/site-packages/distributed/comm/core.py", line 218, in connect
    quiet_exceptions=EnvironmentError,
  File "/scratch/cnt0024/hmg2840/albert7a/anaconda3/lib/python3.7/site-packages/tornado/gen.py", line 735, in run
    value = future.result()
tornado.util.TimeoutError: Timeout

During handling of the above exception, another exception occurred:

Traceback (most recent call last):
  File "/scratch/cnt0024/hmg2840/albert7a/anaconda3/lib/python3.7/site-packages/distributed/utils.py", line 713, in log_errors
    yield
  File "/scratch/cnt0024/hmg2840/albert7a/anaconda3/lib/python3.7/site-packages/distributed/worker.py", line 1923, in gather_dep
    yield self.query_who_has(dep)
  File "/scratch/cnt0024/hmg2840/albert7a/anaconda3/lib/python3.7/site-packages/tornado/gen.py", line 735, in run
    value = future.result()
  File "/scratch/cnt0024/hmg2840/albert7a/anaconda3/lib/python3.7/site-packages/tornado/gen.py", line 742, in run
    yielded = self.gen.throw(*exc_info)  # type: ignore
  File "/scratch/cnt0024/hmg2840/albert7a/anaconda3/lib/python3.7/site-packages/distributed/worker.py", line 1994, in query_who_has
    response = yield self.scheduler.who_has(keys=deps)
  File "/scratch/cnt0024/hmg2840/albert7a/anaconda3/lib/python3.7/site-packages/tornado/gen.py", line 735, in run
    value = future.result()
  File "/scratch/cnt0024/hmg2840/albert7a/anaconda3/lib/python3.7/site-packages/tornado/gen.py", line 742, in run
    yielded = self.gen.throw(*exc_info)  # type: ignore
  File "/scratch/cnt0024/hmg2840/albert7a/anaconda3/lib/python3.7/site-packages/distributed/core.py", line 736, in send_recv_from_rpc
    comm = yield self.pool.connect(self.addr)
  File "/scratch/cnt0024/hmg2840/albert7a/anaconda3/lib/python3.7/site-packages/tornado/gen.py", line 735, in run
    value = future.result()
  File "/scratch/cnt0024/hmg2840/albert7a/anaconda3/lib/python3.7/site-packages/tornado/gen.py", line 742, in run
    yielded = self.gen.throw(*exc_info)  # type: ignore
  File "/scratch/cnt0024/hmg2840/albert7a/anaconda3/lib/python3.7/site-packages/distributed/core.py", line 864, in connect
    connection_args=self.connection_args,
  File "/scratch/cnt0024/hmg2840/albert7a/anaconda3/lib/python3.7/site-packages/tornado/gen.py", line 735, in run
    value = future.result()
  File "/scratch/cnt0024/hmg2840/albert7a/anaconda3/lib/python3.7/site-packages/tornado/gen.py", line 742, in run
    yielded = self.gen.throw(*exc_info)  # type: ignore
  File "/scratch/cnt0024/hmg2840/albert7a/anaconda3/lib/python3.7/site-packages/distributed/comm/core.py", line 230, in connect
    _raise(error)
  File "/scratch/cnt0024/hmg2840/albert7a/anaconda3/lib/python3.7/site-packages/distributed/comm/core.py", line 207, in _raise
    raise IOError(msg)
OSError: Timed out trying to connect to 'tcp://172.30.100.3:40056' after 10 s: connect() didn't finish in time
tornado.application - ERROR - Exception in callback functools.partial(<bound method IOLoop._discard_future_result of <tornado.platform.asyncio.AsyncIOLoop object at 0x2ae469514160>>, <Future finished exception=OSError("Timed out trying to connect to 'tcp://172.30.100.3:40056' after 10 s: connect() didn't finish in time")>)
Traceback (most recent call last):
  File "/scratch/cnt0024/hmg2840/albert7a/anaconda3/lib/python3.7/site-packages/distributed/comm/core.py", line 218, in connect
    quiet_exceptions=EnvironmentError,
  File "/scratch/cnt0024/hmg2840/albert7a/anaconda3/lib/python3.7/site-packages/tornado/gen.py", line 735, in run
    value = future.result()
tornado.util.TimeoutError: Timeout

During handling of the above exception, another exception occurred:

Traceback (most recent call last):
  File "/scratch/cnt0024/hmg2840/albert7a/anaconda3/lib/python3.7/site-packages/tornado/ioloop.py", line 743, in _run_callback
    ret = callback()
  File "/scratch/cnt0024/hmg2840/albert7a/anaconda3/lib/python3.7/site-packages/tornado/ioloop.py", line 767, in _discard_future_result
    future.result()
  File "/scratch/cnt0024/hmg2840/albert7a/anaconda3/lib/python3.7/site-packages/tornado/gen.py", line 742, in run
    yielded = self.gen.throw(*exc_info)  # type: ignore
  File "/scratch/cnt0024/hmg2840/albert7a/anaconda3/lib/python3.7/site-packages/distributed/worker.py", line 1923, in gather_dep
    yield self.query_who_has(dep)
  File "/scratch/cnt0024/hmg2840/albert7a/anaconda3/lib/python3.7/site-packages/tornado/gen.py", line 735, in run
    value = future.result()
  File "/scratch/cnt0024/hmg2840/albert7a/anaconda3/lib/python3.7/site-packages/tornado/gen.py", line 742, in run
    yielded = self.gen.throw(*exc_info)  # type: ignore
  File "/scratch/cnt0024/hmg2840/albert7a/anaconda3/lib/python3.7/site-packages/distributed/worker.py", line 1994, in query_who_has
    response = yield self.scheduler.who_has(keys=deps)
  File "/scratch/cnt0024/hmg2840/albert7a/anaconda3/lib/python3.7/site-packages/tornado/gen.py", line 735, in run
    value = future.result()
  File "/scratch/cnt0024/hmg2840/albert7a/anaconda3/lib/python3.7/site-packages/tornado/gen.py", line 742, in run
    yielded = self.gen.throw(*exc_info)  # type: ignore
  File "/scratch/cnt0024/hmg2840/albert7a/anaconda3/lib/python3.7/site-packages/distributed/core.py", line 736, in send_recv_from_rpc
    comm = yield self.pool.connect(self.addr)
  File "/scratch/cnt0024/hmg2840/albert7a/anaconda3/lib/python3.7/site-packages/tornado/gen.py", line 735, in run
    value = future.result()
  File "/scratch/cnt0024/hmg2840/albert7a/anaconda3/lib/python3.7/site-packages/tornado/gen.py", line 742, in run
    yielded = self.gen.throw(*exc_info)  # type: ignore
  File "/scratch/cnt0024/hmg2840/albert7a/anaconda3/lib/python3.7/site-packages/distributed/core.py", line 864, in connect
    connection_args=self.connection_args,
  File "/scratch/cnt0024/hmg2840/albert7a/anaconda3/lib/python3.7/site-packages/tornado/gen.py", line 735, in run
    value = future.result()
  File "/scratch/cnt0024/hmg2840/albert7a/anaconda3/lib/python3.7/site-packages/tornado/gen.py", line 742, in run
    yielded = self.gen.throw(*exc_info)  # type: ignore
  File "/scratch/cnt0024/hmg2840/albert7a/anaconda3/lib/python3.7/site-packages/distributed/comm/core.py", line 230, in connect
    _raise(error)
  File "/scratch/cnt0024/hmg2840/albert7a/anaconda3/lib/python3.7/site-packages/distributed/comm/core.py", line 207, in _raise
    raise IOError(msg)
OSError: Timed out trying to connect to 'tcp://172.30.100.3:40056' after 10 s: connect() didn't finish in time
distributed.utils - ERROR - Timed out trying to connect to 'tcp://172.30.100.3:40056' after 10 s: connect() didn't finish in time
Traceback (most recent call last):
  File "/scratch/cnt0024/hmg2840/albert7a/anaconda3/lib/python3.7/site-packages/distributed/comm/core.py", line 218, in connect
    quiet_exceptions=EnvironmentError,
  File "/scratch/cnt0024/hmg2840/albert7a/anaconda3/lib/python3.7/site-packages/tornado/gen.py", line 735, in run
    value = future.result()
tornado.util.TimeoutError: Timeout

During handling of the above exception, another exception occurred:

Traceback (most recent call last):
  File "/scratch/cnt0024/hmg2840/albert7a/anaconda3/lib/python3.7/site-packages/distributed/utils.py", line 713, in log_errors
    yield
  File "/scratch/cnt0024/hmg2840/albert7a/anaconda3/lib/python3.7/site-packages/distributed/worker.py", line 1994, in query_who_has
    response = yield self.scheduler.who_has(keys=deps)
  File "/scratch/cnt0024/hmg2840/albert7a/anaconda3/lib/python3.7/site-packages/tornado/gen.py", line 735, in run
    value = future.result()
  File "/scratch/cnt0024/hmg2840/albert7a/anaconda3/lib/python3.7/site-packages/tornado/gen.py", line 742, in run
    yielded = self.gen.throw(*exc_info)  # type: ignore
  File "/scratch/cnt0024/hmg2840/albert7a/anaconda3/lib/python3.7/site-packages/distributed/core.py", line 736, in send_recv_from_rpc
    comm = yield self.pool.connect(self.addr)
  File "/scratch/cnt0024/hmg2840/albert7a/anaconda3/lib/python3.7/site-packages/tornado/gen.py", line 735, in run
    value = future.result()
  File "/scratch/cnt0024/hmg2840/albert7a/anaconda3/lib/python3.7/site-packages/tornado/gen.py", line 742, in run
    yielded = self.gen.throw(*exc_info)  # type: ignore
  File "/scratch/cnt0024/hmg2840/albert7a/anaconda3/lib/python3.7/site-packages/distributed/core.py", line 864, in connect
    connection_args=self.connection_args,
  File "/scratch/cnt0024/hmg2840/albert7a/anaconda3/lib/python3.7/site-packages/tornado/gen.py", line 735, in run
    value = future.result()
  File "/scratch/cnt0024/hmg2840/albert7a/anaconda3/lib/python3.7/site-packages/tornado/gen.py", line 742, in run
    yielded = self.gen.throw(*exc_info)  # type: ignore
  File "/scratch/cnt0024/hmg2840/albert7a/anaconda3/lib/python3.7/site-packages/distributed/comm/core.py", line 230, in connect
    _raise(error)
  File "/scratch/cnt0024/hmg2840/albert7a/anaconda3/lib/python3.7/site-packages/distributed/comm/core.py", line 207, in _raise
    raise IOError(msg)
OSError: Timed out trying to connect to 'tcp://172.30.100.3:40056' after 10 s: connect() didn't finish in time
distributed.utils - ERROR - Timed out trying to connect to 'tcp://172.30.100.3:40056' after 10 s: connect() didn't finish in time
Traceback (most recent call last):
  File "/scratch/cnt0024/hmg2840/albert7a/anaconda3/lib/python3.7/site-packages/distributed/comm/core.py", line 218, in connect
    quiet_exceptions=EnvironmentError,
  File "/scratch/cnt0024/hmg2840/albert7a/anaconda3/lib/python3.7/site-packages/tornado/gen.py", line 735, in run
    value = future.result()
tornado.util.TimeoutError: Timeout

During handling of the above exception, another exception occurred:

Traceback (most recent call last):
  File "/scratch/cnt0024/hmg2840/albert7a/anaconda3/lib/python3.7/site-packages/distributed/utils.py", line 713, in log_errors
    yield
  File "/scratch/cnt0024/hmg2840/albert7a/anaconda3/lib/python3.7/site-packages/distributed/worker.py", line 1923, in gather_dep
    yield self.query_who_has(dep)
  File "/scratch/cnt0024/hmg2840/albert7a/anaconda3/lib/python3.7/site-packages/tornado/gen.py", line 735, in run
    value = future.result()
  File "/scratch/cnt0024/hmg2840/albert7a/anaconda3/lib/python3.7/site-packages/tornado/gen.py", line 742, in run
    yielded = self.gen.throw(*exc_info)  # type: ignore
  File "/scratch/cnt0024/hmg2840/albert7a/anaconda3/lib/python3.7/site-packages/distributed/worker.py", line 1994, in query_who_has
    response = yield self.scheduler.who_has(keys=deps)
  File "/scratch/cnt0024/hmg2840/albert7a/anaconda3/lib/python3.7/site-packages/tornado/gen.py", line 735, in run
    value = future.result()
  File "/scratch/cnt0024/hmg2840/albert7a/anaconda3/lib/python3.7/site-packages/tornado/gen.py", line 742, in run
    yielded = self.gen.throw(*exc_info)  # type: ignore
  File "/scratch/cnt0024/hmg2840/albert7a/anaconda3/lib/python3.7/site-packages/distributed/core.py", line 736, in send_recv_from_rpc
    comm = yield self.pool.connect(self.addr)
  File "/scratch/cnt0024/hmg2840/albert7a/anaconda3/lib/python3.7/site-packages/tornado/gen.py", line 735, in run
    value = future.result()
  File "/scratch/cnt0024/hmg2840/albert7a/anaconda3/lib/python3.7/site-packages/tornado/gen.py", line 742, in run
    yielded = self.gen.throw(*exc_info)  # type: ignore
  File "/scratch/cnt0024/hmg2840/albert7a/anaconda3/lib/python3.7/site-packages/distributed/core.py", line 864, in connect
    connection_args=self.connection_args,
  File "/scratch/cnt0024/hmg2840/albert7a/anaconda3/lib/python3.7/site-packages/tornado/gen.py", line 735, in run
    value = future.result()
  File "/scratch/cnt0024/hmg2840/albert7a/anaconda3/lib/python3.7/site-packages/tornado/gen.py", line 742, in run
    yielded = self.gen.throw(*exc_info)  # type: ignore
  File "/scratch/cnt0024/hmg2840/albert7a/anaconda3/lib/python3.7/site-packages/distributed/comm/core.py", line 230, in connect
    _raise(error)
  File "/scratch/cnt0024/hmg2840/albert7a/anaconda3/lib/python3.7/site-packages/distributed/comm/core.py", line 207, in _raise
    raise IOError(msg)
OSError: Timed out trying to connect to 'tcp://172.30.100.3:40056' after 10 s: connect() didn't finish in time
tornado.application - ERROR - Exception in callback functools.partial(<bound method IOLoop._discard_future_result of <tornado.platform.asyncio.AsyncIOLoop object at 0x2ae469514160>>, <Future finished exception=OSError("Timed out trying to connect to 'tcp://172.30.100.3:40056' after 10 s: connect() didn't finish in time")>)
Traceback (most recent call last):
  File "/scratch/cnt0024/hmg2840/albert7a/anaconda3/lib/python3.7/site-packages/distributed/comm/core.py", line 218, in connect
    quiet_exceptions=EnvironmentError,
  File "/scratch/cnt0024/hmg2840/albert7a/anaconda3/lib/python3.7/site-packages/tornado/gen.py", line 735, in run
    value = future.result()
tornado.util.TimeoutError: Timeout

During handling of the above exception, another exception occurred:

Traceback (most recent call last):
  File "/scratch/cnt0024/hmg2840/albert7a/anaconda3/lib/python3.7/site-packages/tornado/ioloop.py", line 743, in _run_callback
    ret = callback()
  File "/scratch/cnt0024/hmg2840/albert7a/anaconda3/lib/python3.7/site-packages/tornado/ioloop.py", line 767, in _discard_future_result
    future.result()
  File "/scratch/cnt0024/hmg2840/albert7a/anaconda3/lib/python3.7/site-packages/tornado/gen.py", line 742, in run
    yielded = self.gen.throw(*exc_info)  # type: ignore
  File "/scratch/cnt0024/hmg2840/albert7a/anaconda3/lib/python3.7/site-packages/distributed/worker.py", line 1923, in gather_dep
    yield self.query_who_has(dep)
  File "/scratch/cnt0024/hmg2840/albert7a/anaconda3/lib/python3.7/site-packages/tornado/gen.py", line 735, in run
    value = future.result()
  File "/scratch/cnt0024/hmg2840/albert7a/anaconda3/lib/python3.7/site-packages/tornado/gen.py", line 742, in run
    yielded = self.gen.throw(*exc_info)  # type: ignore
  File "/scratch/cnt0024/hmg2840/albert7a/anaconda3/lib/python3.7/site-packages/distributed/worker.py", line 1994, in query_who_has
    response = yield self.scheduler.who_has(keys=deps)
  File "/scratch/cnt0024/hmg2840/albert7a/anaconda3/lib/python3.7/site-packages/tornado/gen.py", line 735, in run
    value = future.result()
  File "/scratch/cnt0024/hmg2840/albert7a/anaconda3/lib/python3.7/site-packages/tornado/gen.py", line 742, in run
    yielded = self.gen.throw(*exc_info)  # type: ignore
  File "/scratch/cnt0024/hmg2840/albert7a/anaconda3/lib/python3.7/site-packages/distributed/core.py", line 736, in send_recv_from_rpc
    comm = yield self.pool.connect(self.addr)
  File "/scratch/cnt0024/hmg2840/albert7a/anaconda3/lib/python3.7/site-packages/tornado/gen.py", line 735, in run
    value = future.result()
  File "/scratch/cnt0024/hmg2840/albert7a/anaconda3/lib/python3.7/site-packages/tornado/gen.py", line 742, in run
    yielded = self.gen.throw(*exc_info)  # type: ignore
  File "/scratch/cnt0024/hmg2840/albert7a/anaconda3/lib/python3.7/site-packages/distributed/core.py", line 864, in connect
    connection_args=self.connection_args,
  File "/scratch/cnt0024/hmg2840/albert7a/anaconda3/lib/python3.7/site-packages/tornado/gen.py", line 735, in run
    value = future.result()
  File "/scratch/cnt0024/hmg2840/albert7a/anaconda3/lib/python3.7/site-packages/tornado/gen.py", line 742, in run
    yielded = self.gen.throw(*exc_info)  # type: ignore
  File "/scratch/cnt0024/hmg2840/albert7a/anaconda3/lib/python3.7/site-packages/distributed/comm/core.py", line 230, in connect
    _raise(error)
  File "/scratch/cnt0024/hmg2840/albert7a/anaconda3/lib/python3.7/site-packages/distributed/comm/core.py", line 207, in _raise
    raise IOError(msg)
OSError: Timed out trying to connect to 'tcp://172.30.100.3:40056' after 10 s: connect() didn't finish in time
distributed.utils - ERROR - Timed out trying to connect to 'tcp://172.30.100.3:40056' after 10 s: connect() didn't finish in time
Traceback (most recent call last):
  File "/scratch/cnt0024/hmg2840/albert7a/anaconda3/lib/python3.7/site-packages/distributed/comm/core.py", line 218, in connect
    quiet_exceptions=EnvironmentError,
  File "/scratch/cnt0024/hmg2840/albert7a/anaconda3/lib/python3.7/site-packages/tornado/gen.py", line 735, in run
    value = future.result()
tornado.util.TimeoutError: Timeout

During handling of the above exception, another exception occurred:

Traceback (most recent call last):
  File "/scratch/cnt0024/hmg2840/albert7a/anaconda3/lib/python3.7/site-packages/distributed/utils.py", line 713, in log_errors
    yield
  File "/scratch/cnt0024/hmg2840/albert7a/anaconda3/lib/python3.7/site-packages/distributed/worker.py", line 1994, in query_who_has
    response = yield self.scheduler.who_has(keys=deps)
  File "/scratch/cnt0024/hmg2840/albert7a/anaconda3/lib/python3.7/site-packages/tornado/gen.py", line 735, in run
    value = future.result()
  File "/scratch/cnt0024/hmg2840/albert7a/anaconda3/lib/python3.7/site-packages/tornado/gen.py", line 742, in run
    yielded = self.gen.throw(*exc_info)  # type: ignore
  File "/scratch/cnt0024/hmg2840/albert7a/anaconda3/lib/python3.7/site-packages/distributed/core.py", line 736, in send_recv_from_rpc
    comm = yield self.pool.connect(self.addr)
  File "/scratch/cnt0024/hmg2840/albert7a/anaconda3/lib/python3.7/site-packages/tornado/gen.py", line 735, in run
    value = future.result()
  File "/scratch/cnt0024/hmg2840/albert7a/anaconda3/lib/python3.7/site-packages/tornado/gen.py", line 742, in run
    yielded = self.gen.throw(*exc_info)  # type: ignore
  File "/scratch/cnt0024/hmg2840/albert7a/anaconda3/lib/python3.7/site-packages/distributed/core.py", line 864, in connect
    connection_args=self.connection_args,
  File "/scratch/cnt0024/hmg2840/albert7a/anaconda3/lib/python3.7/site-packages/tornado/gen.py", line 735, in run
    value = future.result()
  File "/scratch/cnt0024/hmg2840/albert7a/anaconda3/lib/python3.7/site-packages/tornado/gen.py", line 742, in run
    yielded = self.gen.throw(*exc_info)  # type: ignore
  File "/scratch/cnt0024/hmg2840/albert7a/anaconda3/lib/python3.7/site-packages/distributed/comm/core.py", line 230, in connect
    _raise(error)
  File "/scratch/cnt0024/hmg2840/albert7a/anaconda3/lib/python3.7/site-packages/distributed/comm/core.py", line 207, in _raise
    raise IOError(msg)
OSError: Timed out trying to connect to 'tcp://172.30.100.3:40056' after 10 s: connect() didn't finish in time
distributed.utils - ERROR - Timed out trying to connect to 'tcp://172.30.100.3:40056' after 10 s: connect() didn't finish in time
Traceback (most recent call last):
  File "/scratch/cnt0024/hmg2840/albert7a/anaconda3/lib/python3.7/site-packages/distributed/comm/core.py", line 218, in connect
    quiet_exceptions=EnvironmentError,
  File "/scratch/cnt0024/hmg2840/albert7a/anaconda3/lib/python3.7/site-packages/tornado/gen.py", line 735, in run
    value = future.result()
tornado.util.TimeoutError: Timeout

During handling of the above exception, another exception occurred:

Traceback (most recent call last):
  File "/scratch/cnt0024/hmg2840/albert7a/anaconda3/lib/python3.7/site-packages/distributed/utils.py", line 713, in log_errors
    yield
  File "/scratch/cnt0024/hmg2840/albert7a/anaconda3/lib/python3.7/site-packages/distributed/worker.py", line 1923, in gather_dep
    yield self.query_who_has(dep)
  File "/scratch/cnt0024/hmg2840/albert7a/anaconda3/lib/python3.7/site-packages/tornado/gen.py", line 735, in run
    value = future.result()
  File "/scratch/cnt0024/hmg2840/albert7a/anaconda3/lib/python3.7/site-packages/tornado/gen.py", line 742, in run
    yielded = self.gen.throw(*exc_info)  # type: ignore
  File "/scratch/cnt0024/hmg2840/albert7a/anaconda3/lib/python3.7/site-packages/distributed/worker.py", line 1994, in query_who_has
    response = yield self.scheduler.who_has(keys=deps)
  File "/scratch/cnt0024/hmg2840/albert7a/anaconda3/lib/python3.7/site-packages/tornado/gen.py", line 735, in run
    value = future.result()
  File "/scratch/cnt0024/hmg2840/albert7a/anaconda3/lib/python3.7/site-packages/tornado/gen.py", line 742, in run
    yielded = self.gen.throw(*exc_info)  # type: ignore
  File "/scratch/cnt0024/hmg2840/albert7a/anaconda3/lib/python3.7/site-packages/distributed/core.py", line 736, in send_recv_from_rpc
    comm = yield self.pool.connect(self.addr)
  File "/scratch/cnt0024/hmg2840/albert7a/anaconda3/lib/python3.7/site-packages/tornado/gen.py", line 735, in run
    value = future.result()
  File "/scratch/cnt0024/hmg2840/albert7a/anaconda3/lib/python3.7/site-packages/tornado/gen.py", line 742, in run
    yielded = self.gen.throw(*exc_info)  # type: ignore
  File "/scratch/cnt0024/hmg2840/albert7a/anaconda3/lib/python3.7/site-packages/distributed/core.py", line 864, in connect
    connection_args=self.connection_args,
  File "/scratch/cnt0024/hmg2840/albert7a/anaconda3/lib/python3.7/site-packages/tornado/gen.py", line 735, in run
    value = future.result()
  File "/scratch/cnt0024/hmg2840/albert7a/anaconda3/lib/python3.7/site-packages/tornado/gen.py", line 742, in run
    yielded = self.gen.throw(*exc_info)  # type: ignore
  File "/scratch/cnt0024/hmg2840/albert7a/anaconda3/lib/python3.7/site-packages/distributed/comm/core.py", line 230, in connect
    _raise(error)
  File "/scratch/cnt0024/hmg2840/albert7a/anaconda3/lib/python3.7/site-packages/distributed/comm/core.py", line 207, in _raise
    raise IOError(msg)
OSError: Timed out trying to connect to 'tcp://172.30.100.3:40056' after 10 s: connect() didn't finish in time
tornado.application - ERROR - Exception in callback functools.partial(<bound method IOLoop._discard_future_result of <tornado.platform.asyncio.AsyncIOLoop object at 0x2ae469514160>>, <Future finished exception=OSError("Timed out trying to connect to 'tcp://172.30.100.3:40056' after 10 s: connect() didn't finish in time")>)
Traceback (most recent call last):
  File "/scratch/cnt0024/hmg2840/albert7a/anaconda3/lib/python3.7/site-packages/distributed/comm/core.py", line 218, in connect
    quiet_exceptions=EnvironmentError,
  File "/scratch/cnt0024/hmg2840/albert7a/anaconda3/lib/python3.7/site-packages/tornado/gen.py", line 735, in run
    value = future.result()
tornado.util.TimeoutError: Timeout

During handling of the above exception, another exception occurred:

Traceback (most recent call last):
  File "/scratch/cnt0024/hmg2840/albert7a/anaconda3/lib/python3.7/site-packages/tornado/ioloop.py", line 743, in _run_callback
    ret = callback()
  File "/scratch/cnt0024/hmg2840/albert7a/anaconda3/lib/python3.7/site-packages/tornado/ioloop.py", line 767, in _discard_future_result
    future.result()
  File "/scratch/cnt0024/hmg2840/albert7a/anaconda3/lib/python3.7/site-packages/tornado/gen.py", line 742, in run
    yielded = self.gen.throw(*exc_info)  # type: ignore
  File "/scratch/cnt0024/hmg2840/albert7a/anaconda3/lib/python3.7/site-packages/distributed/worker.py", line 1923, in gather_dep
    yield self.query_who_has(dep)
  File "/scratch/cnt0024/hmg2840/albert7a/anaconda3/lib/python3.7/site-packages/tornado/gen.py", line 735, in run
    value = future.result()
  File "/scratch/cnt0024/hmg2840/albert7a/anaconda3/lib/python3.7/site-packages/tornado/gen.py", line 742, in run
    yielded = self.gen.throw(*exc_info)  # type: ignore
  File "/scratch/cnt0024/hmg2840/albert7a/anaconda3/lib/python3.7/site-packages/distributed/worker.py", line 1994, in query_who_has
    response = yield self.scheduler.who_has(keys=deps)
  File "/scratch/cnt0024/hmg2840/albert7a/anaconda3/lib/python3.7/site-packages/tornado/gen.py", line 735, in run
    value = future.result()
  File "/scratch/cnt0024/hmg2840/albert7a/anaconda3/lib/python3.7/site-packages/tornado/gen.py", line 742, in run
    yielded = self.gen.throw(*exc_info)  # type: ignore
  File "/scratch/cnt0024/hmg2840/albert7a/anaconda3/lib/python3.7/site-packages/distributed/core.py", line 736, in send_recv_from_rpc
    comm = yield self.pool.connect(self.addr)
  File "/scratch/cnt0024/hmg2840/albert7a/anaconda3/lib/python3.7/site-packages/tornado/gen.py", line 735, in run
    value = future.result()
  File "/scratch/cnt0024/hmg2840/albert7a/anaconda3/lib/python3.7/site-packages/tornado/gen.py", line 742, in run
    yielded = self.gen.throw(*exc_info)  # type: ignore
  File "/scratch/cnt0024/hmg2840/albert7a/anaconda3/lib/python3.7/site-packages/distributed/core.py", line 864, in connect
    connection_args=self.connection_args,
  File "/scratch/cnt0024/hmg2840/albert7a/anaconda3/lib/python3.7/site-packages/tornado/gen.py", line 735, in run
    value = future.result()
  File "/scratch/cnt0024/hmg2840/albert7a/anaconda3/lib/python3.7/site-packages/tornado/gen.py", line 742, in run
    yielded = self.gen.throw(*exc_info)  # type: ignore
  File "/scratch/cnt0024/hmg2840/albert7a/anaconda3/lib/python3.7/site-packages/distributed/comm/core.py", line 230, in connect
    _raise(error)
  File "/scratch/cnt0024/hmg2840/albert7a/anaconda3/lib/python3.7/site-packages/distributed/comm/core.py", line 207, in _raise
    raise IOError(msg)
OSError: Timed out trying to connect to 'tcp://172.30.100.3:40056' after 10 s: connect() didn't finish in time
distributed.utils - ERROR - Timed out trying to connect to 'tcp://172.30.100.3:40056' after 10 s: connect() didn't finish in time
Traceback (most recent call last):
  File "/scratch/cnt0024/hmg2840/albert7a/anaconda3/lib/python3.7/site-packages/distributed/comm/core.py", line 218, in connect
    quiet_exceptions=EnvironmentError,
  File "/scratch/cnt0024/hmg2840/albert7a/anaconda3/lib/python3.7/site-packages/tornado/gen.py", line 735, in run
    value = future.result()
tornado.util.TimeoutError: Timeout

During handling of the above exception, another exception occurred:

Traceback (most recent call last):
  File "/scratch/cnt0024/hmg2840/albert7a/anaconda3/lib/python3.7/site-packages/distributed/utils.py", line 713, in log_errors
    yield
  File "/scratch/cnt0024/hmg2840/albert7a/anaconda3/lib/python3.7/site-packages/distributed/worker.py", line 1994, in query_who_has
    response = yield self.scheduler.who_has(keys=deps)
  File "/scratch/cnt0024/hmg2840/albert7a/anaconda3/lib/python3.7/site-packages/tornado/gen.py", line 735, in run
    value = future.result()
  File "/scratch/cnt0024/hmg2840/albert7a/anaconda3/lib/python3.7/site-packages/tornado/gen.py", line 742, in run
    yielded = self.gen.throw(*exc_info)  # type: ignore
  File "/scratch/cnt0024/hmg2840/albert7a/anaconda3/lib/python3.7/site-packages/distributed/core.py", line 736, in send_recv_from_rpc
    comm = yield self.pool.connect(self.addr)
  File "/scratch/cnt0024/hmg2840/albert7a/anaconda3/lib/python3.7/site-packages/tornado/gen.py", line 735, in run
    value = future.result()
  File "/scratch/cnt0024/hmg2840/albert7a/anaconda3/lib/python3.7/site-packages/tornado/gen.py", line 742, in run
    yielded = self.gen.throw(*exc_info)  # type: ignore
  File "/scratch/cnt0024/hmg2840/albert7a/anaconda3/lib/python3.7/site-packages/distributed/core.py", line 864, in connect
    connection_args=self.connection_args,
  File "/scratch/cnt0024/hmg2840/albert7a/anaconda3/lib/python3.7/site-packages/tornado/gen.py", line 735, in run
    value = future.result()
  File "/scratch/cnt0024/hmg2840/albert7a/anaconda3/lib/python3.7/site-packages/tornado/gen.py", line 742, in run
    yielded = self.gen.throw(*exc_info)  # type: ignore
  File "/scratch/cnt0024/hmg2840/albert7a/anaconda3/lib/python3.7/site-packages/distributed/comm/core.py", line 230, in connect
    _raise(error)
  File "/scratch/cnt0024/hmg2840/albert7a/anaconda3/lib/python3.7/site-packages/distributed/comm/core.py", line 207, in _raise
    raise IOError(msg)
OSError: Timed out trying to connect to 'tcp://172.30.100.3:40056' after 10 s: connect() didn't finish in time
distributed.utils - ERROR - Timed out trying to connect to 'tcp://172.30.100.3:40056' after 10 s: connect() didn't finish in time
Traceback (most recent call last):
  File "/scratch/cnt0024/hmg2840/albert7a/anaconda3/lib/python3.7/site-packages/distributed/comm/core.py", line 218, in connect
    quiet_exceptions=EnvironmentError,
  File "/scratch/cnt0024/hmg2840/albert7a/anaconda3/lib/python3.7/site-packages/tornado/gen.py", line 735, in run
    value = future.result()
tornado.util.TimeoutError: Timeout

During handling of the above exception, another exception occurred:

Traceback (most recent call last):
  File "/scratch/cnt0024/hmg2840/albert7a/anaconda3/lib/python3.7/site-packages/distributed/utils.py", line 713, in log_errors
    yield
  File "/scratch/cnt0024/hmg2840/albert7a/anaconda3/lib/python3.7/site-packages/distributed/worker.py", line 1923, in gather_dep
    yield self.query_who_has(dep)
  File "/scratch/cnt0024/hmg2840/albert7a/anaconda3/lib/python3.7/site-packages/tornado/gen.py", line 735, in run
    value = future.result()
  File "/scratch/cnt0024/hmg2840/albert7a/anaconda3/lib/python3.7/site-packages/tornado/gen.py", line 742, in run
    yielded = self.gen.throw(*exc_info)  # type: ignore
  File "/scratch/cnt0024/hmg2840/albert7a/anaconda3/lib/python3.7/site-packages/distributed/worker.py", line 1994, in query_who_has
    response = yield self.scheduler.who_has(keys=deps)
  File "/scratch/cnt0024/hmg2840/albert7a/anaconda3/lib/python3.7/site-packages/tornado/gen.py", line 735, in run
    value = future.result()
  File "/scratch/cnt0024/hmg2840/albert7a/anaconda3/lib/python3.7/site-packages/tornado/gen.py", line 742, in run
    yielded = self.gen.throw(*exc_info)  # type: ignore
  File "/scratch/cnt0024/hmg2840/albert7a/anaconda3/lib/python3.7/site-packages/distributed/core.py", line 736, in send_recv_from_rpc
    comm = yield self.pool.connect(self.addr)
  File "/scratch/cnt0024/hmg2840/albert7a/anaconda3/lib/python3.7/site-packages/tornado/gen.py", line 735, in run
    value = future.result()
  File "/scratch/cnt0024/hmg2840/albert7a/anaconda3/lib/python3.7/site-packages/tornado/gen.py", line 742, in run
    yielded = self.gen.throw(*exc_info)  # type: ignore
  File "/scratch/cnt0024/hmg2840/albert7a/anaconda3/lib/python3.7/site-packages/distributed/core.py", line 864, in connect
    connection_args=self.connection_args,
  File "/scratch/cnt0024/hmg2840/albert7a/anaconda3/lib/python3.7/site-packages/tornado/gen.py", line 735, in run
    value = future.result()
  File "/scratch/cnt0024/hmg2840/albert7a/anaconda3/lib/python3.7/site-packages/tornado/gen.py", line 742, in run
    yielded = self.gen.throw(*exc_info)  # type: ignore
  File "/scratch/cnt0024/hmg2840/albert7a/anaconda3/lib/python3.7/site-packages/distributed/comm/core.py", line 230, in connect
    _raise(error)
  File "/scratch/cnt0024/hmg2840/albert7a/anaconda3/lib/python3.7/site-packages/distributed/comm/core.py", line 207, in _raise
    raise IOError(msg)
OSError: Timed out trying to connect to 'tcp://172.30.100.3:40056' after 10 s: connect() didn't finish in time
tornado.application - ERROR - Exception in callback functools.partial(<bound method IOLoop._discard_future_result of <tornado.platform.asyncio.AsyncIOLoop object at 0x2ae469514160>>, <Future finished exception=OSError("Timed out trying to connect to 'tcp://172.30.100.3:40056' after 10 s: connect() didn't finish in time")>)
Traceback (most recent call last):
  File "/scratch/cnt0024/hmg2840/albert7a/anaconda3/lib/python3.7/site-packages/distributed/comm/core.py", line 218, in connect
    quiet_exceptions=EnvironmentError,
  File "/scratch/cnt0024/hmg2840/albert7a/anaconda3/lib/python3.7/site-packages/tornado/gen.py", line 735, in run
    value = future.result()
tornado.util.TimeoutError: Timeout

During handling of the above exception, another exception occurred:

Traceback (most recent call last):
  File "/scratch/cnt0024/hmg2840/albert7a/anaconda3/lib/python3.7/site-packages/tornado/ioloop.py", line 743, in _run_callback
    ret = callback()
  File "/scratch/cnt0024/hmg2840/albert7a/anaconda3/lib/python3.7/site-packages/tornado/ioloop.py", line 767, in _discard_future_result
    future.result()
  File "/scratch/cnt0024/hmg2840/albert7a/anaconda3/lib/python3.7/site-packages/tornado/gen.py", line 742, in run
    yielded = self.gen.throw(*exc_info)  # type: ignore
  File "/scratch/cnt0024/hmg2840/albert7a/anaconda3/lib/python3.7/site-packages/distributed/worker.py", line 1923, in gather_dep
    yield self.query_who_has(dep)
  File "/scratch/cnt0024/hmg2840/albert7a/anaconda3/lib/python3.7/site-packages/tornado/gen.py", line 735, in run
    value = future.result()
  File "/scratch/cnt0024/hmg2840/albert7a/anaconda3/lib/python3.7/site-packages/tornado/gen.py", line 742, in run
    yielded = self.gen.throw(*exc_info)  # type: ignore
  File "/scratch/cnt0024/hmg2840/albert7a/anaconda3/lib/python3.7/site-packages/distributed/worker.py", line 1994, in query_who_has
    response = yield self.scheduler.who_has(keys=deps)
  File "/scratch/cnt0024/hmg2840/albert7a/anaconda3/lib/python3.7/site-packages/tornado/gen.py", line 735, in run
    value = future.result()
  File "/scratch/cnt0024/hmg2840/albert7a/anaconda3/lib/python3.7/site-packages/tornado/gen.py", line 742, in run
    yielded = self.gen.throw(*exc_info)  # type: ignore
  File "/scratch/cnt0024/hmg2840/albert7a/anaconda3/lib/python3.7/site-packages/distributed/core.py", line 736, in send_recv_from_rpc
    comm = yield self.pool.connect(self.addr)
  File "/scratch/cnt0024/hmg2840/albert7a/anaconda3/lib/python3.7/site-packages/tornado/gen.py", line 735, in run
    value = future.result()
  File "/scratch/cnt0024/hmg2840/albert7a/anaconda3/lib/python3.7/site-packages/tornado/gen.py", line 742, in run
    yielded = self.gen.throw(*exc_info)  # type: ignore
  File "/scratch/cnt0024/hmg2840/albert7a/anaconda3/lib/python3.7/site-packages/distributed/core.py", line 864, in connect
    connection_args=self.connection_args,
  File "/scratch/cnt0024/hmg2840/albert7a/anaconda3/lib/python3.7/site-packages/tornado/gen.py", line 735, in run
    value = future.result()
  File "/scratch/cnt0024/hmg2840/albert7a/anaconda3/lib/python3.7/site-packages/tornado/gen.py", line 742, in run
    yielded = self.gen.throw(*exc_info)  # type: ignore
  File "/scratch/cnt0024/hmg2840/albert7a/anaconda3/lib/python3.7/site-packages/distributed/comm/core.py", line 230, in connect
    _raise(error)
  File "/scratch/cnt0024/hmg2840/albert7a/anaconda3/lib/python3.7/site-packages/distributed/comm/core.py", line 207, in _raise
    raise IOError(msg)
OSError: Timed out trying to connect to 'tcp://172.30.100.3:40056' after 10 s: connect() didn't finish in time
distributed.comm.tcp - WARNING - Closing dangling stream in <TCP  local=tcp://172.30.6.48:38628 remote=tcp://172.30.100.3:40056>
distributed.comm.tcp - WARNING - Closing dangling stream in <TCP  local=tcp://172.30.6.48:38634 remote=tcp://172.30.100.3:40056>
/scratch/cnt0024/hmg2840/albert7a/anaconda3/lib/python3.7/site-packages/dask/array/numpy_compat.py:28: RuntimeWarning: invalid value encountered in true_divide
  x = np.divide(x1, x2, out)
distributed.utils_perf - INFO - full garbage collection released 191.82 MB from 1583 reference cycles (threshold: 10.00 MB)
/scratch/cnt0024/hmg2840/albert7a/anaconda3/lib/python3.7/site-packages/dask/array/numpy_compat.py:28: RuntimeWarning: invalid value encountered in true_divide
  x = np.divide(x1, x2, out)
distributed.comm.tcp - WARNING - Closing dangling stream in <TCP  local=tcp://172.30.6.48:38564 remote=tcp://172.30.100.3:40056>
distributed.comm.tcp - WARNING - Closing dangling stream in <TCP  local=tcp://172.30.6.48:38574 remote=tcp://172.30.100.3:40056>
distributed.comm.tcp - WARNING - Closing dangling stream in <TCP  local=tcp://172.30.6.48:38584 remote=tcp://172.30.100.3:40056>
distributed.comm.tcp - WARNING - Closing dangling stream in <TCP  local=tcp://172.30.6.48:38606 remote=tcp://172.30.100.3:40056>
distributed.comm.tcp - WARNING - Closing dangling stream in <TCP  local=tcp://172.30.6.48:38608 remote=tcp://172.30.100.3:40056>
/scratch/cnt0024/hmg2840/albert7a/anaconda3/lib/python3.7/site-packages/dask/array/numpy_compat.py:28: RuntimeWarning: invalid value encountered in true_divide
  x = np.divide(x1, x2, out)
distributed.worker - INFO - Connection to scheduler broken.  Reconnecting...
/scratch/cnt0024/hmg2840/albert7a/anaconda3/lib/python3.7/site-packages/dask/array/numpy_compat.py:28: RuntimeWarning: invalid value encountered in true_divide
  x = np.divide(x1, x2, out)
distributed.worker - INFO - Connection to scheduler broken.  Reconnecting...
/scratch/cnt0024/hmg2840/albert7a/anaconda3/lib/python3.7/site-packages/dask/array/numpy_compat.py:28: RuntimeWarning: invalid value encountered in true_divide
  x = np.divide(x1, x2, out)
distributed.worker - INFO - Connection to scheduler broken.  Reconnecting...
distributed.worker - INFO - -------------------------------------------------
/scratch/cnt0024/hmg2840/albert7a/anaconda3/lib/python3.7/site-packages/dask/array/numpy_compat.py:28: RuntimeWarning: invalid value encountered in true_divide
  x = np.divide(x1, x2, out)
distributed.worker - INFO - Connection to scheduler broken.  Reconnecting...
/scratch/cnt0024/hmg2840/albert7a/anaconda3/lib/python3.7/site-packages/dask/array/numpy_compat.py:28: RuntimeWarning: invalid value encountered in true_divide
  x = np.divide(x1, x2, out)
distributed.worker - INFO - Connection to scheduler broken.  Reconnecting...
/scratch/cnt0024/hmg2840/albert7a/anaconda3/lib/python3.7/site-packages/dask/array/numpy_compat.py:28: RuntimeWarning: invalid value encountered in true_divide
  x = np.divide(x1, x2, out)
distributed.worker - INFO - Connection to scheduler broken.  Reconnecting...
/scratch/cnt0024/hmg2840/albert7a/anaconda3/lib/python3.7/site-packages/dask/array/numpy_compat.py:28: RuntimeWarning: invalid value encountered in true_divide
  x = np.divide(x1, x2, out)
distributed.worker - INFO - Connection to scheduler broken.  Reconnecting...
/scratch/cnt0024/hmg2840/albert7a/anaconda3/lib/python3.7/site-packages/dask/array/numpy_compat.py:28: RuntimeWarning: invalid value encountered in true_divide
  x = np.divide(x1, x2, out)
distributed.worker - INFO - Connection to scheduler broken.  Reconnecting...
distributed.worker - INFO - -------------------------------------------------
distributed.worker - INFO - Connection to scheduler broken.  Reconnecting...
distributed.worker - INFO - -------------------------------------------------
/scratch/cnt0024/hmg2840/albert7a/anaconda3/lib/python3.7/site-packages/dask/array/numpy_compat.py:28: RuntimeWarning: invalid value encountered in true_divide
  x = np.divide(x1, x2, out)
distributed.worker - INFO - Connection to scheduler broken.  Reconnecting...
/scratch/cnt0024/hmg2840/albert7a/anaconda3/lib/python3.7/site-packages/dask/array/numpy_compat.py:28: RuntimeWarning: invalid value encountered in true_divide
  x = np.divide(x1, x2, out)
distributed.worker - INFO - Connection to scheduler broken.  Reconnecting...
/scratch/cnt0024/hmg2840/albert7a/anaconda3/lib/python3.7/site-packages/dask/array/numpy_compat.py:28: RuntimeWarning: invalid value encountered in true_divide
  x = np.divide(x1, x2, out)
distributed.worker - INFO - Connection to scheduler broken.  Reconnecting...
/scratch/cnt0024/hmg2840/albert7a/anaconda3/lib/python3.7/site-packages/dask/array/numpy_compat.py:28: RuntimeWarning: invalid value encountered in true_divide
  x = np.divide(x1, x2, out)
distributed.worker - INFO - Connection to scheduler broken.  Reconnecting...
distributed.worker - INFO - -------------------------------------------------
distributed.worker - INFO - -------------------------------------------------
distributed.worker - INFO - Connection to scheduler broken.  Reconnecting...
distributed.worker - INFO - -------------------------------------------------
/scratch/cnt0024/hmg2840/albert7a/anaconda3/lib/python3.7/site-packages/dask/array/numpy_compat.py:28: RuntimeWarning: invalid value encountered in true_divide
  x = np.divide(x1, x2, out)
distributed.worker - INFO - Connection to scheduler broken.  Reconnecting...
distributed.worker - INFO - -------------------------------------------------
/scratch/cnt0024/hmg2840/albert7a/anaconda3/lib/python3.7/site-packages/dask/array/numpy_compat.py:28: RuntimeWarning: invalid value encountered in true_divide
  x = np.divide(x1, x2, out)
distributed.worker - INFO - Connection to scheduler broken.  Reconnecting...
/scratch/cnt0024/hmg2840/albert7a/anaconda3/lib/python3.7/site-packages/dask/array/numpy_compat.py:28: RuntimeWarning: invalid value encountered in true_divide
  x = np.divide(x1, x2, out)
distributed.worker - INFO - Connection to scheduler broken.  Reconnecting...
/scratch/cnt0024/hmg2840/albert7a/anaconda3/lib/python3.7/site-packages/dask/array/numpy_compat.py:28: RuntimeWarning: invalid value encountered in true_divide
  x = np.divide(x1, x2, out)
distributed.worker - INFO - Connection to scheduler broken.  Reconnecting...
/scratch/cnt0024/hmg2840/albert7a/anaconda3/lib/python3.7/site-packages/dask/array/numpy_compat.py:28: RuntimeWarning: invalid value encountered in true_divide
  x = np.divide(x1, x2, out)
distributed.worker - INFO - Connection to scheduler broken.  Reconnecting...
distributed.worker - INFO - -------------------------------------------------
distributed.worker - INFO - -------------------------------------------------
/scratch/cnt0024/hmg2840/albert7a/anaconda3/lib/python3.7/site-packages/dask/array/numpy_compat.py:28: RuntimeWarning: invalid value encountered in true_divide
  x = np.divide(x1, x2, out)
distributed.worker - INFO - Connection to scheduler broken.  Reconnecting...
distributed.worker - INFO - -------------------------------------------------
distributed.worker - INFO - -------------------------------------------------
distributed.worker - INFO - Connection to scheduler broken.  Reconnecting...
distributed.worker - INFO - -------------------------------------------------
/scratch/cnt0024/hmg2840/albert7a/anaconda3/lib/python3.7/site-packages/dask/array/numpy_compat.py:28: RuntimeWarning: invalid value encountered in true_divide
  x = np.divide(x1, x2, out)
distributed.worker - INFO - Connection to scheduler broken.  Reconnecting...
/scratch/cnt0024/hmg2840/albert7a/anaconda3/lib/python3.7/site-packages/dask/array/numpy_compat.py:28: RuntimeWarning: invalid value encountered in true_divide
  x = np.divide(x1, x2, out)
distributed.worker - INFO - Connection to scheduler broken.  Reconnecting...
distributed.worker - INFO - -------------------------------------------------
distributed.worker - INFO - -------------------------------------------------
distributed.worker - INFO - -------------------------------------------------
distributed.worker - INFO - -------------------------------------------------
distributed.worker - INFO - -------------------------------------------------
/scratch/cnt0024/hmg2840/albert7a/anaconda3/lib/python3.7/site-packages/dask/array/numpy_compat.py:28: RuntimeWarning: invalid value encountered in true_divide
  x = np.divide(x1, x2, out)
distributed.worker - INFO - Connection to scheduler broken.  Reconnecting...
distributed.worker - INFO - -------------------------------------------------
distributed.worker - INFO - -------------------------------------------------
distributed.worker - INFO - -------------------------------------------------
distributed.worker - INFO - -------------------------------------------------
distributed.worker - INFO - -------------------------------------------------
distributed.worker - INFO - Connection to scheduler broken.  Reconnecting...
distributed.worker - INFO - -------------------------------------------------
distributed.worker - INFO - -------------------------------------------------
distributed.worker - INFO - Connection to scheduler broken.  Reconnecting...
distributed.worker - INFO - -------------------------------------------------
/scratch/cnt0024/hmg2840/albert7a/anaconda3/lib/python3.7/site-packages/dask/array/numpy_compat.py:28: RuntimeWarning: invalid value encountered in true_divide
  x = np.divide(x1, x2, out)
distributed.worker - INFO - Connection to scheduler broken.  Reconnecting...
distributed.worker - INFO - -------------------------------------------------
/scratch/cnt0024/hmg2840/albert7a/anaconda3/lib/python3.7/site-packages/dask/array/numpy_compat.py:28: RuntimeWarning: invalid value encountered in true_divide
  x = np.divide(x1, x2, out)
distributed.worker - INFO - Connection to scheduler broken.  Reconnecting...
distributed.worker - INFO - -------------------------------------------------
distributed.worker - INFO - -------------------------------------------------
distributed.worker - INFO - Comm closed
distributed.worker - INFO - Comm closed
distributed.worker - INFO - Comm closed
distributed.worker - INFO - Comm closed
distributed.worker - INFO - Comm closed
distributed.worker - INFO - Comm closed
distributed.worker - INFO - Comm closed
distributed.worker - INFO - Comm closed
distributed.worker - INFO - Comm closed
distributed.worker - INFO - Comm closed
distributed.worker - INFO - Comm closed
distributed.worker - INFO - Comm closed
distributed.worker - INFO - Comm closed
distributed.worker - INFO - Comm closed
distributed.worker - INFO - Comm closed
distributed.worker - INFO - Comm closed
distributed.worker - INFO - Comm closed
distributed.worker - INFO - Comm closed
distributed.worker - INFO - Comm closed
distributed.worker - INFO - Comm closed
distributed.worker - INFO - Comm closed
distributed.worker - INFO - Comm closed
distributed.worker - INFO - Comm closed
distributed.worker - INFO - Comm closed
distributed.worker - INFO - Comm closed
distributed.worker - INFO - Comm closed
distributed.worker - INFO - Comm closed
distributed.worker - INFO - Comm closed
distributed.worker - INFO - Comm closed
distributed.worker - INFO - Comm closed
distributed.worker - INFO - Comm closed
distributed.worker - INFO - Comm closed
distributed.worker - INFO - Comm closed
distributed.worker - INFO - Comm closed
distributed.worker - INFO - Comm closed
distributed.worker - INFO - Comm closed
distributed.worker - INFO - Comm closed
distributed.worker - INFO - Comm closed
distributed.worker - INFO - Comm closed
distributed.worker - INFO - Comm closed
distributed.worker - INFO - Comm closed
distributed.worker - INFO - Comm closed
distributed.worker - INFO - Comm closed
distributed.worker - INFO - Comm closed
distributed.worker - INFO - Comm closed
distributed.worker - INFO - Comm closed
distributed.worker - INFO - Waiting to connect to:   tcp://172.30.100.3:40056
distributed.worker - INFO - Waiting to connect to:   tcp://172.30.100.3:40056
distributed.worker - INFO - Waiting to connect to:   tcp://172.30.100.3:40056
distributed.worker - INFO - Waiting to connect to:   tcp://172.30.100.3:40056
distributed.worker - INFO - Waiting to connect to:   tcp://172.30.100.3:40056
distributed.worker - INFO - Waiting to connect to:   tcp://172.30.100.3:40056
distributed.worker - INFO - Waiting to connect to:   tcp://172.30.100.3:40056
distributed.worker - INFO - Waiting to connect to:   tcp://172.30.100.3:40056
distributed.worker - INFO - Waiting to connect to:   tcp://172.30.100.3:40056
distributed.worker - INFO - Waiting to connect to:   tcp://172.30.100.3:40056
distributed.worker - INFO - Waiting to connect to:   tcp://172.30.100.3:40056
distributed.worker - INFO - Waiting to connect to:   tcp://172.30.100.3:40056
distributed.worker - INFO - Waiting to connect to:   tcp://172.30.100.3:40056
distributed.worker - INFO - Waiting to connect to:   tcp://172.30.100.3:40056
distributed.worker - INFO - Waiting to connect to:   tcp://172.30.100.3:40056
distributed.worker - INFO - Waiting to connect to:   tcp://172.30.100.3:40056
distributed.worker - INFO - Waiting to connect to:   tcp://172.30.100.3:40056
distributed.worker - INFO - Waiting to connect to:   tcp://172.30.100.3:40056
distributed.worker - INFO - Waiting to connect to:   tcp://172.30.100.3:40056
distributed.worker - INFO - Waiting to connect to:   tcp://172.30.100.3:40056
distributed.worker - INFO - Waiting to connect to:   tcp://172.30.100.3:40056
distributed.worker - INFO - Waiting to connect to:   tcp://172.30.100.3:40056
distributed.worker - INFO - Waiting to connect to:   tcp://172.30.100.3:40056
distributed.worker - INFO - Waiting to connect to:   tcp://172.30.100.3:40056
distributed.worker - INFO - Waiting to connect to:   tcp://172.30.100.3:40056
distributed.worker - INFO - Waiting to connect to:   tcp://172.30.100.3:40056
distributed.worker - INFO - Waiting to connect to:   tcp://172.30.100.3:40056
distributed.worker - INFO - Waiting to connect to:   tcp://172.30.100.3:40056
distributed.worker - INFO - Comm closed
distributed.worker - INFO - Comm closed
distributed.worker - INFO - Comm closed
distributed.worker - INFO - Comm closed
distributed.worker - INFO - Comm closed
distributed.worker - INFO - Comm closed
distributed.worker - INFO - Comm closed
distributed.worker - INFO - Comm closed
distributed.worker - INFO - Comm closed
distributed.worker - INFO - Comm closed
distributed.worker - INFO - Comm closed
distributed.worker - INFO - Comm closed
distributed.worker - INFO - Comm closed
distributed.worker - INFO - Comm closed
distributed.worker - INFO - Comm closed
distributed.worker - INFO - Comm closed
distributed.worker - INFO - Comm closed
distributed.worker - INFO - Comm closed
distributed.worker - INFO - Comm closed
distributed.worker - INFO - Comm closed
distributed.worker - INFO - Comm closed
distributed.worker - INFO - Comm closed
distributed.worker - INFO - Comm closed
distributed.worker - INFO - Comm closed
distributed.worker - INFO - Comm closed
distributed.worker - INFO - Comm closed
distributed.worker - INFO - Comm closed
distributed.worker - INFO - Comm closed
distributed.worker - INFO - Comm closed
distributed.worker - INFO - Comm closed
distributed.worker - INFO - Comm closed
distributed.worker - INFO - Comm closed
distributed.worker - INFO - Comm closed
distributed.worker - INFO - Comm closed
distributed.worker - INFO - Comm closed
distributed.worker - INFO - Comm closed
distributed.worker - INFO - Comm closed
distributed.worker - INFO - Comm closed
distributed.worker - INFO - Comm closed
distributed.worker - INFO - Comm closed
distributed.worker - INFO - Comm closed
distributed.worker - INFO - Comm closed
distributed.worker - INFO - Comm closed
distributed.worker - INFO - Comm closed
distributed.worker - INFO - Comm closed
distributed.worker - INFO - Comm closed
distributed.worker - INFO - Comm closed
distributed.worker - INFO - Comm closed
distributed.worker - INFO - Comm closed
distributed.worker - INFO - Comm closed
distributed.worker - INFO - Comm closed
distributed.worker - INFO - Comm closed
distributed.worker - INFO - Waiting to connect to:   tcp://172.30.100.3:40056
distributed.worker - INFO - Waiting to connect to:   tcp://172.30.100.3:40056
distributed.worker - INFO - Waiting to connect to:   tcp://172.30.100.3:40056
distributed.worker - INFO - Waiting to connect to:   tcp://172.30.100.3:40056
distributed.worker - INFO - Waiting to connect to:   tcp://172.30.100.3:40056
distributed.worker - INFO - Waiting to connect to:   tcp://172.30.100.3:40056
distributed.worker - INFO - Waiting to connect to:   tcp://172.30.100.3:40056
distributed.worker - INFO - Waiting to connect to:   tcp://172.30.100.3:40056
distributed.worker - INFO - Waiting to connect to:   tcp://172.30.100.3:40056
distributed.worker - INFO - Waiting to connect to:   tcp://172.30.100.3:40056
distributed.worker - INFO - Waiting to connect to:   tcp://172.30.100.3:40056
distributed.worker - INFO - Comm closed
distributed.worker - INFO - Waiting to connect to:   tcp://172.30.100.3:40056
distributed.worker - INFO - Waiting to connect to:   tcp://172.30.100.3:40056
distributed.worker - INFO - Waiting to connect to:   tcp://172.30.100.3:40056
distributed.worker - INFO - Waiting to connect to:   tcp://172.30.100.3:40056
distributed.worker - INFO - Waiting to connect to:   tcp://172.30.100.3:40056
distributed.worker - INFO - Waiting to connect to:   tcp://172.30.100.3:40056
distributed.worker - INFO - Waiting to connect to:   tcp://172.30.100.3:40056
distributed.worker - INFO - Waiting to connect to:   tcp://172.30.100.3:40056
distributed.worker - INFO - Waiting to connect to:   tcp://172.30.100.3:40056
distributed.worker - INFO - Waiting to connect to:   tcp://172.30.100.3:40056
distributed.worker - INFO - Waiting to connect to:   tcp://172.30.100.3:40056
distributed.worker - INFO - Waiting to connect to:   tcp://172.30.100.3:40056
distributed.worker - INFO - Waiting to connect to:   tcp://172.30.100.3:40056
distributed.worker - INFO - Waiting to connect to:   tcp://172.30.100.3:40056
distributed.worker - INFO - Waiting to connect to:   tcp://172.30.100.3:40056
distributed.worker - INFO - Waiting to connect to:   tcp://172.30.100.3:40056
distributed.worker - INFO - Waiting to connect to:   tcp://172.30.100.3:40056
distributed.worker - INFO - Comm closed
distributed.worker - INFO - Comm closed
distributed.worker - INFO - Comm closed
distributed.worker - INFO - Comm closed
distributed.worker - INFO - Comm closed
distributed.worker - INFO - Comm closed
distributed.worker - INFO - Comm closed
distributed.worker - INFO - Comm closed
distributed.worker - INFO - Comm closed
distributed.worker - INFO - Comm closed
distributed.worker - INFO - Comm closed
distributed.worker - INFO - Comm closed
distributed.worker - INFO - Comm closed
distributed.worker - INFO - Comm closed
distributed.worker - INFO - Comm closed
distributed.worker - INFO - Comm closed
distributed.worker - INFO - Comm closed
distributed.worker - INFO - Comm closed
distributed.worker - INFO - Comm closed
distributed.worker - INFO - Comm closed
distributed.worker - INFO - Comm closed
distributed.worker - INFO - Comm closed
distributed.worker - INFO - Comm closed
distributed.worker - INFO - Comm closed
distributed.worker - INFO - Comm closed
distributed.worker - INFO - Comm closed
distributed.worker - INFO - Comm closed
distributed.worker - INFO - Comm closed
distributed.worker - INFO - Comm closed
distributed.worker - INFO - Comm closed
distributed.worker - INFO - Comm closed
distributed.worker - INFO - Comm closed
distributed.worker - INFO - Comm closed
distributed.worker - INFO - Comm closed
distributed.worker - INFO - Comm closed
distributed.worker - INFO - Comm closed
distributed.worker - INFO - Comm closed
distributed.worker - INFO - Comm closed
distributed.worker - INFO - Comm closed
distributed.worker - INFO - Comm closed
distributed.worker - INFO - Comm closed
distributed.worker - INFO - Comm closed
distributed.worker - INFO - Comm closed
distributed.worker - INFO - Waiting to connect to:   tcp://172.30.100.3:40056
distributed.worker - INFO - Waiting to connect to:   tcp://172.30.100.3:40056
distributed.worker - INFO - Waiting to connect to:   tcp://172.30.100.3:40056
distributed.worker - INFO - Waiting to connect to:   tcp://172.30.100.3:40056
distributed.worker - INFO - Waiting to connect to:   tcp://172.30.100.3:40056
distributed.worker - INFO - Waiting to connect to:   tcp://172.30.100.3:40056
distributed.worker - INFO - Waiting to connect to:   tcp://172.30.100.3:40056
distributed.worker - INFO - Waiting to connect to:   tcp://172.30.100.3:40056
distributed.worker - INFO - Waiting to connect to:   tcp://172.30.100.3:40056
distributed.worker - INFO - Waiting to connect to:   tcp://172.30.100.3:40056
distributed.worker - INFO - Waiting to connect to:   tcp://172.30.100.3:40056
distributed.worker - INFO - Waiting to connect to:   tcp://172.30.100.3:40056
distributed.worker - INFO - Waiting to connect to:   tcp://172.30.100.3:40056
distributed.worker - INFO - Waiting to connect to:   tcp://172.30.100.3:40056
distributed.worker - INFO - Waiting to connect to:   tcp://172.30.100.3:40056
distributed.worker - INFO - Waiting to connect to:   tcp://172.30.100.3:40056
distributed.worker - INFO - Waiting to connect to:   tcp://172.30.100.3:40056
distributed.worker - INFO - Waiting to connect to:   tcp://172.30.100.3:40056
distributed.worker - INFO - Waiting to connect to:   tcp://172.30.100.3:40056
distributed.worker - INFO - Waiting to connect to:   tcp://172.30.100.3:40056
distributed.worker - INFO - Waiting to connect to:   tcp://172.30.100.3:40056
distributed.worker - INFO - Waiting to connect to:   tcp://172.30.100.3:40056
distributed.worker - INFO - Waiting to connect to:   tcp://172.30.100.3:40056
distributed.worker - INFO - Waiting to connect to:   tcp://172.30.100.3:40056
distributed.worker - INFO - Waiting to connect to:   tcp://172.30.100.3:40056
distributed.worker - INFO - Waiting to connect to:   tcp://172.30.100.3:40056
distributed.worker - INFO - Waiting to connect to:   tcp://172.30.100.3:40056
distributed.worker - INFO - Waiting to connect to:   tcp://172.30.100.3:40056
distributed.worker - INFO - Comm closed
distributed.worker - INFO - Comm closed
distributed.worker - INFO - Comm closed
distributed.worker - INFO - Comm closed
distributed.worker - INFO - Comm closed
distributed.worker - INFO - Comm closed
distributed.worker - INFO - Comm closed
distributed.worker - INFO - Comm closed
distributed.worker - INFO - Comm closed
distributed.worker - INFO - Comm closed
distributed.worker - INFO - Comm closed
distributed.worker - INFO - Comm closed
distributed.worker - INFO - Comm closed
distributed.worker - INFO - Comm closed
distributed.worker - INFO - Comm closed
distributed.worker - INFO - Comm closed
distributed.worker - INFO - Comm closed
distributed.worker - INFO - Comm closed
distributed.worker - INFO - Comm closed
distributed.worker - INFO - Comm closed
distributed.worker - INFO - Comm closed
distributed.worker - INFO - Comm closed
distributed.worker - INFO - Comm closed
distributed.worker - INFO - Comm closed
distributed.worker - INFO - Comm closed
distributed.worker - INFO - Comm closed
distributed.worker - INFO - Comm closed
distributed.worker - INFO - Comm closed
distributed.worker - INFO - Comm closed
distributed.worker - INFO - Comm closed
distributed.worker - INFO - Comm closed
distributed.worker - INFO - Comm closed
distributed.worker - INFO - Comm closed
distributed.worker - INFO - Comm closed
distributed.worker - INFO - Comm closed
distributed.worker - INFO - Waiting to connect to:   tcp://172.30.100.3:40056
distributed.worker - INFO - Waiting to connect to:   tcp://172.30.100.3:40056
distributed.worker - INFO - Waiting to connect to:   tcp://172.30.100.3:40056
distributed.worker - INFO - Waiting to connect to:   tcp://172.30.100.3:40056
distributed.worker - INFO - Waiting to connect to:   tcp://172.30.100.3:40056
distributed.worker - INFO - Waiting to connect to:   tcp://172.30.100.3:40056
distributed.worker - INFO - Waiting to connect to:   tcp://172.30.100.3:40056
distributed.worker - INFO - Waiting to connect to:   tcp://172.30.100.3:40056
distributed.worker - INFO - Waiting to connect to:   tcp://172.30.100.3:40056
distributed.worker - INFO - Waiting to connect to:   tcp://172.30.100.3:40056
distributed.worker - INFO - Waiting to connect to:   tcp://172.30.100.3:40056
distributed.worker - INFO - Waiting to connect to:   tcp://172.30.100.3:40056
distributed.worker - INFO - Waiting to connect to:   tcp://172.30.100.3:40056
distributed.worker - INFO - Waiting to connect to:   tcp://172.30.100.3:40056
distributed.worker - INFO - Waiting to connect to:   tcp://172.30.100.3:40056
distributed.worker - INFO - Waiting to connect to:   tcp://172.30.100.3:40056
distributed.worker - INFO - Waiting to connect to:   tcp://172.30.100.3:40056
distributed.worker - INFO - Waiting to connect to:   tcp://172.30.100.3:40056
distributed.worker - INFO - Waiting to connect to:   tcp://172.30.100.3:40056
distributed.worker - INFO - Waiting to connect to:   tcp://172.30.100.3:40056
distributed.worker - INFO - Waiting to connect to:   tcp://172.30.100.3:40056
distributed.worker - INFO - Waiting to connect to:   tcp://172.30.100.3:40056
distributed.worker - INFO - Waiting to connect to:   tcp://172.30.100.3:40056
distributed.worker - INFO - Waiting to connect to:   tcp://172.30.100.3:40056
distributed.worker - INFO - Waiting to connect to:   tcp://172.30.100.3:40056
distributed.worker - INFO - Waiting to connect to:   tcp://172.30.100.3:40056
distributed.worker - INFO - Waiting to connect to:   tcp://172.30.100.3:40056
distributed.worker - INFO - Waiting to connect to:   tcp://172.30.100.3:40056
distributed.worker - INFO - Comm closed
distributed.worker - INFO - Comm closed
distributed.worker - INFO - Comm closed
distributed.worker - INFO - Comm closed
distributed.worker - INFO - Comm closed
distributed.worker - INFO - Comm closed
distributed.worker - INFO - Comm closed
distributed.worker - INFO - Comm closed
distributed.worker - INFO - Comm closed
distributed.worker - INFO - Comm closed
distributed.worker - INFO - Comm closed
distributed.worker - INFO - Comm closed
distributed.worker - INFO - Comm closed
distributed.worker - INFO - Comm closed
distributed.worker - INFO - Comm closed
distributed.worker - INFO - Comm closed
distributed.worker - INFO - Comm closed
distributed.worker - INFO - Comm closed
distributed.worker - INFO - Comm closed
distributed.worker - INFO - Comm closed
distributed.worker - INFO - Comm closed
distributed.worker - INFO - Comm closed
distributed.worker - INFO - Comm closed
distributed.worker - INFO - Comm closed
distributed.worker - INFO - Comm closed
distributed.worker - INFO - Comm closed
distributed.worker - INFO - Comm closed
distributed.worker - INFO - Comm closed
slurmstepd: error: *** JOB 9788782 ON n2279 CANCELLED AT 2020-03-04T13:30:55 DUE TO TIME LIMIT ***
