distributed.nanny - INFO -         Start Nanny at: 'tcp://10.120.40.53:45053'
distributed.worker - INFO -       Start worker at:   tcp://10.120.40.53:42322
distributed.worker - INFO -          Listening to:   tcp://10.120.40.53:42322
distributed.worker - INFO -          dashboard at:         10.120.40.53:41096
distributed.worker - INFO - Waiting to connect to:   tcp://10.120.40.97:33653
distributed.worker - INFO - -------------------------------------------------
distributed.worker - INFO -               Threads:                          1
distributed.worker - INFO -                Memory:                  120.00 GB
distributed.worker - INFO -       Local Directory: /tmp/pbs.6182519.admin01/worker-73mxgwtk
distributed.worker - INFO - -------------------------------------------------
distributed.worker - INFO -         Registered to:   tcp://10.120.40.97:33653
distributed.worker - INFO - -------------------------------------------------
distributed.core - INFO - Starting established connection
/softs/rh7/conda/4.5.4/envs/pangeo_full_201909/lib/python3.7/site-packages/dask/core.py:119: RuntimeWarning: invalid value encountered in less
  return func(*args2)
distributed.utils_perf - INFO - full garbage collection released 15.03 MB from 643 reference cycles (threshold: 10.00 MB)
distributed.worker - INFO - Connection to scheduler broken.  Reconnecting...
distributed.worker - WARNING - Heartbeat to scheduler failed
distributed.worker - WARNING - Heartbeat to scheduler failed
tornado.application - ERROR - Exception in callback functools.partial(<bound method IOLoop._discard_future_result of <tornado.platform.asyncio.AsyncIOLoop object at 0x2aacd5e9eb38>>, <Task finished coro=<Worker.heartbeat() done, defined at /softs/rh7/conda/4.5.4/envs/pangeo_full_201909/lib/python3.7/site-packages/distributed/worker.py:866> exception=OSError("Timed out trying to connect to 'tcp://10.120.40.97:33653' after 10 s: in <distributed.comm.tcp.TCPConnector object at 0x2aaceb059390>: ConnectionRefusedError: [Errno 111] Connection refused")>)
Traceback (most recent call last):
  File "/softs/rh7/conda/4.5.4/envs/pangeo_full_201909/lib/python3.7/site-packages/distributed/comm/core.py", line 215, in connect
    quiet_exceptions=EnvironmentError,
tornado.util.TimeoutError: Timeout

During handling of the above exception, another exception occurred:

Traceback (most recent call last):
  File "/softs/rh7/conda/4.5.4/envs/pangeo_full_201909/lib/python3.7/site-packages/tornado/ioloop.py", line 743, in _run_callback
    ret = callback()
  File "/softs/rh7/conda/4.5.4/envs/pangeo_full_201909/lib/python3.7/site-packages/tornado/ioloop.py", line 767, in _discard_future_result
    future.result()
  File "/softs/rh7/conda/4.5.4/envs/pangeo_full_201909/lib/python3.7/site-packages/distributed/worker.py", line 875, in heartbeat
    metrics=await self.get_metrics(),
  File "/softs/rh7/conda/4.5.4/envs/pangeo_full_201909/lib/python3.7/site-packages/distributed/core.py", line 747, in send_recv_from_rpc
    comm = await self.pool.connect(self.addr)
  File "/softs/rh7/conda/4.5.4/envs/pangeo_full_201909/lib/python3.7/site-packages/distributed/core.py", line 874, in connect
    connection_args=self.connection_args,
  File "/softs/rh7/conda/4.5.4/envs/pangeo_full_201909/lib/python3.7/site-packages/distributed/comm/core.py", line 227, in connect
    _raise(error)
  File "/softs/rh7/conda/4.5.4/envs/pangeo_full_201909/lib/python3.7/site-packages/distributed/comm/core.py", line 204, in _raise
    raise IOError(msg)
OSError: Timed out trying to connect to 'tcp://10.120.40.97:33653' after 10 s: in <distributed.comm.tcp.TCPConnector object at 0x2aaceb059390>: ConnectionRefusedError: [Errno 111] Connection refused
tornado.application - ERROR - Exception in callback functools.partial(<bound method IOLoop._discard_future_result of <tornado.platform.asyncio.AsyncIOLoop object at 0x2aacd5e9eb38>>, <Task finished coro=<Worker.heartbeat() done, defined at /softs/rh7/conda/4.5.4/envs/pangeo_full_201909/lib/python3.7/site-packages/distributed/worker.py:866> exception=OSError("Timed out trying to connect to 'tcp://10.120.40.97:33653' after 10 s: in <distributed.comm.tcp.TCPConnector object at 0x2aaceb059a20>: ConnectionRefusedError: [Errno 111] Connection refused")>)
Traceback (most recent call last):
  File "/softs/rh7/conda/4.5.4/envs/pangeo_full_201909/lib/python3.7/site-packages/distributed/comm/core.py", line 215, in connect
    quiet_exceptions=EnvironmentError,
tornado.util.TimeoutError: Timeout

During handling of the above exception, another exception occurred:

Traceback (most recent call last):
  File "/softs/rh7/conda/4.5.4/envs/pangeo_full_201909/lib/python3.7/site-packages/tornado/ioloop.py", line 743, in _run_callback
    ret = callback()
  File "/softs/rh7/conda/4.5.4/envs/pangeo_full_201909/lib/python3.7/site-packages/tornado/ioloop.py", line 767, in _discard_future_result
    future.result()
  File "/softs/rh7/conda/4.5.4/envs/pangeo_full_201909/lib/python3.7/site-packages/distributed/worker.py", line 875, in heartbeat
    metrics=await self.get_metrics(),
  File "/softs/rh7/conda/4.5.4/envs/pangeo_full_201909/lib/python3.7/site-packages/distributed/core.py", line 747, in send_recv_from_rpc
    comm = await self.pool.connect(self.addr)
  File "/softs/rh7/conda/4.5.4/envs/pangeo_full_201909/lib/python3.7/site-packages/distributed/core.py", line 874, in connect
    connection_args=self.connection_args,
  File "/softs/rh7/conda/4.5.4/envs/pangeo_full_201909/lib/python3.7/site-packages/distributed/comm/core.py", line 227, in connect
    _raise(error)
  File "/softs/rh7/conda/4.5.4/envs/pangeo_full_201909/lib/python3.7/site-packages/distributed/comm/core.py", line 204, in _raise
    raise IOError(msg)
OSError: Timed out trying to connect to 'tcp://10.120.40.97:33653' after 10 s: in <distributed.comm.tcp.TCPConnector object at 0x2aaceb059a20>: ConnectionRefusedError: [Errno 111] Connection refused
tornado.application - ERROR - Exception in callback functools.partial(<bound method IOLoop._discard_future_result of <tornado.platform.asyncio.AsyncIOLoop object at 0x2aacd5e9eb38>>, <Task finished coro=<Worker.heartbeat() done, defined at /softs/rh7/conda/4.5.4/envs/pangeo_full_201909/lib/python3.7/site-packages/distributed/worker.py:866> exception=OSError("Timed out trying to connect to 'tcp://10.120.40.97:33653' after 10 s: in <distributed.comm.tcp.TCPConnector object at 0x2aaceac26b70>: ConnectionRefusedError: [Errno 111] Connection refused")>)
Traceback (most recent call last):
  File "/softs/rh7/conda/4.5.4/envs/pangeo_full_201909/lib/python3.7/site-packages/distributed/comm/core.py", line 215, in connect
    quiet_exceptions=EnvironmentError,
tornado.util.TimeoutError: Timeout

During handling of the above exception, another exception occurred:

Traceback (most recent call last):
  File "/softs/rh7/conda/4.5.4/envs/pangeo_full_201909/lib/python3.7/site-packages/tornado/ioloop.py", line 743, in _run_callback
    ret = callback()
  File "/softs/rh7/conda/4.5.4/envs/pangeo_full_201909/lib/python3.7/site-packages/tornado/ioloop.py", line 767, in _discard_future_result
    future.result()
  File "/softs/rh7/conda/4.5.4/envs/pangeo_full_201909/lib/python3.7/site-packages/distributed/worker.py", line 875, in heartbeat
    metrics=await self.get_metrics(),
  File "/softs/rh7/conda/4.5.4/envs/pangeo_full_201909/lib/python3.7/site-packages/distributed/core.py", line 747, in send_recv_from_rpc
    comm = await self.pool.connect(self.addr)
  File "/softs/rh7/conda/4.5.4/envs/pangeo_full_201909/lib/python3.7/site-packages/distributed/core.py", line 874, in connect
    connection_args=self.connection_args,
  File "/softs/rh7/conda/4.5.4/envs/pangeo_full_201909/lib/python3.7/site-packages/distributed/comm/core.py", line 227, in connect
    _raise(error)
  File "/softs/rh7/conda/4.5.4/envs/pangeo_full_201909/lib/python3.7/site-packages/distributed/comm/core.py", line 204, in _raise
    raise IOError(msg)
OSError: Timed out trying to connect to 'tcp://10.120.40.97:33653' after 10 s: in <distributed.comm.tcp.TCPConnector object at 0x2aaceac26b70>: ConnectionRefusedError: [Errno 111] Connection refused
tornado.application - ERROR - Exception in callback functools.partial(<bound method IOLoop._discard_future_result of <tornado.platform.asyncio.AsyncIOLoop object at 0x2aacd5e9eb38>>, <Task finished coro=<Worker.heartbeat() done, defined at /softs/rh7/conda/4.5.4/envs/pangeo_full_201909/lib/python3.7/site-packages/distributed/worker.py:866> exception=OSError("Timed out trying to connect to 'tcp://10.120.40.97:33653' after 10 s: in <distributed.comm.tcp.TCPConnector object at 0x2aaceb43de80>: ConnectionRefusedError: [Errno 111] Connection refused")>)
Traceback (most recent call last):
  File "/softs/rh7/conda/4.5.4/envs/pangeo_full_201909/lib/python3.7/site-packages/distributed/comm/core.py", line 215, in connect
    quiet_exceptions=EnvironmentError,
tornado.util.TimeoutError: Timeout

During handling of the above exception, another exception occurred:

Traceback (most recent call last):
  File "/softs/rh7/conda/4.5.4/envs/pangeo_full_201909/lib/python3.7/site-packages/tornado/ioloop.py", line 743, in _run_callback
    ret = callback()
  File "/softs/rh7/conda/4.5.4/envs/pangeo_full_201909/lib/python3.7/site-packages/tornado/ioloop.py", line 767, in _discard_future_result
    future.result()
  File "/softs/rh7/conda/4.5.4/envs/pangeo_full_201909/lib/python3.7/site-packages/distributed/worker.py", line 875, in heartbeat
    metrics=await self.get_metrics(),
  File "/softs/rh7/conda/4.5.4/envs/pangeo_full_201909/lib/python3.7/site-packages/distributed/core.py", line 747, in send_recv_from_rpc
    comm = await self.pool.connect(self.addr)
  File "/softs/rh7/conda/4.5.4/envs/pangeo_full_201909/lib/python3.7/site-packages/distributed/core.py", line 874, in connect
    connection_args=self.connection_args,
  File "/softs/rh7/conda/4.5.4/envs/pangeo_full_201909/lib/python3.7/site-packages/distributed/comm/core.py", line 227, in connect
    _raise(error)
  File "/softs/rh7/conda/4.5.4/envs/pangeo_full_201909/lib/python3.7/site-packages/distributed/comm/core.py", line 204, in _raise
    raise IOError(msg)
OSError: Timed out trying to connect to 'tcp://10.120.40.97:33653' after 10 s: in <distributed.comm.tcp.TCPConnector object at 0x2aaceb43de80>: ConnectionRefusedError: [Errno 111] Connection refused
tornado.application - ERROR - Exception in callback <function Worker._register_with_scheduler.<locals>.<lambda> at 0x2aace90462f0>
Traceback (most recent call last):
  File "/softs/rh7/conda/4.5.4/envs/pangeo_full_201909/lib/python3.7/site-packages/tornado/ioloop.py", line 907, in _run
    return self.callback()
  File "/softs/rh7/conda/4.5.4/envs/pangeo_full_201909/lib/python3.7/site-packages/distributed/worker.py", line 857, in <lambda>
    lambda: self.batched_stream.send({"op": "keep-alive"}),
  File "/softs/rh7/conda/4.5.4/envs/pangeo_full_201909/lib/python3.7/site-packages/distributed/batched.py", line 117, in send
    raise CommClosedError
distributed.comm.core.CommClosedError
tornado.application - ERROR - Exception in callback functools.partial(<bound method IOLoop._discard_future_result of <tornado.platform.asyncio.AsyncIOLoop object at 0x2aacd5e9eb38>>, <Task finished coro=<Worker.heartbeat() done, defined at /softs/rh7/conda/4.5.4/envs/pangeo_full_201909/lib/python3.7/site-packages/distributed/worker.py:866> exception=OSError("Timed out trying to connect to 'tcp://10.120.40.97:33653' after 10 s: in <distributed.comm.tcp.TCPConnector object at 0x2aaceb43d630>: ConnectionRefusedError: [Errno 111] Connection refused")>)
Traceback (most recent call last):
  File "/softs/rh7/conda/4.5.4/envs/pangeo_full_201909/lib/python3.7/site-packages/distributed/comm/core.py", line 215, in connect
    quiet_exceptions=EnvironmentError,
tornado.util.TimeoutError: Timeout

During handling of the above exception, another exception occurred:

Traceback (most recent call last):
  File "/softs/rh7/conda/4.5.4/envs/pangeo_full_201909/lib/python3.7/site-packages/tornado/ioloop.py", line 743, in _run_callback
    ret = callback()
  File "/softs/rh7/conda/4.5.4/envs/pangeo_full_201909/lib/python3.7/site-packages/tornado/ioloop.py", line 767, in _discard_future_result
    future.result()
  File "/softs/rh7/conda/4.5.4/envs/pangeo_full_201909/lib/python3.7/site-packages/distributed/worker.py", line 875, in heartbeat
    metrics=await self.get_metrics(),
  File "/softs/rh7/conda/4.5.4/envs/pangeo_full_201909/lib/python3.7/site-packages/distributed/core.py", line 747, in send_recv_from_rpc
    comm = await self.pool.connect(self.addr)
  File "/softs/rh7/conda/4.5.4/envs/pangeo_full_201909/lib/python3.7/site-packages/distributed/core.py", line 874, in connect
    connection_args=self.connection_args,
  File "/softs/rh7/conda/4.5.4/envs/pangeo_full_201909/lib/python3.7/site-packages/distributed/comm/core.py", line 227, in connect
    _raise(error)
  File "/softs/rh7/conda/4.5.4/envs/pangeo_full_201909/lib/python3.7/site-packages/distributed/comm/core.py", line 204, in _raise
    raise IOError(msg)
OSError: Timed out trying to connect to 'tcp://10.120.40.97:33653' after 10 s: in <distributed.comm.tcp.TCPConnector object at 0x2aaceb43d630>: ConnectionRefusedError: [Errno 111] Connection refused
tornado.application - ERROR - Exception in callback functools.partial(<bound method IOLoop._discard_future_result of <tornado.platform.asyncio.AsyncIOLoop object at 0x2aacd5e9eb38>>, <Task finished coro=<Worker.heartbeat() done, defined at /softs/rh7/conda/4.5.4/envs/pangeo_full_201909/lib/python3.7/site-packages/distributed/worker.py:866> exception=OSError("Timed out trying to connect to 'tcp://10.120.40.97:33653' after 10 s: in <distributed.comm.tcp.TCPConnector object at 0x2aaceb43d860>: ConnectionRefusedError: [Errno 111] Connection refused")>)
Traceback (most recent call last):
  File "/softs/rh7/conda/4.5.4/envs/pangeo_full_201909/lib/python3.7/site-packages/distributed/comm/core.py", line 215, in connect
    quiet_exceptions=EnvironmentError,
tornado.util.TimeoutError: Timeout

During handling of the above exception, another exception occurred:

Traceback (most recent call last):
  File "/softs/rh7/conda/4.5.4/envs/pangeo_full_201909/lib/python3.7/site-packages/tornado/ioloop.py", line 743, in _run_callback
    ret = callback()
  File "/softs/rh7/conda/4.5.4/envs/pangeo_full_201909/lib/python3.7/site-packages/tornado/ioloop.py", line 767, in _discard_future_result
    future.result()
  File "/softs/rh7/conda/4.5.4/envs/pangeo_full_201909/lib/python3.7/site-packages/distributed/worker.py", line 875, in heartbeat
    metrics=await self.get_metrics(),
  File "/softs/rh7/conda/4.5.4/envs/pangeo_full_201909/lib/python3.7/site-packages/distributed/core.py", line 747, in send_recv_from_rpc
    comm = await self.pool.connect(self.addr)
  File "/softs/rh7/conda/4.5.4/envs/pangeo_full_201909/lib/python3.7/site-packages/distributed/core.py", line 874, in connect
    connection_args=self.connection_args,
  File "/softs/rh7/conda/4.5.4/envs/pangeo_full_201909/lib/python3.7/site-packages/distributed/comm/core.py", line 227, in connect
    _raise(error)
  File "/softs/rh7/conda/4.5.4/envs/pangeo_full_201909/lib/python3.7/site-packages/distributed/comm/core.py", line 204, in _raise
    raise IOError(msg)
OSError: Timed out trying to connect to 'tcp://10.120.40.97:33653' after 10 s: in <distributed.comm.tcp.TCPConnector object at 0x2aaceb43d860>: ConnectionRefusedError: [Errno 111] Connection refused
tornado.application - ERROR - Exception in callback functools.partial(<bound method IOLoop._discard_future_result of <tornado.platform.asyncio.AsyncIOLoop object at 0x2aacd5e9eb38>>, <Task finished coro=<Worker.heartbeat() done, defined at /softs/rh7/conda/4.5.4/envs/pangeo_full_201909/lib/python3.7/site-packages/distributed/worker.py:866> exception=OSError("Timed out trying to connect to 'tcp://10.120.40.97:33653' after 10 s: in <distributed.comm.tcp.TCPConnector object at 0x2aaceb25a588>: ConnectionRefusedError: [Errno 111] Connection refused")>)
Traceback (most recent call last):
  File "/softs/rh7/conda/4.5.4/envs/pangeo_full_201909/lib/python3.7/site-packages/distributed/comm/core.py", line 215, in connect
    quiet_exceptions=EnvironmentError,
tornado.util.TimeoutError: Timeout

During handling of the above exception, another exception occurred:

Traceback (most recent call last):
  File "/softs/rh7/conda/4.5.4/envs/pangeo_full_201909/lib/python3.7/site-packages/tornado/ioloop.py", line 743, in _run_callback
    ret = callback()
  File "/softs/rh7/conda/4.5.4/envs/pangeo_full_201909/lib/python3.7/site-packages/tornado/ioloop.py", line 767, in _discard_future_result
    future.result()
  File "/softs/rh7/conda/4.5.4/envs/pangeo_full_201909/lib/python3.7/site-packages/distributed/worker.py", line 875, in heartbeat
    metrics=await self.get_metrics(),
  File "/softs/rh7/conda/4.5.4/envs/pangeo_full_201909/lib/python3.7/site-packages/distributed/core.py", line 747, in send_recv_from_rpc
    comm = await self.pool.connect(self.addr)
  File "/softs/rh7/conda/4.5.4/envs/pangeo_full_201909/lib/python3.7/site-packages/distributed/core.py", line 874, in connect
    connection_args=self.connection_args,
  File "/softs/rh7/conda/4.5.4/envs/pangeo_full_201909/lib/python3.7/site-packages/distributed/comm/core.py", line 227, in connect
    _raise(error)
  File "/softs/rh7/conda/4.5.4/envs/pangeo_full_201909/lib/python3.7/site-packages/distributed/comm/core.py", line 204, in _raise
    raise IOError(msg)
OSError: Timed out trying to connect to 'tcp://10.120.40.97:33653' after 10 s: in <distributed.comm.tcp.TCPConnector object at 0x2aaceb25a588>: ConnectionRefusedError: [Errno 111] Connection refused
tornado.application - ERROR - Exception in callback functools.partial(<bound method IOLoop._discard_future_result of <tornado.platform.asyncio.AsyncIOLoop object at 0x2aacd5e9eb38>>, <Task finished coro=<Worker.heartbeat() done, defined at /softs/rh7/conda/4.5.4/envs/pangeo_full_201909/lib/python3.7/site-packages/distributed/worker.py:866> exception=OSError("Timed out trying to connect to 'tcp://10.120.40.97:33653' after 10 s: in <distributed.comm.tcp.TCPConnector object at 0x2aaceb78bba8>: ConnectionRefusedError: [Errno 111] Connection refused")>)
Traceback (most recent call last):
  File "/softs/rh7/conda/4.5.4/envs/pangeo_full_201909/lib/python3.7/site-packages/distributed/comm/core.py", line 215, in connect
    quiet_exceptions=EnvironmentError,
tornado.util.TimeoutError: Timeout

During handling of the above exception, another exception occurred:

Traceback (most recent call last):
  File "/softs/rh7/conda/4.5.4/envs/pangeo_full_201909/lib/python3.7/site-packages/tornado/ioloop.py", line 743, in _run_callback
    ret = callback()
  File "/softs/rh7/conda/4.5.4/envs/pangeo_full_201909/lib/python3.7/site-packages/tornado/ioloop.py", line 767, in _discard_future_result
    future.result()
  File "/softs/rh7/conda/4.5.4/envs/pangeo_full_201909/lib/python3.7/site-packages/distributed/worker.py", line 875, in heartbeat
    metrics=await self.get_metrics(),
  File "/softs/rh7/conda/4.5.4/envs/pangeo_full_201909/lib/python3.7/site-packages/distributed/core.py", line 747, in send_recv_from_rpc
    comm = await self.pool.connect(self.addr)
  File "/softs/rh7/conda/4.5.4/envs/pangeo_full_201909/lib/python3.7/site-packages/distributed/core.py", line 874, in connect
    connection_args=self.connection_args,
  File "/softs/rh7/conda/4.5.4/envs/pangeo_full_201909/lib/python3.7/site-packages/distributed/comm/core.py", line 227, in connect
    _raise(error)
  File "/softs/rh7/conda/4.5.4/envs/pangeo_full_201909/lib/python3.7/site-packages/distributed/comm/core.py", line 204, in _raise
    raise IOError(msg)
OSError: Timed out trying to connect to 'tcp://10.120.40.97:33653' after 10 s: in <distributed.comm.tcp.TCPConnector object at 0x2aaceb78bba8>: ConnectionRefusedError: [Errno 111] Connection refused
tornado.application - ERROR - Exception in callback functools.partial(<bound method IOLoop._discard_future_result of <tornado.platform.asyncio.AsyncIOLoop object at 0x2aacd5e9eb38>>, <Task finished coro=<Worker.heartbeat() done, defined at /softs/rh7/conda/4.5.4/envs/pangeo_full_201909/lib/python3.7/site-packages/distributed/worker.py:866> exception=OSError("Timed out trying to connect to 'tcp://10.120.40.97:33653' after 10 s: in <distributed.comm.tcp.TCPConnector object at 0x2aaceb693c18>: ConnectionRefusedError: [Errno 111] Connection refused")>)
Traceback (most recent call last):
  File "/softs/rh7/conda/4.5.4/envs/pangeo_full_201909/lib/python3.7/site-packages/distributed/comm/core.py", line 215, in connect
    quiet_exceptions=EnvironmentError,
tornado.util.TimeoutError: Timeout

During handling of the above exception, another exception occurred:

Traceback (most recent call last):
  File "/softs/rh7/conda/4.5.4/envs/pangeo_full_201909/lib/python3.7/site-packages/tornado/ioloop.py", line 743, in _run_callback
    ret = callback()
  File "/softs/rh7/conda/4.5.4/envs/pangeo_full_201909/lib/python3.7/site-packages/tornado/ioloop.py", line 767, in _discard_future_result
    future.result()
  File "/softs/rh7/conda/4.5.4/envs/pangeo_full_201909/lib/python3.7/site-packages/distributed/worker.py", line 875, in heartbeat
    metrics=await self.get_metrics(),
  File "/softs/rh7/conda/4.5.4/envs/pangeo_full_201909/lib/python3.7/site-packages/distributed/core.py", line 747, in send_recv_from_rpc
    comm = await self.pool.connect(self.addr)
  File "/softs/rh7/conda/4.5.4/envs/pangeo_full_201909/lib/python3.7/site-packages/distributed/core.py", line 874, in connect
    connection_args=self.connection_args,
  File "/softs/rh7/conda/4.5.4/envs/pangeo_full_201909/lib/python3.7/site-packages/distributed/comm/core.py", line 227, in connect
    _raise(error)
  File "/softs/rh7/conda/4.5.4/envs/pangeo_full_201909/lib/python3.7/site-packages/distributed/comm/core.py", line 204, in _raise
    raise IOError(msg)
OSError: Timed out trying to connect to 'tcp://10.120.40.97:33653' after 10 s: in <distributed.comm.tcp.TCPConnector object at 0x2aaceb693c18>: ConnectionRefusedError: [Errno 111] Connection refused
tornado.application - ERROR - Exception in callback <function Worker._register_with_scheduler.<locals>.<lambda> at 0x2aace90462f0>
Traceback (most recent call last):
  File "/softs/rh7/conda/4.5.4/envs/pangeo_full_201909/lib/python3.7/site-packages/tornado/ioloop.py", line 907, in _run
    return self.callback()
  File "/softs/rh7/conda/4.5.4/envs/pangeo_full_201909/lib/python3.7/site-packages/distributed/worker.py", line 857, in <lambda>
    lambda: self.batched_stream.send({"op": "keep-alive"}),
  File "/softs/rh7/conda/4.5.4/envs/pangeo_full_201909/lib/python3.7/site-packages/distributed/batched.py", line 117, in send
    raise CommClosedError
distributed.comm.core.CommClosedError
tornado.application - ERROR - Exception in callback functools.partial(<bound method IOLoop._discard_future_result of <tornado.platform.asyncio.AsyncIOLoop object at 0x2aacd5e9eb38>>, <Task finished coro=<Worker.heartbeat() done, defined at /softs/rh7/conda/4.5.4/envs/pangeo_full_201909/lib/python3.7/site-packages/distributed/worker.py:866> exception=OSError("Timed out trying to connect to 'tcp://10.120.40.97:33653' after 10 s: in <distributed.comm.tcp.TCPConnector object at 0x2aaceb78bd68>: ConnectionRefusedError: [Errno 111] Connection refused")>)
Traceback (most recent call last):
  File "/softs/rh7/conda/4.5.4/envs/pangeo_full_201909/lib/python3.7/site-packages/distributed/comm/core.py", line 215, in connect
    quiet_exceptions=EnvironmentError,
tornado.util.TimeoutError: Timeout

During handling of the above exception, another exception occurred:

Traceback (most recent call last):
  File "/softs/rh7/conda/4.5.4/envs/pangeo_full_201909/lib/python3.7/site-packages/tornado/ioloop.py", line 743, in _run_callback
    ret = callback()
  File "/softs/rh7/conda/4.5.4/envs/pangeo_full_201909/lib/python3.7/site-packages/tornado/ioloop.py", line 767, in _discard_future_result
    future.result()
  File "/softs/rh7/conda/4.5.4/envs/pangeo_full_201909/lib/python3.7/site-packages/distributed/worker.py", line 875, in heartbeat
    metrics=await self.get_metrics(),
  File "/softs/rh7/conda/4.5.4/envs/pangeo_full_201909/lib/python3.7/site-packages/distributed/core.py", line 747, in send_recv_from_rpc
    comm = await self.pool.connect(self.addr)
  File "/softs/rh7/conda/4.5.4/envs/pangeo_full_201909/lib/python3.7/site-packages/distributed/core.py", line 874, in connect
    connection_args=self.connection_args,
  File "/softs/rh7/conda/4.5.4/envs/pangeo_full_201909/lib/python3.7/site-packages/distributed/comm/core.py", line 227, in connect
    _raise(error)
  File "/softs/rh7/conda/4.5.4/envs/pangeo_full_201909/lib/python3.7/site-packages/distributed/comm/core.py", line 204, in _raise
    raise IOError(msg)
OSError: Timed out trying to connect to 'tcp://10.120.40.97:33653' after 10 s: in <distributed.comm.tcp.TCPConnector object at 0x2aaceb78bd68>: ConnectionRefusedError: [Errno 111] Connection refused
tornado.application - ERROR - Exception in callback functools.partial(<bound method IOLoop._discard_future_result of <tornado.platform.asyncio.AsyncIOLoop object at 0x2aacd5e9eb38>>, <Task finished coro=<Worker.heartbeat() done, defined at /softs/rh7/conda/4.5.4/envs/pangeo_full_201909/lib/python3.7/site-packages/distributed/worker.py:866> exception=OSError("Timed out trying to connect to 'tcp://10.120.40.97:33653' after 10 s: in <distributed.comm.tcp.TCPConnector object at 0x2aaceadf2b00>: ConnectionRefusedError: [Errno 111] Connection refused")>)
Traceback (most recent call last):
  File "/softs/rh7/conda/4.5.4/envs/pangeo_full_201909/lib/python3.7/site-packages/distributed/comm/core.py", line 215, in connect
    quiet_exceptions=EnvironmentError,
tornado.util.TimeoutError: Timeout

During handling of the above exception, another exception occurred:

Traceback (most recent call last):
  File "/softs/rh7/conda/4.5.4/envs/pangeo_full_201909/lib/python3.7/site-packages/tornado/ioloop.py", line 743, in _run_callback
    ret = callback()
  File "/softs/rh7/conda/4.5.4/envs/pangeo_full_201909/lib/python3.7/site-packages/tornado/ioloop.py", line 767, in _discard_future_result
    future.result()
  File "/softs/rh7/conda/4.5.4/envs/pangeo_full_201909/lib/python3.7/site-packages/distributed/worker.py", line 875, in heartbeat
    metrics=await self.get_metrics(),
  File "/softs/rh7/conda/4.5.4/envs/pangeo_full_201909/lib/python3.7/site-packages/distributed/core.py", line 747, in send_recv_from_rpc
    comm = await self.pool.connect(self.addr)
  File "/softs/rh7/conda/4.5.4/envs/pangeo_full_201909/lib/python3.7/site-packages/distributed/core.py", line 874, in connect
    connection_args=self.connection_args,
  File "/softs/rh7/conda/4.5.4/envs/pangeo_full_201909/lib/python3.7/site-packages/distributed/comm/core.py", line 227, in connect
    _raise(error)
  File "/softs/rh7/conda/4.5.4/envs/pangeo_full_201909/lib/python3.7/site-packages/distributed/comm/core.py", line 204, in _raise
    raise IOError(msg)
OSError: Timed out trying to connect to 'tcp://10.120.40.97:33653' after 10 s: in <distributed.comm.tcp.TCPConnector object at 0x2aaceadf2b00>: ConnectionRefusedError: [Errno 111] Connection refused
tornado.application - ERROR - Exception in callback functools.partial(<bound method IOLoop._discard_future_result of <tornado.platform.asyncio.AsyncIOLoop object at 0x2aacd5e9eb38>>, <Task finished coro=<Worker.heartbeat() done, defined at /softs/rh7/conda/4.5.4/envs/pangeo_full_201909/lib/python3.7/site-packages/distributed/worker.py:866> exception=OSError("Timed out trying to connect to 'tcp://10.120.40.97:33653' after 10 s: in <distributed.comm.tcp.TCPConnector object at 0x2aaceaffcef0>: ConnectionRefusedError: [Errno 111] Connection refused")>)
Traceback (most recent call last):
  File "/softs/rh7/conda/4.5.4/envs/pangeo_full_201909/lib/python3.7/site-packages/distributed/comm/core.py", line 215, in connect
    quiet_exceptions=EnvironmentError,
tornado.util.TimeoutError: Timeout

During handling of the above exception, another exception occurred:

Traceback (most recent call last):
  File "/softs/rh7/conda/4.5.4/envs/pangeo_full_201909/lib/python3.7/site-packages/tornado/ioloop.py", line 743, in _run_callback
    ret = callback()
  File "/softs/rh7/conda/4.5.4/envs/pangeo_full_201909/lib/python3.7/site-packages/tornado/ioloop.py", line 767, in _discard_future_result
    future.result()
  File "/softs/rh7/conda/4.5.4/envs/pangeo_full_201909/lib/python3.7/site-packages/distributed/worker.py", line 875, in heartbeat
    metrics=await self.get_metrics(),
  File "/softs/rh7/conda/4.5.4/envs/pangeo_full_201909/lib/python3.7/site-packages/distributed/core.py", line 747, in send_recv_from_rpc
    comm = await self.pool.connect(self.addr)
  File "/softs/rh7/conda/4.5.4/envs/pangeo_full_201909/lib/python3.7/site-packages/distributed/core.py", line 874, in connect
    connection_args=self.connection_args,
  File "/softs/rh7/conda/4.5.4/envs/pangeo_full_201909/lib/python3.7/site-packages/distributed/comm/core.py", line 227, in connect
    _raise(error)
  File "/softs/rh7/conda/4.5.4/envs/pangeo_full_201909/lib/python3.7/site-packages/distributed/comm/core.py", line 204, in _raise
    raise IOError(msg)
OSError: Timed out trying to connect to 'tcp://10.120.40.97:33653' after 10 s: in <distributed.comm.tcp.TCPConnector object at 0x2aaceaffcef0>: ConnectionRefusedError: [Errno 111] Connection refused
tornado.application - ERROR - Exception in callback functools.partial(<bound method IOLoop._discard_future_result of <tornado.platform.asyncio.AsyncIOLoop object at 0x2aacd5e9eb38>>, <Task finished coro=<Worker.heartbeat() done, defined at /softs/rh7/conda/4.5.4/envs/pangeo_full_201909/lib/python3.7/site-packages/distributed/worker.py:866> exception=OSError("Timed out trying to connect to 'tcp://10.120.40.97:33653' after 10 s: in <distributed.comm.tcp.TCPConnector object at 0x2aaceb78b6d8>: ConnectionRefusedError: [Errno 111] Connection refused")>)
Traceback (most recent call last):
  File "/softs/rh7/conda/4.5.4/envs/pangeo_full_201909/lib/python3.7/site-packages/distributed/comm/core.py", line 215, in connect
    quiet_exceptions=EnvironmentError,
tornado.util.TimeoutError: Timeout

During handling of the above exception, another exception occurred:

Traceback (most recent call last):
  File "/softs/rh7/conda/4.5.4/envs/pangeo_full_201909/lib/python3.7/site-packages/tornado/ioloop.py", line 743, in _run_callback
    ret = callback()
  File "/softs/rh7/conda/4.5.4/envs/pangeo_full_201909/lib/python3.7/site-packages/tornado/ioloop.py", line 767, in _discard_future_result
    future.result()
  File "/softs/rh7/conda/4.5.4/envs/pangeo_full_201909/lib/python3.7/site-packages/distributed/worker.py", line 875, in heartbeat
    metrics=await self.get_metrics(),
  File "/softs/rh7/conda/4.5.4/envs/pangeo_full_201909/lib/python3.7/site-packages/distributed/core.py", line 747, in send_recv_from_rpc
    comm = await self.pool.connect(self.addr)
  File "/softs/rh7/conda/4.5.4/envs/pangeo_full_201909/lib/python3.7/site-packages/distributed/core.py", line 874, in connect
    connection_args=self.connection_args,
  File "/softs/rh7/conda/4.5.4/envs/pangeo_full_201909/lib/python3.7/site-packages/distributed/comm/core.py", line 227, in connect
    _raise(error)
  File "/softs/rh7/conda/4.5.4/envs/pangeo_full_201909/lib/python3.7/site-packages/distributed/comm/core.py", line 204, in _raise
    raise IOError(msg)
OSError: Timed out trying to connect to 'tcp://10.120.40.97:33653' after 10 s: in <distributed.comm.tcp.TCPConnector object at 0x2aaceb78b6d8>: ConnectionRefusedError: [Errno 111] Connection refused
tornado.application - ERROR - Exception in callback functools.partial(<bound method IOLoop._discard_future_result of <tornado.platform.asyncio.AsyncIOLoop object at 0x2aacd5e9eb38>>, <Task finished coro=<Worker.heartbeat() done, defined at /softs/rh7/conda/4.5.4/envs/pangeo_full_201909/lib/python3.7/site-packages/distributed/worker.py:866> exception=OSError("Timed out trying to connect to 'tcp://10.120.40.97:33653' after 10 s: in <distributed.comm.tcp.TCPConnector object at 0x2aacea7e7da0>: ConnectionRefusedError: [Errno 111] Connection refused")>)
Traceback (most recent call last):
  File "/softs/rh7/conda/4.5.4/envs/pangeo_full_201909/lib/python3.7/site-packages/distributed/comm/core.py", line 215, in connect
    quiet_exceptions=EnvironmentError,
tornado.util.TimeoutError: Timeout

During handling of the above exception, another exception occurred:

Traceback (most recent call last):
  File "/softs/rh7/conda/4.5.4/envs/pangeo_full_201909/lib/python3.7/site-packages/tornado/ioloop.py", line 743, in _run_callback
    ret = callback()
  File "/softs/rh7/conda/4.5.4/envs/pangeo_full_201909/lib/python3.7/site-packages/tornado/ioloop.py", line 767, in _discard_future_result
    future.result()
  File "/softs/rh7/conda/4.5.4/envs/pangeo_full_201909/lib/python3.7/site-packages/distributed/worker.py", line 875, in heartbeat
    metrics=await self.get_metrics(),
  File "/softs/rh7/conda/4.5.4/envs/pangeo_full_201909/lib/python3.7/site-packages/distributed/core.py", line 747, in send_recv_from_rpc
    comm = await self.pool.connect(self.addr)
  File "/softs/rh7/conda/4.5.4/envs/pangeo_full_201909/lib/python3.7/site-packages/distributed/core.py", line 874, in connect
    connection_args=self.connection_args,
  File "/softs/rh7/conda/4.5.4/envs/pangeo_full_201909/lib/python3.7/site-packages/distributed/comm/core.py", line 227, in connect
    _raise(error)
  File "/softs/rh7/conda/4.5.4/envs/pangeo_full_201909/lib/python3.7/site-packages/distributed/comm/core.py", line 204, in _raise
    raise IOError(msg)
OSError: Timed out trying to connect to 'tcp://10.120.40.97:33653' after 10 s: in <distributed.comm.tcp.TCPConnector object at 0x2aacea7e7da0>: ConnectionRefusedError: [Errno 111] Connection refused
tornado.application - ERROR - Exception in callback functools.partial(<bound method IOLoop._discard_future_result of <tornado.platform.asyncio.AsyncIOLoop object at 0x2aacd5e9eb38>>, <Task finished coro=<Worker.heartbeat() done, defined at /softs/rh7/conda/4.5.4/envs/pangeo_full_201909/lib/python3.7/site-packages/distributed/worker.py:866> exception=OSError("Timed out trying to connect to 'tcp://10.120.40.97:33653' after 10 s: in <distributed.comm.tcp.TCPConnector object at 0x2aaceac26828>: ConnectionRefusedError: [Errno 111] Connection refused")>)
Traceback (most recent call last):
  File "/softs/rh7/conda/4.5.4/envs/pangeo_full_201909/lib/python3.7/site-packages/distributed/comm/core.py", line 215, in connect
    quiet_exceptions=EnvironmentError,
tornado.util.TimeoutError: Timeout

During handling of the above exception, another exception occurred:

Traceback (most recent call last):
  File "/softs/rh7/conda/4.5.4/envs/pangeo_full_201909/lib/python3.7/site-packages/tornado/ioloop.py", line 743, in _run_callback
    ret = callback()
  File "/softs/rh7/conda/4.5.4/envs/pangeo_full_201909/lib/python3.7/site-packages/tornado/ioloop.py", line 767, in _discard_future_result
    future.result()
  File "/softs/rh7/conda/4.5.4/envs/pangeo_full_201909/lib/python3.7/site-packages/distributed/worker.py", line 875, in heartbeat
    metrics=await self.get_metrics(),
  File "/softs/rh7/conda/4.5.4/envs/pangeo_full_201909/lib/python3.7/site-packages/distributed/core.py", line 747, in send_recv_from_rpc
    comm = await self.pool.connect(self.addr)
  File "/softs/rh7/conda/4.5.4/envs/pangeo_full_201909/lib/python3.7/site-packages/distributed/core.py", line 874, in connect
    connection_args=self.connection_args,
  File "/softs/rh7/conda/4.5.4/envs/pangeo_full_201909/lib/python3.7/site-packages/distributed/comm/core.py", line 227, in connect
    _raise(error)
  File "/softs/rh7/conda/4.5.4/envs/pangeo_full_201909/lib/python3.7/site-packages/distributed/comm/core.py", line 204, in _raise
    raise IOError(msg)
OSError: Timed out trying to connect to 'tcp://10.120.40.97:33653' after 10 s: in <distributed.comm.tcp.TCPConnector object at 0x2aaceac26828>: ConnectionRefusedError: [Errno 111] Connection refused
tornado.application - ERROR - Exception in callback <function Worker._register_with_scheduler.<locals>.<lambda> at 0x2aace90462f0>
Traceback (most recent call last):
  File "/softs/rh7/conda/4.5.4/envs/pangeo_full_201909/lib/python3.7/site-packages/tornado/ioloop.py", line 907, in _run
    return self.callback()
  File "/softs/rh7/conda/4.5.4/envs/pangeo_full_201909/lib/python3.7/site-packages/distributed/worker.py", line 857, in <lambda>
    lambda: self.batched_stream.send({"op": "keep-alive"}),
  File "/softs/rh7/conda/4.5.4/envs/pangeo_full_201909/lib/python3.7/site-packages/distributed/batched.py", line 117, in send
    raise CommClosedError
distributed.comm.core.CommClosedError
tornado.application - ERROR - Exception in callback functools.partial(<bound method IOLoop._discard_future_result of <tornado.platform.asyncio.AsyncIOLoop object at 0x2aacd5e9eb38>>, <Task finished coro=<Worker.heartbeat() done, defined at /softs/rh7/conda/4.5.4/envs/pangeo_full_201909/lib/python3.7/site-packages/distributed/worker.py:866> exception=OSError("Timed out trying to connect to 'tcp://10.120.40.97:33653' after 10 s: in <distributed.comm.tcp.TCPConnector object at 0x2aaceb3efe48>: ConnectionRefusedError: [Errno 111] Connection refused")>)
Traceback (most recent call last):
  File "/softs/rh7/conda/4.5.4/envs/pangeo_full_201909/lib/python3.7/site-packages/distributed/comm/core.py", line 215, in connect
    quiet_exceptions=EnvironmentError,
tornado.util.TimeoutError: Timeout

During handling of the above exception, another exception occurred:

Traceback (most recent call last):
  File "/softs/rh7/conda/4.5.4/envs/pangeo_full_201909/lib/python3.7/site-packages/tornado/ioloop.py", line 743, in _run_callback
    ret = callback()
  File "/softs/rh7/conda/4.5.4/envs/pangeo_full_201909/lib/python3.7/site-packages/tornado/ioloop.py", line 767, in _discard_future_result
    future.result()
  File "/softs/rh7/conda/4.5.4/envs/pangeo_full_201909/lib/python3.7/site-packages/distributed/worker.py", line 875, in heartbeat
    metrics=await self.get_metrics(),
  File "/softs/rh7/conda/4.5.4/envs/pangeo_full_201909/lib/python3.7/site-packages/distributed/core.py", line 747, in send_recv_from_rpc
    comm = await self.pool.connect(self.addr)
  File "/softs/rh7/conda/4.5.4/envs/pangeo_full_201909/lib/python3.7/site-packages/distributed/core.py", line 874, in connect
    connection_args=self.connection_args,
  File "/softs/rh7/conda/4.5.4/envs/pangeo_full_201909/lib/python3.7/site-packages/distributed/comm/core.py", line 227, in connect
    _raise(error)
  File "/softs/rh7/conda/4.5.4/envs/pangeo_full_201909/lib/python3.7/site-packages/distributed/comm/core.py", line 204, in _raise
    raise IOError(msg)
OSError: Timed out trying to connect to 'tcp://10.120.40.97:33653' after 10 s: in <distributed.comm.tcp.TCPConnector object at 0x2aaceb3efe48>: ConnectionRefusedError: [Errno 111] Connection refused
tornado.application - ERROR - Exception in callback functools.partial(<bound method IOLoop._discard_future_result of <tornado.platform.asyncio.AsyncIOLoop object at 0x2aacd5e9eb38>>, <Task finished coro=<Worker.heartbeat() done, defined at /softs/rh7/conda/4.5.4/envs/pangeo_full_201909/lib/python3.7/site-packages/distributed/worker.py:866> exception=OSError("Timed out trying to connect to 'tcp://10.120.40.97:33653' after 10 s: in <distributed.comm.tcp.TCPConnector object at 0x2aaceb693198>: ConnectionRefusedError: [Errno 111] Connection refused")>)
Traceback (most recent call last):
  File "/softs/rh7/conda/4.5.4/envs/pangeo_full_201909/lib/python3.7/site-packages/distributed/comm/core.py", line 215, in connect
    quiet_exceptions=EnvironmentError,
tornado.util.TimeoutError: Timeout

During handling of the above exception, another exception occurred:

Traceback (most recent call last):
  File "/softs/rh7/conda/4.5.4/envs/pangeo_full_201909/lib/python3.7/site-packages/tornado/ioloop.py", line 743, in _run_callback
    ret = callback()
  File "/softs/rh7/conda/4.5.4/envs/pangeo_full_201909/lib/python3.7/site-packages/tornado/ioloop.py", line 767, in _discard_future_result
    future.result()
  File "/softs/rh7/conda/4.5.4/envs/pangeo_full_201909/lib/python3.7/site-packages/distributed/worker.py", line 875, in heartbeat
    metrics=await self.get_metrics(),
  File "/softs/rh7/conda/4.5.4/envs/pangeo_full_201909/lib/python3.7/site-packages/distributed/core.py", line 747, in send_recv_from_rpc
    comm = await self.pool.connect(self.addr)
  File "/softs/rh7/conda/4.5.4/envs/pangeo_full_201909/lib/python3.7/site-packages/distributed/core.py", line 874, in connect
    connection_args=self.connection_args,
  File "/softs/rh7/conda/4.5.4/envs/pangeo_full_201909/lib/python3.7/site-packages/distributed/comm/core.py", line 227, in connect
    _raise(error)
  File "/softs/rh7/conda/4.5.4/envs/pangeo_full_201909/lib/python3.7/site-packages/distributed/comm/core.py", line 204, in _raise
    raise IOError(msg)
OSError: Timed out trying to connect to 'tcp://10.120.40.97:33653' after 10 s: in <distributed.comm.tcp.TCPConnector object at 0x2aaceb693198>: ConnectionRefusedError: [Errno 111] Connection refused
tornado.application - ERROR - Exception in callback functools.partial(<bound method IOLoop._discard_future_result of <tornado.platform.asyncio.AsyncIOLoop object at 0x2aacd5e9eb38>>, <Task finished coro=<Worker.heartbeat() done, defined at /softs/rh7/conda/4.5.4/envs/pangeo_full_201909/lib/python3.7/site-packages/distributed/worker.py:866> exception=OSError("Timed out trying to connect to 'tcp://10.120.40.97:33653' after 10 s: in <distributed.comm.tcp.TCPConnector object at 0x2aaceb693828>: ConnectionRefusedError: [Errno 111] Connection refused")>)
Traceback (most recent call last):
  File "/softs/rh7/conda/4.5.4/envs/pangeo_full_201909/lib/python3.7/site-packages/distributed/comm/core.py", line 215, in connect
    quiet_exceptions=EnvironmentError,
tornado.util.TimeoutError: Timeout

During handling of the above exception, another exception occurred:

Traceback (most recent call last):
  File "/softs/rh7/conda/4.5.4/envs/pangeo_full_201909/lib/python3.7/site-packages/tornado/ioloop.py", line 743, in _run_callback
    ret = callback()
  File "/softs/rh7/conda/4.5.4/envs/pangeo_full_201909/lib/python3.7/site-packages/tornado/ioloop.py", line 767, in _discard_future_result
    future.result()
  File "/softs/rh7/conda/4.5.4/envs/pangeo_full_201909/lib/python3.7/site-packages/distributed/worker.py", line 875, in heartbeat
    metrics=await self.get_metrics(),
  File "/softs/rh7/conda/4.5.4/envs/pangeo_full_201909/lib/python3.7/site-packages/distributed/core.py", line 747, in send_recv_from_rpc
    comm = await self.pool.connect(self.addr)
  File "/softs/rh7/conda/4.5.4/envs/pangeo_full_201909/lib/python3.7/site-packages/distributed/core.py", line 874, in connect
    connection_args=self.connection_args,
  File "/softs/rh7/conda/4.5.4/envs/pangeo_full_201909/lib/python3.7/site-packages/distributed/comm/core.py", line 227, in connect
    _raise(error)
  File "/softs/rh7/conda/4.5.4/envs/pangeo_full_201909/lib/python3.7/site-packages/distributed/comm/core.py", line 204, in _raise
    raise IOError(msg)
OSError: Timed out trying to connect to 'tcp://10.120.40.97:33653' after 10 s: in <distributed.comm.tcp.TCPConnector object at 0x2aaceb693828>: ConnectionRefusedError: [Errno 111] Connection refused
tornado.application - ERROR - Exception in callback functools.partial(<bound method IOLoop._discard_future_result of <tornado.platform.asyncio.AsyncIOLoop object at 0x2aacd5e9eb38>>, <Task finished coro=<Worker.heartbeat() done, defined at /softs/rh7/conda/4.5.4/envs/pangeo_full_201909/lib/python3.7/site-packages/distributed/worker.py:866> exception=OSError("Timed out trying to connect to 'tcp://10.120.40.97:33653' after 10 s: in <distributed.comm.tcp.TCPConnector object at 0x2aaceac26e10>: ConnectionRefusedError: [Errno 111] Connection refused")>)
Traceback (most recent call last):
  File "/softs/rh7/conda/4.5.4/envs/pangeo_full_201909/lib/python3.7/site-packages/distributed/comm/core.py", line 215, in connect
    quiet_exceptions=EnvironmentError,
tornado.util.TimeoutError: Timeout

During handling of the above exception, another exception occurred:

Traceback (most recent call last):
  File "/softs/rh7/conda/4.5.4/envs/pangeo_full_201909/lib/python3.7/site-packages/tornado/ioloop.py", line 743, in _run_callback
    ret = callback()
  File "/softs/rh7/conda/4.5.4/envs/pangeo_full_201909/lib/python3.7/site-packages/tornado/ioloop.py", line 767, in _discard_future_result
    future.result()
  File "/softs/rh7/conda/4.5.4/envs/pangeo_full_201909/lib/python3.7/site-packages/distributed/worker.py", line 875, in heartbeat
    metrics=await self.get_metrics(),
  File "/softs/rh7/conda/4.5.4/envs/pangeo_full_201909/lib/python3.7/site-packages/distributed/core.py", line 747, in send_recv_from_rpc
    comm = await self.pool.connect(self.addr)
  File "/softs/rh7/conda/4.5.4/envs/pangeo_full_201909/lib/python3.7/site-packages/distributed/core.py", line 874, in connect
    connection_args=self.connection_args,
  File "/softs/rh7/conda/4.5.4/envs/pangeo_full_201909/lib/python3.7/site-packages/distributed/comm/core.py", line 227, in connect
    _raise(error)
  File "/softs/rh7/conda/4.5.4/envs/pangeo_full_201909/lib/python3.7/site-packages/distributed/comm/core.py", line 204, in _raise
    raise IOError(msg)
OSError: Timed out trying to connect to 'tcp://10.120.40.97:33653' after 10 s: in <distributed.comm.tcp.TCPConnector object at 0x2aaceac26e10>: ConnectionRefusedError: [Errno 111] Connection refused
tornado.application - ERROR - Exception in callback functools.partial(<bound method IOLoop._discard_future_result of <tornado.platform.asyncio.AsyncIOLoop object at 0x2aacd5e9eb38>>, <Task finished coro=<Worker.heartbeat() done, defined at /softs/rh7/conda/4.5.4/envs/pangeo_full_201909/lib/python3.7/site-packages/distributed/worker.py:866> exception=OSError("Timed out trying to connect to 'tcp://10.120.40.97:33653' after 10 s: in <distributed.comm.tcp.TCPConnector object at 0x2aaceb693240>: ConnectionRefusedError: [Errno 111] Connection refused")>)
Traceback (most recent call last):
  File "/softs/rh7/conda/4.5.4/envs/pangeo_full_201909/lib/python3.7/site-packages/distributed/comm/core.py", line 215, in connect
    quiet_exceptions=EnvironmentError,
tornado.util.TimeoutError: Timeout

During handling of the above exception, another exception occurred:

Traceback (most recent call last):
  File "/softs/rh7/conda/4.5.4/envs/pangeo_full_201909/lib/python3.7/site-packages/tornado/ioloop.py", line 743, in _run_callback
    ret = callback()
  File "/softs/rh7/conda/4.5.4/envs/pangeo_full_201909/lib/python3.7/site-packages/tornado/ioloop.py", line 767, in _discard_future_result
    future.result()
  File "/softs/rh7/conda/4.5.4/envs/pangeo_full_201909/lib/python3.7/site-packages/distributed/worker.py", line 875, in heartbeat
    metrics=await self.get_metrics(),
  File "/softs/rh7/conda/4.5.4/envs/pangeo_full_201909/lib/python3.7/site-packages/distributed/core.py", line 747, in send_recv_from_rpc
    comm = await self.pool.connect(self.addr)
  File "/softs/rh7/conda/4.5.4/envs/pangeo_full_201909/lib/python3.7/site-packages/distributed/core.py", line 874, in connect
    connection_args=self.connection_args,
  File "/softs/rh7/conda/4.5.4/envs/pangeo_full_201909/lib/python3.7/site-packages/distributed/comm/core.py", line 227, in connect
    _raise(error)
  File "/softs/rh7/conda/4.5.4/envs/pangeo_full_201909/lib/python3.7/site-packages/distributed/comm/core.py", line 204, in _raise
    raise IOError(msg)
OSError: Timed out trying to connect to 'tcp://10.120.40.97:33653' after 10 s: in <distributed.comm.tcp.TCPConnector object at 0x2aaceb693240>: ConnectionRefusedError: [Errno 111] Connection refused
tornado.application - ERROR - Exception in callback <function Worker._register_with_scheduler.<locals>.<lambda> at 0x2aace90462f0>
Traceback (most recent call last):
  File "/softs/rh7/conda/4.5.4/envs/pangeo_full_201909/lib/python3.7/site-packages/tornado/ioloop.py", line 907, in _run
    return self.callback()
  File "/softs/rh7/conda/4.5.4/envs/pangeo_full_201909/lib/python3.7/site-packages/distributed/worker.py", line 857, in <lambda>
    lambda: self.batched_stream.send({"op": "keep-alive"}),
  File "/softs/rh7/conda/4.5.4/envs/pangeo_full_201909/lib/python3.7/site-packages/distributed/batched.py", line 117, in send
    raise CommClosedError
distributed.comm.core.CommClosedError
tornado.application - ERROR - Exception in callback functools.partial(<bound method IOLoop._discard_future_result of <tornado.platform.asyncio.AsyncIOLoop object at 0x2aacd5e9eb38>>, <Task finished coro=<Worker.heartbeat() done, defined at /softs/rh7/conda/4.5.4/envs/pangeo_full_201909/lib/python3.7/site-packages/distributed/worker.py:866> exception=OSError("Timed out trying to connect to 'tcp://10.120.40.97:33653' after 10 s: in <distributed.comm.tcp.TCPConnector object at 0x2aacea7d1c88>: ConnectionRefusedError: [Errno 111] Connection refused")>)
Traceback (most recent call last):
  File "/softs/rh7/conda/4.5.4/envs/pangeo_full_201909/lib/python3.7/site-packages/distributed/comm/core.py", line 215, in connect
    quiet_exceptions=EnvironmentError,
tornado.util.TimeoutError: Timeout

During handling of the above exception, another exception occurred:

Traceback (most recent call last):
  File "/softs/rh7/conda/4.5.4/envs/pangeo_full_201909/lib/python3.7/site-packages/tornado/ioloop.py", line 743, in _run_callback
    ret = callback()
  File "/softs/rh7/conda/4.5.4/envs/pangeo_full_201909/lib/python3.7/site-packages/tornado/ioloop.py", line 767, in _discard_future_result
    future.result()
  File "/softs/rh7/conda/4.5.4/envs/pangeo_full_201909/lib/python3.7/site-packages/distributed/worker.py", line 875, in heartbeat
    metrics=await self.get_metrics(),
  File "/softs/rh7/conda/4.5.4/envs/pangeo_full_201909/lib/python3.7/site-packages/distributed/core.py", line 747, in send_recv_from_rpc
    comm = await self.pool.connect(self.addr)
  File "/softs/rh7/conda/4.5.4/envs/pangeo_full_201909/lib/python3.7/site-packages/distributed/core.py", line 874, in connect
    connection_args=self.connection_args,
  File "/softs/rh7/conda/4.5.4/envs/pangeo_full_201909/lib/python3.7/site-packages/distributed/comm/core.py", line 227, in connect
    _raise(error)
  File "/softs/rh7/conda/4.5.4/envs/pangeo_full_201909/lib/python3.7/site-packages/distributed/comm/core.py", line 204, in _raise
    raise IOError(msg)
OSError: Timed out trying to connect to 'tcp://10.120.40.97:33653' after 10 s: in <distributed.comm.tcp.TCPConnector object at 0x2aacea7d1c88>: ConnectionRefusedError: [Errno 111] Connection refused
tornado.application - ERROR - Exception in callback functools.partial(<bound method IOLoop._discard_future_result of <tornado.platform.asyncio.AsyncIOLoop object at 0x2aacd5e9eb38>>, <Task finished coro=<Worker.heartbeat() done, defined at /softs/rh7/conda/4.5.4/envs/pangeo_full_201909/lib/python3.7/site-packages/distributed/worker.py:866> exception=OSError("Timed out trying to connect to 'tcp://10.120.40.97:33653' after 10 s: in <distributed.comm.tcp.TCPConnector object at 0x2aaceb059f28>: ConnectionRefusedError: [Errno 111] Connection refused")>)
Traceback (most recent call last):
  File "/softs/rh7/conda/4.5.4/envs/pangeo_full_201909/lib/python3.7/site-packages/distributed/comm/core.py", line 215, in connect
    quiet_exceptions=EnvironmentError,
tornado.util.TimeoutError: Timeout

During handling of the above exception, another exception occurred:

Traceback (most recent call last):
  File "/softs/rh7/conda/4.5.4/envs/pangeo_full_201909/lib/python3.7/site-packages/tornado/ioloop.py", line 743, in _run_callback
    ret = callback()
  File "/softs/rh7/conda/4.5.4/envs/pangeo_full_201909/lib/python3.7/site-packages/tornado/ioloop.py", line 767, in _discard_future_result
    future.result()
  File "/softs/rh7/conda/4.5.4/envs/pangeo_full_201909/lib/python3.7/site-packages/distributed/worker.py", line 875, in heartbeat
    metrics=await self.get_metrics(),
  File "/softs/rh7/conda/4.5.4/envs/pangeo_full_201909/lib/python3.7/site-packages/distributed/core.py", line 747, in send_recv_from_rpc
    comm = await self.pool.connect(self.addr)
  File "/softs/rh7/conda/4.5.4/envs/pangeo_full_201909/lib/python3.7/site-packages/distributed/core.py", line 874, in connect
    connection_args=self.connection_args,
  File "/softs/rh7/conda/4.5.4/envs/pangeo_full_201909/lib/python3.7/site-packages/distributed/comm/core.py", line 227, in connect
    _raise(error)
  File "/softs/rh7/conda/4.5.4/envs/pangeo_full_201909/lib/python3.7/site-packages/distributed/comm/core.py", line 204, in _raise
    raise IOError(msg)
OSError: Timed out trying to connect to 'tcp://10.120.40.97:33653' after 10 s: in <distributed.comm.tcp.TCPConnector object at 0x2aaceb059f28>: ConnectionRefusedError: [Errno 111] Connection refused
tornado.application - ERROR - Exception in callback functools.partial(<bound method IOLoop._discard_future_result of <tornado.platform.asyncio.AsyncIOLoop object at 0x2aacd5e9eb38>>, <Task finished coro=<Worker.heartbeat() done, defined at /softs/rh7/conda/4.5.4/envs/pangeo_full_201909/lib/python3.7/site-packages/distributed/worker.py:866> exception=OSError("Timed out trying to connect to 'tcp://10.120.40.97:33653' after 10 s: in <distributed.comm.tcp.TCPConnector object at 0x2aaceb3ef518>: ConnectionRefusedError: [Errno 111] Connection refused")>)
Traceback (most recent call last):
  File "/softs/rh7/conda/4.5.4/envs/pangeo_full_201909/lib/python3.7/site-packages/distributed/comm/core.py", line 215, in connect
    quiet_exceptions=EnvironmentError,
tornado.util.TimeoutError: Timeout

During handling of the above exception, another exception occurred:

Traceback (most recent call last):
  File "/softs/rh7/conda/4.5.4/envs/pangeo_full_201909/lib/python3.7/site-packages/tornado/ioloop.py", line 743, in _run_callback
    ret = callback()
  File "/softs/rh7/conda/4.5.4/envs/pangeo_full_201909/lib/python3.7/site-packages/tornado/ioloop.py", line 767, in _discard_future_result
    future.result()
  File "/softs/rh7/conda/4.5.4/envs/pangeo_full_201909/lib/python3.7/site-packages/distributed/worker.py", line 875, in heartbeat
    metrics=await self.get_metrics(),
  File "/softs/rh7/conda/4.5.4/envs/pangeo_full_201909/lib/python3.7/site-packages/distributed/core.py", line 747, in send_recv_from_rpc
    comm = await self.pool.connect(self.addr)
  File "/softs/rh7/conda/4.5.4/envs/pangeo_full_201909/lib/python3.7/site-packages/distributed/core.py", line 874, in connect
    connection_args=self.connection_args,
  File "/softs/rh7/conda/4.5.4/envs/pangeo_full_201909/lib/python3.7/site-packages/distributed/comm/core.py", line 227, in connect
    _raise(error)
  File "/softs/rh7/conda/4.5.4/envs/pangeo_full_201909/lib/python3.7/site-packages/distributed/comm/core.py", line 204, in _raise
    raise IOError(msg)
OSError: Timed out trying to connect to 'tcp://10.120.40.97:33653' after 10 s: in <distributed.comm.tcp.TCPConnector object at 0x2aaceb3ef518>: ConnectionRefusedError: [Errno 111] Connection refused
tornado.application - ERROR - Exception in callback functools.partial(<bound method IOLoop._discard_future_result of <tornado.platform.asyncio.AsyncIOLoop object at 0x2aacd5e9eb38>>, <Task finished coro=<Worker.heartbeat() done, defined at /softs/rh7/conda/4.5.4/envs/pangeo_full_201909/lib/python3.7/site-packages/distributed/worker.py:866> exception=OSError("Timed out trying to connect to 'tcp://10.120.40.97:33653' after 10 s: in <distributed.comm.tcp.TCPConnector object at 0x2aaceb78b4a8>: ConnectionRefusedError: [Errno 111] Connection refused")>)
Traceback (most recent call last):
  File "/softs/rh7/conda/4.5.4/envs/pangeo_full_201909/lib/python3.7/site-packages/distributed/comm/tcp.py", line 356, in connect
    ip, port, max_buffer_size=MAX_BUFFER_SIZE, **kwargs
  File "/softs/rh7/conda/4.5.4/envs/pangeo_full_201909/lib/python3.7/site-packages/tornado/tcpclient.py", line 280, in connect
    af, addr, stream = await connector.start(connect_timeout=timeout)
  File "/softs/rh7/conda/4.5.4/envs/pangeo_full_201909/lib/python3.7/site-packages/tornado/tcpclient.py", line 143, in on_connect_done
    stream = future.result()
tornado.iostream.StreamClosedError: Stream is closed

During handling of the above exception, another exception occurred:

Traceback (most recent call last):
  File "/softs/rh7/conda/4.5.4/envs/pangeo_full_201909/lib/python3.7/site-packages/distributed/comm/core.py", line 215, in connect
    quiet_exceptions=EnvironmentError,
  File "/softs/rh7/conda/4.5.4/envs/pangeo_full_201909/lib/python3.7/site-packages/distributed/comm/tcp.py", line 368, in connect
    convert_stream_closed_error(self, e)
  File "/softs/rh7/conda/4.5.4/envs/pangeo_full_201909/lib/python3.7/site-packages/distributed/comm/tcp.py", line 138, in convert_stream_closed_error
    raise CommClosedError("in %s: %s: %s" % (obj, exc.__class__.__name__, exc))
distributed.comm.core.CommClosedError: in <distributed.comm.tcp.TCPConnector object at 0x2aaceb78b4a8>: ConnectionRefusedError: [Errno 111] Connection refused

During handling of the above exception, another exception occurred:

Traceback (most recent call last):
  File "/softs/rh7/conda/4.5.4/envs/pangeo_full_201909/lib/python3.7/site-packages/tornado/ioloop.py", line 743, in _run_callback
    ret = callback()
  File "/softs/rh7/conda/4.5.4/envs/pangeo_full_201909/lib/python3.7/site-packages/tornado/ioloop.py", line 767, in _discard_future_result
    future.result()
  File "/softs/rh7/conda/4.5.4/envs/pangeo_full_201909/lib/python3.7/site-packages/distributed/worker.py", line 875, in heartbeat
    metrics=await self.get_metrics(),
  File "/softs/rh7/conda/4.5.4/envs/pangeo_full_201909/lib/python3.7/site-packages/distributed/core.py", line 747, in send_recv_from_rpc
    comm = await self.pool.connect(self.addr)
  File "/softs/rh7/conda/4.5.4/envs/pangeo_full_201909/lib/python3.7/site-packages/distributed/core.py", line 874, in connect
    connection_args=self.connection_args,
  File "/softs/rh7/conda/4.5.4/envs/pangeo_full_201909/lib/python3.7/site-packages/distributed/comm/core.py", line 225, in connect
    _raise(error)
  File "/softs/rh7/conda/4.5.4/envs/pangeo_full_201909/lib/python3.7/site-packages/distributed/comm/core.py", line 204, in _raise
    raise IOError(msg)
OSError: Timed out trying to connect to 'tcp://10.120.40.97:33653' after 10 s: in <distributed.comm.tcp.TCPConnector object at 0x2aaceb78b4a8>: ConnectionRefusedError: [Errno 111] Connection refused
tornado.application - ERROR - Exception in callback functools.partial(<bound method IOLoop._discard_future_result of <tornado.platform.asyncio.AsyncIOLoop object at 0x2aacd5e9eb38>>, <Task finished coro=<Worker.heartbeat() done, defined at /softs/rh7/conda/4.5.4/envs/pangeo_full_201909/lib/python3.7/site-packages/distributed/worker.py:866> exception=OSError("Timed out trying to connect to 'tcp://10.120.40.97:33653' after 10 s: in <distributed.comm.tcp.TCPConnector object at 0x2aaceadf2a58>: ConnectionRefusedError: [Errno 111] Connection refused")>)
Traceback (most recent call last):
  File "/softs/rh7/conda/4.5.4/envs/pangeo_full_201909/lib/python3.7/site-packages/distributed/comm/core.py", line 215, in connect
    quiet_exceptions=EnvironmentError,
tornado.util.TimeoutError: Timeout

During handling of the above exception, another exception occurred:

Traceback (most recent call last):
  File "/softs/rh7/conda/4.5.4/envs/pangeo_full_201909/lib/python3.7/site-packages/tornado/ioloop.py", line 743, in _run_callback
    ret = callback()
  File "/softs/rh7/conda/4.5.4/envs/pangeo_full_201909/lib/python3.7/site-packages/tornado/ioloop.py", line 767, in _discard_future_result
    future.result()
  File "/softs/rh7/conda/4.5.4/envs/pangeo_full_201909/lib/python3.7/site-packages/distributed/worker.py", line 875, in heartbeat
    metrics=await self.get_metrics(),
  File "/softs/rh7/conda/4.5.4/envs/pangeo_full_201909/lib/python3.7/site-packages/distributed/core.py", line 747, in send_recv_from_rpc
    comm = await self.pool.connect(self.addr)
  File "/softs/rh7/conda/4.5.4/envs/pangeo_full_201909/lib/python3.7/site-packages/distributed/core.py", line 874, in connect
    connection_args=self.connection_args,
  File "/softs/rh7/conda/4.5.4/envs/pangeo_full_201909/lib/python3.7/site-packages/distributed/comm/core.py", line 227, in connect
    _raise(error)
  File "/softs/rh7/conda/4.5.4/envs/pangeo_full_201909/lib/python3.7/site-packages/distributed/comm/core.py", line 204, in _raise
    raise IOError(msg)
OSError: Timed out trying to connect to 'tcp://10.120.40.97:33653' after 10 s: in <distributed.comm.tcp.TCPConnector object at 0x2aaceadf2a58>: ConnectionRefusedError: [Errno 111] Connection refused
tornado.application - ERROR - Exception in callback <function Worker._register_with_scheduler.<locals>.<lambda> at 0x2aace90462f0>
Traceback (most recent call last):
  File "/softs/rh7/conda/4.5.4/envs/pangeo_full_201909/lib/python3.7/site-packages/tornado/ioloop.py", line 907, in _run
    return self.callback()
  File "/softs/rh7/conda/4.5.4/envs/pangeo_full_201909/lib/python3.7/site-packages/distributed/worker.py", line 857, in <lambda>
    lambda: self.batched_stream.send({"op": "keep-alive"}),
  File "/softs/rh7/conda/4.5.4/envs/pangeo_full_201909/lib/python3.7/site-packages/distributed/batched.py", line 117, in send
    raise CommClosedError
distributed.comm.core.CommClosedError
tornado.application - ERROR - Exception in callback functools.partial(<bound method IOLoop._discard_future_result of <tornado.platform.asyncio.AsyncIOLoop object at 0x2aacd5e9eb38>>, <Task finished coro=<Worker.heartbeat() done, defined at /softs/rh7/conda/4.5.4/envs/pangeo_full_201909/lib/python3.7/site-packages/distributed/worker.py:866> exception=OSError("Timed out trying to connect to 'tcp://10.120.40.97:33653' after 10 s: in <distributed.comm.tcp.TCPConnector object at 0x2aaceb25ae80>: ConnectionRefusedError: [Errno 111] Connection refused")>)
Traceback (most recent call last):
  File "/softs/rh7/conda/4.5.4/envs/pangeo_full_201909/lib/python3.7/site-packages/distributed/comm/core.py", line 215, in connect
    quiet_exceptions=EnvironmentError,
tornado.util.TimeoutError: Timeout

During handling of the above exception, another exception occurred:

Traceback (most recent call last):
  File "/softs/rh7/conda/4.5.4/envs/pangeo_full_201909/lib/python3.7/site-packages/tornado/ioloop.py", line 743, in _run_callback
    ret = callback()
  File "/softs/rh7/conda/4.5.4/envs/pangeo_full_201909/lib/python3.7/site-packages/tornado/ioloop.py", line 767, in _discard_future_result
    future.result()
  File "/softs/rh7/conda/4.5.4/envs/pangeo_full_201909/lib/python3.7/site-packages/distributed/worker.py", line 875, in heartbeat
    metrics=await self.get_metrics(),
  File "/softs/rh7/conda/4.5.4/envs/pangeo_full_201909/lib/python3.7/site-packages/distributed/core.py", line 747, in send_recv_from_rpc
    comm = await self.pool.connect(self.addr)
  File "/softs/rh7/conda/4.5.4/envs/pangeo_full_201909/lib/python3.7/site-packages/distributed/core.py", line 874, in connect
    connection_args=self.connection_args,
  File "/softs/rh7/conda/4.5.4/envs/pangeo_full_201909/lib/python3.7/site-packages/distributed/comm/core.py", line 227, in connect
    _raise(error)
  File "/softs/rh7/conda/4.5.4/envs/pangeo_full_201909/lib/python3.7/site-packages/distributed/comm/core.py", line 204, in _raise
    raise IOError(msg)
OSError: Timed out trying to connect to 'tcp://10.120.40.97:33653' after 10 s: in <distributed.comm.tcp.TCPConnector object at 0x2aaceb25ae80>: ConnectionRefusedError: [Errno 111] Connection refused
tornado.application - ERROR - Exception in callback functools.partial(<bound method IOLoop._discard_future_result of <tornado.platform.asyncio.AsyncIOLoop object at 0x2aacd5e9eb38>>, <Task finished coro=<Worker.heartbeat() done, defined at /softs/rh7/conda/4.5.4/envs/pangeo_full_201909/lib/python3.7/site-packages/distributed/worker.py:866> exception=OSError("Timed out trying to connect to 'tcp://10.120.40.97:33653' after 10 s: in <distributed.comm.tcp.TCPConnector object at 0x2aace94484a8>: ConnectionRefusedError: [Errno 111] Connection refused")>)
Traceback (most recent call last):
  File "/softs/rh7/conda/4.5.4/envs/pangeo_full_201909/lib/python3.7/site-packages/distributed/comm/core.py", line 215, in connect
    quiet_exceptions=EnvironmentError,
tornado.util.TimeoutError: Timeout

During handling of the above exception, another exception occurred:

Traceback (most recent call last):
  File "/softs/rh7/conda/4.5.4/envs/pangeo_full_201909/lib/python3.7/site-packages/tornado/ioloop.py", line 743, in _run_callback
    ret = callback()
  File "/softs/rh7/conda/4.5.4/envs/pangeo_full_201909/lib/python3.7/site-packages/tornado/ioloop.py", line 767, in _discard_future_result
    future.result()
  File "/softs/rh7/conda/4.5.4/envs/pangeo_full_201909/lib/python3.7/site-packages/distributed/worker.py", line 875, in heartbeat
    metrics=await self.get_metrics(),
  File "/softs/rh7/conda/4.5.4/envs/pangeo_full_201909/lib/python3.7/site-packages/distributed/core.py", line 747, in send_recv_from_rpc
    comm = await self.pool.connect(self.addr)
  File "/softs/rh7/conda/4.5.4/envs/pangeo_full_201909/lib/python3.7/site-packages/distributed/core.py", line 874, in connect
    connection_args=self.connection_args,
  File "/softs/rh7/conda/4.5.4/envs/pangeo_full_201909/lib/python3.7/site-packages/distributed/comm/core.py", line 227, in connect
    _raise(error)
  File "/softs/rh7/conda/4.5.4/envs/pangeo_full_201909/lib/python3.7/site-packages/distributed/comm/core.py", line 204, in _raise
    raise IOError(msg)
OSError: Timed out trying to connect to 'tcp://10.120.40.97:33653' after 10 s: in <distributed.comm.tcp.TCPConnector object at 0x2aace94484a8>: ConnectionRefusedError: [Errno 111] Connection refused
tornado.application - ERROR - Exception in callback functools.partial(<bound method IOLoop._discard_future_result of <tornado.platform.asyncio.AsyncIOLoop object at 0x2aacd5e9eb38>>, <Task finished coro=<Worker.heartbeat() done, defined at /softs/rh7/conda/4.5.4/envs/pangeo_full_201909/lib/python3.7/site-packages/distributed/worker.py:866> exception=OSError("Timed out trying to connect to 'tcp://10.120.40.97:33653' after 10 s: in <distributed.comm.tcp.TCPConnector object at 0x2aaceb25aa90>: ConnectionRefusedError: [Errno 111] Connection refused")>)
Traceback (most recent call last):
  File "/softs/rh7/conda/4.5.4/envs/pangeo_full_201909/lib/python3.7/site-packages/distributed/comm/core.py", line 215, in connect
    quiet_exceptions=EnvironmentError,
tornado.util.TimeoutError: Timeout

During handling of the above exception, another exception occurred:

Traceback (most recent call last):
  File "/softs/rh7/conda/4.5.4/envs/pangeo_full_201909/lib/python3.7/site-packages/tornado/ioloop.py", line 743, in _run_callback
    ret = callback()
  File "/softs/rh7/conda/4.5.4/envs/pangeo_full_201909/lib/python3.7/site-packages/tornado/ioloop.py", line 767, in _discard_future_result
    future.result()
  File "/softs/rh7/conda/4.5.4/envs/pangeo_full_201909/lib/python3.7/site-packages/distributed/worker.py", line 875, in heartbeat
    metrics=await self.get_metrics(),
  File "/softs/rh7/conda/4.5.4/envs/pangeo_full_201909/lib/python3.7/site-packages/distributed/core.py", line 747, in send_recv_from_rpc
    comm = await self.pool.connect(self.addr)
  File "/softs/rh7/conda/4.5.4/envs/pangeo_full_201909/lib/python3.7/site-packages/distributed/core.py", line 874, in connect
    connection_args=self.connection_args,
  File "/softs/rh7/conda/4.5.4/envs/pangeo_full_201909/lib/python3.7/site-packages/distributed/comm/core.py", line 227, in connect
    _raise(error)
  File "/softs/rh7/conda/4.5.4/envs/pangeo_full_201909/lib/python3.7/site-packages/distributed/comm/core.py", line 204, in _raise
    raise IOError(msg)
OSError: Timed out trying to connect to 'tcp://10.120.40.97:33653' after 10 s: in <distributed.comm.tcp.TCPConnector object at 0x2aaceb25aa90>: ConnectionRefusedError: [Errno 111] Connection refused
tornado.application - ERROR - Exception in callback functools.partial(<bound method IOLoop._discard_future_result of <tornado.platform.asyncio.AsyncIOLoop object at 0x2aacd5e9eb38>>, <Task finished coro=<Worker.heartbeat() done, defined at /softs/rh7/conda/4.5.4/envs/pangeo_full_201909/lib/python3.7/site-packages/distributed/worker.py:866> exception=OSError("Timed out trying to connect to 'tcp://10.120.40.97:33653' after 10 s: in <distributed.comm.tcp.TCPConnector object at 0x2aaceada46d8>: ConnectionRefusedError: [Errno 111] Connection refused")>)
Traceback (most recent call last):
  File "/softs/rh7/conda/4.5.4/envs/pangeo_full_201909/lib/python3.7/site-packages/distributed/comm/core.py", line 215, in connect
    quiet_exceptions=EnvironmentError,
tornado.util.TimeoutError: Timeout

During handling of the above exception, another exception occurred:

Traceback (most recent call last):
  File "/softs/rh7/conda/4.5.4/envs/pangeo_full_201909/lib/python3.7/site-packages/tornado/ioloop.py", line 743, in _run_callback
    ret = callback()
  File "/softs/rh7/conda/4.5.4/envs/pangeo_full_201909/lib/python3.7/site-packages/tornado/ioloop.py", line 767, in _discard_future_result
    future.result()
  File "/softs/rh7/conda/4.5.4/envs/pangeo_full_201909/lib/python3.7/site-packages/distributed/worker.py", line 875, in heartbeat
    metrics=await self.get_metrics(),
  File "/softs/rh7/conda/4.5.4/envs/pangeo_full_201909/lib/python3.7/site-packages/distributed/core.py", line 747, in send_recv_from_rpc
    comm = await self.pool.connect(self.addr)
  File "/softs/rh7/conda/4.5.4/envs/pangeo_full_201909/lib/python3.7/site-packages/distributed/core.py", line 874, in connect
    connection_args=self.connection_args,
  File "/softs/rh7/conda/4.5.4/envs/pangeo_full_201909/lib/python3.7/site-packages/distributed/comm/core.py", line 227, in connect
    _raise(error)
  File "/softs/rh7/conda/4.5.4/envs/pangeo_full_201909/lib/python3.7/site-packages/distributed/comm/core.py", line 204, in _raise
    raise IOError(msg)
OSError: Timed out trying to connect to 'tcp://10.120.40.97:33653' after 10 s: in <distributed.comm.tcp.TCPConnector object at 0x2aaceada46d8>: ConnectionRefusedError: [Errno 111] Connection refused
tornado.application - ERROR - Exception in callback functools.partial(<bound method IOLoop._discard_future_result of <tornado.platform.asyncio.AsyncIOLoop object at 0x2aacd5e9eb38>>, <Task finished coro=<Worker.heartbeat() done, defined at /softs/rh7/conda/4.5.4/envs/pangeo_full_201909/lib/python3.7/site-packages/distributed/worker.py:866> exception=OSError("Timed out trying to connect to 'tcp://10.120.40.97:33653' after 10 s: in <distributed.comm.tcp.TCPConnector object at 0x2aacea7d1b00>: ConnectionRefusedError: [Errno 111] Connection refused")>)
Traceback (most recent call last):
  File "/softs/rh7/conda/4.5.4/envs/pangeo_full_201909/lib/python3.7/site-packages/distributed/comm/core.py", line 215, in connect
    quiet_exceptions=EnvironmentError,
tornado.util.TimeoutError: Timeout

During handling of the above exception, another exception occurred:

Traceback (most recent call last):
  File "/softs/rh7/conda/4.5.4/envs/pangeo_full_201909/lib/python3.7/site-packages/tornado/ioloop.py", line 743, in _run_callback
    ret = callback()
  File "/softs/rh7/conda/4.5.4/envs/pangeo_full_201909/lib/python3.7/site-packages/tornado/ioloop.py", line 767, in _discard_future_result
    future.result()
  File "/softs/rh7/conda/4.5.4/envs/pangeo_full_201909/lib/python3.7/site-packages/distributed/worker.py", line 875, in heartbeat
    metrics=await self.get_metrics(),
  File "/softs/rh7/conda/4.5.4/envs/pangeo_full_201909/lib/python3.7/site-packages/distributed/core.py", line 747, in send_recv_from_rpc
    comm = await self.pool.connect(self.addr)
  File "/softs/rh7/conda/4.5.4/envs/pangeo_full_201909/lib/python3.7/site-packages/distributed/core.py", line 874, in connect
    connection_args=self.connection_args,
  File "/softs/rh7/conda/4.5.4/envs/pangeo_full_201909/lib/python3.7/site-packages/distributed/comm/core.py", line 227, in connect
    _raise(error)
  File "/softs/rh7/conda/4.5.4/envs/pangeo_full_201909/lib/python3.7/site-packages/distributed/comm/core.py", line 204, in _raise
    raise IOError(msg)
OSError: Timed out trying to connect to 'tcp://10.120.40.97:33653' after 10 s: in <distributed.comm.tcp.TCPConnector object at 0x2aacea7d1b00>: ConnectionRefusedError: [Errno 111] Connection refused
tornado.application - ERROR - Exception in callback functools.partial(<bound method IOLoop._discard_future_result of <tornado.platform.asyncio.AsyncIOLoop object at 0x2aacd5e9eb38>>, <Task finished coro=<Worker.heartbeat() done, defined at /softs/rh7/conda/4.5.4/envs/pangeo_full_201909/lib/python3.7/site-packages/distributed/worker.py:866> exception=OSError("Timed out trying to connect to 'tcp://10.120.40.97:33653' after 10 s: in <distributed.comm.tcp.TCPConnector object at 0x2aaceb78b198>: ConnectionRefusedError: [Errno 111] Connection refused")>)
Traceback (most recent call last):
  File "/softs/rh7/conda/4.5.4/envs/pangeo_full_201909/lib/python3.7/site-packages/distributed/comm/core.py", line 215, in connect
    quiet_exceptions=EnvironmentError,
tornado.util.TimeoutError: Timeout

During handling of the above exception, another exception occurred:

Traceback (most recent call last):
  File "/softs/rh7/conda/4.5.4/envs/pangeo_full_201909/lib/python3.7/site-packages/tornado/ioloop.py", line 743, in _run_callback
    ret = callback()
  File "/softs/rh7/conda/4.5.4/envs/pangeo_full_201909/lib/python3.7/site-packages/tornado/ioloop.py", line 767, in _discard_future_result
    future.result()
  File "/softs/rh7/conda/4.5.4/envs/pangeo_full_201909/lib/python3.7/site-packages/distributed/worker.py", line 875, in heartbeat
    metrics=await self.get_metrics(),
  File "/softs/rh7/conda/4.5.4/envs/pangeo_full_201909/lib/python3.7/site-packages/distributed/core.py", line 747, in send_recv_from_rpc
    comm = await self.pool.connect(self.addr)
  File "/softs/rh7/conda/4.5.4/envs/pangeo_full_201909/lib/python3.7/site-packages/distributed/core.py", line 874, in connect
    connection_args=self.connection_args,
  File "/softs/rh7/conda/4.5.4/envs/pangeo_full_201909/lib/python3.7/site-packages/distributed/comm/core.py", line 227, in connect
    _raise(error)
  File "/softs/rh7/conda/4.5.4/envs/pangeo_full_201909/lib/python3.7/site-packages/distributed/comm/core.py", line 204, in _raise
    raise IOError(msg)
OSError: Timed out trying to connect to 'tcp://10.120.40.97:33653' after 10 s: in <distributed.comm.tcp.TCPConnector object at 0x2aaceb78b198>: ConnectionRefusedError: [Errno 111] Connection refused
tornado.application - ERROR - Exception in callback <function Worker._register_with_scheduler.<locals>.<lambda> at 0x2aace90462f0>
Traceback (most recent call last):
  File "/softs/rh7/conda/4.5.4/envs/pangeo_full_201909/lib/python3.7/site-packages/tornado/ioloop.py", line 907, in _run
    return self.callback()
  File "/softs/rh7/conda/4.5.4/envs/pangeo_full_201909/lib/python3.7/site-packages/distributed/worker.py", line 857, in <lambda>
    lambda: self.batched_stream.send({"op": "keep-alive"}),
  File "/softs/rh7/conda/4.5.4/envs/pangeo_full_201909/lib/python3.7/site-packages/distributed/batched.py", line 117, in send
    raise CommClosedError
distributed.comm.core.CommClosedError
tornado.application - ERROR - Exception in callback functools.partial(<bound method IOLoop._discard_future_result of <tornado.platform.asyncio.AsyncIOLoop object at 0x2aacd5e9eb38>>, <Task finished coro=<Worker.heartbeat() done, defined at /softs/rh7/conda/4.5.4/envs/pangeo_full_201909/lib/python3.7/site-packages/distributed/worker.py:866> exception=OSError("Timed out trying to connect to 'tcp://10.120.40.97:33653' after 10 s: in <distributed.comm.tcp.TCPConnector object at 0x2aaceb8540f0>: ConnectionRefusedError: [Errno 111] Connection refused")>)
Traceback (most recent call last):
  File "/softs/rh7/conda/4.5.4/envs/pangeo_full_201909/lib/python3.7/site-packages/distributed/comm/core.py", line 215, in connect
    quiet_exceptions=EnvironmentError,
tornado.util.TimeoutError: Timeout

During handling of the above exception, another exception occurred:

Traceback (most recent call last):
  File "/softs/rh7/conda/4.5.4/envs/pangeo_full_201909/lib/python3.7/site-packages/tornado/ioloop.py", line 743, in _run_callback
    ret = callback()
  File "/softs/rh7/conda/4.5.4/envs/pangeo_full_201909/lib/python3.7/site-packages/tornado/ioloop.py", line 767, in _discard_future_result
    future.result()
  File "/softs/rh7/conda/4.5.4/envs/pangeo_full_201909/lib/python3.7/site-packages/distributed/worker.py", line 875, in heartbeat
    metrics=await self.get_metrics(),
  File "/softs/rh7/conda/4.5.4/envs/pangeo_full_201909/lib/python3.7/site-packages/distributed/core.py", line 747, in send_recv_from_rpc
    comm = await self.pool.connect(self.addr)
  File "/softs/rh7/conda/4.5.4/envs/pangeo_full_201909/lib/python3.7/site-packages/distributed/core.py", line 874, in connect
    connection_args=self.connection_args,
  File "/softs/rh7/conda/4.5.4/envs/pangeo_full_201909/lib/python3.7/site-packages/distributed/comm/core.py", line 227, in connect
    _raise(error)
  File "/softs/rh7/conda/4.5.4/envs/pangeo_full_201909/lib/python3.7/site-packages/distributed/comm/core.py", line 204, in _raise
    raise IOError(msg)
OSError: Timed out trying to connect to 'tcp://10.120.40.97:33653' after 10 s: in <distributed.comm.tcp.TCPConnector object at 0x2aaceb8540f0>: ConnectionRefusedError: [Errno 111] Connection refused
tornado.application - ERROR - Exception in callback functools.partial(<bound method IOLoop._discard_future_result of <tornado.platform.asyncio.AsyncIOLoop object at 0x2aacd5e9eb38>>, <Task finished coro=<Worker.heartbeat() done, defined at /softs/rh7/conda/4.5.4/envs/pangeo_full_201909/lib/python3.7/site-packages/distributed/worker.py:866> exception=OSError("Timed out trying to connect to 'tcp://10.120.40.97:33653' after 10 s: in <distributed.comm.tcp.TCPConnector object at 0x2aaceb78b128>: ConnectionRefusedError: [Errno 111] Connection refused")>)
Traceback (most recent call last):
  File "/softs/rh7/conda/4.5.4/envs/pangeo_full_201909/lib/python3.7/site-packages/distributed/comm/core.py", line 215, in connect
    quiet_exceptions=EnvironmentError,
tornado.util.TimeoutError: Timeout

During handling of the above exception, another exception occurred:

Traceback (most recent call last):
  File "/softs/rh7/conda/4.5.4/envs/pangeo_full_201909/lib/python3.7/site-packages/tornado/ioloop.py", line 743, in _run_callback
    ret = callback()
  File "/softs/rh7/conda/4.5.4/envs/pangeo_full_201909/lib/python3.7/site-packages/tornado/ioloop.py", line 767, in _discard_future_result
    future.result()
  File "/softs/rh7/conda/4.5.4/envs/pangeo_full_201909/lib/python3.7/site-packages/distributed/worker.py", line 875, in heartbeat
    metrics=await self.get_metrics(),
  File "/softs/rh7/conda/4.5.4/envs/pangeo_full_201909/lib/python3.7/site-packages/distributed/core.py", line 747, in send_recv_from_rpc
    comm = await self.pool.connect(self.addr)
  File "/softs/rh7/conda/4.5.4/envs/pangeo_full_201909/lib/python3.7/site-packages/distributed/core.py", line 874, in connect
    connection_args=self.connection_args,
  File "/softs/rh7/conda/4.5.4/envs/pangeo_full_201909/lib/python3.7/site-packages/distributed/comm/core.py", line 227, in connect
    _raise(error)
  File "/softs/rh7/conda/4.5.4/envs/pangeo_full_201909/lib/python3.7/site-packages/distributed/comm/core.py", line 204, in _raise
    raise IOError(msg)
OSError: Timed out trying to connect to 'tcp://10.120.40.97:33653' after 10 s: in <distributed.comm.tcp.TCPConnector object at 0x2aaceb78b128>: ConnectionRefusedError: [Errno 111] Connection refused
tornado.application - ERROR - Exception in callback functools.partial(<bound method IOLoop._discard_future_result of <tornado.platform.asyncio.AsyncIOLoop object at 0x2aacd5e9eb38>>, <Task finished coro=<Worker.heartbeat() done, defined at /softs/rh7/conda/4.5.4/envs/pangeo_full_201909/lib/python3.7/site-packages/distributed/worker.py:866> exception=OSError("Timed out trying to connect to 'tcp://10.120.40.97:33653' after 10 s: in <distributed.comm.tcp.TCPConnector object at 0x2aaceb3312e8>: ConnectionRefusedError: [Errno 111] Connection refused")>)
Traceback (most recent call last):
  File "/softs/rh7/conda/4.5.4/envs/pangeo_full_201909/lib/python3.7/site-packages/distributed/comm/core.py", line 215, in connect
    quiet_exceptions=EnvironmentError,
tornado.util.TimeoutError: Timeout

During handling of the above exception, another exception occurred:

Traceback (most recent call last):
  File "/softs/rh7/conda/4.5.4/envs/pangeo_full_201909/lib/python3.7/site-packages/tornado/ioloop.py", line 743, in _run_callback
    ret = callback()
  File "/softs/rh7/conda/4.5.4/envs/pangeo_full_201909/lib/python3.7/site-packages/tornado/ioloop.py", line 767, in _discard_future_result
    future.result()
  File "/softs/rh7/conda/4.5.4/envs/pangeo_full_201909/lib/python3.7/site-packages/distributed/worker.py", line 875, in heartbeat
    metrics=await self.get_metrics(),
  File "/softs/rh7/conda/4.5.4/envs/pangeo_full_201909/lib/python3.7/site-packages/distributed/core.py", line 747, in send_recv_from_rpc
    comm = await self.pool.connect(self.addr)
  File "/softs/rh7/conda/4.5.4/envs/pangeo_full_201909/lib/python3.7/site-packages/distributed/core.py", line 874, in connect
    connection_args=self.connection_args,
  File "/softs/rh7/conda/4.5.4/envs/pangeo_full_201909/lib/python3.7/site-packages/distributed/comm/core.py", line 227, in connect
    _raise(error)
  File "/softs/rh7/conda/4.5.4/envs/pangeo_full_201909/lib/python3.7/site-packages/distributed/comm/core.py", line 204, in _raise
    raise IOError(msg)
OSError: Timed out trying to connect to 'tcp://10.120.40.97:33653' after 10 s: in <distributed.comm.tcp.TCPConnector object at 0x2aaceb3312e8>: ConnectionRefusedError: [Errno 111] Connection refused
tornado.application - ERROR - Exception in callback functools.partial(<bound method IOLoop._discard_future_result of <tornado.platform.asyncio.AsyncIOLoop object at 0x2aacd5e9eb38>>, <Task finished coro=<Worker.heartbeat() done, defined at /softs/rh7/conda/4.5.4/envs/pangeo_full_201909/lib/python3.7/site-packages/distributed/worker.py:866> exception=OSError("Timed out trying to connect to 'tcp://10.120.40.97:33653' after 10 s: in <distributed.comm.tcp.TCPConnector object at 0x2aaceb059748>: ConnectionRefusedError: [Errno 111] Connection refused")>)
Traceback (most recent call last):
  File "/softs/rh7/conda/4.5.4/envs/pangeo_full_201909/lib/python3.7/site-packages/distributed/comm/core.py", line 215, in connect
    quiet_exceptions=EnvironmentError,
tornado.util.TimeoutError: Timeout

During handling of the above exception, another exception occurred:

Traceback (most recent call last):
  File "/softs/rh7/conda/4.5.4/envs/pangeo_full_201909/lib/python3.7/site-packages/tornado/ioloop.py", line 743, in _run_callback
    ret = callback()
  File "/softs/rh7/conda/4.5.4/envs/pangeo_full_201909/lib/python3.7/site-packages/tornado/ioloop.py", line 767, in _discard_future_result
    future.result()
  File "/softs/rh7/conda/4.5.4/envs/pangeo_full_201909/lib/python3.7/site-packages/distributed/worker.py", line 875, in heartbeat
    metrics=await self.get_metrics(),
  File "/softs/rh7/conda/4.5.4/envs/pangeo_full_201909/lib/python3.7/site-packages/distributed/core.py", line 747, in send_recv_from_rpc
    comm = await self.pool.connect(self.addr)
  File "/softs/rh7/conda/4.5.4/envs/pangeo_full_201909/lib/python3.7/site-packages/distributed/core.py", line 874, in connect
    connection_args=self.connection_args,
  File "/softs/rh7/conda/4.5.4/envs/pangeo_full_201909/lib/python3.7/site-packages/distributed/comm/core.py", line 227, in connect
    _raise(error)
  File "/softs/rh7/conda/4.5.4/envs/pangeo_full_201909/lib/python3.7/site-packages/distributed/comm/core.py", line 204, in _raise
    raise IOError(msg)
OSError: Timed out trying to connect to 'tcp://10.120.40.97:33653' after 10 s: in <distributed.comm.tcp.TCPConnector object at 0x2aaceb059748>: ConnectionRefusedError: [Errno 111] Connection refused
tornado.application - ERROR - Exception in callback functools.partial(<bound method IOLoop._discard_future_result of <tornado.platform.asyncio.AsyncIOLoop object at 0x2aacd5e9eb38>>, <Task finished coro=<Worker.heartbeat() done, defined at /softs/rh7/conda/4.5.4/envs/pangeo_full_201909/lib/python3.7/site-packages/distributed/worker.py:866> exception=OSError("Timed out trying to connect to 'tcp://10.120.40.97:33653' after 10 s: in <distributed.comm.tcp.TCPConnector object at 0x2aaceada45f8>: ConnectionRefusedError: [Errno 111] Connection refused")>)
Traceback (most recent call last):
  File "/softs/rh7/conda/4.5.4/envs/pangeo_full_201909/lib/python3.7/site-packages/distributed/comm/core.py", line 215, in connect
    quiet_exceptions=EnvironmentError,
tornado.util.TimeoutError: Timeout

During handling of the above exception, another exception occurred:

Traceback (most recent call last):
  File "/softs/rh7/conda/4.5.4/envs/pangeo_full_201909/lib/python3.7/site-packages/tornado/ioloop.py", line 743, in _run_callback
    ret = callback()
  File "/softs/rh7/conda/4.5.4/envs/pangeo_full_201909/lib/python3.7/site-packages/tornado/ioloop.py", line 767, in _discard_future_result
    future.result()
  File "/softs/rh7/conda/4.5.4/envs/pangeo_full_201909/lib/python3.7/site-packages/distributed/worker.py", line 875, in heartbeat
    metrics=await self.get_metrics(),
  File "/softs/rh7/conda/4.5.4/envs/pangeo_full_201909/lib/python3.7/site-packages/distributed/core.py", line 747, in send_recv_from_rpc
    comm = await self.pool.connect(self.addr)
  File "/softs/rh7/conda/4.5.4/envs/pangeo_full_201909/lib/python3.7/site-packages/distributed/core.py", line 874, in connect
    connection_args=self.connection_args,
  File "/softs/rh7/conda/4.5.4/envs/pangeo_full_201909/lib/python3.7/site-packages/distributed/comm/core.py", line 227, in connect
    _raise(error)
  File "/softs/rh7/conda/4.5.4/envs/pangeo_full_201909/lib/python3.7/site-packages/distributed/comm/core.py", line 204, in _raise
    raise IOError(msg)
OSError: Timed out trying to connect to 'tcp://10.120.40.97:33653' after 10 s: in <distributed.comm.tcp.TCPConnector object at 0x2aaceada45f8>: ConnectionRefusedError: [Errno 111] Connection refused
tornado.application - ERROR - Exception in callback <function Worker._register_with_scheduler.<locals>.<lambda> at 0x2aace90462f0>
Traceback (most recent call last):
  File "/softs/rh7/conda/4.5.4/envs/pangeo_full_201909/lib/python3.7/site-packages/tornado/ioloop.py", line 907, in _run
    return self.callback()
  File "/softs/rh7/conda/4.5.4/envs/pangeo_full_201909/lib/python3.7/site-packages/distributed/worker.py", line 857, in <lambda>
    lambda: self.batched_stream.send({"op": "keep-alive"}),
  File "/softs/rh7/conda/4.5.4/envs/pangeo_full_201909/lib/python3.7/site-packages/distributed/batched.py", line 117, in send
    raise CommClosedError
distributed.comm.core.CommClosedError
tornado.application - ERROR - Exception in callback functools.partial(<bound method IOLoop._discard_future_result of <tornado.platform.asyncio.AsyncIOLoop object at 0x2aacd5e9eb38>>, <Task finished coro=<Worker.heartbeat() done, defined at /softs/rh7/conda/4.5.4/envs/pangeo_full_201909/lib/python3.7/site-packages/distributed/worker.py:866> exception=OSError("Timed out trying to connect to 'tcp://10.120.40.97:33653' after 10 s: in <distributed.comm.tcp.TCPConnector object at 0x2aacebcab8d0>: ConnectionRefusedError: [Errno 111] Connection refused")>)
Traceback (most recent call last):
  File "/softs/rh7/conda/4.5.4/envs/pangeo_full_201909/lib/python3.7/site-packages/distributed/comm/core.py", line 215, in connect
    quiet_exceptions=EnvironmentError,
tornado.util.TimeoutError: Timeout

During handling of the above exception, another exception occurred:

Traceback (most recent call last):
  File "/softs/rh7/conda/4.5.4/envs/pangeo_full_201909/lib/python3.7/site-packages/tornado/ioloop.py", line 743, in _run_callback
    ret = callback()
  File "/softs/rh7/conda/4.5.4/envs/pangeo_full_201909/lib/python3.7/site-packages/tornado/ioloop.py", line 767, in _discard_future_result
    future.result()
  File "/softs/rh7/conda/4.5.4/envs/pangeo_full_201909/lib/python3.7/site-packages/distributed/worker.py", line 875, in heartbeat
    metrics=await self.get_metrics(),
  File "/softs/rh7/conda/4.5.4/envs/pangeo_full_201909/lib/python3.7/site-packages/distributed/core.py", line 747, in send_recv_from_rpc
    comm = await self.pool.connect(self.addr)
  File "/softs/rh7/conda/4.5.4/envs/pangeo_full_201909/lib/python3.7/site-packages/distributed/core.py", line 874, in connect
    connection_args=self.connection_args,
  File "/softs/rh7/conda/4.5.4/envs/pangeo_full_201909/lib/python3.7/site-packages/distributed/comm/core.py", line 227, in connect
    _raise(error)
  File "/softs/rh7/conda/4.5.4/envs/pangeo_full_201909/lib/python3.7/site-packages/distributed/comm/core.py", line 204, in _raise
    raise IOError(msg)
OSError: Timed out trying to connect to 'tcp://10.120.40.97:33653' after 10 s: in <distributed.comm.tcp.TCPConnector object at 0x2aacebcab8d0>: ConnectionRefusedError: [Errno 111] Connection refused
tornado.application - ERROR - Exception in callback functools.partial(<bound method IOLoop._discard_future_result of <tornado.platform.asyncio.AsyncIOLoop object at 0x2aacd5e9eb38>>, <Task finished coro=<Worker.heartbeat() done, defined at /softs/rh7/conda/4.5.4/envs/pangeo_full_201909/lib/python3.7/site-packages/distributed/worker.py:866> exception=OSError("Timed out trying to connect to 'tcp://10.120.40.97:33653' after 10 s: in <distributed.comm.tcp.TCPConnector object at 0x2aacebc728d0>: ConnectionRefusedError: [Errno 111] Connection refused")>)
Traceback (most recent call last):
  File "/softs/rh7/conda/4.5.4/envs/pangeo_full_201909/lib/python3.7/site-packages/distributed/comm/core.py", line 215, in connect
    quiet_exceptions=EnvironmentError,
tornado.util.TimeoutError: Timeout

During handling of the above exception, another exception occurred:

Traceback (most recent call last):
  File "/softs/rh7/conda/4.5.4/envs/pangeo_full_201909/lib/python3.7/site-packages/tornado/ioloop.py", line 743, in _run_callback
    ret = callback()
  File "/softs/rh7/conda/4.5.4/envs/pangeo_full_201909/lib/python3.7/site-packages/tornado/ioloop.py", line 767, in _discard_future_result
    future.result()
  File "/softs/rh7/conda/4.5.4/envs/pangeo_full_201909/lib/python3.7/site-packages/distributed/worker.py", line 875, in heartbeat
    metrics=await self.get_metrics(),
  File "/softs/rh7/conda/4.5.4/envs/pangeo_full_201909/lib/python3.7/site-packages/distributed/core.py", line 747, in send_recv_from_rpc
    comm = await self.pool.connect(self.addr)
  File "/softs/rh7/conda/4.5.4/envs/pangeo_full_201909/lib/python3.7/site-packages/distributed/core.py", line 874, in connect
    connection_args=self.connection_args,
  File "/softs/rh7/conda/4.5.4/envs/pangeo_full_201909/lib/python3.7/site-packages/distributed/comm/core.py", line 227, in connect
    _raise(error)
  File "/softs/rh7/conda/4.5.4/envs/pangeo_full_201909/lib/python3.7/site-packages/distributed/comm/core.py", line 204, in _raise
    raise IOError(msg)
OSError: Timed out trying to connect to 'tcp://10.120.40.97:33653' after 10 s: in <distributed.comm.tcp.TCPConnector object at 0x2aacebc728d0>: ConnectionRefusedError: [Errno 111] Connection refused
tornado.application - ERROR - Exception in callback functools.partial(<bound method IOLoop._discard_future_result of <tornado.platform.asyncio.AsyncIOLoop object at 0x2aacd5e9eb38>>, <Task finished coro=<Worker.heartbeat() done, defined at /softs/rh7/conda/4.5.4/envs/pangeo_full_201909/lib/python3.7/site-packages/distributed/worker.py:866> exception=OSError("Timed out trying to connect to 'tcp://10.120.40.97:33653' after 10 s: in <distributed.comm.tcp.TCPConnector object at 0x2aacebcda080>: ConnectionRefusedError: [Errno 111] Connection refused")>)
Traceback (most recent call last):
  File "/softs/rh7/conda/4.5.4/envs/pangeo_full_201909/lib/python3.7/site-packages/distributed/comm/core.py", line 215, in connect
    quiet_exceptions=EnvironmentError,
tornado.util.TimeoutError: Timeout

During handling of the above exception, another exception occurred:

Traceback (most recent call last):
  File "/softs/rh7/conda/4.5.4/envs/pangeo_full_201909/lib/python3.7/site-packages/tornado/ioloop.py", line 743, in _run_callback
    ret = callback()
  File "/softs/rh7/conda/4.5.4/envs/pangeo_full_201909/lib/python3.7/site-packages/tornado/ioloop.py", line 767, in _discard_future_result
    future.result()
  File "/softs/rh7/conda/4.5.4/envs/pangeo_full_201909/lib/python3.7/site-packages/distributed/worker.py", line 875, in heartbeat
    metrics=await self.get_metrics(),
  File "/softs/rh7/conda/4.5.4/envs/pangeo_full_201909/lib/python3.7/site-packages/distributed/core.py", line 747, in send_recv_from_rpc
    comm = await self.pool.connect(self.addr)
  File "/softs/rh7/conda/4.5.4/envs/pangeo_full_201909/lib/python3.7/site-packages/distributed/core.py", line 874, in connect
    connection_args=self.connection_args,
  File "/softs/rh7/conda/4.5.4/envs/pangeo_full_201909/lib/python3.7/site-packages/distributed/comm/core.py", line 227, in connect
    _raise(error)
  File "/softs/rh7/conda/4.5.4/envs/pangeo_full_201909/lib/python3.7/site-packages/distributed/comm/core.py", line 204, in _raise
    raise IOError(msg)
OSError: Timed out trying to connect to 'tcp://10.120.40.97:33653' after 10 s: in <distributed.comm.tcp.TCPConnector object at 0x2aacebcda080>: ConnectionRefusedError: [Errno 111] Connection refused
tornado.application - ERROR - Exception in callback functools.partial(<bound method IOLoop._discard_future_result of <tornado.platform.asyncio.AsyncIOLoop object at 0x2aacd5e9eb38>>, <Task finished coro=<Worker.heartbeat() done, defined at /softs/rh7/conda/4.5.4/envs/pangeo_full_201909/lib/python3.7/site-packages/distributed/worker.py:866> exception=OSError("Timed out trying to connect to 'tcp://10.120.40.97:33653' after 10 s: in <distributed.comm.tcp.TCPConnector object at 0x2aacebc72a90>: ConnectionRefusedError: [Errno 111] Connection refused")>)
Traceback (most recent call last):
  File "/softs/rh7/conda/4.5.4/envs/pangeo_full_201909/lib/python3.7/site-packages/distributed/comm/core.py", line 215, in connect
    quiet_exceptions=EnvironmentError,
tornado.util.TimeoutError: Timeout

During handling of the above exception, another exception occurred:

Traceback (most recent call last):
  File "/softs/rh7/conda/4.5.4/envs/pangeo_full_201909/lib/python3.7/site-packages/tornado/ioloop.py", line 743, in _run_callback
    ret = callback()
  File "/softs/rh7/conda/4.5.4/envs/pangeo_full_201909/lib/python3.7/site-packages/tornado/ioloop.py", line 767, in _discard_future_result
    future.result()
  File "/softs/rh7/conda/4.5.4/envs/pangeo_full_201909/lib/python3.7/site-packages/distributed/worker.py", line 875, in heartbeat
    metrics=await self.get_metrics(),
  File "/softs/rh7/conda/4.5.4/envs/pangeo_full_201909/lib/python3.7/site-packages/distributed/core.py", line 747, in send_recv_from_rpc
    comm = await self.pool.connect(self.addr)
  File "/softs/rh7/conda/4.5.4/envs/pangeo_full_201909/lib/python3.7/site-packages/distributed/core.py", line 874, in connect
    connection_args=self.connection_args,
  File "/softs/rh7/conda/4.5.4/envs/pangeo_full_201909/lib/python3.7/site-packages/distributed/comm/core.py", line 227, in connect
    _raise(error)
  File "/softs/rh7/conda/4.5.4/envs/pangeo_full_201909/lib/python3.7/site-packages/distributed/comm/core.py", line 204, in _raise
    raise IOError(msg)
OSError: Timed out trying to connect to 'tcp://10.120.40.97:33653' after 10 s: in <distributed.comm.tcp.TCPConnector object at 0x2aacebc72a90>: ConnectionRefusedError: [Errno 111] Connection refused
tornado.application - ERROR - Exception in callback functools.partial(<bound method IOLoop._discard_future_result of <tornado.platform.asyncio.AsyncIOLoop object at 0x2aacd5e9eb38>>, <Task finished coro=<Worker.heartbeat() done, defined at /softs/rh7/conda/4.5.4/envs/pangeo_full_201909/lib/python3.7/site-packages/distributed/worker.py:866> exception=OSError("Timed out trying to connect to 'tcp://10.120.40.97:33653' after 10 s: in <distributed.comm.tcp.TCPConnector object at 0x2aacebc72f60>: ConnectionRefusedError: [Errno 111] Connection refused")>)
Traceback (most recent call last):
  File "/softs/rh7/conda/4.5.4/envs/pangeo_full_201909/lib/python3.7/site-packages/distributed/comm/core.py", line 215, in connect
    quiet_exceptions=EnvironmentError,
tornado.util.TimeoutError: Timeout

During handling of the above exception, another exception occurred:

Traceback (most recent call last):
  File "/softs/rh7/conda/4.5.4/envs/pangeo_full_201909/lib/python3.7/site-packages/tornado/ioloop.py", line 743, in _run_callback
    ret = callback()
  File "/softs/rh7/conda/4.5.4/envs/pangeo_full_201909/lib/python3.7/site-packages/tornado/ioloop.py", line 767, in _discard_future_result
    future.result()
  File "/softs/rh7/conda/4.5.4/envs/pangeo_full_201909/lib/python3.7/site-packages/distributed/worker.py", line 875, in heartbeat
    metrics=await self.get_metrics(),
  File "/softs/rh7/conda/4.5.4/envs/pangeo_full_201909/lib/python3.7/site-packages/distributed/core.py", line 747, in send_recv_from_rpc
    comm = await self.pool.connect(self.addr)
  File "/softs/rh7/conda/4.5.4/envs/pangeo_full_201909/lib/python3.7/site-packages/distributed/core.py", line 874, in connect
    connection_args=self.connection_args,
  File "/softs/rh7/conda/4.5.4/envs/pangeo_full_201909/lib/python3.7/site-packages/distributed/comm/core.py", line 227, in connect
    _raise(error)
  File "/softs/rh7/conda/4.5.4/envs/pangeo_full_201909/lib/python3.7/site-packages/distributed/comm/core.py", line 204, in _raise
    raise IOError(msg)
OSError: Timed out trying to connect to 'tcp://10.120.40.97:33653' after 10 s: in <distributed.comm.tcp.TCPConnector object at 0x2aacebc72f60>: ConnectionRefusedError: [Errno 111] Connection refused
tornado.application - ERROR - Exception in callback functools.partial(<bound method IOLoop._discard_future_result of <tornado.platform.asyncio.AsyncIOLoop object at 0x2aacd5e9eb38>>, <Task finished coro=<Worker.heartbeat() done, defined at /softs/rh7/conda/4.5.4/envs/pangeo_full_201909/lib/python3.7/site-packages/distributed/worker.py:866> exception=OSError("Timed out trying to connect to 'tcp://10.120.40.97:33653' after 10 s: in <distributed.comm.tcp.TCPConnector object at 0x2aaceb43d630>: ConnectionRefusedError: [Errno 111] Connection refused")>)
Traceback (most recent call last):
  File "/softs/rh7/conda/4.5.4/envs/pangeo_full_201909/lib/python3.7/site-packages/distributed/comm/core.py", line 215, in connect
    quiet_exceptions=EnvironmentError,
tornado.util.TimeoutError: Timeout

During handling of the above exception, another exception occurred:

Traceback (most recent call last):
  File "/softs/rh7/conda/4.5.4/envs/pangeo_full_201909/lib/python3.7/site-packages/tornado/ioloop.py", line 743, in _run_callback
    ret = callback()
  File "/softs/rh7/conda/4.5.4/envs/pangeo_full_201909/lib/python3.7/site-packages/tornado/ioloop.py", line 767, in _discard_future_result
    future.result()
  File "/softs/rh7/conda/4.5.4/envs/pangeo_full_201909/lib/python3.7/site-packages/distributed/worker.py", line 875, in heartbeat
    metrics=await self.get_metrics(),
  File "/softs/rh7/conda/4.5.4/envs/pangeo_full_201909/lib/python3.7/site-packages/distributed/core.py", line 747, in send_recv_from_rpc
    comm = await self.pool.connect(self.addr)
  File "/softs/rh7/conda/4.5.4/envs/pangeo_full_201909/lib/python3.7/site-packages/distributed/core.py", line 874, in connect
    connection_args=self.connection_args,
  File "/softs/rh7/conda/4.5.4/envs/pangeo_full_201909/lib/python3.7/site-packages/distributed/comm/core.py", line 227, in connect
    _raise(error)
  File "/softs/rh7/conda/4.5.4/envs/pangeo_full_201909/lib/python3.7/site-packages/distributed/comm/core.py", line 204, in _raise
    raise IOError(msg)
OSError: Timed out trying to connect to 'tcp://10.120.40.97:33653' after 10 s: in <distributed.comm.tcp.TCPConnector object at 0x2aaceb43d630>: ConnectionRefusedError: [Errno 111] Connection refused
tornado.application - ERROR - Exception in callback <function Worker._register_with_scheduler.<locals>.<lambda> at 0x2aace90462f0>
Traceback (most recent call last):
  File "/softs/rh7/conda/4.5.4/envs/pangeo_full_201909/lib/python3.7/site-packages/tornado/ioloop.py", line 907, in _run
    return self.callback()
  File "/softs/rh7/conda/4.5.4/envs/pangeo_full_201909/lib/python3.7/site-packages/distributed/worker.py", line 857, in <lambda>
    lambda: self.batched_stream.send({"op": "keep-alive"}),
  File "/softs/rh7/conda/4.5.4/envs/pangeo_full_201909/lib/python3.7/site-packages/distributed/batched.py", line 117, in send
    raise CommClosedError
distributed.comm.core.CommClosedError
tornado.application - ERROR - Exception in callback functools.partial(<bound method IOLoop._discard_future_result of <tornado.platform.asyncio.AsyncIOLoop object at 0x2aacd5e9eb38>>, <Task finished coro=<Worker.heartbeat() done, defined at /softs/rh7/conda/4.5.4/envs/pangeo_full_201909/lib/python3.7/site-packages/distributed/worker.py:866> exception=OSError("Timed out trying to connect to 'tcp://10.120.40.97:33653' after 10 s: in <distributed.comm.tcp.TCPConnector object at 0x2aaceb059b38>: ConnectionRefusedError: [Errno 111] Connection refused")>)
Traceback (most recent call last):
  File "/softs/rh7/conda/4.5.4/envs/pangeo_full_201909/lib/python3.7/site-packages/distributed/comm/core.py", line 215, in connect
    quiet_exceptions=EnvironmentError,
tornado.util.TimeoutError: Timeout

During handling of the above exception, another exception occurred:

Traceback (most recent call last):
  File "/softs/rh7/conda/4.5.4/envs/pangeo_full_201909/lib/python3.7/site-packages/tornado/ioloop.py", line 743, in _run_callback
    ret = callback()
  File "/softs/rh7/conda/4.5.4/envs/pangeo_full_201909/lib/python3.7/site-packages/tornado/ioloop.py", line 767, in _discard_future_result
    future.result()
  File "/softs/rh7/conda/4.5.4/envs/pangeo_full_201909/lib/python3.7/site-packages/distributed/worker.py", line 875, in heartbeat
    metrics=await self.get_metrics(),
  File "/softs/rh7/conda/4.5.4/envs/pangeo_full_201909/lib/python3.7/site-packages/distributed/core.py", line 747, in send_recv_from_rpc
    comm = await self.pool.connect(self.addr)
  File "/softs/rh7/conda/4.5.4/envs/pangeo_full_201909/lib/python3.7/site-packages/distributed/core.py", line 874, in connect
    connection_args=self.connection_args,
  File "/softs/rh7/conda/4.5.4/envs/pangeo_full_201909/lib/python3.7/site-packages/distributed/comm/core.py", line 227, in connect
    _raise(error)
  File "/softs/rh7/conda/4.5.4/envs/pangeo_full_201909/lib/python3.7/site-packages/distributed/comm/core.py", line 204, in _raise
    raise IOError(msg)
OSError: Timed out trying to connect to 'tcp://10.120.40.97:33653' after 10 s: in <distributed.comm.tcp.TCPConnector object at 0x2aaceb059b38>: ConnectionRefusedError: [Errno 111] Connection refused
tornado.application - ERROR - Exception in callback functools.partial(<bound method IOLoop._discard_future_result of <tornado.platform.asyncio.AsyncIOLoop object at 0x2aacd5e9eb38>>, <Task finished coro=<Worker.heartbeat() done, defined at /softs/rh7/conda/4.5.4/envs/pangeo_full_201909/lib/python3.7/site-packages/distributed/worker.py:866> exception=OSError("Timed out trying to connect to 'tcp://10.120.40.97:33653' after 10 s: in <distributed.comm.tcp.TCPConnector object at 0x2aaceb01a668>: ConnectionRefusedError: [Errno 111] Connection refused")>)
Traceback (most recent call last):
  File "/softs/rh7/conda/4.5.4/envs/pangeo_full_201909/lib/python3.7/site-packages/distributed/comm/core.py", line 215, in connect
    quiet_exceptions=EnvironmentError,
tornado.util.TimeoutError: Timeout

During handling of the above exception, another exception occurred:

Traceback (most recent call last):
  File "/softs/rh7/conda/4.5.4/envs/pangeo_full_201909/lib/python3.7/site-packages/tornado/ioloop.py", line 743, in _run_callback
    ret = callback()
  File "/softs/rh7/conda/4.5.4/envs/pangeo_full_201909/lib/python3.7/site-packages/tornado/ioloop.py", line 767, in _discard_future_result
    future.result()
  File "/softs/rh7/conda/4.5.4/envs/pangeo_full_201909/lib/python3.7/site-packages/distributed/worker.py", line 875, in heartbeat
    metrics=await self.get_metrics(),
  File "/softs/rh7/conda/4.5.4/envs/pangeo_full_201909/lib/python3.7/site-packages/distributed/core.py", line 747, in send_recv_from_rpc
    comm = await self.pool.connect(self.addr)
  File "/softs/rh7/conda/4.5.4/envs/pangeo_full_201909/lib/python3.7/site-packages/distributed/core.py", line 874, in connect
    connection_args=self.connection_args,
  File "/softs/rh7/conda/4.5.4/envs/pangeo_full_201909/lib/python3.7/site-packages/distributed/comm/core.py", line 227, in connect
    _raise(error)
  File "/softs/rh7/conda/4.5.4/envs/pangeo_full_201909/lib/python3.7/site-packages/distributed/comm/core.py", line 204, in _raise
    raise IOError(msg)
OSError: Timed out trying to connect to 'tcp://10.120.40.97:33653' after 10 s: in <distributed.comm.tcp.TCPConnector object at 0x2aaceb01a668>: ConnectionRefusedError: [Errno 111] Connection refused
tornado.application - ERROR - Exception in callback functools.partial(<bound method IOLoop._discard_future_result of <tornado.platform.asyncio.AsyncIOLoop object at 0x2aacd5e9eb38>>, <Task finished coro=<Worker.heartbeat() done, defined at /softs/rh7/conda/4.5.4/envs/pangeo_full_201909/lib/python3.7/site-packages/distributed/worker.py:866> exception=OSError("Timed out trying to connect to 'tcp://10.120.40.97:33653' after 10 s: in <distributed.comm.tcp.TCPConnector object at 0x2aacebcda2b0>: ConnectionRefusedError: [Errno 111] Connection refused")>)
Traceback (most recent call last):
  File "/softs/rh7/conda/4.5.4/envs/pangeo_full_201909/lib/python3.7/site-packages/distributed/comm/core.py", line 215, in connect
    quiet_exceptions=EnvironmentError,
tornado.util.TimeoutError: Timeout

During handling of the above exception, another exception occurred:

Traceback (most recent call last):
  File "/softs/rh7/conda/4.5.4/envs/pangeo_full_201909/lib/python3.7/site-packages/tornado/ioloop.py", line 743, in _run_callback
    ret = callback()
  File "/softs/rh7/conda/4.5.4/envs/pangeo_full_201909/lib/python3.7/site-packages/tornado/ioloop.py", line 767, in _discard_future_result
    future.result()
  File "/softs/rh7/conda/4.5.4/envs/pangeo_full_201909/lib/python3.7/site-packages/distributed/worker.py", line 875, in heartbeat
    metrics=await self.get_metrics(),
  File "/softs/rh7/conda/4.5.4/envs/pangeo_full_201909/lib/python3.7/site-packages/distributed/core.py", line 747, in send_recv_from_rpc
    comm = await self.pool.connect(self.addr)
  File "/softs/rh7/conda/4.5.4/envs/pangeo_full_201909/lib/python3.7/site-packages/distributed/core.py", line 874, in connect
    connection_args=self.connection_args,
  File "/softs/rh7/conda/4.5.4/envs/pangeo_full_201909/lib/python3.7/site-packages/distributed/comm/core.py", line 227, in connect
    _raise(error)
  File "/softs/rh7/conda/4.5.4/envs/pangeo_full_201909/lib/python3.7/site-packages/distributed/comm/core.py", line 204, in _raise
    raise IOError(msg)
OSError: Timed out trying to connect to 'tcp://10.120.40.97:33653' after 10 s: in <distributed.comm.tcp.TCPConnector object at 0x2aacebcda2b0>: ConnectionRefusedError: [Errno 111] Connection refused
tornado.application - ERROR - Exception in callback functools.partial(<bound method IOLoop._discard_future_result of <tornado.platform.asyncio.AsyncIOLoop object at 0x2aacd5e9eb38>>, <Task finished coro=<Worker.heartbeat() done, defined at /softs/rh7/conda/4.5.4/envs/pangeo_full_201909/lib/python3.7/site-packages/distributed/worker.py:866> exception=OSError("Timed out trying to connect to 'tcp://10.120.40.97:33653' after 10 s: in <distributed.comm.tcp.TCPConnector object at 0x2aaceb01a128>: ConnectionRefusedError: [Errno 111] Connection refused")>)
Traceback (most recent call last):
  File "/softs/rh7/conda/4.5.4/envs/pangeo_full_201909/lib/python3.7/site-packages/distributed/comm/core.py", line 215, in connect
    quiet_exceptions=EnvironmentError,
tornado.util.TimeoutError: Timeout

During handling of the above exception, another exception occurred:

Traceback (most recent call last):
  File "/softs/rh7/conda/4.5.4/envs/pangeo_full_201909/lib/python3.7/site-packages/tornado/ioloop.py", line 743, in _run_callback
    ret = callback()
  File "/softs/rh7/conda/4.5.4/envs/pangeo_full_201909/lib/python3.7/site-packages/tornado/ioloop.py", line 767, in _discard_future_result
    future.result()
  File "/softs/rh7/conda/4.5.4/envs/pangeo_full_201909/lib/python3.7/site-packages/distributed/worker.py", line 875, in heartbeat
    metrics=await self.get_metrics(),
  File "/softs/rh7/conda/4.5.4/envs/pangeo_full_201909/lib/python3.7/site-packages/distributed/core.py", line 747, in send_recv_from_rpc
    comm = await self.pool.connect(self.addr)
  File "/softs/rh7/conda/4.5.4/envs/pangeo_full_201909/lib/python3.7/site-packages/distributed/core.py", line 874, in connect
    connection_args=self.connection_args,
  File "/softs/rh7/conda/4.5.4/envs/pangeo_full_201909/lib/python3.7/site-packages/distributed/comm/core.py", line 227, in connect
    _raise(error)
  File "/softs/rh7/conda/4.5.4/envs/pangeo_full_201909/lib/python3.7/site-packages/distributed/comm/core.py", line 204, in _raise
    raise IOError(msg)
OSError: Timed out trying to connect to 'tcp://10.120.40.97:33653' after 10 s: in <distributed.comm.tcp.TCPConnector object at 0x2aaceb01a128>: ConnectionRefusedError: [Errno 111] Connection refused
tornado.application - ERROR - Exception in callback functools.partial(<bound method IOLoop._discard_future_result of <tornado.platform.asyncio.AsyncIOLoop object at 0x2aacd5e9eb38>>, <Task finished coro=<Worker.heartbeat() done, defined at /softs/rh7/conda/4.5.4/envs/pangeo_full_201909/lib/python3.7/site-packages/distributed/worker.py:866> exception=OSError("Timed out trying to connect to 'tcp://10.120.40.97:33653' after 10 s: in <distributed.comm.tcp.TCPConnector object at 0x2aaceac26320>: ConnectionRefusedError: [Errno 111] Connection refused")>)
Traceback (most recent call last):
  File "/softs/rh7/conda/4.5.4/envs/pangeo_full_201909/lib/python3.7/site-packages/distributed/comm/core.py", line 215, in connect
    quiet_exceptions=EnvironmentError,
tornado.util.TimeoutError: Timeout

During handling of the above exception, another exception occurred:

Traceback (most recent call last):
  File "/softs/rh7/conda/4.5.4/envs/pangeo_full_201909/lib/python3.7/site-packages/tornado/ioloop.py", line 743, in _run_callback
    ret = callback()
  File "/softs/rh7/conda/4.5.4/envs/pangeo_full_201909/lib/python3.7/site-packages/tornado/ioloop.py", line 767, in _discard_future_result
    future.result()
  File "/softs/rh7/conda/4.5.4/envs/pangeo_full_201909/lib/python3.7/site-packages/distributed/worker.py", line 875, in heartbeat
    metrics=await self.get_metrics(),
  File "/softs/rh7/conda/4.5.4/envs/pangeo_full_201909/lib/python3.7/site-packages/distributed/core.py", line 747, in send_recv_from_rpc
    comm = await self.pool.connect(self.addr)
  File "/softs/rh7/conda/4.5.4/envs/pangeo_full_201909/lib/python3.7/site-packages/distributed/core.py", line 874, in connect
    connection_args=self.connection_args,
  File "/softs/rh7/conda/4.5.4/envs/pangeo_full_201909/lib/python3.7/site-packages/distributed/comm/core.py", line 227, in connect
    _raise(error)
  File "/softs/rh7/conda/4.5.4/envs/pangeo_full_201909/lib/python3.7/site-packages/distributed/comm/core.py", line 204, in _raise
    raise IOError(msg)
OSError: Timed out trying to connect to 'tcp://10.120.40.97:33653' after 10 s: in <distributed.comm.tcp.TCPConnector object at 0x2aaceac26320>: ConnectionRefusedError: [Errno 111] Connection refused
tornado.application - ERROR - Exception in callback <function Worker._register_with_scheduler.<locals>.<lambda> at 0x2aace90462f0>
Traceback (most recent call last):
  File "/softs/rh7/conda/4.5.4/envs/pangeo_full_201909/lib/python3.7/site-packages/tornado/ioloop.py", line 907, in _run
    return self.callback()
  File "/softs/rh7/conda/4.5.4/envs/pangeo_full_201909/lib/python3.7/site-packages/distributed/worker.py", line 857, in <lambda>
    lambda: self.batched_stream.send({"op": "keep-alive"}),
  File "/softs/rh7/conda/4.5.4/envs/pangeo_full_201909/lib/python3.7/site-packages/distributed/batched.py", line 117, in send
    raise CommClosedError
distributed.comm.core.CommClosedError
tornado.application - ERROR - Exception in callback functools.partial(<bound method IOLoop._discard_future_result of <tornado.platform.asyncio.AsyncIOLoop object at 0x2aacd5e9eb38>>, <Task finished coro=<Worker.heartbeat() done, defined at /softs/rh7/conda/4.5.4/envs/pangeo_full_201909/lib/python3.7/site-packages/distributed/worker.py:866> exception=OSError("Timed out trying to connect to 'tcp://10.120.40.97:33653' after 10 s: in <distributed.comm.tcp.TCPConnector object at 0x2aaceaffc7b8>: ConnectionRefusedError: [Errno 111] Connection refused")>)
Traceback (most recent call last):
  File "/softs/rh7/conda/4.5.4/envs/pangeo_full_201909/lib/python3.7/site-packages/distributed/comm/core.py", line 215, in connect
    quiet_exceptions=EnvironmentError,
tornado.util.TimeoutError: Timeout

During handling of the above exception, another exception occurred:

Traceback (most recent call last):
  File "/softs/rh7/conda/4.5.4/envs/pangeo_full_201909/lib/python3.7/site-packages/tornado/ioloop.py", line 743, in _run_callback
    ret = callback()
  File "/softs/rh7/conda/4.5.4/envs/pangeo_full_201909/lib/python3.7/site-packages/tornado/ioloop.py", line 767, in _discard_future_result
    future.result()
  File "/softs/rh7/conda/4.5.4/envs/pangeo_full_201909/lib/python3.7/site-packages/distributed/worker.py", line 875, in heartbeat
    metrics=await self.get_metrics(),
  File "/softs/rh7/conda/4.5.4/envs/pangeo_full_201909/lib/python3.7/site-packages/distributed/core.py", line 747, in send_recv_from_rpc
    comm = await self.pool.connect(self.addr)
  File "/softs/rh7/conda/4.5.4/envs/pangeo_full_201909/lib/python3.7/site-packages/distributed/core.py", line 874, in connect
    connection_args=self.connection_args,
  File "/softs/rh7/conda/4.5.4/envs/pangeo_full_201909/lib/python3.7/site-packages/distributed/comm/core.py", line 227, in connect
    _raise(error)
  File "/softs/rh7/conda/4.5.4/envs/pangeo_full_201909/lib/python3.7/site-packages/distributed/comm/core.py", line 204, in _raise
    raise IOError(msg)
OSError: Timed out trying to connect to 'tcp://10.120.40.97:33653' after 10 s: in <distributed.comm.tcp.TCPConnector object at 0x2aaceaffc7b8>: ConnectionRefusedError: [Errno 111] Connection refused
tornado.application - ERROR - Exception in callback functools.partial(<bound method IOLoop._discard_future_result of <tornado.platform.asyncio.AsyncIOLoop object at 0x2aacd5e9eb38>>, <Task finished coro=<Worker.heartbeat() done, defined at /softs/rh7/conda/4.5.4/envs/pangeo_full_201909/lib/python3.7/site-packages/distributed/worker.py:866> exception=OSError("Timed out trying to connect to 'tcp://10.120.40.97:33653' after 10 s: in <distributed.comm.tcp.TCPConnector object at 0x2aaceb3ef080>: ConnectionRefusedError: [Errno 111] Connection refused")>)
Traceback (most recent call last):
  File "/softs/rh7/conda/4.5.4/envs/pangeo_full_201909/lib/python3.7/site-packages/distributed/comm/core.py", line 215, in connect
    quiet_exceptions=EnvironmentError,
tornado.util.TimeoutError: Timeout

During handling of the above exception, another exception occurred:

Traceback (most recent call last):
  File "/softs/rh7/conda/4.5.4/envs/pangeo_full_201909/lib/python3.7/site-packages/tornado/ioloop.py", line 743, in _run_callback
    ret = callback()
  File "/softs/rh7/conda/4.5.4/envs/pangeo_full_201909/lib/python3.7/site-packages/tornado/ioloop.py", line 767, in _discard_future_result
    future.result()
  File "/softs/rh7/conda/4.5.4/envs/pangeo_full_201909/lib/python3.7/site-packages/distributed/worker.py", line 875, in heartbeat
    metrics=await self.get_metrics(),
  File "/softs/rh7/conda/4.5.4/envs/pangeo_full_201909/lib/python3.7/site-packages/distributed/core.py", line 747, in send_recv_from_rpc
    comm = await self.pool.connect(self.addr)
  File "/softs/rh7/conda/4.5.4/envs/pangeo_full_201909/lib/python3.7/site-packages/distributed/core.py", line 874, in connect
    connection_args=self.connection_args,
  File "/softs/rh7/conda/4.5.4/envs/pangeo_full_201909/lib/python3.7/site-packages/distributed/comm/core.py", line 227, in connect
    _raise(error)
  File "/softs/rh7/conda/4.5.4/envs/pangeo_full_201909/lib/python3.7/site-packages/distributed/comm/core.py", line 204, in _raise
    raise IOError(msg)
OSError: Timed out trying to connect to 'tcp://10.120.40.97:33653' after 10 s: in <distributed.comm.tcp.TCPConnector object at 0x2aaceb3ef080>: ConnectionRefusedError: [Errno 111] Connection refused
tornado.application - ERROR - Exception in callback functools.partial(<bound method IOLoop._discard_future_result of <tornado.platform.asyncio.AsyncIOLoop object at 0x2aacd5e9eb38>>, <Task finished coro=<Worker.heartbeat() done, defined at /softs/rh7/conda/4.5.4/envs/pangeo_full_201909/lib/python3.7/site-packages/distributed/worker.py:866> exception=OSError("Timed out trying to connect to 'tcp://10.120.40.97:33653' after 10 s: in <distributed.comm.tcp.TCPConnector object at 0x2aacebcda2e8>: ConnectionRefusedError: [Errno 111] Connection refused")>)
Traceback (most recent call last):
  File "/softs/rh7/conda/4.5.4/envs/pangeo_full_201909/lib/python3.7/site-packages/distributed/comm/core.py", line 215, in connect
    quiet_exceptions=EnvironmentError,
tornado.util.TimeoutError: Timeout

During handling of the above exception, another exception occurred:

Traceback (most recent call last):
  File "/softs/rh7/conda/4.5.4/envs/pangeo_full_201909/lib/python3.7/site-packages/tornado/ioloop.py", line 743, in _run_callback
    ret = callback()
  File "/softs/rh7/conda/4.5.4/envs/pangeo_full_201909/lib/python3.7/site-packages/tornado/ioloop.py", line 767, in _discard_future_result
    future.result()
  File "/softs/rh7/conda/4.5.4/envs/pangeo_full_201909/lib/python3.7/site-packages/distributed/worker.py", line 875, in heartbeat
    metrics=await self.get_metrics(),
  File "/softs/rh7/conda/4.5.4/envs/pangeo_full_201909/lib/python3.7/site-packages/distributed/core.py", line 747, in send_recv_from_rpc
    comm = await self.pool.connect(self.addr)
  File "/softs/rh7/conda/4.5.4/envs/pangeo_full_201909/lib/python3.7/site-packages/distributed/core.py", line 874, in connect
    connection_args=self.connection_args,
  File "/softs/rh7/conda/4.5.4/envs/pangeo_full_201909/lib/python3.7/site-packages/distributed/comm/core.py", line 227, in connect
    _raise(error)
  File "/softs/rh7/conda/4.5.4/envs/pangeo_full_201909/lib/python3.7/site-packages/distributed/comm/core.py", line 204, in _raise
    raise IOError(msg)
OSError: Timed out trying to connect to 'tcp://10.120.40.97:33653' after 10 s: in <distributed.comm.tcp.TCPConnector object at 0x2aacebcda2e8>: ConnectionRefusedError: [Errno 111] Connection refused
tornado.application - ERROR - Exception in callback functools.partial(<bound method IOLoop._discard_future_result of <tornado.platform.asyncio.AsyncIOLoop object at 0x2aacd5e9eb38>>, <Task finished coro=<Worker.heartbeat() done, defined at /softs/rh7/conda/4.5.4/envs/pangeo_full_201909/lib/python3.7/site-packages/distributed/worker.py:866> exception=OSError("Timed out trying to connect to 'tcp://10.120.40.97:33653' after 10 s: in <distributed.comm.tcp.TCPConnector object at 0x2aacebcda630>: ConnectionRefusedError: [Errno 111] Connection refused")>)
Traceback (most recent call last):
  File "/softs/rh7/conda/4.5.4/envs/pangeo_full_201909/lib/python3.7/site-packages/distributed/comm/core.py", line 215, in connect
    quiet_exceptions=EnvironmentError,
tornado.util.TimeoutError: Timeout

During handling of the above exception, another exception occurred:

Traceback (most recent call last):
  File "/softs/rh7/conda/4.5.4/envs/pangeo_full_201909/lib/python3.7/site-packages/tornado/ioloop.py", line 743, in _run_callback
    ret = callback()
  File "/softs/rh7/conda/4.5.4/envs/pangeo_full_201909/lib/python3.7/site-packages/tornado/ioloop.py", line 767, in _discard_future_result
    future.result()
  File "/softs/rh7/conda/4.5.4/envs/pangeo_full_201909/lib/python3.7/site-packages/distributed/worker.py", line 875, in heartbeat
    metrics=await self.get_metrics(),
  File "/softs/rh7/conda/4.5.4/envs/pangeo_full_201909/lib/python3.7/site-packages/distributed/core.py", line 747, in send_recv_from_rpc
    comm = await self.pool.connect(self.addr)
  File "/softs/rh7/conda/4.5.4/envs/pangeo_full_201909/lib/python3.7/site-packages/distributed/core.py", line 874, in connect
    connection_args=self.connection_args,
  File "/softs/rh7/conda/4.5.4/envs/pangeo_full_201909/lib/python3.7/site-packages/distributed/comm/core.py", line 227, in connect
    _raise(error)
  File "/softs/rh7/conda/4.5.4/envs/pangeo_full_201909/lib/python3.7/site-packages/distributed/comm/core.py", line 204, in _raise
    raise IOError(msg)
OSError: Timed out trying to connect to 'tcp://10.120.40.97:33653' after 10 s: in <distributed.comm.tcp.TCPConnector object at 0x2aacebcda630>: ConnectionRefusedError: [Errno 111] Connection refused
tornado.application - ERROR - Exception in callback functools.partial(<bound method IOLoop._discard_future_result of <tornado.platform.asyncio.AsyncIOLoop object at 0x2aacd5e9eb38>>, <Task finished coro=<Worker.heartbeat() done, defined at /softs/rh7/conda/4.5.4/envs/pangeo_full_201909/lib/python3.7/site-packages/distributed/worker.py:866> exception=OSError("Timed out trying to connect to 'tcp://10.120.40.97:33653' after 10 s: in <distributed.comm.tcp.TCPConnector object at 0x2aaceb01a2e8>: ConnectionRefusedError: [Errno 111] Connection refused")>)
Traceback (most recent call last):
  File "/softs/rh7/conda/4.5.4/envs/pangeo_full_201909/lib/python3.7/site-packages/distributed/comm/core.py", line 215, in connect
    quiet_exceptions=EnvironmentError,
tornado.util.TimeoutError: Timeout

During handling of the above exception, another exception occurred:

Traceback (most recent call last):
  File "/softs/rh7/conda/4.5.4/envs/pangeo_full_201909/lib/python3.7/site-packages/tornado/ioloop.py", line 743, in _run_callback
    ret = callback()
  File "/softs/rh7/conda/4.5.4/envs/pangeo_full_201909/lib/python3.7/site-packages/tornado/ioloop.py", line 767, in _discard_future_result
    future.result()
  File "/softs/rh7/conda/4.5.4/envs/pangeo_full_201909/lib/python3.7/site-packages/distributed/worker.py", line 875, in heartbeat
    metrics=await self.get_metrics(),
  File "/softs/rh7/conda/4.5.4/envs/pangeo_full_201909/lib/python3.7/site-packages/distributed/core.py", line 747, in send_recv_from_rpc
    comm = await self.pool.connect(self.addr)
  File "/softs/rh7/conda/4.5.4/envs/pangeo_full_201909/lib/python3.7/site-packages/distributed/core.py", line 874, in connect
    connection_args=self.connection_args,
  File "/softs/rh7/conda/4.5.4/envs/pangeo_full_201909/lib/python3.7/site-packages/distributed/comm/core.py", line 227, in connect
    _raise(error)
  File "/softs/rh7/conda/4.5.4/envs/pangeo_full_201909/lib/python3.7/site-packages/distributed/comm/core.py", line 204, in _raise
    raise IOError(msg)
OSError: Timed out trying to connect to 'tcp://10.120.40.97:33653' after 10 s: in <distributed.comm.tcp.TCPConnector object at 0x2aaceb01a2e8>: ConnectionRefusedError: [Errno 111] Connection refused
tornado.application - ERROR - Exception in callback functools.partial(<bound method IOLoop._discard_future_result of <tornado.platform.asyncio.AsyncIOLoop object at 0x2aacd5e9eb38>>, <Task finished coro=<Worker.heartbeat() done, defined at /softs/rh7/conda/4.5.4/envs/pangeo_full_201909/lib/python3.7/site-packages/distributed/worker.py:866> exception=OSError("Timed out trying to connect to 'tcp://10.120.40.97:33653' after 10 s: in <distributed.comm.tcp.TCPConnector object at 0x2aacebcdab70>: ConnectionRefusedError: [Errno 111] Connection refused")>)
Traceback (most recent call last):
  File "/softs/rh7/conda/4.5.4/envs/pangeo_full_201909/lib/python3.7/site-packages/distributed/comm/core.py", line 215, in connect
    quiet_exceptions=EnvironmentError,
tornado.util.TimeoutError: Timeout

During handling of the above exception, another exception occurred:

Traceback (most recent call last):
  File "/softs/rh7/conda/4.5.4/envs/pangeo_full_201909/lib/python3.7/site-packages/tornado/ioloop.py", line 743, in _run_callback
    ret = callback()
  File "/softs/rh7/conda/4.5.4/envs/pangeo_full_201909/lib/python3.7/site-packages/tornado/ioloop.py", line 767, in _discard_future_result
    future.result()
  File "/softs/rh7/conda/4.5.4/envs/pangeo_full_201909/lib/python3.7/site-packages/distributed/worker.py", line 875, in heartbeat
    metrics=await self.get_metrics(),
  File "/softs/rh7/conda/4.5.4/envs/pangeo_full_201909/lib/python3.7/site-packages/distributed/core.py", line 747, in send_recv_from_rpc
    comm = await self.pool.connect(self.addr)
  File "/softs/rh7/conda/4.5.4/envs/pangeo_full_201909/lib/python3.7/site-packages/distributed/core.py", line 874, in connect
    connection_args=self.connection_args,
  File "/softs/rh7/conda/4.5.4/envs/pangeo_full_201909/lib/python3.7/site-packages/distributed/comm/core.py", line 227, in connect
    _raise(error)
  File "/softs/rh7/conda/4.5.4/envs/pangeo_full_201909/lib/python3.7/site-packages/distributed/comm/core.py", line 204, in _raise
    raise IOError(msg)
OSError: Timed out trying to connect to 'tcp://10.120.40.97:33653' after 10 s: in <distributed.comm.tcp.TCPConnector object at 0x2aacebcdab70>: ConnectionRefusedError: [Errno 111] Connection refused
tornado.application - ERROR - Exception in callback <function Worker._register_with_scheduler.<locals>.<lambda> at 0x2aace90462f0>
Traceback (most recent call last):
  File "/softs/rh7/conda/4.5.4/envs/pangeo_full_201909/lib/python3.7/site-packages/tornado/ioloop.py", line 907, in _run
    return self.callback()
  File "/softs/rh7/conda/4.5.4/envs/pangeo_full_201909/lib/python3.7/site-packages/distributed/worker.py", line 857, in <lambda>
    lambda: self.batched_stream.send({"op": "keep-alive"}),
  File "/softs/rh7/conda/4.5.4/envs/pangeo_full_201909/lib/python3.7/site-packages/distributed/batched.py", line 117, in send
    raise CommClosedError
distributed.comm.core.CommClosedError
tornado.application - ERROR - Exception in callback functools.partial(<bound method IOLoop._discard_future_result of <tornado.platform.asyncio.AsyncIOLoop object at 0x2aacd5e9eb38>>, <Task finished coro=<Worker.heartbeat() done, defined at /softs/rh7/conda/4.5.4/envs/pangeo_full_201909/lib/python3.7/site-packages/distributed/worker.py:866> exception=OSError("Timed out trying to connect to 'tcp://10.120.40.97:33653' after 10 s: in <distributed.comm.tcp.TCPConnector object at 0x2aaceb78b5f8>: ConnectionRefusedError: [Errno 111] Connection refused")>)
Traceback (most recent call last):
  File "/softs/rh7/conda/4.5.4/envs/pangeo_full_201909/lib/python3.7/site-packages/distributed/comm/core.py", line 215, in connect
    quiet_exceptions=EnvironmentError,
tornado.util.TimeoutError: Timeout

During handling of the above exception, another exception occurred:

Traceback (most recent call last):
  File "/softs/rh7/conda/4.5.4/envs/pangeo_full_201909/lib/python3.7/site-packages/tornado/ioloop.py", line 743, in _run_callback
    ret = callback()
  File "/softs/rh7/conda/4.5.4/envs/pangeo_full_201909/lib/python3.7/site-packages/tornado/ioloop.py", line 767, in _discard_future_result
    future.result()
  File "/softs/rh7/conda/4.5.4/envs/pangeo_full_201909/lib/python3.7/site-packages/distributed/worker.py", line 875, in heartbeat
    metrics=await self.get_metrics(),
  File "/softs/rh7/conda/4.5.4/envs/pangeo_full_201909/lib/python3.7/site-packages/distributed/core.py", line 747, in send_recv_from_rpc
    comm = await self.pool.connect(self.addr)
  File "/softs/rh7/conda/4.5.4/envs/pangeo_full_201909/lib/python3.7/site-packages/distributed/core.py", line 874, in connect
    connection_args=self.connection_args,
  File "/softs/rh7/conda/4.5.4/envs/pangeo_full_201909/lib/python3.7/site-packages/distributed/comm/core.py", line 227, in connect
    _raise(error)
  File "/softs/rh7/conda/4.5.4/envs/pangeo_full_201909/lib/python3.7/site-packages/distributed/comm/core.py", line 204, in _raise
    raise IOError(msg)
OSError: Timed out trying to connect to 'tcp://10.120.40.97:33653' after 10 s: in <distributed.comm.tcp.TCPConnector object at 0x2aaceb78b5f8>: ConnectionRefusedError: [Errno 111] Connection refused
tornado.application - ERROR - Exception in callback functools.partial(<bound method IOLoop._discard_future_result of <tornado.platform.asyncio.AsyncIOLoop object at 0x2aacd5e9eb38>>, <Task finished coro=<Worker.heartbeat() done, defined at /softs/rh7/conda/4.5.4/envs/pangeo_full_201909/lib/python3.7/site-packages/distributed/worker.py:866> exception=OSError("Timed out trying to connect to 'tcp://10.120.40.97:33653' after 10 s: in <distributed.comm.tcp.TCPConnector object at 0x2aaceb3ef898>: ConnectionRefusedError: [Errno 111] Connection refused")>)
Traceback (most recent call last):
  File "/softs/rh7/conda/4.5.4/envs/pangeo_full_201909/lib/python3.7/site-packages/distributed/comm/core.py", line 215, in connect
    quiet_exceptions=EnvironmentError,
tornado.util.TimeoutError: Timeout

During handling of the above exception, another exception occurred:

Traceback (most recent call last):
  File "/softs/rh7/conda/4.5.4/envs/pangeo_full_201909/lib/python3.7/site-packages/tornado/ioloop.py", line 743, in _run_callback
    ret = callback()
  File "/softs/rh7/conda/4.5.4/envs/pangeo_full_201909/lib/python3.7/site-packages/tornado/ioloop.py", line 767, in _discard_future_result
    future.result()
  File "/softs/rh7/conda/4.5.4/envs/pangeo_full_201909/lib/python3.7/site-packages/distributed/worker.py", line 875, in heartbeat
    metrics=await self.get_metrics(),
  File "/softs/rh7/conda/4.5.4/envs/pangeo_full_201909/lib/python3.7/site-packages/distributed/core.py", line 747, in send_recv_from_rpc
    comm = await self.pool.connect(self.addr)
  File "/softs/rh7/conda/4.5.4/envs/pangeo_full_201909/lib/python3.7/site-packages/distributed/core.py", line 874, in connect
    connection_args=self.connection_args,
  File "/softs/rh7/conda/4.5.4/envs/pangeo_full_201909/lib/python3.7/site-packages/distributed/comm/core.py", line 227, in connect
    _raise(error)
  File "/softs/rh7/conda/4.5.4/envs/pangeo_full_201909/lib/python3.7/site-packages/distributed/comm/core.py", line 204, in _raise
    raise IOError(msg)
OSError: Timed out trying to connect to 'tcp://10.120.40.97:33653' after 10 s: in <distributed.comm.tcp.TCPConnector object at 0x2aaceb3ef898>: ConnectionRefusedError: [Errno 111] Connection refused
tornado.application - ERROR - Exception in callback functools.partial(<bound method IOLoop._discard_future_result of <tornado.platform.asyncio.AsyncIOLoop object at 0x2aacd5e9eb38>>, <Task finished coro=<Worker.heartbeat() done, defined at /softs/rh7/conda/4.5.4/envs/pangeo_full_201909/lib/python3.7/site-packages/distributed/worker.py:866> exception=OSError("Timed out trying to connect to 'tcp://10.120.40.97:33653' after 10 s: in <distributed.comm.tcp.TCPConnector object at 0x2aaceb78bfd0>: ConnectionRefusedError: [Errno 111] Connection refused")>)
Traceback (most recent call last):
  File "/softs/rh7/conda/4.5.4/envs/pangeo_full_201909/lib/python3.7/site-packages/distributed/comm/core.py", line 215, in connect
    quiet_exceptions=EnvironmentError,
tornado.util.TimeoutError: Timeout

During handling of the above exception, another exception occurred:

Traceback (most recent call last):
  File "/softs/rh7/conda/4.5.4/envs/pangeo_full_201909/lib/python3.7/site-packages/tornado/ioloop.py", line 743, in _run_callback
    ret = callback()
  File "/softs/rh7/conda/4.5.4/envs/pangeo_full_201909/lib/python3.7/site-packages/tornado/ioloop.py", line 767, in _discard_future_result
    future.result()
  File "/softs/rh7/conda/4.5.4/envs/pangeo_full_201909/lib/python3.7/site-packages/distributed/worker.py", line 875, in heartbeat
    metrics=await self.get_metrics(),
  File "/softs/rh7/conda/4.5.4/envs/pangeo_full_201909/lib/python3.7/site-packages/distributed/core.py", line 747, in send_recv_from_rpc
    comm = await self.pool.connect(self.addr)
  File "/softs/rh7/conda/4.5.4/envs/pangeo_full_201909/lib/python3.7/site-packages/distributed/core.py", line 874, in connect
    connection_args=self.connection_args,
  File "/softs/rh7/conda/4.5.4/envs/pangeo_full_201909/lib/python3.7/site-packages/distributed/comm/core.py", line 227, in connect
    _raise(error)
  File "/softs/rh7/conda/4.5.4/envs/pangeo_full_201909/lib/python3.7/site-packages/distributed/comm/core.py", line 204, in _raise
    raise IOError(msg)
OSError: Timed out trying to connect to 'tcp://10.120.40.97:33653' after 10 s: in <distributed.comm.tcp.TCPConnector object at 0x2aaceb78bfd0>: ConnectionRefusedError: [Errno 111] Connection refused
tornado.application - ERROR - Exception in callback functools.partial(<bound method IOLoop._discard_future_result of <tornado.platform.asyncio.AsyncIOLoop object at 0x2aacd5e9eb38>>, <Task finished coro=<Worker.heartbeat() done, defined at /softs/rh7/conda/4.5.4/envs/pangeo_full_201909/lib/python3.7/site-packages/distributed/worker.py:866> exception=OSError("Timed out trying to connect to 'tcp://10.120.40.97:33653' after 10 s: in <distributed.comm.tcp.TCPConnector object at 0x2aaceb78b470>: ConnectionRefusedError: [Errno 111] Connection refused")>)
Traceback (most recent call last):
  File "/softs/rh7/conda/4.5.4/envs/pangeo_full_201909/lib/python3.7/site-packages/distributed/comm/core.py", line 215, in connect
    quiet_exceptions=EnvironmentError,
tornado.util.TimeoutError: Timeout

During handling of the above exception, another exception occurred:

Traceback (most recent call last):
  File "/softs/rh7/conda/4.5.4/envs/pangeo_full_201909/lib/python3.7/site-packages/tornado/ioloop.py", line 743, in _run_callback
    ret = callback()
  File "/softs/rh7/conda/4.5.4/envs/pangeo_full_201909/lib/python3.7/site-packages/tornado/ioloop.py", line 767, in _discard_future_result
    future.result()
  File "/softs/rh7/conda/4.5.4/envs/pangeo_full_201909/lib/python3.7/site-packages/distributed/worker.py", line 875, in heartbeat
    metrics=await self.get_metrics(),
  File "/softs/rh7/conda/4.5.4/envs/pangeo_full_201909/lib/python3.7/site-packages/distributed/core.py", line 747, in send_recv_from_rpc
    comm = await self.pool.connect(self.addr)
  File "/softs/rh7/conda/4.5.4/envs/pangeo_full_201909/lib/python3.7/site-packages/distributed/core.py", line 874, in connect
    connection_args=self.connection_args,
  File "/softs/rh7/conda/4.5.4/envs/pangeo_full_201909/lib/python3.7/site-packages/distributed/comm/core.py", line 227, in connect
    _raise(error)
  File "/softs/rh7/conda/4.5.4/envs/pangeo_full_201909/lib/python3.7/site-packages/distributed/comm/core.py", line 204, in _raise
    raise IOError(msg)
OSError: Timed out trying to connect to 'tcp://10.120.40.97:33653' after 10 s: in <distributed.comm.tcp.TCPConnector object at 0x2aaceb78b470>: ConnectionRefusedError: [Errno 111] Connection refused
tornado.application - ERROR - Exception in callback functools.partial(<bound method IOLoop._discard_future_result of <tornado.platform.asyncio.AsyncIOLoop object at 0x2aacd5e9eb38>>, <Task finished coro=<Worker.heartbeat() done, defined at /softs/rh7/conda/4.5.4/envs/pangeo_full_201909/lib/python3.7/site-packages/distributed/worker.py:866> exception=OSError("Timed out trying to connect to 'tcp://10.120.40.97:33653' after 10 s: in <distributed.comm.tcp.TCPConnector object at 0x2aaceb3ef908>: ConnectionRefusedError: [Errno 111] Connection refused")>)
Traceback (most recent call last):
  File "/softs/rh7/conda/4.5.4/envs/pangeo_full_201909/lib/python3.7/site-packages/distributed/comm/core.py", line 215, in connect
    quiet_exceptions=EnvironmentError,
tornado.util.TimeoutError: Timeout

During handling of the above exception, another exception occurred:

Traceback (most recent call last):
  File "/softs/rh7/conda/4.5.4/envs/pangeo_full_201909/lib/python3.7/site-packages/tornado/ioloop.py", line 743, in _run_callback
    ret = callback()
  File "/softs/rh7/conda/4.5.4/envs/pangeo_full_201909/lib/python3.7/site-packages/tornado/ioloop.py", line 767, in _discard_future_result
    future.result()
  File "/softs/rh7/conda/4.5.4/envs/pangeo_full_201909/lib/python3.7/site-packages/distributed/worker.py", line 875, in heartbeat
    metrics=await self.get_metrics(),
  File "/softs/rh7/conda/4.5.4/envs/pangeo_full_201909/lib/python3.7/site-packages/distributed/core.py", line 747, in send_recv_from_rpc
    comm = await self.pool.connect(self.addr)
  File "/softs/rh7/conda/4.5.4/envs/pangeo_full_201909/lib/python3.7/site-packages/distributed/core.py", line 874, in connect
    connection_args=self.connection_args,
  File "/softs/rh7/conda/4.5.4/envs/pangeo_full_201909/lib/python3.7/site-packages/distributed/comm/core.py", line 227, in connect
    _raise(error)
  File "/softs/rh7/conda/4.5.4/envs/pangeo_full_201909/lib/python3.7/site-packages/distributed/comm/core.py", line 204, in _raise
    raise IOError(msg)
OSError: Timed out trying to connect to 'tcp://10.120.40.97:33653' after 10 s: in <distributed.comm.tcp.TCPConnector object at 0x2aaceb3ef908>: ConnectionRefusedError: [Errno 111] Connection refused
tornado.application - ERROR - Exception in callback <function Worker._register_with_scheduler.<locals>.<lambda> at 0x2aace90462f0>
Traceback (most recent call last):
  File "/softs/rh7/conda/4.5.4/envs/pangeo_full_201909/lib/python3.7/site-packages/tornado/ioloop.py", line 907, in _run
    return self.callback()
  File "/softs/rh7/conda/4.5.4/envs/pangeo_full_201909/lib/python3.7/site-packages/distributed/worker.py", line 857, in <lambda>
    lambda: self.batched_stream.send({"op": "keep-alive"}),
  File "/softs/rh7/conda/4.5.4/envs/pangeo_full_201909/lib/python3.7/site-packages/distributed/batched.py", line 117, in send
    raise CommClosedError
distributed.comm.core.CommClosedError
tornado.application - ERROR - Exception in callback functools.partial(<bound method IOLoop._discard_future_result of <tornado.platform.asyncio.AsyncIOLoop object at 0x2aacd5e9eb38>>, <Task finished coro=<Worker.heartbeat() done, defined at /softs/rh7/conda/4.5.4/envs/pangeo_full_201909/lib/python3.7/site-packages/distributed/worker.py:866> exception=OSError("Timed out trying to connect to 'tcp://10.120.40.97:33653' after 10 s: in <distributed.comm.tcp.TCPConnector object at 0x2aaceb693400>: ConnectionRefusedError: [Errno 111] Connection refused")>)
Traceback (most recent call last):
  File "/softs/rh7/conda/4.5.4/envs/pangeo_full_201909/lib/python3.7/site-packages/distributed/comm/core.py", line 215, in connect
    quiet_exceptions=EnvironmentError,
tornado.util.TimeoutError: Timeout

During handling of the above exception, another exception occurred:

Traceback (most recent call last):
  File "/softs/rh7/conda/4.5.4/envs/pangeo_full_201909/lib/python3.7/site-packages/tornado/ioloop.py", line 743, in _run_callback
    ret = callback()
  File "/softs/rh7/conda/4.5.4/envs/pangeo_full_201909/lib/python3.7/site-packages/tornado/ioloop.py", line 767, in _discard_future_result
    future.result()
  File "/softs/rh7/conda/4.5.4/envs/pangeo_full_201909/lib/python3.7/site-packages/distributed/worker.py", line 875, in heartbeat
    metrics=await self.get_metrics(),
  File "/softs/rh7/conda/4.5.4/envs/pangeo_full_201909/lib/python3.7/site-packages/distributed/core.py", line 747, in send_recv_from_rpc
    comm = await self.pool.connect(self.addr)
  File "/softs/rh7/conda/4.5.4/envs/pangeo_full_201909/lib/python3.7/site-packages/distributed/core.py", line 874, in connect
    connection_args=self.connection_args,
  File "/softs/rh7/conda/4.5.4/envs/pangeo_full_201909/lib/python3.7/site-packages/distributed/comm/core.py", line 227, in connect
    _raise(error)
  File "/softs/rh7/conda/4.5.4/envs/pangeo_full_201909/lib/python3.7/site-packages/distributed/comm/core.py", line 204, in _raise
    raise IOError(msg)
OSError: Timed out trying to connect to 'tcp://10.120.40.97:33653' after 10 s: in <distributed.comm.tcp.TCPConnector object at 0x2aaceb693400>: ConnectionRefusedError: [Errno 111] Connection refused
tornado.application - ERROR - Exception in callback functools.partial(<bound method IOLoop._discard_future_result of <tornado.platform.asyncio.AsyncIOLoop object at 0x2aacd5e9eb38>>, <Task finished coro=<Worker.heartbeat() done, defined at /softs/rh7/conda/4.5.4/envs/pangeo_full_201909/lib/python3.7/site-packages/distributed/worker.py:866> exception=OSError("Timed out trying to connect to 'tcp://10.120.40.97:33653' after 10 s: in <distributed.comm.tcp.TCPConnector object at 0x2aaceada49e8>: ConnectionRefusedError: [Errno 111] Connection refused")>)
Traceback (most recent call last):
  File "/softs/rh7/conda/4.5.4/envs/pangeo_full_201909/lib/python3.7/site-packages/distributed/comm/core.py", line 215, in connect
    quiet_exceptions=EnvironmentError,
tornado.util.TimeoutError: Timeout

During handling of the above exception, another exception occurred:

Traceback (most recent call last):
  File "/softs/rh7/conda/4.5.4/envs/pangeo_full_201909/lib/python3.7/site-packages/tornado/ioloop.py", line 743, in _run_callback
    ret = callback()
  File "/softs/rh7/conda/4.5.4/envs/pangeo_full_201909/lib/python3.7/site-packages/tornado/ioloop.py", line 767, in _discard_future_result
    future.result()
  File "/softs/rh7/conda/4.5.4/envs/pangeo_full_201909/lib/python3.7/site-packages/distributed/worker.py", line 875, in heartbeat
    metrics=await self.get_metrics(),
  File "/softs/rh7/conda/4.5.4/envs/pangeo_full_201909/lib/python3.7/site-packages/distributed/core.py", line 747, in send_recv_from_rpc
    comm = await self.pool.connect(self.addr)
  File "/softs/rh7/conda/4.5.4/envs/pangeo_full_201909/lib/python3.7/site-packages/distributed/core.py", line 874, in connect
    connection_args=self.connection_args,
  File "/softs/rh7/conda/4.5.4/envs/pangeo_full_201909/lib/python3.7/site-packages/distributed/comm/core.py", line 227, in connect
    _raise(error)
  File "/softs/rh7/conda/4.5.4/envs/pangeo_full_201909/lib/python3.7/site-packages/distributed/comm/core.py", line 204, in _raise
    raise IOError(msg)
OSError: Timed out trying to connect to 'tcp://10.120.40.97:33653' after 10 s: in <distributed.comm.tcp.TCPConnector object at 0x2aaceada49e8>: ConnectionRefusedError: [Errno 111] Connection refused
tornado.application - ERROR - Exception in callback functools.partial(<bound method IOLoop._discard_future_result of <tornado.platform.asyncio.AsyncIOLoop object at 0x2aacd5e9eb38>>, <Task finished coro=<Worker.heartbeat() done, defined at /softs/rh7/conda/4.5.4/envs/pangeo_full_201909/lib/python3.7/site-packages/distributed/worker.py:866> exception=OSError("Timed out trying to connect to 'tcp://10.120.40.97:33653' after 10 s: in <distributed.comm.tcp.TCPConnector object at 0x2aaceb693c88>: ConnectionRefusedError: [Errno 111] Connection refused")>)
Traceback (most recent call last):
  File "/softs/rh7/conda/4.5.4/envs/pangeo_full_201909/lib/python3.7/site-packages/distributed/comm/core.py", line 215, in connect
    quiet_exceptions=EnvironmentError,
tornado.util.TimeoutError: Timeout

During handling of the above exception, another exception occurred:

Traceback (most recent call last):
  File "/softs/rh7/conda/4.5.4/envs/pangeo_full_201909/lib/python3.7/site-packages/tornado/ioloop.py", line 743, in _run_callback
    ret = callback()
  File "/softs/rh7/conda/4.5.4/envs/pangeo_full_201909/lib/python3.7/site-packages/tornado/ioloop.py", line 767, in _discard_future_result
    future.result()
  File "/softs/rh7/conda/4.5.4/envs/pangeo_full_201909/lib/python3.7/site-packages/distributed/worker.py", line 875, in heartbeat
    metrics=await self.get_metrics(),
  File "/softs/rh7/conda/4.5.4/envs/pangeo_full_201909/lib/python3.7/site-packages/distributed/core.py", line 747, in send_recv_from_rpc
    comm = await self.pool.connect(self.addr)
  File "/softs/rh7/conda/4.5.4/envs/pangeo_full_201909/lib/python3.7/site-packages/distributed/core.py", line 874, in connect
    connection_args=self.connection_args,
  File "/softs/rh7/conda/4.5.4/envs/pangeo_full_201909/lib/python3.7/site-packages/distributed/comm/core.py", line 227, in connect
    _raise(error)
  File "/softs/rh7/conda/4.5.4/envs/pangeo_full_201909/lib/python3.7/site-packages/distributed/comm/core.py", line 204, in _raise
    raise IOError(msg)
OSError: Timed out trying to connect to 'tcp://10.120.40.97:33653' after 10 s: in <distributed.comm.tcp.TCPConnector object at 0x2aaceb693c88>: ConnectionRefusedError: [Errno 111] Connection refused
tornado.application - ERROR - Exception in callback functools.partial(<bound method IOLoop._discard_future_result of <tornado.platform.asyncio.AsyncIOLoop object at 0x2aacd5e9eb38>>, <Task finished coro=<Worker.heartbeat() done, defined at /softs/rh7/conda/4.5.4/envs/pangeo_full_201909/lib/python3.7/site-packages/distributed/worker.py:866> exception=OSError("Timed out trying to connect to 'tcp://10.120.40.97:33653' after 10 s: in <distributed.comm.tcp.TCPConnector object at 0x2aaceada46d8>: ConnectionRefusedError: [Errno 111] Connection refused")>)
Traceback (most recent call last):
  File "/softs/rh7/conda/4.5.4/envs/pangeo_full_201909/lib/python3.7/site-packages/distributed/comm/core.py", line 215, in connect
    quiet_exceptions=EnvironmentError,
tornado.util.TimeoutError: Timeout

During handling of the above exception, another exception occurred:

Traceback (most recent call last):
  File "/softs/rh7/conda/4.5.4/envs/pangeo_full_201909/lib/python3.7/site-packages/tornado/ioloop.py", line 743, in _run_callback
    ret = callback()
  File "/softs/rh7/conda/4.5.4/envs/pangeo_full_201909/lib/python3.7/site-packages/tornado/ioloop.py", line 767, in _discard_future_result
    future.result()
  File "/softs/rh7/conda/4.5.4/envs/pangeo_full_201909/lib/python3.7/site-packages/distributed/worker.py", line 875, in heartbeat
    metrics=await self.get_metrics(),
  File "/softs/rh7/conda/4.5.4/envs/pangeo_full_201909/lib/python3.7/site-packages/distributed/core.py", line 747, in send_recv_from_rpc
    comm = await self.pool.connect(self.addr)
  File "/softs/rh7/conda/4.5.4/envs/pangeo_full_201909/lib/python3.7/site-packages/distributed/core.py", line 874, in connect
    connection_args=self.connection_args,
  File "/softs/rh7/conda/4.5.4/envs/pangeo_full_201909/lib/python3.7/site-packages/distributed/comm/core.py", line 227, in connect
    _raise(error)
  File "/softs/rh7/conda/4.5.4/envs/pangeo_full_201909/lib/python3.7/site-packages/distributed/comm/core.py", line 204, in _raise
    raise IOError(msg)
OSError: Timed out trying to connect to 'tcp://10.120.40.97:33653' after 10 s: in <distributed.comm.tcp.TCPConnector object at 0x2aaceada46d8>: ConnectionRefusedError: [Errno 111] Connection refused
tornado.application - ERROR - Exception in callback functools.partial(<bound method IOLoop._discard_future_result of <tornado.platform.asyncio.AsyncIOLoop object at 0x2aacd5e9eb38>>, <Task finished coro=<Worker.heartbeat() done, defined at /softs/rh7/conda/4.5.4/envs/pangeo_full_201909/lib/python3.7/site-packages/distributed/worker.py:866> exception=OSError("Timed out trying to connect to 'tcp://10.120.40.97:33653' after 10 s: in <distributed.comm.tcp.TCPConnector object at 0x2aacea7d1c50>: ConnectionRefusedError: [Errno 111] Connection refused")>)
Traceback (most recent call last):
  File "/softs/rh7/conda/4.5.4/envs/pangeo_full_201909/lib/python3.7/site-packages/distributed/comm/core.py", line 215, in connect
    quiet_exceptions=EnvironmentError,
tornado.util.TimeoutError: Timeout

During handling of the above exception, another exception occurred:

Traceback (most recent call last):
  File "/softs/rh7/conda/4.5.4/envs/pangeo_full_201909/lib/python3.7/site-packages/tornado/ioloop.py", line 743, in _run_callback
    ret = callback()
  File "/softs/rh7/conda/4.5.4/envs/pangeo_full_201909/lib/python3.7/site-packages/tornado/ioloop.py", line 767, in _discard_future_result
    future.result()
  File "/softs/rh7/conda/4.5.4/envs/pangeo_full_201909/lib/python3.7/site-packages/distributed/worker.py", line 875, in heartbeat
    metrics=await self.get_metrics(),
  File "/softs/rh7/conda/4.5.4/envs/pangeo_full_201909/lib/python3.7/site-packages/distributed/core.py", line 747, in send_recv_from_rpc
    comm = await self.pool.connect(self.addr)
  File "/softs/rh7/conda/4.5.4/envs/pangeo_full_201909/lib/python3.7/site-packages/distributed/core.py", line 874, in connect
    connection_args=self.connection_args,
  File "/softs/rh7/conda/4.5.4/envs/pangeo_full_201909/lib/python3.7/site-packages/distributed/comm/core.py", line 227, in connect
    _raise(error)
  File "/softs/rh7/conda/4.5.4/envs/pangeo_full_201909/lib/python3.7/site-packages/distributed/comm/core.py", line 204, in _raise
    raise IOError(msg)
OSError: Timed out trying to connect to 'tcp://10.120.40.97:33653' after 10 s: in <distributed.comm.tcp.TCPConnector object at 0x2aacea7d1c50>: ConnectionRefusedError: [Errno 111] Connection refused
tornado.application - ERROR - Exception in callback functools.partial(<bound method IOLoop._discard_future_result of <tornado.platform.asyncio.AsyncIOLoop object at 0x2aacd5e9eb38>>, <Task finished coro=<Worker.heartbeat() done, defined at /softs/rh7/conda/4.5.4/envs/pangeo_full_201909/lib/python3.7/site-packages/distributed/worker.py:866> exception=OSError("Timed out trying to connect to 'tcp://10.120.40.97:33653' after 10 s: in <distributed.comm.tcp.TCPConnector object at 0x2aaceb25aa20>: ConnectionRefusedError: [Errno 111] Connection refused")>)
Traceback (most recent call last):
  File "/softs/rh7/conda/4.5.4/envs/pangeo_full_201909/lib/python3.7/site-packages/distributed/comm/core.py", line 215, in connect
    quiet_exceptions=EnvironmentError,
tornado.util.TimeoutError: Timeout

During handling of the above exception, another exception occurred:

Traceback (most recent call last):
  File "/softs/rh7/conda/4.5.4/envs/pangeo_full_201909/lib/python3.7/site-packages/tornado/ioloop.py", line 743, in _run_callback
    ret = callback()
  File "/softs/rh7/conda/4.5.4/envs/pangeo_full_201909/lib/python3.7/site-packages/tornado/ioloop.py", line 767, in _discard_future_result
    future.result()
  File "/softs/rh7/conda/4.5.4/envs/pangeo_full_201909/lib/python3.7/site-packages/distributed/worker.py", line 875, in heartbeat
    metrics=await self.get_metrics(),
  File "/softs/rh7/conda/4.5.4/envs/pangeo_full_201909/lib/python3.7/site-packages/distributed/core.py", line 747, in send_recv_from_rpc
    comm = await self.pool.connect(self.addr)
  File "/softs/rh7/conda/4.5.4/envs/pangeo_full_201909/lib/python3.7/site-packages/distributed/core.py", line 874, in connect
    connection_args=self.connection_args,
  File "/softs/rh7/conda/4.5.4/envs/pangeo_full_201909/lib/python3.7/site-packages/distributed/comm/core.py", line 227, in connect
    _raise(error)
  File "/softs/rh7/conda/4.5.4/envs/pangeo_full_201909/lib/python3.7/site-packages/distributed/comm/core.py", line 204, in _raise
    raise IOError(msg)
OSError: Timed out trying to connect to 'tcp://10.120.40.97:33653' after 10 s: in <distributed.comm.tcp.TCPConnector object at 0x2aaceb25aa20>: ConnectionRefusedError: [Errno 111] Connection refused
tornado.application - ERROR - Exception in callback <function Worker._register_with_scheduler.<locals>.<lambda> at 0x2aace90462f0>
Traceback (most recent call last):
  File "/softs/rh7/conda/4.5.4/envs/pangeo_full_201909/lib/python3.7/site-packages/tornado/ioloop.py", line 907, in _run
    return self.callback()
  File "/softs/rh7/conda/4.5.4/envs/pangeo_full_201909/lib/python3.7/site-packages/distributed/worker.py", line 857, in <lambda>
    lambda: self.batched_stream.send({"op": "keep-alive"}),
  File "/softs/rh7/conda/4.5.4/envs/pangeo_full_201909/lib/python3.7/site-packages/distributed/batched.py", line 117, in send
    raise CommClosedError
distributed.comm.core.CommClosedError
tornado.application - ERROR - Exception in callback functools.partial(<bound method IOLoop._discard_future_result of <tornado.platform.asyncio.AsyncIOLoop object at 0x2aacd5e9eb38>>, <Task finished coro=<Worker.heartbeat() done, defined at /softs/rh7/conda/4.5.4/envs/pangeo_full_201909/lib/python3.7/site-packages/distributed/worker.py:866> exception=OSError("Timed out trying to connect to 'tcp://10.120.40.97:33653' after 10 s: in <distributed.comm.tcp.TCPConnector object at 0x2aacebcdaf60>: ConnectionRefusedError: [Errno 111] Connection refused")>)
Traceback (most recent call last):
  File "/softs/rh7/conda/4.5.4/envs/pangeo_full_201909/lib/python3.7/site-packages/distributed/comm/core.py", line 215, in connect
    quiet_exceptions=EnvironmentError,
tornado.util.TimeoutError: Timeout

During handling of the above exception, another exception occurred:

Traceback (most recent call last):
  File "/softs/rh7/conda/4.5.4/envs/pangeo_full_201909/lib/python3.7/site-packages/tornado/ioloop.py", line 743, in _run_callback
    ret = callback()
  File "/softs/rh7/conda/4.5.4/envs/pangeo_full_201909/lib/python3.7/site-packages/tornado/ioloop.py", line 767, in _discard_future_result
    future.result()
  File "/softs/rh7/conda/4.5.4/envs/pangeo_full_201909/lib/python3.7/site-packages/distributed/worker.py", line 875, in heartbeat
    metrics=await self.get_metrics(),
  File "/softs/rh7/conda/4.5.4/envs/pangeo_full_201909/lib/python3.7/site-packages/distributed/core.py", line 747, in send_recv_from_rpc
    comm = await self.pool.connect(self.addr)
  File "/softs/rh7/conda/4.5.4/envs/pangeo_full_201909/lib/python3.7/site-packages/distributed/core.py", line 874, in connect
    connection_args=self.connection_args,
  File "/softs/rh7/conda/4.5.4/envs/pangeo_full_201909/lib/python3.7/site-packages/distributed/comm/core.py", line 227, in connect
    _raise(error)
  File "/softs/rh7/conda/4.5.4/envs/pangeo_full_201909/lib/python3.7/site-packages/distributed/comm/core.py", line 204, in _raise
    raise IOError(msg)
OSError: Timed out trying to connect to 'tcp://10.120.40.97:33653' after 10 s: in <distributed.comm.tcp.TCPConnector object at 0x2aacebcdaf60>: ConnectionRefusedError: [Errno 111] Connection refused
tornado.application - ERROR - Exception in callback functools.partial(<bound method IOLoop._discard_future_result of <tornado.platform.asyncio.AsyncIOLoop object at 0x2aacd5e9eb38>>, <Task finished coro=<Worker.heartbeat() done, defined at /softs/rh7/conda/4.5.4/envs/pangeo_full_201909/lib/python3.7/site-packages/distributed/worker.py:866> exception=OSError("Timed out trying to connect to 'tcp://10.120.40.97:33653' after 10 s: in <distributed.comm.tcp.TCPConnector object at 0x2aaceada45f8>: ConnectionRefusedError: [Errno 111] Connection refused")>)
Traceback (most recent call last):
  File "/softs/rh7/conda/4.5.4/envs/pangeo_full_201909/lib/python3.7/site-packages/distributed/comm/core.py", line 215, in connect
    quiet_exceptions=EnvironmentError,
tornado.util.TimeoutError: Timeout

During handling of the above exception, another exception occurred:

Traceback (most recent call last):
  File "/softs/rh7/conda/4.5.4/envs/pangeo_full_201909/lib/python3.7/site-packages/tornado/ioloop.py", line 743, in _run_callback
    ret = callback()
  File "/softs/rh7/conda/4.5.4/envs/pangeo_full_201909/lib/python3.7/site-packages/tornado/ioloop.py", line 767, in _discard_future_result
    future.result()
  File "/softs/rh7/conda/4.5.4/envs/pangeo_full_201909/lib/python3.7/site-packages/distributed/worker.py", line 875, in heartbeat
    metrics=await self.get_metrics(),
  File "/softs/rh7/conda/4.5.4/envs/pangeo_full_201909/lib/python3.7/site-packages/distributed/core.py", line 747, in send_recv_from_rpc
    comm = await self.pool.connect(self.addr)
  File "/softs/rh7/conda/4.5.4/envs/pangeo_full_201909/lib/python3.7/site-packages/distributed/core.py", line 874, in connect
    connection_args=self.connection_args,
  File "/softs/rh7/conda/4.5.4/envs/pangeo_full_201909/lib/python3.7/site-packages/distributed/comm/core.py", line 227, in connect
    _raise(error)
  File "/softs/rh7/conda/4.5.4/envs/pangeo_full_201909/lib/python3.7/site-packages/distributed/comm/core.py", line 204, in _raise
    raise IOError(msg)
OSError: Timed out trying to connect to 'tcp://10.120.40.97:33653' after 10 s: in <distributed.comm.tcp.TCPConnector object at 0x2aaceada45f8>: ConnectionRefusedError: [Errno 111] Connection refused
tornado.application - ERROR - Exception in callback functools.partial(<bound method IOLoop._discard_future_result of <tornado.platform.asyncio.AsyncIOLoop object at 0x2aacd5e9eb38>>, <Task finished coro=<Worker.heartbeat() done, defined at /softs/rh7/conda/4.5.4/envs/pangeo_full_201909/lib/python3.7/site-packages/distributed/worker.py:866> exception=OSError("Timed out trying to connect to 'tcp://10.120.40.97:33653' after 10 s: in <distributed.comm.tcp.TCPConnector object at 0x2aacebcfdf60>: ConnectionRefusedError: [Errno 111] Connection refused")>)
Traceback (most recent call last):
  File "/softs/rh7/conda/4.5.4/envs/pangeo_full_201909/lib/python3.7/site-packages/distributed/comm/core.py", line 215, in connect
    quiet_exceptions=EnvironmentError,
tornado.util.TimeoutError: Timeout

During handling of the above exception, another exception occurred:

Traceback (most recent call last):
  File "/softs/rh7/conda/4.5.4/envs/pangeo_full_201909/lib/python3.7/site-packages/tornado/ioloop.py", line 743, in _run_callback
    ret = callback()
  File "/softs/rh7/conda/4.5.4/envs/pangeo_full_201909/lib/python3.7/site-packages/tornado/ioloop.py", line 767, in _discard_future_result
    future.result()
  File "/softs/rh7/conda/4.5.4/envs/pangeo_full_201909/lib/python3.7/site-packages/distributed/worker.py", line 875, in heartbeat
    metrics=await self.get_metrics(),
  File "/softs/rh7/conda/4.5.4/envs/pangeo_full_201909/lib/python3.7/site-packages/distributed/core.py", line 747, in send_recv_from_rpc
    comm = await self.pool.connect(self.addr)
  File "/softs/rh7/conda/4.5.4/envs/pangeo_full_201909/lib/python3.7/site-packages/distributed/core.py", line 874, in connect
    connection_args=self.connection_args,
  File "/softs/rh7/conda/4.5.4/envs/pangeo_full_201909/lib/python3.7/site-packages/distributed/comm/core.py", line 227, in connect
    _raise(error)
  File "/softs/rh7/conda/4.5.4/envs/pangeo_full_201909/lib/python3.7/site-packages/distributed/comm/core.py", line 204, in _raise
    raise IOError(msg)
OSError: Timed out trying to connect to 'tcp://10.120.40.97:33653' after 10 s: in <distributed.comm.tcp.TCPConnector object at 0x2aacebcfdf60>: ConnectionRefusedError: [Errno 111] Connection refused
tornado.application - ERROR - Exception in callback functools.partial(<bound method IOLoop._discard_future_result of <tornado.platform.asyncio.AsyncIOLoop object at 0x2aacd5e9eb38>>, <Task finished coro=<Worker.heartbeat() done, defined at /softs/rh7/conda/4.5.4/envs/pangeo_full_201909/lib/python3.7/site-packages/distributed/worker.py:866> exception=OSError("Timed out trying to connect to 'tcp://10.120.40.97:33653' after 10 s: in <distributed.comm.tcp.TCPConnector object at 0x2aaceb854be0>: ConnectionRefusedError: [Errno 111] Connection refused")>)
Traceback (most recent call last):
  File "/softs/rh7/conda/4.5.4/envs/pangeo_full_201909/lib/python3.7/site-packages/distributed/comm/core.py", line 215, in connect
    quiet_exceptions=EnvironmentError,
tornado.util.TimeoutError: Timeout

During handling of the above exception, another exception occurred:

Traceback (most recent call last):
  File "/softs/rh7/conda/4.5.4/envs/pangeo_full_201909/lib/python3.7/site-packages/tornado/ioloop.py", line 743, in _run_callback
    ret = callback()
  File "/softs/rh7/conda/4.5.4/envs/pangeo_full_201909/lib/python3.7/site-packages/tornado/ioloop.py", line 767, in _discard_future_result
    future.result()
  File "/softs/rh7/conda/4.5.4/envs/pangeo_full_201909/lib/python3.7/site-packages/distributed/worker.py", line 875, in heartbeat
    metrics=await self.get_metrics(),
  File "/softs/rh7/conda/4.5.4/envs/pangeo_full_201909/lib/python3.7/site-packages/distributed/core.py", line 747, in send_recv_from_rpc
    comm = await self.pool.connect(self.addr)
  File "/softs/rh7/conda/4.5.4/envs/pangeo_full_201909/lib/python3.7/site-packages/distributed/core.py", line 874, in connect
    connection_args=self.connection_args,
  File "/softs/rh7/conda/4.5.4/envs/pangeo_full_201909/lib/python3.7/site-packages/distributed/comm/core.py", line 227, in connect
    _raise(error)
  File "/softs/rh7/conda/4.5.4/envs/pangeo_full_201909/lib/python3.7/site-packages/distributed/comm/core.py", line 204, in _raise
    raise IOError(msg)
OSError: Timed out trying to connect to 'tcp://10.120.40.97:33653' after 10 s: in <distributed.comm.tcp.TCPConnector object at 0x2aaceb854be0>: ConnectionRefusedError: [Errno 111] Connection refused
tornado.application - ERROR - Exception in callback functools.partial(<bound method IOLoop._discard_future_result of <tornado.platform.asyncio.AsyncIOLoop object at 0x2aacd5e9eb38>>, <Task finished coro=<Worker.heartbeat() done, defined at /softs/rh7/conda/4.5.4/envs/pangeo_full_201909/lib/python3.7/site-packages/distributed/worker.py:866> exception=OSError("Timed out trying to connect to 'tcp://10.120.40.97:33653' after 10 s: in <distributed.comm.tcp.TCPConnector object at 0x2aacebcfdd68>: ConnectionRefusedError: [Errno 111] Connection refused")>)
Traceback (most recent call last):
  File "/softs/rh7/conda/4.5.4/envs/pangeo_full_201909/lib/python3.7/site-packages/distributed/comm/core.py", line 215, in connect
    quiet_exceptions=EnvironmentError,
tornado.util.TimeoutError: Timeout

During handling of the above exception, another exception occurred:

Traceback (most recent call last):
  File "/softs/rh7/conda/4.5.4/envs/pangeo_full_201909/lib/python3.7/site-packages/tornado/ioloop.py", line 743, in _run_callback
    ret = callback()
  File "/softs/rh7/conda/4.5.4/envs/pangeo_full_201909/lib/python3.7/site-packages/tornado/ioloop.py", line 767, in _discard_future_result
    future.result()
  File "/softs/rh7/conda/4.5.4/envs/pangeo_full_201909/lib/python3.7/site-packages/distributed/worker.py", line 875, in heartbeat
    metrics=await self.get_metrics(),
  File "/softs/rh7/conda/4.5.4/envs/pangeo_full_201909/lib/python3.7/site-packages/distributed/core.py", line 747, in send_recv_from_rpc
    comm = await self.pool.connect(self.addr)
  File "/softs/rh7/conda/4.5.4/envs/pangeo_full_201909/lib/python3.7/site-packages/distributed/core.py", line 874, in connect
    connection_args=self.connection_args,
  File "/softs/rh7/conda/4.5.4/envs/pangeo_full_201909/lib/python3.7/site-packages/distributed/comm/core.py", line 227, in connect
    _raise(error)
  File "/softs/rh7/conda/4.5.4/envs/pangeo_full_201909/lib/python3.7/site-packages/distributed/comm/core.py", line 204, in _raise
    raise IOError(msg)
OSError: Timed out trying to connect to 'tcp://10.120.40.97:33653' after 10 s: in <distributed.comm.tcp.TCPConnector object at 0x2aacebcfdd68>: ConnectionRefusedError: [Errno 111] Connection refused
tornado.application - ERROR - Exception in callback <function Worker._register_with_scheduler.<locals>.<lambda> at 0x2aace90462f0>
Traceback (most recent call last):
  File "/softs/rh7/conda/4.5.4/envs/pangeo_full_201909/lib/python3.7/site-packages/tornado/ioloop.py", line 907, in _run
    return self.callback()
  File "/softs/rh7/conda/4.5.4/envs/pangeo_full_201909/lib/python3.7/site-packages/distributed/worker.py", line 857, in <lambda>
    lambda: self.batched_stream.send({"op": "keep-alive"}),
  File "/softs/rh7/conda/4.5.4/envs/pangeo_full_201909/lib/python3.7/site-packages/distributed/batched.py", line 117, in send
    raise CommClosedError
distributed.comm.core.CommClosedError
tornado.application - ERROR - Exception in callback functools.partial(<bound method IOLoop._discard_future_result of <tornado.platform.asyncio.AsyncIOLoop object at 0x2aacd5e9eb38>>, <Task finished coro=<Worker.heartbeat() done, defined at /softs/rh7/conda/4.5.4/envs/pangeo_full_201909/lib/python3.7/site-packages/distributed/worker.py:866> exception=OSError("Timed out trying to connect to 'tcp://10.120.40.97:33653' after 10 s: in <distributed.comm.tcp.TCPConnector object at 0x2aacea7d1ef0>: ConnectionRefusedError: [Errno 111] Connection refused")>)
Traceback (most recent call last):
  File "/softs/rh7/conda/4.5.4/envs/pangeo_full_201909/lib/python3.7/site-packages/distributed/comm/core.py", line 215, in connect
    quiet_exceptions=EnvironmentError,
tornado.util.TimeoutError: Timeout

During handling of the above exception, another exception occurred:

Traceback (most recent call last):
  File "/softs/rh7/conda/4.5.4/envs/pangeo_full_201909/lib/python3.7/site-packages/tornado/ioloop.py", line 743, in _run_callback
    ret = callback()
  File "/softs/rh7/conda/4.5.4/envs/pangeo_full_201909/lib/python3.7/site-packages/tornado/ioloop.py", line 767, in _discard_future_result
    future.result()
  File "/softs/rh7/conda/4.5.4/envs/pangeo_full_201909/lib/python3.7/site-packages/distributed/worker.py", line 875, in heartbeat
    metrics=await self.get_metrics(),
  File "/softs/rh7/conda/4.5.4/envs/pangeo_full_201909/lib/python3.7/site-packages/distributed/core.py", line 747, in send_recv_from_rpc
    comm = await self.pool.connect(self.addr)
  File "/softs/rh7/conda/4.5.4/envs/pangeo_full_201909/lib/python3.7/site-packages/distributed/core.py", line 874, in connect
    connection_args=self.connection_args,
  File "/softs/rh7/conda/4.5.4/envs/pangeo_full_201909/lib/python3.7/site-packages/distributed/comm/core.py", line 227, in connect
    _raise(error)
  File "/softs/rh7/conda/4.5.4/envs/pangeo_full_201909/lib/python3.7/site-packages/distributed/comm/core.py", line 204, in _raise
    raise IOError(msg)
OSError: Timed out trying to connect to 'tcp://10.120.40.97:33653' after 10 s: in <distributed.comm.tcp.TCPConnector object at 0x2aacea7d1ef0>: ConnectionRefusedError: [Errno 111] Connection refused
tornado.application - ERROR - Exception in callback functools.partial(<bound method IOLoop._discard_future_result of <tornado.platform.asyncio.AsyncIOLoop object at 0x2aacd5e9eb38>>, <Task finished coro=<Worker.heartbeat() done, defined at /softs/rh7/conda/4.5.4/envs/pangeo_full_201909/lib/python3.7/site-packages/distributed/worker.py:866> exception=OSError("Timed out trying to connect to 'tcp://10.120.40.97:33653' after 10 s: in <distributed.comm.tcp.TCPConnector object at 0x2aacea7e7898>: ConnectionRefusedError: [Errno 111] Connection refused")>)
Traceback (most recent call last):
  File "/softs/rh7/conda/4.5.4/envs/pangeo_full_201909/lib/python3.7/site-packages/distributed/comm/core.py", line 215, in connect
    quiet_exceptions=EnvironmentError,
tornado.util.TimeoutError: Timeout

During handling of the above exception, another exception occurred:

Traceback (most recent call last):
  File "/softs/rh7/conda/4.5.4/envs/pangeo_full_201909/lib/python3.7/site-packages/tornado/ioloop.py", line 743, in _run_callback
    ret = callback()
  File "/softs/rh7/conda/4.5.4/envs/pangeo_full_201909/lib/python3.7/site-packages/tornado/ioloop.py", line 767, in _discard_future_result
    future.result()
  File "/softs/rh7/conda/4.5.4/envs/pangeo_full_201909/lib/python3.7/site-packages/distributed/worker.py", line 875, in heartbeat
    metrics=await self.get_metrics(),
  File "/softs/rh7/conda/4.5.4/envs/pangeo_full_201909/lib/python3.7/site-packages/distributed/core.py", line 747, in send_recv_from_rpc
    comm = await self.pool.connect(self.addr)
  File "/softs/rh7/conda/4.5.4/envs/pangeo_full_201909/lib/python3.7/site-packages/distributed/core.py", line 874, in connect
    connection_args=self.connection_args,
  File "/softs/rh7/conda/4.5.4/envs/pangeo_full_201909/lib/python3.7/site-packages/distributed/comm/core.py", line 227, in connect
    _raise(error)
  File "/softs/rh7/conda/4.5.4/envs/pangeo_full_201909/lib/python3.7/site-packages/distributed/comm/core.py", line 204, in _raise
    raise IOError(msg)
OSError: Timed out trying to connect to 'tcp://10.120.40.97:33653' after 10 s: in <distributed.comm.tcp.TCPConnector object at 0x2aacea7e7898>: ConnectionRefusedError: [Errno 111] Connection refused
tornado.application - ERROR - Exception in callback functools.partial(<bound method IOLoop._discard_future_result of <tornado.platform.asyncio.AsyncIOLoop object at 0x2aacd5e9eb38>>, <Task finished coro=<Worker.heartbeat() done, defined at /softs/rh7/conda/4.5.4/envs/pangeo_full_201909/lib/python3.7/site-packages/distributed/worker.py:866> exception=OSError("Timed out trying to connect to 'tcp://10.120.40.97:33653' after 10 s: in <distributed.comm.tcp.TCPConnector object at 0x2aacea7d13c8>: ConnectionRefusedError: [Errno 111] Connection refused")>)
Traceback (most recent call last):
  File "/softs/rh7/conda/4.5.4/envs/pangeo_full_201909/lib/python3.7/site-packages/distributed/comm/core.py", line 215, in connect
    quiet_exceptions=EnvironmentError,
tornado.util.TimeoutError: Timeout

During handling of the above exception, another exception occurred:

Traceback (most recent call last):
  File "/softs/rh7/conda/4.5.4/envs/pangeo_full_201909/lib/python3.7/site-packages/tornado/ioloop.py", line 743, in _run_callback
    ret = callback()
  File "/softs/rh7/conda/4.5.4/envs/pangeo_full_201909/lib/python3.7/site-packages/tornado/ioloop.py", line 767, in _discard_future_result
    future.result()
  File "/softs/rh7/conda/4.5.4/envs/pangeo_full_201909/lib/python3.7/site-packages/distributed/worker.py", line 875, in heartbeat
    metrics=await self.get_metrics(),
  File "/softs/rh7/conda/4.5.4/envs/pangeo_full_201909/lib/python3.7/site-packages/distributed/core.py", line 747, in send_recv_from_rpc
    comm = await self.pool.connect(self.addr)
  File "/softs/rh7/conda/4.5.4/envs/pangeo_full_201909/lib/python3.7/site-packages/distributed/core.py", line 874, in connect
    connection_args=self.connection_args,
  File "/softs/rh7/conda/4.5.4/envs/pangeo_full_201909/lib/python3.7/site-packages/distributed/comm/core.py", line 227, in connect
    _raise(error)
  File "/softs/rh7/conda/4.5.4/envs/pangeo_full_201909/lib/python3.7/site-packages/distributed/comm/core.py", line 204, in _raise
    raise IOError(msg)
OSError: Timed out trying to connect to 'tcp://10.120.40.97:33653' after 10 s: in <distributed.comm.tcp.TCPConnector object at 0x2aacea7d13c8>: ConnectionRefusedError: [Errno 111] Connection refused
tornado.application - ERROR - Exception in callback functools.partial(<bound method IOLoop._discard_future_result of <tornado.platform.asyncio.AsyncIOLoop object at 0x2aacd5e9eb38>>, <Task finished coro=<Worker.heartbeat() done, defined at /softs/rh7/conda/4.5.4/envs/pangeo_full_201909/lib/python3.7/site-packages/distributed/worker.py:866> exception=OSError("Timed out trying to connect to 'tcp://10.120.40.97:33653' after 10 s: in <distributed.comm.tcp.TCPConnector object at 0x2aaceb854a20>: ConnectionRefusedError: [Errno 111] Connection refused")>)
Traceback (most recent call last):
  File "/softs/rh7/conda/4.5.4/envs/pangeo_full_201909/lib/python3.7/site-packages/distributed/comm/core.py", line 215, in connect
    quiet_exceptions=EnvironmentError,
tornado.util.TimeoutError: Timeout

During handling of the above exception, another exception occurred:

Traceback (most recent call last):
  File "/softs/rh7/conda/4.5.4/envs/pangeo_full_201909/lib/python3.7/site-packages/tornado/ioloop.py", line 743, in _run_callback
    ret = callback()
  File "/softs/rh7/conda/4.5.4/envs/pangeo_full_201909/lib/python3.7/site-packages/tornado/ioloop.py", line 767, in _discard_future_result
    future.result()
  File "/softs/rh7/conda/4.5.4/envs/pangeo_full_201909/lib/python3.7/site-packages/distributed/worker.py", line 875, in heartbeat
    metrics=await self.get_metrics(),
  File "/softs/rh7/conda/4.5.4/envs/pangeo_full_201909/lib/python3.7/site-packages/distributed/core.py", line 747, in send_recv_from_rpc
    comm = await self.pool.connect(self.addr)
  File "/softs/rh7/conda/4.5.4/envs/pangeo_full_201909/lib/python3.7/site-packages/distributed/core.py", line 874, in connect
    connection_args=self.connection_args,
  File "/softs/rh7/conda/4.5.4/envs/pangeo_full_201909/lib/python3.7/site-packages/distributed/comm/core.py", line 227, in connect
    _raise(error)
  File "/softs/rh7/conda/4.5.4/envs/pangeo_full_201909/lib/python3.7/site-packages/distributed/comm/core.py", line 204, in _raise
    raise IOError(msg)
OSError: Timed out trying to connect to 'tcp://10.120.40.97:33653' after 10 s: in <distributed.comm.tcp.TCPConnector object at 0x2aaceb854a20>: ConnectionRefusedError: [Errno 111] Connection refused
tornado.application - ERROR - Exception in callback functools.partial(<bound method IOLoop._discard_future_result of <tornado.platform.asyncio.AsyncIOLoop object at 0x2aacd5e9eb38>>, <Task finished coro=<Worker.heartbeat() done, defined at /softs/rh7/conda/4.5.4/envs/pangeo_full_201909/lib/python3.7/site-packages/distributed/worker.py:866> exception=OSError("Timed out trying to connect to 'tcp://10.120.40.97:33653' after 10 s: in <distributed.comm.tcp.TCPConnector object at 0x2aaceb78b588>: ConnectionRefusedError: [Errno 111] Connection refused")>)
Traceback (most recent call last):
  File "/softs/rh7/conda/4.5.4/envs/pangeo_full_201909/lib/python3.7/site-packages/distributed/comm/core.py", line 215, in connect
    quiet_exceptions=EnvironmentError,
tornado.util.TimeoutError: Timeout

During handling of the above exception, another exception occurred:

Traceback (most recent call last):
  File "/softs/rh7/conda/4.5.4/envs/pangeo_full_201909/lib/python3.7/site-packages/tornado/ioloop.py", line 743, in _run_callback
    ret = callback()
  File "/softs/rh7/conda/4.5.4/envs/pangeo_full_201909/lib/python3.7/site-packages/tornado/ioloop.py", line 767, in _discard_future_result
    future.result()
  File "/softs/rh7/conda/4.5.4/envs/pangeo_full_201909/lib/python3.7/site-packages/distributed/worker.py", line 875, in heartbeat
    metrics=await self.get_metrics(),
  File "/softs/rh7/conda/4.5.4/envs/pangeo_full_201909/lib/python3.7/site-packages/distributed/core.py", line 747, in send_recv_from_rpc
    comm = await self.pool.connect(self.addr)
  File "/softs/rh7/conda/4.5.4/envs/pangeo_full_201909/lib/python3.7/site-packages/distributed/core.py", line 874, in connect
    connection_args=self.connection_args,
  File "/softs/rh7/conda/4.5.4/envs/pangeo_full_201909/lib/python3.7/site-packages/distributed/comm/core.py", line 227, in connect
    _raise(error)
  File "/softs/rh7/conda/4.5.4/envs/pangeo_full_201909/lib/python3.7/site-packages/distributed/comm/core.py", line 204, in _raise
    raise IOError(msg)
OSError: Timed out trying to connect to 'tcp://10.120.40.97:33653' after 10 s: in <distributed.comm.tcp.TCPConnector object at 0x2aaceb78b588>: ConnectionRefusedError: [Errno 111] Connection refused
=>> PBS: job killed: walltime 1802 exceeded limit 1800
distributed.dask_worker - INFO - Exiting on signal 15
distributed.nanny - INFO - Closing Nanny at 'tcp://10.120.40.53:45053'
distributed.dask_worker - INFO - End worker
Traceback (most recent call last):
  File "/softs/rh7/conda/4.5.4/envs/pangeo_full_201909/lib/python3.7/runpy.py", line 193, in _run_module_as_main
    "__main__", mod_spec)
  File "/softs/rh7/conda/4.5.4/envs/pangeo_full_201909/lib/python3.7/runpy.py", line 85, in _run_code
    exec(code, run_globals)
  File "/softs/rh7/conda/4.5.4/envs/pangeo_full_201909/lib/python3.7/site-packages/distributed/cli/dask_worker.py", line 410, in <module>
    go()
  File "/softs/rh7/conda/4.5.4/envs/pangeo_full_201909/lib/python3.7/site-packages/distributed/cli/dask_worker.py", line 406, in go
    main()
  File "/softs/rh7/conda/4.5.4/envs/pangeo_full_201909/lib/python3.7/site-packages/click/core.py", line 764, in __call__
    return self.main(*args, **kwargs)
  File "/softs/rh7/conda/4.5.4/envs/pangeo_full_201909/lib/python3.7/site-packages/click/core.py", line 717, in main
    rv = self.invoke(ctx)
  File "/softs/rh7/conda/4.5.4/envs/pangeo_full_201909/lib/python3.7/site-packages/click/core.py", line 956, in invoke
    return ctx.invoke(self.callback, **ctx.params)
  File "/softs/rh7/conda/4.5.4/envs/pangeo_full_201909/lib/python3.7/site-packages/click/core.py", line 555, in invoke
    return callback(*args, **kwargs)
  File "/softs/rh7/conda/4.5.4/envs/pangeo_full_201909/lib/python3.7/site-packages/distributed/cli/dask_worker.py", line 397, in main
    raise TimeoutError("Timed out starting worker.") from None
tornado.util.TimeoutError: Timed out starting worker.
