distributed.nanny - INFO -         Start Nanny at: 'tcp://10.120.40.72:38848'
distributed.worker - INFO -       Start worker at:   tcp://10.120.40.72:40069
distributed.worker - INFO -          Listening to:   tcp://10.120.40.72:40069
distributed.worker - INFO -          dashboard at:         10.120.40.72:34346
distributed.worker - INFO - Waiting to connect to:   tcp://10.120.40.97:33653
distributed.worker - INFO - -------------------------------------------------
distributed.worker - INFO -               Threads:                          1
distributed.worker - INFO -                Memory:                  120.00 GB
distributed.worker - INFO -       Local Directory: /tmp/pbs.6182553.admin01/worker-z87aha8a
distributed.worker - INFO - -------------------------------------------------
distributed.worker - INFO -         Registered to:   tcp://10.120.40.97:33653
distributed.worker - INFO - -------------------------------------------------
distributed.core - INFO - Starting established connection
/softs/rh7/conda/4.5.4/envs/pangeo_full_201909/lib/python3.7/site-packages/dask/core.py:119: RuntimeWarning: invalid value encountered in less
  return func(*args2)
distributed.utils_perf - INFO - full garbage collection released 18.10 MB from 797 reference cycles (threshold: 10.00 MB)
distributed.worker - INFO - Connection to scheduler broken.  Reconnecting...
distributed.worker - WARNING - Heartbeat to scheduler failed
tornado.application - ERROR - Exception in callback functools.partial(<bound method IOLoop._discard_future_result of <tornado.platform.asyncio.AsyncIOLoop object at 0x2b2433c61c88>>, <Task finished coro=<Worker.heartbeat() done, defined at /softs/rh7/conda/4.5.4/envs/pangeo_full_201909/lib/python3.7/site-packages/distributed/worker.py:866> exception=OSError("Timed out trying to connect to 'tcp://10.120.40.97:33653' after 10 s: in <distributed.comm.tcp.TCPConnector object at 0x2b244d484748>: ConnectionRefusedError: [Errno 111] Connection refused")>)
Traceback (most recent call last):
  File "/softs/rh7/conda/4.5.4/envs/pangeo_full_201909/lib/python3.7/site-packages/distributed/comm/core.py", line 215, in connect
    quiet_exceptions=EnvironmentError,
tornado.util.TimeoutError: Timeout

During handling of the above exception, another exception occurred:

Traceback (most recent call last):
  File "/softs/rh7/conda/4.5.4/envs/pangeo_full_201909/lib/python3.7/site-packages/tornado/ioloop.py", line 743, in _run_callback
    ret = callback()
  File "/softs/rh7/conda/4.5.4/envs/pangeo_full_201909/lib/python3.7/site-packages/tornado/ioloop.py", line 767, in _discard_future_result
    future.result()
  File "/softs/rh7/conda/4.5.4/envs/pangeo_full_201909/lib/python3.7/site-packages/distributed/worker.py", line 875, in heartbeat
    metrics=await self.get_metrics(),
  File "/softs/rh7/conda/4.5.4/envs/pangeo_full_201909/lib/python3.7/site-packages/distributed/core.py", line 747, in send_recv_from_rpc
    comm = await self.pool.connect(self.addr)
  File "/softs/rh7/conda/4.5.4/envs/pangeo_full_201909/lib/python3.7/site-packages/distributed/core.py", line 874, in connect
    connection_args=self.connection_args,
  File "/softs/rh7/conda/4.5.4/envs/pangeo_full_201909/lib/python3.7/site-packages/distributed/comm/core.py", line 227, in connect
    _raise(error)
  File "/softs/rh7/conda/4.5.4/envs/pangeo_full_201909/lib/python3.7/site-packages/distributed/comm/core.py", line 204, in _raise
    raise IOError(msg)
OSError: Timed out trying to connect to 'tcp://10.120.40.97:33653' after 10 s: in <distributed.comm.tcp.TCPConnector object at 0x2b244d484748>: ConnectionRefusedError: [Errno 111] Connection refused
tornado.application - ERROR - Exception in callback functools.partial(<bound method IOLoop._discard_future_result of <tornado.platform.asyncio.AsyncIOLoop object at 0x2b2433c61c88>>, <Task finished coro=<Worker.heartbeat() done, defined at /softs/rh7/conda/4.5.4/envs/pangeo_full_201909/lib/python3.7/site-packages/distributed/worker.py:866> exception=OSError("Timed out trying to connect to 'tcp://10.120.40.97:33653' after 10 s: in <distributed.comm.tcp.TCPConnector object at 0x2b244dd06eb8>: ConnectionRefusedError: [Errno 111] Connection refused")>)
Traceback (most recent call last):
  File "/softs/rh7/conda/4.5.4/envs/pangeo_full_201909/lib/python3.7/site-packages/distributed/comm/core.py", line 215, in connect
    quiet_exceptions=EnvironmentError,
tornado.util.TimeoutError: Timeout

During handling of the above exception, another exception occurred:

Traceback (most recent call last):
  File "/softs/rh7/conda/4.5.4/envs/pangeo_full_201909/lib/python3.7/site-packages/tornado/ioloop.py", line 743, in _run_callback
    ret = callback()
  File "/softs/rh7/conda/4.5.4/envs/pangeo_full_201909/lib/python3.7/site-packages/tornado/ioloop.py", line 767, in _discard_future_result
    future.result()
  File "/softs/rh7/conda/4.5.4/envs/pangeo_full_201909/lib/python3.7/site-packages/distributed/worker.py", line 875, in heartbeat
    metrics=await self.get_metrics(),
  File "/softs/rh7/conda/4.5.4/envs/pangeo_full_201909/lib/python3.7/site-packages/distributed/core.py", line 747, in send_recv_from_rpc
    comm = await self.pool.connect(self.addr)
  File "/softs/rh7/conda/4.5.4/envs/pangeo_full_201909/lib/python3.7/site-packages/distributed/core.py", line 874, in connect
    connection_args=self.connection_args,
  File "/softs/rh7/conda/4.5.4/envs/pangeo_full_201909/lib/python3.7/site-packages/distributed/comm/core.py", line 227, in connect
    _raise(error)
  File "/softs/rh7/conda/4.5.4/envs/pangeo_full_201909/lib/python3.7/site-packages/distributed/comm/core.py", line 204, in _raise
    raise IOError(msg)
OSError: Timed out trying to connect to 'tcp://10.120.40.97:33653' after 10 s: in <distributed.comm.tcp.TCPConnector object at 0x2b244dd06eb8>: ConnectionRefusedError: [Errno 111] Connection refused
tornado.application - ERROR - Exception in callback functools.partial(<bound method IOLoop._discard_future_result of <tornado.platform.asyncio.AsyncIOLoop object at 0x2b2433c61c88>>, <Task finished coro=<Worker.heartbeat() done, defined at /softs/rh7/conda/4.5.4/envs/pangeo_full_201909/lib/python3.7/site-packages/distributed/worker.py:866> exception=OSError("Timed out trying to connect to 'tcp://10.120.40.97:33653' after 10 s: in <distributed.comm.tcp.TCPConnector object at 0x2b244e382b70>: ConnectionRefusedError: [Errno 111] Connection refused")>)
Traceback (most recent call last):
  File "/softs/rh7/conda/4.5.4/envs/pangeo_full_201909/lib/python3.7/site-packages/distributed/comm/core.py", line 215, in connect
    quiet_exceptions=EnvironmentError,
tornado.util.TimeoutError: Timeout

During handling of the above exception, another exception occurred:

Traceback (most recent call last):
  File "/softs/rh7/conda/4.5.4/envs/pangeo_full_201909/lib/python3.7/site-packages/tornado/ioloop.py", line 743, in _run_callback
    ret = callback()
  File "/softs/rh7/conda/4.5.4/envs/pangeo_full_201909/lib/python3.7/site-packages/tornado/ioloop.py", line 767, in _discard_future_result
    future.result()
  File "/softs/rh7/conda/4.5.4/envs/pangeo_full_201909/lib/python3.7/site-packages/distributed/worker.py", line 875, in heartbeat
    metrics=await self.get_metrics(),
  File "/softs/rh7/conda/4.5.4/envs/pangeo_full_201909/lib/python3.7/site-packages/distributed/core.py", line 747, in send_recv_from_rpc
    comm = await self.pool.connect(self.addr)
  File "/softs/rh7/conda/4.5.4/envs/pangeo_full_201909/lib/python3.7/site-packages/distributed/core.py", line 874, in connect
    connection_args=self.connection_args,
  File "/softs/rh7/conda/4.5.4/envs/pangeo_full_201909/lib/python3.7/site-packages/distributed/comm/core.py", line 227, in connect
    _raise(error)
  File "/softs/rh7/conda/4.5.4/envs/pangeo_full_201909/lib/python3.7/site-packages/distributed/comm/core.py", line 204, in _raise
    raise IOError(msg)
OSError: Timed out trying to connect to 'tcp://10.120.40.97:33653' after 10 s: in <distributed.comm.tcp.TCPConnector object at 0x2b244e382b70>: ConnectionRefusedError: [Errno 111] Connection refused
tornado.application - ERROR - Exception in callback functools.partial(<bound method IOLoop._discard_future_result of <tornado.platform.asyncio.AsyncIOLoop object at 0x2b2433c61c88>>, <Task finished coro=<Worker.heartbeat() done, defined at /softs/rh7/conda/4.5.4/envs/pangeo_full_201909/lib/python3.7/site-packages/distributed/worker.py:866> exception=OSError("Timed out trying to connect to 'tcp://10.120.40.97:33653' after 10 s: in <distributed.comm.tcp.TCPConnector object at 0x2b244e576be0>: ConnectionRefusedError: [Errno 111] Connection refused")>)
Traceback (most recent call last):
  File "/softs/rh7/conda/4.5.4/envs/pangeo_full_201909/lib/python3.7/site-packages/distributed/comm/core.py", line 215, in connect
    quiet_exceptions=EnvironmentError,
tornado.util.TimeoutError: Timeout

During handling of the above exception, another exception occurred:

Traceback (most recent call last):
  File "/softs/rh7/conda/4.5.4/envs/pangeo_full_201909/lib/python3.7/site-packages/tornado/ioloop.py", line 743, in _run_callback
    ret = callback()
  File "/softs/rh7/conda/4.5.4/envs/pangeo_full_201909/lib/python3.7/site-packages/tornado/ioloop.py", line 767, in _discard_future_result
    future.result()
  File "/softs/rh7/conda/4.5.4/envs/pangeo_full_201909/lib/python3.7/site-packages/distributed/worker.py", line 875, in heartbeat
    metrics=await self.get_metrics(),
  File "/softs/rh7/conda/4.5.4/envs/pangeo_full_201909/lib/python3.7/site-packages/distributed/core.py", line 747, in send_recv_from_rpc
    comm = await self.pool.connect(self.addr)
  File "/softs/rh7/conda/4.5.4/envs/pangeo_full_201909/lib/python3.7/site-packages/distributed/core.py", line 874, in connect
    connection_args=self.connection_args,
  File "/softs/rh7/conda/4.5.4/envs/pangeo_full_201909/lib/python3.7/site-packages/distributed/comm/core.py", line 227, in connect
    _raise(error)
  File "/softs/rh7/conda/4.5.4/envs/pangeo_full_201909/lib/python3.7/site-packages/distributed/comm/core.py", line 204, in _raise
    raise IOError(msg)
OSError: Timed out trying to connect to 'tcp://10.120.40.97:33653' after 10 s: in <distributed.comm.tcp.TCPConnector object at 0x2b244e576be0>: ConnectionRefusedError: [Errno 111] Connection refused
tornado.application - ERROR - Exception in callback <function Worker._register_with_scheduler.<locals>.<lambda> at 0x2b2437efe2f0>
Traceback (most recent call last):
  File "/softs/rh7/conda/4.5.4/envs/pangeo_full_201909/lib/python3.7/site-packages/tornado/ioloop.py", line 907, in _run
    return self.callback()
  File "/softs/rh7/conda/4.5.4/envs/pangeo_full_201909/lib/python3.7/site-packages/distributed/worker.py", line 857, in <lambda>
    lambda: self.batched_stream.send({"op": "keep-alive"}),
  File "/softs/rh7/conda/4.5.4/envs/pangeo_full_201909/lib/python3.7/site-packages/distributed/batched.py", line 117, in send
    raise CommClosedError
distributed.comm.core.CommClosedError
tornado.application - ERROR - Exception in callback functools.partial(<bound method IOLoop._discard_future_result of <tornado.platform.asyncio.AsyncIOLoop object at 0x2b2433c61c88>>, <Task finished coro=<Worker.heartbeat() done, defined at /softs/rh7/conda/4.5.4/envs/pangeo_full_201909/lib/python3.7/site-packages/distributed/worker.py:866> exception=OSError("Timed out trying to connect to 'tcp://10.120.40.97:33653' after 10 s: in <distributed.comm.tcp.TCPConnector object at 0x2b244e576f98>: ConnectionRefusedError: [Errno 111] Connection refused")>)
Traceback (most recent call last):
  File "/softs/rh7/conda/4.5.4/envs/pangeo_full_201909/lib/python3.7/site-packages/distributed/comm/core.py", line 215, in connect
    quiet_exceptions=EnvironmentError,
tornado.util.TimeoutError: Timeout

During handling of the above exception, another exception occurred:

Traceback (most recent call last):
  File "/softs/rh7/conda/4.5.4/envs/pangeo_full_201909/lib/python3.7/site-packages/tornado/ioloop.py", line 743, in _run_callback
    ret = callback()
  File "/softs/rh7/conda/4.5.4/envs/pangeo_full_201909/lib/python3.7/site-packages/tornado/ioloop.py", line 767, in _discard_future_result
    future.result()
  File "/softs/rh7/conda/4.5.4/envs/pangeo_full_201909/lib/python3.7/site-packages/distributed/worker.py", line 875, in heartbeat
    metrics=await self.get_metrics(),
  File "/softs/rh7/conda/4.5.4/envs/pangeo_full_201909/lib/python3.7/site-packages/distributed/core.py", line 747, in send_recv_from_rpc
    comm = await self.pool.connect(self.addr)
  File "/softs/rh7/conda/4.5.4/envs/pangeo_full_201909/lib/python3.7/site-packages/distributed/core.py", line 874, in connect
    connection_args=self.connection_args,
  File "/softs/rh7/conda/4.5.4/envs/pangeo_full_201909/lib/python3.7/site-packages/distributed/comm/core.py", line 227, in connect
    _raise(error)
  File "/softs/rh7/conda/4.5.4/envs/pangeo_full_201909/lib/python3.7/site-packages/distributed/comm/core.py", line 204, in _raise
    raise IOError(msg)
OSError: Timed out trying to connect to 'tcp://10.120.40.97:33653' after 10 s: in <distributed.comm.tcp.TCPConnector object at 0x2b244e576f98>: ConnectionRefusedError: [Errno 111] Connection refused
tornado.application - ERROR - Exception in callback functools.partial(<bound method IOLoop._discard_future_result of <tornado.platform.asyncio.AsyncIOLoop object at 0x2b2433c61c88>>, <Task finished coro=<Worker.heartbeat() done, defined at /softs/rh7/conda/4.5.4/envs/pangeo_full_201909/lib/python3.7/site-packages/distributed/worker.py:866> exception=OSError("Timed out trying to connect to 'tcp://10.120.40.97:33653' after 10 s: in <distributed.comm.tcp.TCPConnector object at 0x2b244e576518>: ConnectionRefusedError: [Errno 111] Connection refused")>)
Traceback (most recent call last):
  File "/softs/rh7/conda/4.5.4/envs/pangeo_full_201909/lib/python3.7/site-packages/distributed/comm/core.py", line 215, in connect
    quiet_exceptions=EnvironmentError,
tornado.util.TimeoutError: Timeout

During handling of the above exception, another exception occurred:

Traceback (most recent call last):
  File "/softs/rh7/conda/4.5.4/envs/pangeo_full_201909/lib/python3.7/site-packages/tornado/ioloop.py", line 743, in _run_callback
    ret = callback()
  File "/softs/rh7/conda/4.5.4/envs/pangeo_full_201909/lib/python3.7/site-packages/tornado/ioloop.py", line 767, in _discard_future_result
    future.result()
  File "/softs/rh7/conda/4.5.4/envs/pangeo_full_201909/lib/python3.7/site-packages/distributed/worker.py", line 875, in heartbeat
    metrics=await self.get_metrics(),
  File "/softs/rh7/conda/4.5.4/envs/pangeo_full_201909/lib/python3.7/site-packages/distributed/core.py", line 747, in send_recv_from_rpc
    comm = await self.pool.connect(self.addr)
  File "/softs/rh7/conda/4.5.4/envs/pangeo_full_201909/lib/python3.7/site-packages/distributed/core.py", line 874, in connect
    connection_args=self.connection_args,
  File "/softs/rh7/conda/4.5.4/envs/pangeo_full_201909/lib/python3.7/site-packages/distributed/comm/core.py", line 227, in connect
    _raise(error)
  File "/softs/rh7/conda/4.5.4/envs/pangeo_full_201909/lib/python3.7/site-packages/distributed/comm/core.py", line 204, in _raise
    raise IOError(msg)
OSError: Timed out trying to connect to 'tcp://10.120.40.97:33653' after 10 s: in <distributed.comm.tcp.TCPConnector object at 0x2b244e576518>: ConnectionRefusedError: [Errno 111] Connection refused
tornado.application - ERROR - Exception in callback functools.partial(<bound method IOLoop._discard_future_result of <tornado.platform.asyncio.AsyncIOLoop object at 0x2b2433c61c88>>, <Task finished coro=<Worker.heartbeat() done, defined at /softs/rh7/conda/4.5.4/envs/pangeo_full_201909/lib/python3.7/site-packages/distributed/worker.py:866> exception=OSError("Timed out trying to connect to 'tcp://10.120.40.97:33653' after 10 s: in <distributed.comm.tcp.TCPConnector object at 0x2b244e61bba8>: ConnectionRefusedError: [Errno 111] Connection refused")>)
Traceback (most recent call last):
  File "/softs/rh7/conda/4.5.4/envs/pangeo_full_201909/lib/python3.7/site-packages/distributed/comm/core.py", line 215, in connect
    quiet_exceptions=EnvironmentError,
tornado.util.TimeoutError: Timeout

During handling of the above exception, another exception occurred:

Traceback (most recent call last):
  File "/softs/rh7/conda/4.5.4/envs/pangeo_full_201909/lib/python3.7/site-packages/tornado/ioloop.py", line 743, in _run_callback
    ret = callback()
  File "/softs/rh7/conda/4.5.4/envs/pangeo_full_201909/lib/python3.7/site-packages/tornado/ioloop.py", line 767, in _discard_future_result
    future.result()
  File "/softs/rh7/conda/4.5.4/envs/pangeo_full_201909/lib/python3.7/site-packages/distributed/worker.py", line 875, in heartbeat
    metrics=await self.get_metrics(),
  File "/softs/rh7/conda/4.5.4/envs/pangeo_full_201909/lib/python3.7/site-packages/distributed/core.py", line 747, in send_recv_from_rpc
    comm = await self.pool.connect(self.addr)
  File "/softs/rh7/conda/4.5.4/envs/pangeo_full_201909/lib/python3.7/site-packages/distributed/core.py", line 874, in connect
    connection_args=self.connection_args,
  File "/softs/rh7/conda/4.5.4/envs/pangeo_full_201909/lib/python3.7/site-packages/distributed/comm/core.py", line 227, in connect
    _raise(error)
  File "/softs/rh7/conda/4.5.4/envs/pangeo_full_201909/lib/python3.7/site-packages/distributed/comm/core.py", line 204, in _raise
    raise IOError(msg)
OSError: Timed out trying to connect to 'tcp://10.120.40.97:33653' after 10 s: in <distributed.comm.tcp.TCPConnector object at 0x2b244e61bba8>: ConnectionRefusedError: [Errno 111] Connection refused
tornado.application - ERROR - Exception in callback functools.partial(<bound method IOLoop._discard_future_result of <tornado.platform.asyncio.AsyncIOLoop object at 0x2b2433c61c88>>, <Task finished coro=<Worker.heartbeat() done, defined at /softs/rh7/conda/4.5.4/envs/pangeo_full_201909/lib/python3.7/site-packages/distributed/worker.py:866> exception=OSError("Timed out trying to connect to 'tcp://10.120.40.97:33653' after 10 s: in <distributed.comm.tcp.TCPConnector object at 0x2b244e61b278>: ConnectionRefusedError: [Errno 111] Connection refused")>)
Traceback (most recent call last):
  File "/softs/rh7/conda/4.5.4/envs/pangeo_full_201909/lib/python3.7/site-packages/distributed/comm/core.py", line 215, in connect
    quiet_exceptions=EnvironmentError,
tornado.util.TimeoutError: Timeout

During handling of the above exception, another exception occurred:

Traceback (most recent call last):
  File "/softs/rh7/conda/4.5.4/envs/pangeo_full_201909/lib/python3.7/site-packages/tornado/ioloop.py", line 743, in _run_callback
    ret = callback()
  File "/softs/rh7/conda/4.5.4/envs/pangeo_full_201909/lib/python3.7/site-packages/tornado/ioloop.py", line 767, in _discard_future_result
    future.result()
  File "/softs/rh7/conda/4.5.4/envs/pangeo_full_201909/lib/python3.7/site-packages/distributed/worker.py", line 875, in heartbeat
    metrics=await self.get_metrics(),
  File "/softs/rh7/conda/4.5.4/envs/pangeo_full_201909/lib/python3.7/site-packages/distributed/core.py", line 747, in send_recv_from_rpc
    comm = await self.pool.connect(self.addr)
  File "/softs/rh7/conda/4.5.4/envs/pangeo_full_201909/lib/python3.7/site-packages/distributed/core.py", line 874, in connect
    connection_args=self.connection_args,
  File "/softs/rh7/conda/4.5.4/envs/pangeo_full_201909/lib/python3.7/site-packages/distributed/comm/core.py", line 227, in connect
    _raise(error)
  File "/softs/rh7/conda/4.5.4/envs/pangeo_full_201909/lib/python3.7/site-packages/distributed/comm/core.py", line 204, in _raise
    raise IOError(msg)
OSError: Timed out trying to connect to 'tcp://10.120.40.97:33653' after 10 s: in <distributed.comm.tcp.TCPConnector object at 0x2b244e61b278>: ConnectionRefusedError: [Errno 111] Connection refused
tornado.application - ERROR - Exception in callback functools.partial(<bound method IOLoop._discard_future_result of <tornado.platform.asyncio.AsyncIOLoop object at 0x2b2433c61c88>>, <Task finished coro=<Worker.heartbeat() done, defined at /softs/rh7/conda/4.5.4/envs/pangeo_full_201909/lib/python3.7/site-packages/distributed/worker.py:866> exception=OSError("Timed out trying to connect to 'tcp://10.120.40.97:33653' after 10 s: in <distributed.comm.tcp.TCPConnector object at 0x2b244e61b3c8>: ConnectionRefusedError: [Errno 111] Connection refused")>)
Traceback (most recent call last):
  File "/softs/rh7/conda/4.5.4/envs/pangeo_full_201909/lib/python3.7/site-packages/distributed/comm/core.py", line 215, in connect
    quiet_exceptions=EnvironmentError,
tornado.util.TimeoutError: Timeout

During handling of the above exception, another exception occurred:

Traceback (most recent call last):
  File "/softs/rh7/conda/4.5.4/envs/pangeo_full_201909/lib/python3.7/site-packages/tornado/ioloop.py", line 743, in _run_callback
    ret = callback()
  File "/softs/rh7/conda/4.5.4/envs/pangeo_full_201909/lib/python3.7/site-packages/tornado/ioloop.py", line 767, in _discard_future_result
    future.result()
  File "/softs/rh7/conda/4.5.4/envs/pangeo_full_201909/lib/python3.7/site-packages/distributed/worker.py", line 875, in heartbeat
    metrics=await self.get_metrics(),
  File "/softs/rh7/conda/4.5.4/envs/pangeo_full_201909/lib/python3.7/site-packages/distributed/core.py", line 747, in send_recv_from_rpc
    comm = await self.pool.connect(self.addr)
  File "/softs/rh7/conda/4.5.4/envs/pangeo_full_201909/lib/python3.7/site-packages/distributed/core.py", line 874, in connect
    connection_args=self.connection_args,
  File "/softs/rh7/conda/4.5.4/envs/pangeo_full_201909/lib/python3.7/site-packages/distributed/comm/core.py", line 227, in connect
    _raise(error)
  File "/softs/rh7/conda/4.5.4/envs/pangeo_full_201909/lib/python3.7/site-packages/distributed/comm/core.py", line 204, in _raise
    raise IOError(msg)
OSError: Timed out trying to connect to 'tcp://10.120.40.97:33653' after 10 s: in <distributed.comm.tcp.TCPConnector object at 0x2b244e61b3c8>: ConnectionRefusedError: [Errno 111] Connection refused
tornado.application - ERROR - Exception in callback functools.partial(<bound method IOLoop._discard_future_result of <tornado.platform.asyncio.AsyncIOLoop object at 0x2b2433c61c88>>, <Task finished coro=<Worker.heartbeat() done, defined at /softs/rh7/conda/4.5.4/envs/pangeo_full_201909/lib/python3.7/site-packages/distributed/worker.py:866> exception=OSError("Timed out trying to connect to 'tcp://10.120.40.97:33653' after 10 s: in <distributed.comm.tcp.TCPConnector object at 0x2b244e659128>: ConnectionRefusedError: [Errno 111] Connection refused")>)
Traceback (most recent call last):
  File "/softs/rh7/conda/4.5.4/envs/pangeo_full_201909/lib/python3.7/site-packages/distributed/comm/core.py", line 215, in connect
    quiet_exceptions=EnvironmentError,
tornado.util.TimeoutError: Timeout

During handling of the above exception, another exception occurred:

Traceback (most recent call last):
  File "/softs/rh7/conda/4.5.4/envs/pangeo_full_201909/lib/python3.7/site-packages/tornado/ioloop.py", line 743, in _run_callback
    ret = callback()
  File "/softs/rh7/conda/4.5.4/envs/pangeo_full_201909/lib/python3.7/site-packages/tornado/ioloop.py", line 767, in _discard_future_result
    future.result()
  File "/softs/rh7/conda/4.5.4/envs/pangeo_full_201909/lib/python3.7/site-packages/distributed/worker.py", line 875, in heartbeat
    metrics=await self.get_metrics(),
  File "/softs/rh7/conda/4.5.4/envs/pangeo_full_201909/lib/python3.7/site-packages/distributed/core.py", line 747, in send_recv_from_rpc
    comm = await self.pool.connect(self.addr)
  File "/softs/rh7/conda/4.5.4/envs/pangeo_full_201909/lib/python3.7/site-packages/distributed/core.py", line 874, in connect
    connection_args=self.connection_args,
  File "/softs/rh7/conda/4.5.4/envs/pangeo_full_201909/lib/python3.7/site-packages/distributed/comm/core.py", line 227, in connect
    _raise(error)
  File "/softs/rh7/conda/4.5.4/envs/pangeo_full_201909/lib/python3.7/site-packages/distributed/comm/core.py", line 204, in _raise
    raise IOError(msg)
OSError: Timed out trying to connect to 'tcp://10.120.40.97:33653' after 10 s: in <distributed.comm.tcp.TCPConnector object at 0x2b244e659128>: ConnectionRefusedError: [Errno 111] Connection refused
tornado.application - ERROR - Exception in callback <function Worker._register_with_scheduler.<locals>.<lambda> at 0x2b2437efe2f0>
Traceback (most recent call last):
  File "/softs/rh7/conda/4.5.4/envs/pangeo_full_201909/lib/python3.7/site-packages/tornado/ioloop.py", line 907, in _run
    return self.callback()
  File "/softs/rh7/conda/4.5.4/envs/pangeo_full_201909/lib/python3.7/site-packages/distributed/worker.py", line 857, in <lambda>
    lambda: self.batched_stream.send({"op": "keep-alive"}),
  File "/softs/rh7/conda/4.5.4/envs/pangeo_full_201909/lib/python3.7/site-packages/distributed/batched.py", line 117, in send
    raise CommClosedError
distributed.comm.core.CommClosedError
tornado.application - ERROR - Exception in callback functools.partial(<bound method IOLoop._discard_future_result of <tornado.platform.asyncio.AsyncIOLoop object at 0x2b2433c61c88>>, <Task finished coro=<Worker.heartbeat() done, defined at /softs/rh7/conda/4.5.4/envs/pangeo_full_201909/lib/python3.7/site-packages/distributed/worker.py:866> exception=OSError("Timed out trying to connect to 'tcp://10.120.40.97:33653' after 10 s: in <distributed.comm.tcp.TCPConnector object at 0x2b244dd537b8>: ConnectionRefusedError: [Errno 111] Connection refused")>)
Traceback (most recent call last):
  File "/softs/rh7/conda/4.5.4/envs/pangeo_full_201909/lib/python3.7/site-packages/distributed/comm/core.py", line 215, in connect
    quiet_exceptions=EnvironmentError,
tornado.util.TimeoutError: Timeout

During handling of the above exception, another exception occurred:

Traceback (most recent call last):
  File "/softs/rh7/conda/4.5.4/envs/pangeo_full_201909/lib/python3.7/site-packages/tornado/ioloop.py", line 743, in _run_callback
    ret = callback()
  File "/softs/rh7/conda/4.5.4/envs/pangeo_full_201909/lib/python3.7/site-packages/tornado/ioloop.py", line 767, in _discard_future_result
    future.result()
  File "/softs/rh7/conda/4.5.4/envs/pangeo_full_201909/lib/python3.7/site-packages/distributed/worker.py", line 875, in heartbeat
    metrics=await self.get_metrics(),
  File "/softs/rh7/conda/4.5.4/envs/pangeo_full_201909/lib/python3.7/site-packages/distributed/core.py", line 747, in send_recv_from_rpc
    comm = await self.pool.connect(self.addr)
  File "/softs/rh7/conda/4.5.4/envs/pangeo_full_201909/lib/python3.7/site-packages/distributed/core.py", line 874, in connect
    connection_args=self.connection_args,
  File "/softs/rh7/conda/4.5.4/envs/pangeo_full_201909/lib/python3.7/site-packages/distributed/comm/core.py", line 227, in connect
    _raise(error)
  File "/softs/rh7/conda/4.5.4/envs/pangeo_full_201909/lib/python3.7/site-packages/distributed/comm/core.py", line 204, in _raise
    raise IOError(msg)
OSError: Timed out trying to connect to 'tcp://10.120.40.97:33653' after 10 s: in <distributed.comm.tcp.TCPConnector object at 0x2b244dd537b8>: ConnectionRefusedError: [Errno 111] Connection refused
tornado.application - ERROR - Exception in callback functools.partial(<bound method IOLoop._discard_future_result of <tornado.platform.asyncio.AsyncIOLoop object at 0x2b2433c61c88>>, <Task finished coro=<Worker.heartbeat() done, defined at /softs/rh7/conda/4.5.4/envs/pangeo_full_201909/lib/python3.7/site-packages/distributed/worker.py:866> exception=OSError("Timed out trying to connect to 'tcp://10.120.40.97:33653' after 10 s: in <distributed.comm.tcp.TCPConnector object at 0x2b244e0d8fd0>: ConnectionRefusedError: [Errno 111] Connection refused")>)
Traceback (most recent call last):
  File "/softs/rh7/conda/4.5.4/envs/pangeo_full_201909/lib/python3.7/site-packages/distributed/comm/core.py", line 215, in connect
    quiet_exceptions=EnvironmentError,
tornado.util.TimeoutError: Timeout

During handling of the above exception, another exception occurred:

Traceback (most recent call last):
  File "/softs/rh7/conda/4.5.4/envs/pangeo_full_201909/lib/python3.7/site-packages/tornado/ioloop.py", line 743, in _run_callback
    ret = callback()
  File "/softs/rh7/conda/4.5.4/envs/pangeo_full_201909/lib/python3.7/site-packages/tornado/ioloop.py", line 767, in _discard_future_result
    future.result()
  File "/softs/rh7/conda/4.5.4/envs/pangeo_full_201909/lib/python3.7/site-packages/distributed/worker.py", line 875, in heartbeat
    metrics=await self.get_metrics(),
  File "/softs/rh7/conda/4.5.4/envs/pangeo_full_201909/lib/python3.7/site-packages/distributed/core.py", line 747, in send_recv_from_rpc
    comm = await self.pool.connect(self.addr)
  File "/softs/rh7/conda/4.5.4/envs/pangeo_full_201909/lib/python3.7/site-packages/distributed/core.py", line 874, in connect
    connection_args=self.connection_args,
  File "/softs/rh7/conda/4.5.4/envs/pangeo_full_201909/lib/python3.7/site-packages/distributed/comm/core.py", line 227, in connect
    _raise(error)
  File "/softs/rh7/conda/4.5.4/envs/pangeo_full_201909/lib/python3.7/site-packages/distributed/comm/core.py", line 204, in _raise
    raise IOError(msg)
OSError: Timed out trying to connect to 'tcp://10.120.40.97:33653' after 10 s: in <distributed.comm.tcp.TCPConnector object at 0x2b244e0d8fd0>: ConnectionRefusedError: [Errno 111] Connection refused
tornado.application - ERROR - Exception in callback functools.partial(<bound method IOLoop._discard_future_result of <tornado.platform.asyncio.AsyncIOLoop object at 0x2b2433c61c88>>, <Task finished coro=<Worker.heartbeat() done, defined at /softs/rh7/conda/4.5.4/envs/pangeo_full_201909/lib/python3.7/site-packages/distributed/worker.py:866> exception=OSError("Timed out trying to connect to 'tcp://10.120.40.97:33653' after 10 s: in <distributed.comm.tcp.TCPConnector object at 0x2b244e576c88>: ConnectionRefusedError: [Errno 111] Connection refused")>)
Traceback (most recent call last):
  File "/softs/rh7/conda/4.5.4/envs/pangeo_full_201909/lib/python3.7/site-packages/distributed/comm/core.py", line 215, in connect
    quiet_exceptions=EnvironmentError,
tornado.util.TimeoutError: Timeout

During handling of the above exception, another exception occurred:

Traceback (most recent call last):
  File "/softs/rh7/conda/4.5.4/envs/pangeo_full_201909/lib/python3.7/site-packages/tornado/ioloop.py", line 743, in _run_callback
    ret = callback()
  File "/softs/rh7/conda/4.5.4/envs/pangeo_full_201909/lib/python3.7/site-packages/tornado/ioloop.py", line 767, in _discard_future_result
    future.result()
  File "/softs/rh7/conda/4.5.4/envs/pangeo_full_201909/lib/python3.7/site-packages/distributed/worker.py", line 875, in heartbeat
    metrics=await self.get_metrics(),
  File "/softs/rh7/conda/4.5.4/envs/pangeo_full_201909/lib/python3.7/site-packages/distributed/core.py", line 747, in send_recv_from_rpc
    comm = await self.pool.connect(self.addr)
  File "/softs/rh7/conda/4.5.4/envs/pangeo_full_201909/lib/python3.7/site-packages/distributed/core.py", line 874, in connect
    connection_args=self.connection_args,
  File "/softs/rh7/conda/4.5.4/envs/pangeo_full_201909/lib/python3.7/site-packages/distributed/comm/core.py", line 227, in connect
    _raise(error)
  File "/softs/rh7/conda/4.5.4/envs/pangeo_full_201909/lib/python3.7/site-packages/distributed/comm/core.py", line 204, in _raise
    raise IOError(msg)
OSError: Timed out trying to connect to 'tcp://10.120.40.97:33653' after 10 s: in <distributed.comm.tcp.TCPConnector object at 0x2b244e576c88>: ConnectionRefusedError: [Errno 111] Connection refused
tornado.application - ERROR - Exception in callback functools.partial(<bound method IOLoop._discard_future_result of <tornado.platform.asyncio.AsyncIOLoop object at 0x2b2433c61c88>>, <Task finished coro=<Worker.heartbeat() done, defined at /softs/rh7/conda/4.5.4/envs/pangeo_full_201909/lib/python3.7/site-packages/distributed/worker.py:866> exception=OSError("Timed out trying to connect to 'tcp://10.120.40.97:33653' after 10 s: in <distributed.comm.tcp.TCPConnector object at 0x2b244d6c9128>: ConnectionRefusedError: [Errno 111] Connection refused")>)
Traceback (most recent call last):
  File "/softs/rh7/conda/4.5.4/envs/pangeo_full_201909/lib/python3.7/site-packages/distributed/comm/core.py", line 215, in connect
    quiet_exceptions=EnvironmentError,
tornado.util.TimeoutError: Timeout

During handling of the above exception, another exception occurred:

Traceback (most recent call last):
  File "/softs/rh7/conda/4.5.4/envs/pangeo_full_201909/lib/python3.7/site-packages/tornado/ioloop.py", line 743, in _run_callback
    ret = callback()
  File "/softs/rh7/conda/4.5.4/envs/pangeo_full_201909/lib/python3.7/site-packages/tornado/ioloop.py", line 767, in _discard_future_result
    future.result()
  File "/softs/rh7/conda/4.5.4/envs/pangeo_full_201909/lib/python3.7/site-packages/distributed/worker.py", line 875, in heartbeat
    metrics=await self.get_metrics(),
  File "/softs/rh7/conda/4.5.4/envs/pangeo_full_201909/lib/python3.7/site-packages/distributed/core.py", line 747, in send_recv_from_rpc
    comm = await self.pool.connect(self.addr)
  File "/softs/rh7/conda/4.5.4/envs/pangeo_full_201909/lib/python3.7/site-packages/distributed/core.py", line 874, in connect
    connection_args=self.connection_args,
  File "/softs/rh7/conda/4.5.4/envs/pangeo_full_201909/lib/python3.7/site-packages/distributed/comm/core.py", line 227, in connect
    _raise(error)
  File "/softs/rh7/conda/4.5.4/envs/pangeo_full_201909/lib/python3.7/site-packages/distributed/comm/core.py", line 204, in _raise
    raise IOError(msg)
OSError: Timed out trying to connect to 'tcp://10.120.40.97:33653' after 10 s: in <distributed.comm.tcp.TCPConnector object at 0x2b244d6c9128>: ConnectionRefusedError: [Errno 111] Connection refused
tornado.application - ERROR - Exception in callback functools.partial(<bound method IOLoop._discard_future_result of <tornado.platform.asyncio.AsyncIOLoop object at 0x2b2433c61c88>>, <Task finished coro=<Worker.heartbeat() done, defined at /softs/rh7/conda/4.5.4/envs/pangeo_full_201909/lib/python3.7/site-packages/distributed/worker.py:866> exception=OSError("Timed out trying to connect to 'tcp://10.120.40.97:33653' after 10 s: in <distributed.comm.tcp.TCPConnector object at 0x2b244dd53eb8>: ConnectionRefusedError: [Errno 111] Connection refused")>)
Traceback (most recent call last):
  File "/softs/rh7/conda/4.5.4/envs/pangeo_full_201909/lib/python3.7/site-packages/distributed/comm/core.py", line 215, in connect
    quiet_exceptions=EnvironmentError,
tornado.util.TimeoutError: Timeout

During handling of the above exception, another exception occurred:

Traceback (most recent call last):
  File "/softs/rh7/conda/4.5.4/envs/pangeo_full_201909/lib/python3.7/site-packages/tornado/ioloop.py", line 743, in _run_callback
    ret = callback()
  File "/softs/rh7/conda/4.5.4/envs/pangeo_full_201909/lib/python3.7/site-packages/tornado/ioloop.py", line 767, in _discard_future_result
    future.result()
  File "/softs/rh7/conda/4.5.4/envs/pangeo_full_201909/lib/python3.7/site-packages/distributed/worker.py", line 875, in heartbeat
    metrics=await self.get_metrics(),
  File "/softs/rh7/conda/4.5.4/envs/pangeo_full_201909/lib/python3.7/site-packages/distributed/core.py", line 747, in send_recv_from_rpc
    comm = await self.pool.connect(self.addr)
  File "/softs/rh7/conda/4.5.4/envs/pangeo_full_201909/lib/python3.7/site-packages/distributed/core.py", line 874, in connect
    connection_args=self.connection_args,
  File "/softs/rh7/conda/4.5.4/envs/pangeo_full_201909/lib/python3.7/site-packages/distributed/comm/core.py", line 227, in connect
    _raise(error)
  File "/softs/rh7/conda/4.5.4/envs/pangeo_full_201909/lib/python3.7/site-packages/distributed/comm/core.py", line 204, in _raise
    raise IOError(msg)
OSError: Timed out trying to connect to 'tcp://10.120.40.97:33653' after 10 s: in <distributed.comm.tcp.TCPConnector object at 0x2b244dd53eb8>: ConnectionRefusedError: [Errno 111] Connection refused
tornado.application - ERROR - Exception in callback <function Worker._register_with_scheduler.<locals>.<lambda> at 0x2b2437efe2f0>
Traceback (most recent call last):
  File "/softs/rh7/conda/4.5.4/envs/pangeo_full_201909/lib/python3.7/site-packages/tornado/ioloop.py", line 907, in _run
    return self.callback()
  File "/softs/rh7/conda/4.5.4/envs/pangeo_full_201909/lib/python3.7/site-packages/distributed/worker.py", line 857, in <lambda>
    lambda: self.batched_stream.send({"op": "keep-alive"}),
  File "/softs/rh7/conda/4.5.4/envs/pangeo_full_201909/lib/python3.7/site-packages/distributed/batched.py", line 117, in send
    raise CommClosedError
distributed.comm.core.CommClosedError
tornado.application - ERROR - Exception in callback functools.partial(<bound method IOLoop._discard_future_result of <tornado.platform.asyncio.AsyncIOLoop object at 0x2b2433c61c88>>, <Task finished coro=<Worker.heartbeat() done, defined at /softs/rh7/conda/4.5.4/envs/pangeo_full_201909/lib/python3.7/site-packages/distributed/worker.py:866> exception=OSError("Timed out trying to connect to 'tcp://10.120.40.97:33653' after 10 s: in <distributed.comm.tcp.TCPConnector object at 0x2b244d6c9e48>: ConnectionRefusedError: [Errno 111] Connection refused")>)
Traceback (most recent call last):
  File "/softs/rh7/conda/4.5.4/envs/pangeo_full_201909/lib/python3.7/site-packages/distributed/comm/core.py", line 215, in connect
    quiet_exceptions=EnvironmentError,
tornado.util.TimeoutError: Timeout

During handling of the above exception, another exception occurred:

Traceback (most recent call last):
  File "/softs/rh7/conda/4.5.4/envs/pangeo_full_201909/lib/python3.7/site-packages/tornado/ioloop.py", line 743, in _run_callback
    ret = callback()
  File "/softs/rh7/conda/4.5.4/envs/pangeo_full_201909/lib/python3.7/site-packages/tornado/ioloop.py", line 767, in _discard_future_result
    future.result()
  File "/softs/rh7/conda/4.5.4/envs/pangeo_full_201909/lib/python3.7/site-packages/distributed/worker.py", line 875, in heartbeat
    metrics=await self.get_metrics(),
  File "/softs/rh7/conda/4.5.4/envs/pangeo_full_201909/lib/python3.7/site-packages/distributed/core.py", line 747, in send_recv_from_rpc
    comm = await self.pool.connect(self.addr)
  File "/softs/rh7/conda/4.5.4/envs/pangeo_full_201909/lib/python3.7/site-packages/distributed/core.py", line 874, in connect
    connection_args=self.connection_args,
  File "/softs/rh7/conda/4.5.4/envs/pangeo_full_201909/lib/python3.7/site-packages/distributed/comm/core.py", line 227, in connect
    _raise(error)
  File "/softs/rh7/conda/4.5.4/envs/pangeo_full_201909/lib/python3.7/site-packages/distributed/comm/core.py", line 204, in _raise
    raise IOError(msg)
OSError: Timed out trying to connect to 'tcp://10.120.40.97:33653' after 10 s: in <distributed.comm.tcp.TCPConnector object at 0x2b244d6c9e48>: ConnectionRefusedError: [Errno 111] Connection refused
tornado.application - ERROR - Exception in callback functools.partial(<bound method IOLoop._discard_future_result of <tornado.platform.asyncio.AsyncIOLoop object at 0x2b2433c61c88>>, <Task finished coro=<Worker.heartbeat() done, defined at /softs/rh7/conda/4.5.4/envs/pangeo_full_201909/lib/python3.7/site-packages/distributed/worker.py:866> exception=OSError("Timed out trying to connect to 'tcp://10.120.40.97:33653' after 10 s: in <distributed.comm.tcp.TCPConnector object at 0x2b244d6c9400>: ConnectionRefusedError: [Errno 111] Connection refused")>)
Traceback (most recent call last):
  File "/softs/rh7/conda/4.5.4/envs/pangeo_full_201909/lib/python3.7/site-packages/distributed/comm/core.py", line 215, in connect
    quiet_exceptions=EnvironmentError,
tornado.util.TimeoutError: Timeout

During handling of the above exception, another exception occurred:

Traceback (most recent call last):
  File "/softs/rh7/conda/4.5.4/envs/pangeo_full_201909/lib/python3.7/site-packages/tornado/ioloop.py", line 743, in _run_callback
    ret = callback()
  File "/softs/rh7/conda/4.5.4/envs/pangeo_full_201909/lib/python3.7/site-packages/tornado/ioloop.py", line 767, in _discard_future_result
    future.result()
  File "/softs/rh7/conda/4.5.4/envs/pangeo_full_201909/lib/python3.7/site-packages/distributed/worker.py", line 875, in heartbeat
    metrics=await self.get_metrics(),
  File "/softs/rh7/conda/4.5.4/envs/pangeo_full_201909/lib/python3.7/site-packages/distributed/core.py", line 747, in send_recv_from_rpc
    comm = await self.pool.connect(self.addr)
  File "/softs/rh7/conda/4.5.4/envs/pangeo_full_201909/lib/python3.7/site-packages/distributed/core.py", line 874, in connect
    connection_args=self.connection_args,
  File "/softs/rh7/conda/4.5.4/envs/pangeo_full_201909/lib/python3.7/site-packages/distributed/comm/core.py", line 227, in connect
    _raise(error)
  File "/softs/rh7/conda/4.5.4/envs/pangeo_full_201909/lib/python3.7/site-packages/distributed/comm/core.py", line 204, in _raise
    raise IOError(msg)
OSError: Timed out trying to connect to 'tcp://10.120.40.97:33653' after 10 s: in <distributed.comm.tcp.TCPConnector object at 0x2b244d6c9400>: ConnectionRefusedError: [Errno 111] Connection refused
tornado.application - ERROR - Exception in callback functools.partial(<bound method IOLoop._discard_future_result of <tornado.platform.asyncio.AsyncIOLoop object at 0x2b2433c61c88>>, <Task finished coro=<Worker.heartbeat() done, defined at /softs/rh7/conda/4.5.4/envs/pangeo_full_201909/lib/python3.7/site-packages/distributed/worker.py:866> exception=OSError("Timed out trying to connect to 'tcp://10.120.40.97:33653' after 10 s: in <distributed.comm.tcp.TCPConnector object at 0x2b244e576a90>: ConnectionRefusedError: [Errno 111] Connection refused")>)
Traceback (most recent call last):
  File "/softs/rh7/conda/4.5.4/envs/pangeo_full_201909/lib/python3.7/site-packages/distributed/comm/core.py", line 215, in connect
    quiet_exceptions=EnvironmentError,
tornado.util.TimeoutError: Timeout

During handling of the above exception, another exception occurred:

Traceback (most recent call last):
  File "/softs/rh7/conda/4.5.4/envs/pangeo_full_201909/lib/python3.7/site-packages/tornado/ioloop.py", line 743, in _run_callback
    ret = callback()
  File "/softs/rh7/conda/4.5.4/envs/pangeo_full_201909/lib/python3.7/site-packages/tornado/ioloop.py", line 767, in _discard_future_result
    future.result()
  File "/softs/rh7/conda/4.5.4/envs/pangeo_full_201909/lib/python3.7/site-packages/distributed/worker.py", line 875, in heartbeat
    metrics=await self.get_metrics(),
  File "/softs/rh7/conda/4.5.4/envs/pangeo_full_201909/lib/python3.7/site-packages/distributed/core.py", line 747, in send_recv_from_rpc
    comm = await self.pool.connect(self.addr)
  File "/softs/rh7/conda/4.5.4/envs/pangeo_full_201909/lib/python3.7/site-packages/distributed/core.py", line 874, in connect
    connection_args=self.connection_args,
  File "/softs/rh7/conda/4.5.4/envs/pangeo_full_201909/lib/python3.7/site-packages/distributed/comm/core.py", line 227, in connect
    _raise(error)
  File "/softs/rh7/conda/4.5.4/envs/pangeo_full_201909/lib/python3.7/site-packages/distributed/comm/core.py", line 204, in _raise
    raise IOError(msg)
OSError: Timed out trying to connect to 'tcp://10.120.40.97:33653' after 10 s: in <distributed.comm.tcp.TCPConnector object at 0x2b244e576a90>: ConnectionRefusedError: [Errno 111] Connection refused
tornado.application - ERROR - Exception in callback functools.partial(<bound method IOLoop._discard_future_result of <tornado.platform.asyncio.AsyncIOLoop object at 0x2b2433c61c88>>, <Task finished coro=<Worker.heartbeat() done, defined at /softs/rh7/conda/4.5.4/envs/pangeo_full_201909/lib/python3.7/site-packages/distributed/worker.py:866> exception=OSError("Timed out trying to connect to 'tcp://10.120.40.97:33653' after 10 s: in <distributed.comm.tcp.TCPConnector object at 0x2b244db5f0b8>: ConnectionRefusedError: [Errno 111] Connection refused")>)
Traceback (most recent call last):
  File "/softs/rh7/conda/4.5.4/envs/pangeo_full_201909/lib/python3.7/site-packages/distributed/comm/core.py", line 215, in connect
    quiet_exceptions=EnvironmentError,
tornado.util.TimeoutError: Timeout

During handling of the above exception, another exception occurred:

Traceback (most recent call last):
  File "/softs/rh7/conda/4.5.4/envs/pangeo_full_201909/lib/python3.7/site-packages/tornado/ioloop.py", line 743, in _run_callback
    ret = callback()
  File "/softs/rh7/conda/4.5.4/envs/pangeo_full_201909/lib/python3.7/site-packages/tornado/ioloop.py", line 767, in _discard_future_result
    future.result()
  File "/softs/rh7/conda/4.5.4/envs/pangeo_full_201909/lib/python3.7/site-packages/distributed/worker.py", line 875, in heartbeat
    metrics=await self.get_metrics(),
  File "/softs/rh7/conda/4.5.4/envs/pangeo_full_201909/lib/python3.7/site-packages/distributed/core.py", line 747, in send_recv_from_rpc
    comm = await self.pool.connect(self.addr)
  File "/softs/rh7/conda/4.5.4/envs/pangeo_full_201909/lib/python3.7/site-packages/distributed/core.py", line 874, in connect
    connection_args=self.connection_args,
  File "/softs/rh7/conda/4.5.4/envs/pangeo_full_201909/lib/python3.7/site-packages/distributed/comm/core.py", line 227, in connect
    _raise(error)
  File "/softs/rh7/conda/4.5.4/envs/pangeo_full_201909/lib/python3.7/site-packages/distributed/comm/core.py", line 204, in _raise
    raise IOError(msg)
OSError: Timed out trying to connect to 'tcp://10.120.40.97:33653' after 10 s: in <distributed.comm.tcp.TCPConnector object at 0x2b244db5f0b8>: ConnectionRefusedError: [Errno 111] Connection refused
tornado.application - ERROR - Exception in callback functools.partial(<bound method IOLoop._discard_future_result of <tornado.platform.asyncio.AsyncIOLoop object at 0x2b2433c61c88>>, <Task finished coro=<Worker.heartbeat() done, defined at /softs/rh7/conda/4.5.4/envs/pangeo_full_201909/lib/python3.7/site-packages/distributed/worker.py:866> exception=OSError("Timed out trying to connect to 'tcp://10.120.40.97:33653' after 10 s: in <distributed.comm.tcp.TCPConnector object at 0x2b244dd53470>: ConnectionRefusedError: [Errno 111] Connection refused")>)
Traceback (most recent call last):
  File "/softs/rh7/conda/4.5.4/envs/pangeo_full_201909/lib/python3.7/site-packages/distributed/comm/core.py", line 215, in connect
    quiet_exceptions=EnvironmentError,
tornado.util.TimeoutError: Timeout

During handling of the above exception, another exception occurred:

Traceback (most recent call last):
  File "/softs/rh7/conda/4.5.4/envs/pangeo_full_201909/lib/python3.7/site-packages/tornado/ioloop.py", line 743, in _run_callback
    ret = callback()
  File "/softs/rh7/conda/4.5.4/envs/pangeo_full_201909/lib/python3.7/site-packages/tornado/ioloop.py", line 767, in _discard_future_result
    future.result()
  File "/softs/rh7/conda/4.5.4/envs/pangeo_full_201909/lib/python3.7/site-packages/distributed/worker.py", line 875, in heartbeat
    metrics=await self.get_metrics(),
  File "/softs/rh7/conda/4.5.4/envs/pangeo_full_201909/lib/python3.7/site-packages/distributed/core.py", line 747, in send_recv_from_rpc
    comm = await self.pool.connect(self.addr)
  File "/softs/rh7/conda/4.5.4/envs/pangeo_full_201909/lib/python3.7/site-packages/distributed/core.py", line 874, in connect
    connection_args=self.connection_args,
  File "/softs/rh7/conda/4.5.4/envs/pangeo_full_201909/lib/python3.7/site-packages/distributed/comm/core.py", line 227, in connect
    _raise(error)
  File "/softs/rh7/conda/4.5.4/envs/pangeo_full_201909/lib/python3.7/site-packages/distributed/comm/core.py", line 204, in _raise
    raise IOError(msg)
OSError: Timed out trying to connect to 'tcp://10.120.40.97:33653' after 10 s: in <distributed.comm.tcp.TCPConnector object at 0x2b244dd53470>: ConnectionRefusedError: [Errno 111] Connection refused
tornado.application - ERROR - Exception in callback <function Worker._register_with_scheduler.<locals>.<lambda> at 0x2b2437efe2f0>
Traceback (most recent call last):
  File "/softs/rh7/conda/4.5.4/envs/pangeo_full_201909/lib/python3.7/site-packages/tornado/ioloop.py", line 907, in _run
    return self.callback()
  File "/softs/rh7/conda/4.5.4/envs/pangeo_full_201909/lib/python3.7/site-packages/distributed/worker.py", line 857, in <lambda>
    lambda: self.batched_stream.send({"op": "keep-alive"}),
  File "/softs/rh7/conda/4.5.4/envs/pangeo_full_201909/lib/python3.7/site-packages/distributed/batched.py", line 117, in send
    raise CommClosedError
distributed.comm.core.CommClosedError
tornado.application - ERROR - Exception in callback functools.partial(<bound method IOLoop._discard_future_result of <tornado.platform.asyncio.AsyncIOLoop object at 0x2b2433c61c88>>, <Task finished coro=<Worker.heartbeat() done, defined at /softs/rh7/conda/4.5.4/envs/pangeo_full_201909/lib/python3.7/site-packages/distributed/worker.py:866> exception=OSError("Timed out trying to connect to 'tcp://10.120.40.97:33653' after 10 s: in <distributed.comm.tcp.TCPConnector object at 0x2b244dd53f98>: ConnectionRefusedError: [Errno 111] Connection refused")>)
Traceback (most recent call last):
  File "/softs/rh7/conda/4.5.4/envs/pangeo_full_201909/lib/python3.7/site-packages/distributed/comm/core.py", line 215, in connect
    quiet_exceptions=EnvironmentError,
tornado.util.TimeoutError: Timeout

During handling of the above exception, another exception occurred:

Traceback (most recent call last):
  File "/softs/rh7/conda/4.5.4/envs/pangeo_full_201909/lib/python3.7/site-packages/tornado/ioloop.py", line 743, in _run_callback
    ret = callback()
  File "/softs/rh7/conda/4.5.4/envs/pangeo_full_201909/lib/python3.7/site-packages/tornado/ioloop.py", line 767, in _discard_future_result
    future.result()
  File "/softs/rh7/conda/4.5.4/envs/pangeo_full_201909/lib/python3.7/site-packages/distributed/worker.py", line 875, in heartbeat
    metrics=await self.get_metrics(),
  File "/softs/rh7/conda/4.5.4/envs/pangeo_full_201909/lib/python3.7/site-packages/distributed/core.py", line 747, in send_recv_from_rpc
    comm = await self.pool.connect(self.addr)
  File "/softs/rh7/conda/4.5.4/envs/pangeo_full_201909/lib/python3.7/site-packages/distributed/core.py", line 874, in connect
    connection_args=self.connection_args,
  File "/softs/rh7/conda/4.5.4/envs/pangeo_full_201909/lib/python3.7/site-packages/distributed/comm/core.py", line 227, in connect
    _raise(error)
  File "/softs/rh7/conda/4.5.4/envs/pangeo_full_201909/lib/python3.7/site-packages/distributed/comm/core.py", line 204, in _raise
    raise IOError(msg)
OSError: Timed out trying to connect to 'tcp://10.120.40.97:33653' after 10 s: in <distributed.comm.tcp.TCPConnector object at 0x2b244dd53f98>: ConnectionRefusedError: [Errno 111] Connection refused
tornado.application - ERROR - Exception in callback functools.partial(<bound method IOLoop._discard_future_result of <tornado.platform.asyncio.AsyncIOLoop object at 0x2b2433c61c88>>, <Task finished coro=<Worker.heartbeat() done, defined at /softs/rh7/conda/4.5.4/envs/pangeo_full_201909/lib/python3.7/site-packages/distributed/worker.py:866> exception=OSError("Timed out trying to connect to 'tcp://10.120.40.97:33653' after 10 s: in <distributed.comm.tcp.TCPConnector object at 0x2b244db5fdd8>: ConnectionRefusedError: [Errno 111] Connection refused")>)
Traceback (most recent call last):
  File "/softs/rh7/conda/4.5.4/envs/pangeo_full_201909/lib/python3.7/site-packages/distributed/comm/core.py", line 215, in connect
    quiet_exceptions=EnvironmentError,
tornado.util.TimeoutError: Timeout

During handling of the above exception, another exception occurred:

Traceback (most recent call last):
  File "/softs/rh7/conda/4.5.4/envs/pangeo_full_201909/lib/python3.7/site-packages/tornado/ioloop.py", line 743, in _run_callback
    ret = callback()
  File "/softs/rh7/conda/4.5.4/envs/pangeo_full_201909/lib/python3.7/site-packages/tornado/ioloop.py", line 767, in _discard_future_result
    future.result()
  File "/softs/rh7/conda/4.5.4/envs/pangeo_full_201909/lib/python3.7/site-packages/distributed/worker.py", line 875, in heartbeat
    metrics=await self.get_metrics(),
  File "/softs/rh7/conda/4.5.4/envs/pangeo_full_201909/lib/python3.7/site-packages/distributed/core.py", line 747, in send_recv_from_rpc
    comm = await self.pool.connect(self.addr)
  File "/softs/rh7/conda/4.5.4/envs/pangeo_full_201909/lib/python3.7/site-packages/distributed/core.py", line 874, in connect
    connection_args=self.connection_args,
  File "/softs/rh7/conda/4.5.4/envs/pangeo_full_201909/lib/python3.7/site-packages/distributed/comm/core.py", line 227, in connect
    _raise(error)
  File "/softs/rh7/conda/4.5.4/envs/pangeo_full_201909/lib/python3.7/site-packages/distributed/comm/core.py", line 204, in _raise
    raise IOError(msg)
OSError: Timed out trying to connect to 'tcp://10.120.40.97:33653' after 10 s: in <distributed.comm.tcp.TCPConnector object at 0x2b244db5fdd8>: ConnectionRefusedError: [Errno 111] Connection refused
tornado.application - ERROR - Exception in callback functools.partial(<bound method IOLoop._discard_future_result of <tornado.platform.asyncio.AsyncIOLoop object at 0x2b2433c61c88>>, <Task finished coro=<Worker.heartbeat() done, defined at /softs/rh7/conda/4.5.4/envs/pangeo_full_201909/lib/python3.7/site-packages/distributed/worker.py:866> exception=OSError("Timed out trying to connect to 'tcp://10.120.40.97:33653' after 10 s: in <distributed.comm.tcp.TCPConnector object at 0x2b244e2426a0>: ConnectionRefusedError: [Errno 111] Connection refused")>)
Traceback (most recent call last):
  File "/softs/rh7/conda/4.5.4/envs/pangeo_full_201909/lib/python3.7/site-packages/distributed/comm/core.py", line 215, in connect
    quiet_exceptions=EnvironmentError,
tornado.util.TimeoutError: Timeout

During handling of the above exception, another exception occurred:

Traceback (most recent call last):
  File "/softs/rh7/conda/4.5.4/envs/pangeo_full_201909/lib/python3.7/site-packages/tornado/ioloop.py", line 743, in _run_callback
    ret = callback()
  File "/softs/rh7/conda/4.5.4/envs/pangeo_full_201909/lib/python3.7/site-packages/tornado/ioloop.py", line 767, in _discard_future_result
    future.result()
  File "/softs/rh7/conda/4.5.4/envs/pangeo_full_201909/lib/python3.7/site-packages/distributed/worker.py", line 875, in heartbeat
    metrics=await self.get_metrics(),
  File "/softs/rh7/conda/4.5.4/envs/pangeo_full_201909/lib/python3.7/site-packages/distributed/core.py", line 747, in send_recv_from_rpc
    comm = await self.pool.connect(self.addr)
  File "/softs/rh7/conda/4.5.4/envs/pangeo_full_201909/lib/python3.7/site-packages/distributed/core.py", line 874, in connect
    connection_args=self.connection_args,
  File "/softs/rh7/conda/4.5.4/envs/pangeo_full_201909/lib/python3.7/site-packages/distributed/comm/core.py", line 227, in connect
    _raise(error)
  File "/softs/rh7/conda/4.5.4/envs/pangeo_full_201909/lib/python3.7/site-packages/distributed/comm/core.py", line 204, in _raise
    raise IOError(msg)
OSError: Timed out trying to connect to 'tcp://10.120.40.97:33653' after 10 s: in <distributed.comm.tcp.TCPConnector object at 0x2b244e2426a0>: ConnectionRefusedError: [Errno 111] Connection refused
tornado.application - ERROR - Exception in callback functools.partial(<bound method IOLoop._discard_future_result of <tornado.platform.asyncio.AsyncIOLoop object at 0x2b2433c61c88>>, <Task finished coro=<Worker.heartbeat() done, defined at /softs/rh7/conda/4.5.4/envs/pangeo_full_201909/lib/python3.7/site-packages/distributed/worker.py:866> exception=OSError("Timed out trying to connect to 'tcp://10.120.40.97:33653' after 10 s: in <distributed.comm.tcp.TCPConnector object at 0x2b244d6fb470>: ConnectionRefusedError: [Errno 111] Connection refused")>)
Traceback (most recent call last):
  File "/softs/rh7/conda/4.5.4/envs/pangeo_full_201909/lib/python3.7/site-packages/distributed/comm/core.py", line 215, in connect
    quiet_exceptions=EnvironmentError,
tornado.util.TimeoutError: Timeout

During handling of the above exception, another exception occurred:

Traceback (most recent call last):
  File "/softs/rh7/conda/4.5.4/envs/pangeo_full_201909/lib/python3.7/site-packages/tornado/ioloop.py", line 743, in _run_callback
    ret = callback()
  File "/softs/rh7/conda/4.5.4/envs/pangeo_full_201909/lib/python3.7/site-packages/tornado/ioloop.py", line 767, in _discard_future_result
    future.result()
  File "/softs/rh7/conda/4.5.4/envs/pangeo_full_201909/lib/python3.7/site-packages/distributed/worker.py", line 875, in heartbeat
    metrics=await self.get_metrics(),
  File "/softs/rh7/conda/4.5.4/envs/pangeo_full_201909/lib/python3.7/site-packages/distributed/core.py", line 747, in send_recv_from_rpc
    comm = await self.pool.connect(self.addr)
  File "/softs/rh7/conda/4.5.4/envs/pangeo_full_201909/lib/python3.7/site-packages/distributed/core.py", line 874, in connect
    connection_args=self.connection_args,
  File "/softs/rh7/conda/4.5.4/envs/pangeo_full_201909/lib/python3.7/site-packages/distributed/comm/core.py", line 227, in connect
    _raise(error)
  File "/softs/rh7/conda/4.5.4/envs/pangeo_full_201909/lib/python3.7/site-packages/distributed/comm/core.py", line 204, in _raise
    raise IOError(msg)
OSError: Timed out trying to connect to 'tcp://10.120.40.97:33653' after 10 s: in <distributed.comm.tcp.TCPConnector object at 0x2b244d6fb470>: ConnectionRefusedError: [Errno 111] Connection refused
tornado.application - ERROR - Exception in callback functools.partial(<bound method IOLoop._discard_future_result of <tornado.platform.asyncio.AsyncIOLoop object at 0x2b2433c61c88>>, <Task finished coro=<Worker.heartbeat() done, defined at /softs/rh7/conda/4.5.4/envs/pangeo_full_201909/lib/python3.7/site-packages/distributed/worker.py:866> exception=OSError("Timed out trying to connect to 'tcp://10.120.40.97:33653' after 10 s: in <distributed.comm.tcp.TCPConnector object at 0x2b244df74470>: ConnectionRefusedError: [Errno 111] Connection refused")>)
Traceback (most recent call last):
  File "/softs/rh7/conda/4.5.4/envs/pangeo_full_201909/lib/python3.7/site-packages/distributed/comm/core.py", line 215, in connect
    quiet_exceptions=EnvironmentError,
tornado.util.TimeoutError: Timeout

During handling of the above exception, another exception occurred:

Traceback (most recent call last):
  File "/softs/rh7/conda/4.5.4/envs/pangeo_full_201909/lib/python3.7/site-packages/tornado/ioloop.py", line 743, in _run_callback
    ret = callback()
  File "/softs/rh7/conda/4.5.4/envs/pangeo_full_201909/lib/python3.7/site-packages/tornado/ioloop.py", line 767, in _discard_future_result
    future.result()
  File "/softs/rh7/conda/4.5.4/envs/pangeo_full_201909/lib/python3.7/site-packages/distributed/worker.py", line 875, in heartbeat
    metrics=await self.get_metrics(),
  File "/softs/rh7/conda/4.5.4/envs/pangeo_full_201909/lib/python3.7/site-packages/distributed/core.py", line 747, in send_recv_from_rpc
    comm = await self.pool.connect(self.addr)
  File "/softs/rh7/conda/4.5.4/envs/pangeo_full_201909/lib/python3.7/site-packages/distributed/core.py", line 874, in connect
    connection_args=self.connection_args,
  File "/softs/rh7/conda/4.5.4/envs/pangeo_full_201909/lib/python3.7/site-packages/distributed/comm/core.py", line 227, in connect
    _raise(error)
  File "/softs/rh7/conda/4.5.4/envs/pangeo_full_201909/lib/python3.7/site-packages/distributed/comm/core.py", line 204, in _raise
    raise IOError(msg)
OSError: Timed out trying to connect to 'tcp://10.120.40.97:33653' after 10 s: in <distributed.comm.tcp.TCPConnector object at 0x2b244df74470>: ConnectionRefusedError: [Errno 111] Connection refused
tornado.application - ERROR - Exception in callback functools.partial(<bound method IOLoop._discard_future_result of <tornado.platform.asyncio.AsyncIOLoop object at 0x2b2433c61c88>>, <Task finished coro=<Worker.heartbeat() done, defined at /softs/rh7/conda/4.5.4/envs/pangeo_full_201909/lib/python3.7/site-packages/distributed/worker.py:866> exception=OSError("Timed out trying to connect to 'tcp://10.120.40.97:33653' after 10 s: in <distributed.comm.tcp.TCPConnector object at 0x2b244df74a20>: ConnectionRefusedError: [Errno 111] Connection refused")>)
Traceback (most recent call last):
  File "/softs/rh7/conda/4.5.4/envs/pangeo_full_201909/lib/python3.7/site-packages/distributed/comm/core.py", line 215, in connect
    quiet_exceptions=EnvironmentError,
tornado.util.TimeoutError: Timeout

During handling of the above exception, another exception occurred:

Traceback (most recent call last):
  File "/softs/rh7/conda/4.5.4/envs/pangeo_full_201909/lib/python3.7/site-packages/tornado/ioloop.py", line 743, in _run_callback
    ret = callback()
  File "/softs/rh7/conda/4.5.4/envs/pangeo_full_201909/lib/python3.7/site-packages/tornado/ioloop.py", line 767, in _discard_future_result
    future.result()
  File "/softs/rh7/conda/4.5.4/envs/pangeo_full_201909/lib/python3.7/site-packages/distributed/worker.py", line 875, in heartbeat
    metrics=await self.get_metrics(),
  File "/softs/rh7/conda/4.5.4/envs/pangeo_full_201909/lib/python3.7/site-packages/distributed/core.py", line 747, in send_recv_from_rpc
    comm = await self.pool.connect(self.addr)
  File "/softs/rh7/conda/4.5.4/envs/pangeo_full_201909/lib/python3.7/site-packages/distributed/core.py", line 874, in connect
    connection_args=self.connection_args,
  File "/softs/rh7/conda/4.5.4/envs/pangeo_full_201909/lib/python3.7/site-packages/distributed/comm/core.py", line 227, in connect
    _raise(error)
  File "/softs/rh7/conda/4.5.4/envs/pangeo_full_201909/lib/python3.7/site-packages/distributed/comm/core.py", line 204, in _raise
    raise IOError(msg)
OSError: Timed out trying to connect to 'tcp://10.120.40.97:33653' after 10 s: in <distributed.comm.tcp.TCPConnector object at 0x2b244df74a20>: ConnectionRefusedError: [Errno 111] Connection refused
tornado.application - ERROR - Exception in callback <function Worker._register_with_scheduler.<locals>.<lambda> at 0x2b2437efe2f0>
Traceback (most recent call last):
  File "/softs/rh7/conda/4.5.4/envs/pangeo_full_201909/lib/python3.7/site-packages/tornado/ioloop.py", line 907, in _run
    return self.callback()
  File "/softs/rh7/conda/4.5.4/envs/pangeo_full_201909/lib/python3.7/site-packages/distributed/worker.py", line 857, in <lambda>
    lambda: self.batched_stream.send({"op": "keep-alive"}),
  File "/softs/rh7/conda/4.5.4/envs/pangeo_full_201909/lib/python3.7/site-packages/distributed/batched.py", line 117, in send
    raise CommClosedError
distributed.comm.core.CommClosedError
tornado.application - ERROR - Exception in callback functools.partial(<bound method IOLoop._discard_future_result of <tornado.platform.asyncio.AsyncIOLoop object at 0x2b2433c61c88>>, <Task finished coro=<Worker.heartbeat() done, defined at /softs/rh7/conda/4.5.4/envs/pangeo_full_201909/lib/python3.7/site-packages/distributed/worker.py:866> exception=OSError("Timed out trying to connect to 'tcp://10.120.40.97:33653' after 10 s: in <distributed.comm.tcp.TCPConnector object at 0x2b244e576080>: ConnectionRefusedError: [Errno 111] Connection refused")>)
Traceback (most recent call last):
  File "/softs/rh7/conda/4.5.4/envs/pangeo_full_201909/lib/python3.7/site-packages/distributed/comm/core.py", line 215, in connect
    quiet_exceptions=EnvironmentError,
tornado.util.TimeoutError: Timeout

During handling of the above exception, another exception occurred:

Traceback (most recent call last):
  File "/softs/rh7/conda/4.5.4/envs/pangeo_full_201909/lib/python3.7/site-packages/tornado/ioloop.py", line 743, in _run_callback
    ret = callback()
  File "/softs/rh7/conda/4.5.4/envs/pangeo_full_201909/lib/python3.7/site-packages/tornado/ioloop.py", line 767, in _discard_future_result
    future.result()
  File "/softs/rh7/conda/4.5.4/envs/pangeo_full_201909/lib/python3.7/site-packages/distributed/worker.py", line 875, in heartbeat
    metrics=await self.get_metrics(),
  File "/softs/rh7/conda/4.5.4/envs/pangeo_full_201909/lib/python3.7/site-packages/distributed/core.py", line 747, in send_recv_from_rpc
    comm = await self.pool.connect(self.addr)
  File "/softs/rh7/conda/4.5.4/envs/pangeo_full_201909/lib/python3.7/site-packages/distributed/core.py", line 874, in connect
    connection_args=self.connection_args,
  File "/softs/rh7/conda/4.5.4/envs/pangeo_full_201909/lib/python3.7/site-packages/distributed/comm/core.py", line 227, in connect
    _raise(error)
  File "/softs/rh7/conda/4.5.4/envs/pangeo_full_201909/lib/python3.7/site-packages/distributed/comm/core.py", line 204, in _raise
    raise IOError(msg)
OSError: Timed out trying to connect to 'tcp://10.120.40.97:33653' after 10 s: in <distributed.comm.tcp.TCPConnector object at 0x2b244e576080>: ConnectionRefusedError: [Errno 111] Connection refused
tornado.application - ERROR - Exception in callback functools.partial(<bound method IOLoop._discard_future_result of <tornado.platform.asyncio.AsyncIOLoop object at 0x2b2433c61c88>>, <Task finished coro=<Worker.heartbeat() done, defined at /softs/rh7/conda/4.5.4/envs/pangeo_full_201909/lib/python3.7/site-packages/distributed/worker.py:866> exception=OSError("Timed out trying to connect to 'tcp://10.120.40.97:33653' after 10 s: in <distributed.comm.tcp.TCPConnector object at 0x2b244e382400>: ConnectionRefusedError: [Errno 111] Connection refused")>)
Traceback (most recent call last):
  File "/softs/rh7/conda/4.5.4/envs/pangeo_full_201909/lib/python3.7/site-packages/distributed/comm/core.py", line 215, in connect
    quiet_exceptions=EnvironmentError,
tornado.util.TimeoutError: Timeout

During handling of the above exception, another exception occurred:

Traceback (most recent call last):
  File "/softs/rh7/conda/4.5.4/envs/pangeo_full_201909/lib/python3.7/site-packages/tornado/ioloop.py", line 743, in _run_callback
    ret = callback()
  File "/softs/rh7/conda/4.5.4/envs/pangeo_full_201909/lib/python3.7/site-packages/tornado/ioloop.py", line 767, in _discard_future_result
    future.result()
  File "/softs/rh7/conda/4.5.4/envs/pangeo_full_201909/lib/python3.7/site-packages/distributed/worker.py", line 875, in heartbeat
    metrics=await self.get_metrics(),
  File "/softs/rh7/conda/4.5.4/envs/pangeo_full_201909/lib/python3.7/site-packages/distributed/core.py", line 747, in send_recv_from_rpc
    comm = await self.pool.connect(self.addr)
  File "/softs/rh7/conda/4.5.4/envs/pangeo_full_201909/lib/python3.7/site-packages/distributed/core.py", line 874, in connect
    connection_args=self.connection_args,
  File "/softs/rh7/conda/4.5.4/envs/pangeo_full_201909/lib/python3.7/site-packages/distributed/comm/core.py", line 227, in connect
    _raise(error)
  File "/softs/rh7/conda/4.5.4/envs/pangeo_full_201909/lib/python3.7/site-packages/distributed/comm/core.py", line 204, in _raise
    raise IOError(msg)
OSError: Timed out trying to connect to 'tcp://10.120.40.97:33653' after 10 s: in <distributed.comm.tcp.TCPConnector object at 0x2b244e382400>: ConnectionRefusedError: [Errno 111] Connection refused
tornado.application - ERROR - Exception in callback functools.partial(<bound method IOLoop._discard_future_result of <tornado.platform.asyncio.AsyncIOLoop object at 0x2b2433c61c88>>, <Task finished coro=<Worker.heartbeat() done, defined at /softs/rh7/conda/4.5.4/envs/pangeo_full_201909/lib/python3.7/site-packages/distributed/worker.py:866> exception=OSError("Timed out trying to connect to 'tcp://10.120.40.97:33653' after 10 s: in <distributed.comm.tcp.TCPConnector object at 0x2b244e857860>: ConnectionRefusedError: [Errno 111] Connection refused")>)
Traceback (most recent call last):
  File "/softs/rh7/conda/4.5.4/envs/pangeo_full_201909/lib/python3.7/site-packages/distributed/comm/core.py", line 215, in connect
    quiet_exceptions=EnvironmentError,
tornado.util.TimeoutError: Timeout

During handling of the above exception, another exception occurred:

Traceback (most recent call last):
  File "/softs/rh7/conda/4.5.4/envs/pangeo_full_201909/lib/python3.7/site-packages/tornado/ioloop.py", line 743, in _run_callback
    ret = callback()
  File "/softs/rh7/conda/4.5.4/envs/pangeo_full_201909/lib/python3.7/site-packages/tornado/ioloop.py", line 767, in _discard_future_result
    future.result()
  File "/softs/rh7/conda/4.5.4/envs/pangeo_full_201909/lib/python3.7/site-packages/distributed/worker.py", line 875, in heartbeat
    metrics=await self.get_metrics(),
  File "/softs/rh7/conda/4.5.4/envs/pangeo_full_201909/lib/python3.7/site-packages/distributed/core.py", line 747, in send_recv_from_rpc
    comm = await self.pool.connect(self.addr)
  File "/softs/rh7/conda/4.5.4/envs/pangeo_full_201909/lib/python3.7/site-packages/distributed/core.py", line 874, in connect
    connection_args=self.connection_args,
  File "/softs/rh7/conda/4.5.4/envs/pangeo_full_201909/lib/python3.7/site-packages/distributed/comm/core.py", line 227, in connect
    _raise(error)
  File "/softs/rh7/conda/4.5.4/envs/pangeo_full_201909/lib/python3.7/site-packages/distributed/comm/core.py", line 204, in _raise
    raise IOError(msg)
OSError: Timed out trying to connect to 'tcp://10.120.40.97:33653' after 10 s: in <distributed.comm.tcp.TCPConnector object at 0x2b244e857860>: ConnectionRefusedError: [Errno 111] Connection refused
tornado.application - ERROR - Exception in callback functools.partial(<bound method IOLoop._discard_future_result of <tornado.platform.asyncio.AsyncIOLoop object at 0x2b2433c61c88>>, <Task finished coro=<Worker.heartbeat() done, defined at /softs/rh7/conda/4.5.4/envs/pangeo_full_201909/lib/python3.7/site-packages/distributed/worker.py:866> exception=OSError("Timed out trying to connect to 'tcp://10.120.40.97:33653' after 10 s: in <distributed.comm.tcp.TCPConnector object at 0x2b244e576c50>: ConnectionRefusedError: [Errno 111] Connection refused")>)
Traceback (most recent call last):
  File "/softs/rh7/conda/4.5.4/envs/pangeo_full_201909/lib/python3.7/site-packages/distributed/comm/core.py", line 215, in connect
    quiet_exceptions=EnvironmentError,
tornado.util.TimeoutError: Timeout

During handling of the above exception, another exception occurred:

Traceback (most recent call last):
  File "/softs/rh7/conda/4.5.4/envs/pangeo_full_201909/lib/python3.7/site-packages/tornado/ioloop.py", line 743, in _run_callback
    ret = callback()
  File "/softs/rh7/conda/4.5.4/envs/pangeo_full_201909/lib/python3.7/site-packages/tornado/ioloop.py", line 767, in _discard_future_result
    future.result()
  File "/softs/rh7/conda/4.5.4/envs/pangeo_full_201909/lib/python3.7/site-packages/distributed/worker.py", line 875, in heartbeat
    metrics=await self.get_metrics(),
  File "/softs/rh7/conda/4.5.4/envs/pangeo_full_201909/lib/python3.7/site-packages/distributed/core.py", line 747, in send_recv_from_rpc
    comm = await self.pool.connect(self.addr)
  File "/softs/rh7/conda/4.5.4/envs/pangeo_full_201909/lib/python3.7/site-packages/distributed/core.py", line 874, in connect
    connection_args=self.connection_args,
  File "/softs/rh7/conda/4.5.4/envs/pangeo_full_201909/lib/python3.7/site-packages/distributed/comm/core.py", line 227, in connect
    _raise(error)
  File "/softs/rh7/conda/4.5.4/envs/pangeo_full_201909/lib/python3.7/site-packages/distributed/comm/core.py", line 204, in _raise
    raise IOError(msg)
OSError: Timed out trying to connect to 'tcp://10.120.40.97:33653' after 10 s: in <distributed.comm.tcp.TCPConnector object at 0x2b244e576c50>: ConnectionRefusedError: [Errno 111] Connection refused
tornado.application - ERROR - Exception in callback functools.partial(<bound method IOLoop._discard_future_result of <tornado.platform.asyncio.AsyncIOLoop object at 0x2b2433c61c88>>, <Task finished coro=<Worker.heartbeat() done, defined at /softs/rh7/conda/4.5.4/envs/pangeo_full_201909/lib/python3.7/site-packages/distributed/worker.py:866> exception=OSError("Timed out trying to connect to 'tcp://10.120.40.97:33653' after 10 s: in <distributed.comm.tcp.TCPConnector object at 0x2b244e857d68>: ConnectionRefusedError: [Errno 111] Connection refused")>)
Traceback (most recent call last):
  File "/softs/rh7/conda/4.5.4/envs/pangeo_full_201909/lib/python3.7/site-packages/distributed/comm/core.py", line 215, in connect
    quiet_exceptions=EnvironmentError,
tornado.util.TimeoutError: Timeout

During handling of the above exception, another exception occurred:

Traceback (most recent call last):
  File "/softs/rh7/conda/4.5.4/envs/pangeo_full_201909/lib/python3.7/site-packages/tornado/ioloop.py", line 743, in _run_callback
    ret = callback()
  File "/softs/rh7/conda/4.5.4/envs/pangeo_full_201909/lib/python3.7/site-packages/tornado/ioloop.py", line 767, in _discard_future_result
    future.result()
  File "/softs/rh7/conda/4.5.4/envs/pangeo_full_201909/lib/python3.7/site-packages/distributed/worker.py", line 875, in heartbeat
    metrics=await self.get_metrics(),
  File "/softs/rh7/conda/4.5.4/envs/pangeo_full_201909/lib/python3.7/site-packages/distributed/core.py", line 747, in send_recv_from_rpc
    comm = await self.pool.connect(self.addr)
  File "/softs/rh7/conda/4.5.4/envs/pangeo_full_201909/lib/python3.7/site-packages/distributed/core.py", line 874, in connect
    connection_args=self.connection_args,
  File "/softs/rh7/conda/4.5.4/envs/pangeo_full_201909/lib/python3.7/site-packages/distributed/comm/core.py", line 227, in connect
    _raise(error)
  File "/softs/rh7/conda/4.5.4/envs/pangeo_full_201909/lib/python3.7/site-packages/distributed/comm/core.py", line 204, in _raise
    raise IOError(msg)
OSError: Timed out trying to connect to 'tcp://10.120.40.97:33653' after 10 s: in <distributed.comm.tcp.TCPConnector object at 0x2b244e857d68>: ConnectionRefusedError: [Errno 111] Connection refused
tornado.application - ERROR - Exception in callback <function Worker._register_with_scheduler.<locals>.<lambda> at 0x2b2437efe2f0>
Traceback (most recent call last):
  File "/softs/rh7/conda/4.5.4/envs/pangeo_full_201909/lib/python3.7/site-packages/tornado/ioloop.py", line 907, in _run
    return self.callback()
  File "/softs/rh7/conda/4.5.4/envs/pangeo_full_201909/lib/python3.7/site-packages/distributed/worker.py", line 857, in <lambda>
    lambda: self.batched_stream.send({"op": "keep-alive"}),
  File "/softs/rh7/conda/4.5.4/envs/pangeo_full_201909/lib/python3.7/site-packages/distributed/batched.py", line 117, in send
    raise CommClosedError
distributed.comm.core.CommClosedError
tornado.application - ERROR - Exception in callback functools.partial(<bound method IOLoop._discard_future_result of <tornado.platform.asyncio.AsyncIOLoop object at 0x2b2433c61c88>>, <Task finished coro=<Worker.heartbeat() done, defined at /softs/rh7/conda/4.5.4/envs/pangeo_full_201909/lib/python3.7/site-packages/distributed/worker.py:866> exception=OSError("Timed out trying to connect to 'tcp://10.120.40.97:33653' after 10 s: in <distributed.comm.tcp.TCPConnector object at 0x2b244dd534e0>: ConnectionRefusedError: [Errno 111] Connection refused")>)
Traceback (most recent call last):
  File "/softs/rh7/conda/4.5.4/envs/pangeo_full_201909/lib/python3.7/site-packages/distributed/comm/core.py", line 215, in connect
    quiet_exceptions=EnvironmentError,
tornado.util.TimeoutError: Timeout

During handling of the above exception, another exception occurred:

Traceback (most recent call last):
  File "/softs/rh7/conda/4.5.4/envs/pangeo_full_201909/lib/python3.7/site-packages/tornado/ioloop.py", line 743, in _run_callback
    ret = callback()
  File "/softs/rh7/conda/4.5.4/envs/pangeo_full_201909/lib/python3.7/site-packages/tornado/ioloop.py", line 767, in _discard_future_result
    future.result()
  File "/softs/rh7/conda/4.5.4/envs/pangeo_full_201909/lib/python3.7/site-packages/distributed/worker.py", line 875, in heartbeat
    metrics=await self.get_metrics(),
  File "/softs/rh7/conda/4.5.4/envs/pangeo_full_201909/lib/python3.7/site-packages/distributed/core.py", line 747, in send_recv_from_rpc
    comm = await self.pool.connect(self.addr)
  File "/softs/rh7/conda/4.5.4/envs/pangeo_full_201909/lib/python3.7/site-packages/distributed/core.py", line 874, in connect
    connection_args=self.connection_args,
  File "/softs/rh7/conda/4.5.4/envs/pangeo_full_201909/lib/python3.7/site-packages/distributed/comm/core.py", line 227, in connect
    _raise(error)
  File "/softs/rh7/conda/4.5.4/envs/pangeo_full_201909/lib/python3.7/site-packages/distributed/comm/core.py", line 204, in _raise
    raise IOError(msg)
OSError: Timed out trying to connect to 'tcp://10.120.40.97:33653' after 10 s: in <distributed.comm.tcp.TCPConnector object at 0x2b244dd534e0>: ConnectionRefusedError: [Errno 111] Connection refused
tornado.application - ERROR - Exception in callback functools.partial(<bound method IOLoop._discard_future_result of <tornado.platform.asyncio.AsyncIOLoop object at 0x2b2433c61c88>>, <Task finished coro=<Worker.heartbeat() done, defined at /softs/rh7/conda/4.5.4/envs/pangeo_full_201909/lib/python3.7/site-packages/distributed/worker.py:866> exception=OSError("Timed out trying to connect to 'tcp://10.120.40.97:33653' after 10 s: in <distributed.comm.tcp.TCPConnector object at 0x2b244e576940>: ConnectionRefusedError: [Errno 111] Connection refused")>)
Traceback (most recent call last):
  File "/softs/rh7/conda/4.5.4/envs/pangeo_full_201909/lib/python3.7/site-packages/distributed/comm/core.py", line 215, in connect
    quiet_exceptions=EnvironmentError,
tornado.util.TimeoutError: Timeout

During handling of the above exception, another exception occurred:

Traceback (most recent call last):
  File "/softs/rh7/conda/4.5.4/envs/pangeo_full_201909/lib/python3.7/site-packages/tornado/ioloop.py", line 743, in _run_callback
    ret = callback()
  File "/softs/rh7/conda/4.5.4/envs/pangeo_full_201909/lib/python3.7/site-packages/tornado/ioloop.py", line 767, in _discard_future_result
    future.result()
  File "/softs/rh7/conda/4.5.4/envs/pangeo_full_201909/lib/python3.7/site-packages/distributed/worker.py", line 875, in heartbeat
    metrics=await self.get_metrics(),
  File "/softs/rh7/conda/4.5.4/envs/pangeo_full_201909/lib/python3.7/site-packages/distributed/core.py", line 747, in send_recv_from_rpc
    comm = await self.pool.connect(self.addr)
  File "/softs/rh7/conda/4.5.4/envs/pangeo_full_201909/lib/python3.7/site-packages/distributed/core.py", line 874, in connect
    connection_args=self.connection_args,
  File "/softs/rh7/conda/4.5.4/envs/pangeo_full_201909/lib/python3.7/site-packages/distributed/comm/core.py", line 227, in connect
    _raise(error)
  File "/softs/rh7/conda/4.5.4/envs/pangeo_full_201909/lib/python3.7/site-packages/distributed/comm/core.py", line 204, in _raise
    raise IOError(msg)
OSError: Timed out trying to connect to 'tcp://10.120.40.97:33653' after 10 s: in <distributed.comm.tcp.TCPConnector object at 0x2b244e576940>: ConnectionRefusedError: [Errno 111] Connection refused
tornado.application - ERROR - Exception in callback functools.partial(<bound method IOLoop._discard_future_result of <tornado.platform.asyncio.AsyncIOLoop object at 0x2b2433c61c88>>, <Task finished coro=<Worker.heartbeat() done, defined at /softs/rh7/conda/4.5.4/envs/pangeo_full_201909/lib/python3.7/site-packages/distributed/worker.py:866> exception=OSError("Timed out trying to connect to 'tcp://10.120.40.97:33653' after 10 s: in <distributed.comm.tcp.TCPConnector object at 0x2b244e659ba8>: ConnectionRefusedError: [Errno 111] Connection refused")>)
Traceback (most recent call last):
  File "/softs/rh7/conda/4.5.4/envs/pangeo_full_201909/lib/python3.7/site-packages/distributed/comm/core.py", line 215, in connect
    quiet_exceptions=EnvironmentError,
tornado.util.TimeoutError: Timeout

During handling of the above exception, another exception occurred:

Traceback (most recent call last):
  File "/softs/rh7/conda/4.5.4/envs/pangeo_full_201909/lib/python3.7/site-packages/tornado/ioloop.py", line 743, in _run_callback
    ret = callback()
  File "/softs/rh7/conda/4.5.4/envs/pangeo_full_201909/lib/python3.7/site-packages/tornado/ioloop.py", line 767, in _discard_future_result
    future.result()
  File "/softs/rh7/conda/4.5.4/envs/pangeo_full_201909/lib/python3.7/site-packages/distributed/worker.py", line 875, in heartbeat
    metrics=await self.get_metrics(),
  File "/softs/rh7/conda/4.5.4/envs/pangeo_full_201909/lib/python3.7/site-packages/distributed/core.py", line 747, in send_recv_from_rpc
    comm = await self.pool.connect(self.addr)
  File "/softs/rh7/conda/4.5.4/envs/pangeo_full_201909/lib/python3.7/site-packages/distributed/core.py", line 874, in connect
    connection_args=self.connection_args,
  File "/softs/rh7/conda/4.5.4/envs/pangeo_full_201909/lib/python3.7/site-packages/distributed/comm/core.py", line 227, in connect
    _raise(error)
  File "/softs/rh7/conda/4.5.4/envs/pangeo_full_201909/lib/python3.7/site-packages/distributed/comm/core.py", line 204, in _raise
    raise IOError(msg)
OSError: Timed out trying to connect to 'tcp://10.120.40.97:33653' after 10 s: in <distributed.comm.tcp.TCPConnector object at 0x2b244e659ba8>: ConnectionRefusedError: [Errno 111] Connection refused
tornado.application - ERROR - Exception in callback functools.partial(<bound method IOLoop._discard_future_result of <tornado.platform.asyncio.AsyncIOLoop object at 0x2b2433c61c88>>, <Task finished coro=<Worker.heartbeat() done, defined at /softs/rh7/conda/4.5.4/envs/pangeo_full_201909/lib/python3.7/site-packages/distributed/worker.py:866> exception=OSError("Timed out trying to connect to 'tcp://10.120.40.97:33653' after 10 s: in <distributed.comm.tcp.TCPConnector object at 0x2b244e900080>: ConnectionRefusedError: [Errno 111] Connection refused")>)
Traceback (most recent call last):
  File "/softs/rh7/conda/4.5.4/envs/pangeo_full_201909/lib/python3.7/site-packages/distributed/comm/core.py", line 215, in connect
    quiet_exceptions=EnvironmentError,
tornado.util.TimeoutError: Timeout

During handling of the above exception, another exception occurred:

Traceback (most recent call last):
  File "/softs/rh7/conda/4.5.4/envs/pangeo_full_201909/lib/python3.7/site-packages/tornado/ioloop.py", line 743, in _run_callback
    ret = callback()
  File "/softs/rh7/conda/4.5.4/envs/pangeo_full_201909/lib/python3.7/site-packages/tornado/ioloop.py", line 767, in _discard_future_result
    future.result()
  File "/softs/rh7/conda/4.5.4/envs/pangeo_full_201909/lib/python3.7/site-packages/distributed/worker.py", line 875, in heartbeat
    metrics=await self.get_metrics(),
  File "/softs/rh7/conda/4.5.4/envs/pangeo_full_201909/lib/python3.7/site-packages/distributed/core.py", line 747, in send_recv_from_rpc
    comm = await self.pool.connect(self.addr)
  File "/softs/rh7/conda/4.5.4/envs/pangeo_full_201909/lib/python3.7/site-packages/distributed/core.py", line 874, in connect
    connection_args=self.connection_args,
  File "/softs/rh7/conda/4.5.4/envs/pangeo_full_201909/lib/python3.7/site-packages/distributed/comm/core.py", line 227, in connect
    _raise(error)
  File "/softs/rh7/conda/4.5.4/envs/pangeo_full_201909/lib/python3.7/site-packages/distributed/comm/core.py", line 204, in _raise
    raise IOError(msg)
OSError: Timed out trying to connect to 'tcp://10.120.40.97:33653' after 10 s: in <distributed.comm.tcp.TCPConnector object at 0x2b244e900080>: ConnectionRefusedError: [Errno 111] Connection refused
tornado.application - ERROR - Exception in callback functools.partial(<bound method IOLoop._discard_future_result of <tornado.platform.asyncio.AsyncIOLoop object at 0x2b2433c61c88>>, <Task finished coro=<Worker.heartbeat() done, defined at /softs/rh7/conda/4.5.4/envs/pangeo_full_201909/lib/python3.7/site-packages/distributed/worker.py:866> exception=OSError("Timed out trying to connect to 'tcp://10.120.40.97:33653' after 10 s: in <distributed.comm.tcp.TCPConnector object at 0x2b244e950a58>: ConnectionRefusedError: [Errno 111] Connection refused")>)
Traceback (most recent call last):
  File "/softs/rh7/conda/4.5.4/envs/pangeo_full_201909/lib/python3.7/site-packages/distributed/comm/core.py", line 215, in connect
    quiet_exceptions=EnvironmentError,
tornado.util.TimeoutError: Timeout

During handling of the above exception, another exception occurred:

Traceback (most recent call last):
  File "/softs/rh7/conda/4.5.4/envs/pangeo_full_201909/lib/python3.7/site-packages/tornado/ioloop.py", line 743, in _run_callback
    ret = callback()
  File "/softs/rh7/conda/4.5.4/envs/pangeo_full_201909/lib/python3.7/site-packages/tornado/ioloop.py", line 767, in _discard_future_result
    future.result()
  File "/softs/rh7/conda/4.5.4/envs/pangeo_full_201909/lib/python3.7/site-packages/distributed/worker.py", line 875, in heartbeat
    metrics=await self.get_metrics(),
  File "/softs/rh7/conda/4.5.4/envs/pangeo_full_201909/lib/python3.7/site-packages/distributed/core.py", line 747, in send_recv_from_rpc
    comm = await self.pool.connect(self.addr)
  File "/softs/rh7/conda/4.5.4/envs/pangeo_full_201909/lib/python3.7/site-packages/distributed/core.py", line 874, in connect
    connection_args=self.connection_args,
  File "/softs/rh7/conda/4.5.4/envs/pangeo_full_201909/lib/python3.7/site-packages/distributed/comm/core.py", line 227, in connect
    _raise(error)
  File "/softs/rh7/conda/4.5.4/envs/pangeo_full_201909/lib/python3.7/site-packages/distributed/comm/core.py", line 204, in _raise
    raise IOError(msg)
OSError: Timed out trying to connect to 'tcp://10.120.40.97:33653' after 10 s: in <distributed.comm.tcp.TCPConnector object at 0x2b244e950a58>: ConnectionRefusedError: [Errno 111] Connection refused
tornado.application - ERROR - Exception in callback functools.partial(<bound method IOLoop._discard_future_result of <tornado.platform.asyncio.AsyncIOLoop object at 0x2b2433c61c88>>, <Task finished coro=<Worker.heartbeat() done, defined at /softs/rh7/conda/4.5.4/envs/pangeo_full_201909/lib/python3.7/site-packages/distributed/worker.py:866> exception=OSError("Timed out trying to connect to 'tcp://10.120.40.97:33653' after 10 s: in <distributed.comm.tcp.TCPConnector object at 0x2b244e8afef0>: ConnectionRefusedError: [Errno 111] Connection refused")>)
Traceback (most recent call last):
  File "/softs/rh7/conda/4.5.4/envs/pangeo_full_201909/lib/python3.7/site-packages/distributed/comm/core.py", line 215, in connect
    quiet_exceptions=EnvironmentError,
tornado.util.TimeoutError: Timeout

During handling of the above exception, another exception occurred:

Traceback (most recent call last):
  File "/softs/rh7/conda/4.5.4/envs/pangeo_full_201909/lib/python3.7/site-packages/tornado/ioloop.py", line 743, in _run_callback
    ret = callback()
  File "/softs/rh7/conda/4.5.4/envs/pangeo_full_201909/lib/python3.7/site-packages/tornado/ioloop.py", line 767, in _discard_future_result
    future.result()
  File "/softs/rh7/conda/4.5.4/envs/pangeo_full_201909/lib/python3.7/site-packages/distributed/worker.py", line 875, in heartbeat
    metrics=await self.get_metrics(),
  File "/softs/rh7/conda/4.5.4/envs/pangeo_full_201909/lib/python3.7/site-packages/distributed/core.py", line 747, in send_recv_from_rpc
    comm = await self.pool.connect(self.addr)
  File "/softs/rh7/conda/4.5.4/envs/pangeo_full_201909/lib/python3.7/site-packages/distributed/core.py", line 874, in connect
    connection_args=self.connection_args,
  File "/softs/rh7/conda/4.5.4/envs/pangeo_full_201909/lib/python3.7/site-packages/distributed/comm/core.py", line 227, in connect
    _raise(error)
  File "/softs/rh7/conda/4.5.4/envs/pangeo_full_201909/lib/python3.7/site-packages/distributed/comm/core.py", line 204, in _raise
    raise IOError(msg)
OSError: Timed out trying to connect to 'tcp://10.120.40.97:33653' after 10 s: in <distributed.comm.tcp.TCPConnector object at 0x2b244e8afef0>: ConnectionRefusedError: [Errno 111] Connection refused
tornado.application - ERROR - Exception in callback <function Worker._register_with_scheduler.<locals>.<lambda> at 0x2b2437efe2f0>
Traceback (most recent call last):
  File "/softs/rh7/conda/4.5.4/envs/pangeo_full_201909/lib/python3.7/site-packages/tornado/ioloop.py", line 907, in _run
    return self.callback()
  File "/softs/rh7/conda/4.5.4/envs/pangeo_full_201909/lib/python3.7/site-packages/distributed/worker.py", line 857, in <lambda>
    lambda: self.batched_stream.send({"op": "keep-alive"}),
  File "/softs/rh7/conda/4.5.4/envs/pangeo_full_201909/lib/python3.7/site-packages/distributed/batched.py", line 117, in send
    raise CommClosedError
distributed.comm.core.CommClosedError
tornado.application - ERROR - Exception in callback functools.partial(<bound method IOLoop._discard_future_result of <tornado.platform.asyncio.AsyncIOLoop object at 0x2b2433c61c88>>, <Task finished coro=<Worker.heartbeat() done, defined at /softs/rh7/conda/4.5.4/envs/pangeo_full_201909/lib/python3.7/site-packages/distributed/worker.py:866> exception=OSError("Timed out trying to connect to 'tcp://10.120.40.97:33653' after 10 s: in <distributed.comm.tcp.TCPConnector object at 0x2b244e382940>: ConnectionRefusedError: [Errno 111] Connection refused")>)
Traceback (most recent call last):
  File "/softs/rh7/conda/4.5.4/envs/pangeo_full_201909/lib/python3.7/site-packages/distributed/comm/core.py", line 215, in connect
    quiet_exceptions=EnvironmentError,
tornado.util.TimeoutError: Timeout

During handling of the above exception, another exception occurred:

Traceback (most recent call last):
  File "/softs/rh7/conda/4.5.4/envs/pangeo_full_201909/lib/python3.7/site-packages/tornado/ioloop.py", line 743, in _run_callback
    ret = callback()
  File "/softs/rh7/conda/4.5.4/envs/pangeo_full_201909/lib/python3.7/site-packages/tornado/ioloop.py", line 767, in _discard_future_result
    future.result()
  File "/softs/rh7/conda/4.5.4/envs/pangeo_full_201909/lib/python3.7/site-packages/distributed/worker.py", line 875, in heartbeat
    metrics=await self.get_metrics(),
  File "/softs/rh7/conda/4.5.4/envs/pangeo_full_201909/lib/python3.7/site-packages/distributed/core.py", line 747, in send_recv_from_rpc
    comm = await self.pool.connect(self.addr)
  File "/softs/rh7/conda/4.5.4/envs/pangeo_full_201909/lib/python3.7/site-packages/distributed/core.py", line 874, in connect
    connection_args=self.connection_args,
  File "/softs/rh7/conda/4.5.4/envs/pangeo_full_201909/lib/python3.7/site-packages/distributed/comm/core.py", line 227, in connect
    _raise(error)
  File "/softs/rh7/conda/4.5.4/envs/pangeo_full_201909/lib/python3.7/site-packages/distributed/comm/core.py", line 204, in _raise
    raise IOError(msg)
OSError: Timed out trying to connect to 'tcp://10.120.40.97:33653' after 10 s: in <distributed.comm.tcp.TCPConnector object at 0x2b244e382940>: ConnectionRefusedError: [Errno 111] Connection refused
tornado.application - ERROR - Exception in callback functools.partial(<bound method IOLoop._discard_future_result of <tornado.platform.asyncio.AsyncIOLoop object at 0x2b2433c61c88>>, <Task finished coro=<Worker.heartbeat() done, defined at /softs/rh7/conda/4.5.4/envs/pangeo_full_201909/lib/python3.7/site-packages/distributed/worker.py:866> exception=OSError("Timed out trying to connect to 'tcp://10.120.40.97:33653' after 10 s: in <distributed.comm.tcp.TCPConnector object at 0x2b244e382d68>: ConnectionRefusedError: [Errno 111] Connection refused")>)
Traceback (most recent call last):
  File "/softs/rh7/conda/4.5.4/envs/pangeo_full_201909/lib/python3.7/site-packages/distributed/comm/core.py", line 215, in connect
    quiet_exceptions=EnvironmentError,
tornado.util.TimeoutError: Timeout

During handling of the above exception, another exception occurred:

Traceback (most recent call last):
  File "/softs/rh7/conda/4.5.4/envs/pangeo_full_201909/lib/python3.7/site-packages/tornado/ioloop.py", line 743, in _run_callback
    ret = callback()
  File "/softs/rh7/conda/4.5.4/envs/pangeo_full_201909/lib/python3.7/site-packages/tornado/ioloop.py", line 767, in _discard_future_result
    future.result()
  File "/softs/rh7/conda/4.5.4/envs/pangeo_full_201909/lib/python3.7/site-packages/distributed/worker.py", line 875, in heartbeat
    metrics=await self.get_metrics(),
  File "/softs/rh7/conda/4.5.4/envs/pangeo_full_201909/lib/python3.7/site-packages/distributed/core.py", line 747, in send_recv_from_rpc
    comm = await self.pool.connect(self.addr)
  File "/softs/rh7/conda/4.5.4/envs/pangeo_full_201909/lib/python3.7/site-packages/distributed/core.py", line 874, in connect
    connection_args=self.connection_args,
  File "/softs/rh7/conda/4.5.4/envs/pangeo_full_201909/lib/python3.7/site-packages/distributed/comm/core.py", line 227, in connect
    _raise(error)
  File "/softs/rh7/conda/4.5.4/envs/pangeo_full_201909/lib/python3.7/site-packages/distributed/comm/core.py", line 204, in _raise
    raise IOError(msg)
OSError: Timed out trying to connect to 'tcp://10.120.40.97:33653' after 10 s: in <distributed.comm.tcp.TCPConnector object at 0x2b244e382d68>: ConnectionRefusedError: [Errno 111] Connection refused
tornado.application - ERROR - Exception in callback functools.partial(<bound method IOLoop._discard_future_result of <tornado.platform.asyncio.AsyncIOLoop object at 0x2b2433c61c88>>, <Task finished coro=<Worker.heartbeat() done, defined at /softs/rh7/conda/4.5.4/envs/pangeo_full_201909/lib/python3.7/site-packages/distributed/worker.py:866> exception=OSError("Timed out trying to connect to 'tcp://10.120.40.97:33653' after 10 s: in <distributed.comm.tcp.TCPConnector object at 0x2b244e900240>: ConnectionRefusedError: [Errno 111] Connection refused")>)
Traceback (most recent call last):
  File "/softs/rh7/conda/4.5.4/envs/pangeo_full_201909/lib/python3.7/site-packages/distributed/comm/core.py", line 215, in connect
    quiet_exceptions=EnvironmentError,
tornado.util.TimeoutError: Timeout

During handling of the above exception, another exception occurred:

Traceback (most recent call last):
  File "/softs/rh7/conda/4.5.4/envs/pangeo_full_201909/lib/python3.7/site-packages/tornado/ioloop.py", line 743, in _run_callback
    ret = callback()
  File "/softs/rh7/conda/4.5.4/envs/pangeo_full_201909/lib/python3.7/site-packages/tornado/ioloop.py", line 767, in _discard_future_result
    future.result()
  File "/softs/rh7/conda/4.5.4/envs/pangeo_full_201909/lib/python3.7/site-packages/distributed/worker.py", line 875, in heartbeat
    metrics=await self.get_metrics(),
  File "/softs/rh7/conda/4.5.4/envs/pangeo_full_201909/lib/python3.7/site-packages/distributed/core.py", line 747, in send_recv_from_rpc
    comm = await self.pool.connect(self.addr)
  File "/softs/rh7/conda/4.5.4/envs/pangeo_full_201909/lib/python3.7/site-packages/distributed/core.py", line 874, in connect
    connection_args=self.connection_args,
  File "/softs/rh7/conda/4.5.4/envs/pangeo_full_201909/lib/python3.7/site-packages/distributed/comm/core.py", line 227, in connect
    _raise(error)
  File "/softs/rh7/conda/4.5.4/envs/pangeo_full_201909/lib/python3.7/site-packages/distributed/comm/core.py", line 204, in _raise
    raise IOError(msg)
OSError: Timed out trying to connect to 'tcp://10.120.40.97:33653' after 10 s: in <distributed.comm.tcp.TCPConnector object at 0x2b244e900240>: ConnectionRefusedError: [Errno 111] Connection refused
tornado.application - ERROR - Exception in callback functools.partial(<bound method IOLoop._discard_future_result of <tornado.platform.asyncio.AsyncIOLoop object at 0x2b2433c61c88>>, <Task finished coro=<Worker.heartbeat() done, defined at /softs/rh7/conda/4.5.4/envs/pangeo_full_201909/lib/python3.7/site-packages/distributed/worker.py:866> exception=OSError("Timed out trying to connect to 'tcp://10.120.40.97:33653' after 10 s: in <distributed.comm.tcp.TCPConnector object at 0x2b244e900400>: ConnectionRefusedError: [Errno 111] Connection refused")>)
Traceback (most recent call last):
  File "/softs/rh7/conda/4.5.4/envs/pangeo_full_201909/lib/python3.7/site-packages/distributed/comm/core.py", line 215, in connect
    quiet_exceptions=EnvironmentError,
tornado.util.TimeoutError: Timeout

During handling of the above exception, another exception occurred:

Traceback (most recent call last):
  File "/softs/rh7/conda/4.5.4/envs/pangeo_full_201909/lib/python3.7/site-packages/tornado/ioloop.py", line 743, in _run_callback
    ret = callback()
  File "/softs/rh7/conda/4.5.4/envs/pangeo_full_201909/lib/python3.7/site-packages/tornado/ioloop.py", line 767, in _discard_future_result
    future.result()
  File "/softs/rh7/conda/4.5.4/envs/pangeo_full_201909/lib/python3.7/site-packages/distributed/worker.py", line 875, in heartbeat
    metrics=await self.get_metrics(),
  File "/softs/rh7/conda/4.5.4/envs/pangeo_full_201909/lib/python3.7/site-packages/distributed/core.py", line 747, in send_recv_from_rpc
    comm = await self.pool.connect(self.addr)
  File "/softs/rh7/conda/4.5.4/envs/pangeo_full_201909/lib/python3.7/site-packages/distributed/core.py", line 874, in connect
    connection_args=self.connection_args,
  File "/softs/rh7/conda/4.5.4/envs/pangeo_full_201909/lib/python3.7/site-packages/distributed/comm/core.py", line 227, in connect
    _raise(error)
  File "/softs/rh7/conda/4.5.4/envs/pangeo_full_201909/lib/python3.7/site-packages/distributed/comm/core.py", line 204, in _raise
    raise IOError(msg)
OSError: Timed out trying to connect to 'tcp://10.120.40.97:33653' after 10 s: in <distributed.comm.tcp.TCPConnector object at 0x2b244e900400>: ConnectionRefusedError: [Errno 111] Connection refused
tornado.application - ERROR - Exception in callback functools.partial(<bound method IOLoop._discard_future_result of <tornado.platform.asyncio.AsyncIOLoop object at 0x2b2433c61c88>>, <Task finished coro=<Worker.heartbeat() done, defined at /softs/rh7/conda/4.5.4/envs/pangeo_full_201909/lib/python3.7/site-packages/distributed/worker.py:866> exception=OSError("Timed out trying to connect to 'tcp://10.120.40.97:33653' after 10 s: in <distributed.comm.tcp.TCPConnector object at 0x2b244e8570b8>: ConnectionRefusedError: [Errno 111] Connection refused")>)
Traceback (most recent call last):
  File "/softs/rh7/conda/4.5.4/envs/pangeo_full_201909/lib/python3.7/site-packages/distributed/comm/core.py", line 215, in connect
    quiet_exceptions=EnvironmentError,
tornado.util.TimeoutError: Timeout

During handling of the above exception, another exception occurred:

Traceback (most recent call last):
  File "/softs/rh7/conda/4.5.4/envs/pangeo_full_201909/lib/python3.7/site-packages/tornado/ioloop.py", line 743, in _run_callback
    ret = callback()
  File "/softs/rh7/conda/4.5.4/envs/pangeo_full_201909/lib/python3.7/site-packages/tornado/ioloop.py", line 767, in _discard_future_result
    future.result()
  File "/softs/rh7/conda/4.5.4/envs/pangeo_full_201909/lib/python3.7/site-packages/distributed/worker.py", line 875, in heartbeat
    metrics=await self.get_metrics(),
  File "/softs/rh7/conda/4.5.4/envs/pangeo_full_201909/lib/python3.7/site-packages/distributed/core.py", line 747, in send_recv_from_rpc
    comm = await self.pool.connect(self.addr)
  File "/softs/rh7/conda/4.5.4/envs/pangeo_full_201909/lib/python3.7/site-packages/distributed/core.py", line 874, in connect
    connection_args=self.connection_args,
  File "/softs/rh7/conda/4.5.4/envs/pangeo_full_201909/lib/python3.7/site-packages/distributed/comm/core.py", line 227, in connect
    _raise(error)
  File "/softs/rh7/conda/4.5.4/envs/pangeo_full_201909/lib/python3.7/site-packages/distributed/comm/core.py", line 204, in _raise
    raise IOError(msg)
OSError: Timed out trying to connect to 'tcp://10.120.40.97:33653' after 10 s: in <distributed.comm.tcp.TCPConnector object at 0x2b244e8570b8>: ConnectionRefusedError: [Errno 111] Connection refused
tornado.application - ERROR - Exception in callback <function Worker._register_with_scheduler.<locals>.<lambda> at 0x2b2437efe2f0>
Traceback (most recent call last):
  File "/softs/rh7/conda/4.5.4/envs/pangeo_full_201909/lib/python3.7/site-packages/tornado/ioloop.py", line 907, in _run
    return self.callback()
  File "/softs/rh7/conda/4.5.4/envs/pangeo_full_201909/lib/python3.7/site-packages/distributed/worker.py", line 857, in <lambda>
    lambda: self.batched_stream.send({"op": "keep-alive"}),
  File "/softs/rh7/conda/4.5.4/envs/pangeo_full_201909/lib/python3.7/site-packages/distributed/batched.py", line 117, in send
    raise CommClosedError
distributed.comm.core.CommClosedError
tornado.application - ERROR - Exception in callback functools.partial(<bound method IOLoop._discard_future_result of <tornado.platform.asyncio.AsyncIOLoop object at 0x2b2433c61c88>>, <Task finished coro=<Worker.heartbeat() done, defined at /softs/rh7/conda/4.5.4/envs/pangeo_full_201909/lib/python3.7/site-packages/distributed/worker.py:866> exception=OSError("Timed out trying to connect to 'tcp://10.120.40.97:33653' after 10 s: in <distributed.comm.tcp.TCPConnector object at 0x2b244e857630>: ConnectionRefusedError: [Errno 111] Connection refused")>)
Traceback (most recent call last):
  File "/softs/rh7/conda/4.5.4/envs/pangeo_full_201909/lib/python3.7/site-packages/distributed/comm/core.py", line 215, in connect
    quiet_exceptions=EnvironmentError,
tornado.util.TimeoutError: Timeout

During handling of the above exception, another exception occurred:

Traceback (most recent call last):
  File "/softs/rh7/conda/4.5.4/envs/pangeo_full_201909/lib/python3.7/site-packages/tornado/ioloop.py", line 743, in _run_callback
    ret = callback()
  File "/softs/rh7/conda/4.5.4/envs/pangeo_full_201909/lib/python3.7/site-packages/tornado/ioloop.py", line 767, in _discard_future_result
    future.result()
  File "/softs/rh7/conda/4.5.4/envs/pangeo_full_201909/lib/python3.7/site-packages/distributed/worker.py", line 875, in heartbeat
    metrics=await self.get_metrics(),
  File "/softs/rh7/conda/4.5.4/envs/pangeo_full_201909/lib/python3.7/site-packages/distributed/core.py", line 747, in send_recv_from_rpc
    comm = await self.pool.connect(self.addr)
  File "/softs/rh7/conda/4.5.4/envs/pangeo_full_201909/lib/python3.7/site-packages/distributed/core.py", line 874, in connect
    connection_args=self.connection_args,
  File "/softs/rh7/conda/4.5.4/envs/pangeo_full_201909/lib/python3.7/site-packages/distributed/comm/core.py", line 227, in connect
    _raise(error)
  File "/softs/rh7/conda/4.5.4/envs/pangeo_full_201909/lib/python3.7/site-packages/distributed/comm/core.py", line 204, in _raise
    raise IOError(msg)
OSError: Timed out trying to connect to 'tcp://10.120.40.97:33653' after 10 s: in <distributed.comm.tcp.TCPConnector object at 0x2b244e857630>: ConnectionRefusedError: [Errno 111] Connection refused
tornado.application - ERROR - Exception in callback functools.partial(<bound method IOLoop._discard_future_result of <tornado.platform.asyncio.AsyncIOLoop object at 0x2b2433c61c88>>, <Task finished coro=<Worker.heartbeat() done, defined at /softs/rh7/conda/4.5.4/envs/pangeo_full_201909/lib/python3.7/site-packages/distributed/worker.py:866> exception=OSError("Timed out trying to connect to 'tcp://10.120.40.97:33653' after 10 s: in <distributed.comm.tcp.TCPConnector object at 0x2b244e900860>: ConnectionRefusedError: [Errno 111] Connection refused")>)
Traceback (most recent call last):
  File "/softs/rh7/conda/4.5.4/envs/pangeo_full_201909/lib/python3.7/site-packages/distributed/comm/core.py", line 215, in connect
    quiet_exceptions=EnvironmentError,
tornado.util.TimeoutError: Timeout

During handling of the above exception, another exception occurred:

Traceback (most recent call last):
  File "/softs/rh7/conda/4.5.4/envs/pangeo_full_201909/lib/python3.7/site-packages/tornado/ioloop.py", line 743, in _run_callback
    ret = callback()
  File "/softs/rh7/conda/4.5.4/envs/pangeo_full_201909/lib/python3.7/site-packages/tornado/ioloop.py", line 767, in _discard_future_result
    future.result()
  File "/softs/rh7/conda/4.5.4/envs/pangeo_full_201909/lib/python3.7/site-packages/distributed/worker.py", line 875, in heartbeat
    metrics=await self.get_metrics(),
  File "/softs/rh7/conda/4.5.4/envs/pangeo_full_201909/lib/python3.7/site-packages/distributed/core.py", line 747, in send_recv_from_rpc
    comm = await self.pool.connect(self.addr)
  File "/softs/rh7/conda/4.5.4/envs/pangeo_full_201909/lib/python3.7/site-packages/distributed/core.py", line 874, in connect
    connection_args=self.connection_args,
  File "/softs/rh7/conda/4.5.4/envs/pangeo_full_201909/lib/python3.7/site-packages/distributed/comm/core.py", line 227, in connect
    _raise(error)
  File "/softs/rh7/conda/4.5.4/envs/pangeo_full_201909/lib/python3.7/site-packages/distributed/comm/core.py", line 204, in _raise
    raise IOError(msg)
OSError: Timed out trying to connect to 'tcp://10.120.40.97:33653' after 10 s: in <distributed.comm.tcp.TCPConnector object at 0x2b244e900860>: ConnectionRefusedError: [Errno 111] Connection refused
tornado.application - ERROR - Exception in callback functools.partial(<bound method IOLoop._discard_future_result of <tornado.platform.asyncio.AsyncIOLoop object at 0x2b2433c61c88>>, <Task finished coro=<Worker.heartbeat() done, defined at /softs/rh7/conda/4.5.4/envs/pangeo_full_201909/lib/python3.7/site-packages/distributed/worker.py:866> exception=OSError("Timed out trying to connect to 'tcp://10.120.40.97:33653' after 10 s: in <distributed.comm.tcp.TCPConnector object at 0x2b244dcc9588>: ConnectionRefusedError: [Errno 111] Connection refused")>)
Traceback (most recent call last):
  File "/softs/rh7/conda/4.5.4/envs/pangeo_full_201909/lib/python3.7/site-packages/distributed/comm/core.py", line 215, in connect
    quiet_exceptions=EnvironmentError,
tornado.util.TimeoutError: Timeout

During handling of the above exception, another exception occurred:

Traceback (most recent call last):
  File "/softs/rh7/conda/4.5.4/envs/pangeo_full_201909/lib/python3.7/site-packages/tornado/ioloop.py", line 743, in _run_callback
    ret = callback()
  File "/softs/rh7/conda/4.5.4/envs/pangeo_full_201909/lib/python3.7/site-packages/tornado/ioloop.py", line 767, in _discard_future_result
    future.result()
  File "/softs/rh7/conda/4.5.4/envs/pangeo_full_201909/lib/python3.7/site-packages/distributed/worker.py", line 875, in heartbeat
    metrics=await self.get_metrics(),
  File "/softs/rh7/conda/4.5.4/envs/pangeo_full_201909/lib/python3.7/site-packages/distributed/core.py", line 747, in send_recv_from_rpc
    comm = await self.pool.connect(self.addr)
  File "/softs/rh7/conda/4.5.4/envs/pangeo_full_201909/lib/python3.7/site-packages/distributed/core.py", line 874, in connect
    connection_args=self.connection_args,
  File "/softs/rh7/conda/4.5.4/envs/pangeo_full_201909/lib/python3.7/site-packages/distributed/comm/core.py", line 227, in connect
    _raise(error)
  File "/softs/rh7/conda/4.5.4/envs/pangeo_full_201909/lib/python3.7/site-packages/distributed/comm/core.py", line 204, in _raise
    raise IOError(msg)
OSError: Timed out trying to connect to 'tcp://10.120.40.97:33653' after 10 s: in <distributed.comm.tcp.TCPConnector object at 0x2b244dcc9588>: ConnectionRefusedError: [Errno 111] Connection refused
tornado.application - ERROR - Exception in callback functools.partial(<bound method IOLoop._discard_future_result of <tornado.platform.asyncio.AsyncIOLoop object at 0x2b2433c61c88>>, <Task finished coro=<Worker.heartbeat() done, defined at /softs/rh7/conda/4.5.4/envs/pangeo_full_201909/lib/python3.7/site-packages/distributed/worker.py:866> exception=OSError("Timed out trying to connect to 'tcp://10.120.40.97:33653' after 10 s: in <distributed.comm.tcp.TCPConnector object at 0x2b244dd06ef0>: ConnectionRefusedError: [Errno 111] Connection refused")>)
Traceback (most recent call last):
  File "/softs/rh7/conda/4.5.4/envs/pangeo_full_201909/lib/python3.7/site-packages/distributed/comm/core.py", line 215, in connect
    quiet_exceptions=EnvironmentError,
tornado.util.TimeoutError: Timeout

During handling of the above exception, another exception occurred:

Traceback (most recent call last):
  File "/softs/rh7/conda/4.5.4/envs/pangeo_full_201909/lib/python3.7/site-packages/tornado/ioloop.py", line 743, in _run_callback
    ret = callback()
  File "/softs/rh7/conda/4.5.4/envs/pangeo_full_201909/lib/python3.7/site-packages/tornado/ioloop.py", line 767, in _discard_future_result
    future.result()
  File "/softs/rh7/conda/4.5.4/envs/pangeo_full_201909/lib/python3.7/site-packages/distributed/worker.py", line 875, in heartbeat
    metrics=await self.get_metrics(),
  File "/softs/rh7/conda/4.5.4/envs/pangeo_full_201909/lib/python3.7/site-packages/distributed/core.py", line 747, in send_recv_from_rpc
    comm = await self.pool.connect(self.addr)
  File "/softs/rh7/conda/4.5.4/envs/pangeo_full_201909/lib/python3.7/site-packages/distributed/core.py", line 874, in connect
    connection_args=self.connection_args,
  File "/softs/rh7/conda/4.5.4/envs/pangeo_full_201909/lib/python3.7/site-packages/distributed/comm/core.py", line 227, in connect
    _raise(error)
  File "/softs/rh7/conda/4.5.4/envs/pangeo_full_201909/lib/python3.7/site-packages/distributed/comm/core.py", line 204, in _raise
    raise IOError(msg)
OSError: Timed out trying to connect to 'tcp://10.120.40.97:33653' after 10 s: in <distributed.comm.tcp.TCPConnector object at 0x2b244dd06ef0>: ConnectionRefusedError: [Errno 111] Connection refused
tornado.application - ERROR - Exception in callback functools.partial(<bound method IOLoop._discard_future_result of <tornado.platform.asyncio.AsyncIOLoop object at 0x2b2433c61c88>>, <Task finished coro=<Worker.heartbeat() done, defined at /softs/rh7/conda/4.5.4/envs/pangeo_full_201909/lib/python3.7/site-packages/distributed/worker.py:866> exception=OSError("Timed out trying to connect to 'tcp://10.120.40.97:33653' after 10 s: in <distributed.comm.tcp.TCPConnector object at 0x2b244e857be0>: ConnectionRefusedError: [Errno 111] Connection refused")>)
Traceback (most recent call last):
  File "/softs/rh7/conda/4.5.4/envs/pangeo_full_201909/lib/python3.7/site-packages/distributed/comm/core.py", line 215, in connect
    quiet_exceptions=EnvironmentError,
tornado.util.TimeoutError: Timeout

During handling of the above exception, another exception occurred:

Traceback (most recent call last):
  File "/softs/rh7/conda/4.5.4/envs/pangeo_full_201909/lib/python3.7/site-packages/tornado/ioloop.py", line 743, in _run_callback
    ret = callback()
  File "/softs/rh7/conda/4.5.4/envs/pangeo_full_201909/lib/python3.7/site-packages/tornado/ioloop.py", line 767, in _discard_future_result
    future.result()
  File "/softs/rh7/conda/4.5.4/envs/pangeo_full_201909/lib/python3.7/site-packages/distributed/worker.py", line 875, in heartbeat
    metrics=await self.get_metrics(),
  File "/softs/rh7/conda/4.5.4/envs/pangeo_full_201909/lib/python3.7/site-packages/distributed/core.py", line 747, in send_recv_from_rpc
    comm = await self.pool.connect(self.addr)
  File "/softs/rh7/conda/4.5.4/envs/pangeo_full_201909/lib/python3.7/site-packages/distributed/core.py", line 874, in connect
    connection_args=self.connection_args,
  File "/softs/rh7/conda/4.5.4/envs/pangeo_full_201909/lib/python3.7/site-packages/distributed/comm/core.py", line 227, in connect
    _raise(error)
  File "/softs/rh7/conda/4.5.4/envs/pangeo_full_201909/lib/python3.7/site-packages/distributed/comm/core.py", line 204, in _raise
    raise IOError(msg)
OSError: Timed out trying to connect to 'tcp://10.120.40.97:33653' after 10 s: in <distributed.comm.tcp.TCPConnector object at 0x2b244e857be0>: ConnectionRefusedError: [Errno 111] Connection refused
tornado.application - ERROR - Exception in callback functools.partial(<bound method IOLoop._discard_future_result of <tornado.platform.asyncio.AsyncIOLoop object at 0x2b2433c61c88>>, <Task finished coro=<Worker.heartbeat() done, defined at /softs/rh7/conda/4.5.4/envs/pangeo_full_201909/lib/python3.7/site-packages/distributed/worker.py:866> exception=OSError("Timed out trying to connect to 'tcp://10.120.40.97:33653' after 10 s: in <distributed.comm.tcp.TCPConnector object at 0x2b244dd90240>: ConnectionRefusedError: [Errno 111] Connection refused")>)
Traceback (most recent call last):
  File "/softs/rh7/conda/4.5.4/envs/pangeo_full_201909/lib/python3.7/site-packages/distributed/comm/core.py", line 215, in connect
    quiet_exceptions=EnvironmentError,
tornado.util.TimeoutError: Timeout

During handling of the above exception, another exception occurred:

Traceback (most recent call last):
  File "/softs/rh7/conda/4.5.4/envs/pangeo_full_201909/lib/python3.7/site-packages/tornado/ioloop.py", line 743, in _run_callback
    ret = callback()
  File "/softs/rh7/conda/4.5.4/envs/pangeo_full_201909/lib/python3.7/site-packages/tornado/ioloop.py", line 767, in _discard_future_result
    future.result()
  File "/softs/rh7/conda/4.5.4/envs/pangeo_full_201909/lib/python3.7/site-packages/distributed/worker.py", line 875, in heartbeat
    metrics=await self.get_metrics(),
  File "/softs/rh7/conda/4.5.4/envs/pangeo_full_201909/lib/python3.7/site-packages/distributed/core.py", line 747, in send_recv_from_rpc
    comm = await self.pool.connect(self.addr)
  File "/softs/rh7/conda/4.5.4/envs/pangeo_full_201909/lib/python3.7/site-packages/distributed/core.py", line 874, in connect
    connection_args=self.connection_args,
  File "/softs/rh7/conda/4.5.4/envs/pangeo_full_201909/lib/python3.7/site-packages/distributed/comm/core.py", line 227, in connect
    _raise(error)
  File "/softs/rh7/conda/4.5.4/envs/pangeo_full_201909/lib/python3.7/site-packages/distributed/comm/core.py", line 204, in _raise
    raise IOError(msg)
OSError: Timed out trying to connect to 'tcp://10.120.40.97:33653' after 10 s: in <distributed.comm.tcp.TCPConnector object at 0x2b244dd90240>: ConnectionRefusedError: [Errno 111] Connection refused
tornado.application - ERROR - Exception in callback <function Worker._register_with_scheduler.<locals>.<lambda> at 0x2b2437efe2f0>
Traceback (most recent call last):
  File "/softs/rh7/conda/4.5.4/envs/pangeo_full_201909/lib/python3.7/site-packages/tornado/ioloop.py", line 907, in _run
    return self.callback()
  File "/softs/rh7/conda/4.5.4/envs/pangeo_full_201909/lib/python3.7/site-packages/distributed/worker.py", line 857, in <lambda>
    lambda: self.batched_stream.send({"op": "keep-alive"}),
  File "/softs/rh7/conda/4.5.4/envs/pangeo_full_201909/lib/python3.7/site-packages/distributed/batched.py", line 117, in send
    raise CommClosedError
distributed.comm.core.CommClosedError
tornado.application - ERROR - Exception in callback functools.partial(<bound method IOLoop._discard_future_result of <tornado.platform.asyncio.AsyncIOLoop object at 0x2b2433c61c88>>, <Task finished coro=<Worker.heartbeat() done, defined at /softs/rh7/conda/4.5.4/envs/pangeo_full_201909/lib/python3.7/site-packages/distributed/worker.py:866> exception=OSError("Timed out trying to connect to 'tcp://10.120.40.97:33653' after 10 s: in <distributed.comm.tcp.TCPConnector object at 0x2b244e900198>: ConnectionRefusedError: [Errno 111] Connection refused")>)
Traceback (most recent call last):
  File "/softs/rh7/conda/4.5.4/envs/pangeo_full_201909/lib/python3.7/site-packages/distributed/comm/core.py", line 215, in connect
    quiet_exceptions=EnvironmentError,
tornado.util.TimeoutError: Timeout

During handling of the above exception, another exception occurred:

Traceback (most recent call last):
  File "/softs/rh7/conda/4.5.4/envs/pangeo_full_201909/lib/python3.7/site-packages/tornado/ioloop.py", line 743, in _run_callback
    ret = callback()
  File "/softs/rh7/conda/4.5.4/envs/pangeo_full_201909/lib/python3.7/site-packages/tornado/ioloop.py", line 767, in _discard_future_result
    future.result()
  File "/softs/rh7/conda/4.5.4/envs/pangeo_full_201909/lib/python3.7/site-packages/distributed/worker.py", line 875, in heartbeat
    metrics=await self.get_metrics(),
  File "/softs/rh7/conda/4.5.4/envs/pangeo_full_201909/lib/python3.7/site-packages/distributed/core.py", line 747, in send_recv_from_rpc
    comm = await self.pool.connect(self.addr)
  File "/softs/rh7/conda/4.5.4/envs/pangeo_full_201909/lib/python3.7/site-packages/distributed/core.py", line 874, in connect
    connection_args=self.connection_args,
  File "/softs/rh7/conda/4.5.4/envs/pangeo_full_201909/lib/python3.7/site-packages/distributed/comm/core.py", line 227, in connect
    _raise(error)
  File "/softs/rh7/conda/4.5.4/envs/pangeo_full_201909/lib/python3.7/site-packages/distributed/comm/core.py", line 204, in _raise
    raise IOError(msg)
OSError: Timed out trying to connect to 'tcp://10.120.40.97:33653' after 10 s: in <distributed.comm.tcp.TCPConnector object at 0x2b244e900198>: ConnectionRefusedError: [Errno 111] Connection refused
tornado.application - ERROR - Exception in callback functools.partial(<bound method IOLoop._discard_future_result of <tornado.platform.asyncio.AsyncIOLoop object at 0x2b2433c61c88>>, <Task finished coro=<Worker.heartbeat() done, defined at /softs/rh7/conda/4.5.4/envs/pangeo_full_201909/lib/python3.7/site-packages/distributed/worker.py:866> exception=OSError("Timed out trying to connect to 'tcp://10.120.40.97:33653' after 10 s: in <distributed.comm.tcp.TCPConnector object at 0x2b244dd906d8>: ConnectionRefusedError: [Errno 111] Connection refused")>)
Traceback (most recent call last):
  File "/softs/rh7/conda/4.5.4/envs/pangeo_full_201909/lib/python3.7/site-packages/distributed/comm/core.py", line 215, in connect
    quiet_exceptions=EnvironmentError,
tornado.util.TimeoutError: Timeout

During handling of the above exception, another exception occurred:

Traceback (most recent call last):
  File "/softs/rh7/conda/4.5.4/envs/pangeo_full_201909/lib/python3.7/site-packages/tornado/ioloop.py", line 743, in _run_callback
    ret = callback()
  File "/softs/rh7/conda/4.5.4/envs/pangeo_full_201909/lib/python3.7/site-packages/tornado/ioloop.py", line 767, in _discard_future_result
    future.result()
  File "/softs/rh7/conda/4.5.4/envs/pangeo_full_201909/lib/python3.7/site-packages/distributed/worker.py", line 875, in heartbeat
    metrics=await self.get_metrics(),
  File "/softs/rh7/conda/4.5.4/envs/pangeo_full_201909/lib/python3.7/site-packages/distributed/core.py", line 747, in send_recv_from_rpc
    comm = await self.pool.connect(self.addr)
  File "/softs/rh7/conda/4.5.4/envs/pangeo_full_201909/lib/python3.7/site-packages/distributed/core.py", line 874, in connect
    connection_args=self.connection_args,
  File "/softs/rh7/conda/4.5.4/envs/pangeo_full_201909/lib/python3.7/site-packages/distributed/comm/core.py", line 227, in connect
    _raise(error)
  File "/softs/rh7/conda/4.5.4/envs/pangeo_full_201909/lib/python3.7/site-packages/distributed/comm/core.py", line 204, in _raise
    raise IOError(msg)
OSError: Timed out trying to connect to 'tcp://10.120.40.97:33653' after 10 s: in <distributed.comm.tcp.TCPConnector object at 0x2b244dd906d8>: ConnectionRefusedError: [Errno 111] Connection refused
tornado.application - ERROR - Exception in callback functools.partial(<bound method IOLoop._discard_future_result of <tornado.platform.asyncio.AsyncIOLoop object at 0x2b2433c61c88>>, <Task finished coro=<Worker.heartbeat() done, defined at /softs/rh7/conda/4.5.4/envs/pangeo_full_201909/lib/python3.7/site-packages/distributed/worker.py:866> exception=OSError("Timed out trying to connect to 'tcp://10.120.40.97:33653' after 10 s: in <distributed.comm.tcp.TCPConnector object at 0x2b2437f8f3c8>: ConnectionRefusedError: [Errno 111] Connection refused")>)
Traceback (most recent call last):
  File "/softs/rh7/conda/4.5.4/envs/pangeo_full_201909/lib/python3.7/site-packages/distributed/comm/core.py", line 215, in connect
    quiet_exceptions=EnvironmentError,
tornado.util.TimeoutError: Timeout

During handling of the above exception, another exception occurred:

Traceback (most recent call last):
  File "/softs/rh7/conda/4.5.4/envs/pangeo_full_201909/lib/python3.7/site-packages/tornado/ioloop.py", line 743, in _run_callback
    ret = callback()
  File "/softs/rh7/conda/4.5.4/envs/pangeo_full_201909/lib/python3.7/site-packages/tornado/ioloop.py", line 767, in _discard_future_result
    future.result()
  File "/softs/rh7/conda/4.5.4/envs/pangeo_full_201909/lib/python3.7/site-packages/distributed/worker.py", line 875, in heartbeat
    metrics=await self.get_metrics(),
  File "/softs/rh7/conda/4.5.4/envs/pangeo_full_201909/lib/python3.7/site-packages/distributed/core.py", line 747, in send_recv_from_rpc
    comm = await self.pool.connect(self.addr)
  File "/softs/rh7/conda/4.5.4/envs/pangeo_full_201909/lib/python3.7/site-packages/distributed/core.py", line 874, in connect
    connection_args=self.connection_args,
  File "/softs/rh7/conda/4.5.4/envs/pangeo_full_201909/lib/python3.7/site-packages/distributed/comm/core.py", line 227, in connect
    _raise(error)
  File "/softs/rh7/conda/4.5.4/envs/pangeo_full_201909/lib/python3.7/site-packages/distributed/comm/core.py", line 204, in _raise
    raise IOError(msg)
OSError: Timed out trying to connect to 'tcp://10.120.40.97:33653' after 10 s: in <distributed.comm.tcp.TCPConnector object at 0x2b2437f8f3c8>: ConnectionRefusedError: [Errno 111] Connection refused
tornado.application - ERROR - Exception in callback functools.partial(<bound method IOLoop._discard_future_result of <tornado.platform.asyncio.AsyncIOLoop object at 0x2b2433c61c88>>, <Task finished coro=<Worker.heartbeat() done, defined at /softs/rh7/conda/4.5.4/envs/pangeo_full_201909/lib/python3.7/site-packages/distributed/worker.py:866> exception=OSError("Timed out trying to connect to 'tcp://10.120.40.97:33653' after 10 s: in <distributed.comm.tcp.TCPConnector object at 0x2b244e857710>: ConnectionRefusedError: [Errno 111] Connection refused")>)
Traceback (most recent call last):
  File "/softs/rh7/conda/4.5.4/envs/pangeo_full_201909/lib/python3.7/site-packages/distributed/comm/core.py", line 215, in connect
    quiet_exceptions=EnvironmentError,
tornado.util.TimeoutError: Timeout

During handling of the above exception, another exception occurred:

Traceback (most recent call last):
  File "/softs/rh7/conda/4.5.4/envs/pangeo_full_201909/lib/python3.7/site-packages/tornado/ioloop.py", line 743, in _run_callback
    ret = callback()
  File "/softs/rh7/conda/4.5.4/envs/pangeo_full_201909/lib/python3.7/site-packages/tornado/ioloop.py", line 767, in _discard_future_result
    future.result()
  File "/softs/rh7/conda/4.5.4/envs/pangeo_full_201909/lib/python3.7/site-packages/distributed/worker.py", line 875, in heartbeat
    metrics=await self.get_metrics(),
  File "/softs/rh7/conda/4.5.4/envs/pangeo_full_201909/lib/python3.7/site-packages/distributed/core.py", line 747, in send_recv_from_rpc
    comm = await self.pool.connect(self.addr)
  File "/softs/rh7/conda/4.5.4/envs/pangeo_full_201909/lib/python3.7/site-packages/distributed/core.py", line 874, in connect
    connection_args=self.connection_args,
  File "/softs/rh7/conda/4.5.4/envs/pangeo_full_201909/lib/python3.7/site-packages/distributed/comm/core.py", line 227, in connect
    _raise(error)
  File "/softs/rh7/conda/4.5.4/envs/pangeo_full_201909/lib/python3.7/site-packages/distributed/comm/core.py", line 204, in _raise
    raise IOError(msg)
OSError: Timed out trying to connect to 'tcp://10.120.40.97:33653' after 10 s: in <distributed.comm.tcp.TCPConnector object at 0x2b244e857710>: ConnectionRefusedError: [Errno 111] Connection refused
tornado.application - ERROR - Exception in callback functools.partial(<bound method IOLoop._discard_future_result of <tornado.platform.asyncio.AsyncIOLoop object at 0x2b2433c61c88>>, <Task finished coro=<Worker.heartbeat() done, defined at /softs/rh7/conda/4.5.4/envs/pangeo_full_201909/lib/python3.7/site-packages/distributed/worker.py:866> exception=OSError("Timed out trying to connect to 'tcp://10.120.40.97:33653' after 10 s: in <distributed.comm.tcp.TCPConnector object at 0x2b244e900eb8>: ConnectionRefusedError: [Errno 111] Connection refused")>)
Traceback (most recent call last):
  File "/softs/rh7/conda/4.5.4/envs/pangeo_full_201909/lib/python3.7/site-packages/distributed/comm/core.py", line 215, in connect
    quiet_exceptions=EnvironmentError,
tornado.util.TimeoutError: Timeout

During handling of the above exception, another exception occurred:

Traceback (most recent call last):
  File "/softs/rh7/conda/4.5.4/envs/pangeo_full_201909/lib/python3.7/site-packages/tornado/ioloop.py", line 743, in _run_callback
    ret = callback()
  File "/softs/rh7/conda/4.5.4/envs/pangeo_full_201909/lib/python3.7/site-packages/tornado/ioloop.py", line 767, in _discard_future_result
    future.result()
  File "/softs/rh7/conda/4.5.4/envs/pangeo_full_201909/lib/python3.7/site-packages/distributed/worker.py", line 875, in heartbeat
    metrics=await self.get_metrics(),
  File "/softs/rh7/conda/4.5.4/envs/pangeo_full_201909/lib/python3.7/site-packages/distributed/core.py", line 747, in send_recv_from_rpc
    comm = await self.pool.connect(self.addr)
  File "/softs/rh7/conda/4.5.4/envs/pangeo_full_201909/lib/python3.7/site-packages/distributed/core.py", line 874, in connect
    connection_args=self.connection_args,
  File "/softs/rh7/conda/4.5.4/envs/pangeo_full_201909/lib/python3.7/site-packages/distributed/comm/core.py", line 227, in connect
    _raise(error)
  File "/softs/rh7/conda/4.5.4/envs/pangeo_full_201909/lib/python3.7/site-packages/distributed/comm/core.py", line 204, in _raise
    raise IOError(msg)
OSError: Timed out trying to connect to 'tcp://10.120.40.97:33653' after 10 s: in <distributed.comm.tcp.TCPConnector object at 0x2b244e900eb8>: ConnectionRefusedError: [Errno 111] Connection refused
tornado.application - ERROR - Exception in callback <function Worker._register_with_scheduler.<locals>.<lambda> at 0x2b2437efe2f0>
Traceback (most recent call last):
  File "/softs/rh7/conda/4.5.4/envs/pangeo_full_201909/lib/python3.7/site-packages/tornado/ioloop.py", line 907, in _run
    return self.callback()
  File "/softs/rh7/conda/4.5.4/envs/pangeo_full_201909/lib/python3.7/site-packages/distributed/worker.py", line 857, in <lambda>
    lambda: self.batched_stream.send({"op": "keep-alive"}),
  File "/softs/rh7/conda/4.5.4/envs/pangeo_full_201909/lib/python3.7/site-packages/distributed/batched.py", line 117, in send
    raise CommClosedError
distributed.comm.core.CommClosedError
tornado.application - ERROR - Exception in callback functools.partial(<bound method IOLoop._discard_future_result of <tornado.platform.asyncio.AsyncIOLoop object at 0x2b2433c61c88>>, <Task finished coro=<Worker.heartbeat() done, defined at /softs/rh7/conda/4.5.4/envs/pangeo_full_201909/lib/python3.7/site-packages/distributed/worker.py:866> exception=OSError("Timed out trying to connect to 'tcp://10.120.40.97:33653' after 10 s: in <distributed.comm.tcp.TCPConnector object at 0x2b244e900d30>: ConnectionRefusedError: [Errno 111] Connection refused")>)
Traceback (most recent call last):
  File "/softs/rh7/conda/4.5.4/envs/pangeo_full_201909/lib/python3.7/site-packages/distributed/comm/core.py", line 215, in connect
    quiet_exceptions=EnvironmentError,
tornado.util.TimeoutError: Timeout

During handling of the above exception, another exception occurred:

Traceback (most recent call last):
  File "/softs/rh7/conda/4.5.4/envs/pangeo_full_201909/lib/python3.7/site-packages/tornado/ioloop.py", line 743, in _run_callback
    ret = callback()
  File "/softs/rh7/conda/4.5.4/envs/pangeo_full_201909/lib/python3.7/site-packages/tornado/ioloop.py", line 767, in _discard_future_result
    future.result()
  File "/softs/rh7/conda/4.5.4/envs/pangeo_full_201909/lib/python3.7/site-packages/distributed/worker.py", line 875, in heartbeat
    metrics=await self.get_metrics(),
  File "/softs/rh7/conda/4.5.4/envs/pangeo_full_201909/lib/python3.7/site-packages/distributed/core.py", line 747, in send_recv_from_rpc
    comm = await self.pool.connect(self.addr)
  File "/softs/rh7/conda/4.5.4/envs/pangeo_full_201909/lib/python3.7/site-packages/distributed/core.py", line 874, in connect
    connection_args=self.connection_args,
  File "/softs/rh7/conda/4.5.4/envs/pangeo_full_201909/lib/python3.7/site-packages/distributed/comm/core.py", line 227, in connect
    _raise(error)
  File "/softs/rh7/conda/4.5.4/envs/pangeo_full_201909/lib/python3.7/site-packages/distributed/comm/core.py", line 204, in _raise
    raise IOError(msg)
OSError: Timed out trying to connect to 'tcp://10.120.40.97:33653' after 10 s: in <distributed.comm.tcp.TCPConnector object at 0x2b244e900d30>: ConnectionRefusedError: [Errno 111] Connection refused
tornado.application - ERROR - Exception in callback functools.partial(<bound method IOLoop._discard_future_result of <tornado.platform.asyncio.AsyncIOLoop object at 0x2b2433c61c88>>, <Task finished coro=<Worker.heartbeat() done, defined at /softs/rh7/conda/4.5.4/envs/pangeo_full_201909/lib/python3.7/site-packages/distributed/worker.py:866> exception=OSError("Timed out trying to connect to 'tcp://10.120.40.97:33653' after 10 s: in <distributed.comm.tcp.TCPConnector object at 0x2b244e659cf8>: ConnectionRefusedError: [Errno 111] Connection refused")>)
Traceback (most recent call last):
  File "/softs/rh7/conda/4.5.4/envs/pangeo_full_201909/lib/python3.7/site-packages/distributed/comm/core.py", line 215, in connect
    quiet_exceptions=EnvironmentError,
tornado.util.TimeoutError: Timeout

During handling of the above exception, another exception occurred:

Traceback (most recent call last):
  File "/softs/rh7/conda/4.5.4/envs/pangeo_full_201909/lib/python3.7/site-packages/tornado/ioloop.py", line 743, in _run_callback
    ret = callback()
  File "/softs/rh7/conda/4.5.4/envs/pangeo_full_201909/lib/python3.7/site-packages/tornado/ioloop.py", line 767, in _discard_future_result
    future.result()
  File "/softs/rh7/conda/4.5.4/envs/pangeo_full_201909/lib/python3.7/site-packages/distributed/worker.py", line 875, in heartbeat
    metrics=await self.get_metrics(),
  File "/softs/rh7/conda/4.5.4/envs/pangeo_full_201909/lib/python3.7/site-packages/distributed/core.py", line 747, in send_recv_from_rpc
    comm = await self.pool.connect(self.addr)
  File "/softs/rh7/conda/4.5.4/envs/pangeo_full_201909/lib/python3.7/site-packages/distributed/core.py", line 874, in connect
    connection_args=self.connection_args,
  File "/softs/rh7/conda/4.5.4/envs/pangeo_full_201909/lib/python3.7/site-packages/distributed/comm/core.py", line 227, in connect
    _raise(error)
  File "/softs/rh7/conda/4.5.4/envs/pangeo_full_201909/lib/python3.7/site-packages/distributed/comm/core.py", line 204, in _raise
    raise IOError(msg)
OSError: Timed out trying to connect to 'tcp://10.120.40.97:33653' after 10 s: in <distributed.comm.tcp.TCPConnector object at 0x2b244e659cf8>: ConnectionRefusedError: [Errno 111] Connection refused
tornado.application - ERROR - Exception in callback functools.partial(<bound method IOLoop._discard_future_result of <tornado.platform.asyncio.AsyncIOLoop object at 0x2b2433c61c88>>, <Task finished coro=<Worker.heartbeat() done, defined at /softs/rh7/conda/4.5.4/envs/pangeo_full_201909/lib/python3.7/site-packages/distributed/worker.py:866> exception=OSError("Timed out trying to connect to 'tcp://10.120.40.97:33653' after 10 s: in <distributed.comm.tcp.TCPConnector object at 0x2b244e8578d0>: ConnectionRefusedError: [Errno 111] Connection refused")>)
Traceback (most recent call last):
  File "/softs/rh7/conda/4.5.4/envs/pangeo_full_201909/lib/python3.7/site-packages/distributed/comm/core.py", line 215, in connect
    quiet_exceptions=EnvironmentError,
tornado.util.TimeoutError: Timeout

During handling of the above exception, another exception occurred:

Traceback (most recent call last):
  File "/softs/rh7/conda/4.5.4/envs/pangeo_full_201909/lib/python3.7/site-packages/tornado/ioloop.py", line 743, in _run_callback
    ret = callback()
  File "/softs/rh7/conda/4.5.4/envs/pangeo_full_201909/lib/python3.7/site-packages/tornado/ioloop.py", line 767, in _discard_future_result
    future.result()
  File "/softs/rh7/conda/4.5.4/envs/pangeo_full_201909/lib/python3.7/site-packages/distributed/worker.py", line 875, in heartbeat
    metrics=await self.get_metrics(),
  File "/softs/rh7/conda/4.5.4/envs/pangeo_full_201909/lib/python3.7/site-packages/distributed/core.py", line 747, in send_recv_from_rpc
    comm = await self.pool.connect(self.addr)
  File "/softs/rh7/conda/4.5.4/envs/pangeo_full_201909/lib/python3.7/site-packages/distributed/core.py", line 874, in connect
    connection_args=self.connection_args,
  File "/softs/rh7/conda/4.5.4/envs/pangeo_full_201909/lib/python3.7/site-packages/distributed/comm/core.py", line 227, in connect
    _raise(error)
  File "/softs/rh7/conda/4.5.4/envs/pangeo_full_201909/lib/python3.7/site-packages/distributed/comm/core.py", line 204, in _raise
    raise IOError(msg)
OSError: Timed out trying to connect to 'tcp://10.120.40.97:33653' after 10 s: in <distributed.comm.tcp.TCPConnector object at 0x2b244e8578d0>: ConnectionRefusedError: [Errno 111] Connection refused
tornado.application - ERROR - Exception in callback functools.partial(<bound method IOLoop._discard_future_result of <tornado.platform.asyncio.AsyncIOLoop object at 0x2b2433c61c88>>, <Task finished coro=<Worker.heartbeat() done, defined at /softs/rh7/conda/4.5.4/envs/pangeo_full_201909/lib/python3.7/site-packages/distributed/worker.py:866> exception=OSError("Timed out trying to connect to 'tcp://10.120.40.97:33653' after 10 s: in <distributed.comm.tcp.TCPConnector object at 0x2b244dd90f28>: ConnectionRefusedError: [Errno 111] Connection refused")>)
Traceback (most recent call last):
  File "/softs/rh7/conda/4.5.4/envs/pangeo_full_201909/lib/python3.7/site-packages/distributed/comm/core.py", line 215, in connect
    quiet_exceptions=EnvironmentError,
tornado.util.TimeoutError: Timeout

During handling of the above exception, another exception occurred:

Traceback (most recent call last):
  File "/softs/rh7/conda/4.5.4/envs/pangeo_full_201909/lib/python3.7/site-packages/tornado/ioloop.py", line 743, in _run_callback
    ret = callback()
  File "/softs/rh7/conda/4.5.4/envs/pangeo_full_201909/lib/python3.7/site-packages/tornado/ioloop.py", line 767, in _discard_future_result
    future.result()
  File "/softs/rh7/conda/4.5.4/envs/pangeo_full_201909/lib/python3.7/site-packages/distributed/worker.py", line 875, in heartbeat
    metrics=await self.get_metrics(),
  File "/softs/rh7/conda/4.5.4/envs/pangeo_full_201909/lib/python3.7/site-packages/distributed/core.py", line 747, in send_recv_from_rpc
    comm = await self.pool.connect(self.addr)
  File "/softs/rh7/conda/4.5.4/envs/pangeo_full_201909/lib/python3.7/site-packages/distributed/core.py", line 874, in connect
    connection_args=self.connection_args,
  File "/softs/rh7/conda/4.5.4/envs/pangeo_full_201909/lib/python3.7/site-packages/distributed/comm/core.py", line 227, in connect
    _raise(error)
  File "/softs/rh7/conda/4.5.4/envs/pangeo_full_201909/lib/python3.7/site-packages/distributed/comm/core.py", line 204, in _raise
    raise IOError(msg)
OSError: Timed out trying to connect to 'tcp://10.120.40.97:33653' after 10 s: in <distributed.comm.tcp.TCPConnector object at 0x2b244dd90f28>: ConnectionRefusedError: [Errno 111] Connection refused
tornado.application - ERROR - Exception in callback functools.partial(<bound method IOLoop._discard_future_result of <tornado.platform.asyncio.AsyncIOLoop object at 0x2b2433c61c88>>, <Task finished coro=<Worker.heartbeat() done, defined at /softs/rh7/conda/4.5.4/envs/pangeo_full_201909/lib/python3.7/site-packages/distributed/worker.py:866> exception=OSError("Timed out trying to connect to 'tcp://10.120.40.97:33653' after 10 s: in <distributed.comm.tcp.TCPConnector object at 0x2b244e857198>: ConnectionRefusedError: [Errno 111] Connection refused")>)
Traceback (most recent call last):
  File "/softs/rh7/conda/4.5.4/envs/pangeo_full_201909/lib/python3.7/site-packages/distributed/comm/core.py", line 215, in connect
    quiet_exceptions=EnvironmentError,
tornado.util.TimeoutError: Timeout

During handling of the above exception, another exception occurred:

Traceback (most recent call last):
  File "/softs/rh7/conda/4.5.4/envs/pangeo_full_201909/lib/python3.7/site-packages/tornado/ioloop.py", line 743, in _run_callback
    ret = callback()
  File "/softs/rh7/conda/4.5.4/envs/pangeo_full_201909/lib/python3.7/site-packages/tornado/ioloop.py", line 767, in _discard_future_result
    future.result()
  File "/softs/rh7/conda/4.5.4/envs/pangeo_full_201909/lib/python3.7/site-packages/distributed/worker.py", line 875, in heartbeat
    metrics=await self.get_metrics(),
  File "/softs/rh7/conda/4.5.4/envs/pangeo_full_201909/lib/python3.7/site-packages/distributed/core.py", line 747, in send_recv_from_rpc
    comm = await self.pool.connect(self.addr)
  File "/softs/rh7/conda/4.5.4/envs/pangeo_full_201909/lib/python3.7/site-packages/distributed/core.py", line 874, in connect
    connection_args=self.connection_args,
  File "/softs/rh7/conda/4.5.4/envs/pangeo_full_201909/lib/python3.7/site-packages/distributed/comm/core.py", line 227, in connect
    _raise(error)
  File "/softs/rh7/conda/4.5.4/envs/pangeo_full_201909/lib/python3.7/site-packages/distributed/comm/core.py", line 204, in _raise
    raise IOError(msg)
OSError: Timed out trying to connect to 'tcp://10.120.40.97:33653' after 10 s: in <distributed.comm.tcp.TCPConnector object at 0x2b244e857198>: ConnectionRefusedError: [Errno 111] Connection refused
tornado.application - ERROR - Exception in callback functools.partial(<bound method IOLoop._discard_future_result of <tornado.platform.asyncio.AsyncIOLoop object at 0x2b2433c61c88>>, <Task finished coro=<Worker.heartbeat() done, defined at /softs/rh7/conda/4.5.4/envs/pangeo_full_201909/lib/python3.7/site-packages/distributed/worker.py:866> exception=OSError("Timed out trying to connect to 'tcp://10.120.40.97:33653' after 10 s: in <distributed.comm.tcp.TCPConnector object at 0x2b244e98e550>: ConnectionRefusedError: [Errno 111] Connection refused")>)
Traceback (most recent call last):
  File "/softs/rh7/conda/4.5.4/envs/pangeo_full_201909/lib/python3.7/site-packages/distributed/comm/core.py", line 215, in connect
    quiet_exceptions=EnvironmentError,
tornado.util.TimeoutError: Timeout

During handling of the above exception, another exception occurred:

Traceback (most recent call last):
  File "/softs/rh7/conda/4.5.4/envs/pangeo_full_201909/lib/python3.7/site-packages/tornado/ioloop.py", line 743, in _run_callback
    ret = callback()
  File "/softs/rh7/conda/4.5.4/envs/pangeo_full_201909/lib/python3.7/site-packages/tornado/ioloop.py", line 767, in _discard_future_result
    future.result()
  File "/softs/rh7/conda/4.5.4/envs/pangeo_full_201909/lib/python3.7/site-packages/distributed/worker.py", line 875, in heartbeat
    metrics=await self.get_metrics(),
  File "/softs/rh7/conda/4.5.4/envs/pangeo_full_201909/lib/python3.7/site-packages/distributed/core.py", line 747, in send_recv_from_rpc
    comm = await self.pool.connect(self.addr)
  File "/softs/rh7/conda/4.5.4/envs/pangeo_full_201909/lib/python3.7/site-packages/distributed/core.py", line 874, in connect
    connection_args=self.connection_args,
  File "/softs/rh7/conda/4.5.4/envs/pangeo_full_201909/lib/python3.7/site-packages/distributed/comm/core.py", line 227, in connect
    _raise(error)
  File "/softs/rh7/conda/4.5.4/envs/pangeo_full_201909/lib/python3.7/site-packages/distributed/comm/core.py", line 204, in _raise
    raise IOError(msg)
OSError: Timed out trying to connect to 'tcp://10.120.40.97:33653' after 10 s: in <distributed.comm.tcp.TCPConnector object at 0x2b244e98e550>: ConnectionRefusedError: [Errno 111] Connection refused
tornado.application - ERROR - Exception in callback <function Worker._register_with_scheduler.<locals>.<lambda> at 0x2b2437efe2f0>
Traceback (most recent call last):
  File "/softs/rh7/conda/4.5.4/envs/pangeo_full_201909/lib/python3.7/site-packages/tornado/ioloop.py", line 907, in _run
    return self.callback()
  File "/softs/rh7/conda/4.5.4/envs/pangeo_full_201909/lib/python3.7/site-packages/distributed/worker.py", line 857, in <lambda>
    lambda: self.batched_stream.send({"op": "keep-alive"}),
  File "/softs/rh7/conda/4.5.4/envs/pangeo_full_201909/lib/python3.7/site-packages/distributed/batched.py", line 117, in send
    raise CommClosedError
distributed.comm.core.CommClosedError
tornado.application - ERROR - Exception in callback functools.partial(<bound method IOLoop._discard_future_result of <tornado.platform.asyncio.AsyncIOLoop object at 0x2b2433c61c88>>, <Task finished coro=<Worker.heartbeat() done, defined at /softs/rh7/conda/4.5.4/envs/pangeo_full_201909/lib/python3.7/site-packages/distributed/worker.py:866> exception=OSError("Timed out trying to connect to 'tcp://10.120.40.97:33653' after 10 s: in <distributed.comm.tcp.TCPConnector object at 0x2b244e98e518>: ConnectionRefusedError: [Errno 111] Connection refused")>)
Traceback (most recent call last):
  File "/softs/rh7/conda/4.5.4/envs/pangeo_full_201909/lib/python3.7/site-packages/distributed/comm/core.py", line 215, in connect
    quiet_exceptions=EnvironmentError,
tornado.util.TimeoutError: Timeout

During handling of the above exception, another exception occurred:

Traceback (most recent call last):
  File "/softs/rh7/conda/4.5.4/envs/pangeo_full_201909/lib/python3.7/site-packages/tornado/ioloop.py", line 743, in _run_callback
    ret = callback()
  File "/softs/rh7/conda/4.5.4/envs/pangeo_full_201909/lib/python3.7/site-packages/tornado/ioloop.py", line 767, in _discard_future_result
    future.result()
  File "/softs/rh7/conda/4.5.4/envs/pangeo_full_201909/lib/python3.7/site-packages/distributed/worker.py", line 875, in heartbeat
    metrics=await self.get_metrics(),
  File "/softs/rh7/conda/4.5.4/envs/pangeo_full_201909/lib/python3.7/site-packages/distributed/core.py", line 747, in send_recv_from_rpc
    comm = await self.pool.connect(self.addr)
  File "/softs/rh7/conda/4.5.4/envs/pangeo_full_201909/lib/python3.7/site-packages/distributed/core.py", line 874, in connect
    connection_args=self.connection_args,
  File "/softs/rh7/conda/4.5.4/envs/pangeo_full_201909/lib/python3.7/site-packages/distributed/comm/core.py", line 227, in connect
    _raise(error)
  File "/softs/rh7/conda/4.5.4/envs/pangeo_full_201909/lib/python3.7/site-packages/distributed/comm/core.py", line 204, in _raise
    raise IOError(msg)
OSError: Timed out trying to connect to 'tcp://10.120.40.97:33653' after 10 s: in <distributed.comm.tcp.TCPConnector object at 0x2b244e98e518>: ConnectionRefusedError: [Errno 111] Connection refused
tornado.application - ERROR - Exception in callback functools.partial(<bound method IOLoop._discard_future_result of <tornado.platform.asyncio.AsyncIOLoop object at 0x2b2433c61c88>>, <Task finished coro=<Worker.heartbeat() done, defined at /softs/rh7/conda/4.5.4/envs/pangeo_full_201909/lib/python3.7/site-packages/distributed/worker.py:866> exception=OSError("Timed out trying to connect to 'tcp://10.120.40.97:33653' after 10 s: in <distributed.comm.tcp.TCPConnector object at 0x2b244e0d82b0>: ConnectionRefusedError: [Errno 111] Connection refused")>)
Traceback (most recent call last):
  File "/softs/rh7/conda/4.5.4/envs/pangeo_full_201909/lib/python3.7/site-packages/distributed/comm/core.py", line 215, in connect
    quiet_exceptions=EnvironmentError,
tornado.util.TimeoutError: Timeout

During handling of the above exception, another exception occurred:

Traceback (most recent call last):
  File "/softs/rh7/conda/4.5.4/envs/pangeo_full_201909/lib/python3.7/site-packages/tornado/ioloop.py", line 743, in _run_callback
    ret = callback()
  File "/softs/rh7/conda/4.5.4/envs/pangeo_full_201909/lib/python3.7/site-packages/tornado/ioloop.py", line 767, in _discard_future_result
    future.result()
  File "/softs/rh7/conda/4.5.4/envs/pangeo_full_201909/lib/python3.7/site-packages/distributed/worker.py", line 875, in heartbeat
    metrics=await self.get_metrics(),
  File "/softs/rh7/conda/4.5.4/envs/pangeo_full_201909/lib/python3.7/site-packages/distributed/core.py", line 747, in send_recv_from_rpc
    comm = await self.pool.connect(self.addr)
  File "/softs/rh7/conda/4.5.4/envs/pangeo_full_201909/lib/python3.7/site-packages/distributed/core.py", line 874, in connect
    connection_args=self.connection_args,
  File "/softs/rh7/conda/4.5.4/envs/pangeo_full_201909/lib/python3.7/site-packages/distributed/comm/core.py", line 227, in connect
    _raise(error)
  File "/softs/rh7/conda/4.5.4/envs/pangeo_full_201909/lib/python3.7/site-packages/distributed/comm/core.py", line 204, in _raise
    raise IOError(msg)
OSError: Timed out trying to connect to 'tcp://10.120.40.97:33653' after 10 s: in <distributed.comm.tcp.TCPConnector object at 0x2b244e0d82b0>: ConnectionRefusedError: [Errno 111] Connection refused
tornado.application - ERROR - Exception in callback functools.partial(<bound method IOLoop._discard_future_result of <tornado.platform.asyncio.AsyncIOLoop object at 0x2b2433c61c88>>, <Task finished coro=<Worker.heartbeat() done, defined at /softs/rh7/conda/4.5.4/envs/pangeo_full_201909/lib/python3.7/site-packages/distributed/worker.py:866> exception=OSError("Timed out trying to connect to 'tcp://10.120.40.97:33653' after 10 s: in <distributed.comm.tcp.TCPConnector object at 0x2b244e659828>: ConnectionRefusedError: [Errno 111] Connection refused")>)
Traceback (most recent call last):
  File "/softs/rh7/conda/4.5.4/envs/pangeo_full_201909/lib/python3.7/site-packages/distributed/comm/core.py", line 215, in connect
    quiet_exceptions=EnvironmentError,
tornado.util.TimeoutError: Timeout

During handling of the above exception, another exception occurred:

Traceback (most recent call last):
  File "/softs/rh7/conda/4.5.4/envs/pangeo_full_201909/lib/python3.7/site-packages/tornado/ioloop.py", line 743, in _run_callback
    ret = callback()
  File "/softs/rh7/conda/4.5.4/envs/pangeo_full_201909/lib/python3.7/site-packages/tornado/ioloop.py", line 767, in _discard_future_result
    future.result()
  File "/softs/rh7/conda/4.5.4/envs/pangeo_full_201909/lib/python3.7/site-packages/distributed/worker.py", line 875, in heartbeat
    metrics=await self.get_metrics(),
  File "/softs/rh7/conda/4.5.4/envs/pangeo_full_201909/lib/python3.7/site-packages/distributed/core.py", line 747, in send_recv_from_rpc
    comm = await self.pool.connect(self.addr)
  File "/softs/rh7/conda/4.5.4/envs/pangeo_full_201909/lib/python3.7/site-packages/distributed/core.py", line 874, in connect
    connection_args=self.connection_args,
  File "/softs/rh7/conda/4.5.4/envs/pangeo_full_201909/lib/python3.7/site-packages/distributed/comm/core.py", line 227, in connect
    _raise(error)
  File "/softs/rh7/conda/4.5.4/envs/pangeo_full_201909/lib/python3.7/site-packages/distributed/comm/core.py", line 204, in _raise
    raise IOError(msg)
OSError: Timed out trying to connect to 'tcp://10.120.40.97:33653' after 10 s: in <distributed.comm.tcp.TCPConnector object at 0x2b244e659828>: ConnectionRefusedError: [Errno 111] Connection refused
tornado.application - ERROR - Exception in callback functools.partial(<bound method IOLoop._discard_future_result of <tornado.platform.asyncio.AsyncIOLoop object at 0x2b2433c61c88>>, <Task finished coro=<Worker.heartbeat() done, defined at /softs/rh7/conda/4.5.4/envs/pangeo_full_201909/lib/python3.7/site-packages/distributed/worker.py:866> exception=OSError("Timed out trying to connect to 'tcp://10.120.40.97:33653' after 10 s: in <distributed.comm.tcp.TCPConnector object at 0x2b244e242400>: ConnectionRefusedError: [Errno 111] Connection refused")>)
Traceback (most recent call last):
  File "/softs/rh7/conda/4.5.4/envs/pangeo_full_201909/lib/python3.7/site-packages/distributed/comm/core.py", line 215, in connect
    quiet_exceptions=EnvironmentError,
tornado.util.TimeoutError: Timeout

During handling of the above exception, another exception occurred:

Traceback (most recent call last):
  File "/softs/rh7/conda/4.5.4/envs/pangeo_full_201909/lib/python3.7/site-packages/tornado/ioloop.py", line 743, in _run_callback
    ret = callback()
  File "/softs/rh7/conda/4.5.4/envs/pangeo_full_201909/lib/python3.7/site-packages/tornado/ioloop.py", line 767, in _discard_future_result
    future.result()
  File "/softs/rh7/conda/4.5.4/envs/pangeo_full_201909/lib/python3.7/site-packages/distributed/worker.py", line 875, in heartbeat
    metrics=await self.get_metrics(),
  File "/softs/rh7/conda/4.5.4/envs/pangeo_full_201909/lib/python3.7/site-packages/distributed/core.py", line 747, in send_recv_from_rpc
    comm = await self.pool.connect(self.addr)
  File "/softs/rh7/conda/4.5.4/envs/pangeo_full_201909/lib/python3.7/site-packages/distributed/core.py", line 874, in connect
    connection_args=self.connection_args,
  File "/softs/rh7/conda/4.5.4/envs/pangeo_full_201909/lib/python3.7/site-packages/distributed/comm/core.py", line 227, in connect
    _raise(error)
  File "/softs/rh7/conda/4.5.4/envs/pangeo_full_201909/lib/python3.7/site-packages/distributed/comm/core.py", line 204, in _raise
    raise IOError(msg)
OSError: Timed out trying to connect to 'tcp://10.120.40.97:33653' after 10 s: in <distributed.comm.tcp.TCPConnector object at 0x2b244e242400>: ConnectionRefusedError: [Errno 111] Connection refused
tornado.application - ERROR - Exception in callback functools.partial(<bound method IOLoop._discard_future_result of <tornado.platform.asyncio.AsyncIOLoop object at 0x2b2433c61c88>>, <Task finished coro=<Worker.heartbeat() done, defined at /softs/rh7/conda/4.5.4/envs/pangeo_full_201909/lib/python3.7/site-packages/distributed/worker.py:866> exception=OSError("Timed out trying to connect to 'tcp://10.120.40.97:33653' after 10 s: in <distributed.comm.tcp.TCPConnector object at 0x2b244e950e10>: ConnectionRefusedError: [Errno 111] Connection refused")>)
Traceback (most recent call last):
  File "/softs/rh7/conda/4.5.4/envs/pangeo_full_201909/lib/python3.7/site-packages/distributed/comm/core.py", line 215, in connect
    quiet_exceptions=EnvironmentError,
tornado.util.TimeoutError: Timeout

During handling of the above exception, another exception occurred:

Traceback (most recent call last):
  File "/softs/rh7/conda/4.5.4/envs/pangeo_full_201909/lib/python3.7/site-packages/tornado/ioloop.py", line 743, in _run_callback
    ret = callback()
  File "/softs/rh7/conda/4.5.4/envs/pangeo_full_201909/lib/python3.7/site-packages/tornado/ioloop.py", line 767, in _discard_future_result
    future.result()
  File "/softs/rh7/conda/4.5.4/envs/pangeo_full_201909/lib/python3.7/site-packages/distributed/worker.py", line 875, in heartbeat
    metrics=await self.get_metrics(),
  File "/softs/rh7/conda/4.5.4/envs/pangeo_full_201909/lib/python3.7/site-packages/distributed/core.py", line 747, in send_recv_from_rpc
    comm = await self.pool.connect(self.addr)
  File "/softs/rh7/conda/4.5.4/envs/pangeo_full_201909/lib/python3.7/site-packages/distributed/core.py", line 874, in connect
    connection_args=self.connection_args,
  File "/softs/rh7/conda/4.5.4/envs/pangeo_full_201909/lib/python3.7/site-packages/distributed/comm/core.py", line 227, in connect
    _raise(error)
  File "/softs/rh7/conda/4.5.4/envs/pangeo_full_201909/lib/python3.7/site-packages/distributed/comm/core.py", line 204, in _raise
    raise IOError(msg)
OSError: Timed out trying to connect to 'tcp://10.120.40.97:33653' after 10 s: in <distributed.comm.tcp.TCPConnector object at 0x2b244e950e10>: ConnectionRefusedError: [Errno 111] Connection refused
tornado.application - ERROR - Exception in callback <function Worker._register_with_scheduler.<locals>.<lambda> at 0x2b2437efe2f0>
Traceback (most recent call last):
  File "/softs/rh7/conda/4.5.4/envs/pangeo_full_201909/lib/python3.7/site-packages/tornado/ioloop.py", line 907, in _run
    return self.callback()
  File "/softs/rh7/conda/4.5.4/envs/pangeo_full_201909/lib/python3.7/site-packages/distributed/worker.py", line 857, in <lambda>
    lambda: self.batched_stream.send({"op": "keep-alive"}),
  File "/softs/rh7/conda/4.5.4/envs/pangeo_full_201909/lib/python3.7/site-packages/distributed/batched.py", line 117, in send
    raise CommClosedError
distributed.comm.core.CommClosedError
tornado.application - ERROR - Exception in callback functools.partial(<bound method IOLoop._discard_future_result of <tornado.platform.asyncio.AsyncIOLoop object at 0x2b2433c61c88>>, <Task finished coro=<Worker.heartbeat() done, defined at /softs/rh7/conda/4.5.4/envs/pangeo_full_201909/lib/python3.7/site-packages/distributed/worker.py:866> exception=OSError("Timed out trying to connect to 'tcp://10.120.40.97:33653' after 10 s: in <distributed.comm.tcp.TCPConnector object at 0x2b244e8aff98>: ConnectionRefusedError: [Errno 111] Connection refused")>)
Traceback (most recent call last):
  File "/softs/rh7/conda/4.5.4/envs/pangeo_full_201909/lib/python3.7/site-packages/distributed/comm/core.py", line 215, in connect
    quiet_exceptions=EnvironmentError,
tornado.util.TimeoutError: Timeout

During handling of the above exception, another exception occurred:

Traceback (most recent call last):
  File "/softs/rh7/conda/4.5.4/envs/pangeo_full_201909/lib/python3.7/site-packages/tornado/ioloop.py", line 743, in _run_callback
    ret = callback()
  File "/softs/rh7/conda/4.5.4/envs/pangeo_full_201909/lib/python3.7/site-packages/tornado/ioloop.py", line 767, in _discard_future_result
    future.result()
  File "/softs/rh7/conda/4.5.4/envs/pangeo_full_201909/lib/python3.7/site-packages/distributed/worker.py", line 875, in heartbeat
    metrics=await self.get_metrics(),
  File "/softs/rh7/conda/4.5.4/envs/pangeo_full_201909/lib/python3.7/site-packages/distributed/core.py", line 747, in send_recv_from_rpc
    comm = await self.pool.connect(self.addr)
  File "/softs/rh7/conda/4.5.4/envs/pangeo_full_201909/lib/python3.7/site-packages/distributed/core.py", line 874, in connect
    connection_args=self.connection_args,
  File "/softs/rh7/conda/4.5.4/envs/pangeo_full_201909/lib/python3.7/site-packages/distributed/comm/core.py", line 227, in connect
    _raise(error)
  File "/softs/rh7/conda/4.5.4/envs/pangeo_full_201909/lib/python3.7/site-packages/distributed/comm/core.py", line 204, in _raise
    raise IOError(msg)
OSError: Timed out trying to connect to 'tcp://10.120.40.97:33653' after 10 s: in <distributed.comm.tcp.TCPConnector object at 0x2b244e8aff98>: ConnectionRefusedError: [Errno 111] Connection refused
tornado.application - ERROR - Exception in callback functools.partial(<bound method IOLoop._discard_future_result of <tornado.platform.asyncio.AsyncIOLoop object at 0x2b2433c61c88>>, <Task finished coro=<Worker.heartbeat() done, defined at /softs/rh7/conda/4.5.4/envs/pangeo_full_201909/lib/python3.7/site-packages/distributed/worker.py:866> exception=OSError("Timed out trying to connect to 'tcp://10.120.40.97:33653' after 10 s: in <distributed.comm.tcp.TCPConnector object at 0x2b244dd53668>: ConnectionRefusedError: [Errno 111] Connection refused")>)
Traceback (most recent call last):
  File "/softs/rh7/conda/4.5.4/envs/pangeo_full_201909/lib/python3.7/site-packages/distributed/comm/core.py", line 215, in connect
    quiet_exceptions=EnvironmentError,
tornado.util.TimeoutError: Timeout

During handling of the above exception, another exception occurred:

Traceback (most recent call last):
  File "/softs/rh7/conda/4.5.4/envs/pangeo_full_201909/lib/python3.7/site-packages/tornado/ioloop.py", line 743, in _run_callback
    ret = callback()
  File "/softs/rh7/conda/4.5.4/envs/pangeo_full_201909/lib/python3.7/site-packages/tornado/ioloop.py", line 767, in _discard_future_result
    future.result()
  File "/softs/rh7/conda/4.5.4/envs/pangeo_full_201909/lib/python3.7/site-packages/distributed/worker.py", line 875, in heartbeat
    metrics=await self.get_metrics(),
  File "/softs/rh7/conda/4.5.4/envs/pangeo_full_201909/lib/python3.7/site-packages/distributed/core.py", line 747, in send_recv_from_rpc
    comm = await self.pool.connect(self.addr)
  File "/softs/rh7/conda/4.5.4/envs/pangeo_full_201909/lib/python3.7/site-packages/distributed/core.py", line 874, in connect
    connection_args=self.connection_args,
  File "/softs/rh7/conda/4.5.4/envs/pangeo_full_201909/lib/python3.7/site-packages/distributed/comm/core.py", line 227, in connect
    _raise(error)
  File "/softs/rh7/conda/4.5.4/envs/pangeo_full_201909/lib/python3.7/site-packages/distributed/comm/core.py", line 204, in _raise
    raise IOError(msg)
OSError: Timed out trying to connect to 'tcp://10.120.40.97:33653' after 10 s: in <distributed.comm.tcp.TCPConnector object at 0x2b244dd53668>: ConnectionRefusedError: [Errno 111] Connection refused
tornado.application - ERROR - Exception in callback functools.partial(<bound method IOLoop._discard_future_result of <tornado.platform.asyncio.AsyncIOLoop object at 0x2b2433c61c88>>, <Task finished coro=<Worker.heartbeat() done, defined at /softs/rh7/conda/4.5.4/envs/pangeo_full_201909/lib/python3.7/site-packages/distributed/worker.py:866> exception=OSError("Timed out trying to connect to 'tcp://10.120.40.97:33653' after 10 s: in <distributed.comm.tcp.TCPConnector object at 0x2b244e659ac8>: ConnectionRefusedError: [Errno 111] Connection refused")>)
Traceback (most recent call last):
  File "/softs/rh7/conda/4.5.4/envs/pangeo_full_201909/lib/python3.7/site-packages/distributed/comm/core.py", line 215, in connect
    quiet_exceptions=EnvironmentError,
tornado.util.TimeoutError: Timeout

During handling of the above exception, another exception occurred:

Traceback (most recent call last):
  File "/softs/rh7/conda/4.5.4/envs/pangeo_full_201909/lib/python3.7/site-packages/tornado/ioloop.py", line 743, in _run_callback
    ret = callback()
  File "/softs/rh7/conda/4.5.4/envs/pangeo_full_201909/lib/python3.7/site-packages/tornado/ioloop.py", line 767, in _discard_future_result
    future.result()
  File "/softs/rh7/conda/4.5.4/envs/pangeo_full_201909/lib/python3.7/site-packages/distributed/worker.py", line 875, in heartbeat
    metrics=await self.get_metrics(),
  File "/softs/rh7/conda/4.5.4/envs/pangeo_full_201909/lib/python3.7/site-packages/distributed/core.py", line 747, in send_recv_from_rpc
    comm = await self.pool.connect(self.addr)
  File "/softs/rh7/conda/4.5.4/envs/pangeo_full_201909/lib/python3.7/site-packages/distributed/core.py", line 874, in connect
    connection_args=self.connection_args,
  File "/softs/rh7/conda/4.5.4/envs/pangeo_full_201909/lib/python3.7/site-packages/distributed/comm/core.py", line 227, in connect
    _raise(error)
  File "/softs/rh7/conda/4.5.4/envs/pangeo_full_201909/lib/python3.7/site-packages/distributed/comm/core.py", line 204, in _raise
    raise IOError(msg)
OSError: Timed out trying to connect to 'tcp://10.120.40.97:33653' after 10 s: in <distributed.comm.tcp.TCPConnector object at 0x2b244e659ac8>: ConnectionRefusedError: [Errno 111] Connection refused
tornado.application - ERROR - Exception in callback functools.partial(<bound method IOLoop._discard_future_result of <tornado.platform.asyncio.AsyncIOLoop object at 0x2b2433c61c88>>, <Task finished coro=<Worker.heartbeat() done, defined at /softs/rh7/conda/4.5.4/envs/pangeo_full_201909/lib/python3.7/site-packages/distributed/worker.py:866> exception=OSError("Timed out trying to connect to 'tcp://10.120.40.97:33653' after 10 s: in <distributed.comm.tcp.TCPConnector object at 0x2b244d6c95f8>: ConnectionRefusedError: [Errno 111] Connection refused")>)
Traceback (most recent call last):
  File "/softs/rh7/conda/4.5.4/envs/pangeo_full_201909/lib/python3.7/site-packages/distributed/comm/core.py", line 215, in connect
    quiet_exceptions=EnvironmentError,
tornado.util.TimeoutError: Timeout

During handling of the above exception, another exception occurred:

Traceback (most recent call last):
  File "/softs/rh7/conda/4.5.4/envs/pangeo_full_201909/lib/python3.7/site-packages/tornado/ioloop.py", line 743, in _run_callback
    ret = callback()
  File "/softs/rh7/conda/4.5.4/envs/pangeo_full_201909/lib/python3.7/site-packages/tornado/ioloop.py", line 767, in _discard_future_result
    future.result()
  File "/softs/rh7/conda/4.5.4/envs/pangeo_full_201909/lib/python3.7/site-packages/distributed/worker.py", line 875, in heartbeat
    metrics=await self.get_metrics(),
  File "/softs/rh7/conda/4.5.4/envs/pangeo_full_201909/lib/python3.7/site-packages/distributed/core.py", line 747, in send_recv_from_rpc
    comm = await self.pool.connect(self.addr)
  File "/softs/rh7/conda/4.5.4/envs/pangeo_full_201909/lib/python3.7/site-packages/distributed/core.py", line 874, in connect
    connection_args=self.connection_args,
  File "/softs/rh7/conda/4.5.4/envs/pangeo_full_201909/lib/python3.7/site-packages/distributed/comm/core.py", line 227, in connect
    _raise(error)
  File "/softs/rh7/conda/4.5.4/envs/pangeo_full_201909/lib/python3.7/site-packages/distributed/comm/core.py", line 204, in _raise
    raise IOError(msg)
OSError: Timed out trying to connect to 'tcp://10.120.40.97:33653' after 10 s: in <distributed.comm.tcp.TCPConnector object at 0x2b244d6c95f8>: ConnectionRefusedError: [Errno 111] Connection refused
tornado.application - ERROR - Exception in callback functools.partial(<bound method IOLoop._discard_future_result of <tornado.platform.asyncio.AsyncIOLoop object at 0x2b2433c61c88>>, <Task finished coro=<Worker.heartbeat() done, defined at /softs/rh7/conda/4.5.4/envs/pangeo_full_201909/lib/python3.7/site-packages/distributed/worker.py:866> exception=OSError("Timed out trying to connect to 'tcp://10.120.40.97:33653' after 10 s: in <distributed.comm.tcp.TCPConnector object at 0x2b244e950898>: ConnectionRefusedError: [Errno 111] Connection refused")>)
Traceback (most recent call last):
  File "/softs/rh7/conda/4.5.4/envs/pangeo_full_201909/lib/python3.7/site-packages/distributed/comm/core.py", line 215, in connect
    quiet_exceptions=EnvironmentError,
tornado.util.TimeoutError: Timeout

During handling of the above exception, another exception occurred:

Traceback (most recent call last):
  File "/softs/rh7/conda/4.5.4/envs/pangeo_full_201909/lib/python3.7/site-packages/tornado/ioloop.py", line 743, in _run_callback
    ret = callback()
  File "/softs/rh7/conda/4.5.4/envs/pangeo_full_201909/lib/python3.7/site-packages/tornado/ioloop.py", line 767, in _discard_future_result
    future.result()
  File "/softs/rh7/conda/4.5.4/envs/pangeo_full_201909/lib/python3.7/site-packages/distributed/worker.py", line 875, in heartbeat
    metrics=await self.get_metrics(),
  File "/softs/rh7/conda/4.5.4/envs/pangeo_full_201909/lib/python3.7/site-packages/distributed/core.py", line 747, in send_recv_from_rpc
    comm = await self.pool.connect(self.addr)
  File "/softs/rh7/conda/4.5.4/envs/pangeo_full_201909/lib/python3.7/site-packages/distributed/core.py", line 874, in connect
    connection_args=self.connection_args,
  File "/softs/rh7/conda/4.5.4/envs/pangeo_full_201909/lib/python3.7/site-packages/distributed/comm/core.py", line 227, in connect
    _raise(error)
  File "/softs/rh7/conda/4.5.4/envs/pangeo_full_201909/lib/python3.7/site-packages/distributed/comm/core.py", line 204, in _raise
    raise IOError(msg)
OSError: Timed out trying to connect to 'tcp://10.120.40.97:33653' after 10 s: in <distributed.comm.tcp.TCPConnector object at 0x2b244e950898>: ConnectionRefusedError: [Errno 111] Connection refused
tornado.application - ERROR - Exception in callback functools.partial(<bound method IOLoop._discard_future_result of <tornado.platform.asyncio.AsyncIOLoop object at 0x2b2433c61c88>>, <Task finished coro=<Worker.heartbeat() done, defined at /softs/rh7/conda/4.5.4/envs/pangeo_full_201909/lib/python3.7/site-packages/distributed/worker.py:866> exception=OSError("Timed out trying to connect to 'tcp://10.120.40.97:33653' after 10 s: in <distributed.comm.tcp.TCPConnector object at 0x2b244e242fd0>: ConnectionRefusedError: [Errno 111] Connection refused")>)
Traceback (most recent call last):
  File "/softs/rh7/conda/4.5.4/envs/pangeo_full_201909/lib/python3.7/site-packages/distributed/comm/core.py", line 215, in connect
    quiet_exceptions=EnvironmentError,
tornado.util.TimeoutError: Timeout

During handling of the above exception, another exception occurred:

Traceback (most recent call last):
  File "/softs/rh7/conda/4.5.4/envs/pangeo_full_201909/lib/python3.7/site-packages/tornado/ioloop.py", line 743, in _run_callback
    ret = callback()
  File "/softs/rh7/conda/4.5.4/envs/pangeo_full_201909/lib/python3.7/site-packages/tornado/ioloop.py", line 767, in _discard_future_result
    future.result()
  File "/softs/rh7/conda/4.5.4/envs/pangeo_full_201909/lib/python3.7/site-packages/distributed/worker.py", line 875, in heartbeat
    metrics=await self.get_metrics(),
  File "/softs/rh7/conda/4.5.4/envs/pangeo_full_201909/lib/python3.7/site-packages/distributed/core.py", line 747, in send_recv_from_rpc
    comm = await self.pool.connect(self.addr)
  File "/softs/rh7/conda/4.5.4/envs/pangeo_full_201909/lib/python3.7/site-packages/distributed/core.py", line 874, in connect
    connection_args=self.connection_args,
  File "/softs/rh7/conda/4.5.4/envs/pangeo_full_201909/lib/python3.7/site-packages/distributed/comm/core.py", line 227, in connect
    _raise(error)
  File "/softs/rh7/conda/4.5.4/envs/pangeo_full_201909/lib/python3.7/site-packages/distributed/comm/core.py", line 204, in _raise
    raise IOError(msg)
OSError: Timed out trying to connect to 'tcp://10.120.40.97:33653' after 10 s: in <distributed.comm.tcp.TCPConnector object at 0x2b244e242fd0>: ConnectionRefusedError: [Errno 111] Connection refused
tornado.application - ERROR - Exception in callback <function Worker._register_with_scheduler.<locals>.<lambda> at 0x2b2437efe2f0>
Traceback (most recent call last):
  File "/softs/rh7/conda/4.5.4/envs/pangeo_full_201909/lib/python3.7/site-packages/tornado/ioloop.py", line 907, in _run
    return self.callback()
  File "/softs/rh7/conda/4.5.4/envs/pangeo_full_201909/lib/python3.7/site-packages/distributed/worker.py", line 857, in <lambda>
    lambda: self.batched_stream.send({"op": "keep-alive"}),
  File "/softs/rh7/conda/4.5.4/envs/pangeo_full_201909/lib/python3.7/site-packages/distributed/batched.py", line 117, in send
    raise CommClosedError
distributed.comm.core.CommClosedError
tornado.application - ERROR - Exception in callback functools.partial(<bound method IOLoop._discard_future_result of <tornado.platform.asyncio.AsyncIOLoop object at 0x2b2433c61c88>>, <Task finished coro=<Worker.heartbeat() done, defined at /softs/rh7/conda/4.5.4/envs/pangeo_full_201909/lib/python3.7/site-packages/distributed/worker.py:866> exception=OSError("Timed out trying to connect to 'tcp://10.120.40.97:33653' after 10 s: in <distributed.comm.tcp.TCPConnector object at 0x2b244e242278>: ConnectionRefusedError: [Errno 111] Connection refused")>)
Traceback (most recent call last):
  File "/softs/rh7/conda/4.5.4/envs/pangeo_full_201909/lib/python3.7/site-packages/distributed/comm/tcp.py", line 356, in connect
    ip, port, max_buffer_size=MAX_BUFFER_SIZE, **kwargs
  File "/softs/rh7/conda/4.5.4/envs/pangeo_full_201909/lib/python3.7/site-packages/tornado/tcpclient.py", line 280, in connect
    af, addr, stream = await connector.start(connect_timeout=timeout)
  File "/softs/rh7/conda/4.5.4/envs/pangeo_full_201909/lib/python3.7/site-packages/tornado/tcpclient.py", line 143, in on_connect_done
    stream = future.result()
tornado.iostream.StreamClosedError: Stream is closed

During handling of the above exception, another exception occurred:

Traceback (most recent call last):
  File "/softs/rh7/conda/4.5.4/envs/pangeo_full_201909/lib/python3.7/site-packages/distributed/comm/core.py", line 215, in connect
    quiet_exceptions=EnvironmentError,
  File "/softs/rh7/conda/4.5.4/envs/pangeo_full_201909/lib/python3.7/site-packages/distributed/comm/tcp.py", line 368, in connect
    convert_stream_closed_error(self, e)
  File "/softs/rh7/conda/4.5.4/envs/pangeo_full_201909/lib/python3.7/site-packages/distributed/comm/tcp.py", line 138, in convert_stream_closed_error
    raise CommClosedError("in %s: %s: %s" % (obj, exc.__class__.__name__, exc))
distributed.comm.core.CommClosedError: in <distributed.comm.tcp.TCPConnector object at 0x2b244e242278>: ConnectionRefusedError: [Errno 111] Connection refused

During handling of the above exception, another exception occurred:

Traceback (most recent call last):
  File "/softs/rh7/conda/4.5.4/envs/pangeo_full_201909/lib/python3.7/site-packages/tornado/ioloop.py", line 743, in _run_callback
    ret = callback()
  File "/softs/rh7/conda/4.5.4/envs/pangeo_full_201909/lib/python3.7/site-packages/tornado/ioloop.py", line 767, in _discard_future_result
    future.result()
  File "/softs/rh7/conda/4.5.4/envs/pangeo_full_201909/lib/python3.7/site-packages/distributed/worker.py", line 875, in heartbeat
    metrics=await self.get_metrics(),
  File "/softs/rh7/conda/4.5.4/envs/pangeo_full_201909/lib/python3.7/site-packages/distributed/core.py", line 747, in send_recv_from_rpc
    comm = await self.pool.connect(self.addr)
  File "/softs/rh7/conda/4.5.4/envs/pangeo_full_201909/lib/python3.7/site-packages/distributed/core.py", line 874, in connect
    connection_args=self.connection_args,
  File "/softs/rh7/conda/4.5.4/envs/pangeo_full_201909/lib/python3.7/site-packages/distributed/comm/core.py", line 225, in connect
    _raise(error)
  File "/softs/rh7/conda/4.5.4/envs/pangeo_full_201909/lib/python3.7/site-packages/distributed/comm/core.py", line 204, in _raise
    raise IOError(msg)
OSError: Timed out trying to connect to 'tcp://10.120.40.97:33653' after 10 s: in <distributed.comm.tcp.TCPConnector object at 0x2b244e242278>: ConnectionRefusedError: [Errno 111] Connection refused
tornado.application - ERROR - Exception in callback functools.partial(<bound method IOLoop._discard_future_result of <tornado.platform.asyncio.AsyncIOLoop object at 0x2b2433c61c88>>, <Task finished coro=<Worker.heartbeat() done, defined at /softs/rh7/conda/4.5.4/envs/pangeo_full_201909/lib/python3.7/site-packages/distributed/worker.py:866> exception=OSError("Timed out trying to connect to 'tcp://10.120.40.97:33653' after 10 s: in <distributed.comm.tcp.TCPConnector object at 0x2b244e242128>: ConnectionRefusedError: [Errno 111] Connection refused")>)
Traceback (most recent call last):
  File "/softs/rh7/conda/4.5.4/envs/pangeo_full_201909/lib/python3.7/site-packages/distributed/comm/core.py", line 215, in connect
    quiet_exceptions=EnvironmentError,
tornado.util.TimeoutError: Timeout

During handling of the above exception, another exception occurred:

Traceback (most recent call last):
  File "/softs/rh7/conda/4.5.4/envs/pangeo_full_201909/lib/python3.7/site-packages/tornado/ioloop.py", line 743, in _run_callback
    ret = callback()
  File "/softs/rh7/conda/4.5.4/envs/pangeo_full_201909/lib/python3.7/site-packages/tornado/ioloop.py", line 767, in _discard_future_result
    future.result()
  File "/softs/rh7/conda/4.5.4/envs/pangeo_full_201909/lib/python3.7/site-packages/distributed/worker.py", line 875, in heartbeat
    metrics=await self.get_metrics(),
  File "/softs/rh7/conda/4.5.4/envs/pangeo_full_201909/lib/python3.7/site-packages/distributed/core.py", line 747, in send_recv_from_rpc
    comm = await self.pool.connect(self.addr)
  File "/softs/rh7/conda/4.5.4/envs/pangeo_full_201909/lib/python3.7/site-packages/distributed/core.py", line 874, in connect
    connection_args=self.connection_args,
  File "/softs/rh7/conda/4.5.4/envs/pangeo_full_201909/lib/python3.7/site-packages/distributed/comm/core.py", line 227, in connect
    _raise(error)
  File "/softs/rh7/conda/4.5.4/envs/pangeo_full_201909/lib/python3.7/site-packages/distributed/comm/core.py", line 204, in _raise
    raise IOError(msg)
OSError: Timed out trying to connect to 'tcp://10.120.40.97:33653' after 10 s: in <distributed.comm.tcp.TCPConnector object at 0x2b244e242128>: ConnectionRefusedError: [Errno 111] Connection refused
tornado.application - ERROR - Exception in callback functools.partial(<bound method IOLoop._discard_future_result of <tornado.platform.asyncio.AsyncIOLoop object at 0x2b2433c61c88>>, <Task finished coro=<Worker.heartbeat() done, defined at /softs/rh7/conda/4.5.4/envs/pangeo_full_201909/lib/python3.7/site-packages/distributed/worker.py:866> exception=OSError("Timed out trying to connect to 'tcp://10.120.40.97:33653' after 10 s: in <distributed.comm.tcp.TCPConnector object at 0x2b244dd53390>: ConnectionRefusedError: [Errno 111] Connection refused")>)
Traceback (most recent call last):
  File "/softs/rh7/conda/4.5.4/envs/pangeo_full_201909/lib/python3.7/site-packages/distributed/comm/core.py", line 215, in connect
    quiet_exceptions=EnvironmentError,
tornado.util.TimeoutError: Timeout

During handling of the above exception, another exception occurred:

Traceback (most recent call last):
  File "/softs/rh7/conda/4.5.4/envs/pangeo_full_201909/lib/python3.7/site-packages/tornado/ioloop.py", line 743, in _run_callback
    ret = callback()
  File "/softs/rh7/conda/4.5.4/envs/pangeo_full_201909/lib/python3.7/site-packages/tornado/ioloop.py", line 767, in _discard_future_result
    future.result()
  File "/softs/rh7/conda/4.5.4/envs/pangeo_full_201909/lib/python3.7/site-packages/distributed/worker.py", line 875, in heartbeat
    metrics=await self.get_metrics(),
  File "/softs/rh7/conda/4.5.4/envs/pangeo_full_201909/lib/python3.7/site-packages/distributed/core.py", line 747, in send_recv_from_rpc
    comm = await self.pool.connect(self.addr)
  File "/softs/rh7/conda/4.5.4/envs/pangeo_full_201909/lib/python3.7/site-packages/distributed/core.py", line 874, in connect
    connection_args=self.connection_args,
  File "/softs/rh7/conda/4.5.4/envs/pangeo_full_201909/lib/python3.7/site-packages/distributed/comm/core.py", line 227, in connect
    _raise(error)
  File "/softs/rh7/conda/4.5.4/envs/pangeo_full_201909/lib/python3.7/site-packages/distributed/comm/core.py", line 204, in _raise
    raise IOError(msg)
OSError: Timed out trying to connect to 'tcp://10.120.40.97:33653' after 10 s: in <distributed.comm.tcp.TCPConnector object at 0x2b244dd53390>: ConnectionRefusedError: [Errno 111] Connection refused
tornado.application - ERROR - Exception in callback functools.partial(<bound method IOLoop._discard_future_result of <tornado.platform.asyncio.AsyncIOLoop object at 0x2b2433c61c88>>, <Task finished coro=<Worker.heartbeat() done, defined at /softs/rh7/conda/4.5.4/envs/pangeo_full_201909/lib/python3.7/site-packages/distributed/worker.py:866> exception=OSError("Timed out trying to connect to 'tcp://10.120.40.97:33653' after 10 s: in <distributed.comm.tcp.TCPConnector object at 0x2b244dd53710>: ConnectionRefusedError: [Errno 111] Connection refused")>)
Traceback (most recent call last):
  File "/softs/rh7/conda/4.5.4/envs/pangeo_full_201909/lib/python3.7/site-packages/distributed/comm/core.py", line 215, in connect
    quiet_exceptions=EnvironmentError,
tornado.util.TimeoutError: Timeout

During handling of the above exception, another exception occurred:

Traceback (most recent call last):
  File "/softs/rh7/conda/4.5.4/envs/pangeo_full_201909/lib/python3.7/site-packages/tornado/ioloop.py", line 743, in _run_callback
    ret = callback()
  File "/softs/rh7/conda/4.5.4/envs/pangeo_full_201909/lib/python3.7/site-packages/tornado/ioloop.py", line 767, in _discard_future_result
    future.result()
  File "/softs/rh7/conda/4.5.4/envs/pangeo_full_201909/lib/python3.7/site-packages/distributed/worker.py", line 875, in heartbeat
    metrics=await self.get_metrics(),
  File "/softs/rh7/conda/4.5.4/envs/pangeo_full_201909/lib/python3.7/site-packages/distributed/core.py", line 747, in send_recv_from_rpc
    comm = await self.pool.connect(self.addr)
  File "/softs/rh7/conda/4.5.4/envs/pangeo_full_201909/lib/python3.7/site-packages/distributed/core.py", line 874, in connect
    connection_args=self.connection_args,
  File "/softs/rh7/conda/4.5.4/envs/pangeo_full_201909/lib/python3.7/site-packages/distributed/comm/core.py", line 227, in connect
    _raise(error)
  File "/softs/rh7/conda/4.5.4/envs/pangeo_full_201909/lib/python3.7/site-packages/distributed/comm/core.py", line 204, in _raise
    raise IOError(msg)
OSError: Timed out trying to connect to 'tcp://10.120.40.97:33653' after 10 s: in <distributed.comm.tcp.TCPConnector object at 0x2b244dd53710>: ConnectionRefusedError: [Errno 111] Connection refused
tornado.application - ERROR - Exception in callback functools.partial(<bound method IOLoop._discard_future_result of <tornado.platform.asyncio.AsyncIOLoop object at 0x2b2433c61c88>>, <Task finished coro=<Worker.heartbeat() done, defined at /softs/rh7/conda/4.5.4/envs/pangeo_full_201909/lib/python3.7/site-packages/distributed/worker.py:866> exception=OSError("Timed out trying to connect to 'tcp://10.120.40.97:33653' after 10 s: in <distributed.comm.tcp.TCPConnector object at 0x2b244e9f0b70>: ConnectionRefusedError: [Errno 111] Connection refused")>)
Traceback (most recent call last):
  File "/softs/rh7/conda/4.5.4/envs/pangeo_full_201909/lib/python3.7/site-packages/distributed/comm/core.py", line 215, in connect
    quiet_exceptions=EnvironmentError,
tornado.util.TimeoutError: Timeout

During handling of the above exception, another exception occurred:

Traceback (most recent call last):
  File "/softs/rh7/conda/4.5.4/envs/pangeo_full_201909/lib/python3.7/site-packages/tornado/ioloop.py", line 743, in _run_callback
    ret = callback()
  File "/softs/rh7/conda/4.5.4/envs/pangeo_full_201909/lib/python3.7/site-packages/tornado/ioloop.py", line 767, in _discard_future_result
    future.result()
  File "/softs/rh7/conda/4.5.4/envs/pangeo_full_201909/lib/python3.7/site-packages/distributed/worker.py", line 875, in heartbeat
    metrics=await self.get_metrics(),
  File "/softs/rh7/conda/4.5.4/envs/pangeo_full_201909/lib/python3.7/site-packages/distributed/core.py", line 747, in send_recv_from_rpc
    comm = await self.pool.connect(self.addr)
  File "/softs/rh7/conda/4.5.4/envs/pangeo_full_201909/lib/python3.7/site-packages/distributed/core.py", line 874, in connect
    connection_args=self.connection_args,
  File "/softs/rh7/conda/4.5.4/envs/pangeo_full_201909/lib/python3.7/site-packages/distributed/comm/core.py", line 227, in connect
    _raise(error)
  File "/softs/rh7/conda/4.5.4/envs/pangeo_full_201909/lib/python3.7/site-packages/distributed/comm/core.py", line 204, in _raise
    raise IOError(msg)
OSError: Timed out trying to connect to 'tcp://10.120.40.97:33653' after 10 s: in <distributed.comm.tcp.TCPConnector object at 0x2b244e9f0b70>: ConnectionRefusedError: [Errno 111] Connection refused
tornado.application - ERROR - Exception in callback <function Worker._register_with_scheduler.<locals>.<lambda> at 0x2b2437efe2f0>
Traceback (most recent call last):
  File "/softs/rh7/conda/4.5.4/envs/pangeo_full_201909/lib/python3.7/site-packages/tornado/ioloop.py", line 907, in _run
    return self.callback()
  File "/softs/rh7/conda/4.5.4/envs/pangeo_full_201909/lib/python3.7/site-packages/distributed/worker.py", line 857, in <lambda>
    lambda: self.batched_stream.send({"op": "keep-alive"}),
  File "/softs/rh7/conda/4.5.4/envs/pangeo_full_201909/lib/python3.7/site-packages/distributed/batched.py", line 117, in send
    raise CommClosedError
distributed.comm.core.CommClosedError
tornado.application - ERROR - Exception in callback functools.partial(<bound method IOLoop._discard_future_result of <tornado.platform.asyncio.AsyncIOLoop object at 0x2b2433c61c88>>, <Task finished coro=<Worker.heartbeat() done, defined at /softs/rh7/conda/4.5.4/envs/pangeo_full_201909/lib/python3.7/site-packages/distributed/worker.py:866> exception=OSError("Timed out trying to connect to 'tcp://10.120.40.97:33653' after 10 s: in <distributed.comm.tcp.TCPConnector object at 0x2b244e0d8cf8>: ConnectionRefusedError: [Errno 111] Connection refused")>)
Traceback (most recent call last):
  File "/softs/rh7/conda/4.5.4/envs/pangeo_full_201909/lib/python3.7/site-packages/distributed/comm/core.py", line 215, in connect
    quiet_exceptions=EnvironmentError,
tornado.util.TimeoutError: Timeout

During handling of the above exception, another exception occurred:

Traceback (most recent call last):
  File "/softs/rh7/conda/4.5.4/envs/pangeo_full_201909/lib/python3.7/site-packages/tornado/ioloop.py", line 743, in _run_callback
    ret = callback()
  File "/softs/rh7/conda/4.5.4/envs/pangeo_full_201909/lib/python3.7/site-packages/tornado/ioloop.py", line 767, in _discard_future_result
    future.result()
  File "/softs/rh7/conda/4.5.4/envs/pangeo_full_201909/lib/python3.7/site-packages/distributed/worker.py", line 875, in heartbeat
    metrics=await self.get_metrics(),
  File "/softs/rh7/conda/4.5.4/envs/pangeo_full_201909/lib/python3.7/site-packages/distributed/core.py", line 747, in send_recv_from_rpc
    comm = await self.pool.connect(self.addr)
  File "/softs/rh7/conda/4.5.4/envs/pangeo_full_201909/lib/python3.7/site-packages/distributed/core.py", line 874, in connect
    connection_args=self.connection_args,
  File "/softs/rh7/conda/4.5.4/envs/pangeo_full_201909/lib/python3.7/site-packages/distributed/comm/core.py", line 227, in connect
    _raise(error)
  File "/softs/rh7/conda/4.5.4/envs/pangeo_full_201909/lib/python3.7/site-packages/distributed/comm/core.py", line 204, in _raise
    raise IOError(msg)
OSError: Timed out trying to connect to 'tcp://10.120.40.97:33653' after 10 s: in <distributed.comm.tcp.TCPConnector object at 0x2b244e0d8cf8>: ConnectionRefusedError: [Errno 111] Connection refused
=>> PBS: job killed: walltime 1818 exceeded limit 1800
distributed.nanny - INFO - Worker process 2180 was killed by unknown signal
distributed.dask_worker - INFO - Exiting on signal 15
distributed.nanny - INFO - Closing Nanny at 'tcp://10.120.40.72:38848'
distributed.dask_worker - INFO - End worker
Traceback (most recent call last):
  File "/softs/rh7/conda/4.5.4/envs/pangeo_full_201909/lib/python3.7/runpy.py", line 193, in _run_module_as_main
    "__main__", mod_spec)
  File "/softs/rh7/conda/4.5.4/envs/pangeo_full_201909/lib/python3.7/runpy.py", line 85, in _run_code
    exec(code, run_globals)
  File "/softs/rh7/conda/4.5.4/envs/pangeo_full_201909/lib/python3.7/site-packages/distributed/cli/dask_worker.py", line 410, in <module>
    go()
  File "/softs/rh7/conda/4.5.4/envs/pangeo_full_201909/lib/python3.7/site-packages/distributed/cli/dask_worker.py", line 406, in go
    main()
  File "/softs/rh7/conda/4.5.4/envs/pangeo_full_201909/lib/python3.7/site-packages/click/core.py", line 764, in __call__
    return self.main(*args, **kwargs)
  File "/softs/rh7/conda/4.5.4/envs/pangeo_full_201909/lib/python3.7/site-packages/click/core.py", line 717, in main
    rv = self.invoke(ctx)
  File "/softs/rh7/conda/4.5.4/envs/pangeo_full_201909/lib/python3.7/site-packages/click/core.py", line 956, in invoke
    return ctx.invoke(self.callback, **ctx.params)
  File "/softs/rh7/conda/4.5.4/envs/pangeo_full_201909/lib/python3.7/site-packages/click/core.py", line 555, in invoke
    return callback(*args, **kwargs)
  File "/softs/rh7/conda/4.5.4/envs/pangeo_full_201909/lib/python3.7/site-packages/distributed/cli/dask_worker.py", line 397, in main
    raise TimeoutError("Timed out starting worker.") from None
tornado.util.TimeoutError: Timed out starting worker.
