distributed.nanny - INFO -         Start Nanny at: 'tcp://10.120.40.58:43553'
distributed.worker - INFO -       Start worker at:   tcp://10.120.40.58:35654
distributed.worker - INFO -          Listening to:   tcp://10.120.40.58:35654
distributed.worker - INFO -          dashboard at:         10.120.40.58:34086
distributed.worker - INFO - Waiting to connect to:   tcp://10.120.40.97:33653
distributed.worker - INFO - -------------------------------------------------
distributed.worker - INFO -               Threads:                          1
distributed.worker - INFO -                Memory:                  120.00 GB
distributed.worker - INFO -       Local Directory: /tmp/pbs.6182525.admin01/worker-0qfb1m91
distributed.worker - INFO - -------------------------------------------------
distributed.worker - INFO -         Registered to:   tcp://10.120.40.97:33653
distributed.worker - INFO - -------------------------------------------------
distributed.core - INFO - Starting established connection
/softs/rh7/conda/4.5.4/envs/pangeo_full_201909/lib/python3.7/site-packages/dask/core.py:119: RuntimeWarning: invalid value encountered in less
  return func(*args2)
distributed.utils_perf - INFO - full garbage collection released 17.11 MB from 801 reference cycles (threshold: 10.00 MB)
distributed.worker - INFO - Connection to scheduler broken.  Reconnecting...
distributed.worker - WARNING - Heartbeat to scheduler failed
tornado.application - ERROR - Exception in callback functools.partial(<bound method IOLoop._discard_future_result of <tornado.platform.asyncio.AsyncIOLoop object at 0x2b9fed87bb38>>, <Task finished coro=<Worker.heartbeat() done, defined at /softs/rh7/conda/4.5.4/envs/pangeo_full_201909/lib/python3.7/site-packages/distributed/worker.py:866> exception=OSError("Timed out trying to connect to 'tcp://10.120.40.97:33653' after 10 s: in <distributed.comm.tcp.TCPConnector object at 0x2ba001393208>: ConnectionRefusedError: [Errno 111] Connection refused")>)
Traceback (most recent call last):
  File "/softs/rh7/conda/4.5.4/envs/pangeo_full_201909/lib/python3.7/site-packages/distributed/comm/core.py", line 215, in connect
    quiet_exceptions=EnvironmentError,
tornado.util.TimeoutError: Timeout

During handling of the above exception, another exception occurred:

Traceback (most recent call last):
  File "/softs/rh7/conda/4.5.4/envs/pangeo_full_201909/lib/python3.7/site-packages/tornado/ioloop.py", line 743, in _run_callback
    ret = callback()
  File "/softs/rh7/conda/4.5.4/envs/pangeo_full_201909/lib/python3.7/site-packages/tornado/ioloop.py", line 767, in _discard_future_result
    future.result()
  File "/softs/rh7/conda/4.5.4/envs/pangeo_full_201909/lib/python3.7/site-packages/distributed/worker.py", line 875, in heartbeat
    metrics=await self.get_metrics(),
  File "/softs/rh7/conda/4.5.4/envs/pangeo_full_201909/lib/python3.7/site-packages/distributed/core.py", line 747, in send_recv_from_rpc
    comm = await self.pool.connect(self.addr)
  File "/softs/rh7/conda/4.5.4/envs/pangeo_full_201909/lib/python3.7/site-packages/distributed/core.py", line 874, in connect
    connection_args=self.connection_args,
  File "/softs/rh7/conda/4.5.4/envs/pangeo_full_201909/lib/python3.7/site-packages/distributed/comm/core.py", line 227, in connect
    _raise(error)
  File "/softs/rh7/conda/4.5.4/envs/pangeo_full_201909/lib/python3.7/site-packages/distributed/comm/core.py", line 204, in _raise
    raise IOError(msg)
OSError: Timed out trying to connect to 'tcp://10.120.40.97:33653' after 10 s: in <distributed.comm.tcp.TCPConnector object at 0x2ba001393208>: ConnectionRefusedError: [Errno 111] Connection refused
tornado.application - ERROR - Exception in callback functools.partial(<bound method IOLoop._discard_future_result of <tornado.platform.asyncio.AsyncIOLoop object at 0x2b9fed87bb38>>, <Task finished coro=<Worker.heartbeat() done, defined at /softs/rh7/conda/4.5.4/envs/pangeo_full_201909/lib/python3.7/site-packages/distributed/worker.py:866> exception=OSError("Timed out trying to connect to 'tcp://10.120.40.97:33653' after 10 s: in <distributed.comm.tcp.TCPConnector object at 0x2ba0029eef60>: ConnectionRefusedError: [Errno 111] Connection refused")>)
Traceback (most recent call last):
  File "/softs/rh7/conda/4.5.4/envs/pangeo_full_201909/lib/python3.7/site-packages/distributed/comm/core.py", line 215, in connect
    quiet_exceptions=EnvironmentError,
tornado.util.TimeoutError: Timeout

During handling of the above exception, another exception occurred:

Traceback (most recent call last):
  File "/softs/rh7/conda/4.5.4/envs/pangeo_full_201909/lib/python3.7/site-packages/tornado/ioloop.py", line 743, in _run_callback
    ret = callback()
  File "/softs/rh7/conda/4.5.4/envs/pangeo_full_201909/lib/python3.7/site-packages/tornado/ioloop.py", line 767, in _discard_future_result
    future.result()
  File "/softs/rh7/conda/4.5.4/envs/pangeo_full_201909/lib/python3.7/site-packages/distributed/worker.py", line 875, in heartbeat
    metrics=await self.get_metrics(),
  File "/softs/rh7/conda/4.5.4/envs/pangeo_full_201909/lib/python3.7/site-packages/distributed/core.py", line 747, in send_recv_from_rpc
    comm = await self.pool.connect(self.addr)
  File "/softs/rh7/conda/4.5.4/envs/pangeo_full_201909/lib/python3.7/site-packages/distributed/core.py", line 874, in connect
    connection_args=self.connection_args,
  File "/softs/rh7/conda/4.5.4/envs/pangeo_full_201909/lib/python3.7/site-packages/distributed/comm/core.py", line 227, in connect
    _raise(error)
  File "/softs/rh7/conda/4.5.4/envs/pangeo_full_201909/lib/python3.7/site-packages/distributed/comm/core.py", line 204, in _raise
    raise IOError(msg)
OSError: Timed out trying to connect to 'tcp://10.120.40.97:33653' after 10 s: in <distributed.comm.tcp.TCPConnector object at 0x2ba0029eef60>: ConnectionRefusedError: [Errno 111] Connection refused
tornado.application - ERROR - Exception in callback functools.partial(<bound method IOLoop._discard_future_result of <tornado.platform.asyncio.AsyncIOLoop object at 0x2b9fed87bb38>>, <Task finished coro=<Worker.heartbeat() done, defined at /softs/rh7/conda/4.5.4/envs/pangeo_full_201909/lib/python3.7/site-packages/distributed/worker.py:866> exception=OSError("Timed out trying to connect to 'tcp://10.120.40.97:33653' after 10 s: in <distributed.comm.tcp.TCPConnector object at 0x2ba0029b0b00>: ConnectionRefusedError: [Errno 111] Connection refused")>)
Traceback (most recent call last):
  File "/softs/rh7/conda/4.5.4/envs/pangeo_full_201909/lib/python3.7/site-packages/distributed/comm/core.py", line 215, in connect
    quiet_exceptions=EnvironmentError,
tornado.util.TimeoutError: Timeout

During handling of the above exception, another exception occurred:

Traceback (most recent call last):
  File "/softs/rh7/conda/4.5.4/envs/pangeo_full_201909/lib/python3.7/site-packages/tornado/ioloop.py", line 743, in _run_callback
    ret = callback()
  File "/softs/rh7/conda/4.5.4/envs/pangeo_full_201909/lib/python3.7/site-packages/tornado/ioloop.py", line 767, in _discard_future_result
    future.result()
  File "/softs/rh7/conda/4.5.4/envs/pangeo_full_201909/lib/python3.7/site-packages/distributed/worker.py", line 875, in heartbeat
    metrics=await self.get_metrics(),
  File "/softs/rh7/conda/4.5.4/envs/pangeo_full_201909/lib/python3.7/site-packages/distributed/core.py", line 747, in send_recv_from_rpc
    comm = await self.pool.connect(self.addr)
  File "/softs/rh7/conda/4.5.4/envs/pangeo_full_201909/lib/python3.7/site-packages/distributed/core.py", line 874, in connect
    connection_args=self.connection_args,
  File "/softs/rh7/conda/4.5.4/envs/pangeo_full_201909/lib/python3.7/site-packages/distributed/comm/core.py", line 227, in connect
    _raise(error)
  File "/softs/rh7/conda/4.5.4/envs/pangeo_full_201909/lib/python3.7/site-packages/distributed/comm/core.py", line 204, in _raise
    raise IOError(msg)
OSError: Timed out trying to connect to 'tcp://10.120.40.97:33653' after 10 s: in <distributed.comm.tcp.TCPConnector object at 0x2ba0029b0b00>: ConnectionRefusedError: [Errno 111] Connection refused
tornado.application - ERROR - Exception in callback functools.partial(<bound method IOLoop._discard_future_result of <tornado.platform.asyncio.AsyncIOLoop object at 0x2b9fed87bb38>>, <Task finished coro=<Worker.heartbeat() done, defined at /softs/rh7/conda/4.5.4/envs/pangeo_full_201909/lib/python3.7/site-packages/distributed/worker.py:866> exception=OSError("Timed out trying to connect to 'tcp://10.120.40.97:33653' after 10 s: in <distributed.comm.tcp.TCPConnector object at 0x2ba0029b0630>: ConnectionRefusedError: [Errno 111] Connection refused")>)
Traceback (most recent call last):
  File "/softs/rh7/conda/4.5.4/envs/pangeo_full_201909/lib/python3.7/site-packages/distributed/comm/core.py", line 215, in connect
    quiet_exceptions=EnvironmentError,
tornado.util.TimeoutError: Timeout

During handling of the above exception, another exception occurred:

Traceback (most recent call last):
  File "/softs/rh7/conda/4.5.4/envs/pangeo_full_201909/lib/python3.7/site-packages/tornado/ioloop.py", line 743, in _run_callback
    ret = callback()
  File "/softs/rh7/conda/4.5.4/envs/pangeo_full_201909/lib/python3.7/site-packages/tornado/ioloop.py", line 767, in _discard_future_result
    future.result()
  File "/softs/rh7/conda/4.5.4/envs/pangeo_full_201909/lib/python3.7/site-packages/distributed/worker.py", line 875, in heartbeat
    metrics=await self.get_metrics(),
  File "/softs/rh7/conda/4.5.4/envs/pangeo_full_201909/lib/python3.7/site-packages/distributed/core.py", line 747, in send_recv_from_rpc
    comm = await self.pool.connect(self.addr)
  File "/softs/rh7/conda/4.5.4/envs/pangeo_full_201909/lib/python3.7/site-packages/distributed/core.py", line 874, in connect
    connection_args=self.connection_args,
  File "/softs/rh7/conda/4.5.4/envs/pangeo_full_201909/lib/python3.7/site-packages/distributed/comm/core.py", line 227, in connect
    _raise(error)
  File "/softs/rh7/conda/4.5.4/envs/pangeo_full_201909/lib/python3.7/site-packages/distributed/comm/core.py", line 204, in _raise
    raise IOError(msg)
OSError: Timed out trying to connect to 'tcp://10.120.40.97:33653' after 10 s: in <distributed.comm.tcp.TCPConnector object at 0x2ba0029b0630>: ConnectionRefusedError: [Errno 111] Connection refused
tornado.application - ERROR - Exception in callback <function Worker._register_with_scheduler.<locals>.<lambda> at 0x2ba0005ead90>
Traceback (most recent call last):
  File "/softs/rh7/conda/4.5.4/envs/pangeo_full_201909/lib/python3.7/site-packages/tornado/ioloop.py", line 907, in _run
    return self.callback()
  File "/softs/rh7/conda/4.5.4/envs/pangeo_full_201909/lib/python3.7/site-packages/distributed/worker.py", line 857, in <lambda>
    lambda: self.batched_stream.send({"op": "keep-alive"}),
  File "/softs/rh7/conda/4.5.4/envs/pangeo_full_201909/lib/python3.7/site-packages/distributed/batched.py", line 117, in send
    raise CommClosedError
distributed.comm.core.CommClosedError
tornado.application - ERROR - Exception in callback functools.partial(<bound method IOLoop._discard_future_result of <tornado.platform.asyncio.AsyncIOLoop object at 0x2b9fed87bb38>>, <Task finished coro=<Worker.heartbeat() done, defined at /softs/rh7/conda/4.5.4/envs/pangeo_full_201909/lib/python3.7/site-packages/distributed/worker.py:866> exception=OSError("Timed out trying to connect to 'tcp://10.120.40.97:33653' after 10 s: in <distributed.comm.tcp.TCPConnector object at 0x2ba0029b0eb8>: ConnectionRefusedError: [Errno 111] Connection refused")>)
Traceback (most recent call last):
  File "/softs/rh7/conda/4.5.4/envs/pangeo_full_201909/lib/python3.7/site-packages/distributed/comm/core.py", line 215, in connect
    quiet_exceptions=EnvironmentError,
tornado.util.TimeoutError: Timeout

During handling of the above exception, another exception occurred:

Traceback (most recent call last):
  File "/softs/rh7/conda/4.5.4/envs/pangeo_full_201909/lib/python3.7/site-packages/tornado/ioloop.py", line 743, in _run_callback
    ret = callback()
  File "/softs/rh7/conda/4.5.4/envs/pangeo_full_201909/lib/python3.7/site-packages/tornado/ioloop.py", line 767, in _discard_future_result
    future.result()
  File "/softs/rh7/conda/4.5.4/envs/pangeo_full_201909/lib/python3.7/site-packages/distributed/worker.py", line 875, in heartbeat
    metrics=await self.get_metrics(),
  File "/softs/rh7/conda/4.5.4/envs/pangeo_full_201909/lib/python3.7/site-packages/distributed/core.py", line 747, in send_recv_from_rpc
    comm = await self.pool.connect(self.addr)
  File "/softs/rh7/conda/4.5.4/envs/pangeo_full_201909/lib/python3.7/site-packages/distributed/core.py", line 874, in connect
    connection_args=self.connection_args,
  File "/softs/rh7/conda/4.5.4/envs/pangeo_full_201909/lib/python3.7/site-packages/distributed/comm/core.py", line 227, in connect
    _raise(error)
  File "/softs/rh7/conda/4.5.4/envs/pangeo_full_201909/lib/python3.7/site-packages/distributed/comm/core.py", line 204, in _raise
    raise IOError(msg)
OSError: Timed out trying to connect to 'tcp://10.120.40.97:33653' after 10 s: in <distributed.comm.tcp.TCPConnector object at 0x2ba0029b0eb8>: ConnectionRefusedError: [Errno 111] Connection refused
tornado.application - ERROR - Exception in callback functools.partial(<bound method IOLoop._discard_future_result of <tornado.platform.asyncio.AsyncIOLoop object at 0x2b9fed87bb38>>, <Task finished coro=<Worker.heartbeat() done, defined at /softs/rh7/conda/4.5.4/envs/pangeo_full_201909/lib/python3.7/site-packages/distributed/worker.py:866> exception=OSError("Timed out trying to connect to 'tcp://10.120.40.97:33653' after 10 s: in <distributed.comm.tcp.TCPConnector object at 0x2ba002efdeb8>: ConnectionRefusedError: [Errno 111] Connection refused")>)
Traceback (most recent call last):
  File "/softs/rh7/conda/4.5.4/envs/pangeo_full_201909/lib/python3.7/site-packages/distributed/comm/core.py", line 215, in connect
    quiet_exceptions=EnvironmentError,
tornado.util.TimeoutError: Timeout

During handling of the above exception, another exception occurred:

Traceback (most recent call last):
  File "/softs/rh7/conda/4.5.4/envs/pangeo_full_201909/lib/python3.7/site-packages/tornado/ioloop.py", line 743, in _run_callback
    ret = callback()
  File "/softs/rh7/conda/4.5.4/envs/pangeo_full_201909/lib/python3.7/site-packages/tornado/ioloop.py", line 767, in _discard_future_result
    future.result()
  File "/softs/rh7/conda/4.5.4/envs/pangeo_full_201909/lib/python3.7/site-packages/distributed/worker.py", line 875, in heartbeat
    metrics=await self.get_metrics(),
  File "/softs/rh7/conda/4.5.4/envs/pangeo_full_201909/lib/python3.7/site-packages/distributed/core.py", line 747, in send_recv_from_rpc
    comm = await self.pool.connect(self.addr)
  File "/softs/rh7/conda/4.5.4/envs/pangeo_full_201909/lib/python3.7/site-packages/distributed/core.py", line 874, in connect
    connection_args=self.connection_args,
  File "/softs/rh7/conda/4.5.4/envs/pangeo_full_201909/lib/python3.7/site-packages/distributed/comm/core.py", line 227, in connect
    _raise(error)
  File "/softs/rh7/conda/4.5.4/envs/pangeo_full_201909/lib/python3.7/site-packages/distributed/comm/core.py", line 204, in _raise
    raise IOError(msg)
OSError: Timed out trying to connect to 'tcp://10.120.40.97:33653' after 10 s: in <distributed.comm.tcp.TCPConnector object at 0x2ba002efdeb8>: ConnectionRefusedError: [Errno 111] Connection refused
tornado.application - ERROR - Exception in callback functools.partial(<bound method IOLoop._discard_future_result of <tornado.platform.asyncio.AsyncIOLoop object at 0x2b9fed87bb38>>, <Task finished coro=<Worker.heartbeat() done, defined at /softs/rh7/conda/4.5.4/envs/pangeo_full_201909/lib/python3.7/site-packages/distributed/worker.py:866> exception=OSError("Timed out trying to connect to 'tcp://10.120.40.97:33653' after 10 s: in <distributed.comm.tcp.TCPConnector object at 0x2ba002efd630>: ConnectionRefusedError: [Errno 111] Connection refused")>)
Traceback (most recent call last):
  File "/softs/rh7/conda/4.5.4/envs/pangeo_full_201909/lib/python3.7/site-packages/distributed/comm/core.py", line 215, in connect
    quiet_exceptions=EnvironmentError,
tornado.util.TimeoutError: Timeout

During handling of the above exception, another exception occurred:

Traceback (most recent call last):
  File "/softs/rh7/conda/4.5.4/envs/pangeo_full_201909/lib/python3.7/site-packages/tornado/ioloop.py", line 743, in _run_callback
    ret = callback()
  File "/softs/rh7/conda/4.5.4/envs/pangeo_full_201909/lib/python3.7/site-packages/tornado/ioloop.py", line 767, in _discard_future_result
    future.result()
  File "/softs/rh7/conda/4.5.4/envs/pangeo_full_201909/lib/python3.7/site-packages/distributed/worker.py", line 875, in heartbeat
    metrics=await self.get_metrics(),
  File "/softs/rh7/conda/4.5.4/envs/pangeo_full_201909/lib/python3.7/site-packages/distributed/core.py", line 747, in send_recv_from_rpc
    comm = await self.pool.connect(self.addr)
  File "/softs/rh7/conda/4.5.4/envs/pangeo_full_201909/lib/python3.7/site-packages/distributed/core.py", line 874, in connect
    connection_args=self.connection_args,
  File "/softs/rh7/conda/4.5.4/envs/pangeo_full_201909/lib/python3.7/site-packages/distributed/comm/core.py", line 227, in connect
    _raise(error)
  File "/softs/rh7/conda/4.5.4/envs/pangeo_full_201909/lib/python3.7/site-packages/distributed/comm/core.py", line 204, in _raise
    raise IOError(msg)
OSError: Timed out trying to connect to 'tcp://10.120.40.97:33653' after 10 s: in <distributed.comm.tcp.TCPConnector object at 0x2ba002efd630>: ConnectionRefusedError: [Errno 111] Connection refused
tornado.application - ERROR - Exception in callback functools.partial(<bound method IOLoop._discard_future_result of <tornado.platform.asyncio.AsyncIOLoop object at 0x2b9fed87bb38>>, <Task finished coro=<Worker.heartbeat() done, defined at /softs/rh7/conda/4.5.4/envs/pangeo_full_201909/lib/python3.7/site-packages/distributed/worker.py:866> exception=OSError("Timed out trying to connect to 'tcp://10.120.40.97:33653' after 10 s: in <distributed.comm.tcp.TCPConnector object at 0x2ba002f32b00>: ConnectionRefusedError: [Errno 111] Connection refused")>)
Traceback (most recent call last):
  File "/softs/rh7/conda/4.5.4/envs/pangeo_full_201909/lib/python3.7/site-packages/distributed/comm/core.py", line 215, in connect
    quiet_exceptions=EnvironmentError,
tornado.util.TimeoutError: Timeout

During handling of the above exception, another exception occurred:

Traceback (most recent call last):
  File "/softs/rh7/conda/4.5.4/envs/pangeo_full_201909/lib/python3.7/site-packages/tornado/ioloop.py", line 743, in _run_callback
    ret = callback()
  File "/softs/rh7/conda/4.5.4/envs/pangeo_full_201909/lib/python3.7/site-packages/tornado/ioloop.py", line 767, in _discard_future_result
    future.result()
  File "/softs/rh7/conda/4.5.4/envs/pangeo_full_201909/lib/python3.7/site-packages/distributed/worker.py", line 875, in heartbeat
    metrics=await self.get_metrics(),
  File "/softs/rh7/conda/4.5.4/envs/pangeo_full_201909/lib/python3.7/site-packages/distributed/core.py", line 747, in send_recv_from_rpc
    comm = await self.pool.connect(self.addr)
  File "/softs/rh7/conda/4.5.4/envs/pangeo_full_201909/lib/python3.7/site-packages/distributed/core.py", line 874, in connect
    connection_args=self.connection_args,
  File "/softs/rh7/conda/4.5.4/envs/pangeo_full_201909/lib/python3.7/site-packages/distributed/comm/core.py", line 227, in connect
    _raise(error)
  File "/softs/rh7/conda/4.5.4/envs/pangeo_full_201909/lib/python3.7/site-packages/distributed/comm/core.py", line 204, in _raise
    raise IOError(msg)
OSError: Timed out trying to connect to 'tcp://10.120.40.97:33653' after 10 s: in <distributed.comm.tcp.TCPConnector object at 0x2ba002f32b00>: ConnectionRefusedError: [Errno 111] Connection refused
tornado.application - ERROR - Exception in callback functools.partial(<bound method IOLoop._discard_future_result of <tornado.platform.asyncio.AsyncIOLoop object at 0x2b9fed87bb38>>, <Task finished coro=<Worker.heartbeat() done, defined at /softs/rh7/conda/4.5.4/envs/pangeo_full_201909/lib/python3.7/site-packages/distributed/worker.py:866> exception=OSError("Timed out trying to connect to 'tcp://10.120.40.97:33653' after 10 s: in <distributed.comm.tcp.TCPConnector object at 0x2ba002efd400>: ConnectionRefusedError: [Errno 111] Connection refused")>)
Traceback (most recent call last):
  File "/softs/rh7/conda/4.5.4/envs/pangeo_full_201909/lib/python3.7/site-packages/distributed/comm/core.py", line 215, in connect
    quiet_exceptions=EnvironmentError,
tornado.util.TimeoutError: Timeout

During handling of the above exception, another exception occurred:

Traceback (most recent call last):
  File "/softs/rh7/conda/4.5.4/envs/pangeo_full_201909/lib/python3.7/site-packages/tornado/ioloop.py", line 743, in _run_callback
    ret = callback()
  File "/softs/rh7/conda/4.5.4/envs/pangeo_full_201909/lib/python3.7/site-packages/tornado/ioloop.py", line 767, in _discard_future_result
    future.result()
  File "/softs/rh7/conda/4.5.4/envs/pangeo_full_201909/lib/python3.7/site-packages/distributed/worker.py", line 875, in heartbeat
    metrics=await self.get_metrics(),
  File "/softs/rh7/conda/4.5.4/envs/pangeo_full_201909/lib/python3.7/site-packages/distributed/core.py", line 747, in send_recv_from_rpc
    comm = await self.pool.connect(self.addr)
  File "/softs/rh7/conda/4.5.4/envs/pangeo_full_201909/lib/python3.7/site-packages/distributed/core.py", line 874, in connect
    connection_args=self.connection_args,
  File "/softs/rh7/conda/4.5.4/envs/pangeo_full_201909/lib/python3.7/site-packages/distributed/comm/core.py", line 227, in connect
    _raise(error)
  File "/softs/rh7/conda/4.5.4/envs/pangeo_full_201909/lib/python3.7/site-packages/distributed/comm/core.py", line 204, in _raise
    raise IOError(msg)
OSError: Timed out trying to connect to 'tcp://10.120.40.97:33653' after 10 s: in <distributed.comm.tcp.TCPConnector object at 0x2ba002efd400>: ConnectionRefusedError: [Errno 111] Connection refused
tornado.application - ERROR - Exception in callback <function Worker._register_with_scheduler.<locals>.<lambda> at 0x2ba0005ead90>
Traceback (most recent call last):
  File "/softs/rh7/conda/4.5.4/envs/pangeo_full_201909/lib/python3.7/site-packages/tornado/ioloop.py", line 907, in _run
    return self.callback()
  File "/softs/rh7/conda/4.5.4/envs/pangeo_full_201909/lib/python3.7/site-packages/distributed/worker.py", line 857, in <lambda>
    lambda: self.batched_stream.send({"op": "keep-alive"}),
  File "/softs/rh7/conda/4.5.4/envs/pangeo_full_201909/lib/python3.7/site-packages/distributed/batched.py", line 117, in send
    raise CommClosedError
distributed.comm.core.CommClosedError
tornado.application - ERROR - Exception in callback functools.partial(<bound method IOLoop._discard_future_result of <tornado.platform.asyncio.AsyncIOLoop object at 0x2b9fed87bb38>>, <Task finished coro=<Worker.heartbeat() done, defined at /softs/rh7/conda/4.5.4/envs/pangeo_full_201909/lib/python3.7/site-packages/distributed/worker.py:866> exception=OSError("Timed out trying to connect to 'tcp://10.120.40.97:33653' after 10 s: in <distributed.comm.tcp.TCPConnector object at 0x2ba0021ffd68>: ConnectionRefusedError: [Errno 111] Connection refused")>)
Traceback (most recent call last):
  File "/softs/rh7/conda/4.5.4/envs/pangeo_full_201909/lib/python3.7/site-packages/distributed/comm/core.py", line 215, in connect
    quiet_exceptions=EnvironmentError,
tornado.util.TimeoutError: Timeout

During handling of the above exception, another exception occurred:

Traceback (most recent call last):
  File "/softs/rh7/conda/4.5.4/envs/pangeo_full_201909/lib/python3.7/site-packages/tornado/ioloop.py", line 743, in _run_callback
    ret = callback()
  File "/softs/rh7/conda/4.5.4/envs/pangeo_full_201909/lib/python3.7/site-packages/tornado/ioloop.py", line 767, in _discard_future_result
    future.result()
  File "/softs/rh7/conda/4.5.4/envs/pangeo_full_201909/lib/python3.7/site-packages/distributed/worker.py", line 875, in heartbeat
    metrics=await self.get_metrics(),
  File "/softs/rh7/conda/4.5.4/envs/pangeo_full_201909/lib/python3.7/site-packages/distributed/core.py", line 747, in send_recv_from_rpc
    comm = await self.pool.connect(self.addr)
  File "/softs/rh7/conda/4.5.4/envs/pangeo_full_201909/lib/python3.7/site-packages/distributed/core.py", line 874, in connect
    connection_args=self.connection_args,
  File "/softs/rh7/conda/4.5.4/envs/pangeo_full_201909/lib/python3.7/site-packages/distributed/comm/core.py", line 227, in connect
    _raise(error)
  File "/softs/rh7/conda/4.5.4/envs/pangeo_full_201909/lib/python3.7/site-packages/distributed/comm/core.py", line 204, in _raise
    raise IOError(msg)
OSError: Timed out trying to connect to 'tcp://10.120.40.97:33653' after 10 s: in <distributed.comm.tcp.TCPConnector object at 0x2ba0021ffd68>: ConnectionRefusedError: [Errno 111] Connection refused
tornado.application - ERROR - Exception in callback functools.partial(<bound method IOLoop._discard_future_result of <tornado.platform.asyncio.AsyncIOLoop object at 0x2b9fed87bb38>>, <Task finished coro=<Worker.heartbeat() done, defined at /softs/rh7/conda/4.5.4/envs/pangeo_full_201909/lib/python3.7/site-packages/distributed/worker.py:866> exception=OSError("Timed out trying to connect to 'tcp://10.120.40.97:33653' after 10 s: in <distributed.comm.tcp.TCPConnector object at 0x2ba0029ee6d8>: ConnectionRefusedError: [Errno 111] Connection refused")>)
Traceback (most recent call last):
  File "/softs/rh7/conda/4.5.4/envs/pangeo_full_201909/lib/python3.7/site-packages/distributed/comm/core.py", line 215, in connect
    quiet_exceptions=EnvironmentError,
tornado.util.TimeoutError: Timeout

During handling of the above exception, another exception occurred:

Traceback (most recent call last):
  File "/softs/rh7/conda/4.5.4/envs/pangeo_full_201909/lib/python3.7/site-packages/tornado/ioloop.py", line 743, in _run_callback
    ret = callback()
  File "/softs/rh7/conda/4.5.4/envs/pangeo_full_201909/lib/python3.7/site-packages/tornado/ioloop.py", line 767, in _discard_future_result
    future.result()
  File "/softs/rh7/conda/4.5.4/envs/pangeo_full_201909/lib/python3.7/site-packages/distributed/worker.py", line 875, in heartbeat
    metrics=await self.get_metrics(),
  File "/softs/rh7/conda/4.5.4/envs/pangeo_full_201909/lib/python3.7/site-packages/distributed/core.py", line 747, in send_recv_from_rpc
    comm = await self.pool.connect(self.addr)
  File "/softs/rh7/conda/4.5.4/envs/pangeo_full_201909/lib/python3.7/site-packages/distributed/core.py", line 874, in connect
    connection_args=self.connection_args,
  File "/softs/rh7/conda/4.5.4/envs/pangeo_full_201909/lib/python3.7/site-packages/distributed/comm/core.py", line 227, in connect
    _raise(error)
  File "/softs/rh7/conda/4.5.4/envs/pangeo_full_201909/lib/python3.7/site-packages/distributed/comm/core.py", line 204, in _raise
    raise IOError(msg)
OSError: Timed out trying to connect to 'tcp://10.120.40.97:33653' after 10 s: in <distributed.comm.tcp.TCPConnector object at 0x2ba0029ee6d8>: ConnectionRefusedError: [Errno 111] Connection refused
tornado.application - ERROR - Exception in callback functools.partial(<bound method IOLoop._discard_future_result of <tornado.platform.asyncio.AsyncIOLoop object at 0x2b9fed87bb38>>, <Task finished coro=<Worker.heartbeat() done, defined at /softs/rh7/conda/4.5.4/envs/pangeo_full_201909/lib/python3.7/site-packages/distributed/worker.py:866> exception=OSError("Timed out trying to connect to 'tcp://10.120.40.97:33653' after 10 s: in <distributed.comm.tcp.TCPConnector object at 0x2ba002251828>: ConnectionRefusedError: [Errno 111] Connection refused")>)
Traceback (most recent call last):
  File "/softs/rh7/conda/4.5.4/envs/pangeo_full_201909/lib/python3.7/site-packages/distributed/comm/core.py", line 215, in connect
    quiet_exceptions=EnvironmentError,
tornado.util.TimeoutError: Timeout

During handling of the above exception, another exception occurred:

Traceback (most recent call last):
  File "/softs/rh7/conda/4.5.4/envs/pangeo_full_201909/lib/python3.7/site-packages/tornado/ioloop.py", line 743, in _run_callback
    ret = callback()
  File "/softs/rh7/conda/4.5.4/envs/pangeo_full_201909/lib/python3.7/site-packages/tornado/ioloop.py", line 767, in _discard_future_result
    future.result()
  File "/softs/rh7/conda/4.5.4/envs/pangeo_full_201909/lib/python3.7/site-packages/distributed/worker.py", line 875, in heartbeat
    metrics=await self.get_metrics(),
  File "/softs/rh7/conda/4.5.4/envs/pangeo_full_201909/lib/python3.7/site-packages/distributed/core.py", line 747, in send_recv_from_rpc
    comm = await self.pool.connect(self.addr)
  File "/softs/rh7/conda/4.5.4/envs/pangeo_full_201909/lib/python3.7/site-packages/distributed/core.py", line 874, in connect
    connection_args=self.connection_args,
  File "/softs/rh7/conda/4.5.4/envs/pangeo_full_201909/lib/python3.7/site-packages/distributed/comm/core.py", line 227, in connect
    _raise(error)
  File "/softs/rh7/conda/4.5.4/envs/pangeo_full_201909/lib/python3.7/site-packages/distributed/comm/core.py", line 204, in _raise
    raise IOError(msg)
OSError: Timed out trying to connect to 'tcp://10.120.40.97:33653' after 10 s: in <distributed.comm.tcp.TCPConnector object at 0x2ba002251828>: ConnectionRefusedError: [Errno 111] Connection refused
tornado.application - ERROR - Exception in callback functools.partial(<bound method IOLoop._discard_future_result of <tornado.platform.asyncio.AsyncIOLoop object at 0x2b9fed87bb38>>, <Task finished coro=<Worker.heartbeat() done, defined at /softs/rh7/conda/4.5.4/envs/pangeo_full_201909/lib/python3.7/site-packages/distributed/worker.py:866> exception=OSError("Timed out trying to connect to 'tcp://10.120.40.97:33653' after 10 s: in <distributed.comm.tcp.TCPConnector object at 0x2ba0022517f0>: ConnectionRefusedError: [Errno 111] Connection refused")>)
Traceback (most recent call last):
  File "/softs/rh7/conda/4.5.4/envs/pangeo_full_201909/lib/python3.7/site-packages/distributed/comm/core.py", line 215, in connect
    quiet_exceptions=EnvironmentError,
tornado.util.TimeoutError: Timeout

During handling of the above exception, another exception occurred:

Traceback (most recent call last):
  File "/softs/rh7/conda/4.5.4/envs/pangeo_full_201909/lib/python3.7/site-packages/tornado/ioloop.py", line 743, in _run_callback
    ret = callback()
  File "/softs/rh7/conda/4.5.4/envs/pangeo_full_201909/lib/python3.7/site-packages/tornado/ioloop.py", line 767, in _discard_future_result
    future.result()
  File "/softs/rh7/conda/4.5.4/envs/pangeo_full_201909/lib/python3.7/site-packages/distributed/worker.py", line 875, in heartbeat
    metrics=await self.get_metrics(),
  File "/softs/rh7/conda/4.5.4/envs/pangeo_full_201909/lib/python3.7/site-packages/distributed/core.py", line 747, in send_recv_from_rpc
    comm = await self.pool.connect(self.addr)
  File "/softs/rh7/conda/4.5.4/envs/pangeo_full_201909/lib/python3.7/site-packages/distributed/core.py", line 874, in connect
    connection_args=self.connection_args,
  File "/softs/rh7/conda/4.5.4/envs/pangeo_full_201909/lib/python3.7/site-packages/distributed/comm/core.py", line 227, in connect
    _raise(error)
  File "/softs/rh7/conda/4.5.4/envs/pangeo_full_201909/lib/python3.7/site-packages/distributed/comm/core.py", line 204, in _raise
    raise IOError(msg)
OSError: Timed out trying to connect to 'tcp://10.120.40.97:33653' after 10 s: in <distributed.comm.tcp.TCPConnector object at 0x2ba0022517f0>: ConnectionRefusedError: [Errno 111] Connection refused
tornado.application - ERROR - Exception in callback functools.partial(<bound method IOLoop._discard_future_result of <tornado.platform.asyncio.AsyncIOLoop object at 0x2b9fed87bb38>>, <Task finished coro=<Worker.heartbeat() done, defined at /softs/rh7/conda/4.5.4/envs/pangeo_full_201909/lib/python3.7/site-packages/distributed/worker.py:866> exception=OSError("Timed out trying to connect to 'tcp://10.120.40.97:33653' after 10 s: in <distributed.comm.tcp.TCPConnector object at 0x2ba002e59160>: ConnectionRefusedError: [Errno 111] Connection refused")>)
Traceback (most recent call last):
  File "/softs/rh7/conda/4.5.4/envs/pangeo_full_201909/lib/python3.7/site-packages/distributed/comm/core.py", line 215, in connect
    quiet_exceptions=EnvironmentError,
tornado.util.TimeoutError: Timeout

During handling of the above exception, another exception occurred:

Traceback (most recent call last):
  File "/softs/rh7/conda/4.5.4/envs/pangeo_full_201909/lib/python3.7/site-packages/tornado/ioloop.py", line 743, in _run_callback
    ret = callback()
  File "/softs/rh7/conda/4.5.4/envs/pangeo_full_201909/lib/python3.7/site-packages/tornado/ioloop.py", line 767, in _discard_future_result
    future.result()
  File "/softs/rh7/conda/4.5.4/envs/pangeo_full_201909/lib/python3.7/site-packages/distributed/worker.py", line 875, in heartbeat
    metrics=await self.get_metrics(),
  File "/softs/rh7/conda/4.5.4/envs/pangeo_full_201909/lib/python3.7/site-packages/distributed/core.py", line 747, in send_recv_from_rpc
    comm = await self.pool.connect(self.addr)
  File "/softs/rh7/conda/4.5.4/envs/pangeo_full_201909/lib/python3.7/site-packages/distributed/core.py", line 874, in connect
    connection_args=self.connection_args,
  File "/softs/rh7/conda/4.5.4/envs/pangeo_full_201909/lib/python3.7/site-packages/distributed/comm/core.py", line 227, in connect
    _raise(error)
  File "/softs/rh7/conda/4.5.4/envs/pangeo_full_201909/lib/python3.7/site-packages/distributed/comm/core.py", line 204, in _raise
    raise IOError(msg)
OSError: Timed out trying to connect to 'tcp://10.120.40.97:33653' after 10 s: in <distributed.comm.tcp.TCPConnector object at 0x2ba002e59160>: ConnectionRefusedError: [Errno 111] Connection refused
tornado.application - ERROR - Exception in callback functools.partial(<bound method IOLoop._discard_future_result of <tornado.platform.asyncio.AsyncIOLoop object at 0x2b9fed87bb38>>, <Task finished coro=<Worker.heartbeat() done, defined at /softs/rh7/conda/4.5.4/envs/pangeo_full_201909/lib/python3.7/site-packages/distributed/worker.py:866> exception=OSError("Timed out trying to connect to 'tcp://10.120.40.97:33653' after 10 s: in <distributed.comm.tcp.TCPConnector object at 0x2ba00282c208>: ConnectionRefusedError: [Errno 111] Connection refused")>)
Traceback (most recent call last):
  File "/softs/rh7/conda/4.5.4/envs/pangeo_full_201909/lib/python3.7/site-packages/distributed/comm/core.py", line 215, in connect
    quiet_exceptions=EnvironmentError,
tornado.util.TimeoutError: Timeout

During handling of the above exception, another exception occurred:

Traceback (most recent call last):
  File "/softs/rh7/conda/4.5.4/envs/pangeo_full_201909/lib/python3.7/site-packages/tornado/ioloop.py", line 743, in _run_callback
    ret = callback()
  File "/softs/rh7/conda/4.5.4/envs/pangeo_full_201909/lib/python3.7/site-packages/tornado/ioloop.py", line 767, in _discard_future_result
    future.result()
  File "/softs/rh7/conda/4.5.4/envs/pangeo_full_201909/lib/python3.7/site-packages/distributed/worker.py", line 875, in heartbeat
    metrics=await self.get_metrics(),
  File "/softs/rh7/conda/4.5.4/envs/pangeo_full_201909/lib/python3.7/site-packages/distributed/core.py", line 747, in send_recv_from_rpc
    comm = await self.pool.connect(self.addr)
  File "/softs/rh7/conda/4.5.4/envs/pangeo_full_201909/lib/python3.7/site-packages/distributed/core.py", line 874, in connect
    connection_args=self.connection_args,
  File "/softs/rh7/conda/4.5.4/envs/pangeo_full_201909/lib/python3.7/site-packages/distributed/comm/core.py", line 227, in connect
    _raise(error)
  File "/softs/rh7/conda/4.5.4/envs/pangeo_full_201909/lib/python3.7/site-packages/distributed/comm/core.py", line 204, in _raise
    raise IOError(msg)
OSError: Timed out trying to connect to 'tcp://10.120.40.97:33653' after 10 s: in <distributed.comm.tcp.TCPConnector object at 0x2ba00282c208>: ConnectionRefusedError: [Errno 111] Connection refused
tornado.application - ERROR - Exception in callback <function Worker._register_with_scheduler.<locals>.<lambda> at 0x2ba0005ead90>
Traceback (most recent call last):
  File "/softs/rh7/conda/4.5.4/envs/pangeo_full_201909/lib/python3.7/site-packages/tornado/ioloop.py", line 907, in _run
    return self.callback()
  File "/softs/rh7/conda/4.5.4/envs/pangeo_full_201909/lib/python3.7/site-packages/distributed/worker.py", line 857, in <lambda>
    lambda: self.batched_stream.send({"op": "keep-alive"}),
  File "/softs/rh7/conda/4.5.4/envs/pangeo_full_201909/lib/python3.7/site-packages/distributed/batched.py", line 117, in send
    raise CommClosedError
distributed.comm.core.CommClosedError
tornado.application - ERROR - Exception in callback functools.partial(<bound method IOLoop._discard_future_result of <tornado.platform.asyncio.AsyncIOLoop object at 0x2b9fed87bb38>>, <Task finished coro=<Worker.heartbeat() done, defined at /softs/rh7/conda/4.5.4/envs/pangeo_full_201909/lib/python3.7/site-packages/distributed/worker.py:866> exception=OSError("Timed out trying to connect to 'tcp://10.120.40.97:33653' after 10 s: in <distributed.comm.tcp.TCPConnector object at 0x2ba002251198>: ConnectionRefusedError: [Errno 111] Connection refused")>)
Traceback (most recent call last):
  File "/softs/rh7/conda/4.5.4/envs/pangeo_full_201909/lib/python3.7/site-packages/distributed/comm/core.py", line 215, in connect
    quiet_exceptions=EnvironmentError,
tornado.util.TimeoutError: Timeout

During handling of the above exception, another exception occurred:

Traceback (most recent call last):
  File "/softs/rh7/conda/4.5.4/envs/pangeo_full_201909/lib/python3.7/site-packages/tornado/ioloop.py", line 743, in _run_callback
    ret = callback()
  File "/softs/rh7/conda/4.5.4/envs/pangeo_full_201909/lib/python3.7/site-packages/tornado/ioloop.py", line 767, in _discard_future_result
    future.result()
  File "/softs/rh7/conda/4.5.4/envs/pangeo_full_201909/lib/python3.7/site-packages/distributed/worker.py", line 875, in heartbeat
    metrics=await self.get_metrics(),
  File "/softs/rh7/conda/4.5.4/envs/pangeo_full_201909/lib/python3.7/site-packages/distributed/core.py", line 747, in send_recv_from_rpc
    comm = await self.pool.connect(self.addr)
  File "/softs/rh7/conda/4.5.4/envs/pangeo_full_201909/lib/python3.7/site-packages/distributed/core.py", line 874, in connect
    connection_args=self.connection_args,
  File "/softs/rh7/conda/4.5.4/envs/pangeo_full_201909/lib/python3.7/site-packages/distributed/comm/core.py", line 227, in connect
    _raise(error)
  File "/softs/rh7/conda/4.5.4/envs/pangeo_full_201909/lib/python3.7/site-packages/distributed/comm/core.py", line 204, in _raise
    raise IOError(msg)
OSError: Timed out trying to connect to 'tcp://10.120.40.97:33653' after 10 s: in <distributed.comm.tcp.TCPConnector object at 0x2ba002251198>: ConnectionRefusedError: [Errno 111] Connection refused
tornado.application - ERROR - Exception in callback functools.partial(<bound method IOLoop._discard_future_result of <tornado.platform.asyncio.AsyncIOLoop object at 0x2b9fed87bb38>>, <Task finished coro=<Worker.heartbeat() done, defined at /softs/rh7/conda/4.5.4/envs/pangeo_full_201909/lib/python3.7/site-packages/distributed/worker.py:866> exception=OSError("Timed out trying to connect to 'tcp://10.120.40.97:33653' after 10 s: in <distributed.comm.tcp.TCPConnector object at 0x2ba002efde48>: ConnectionRefusedError: [Errno 111] Connection refused")>)
Traceback (most recent call last):
  File "/softs/rh7/conda/4.5.4/envs/pangeo_full_201909/lib/python3.7/site-packages/distributed/comm/core.py", line 215, in connect
    quiet_exceptions=EnvironmentError,
tornado.util.TimeoutError: Timeout

During handling of the above exception, another exception occurred:

Traceback (most recent call last):
  File "/softs/rh7/conda/4.5.4/envs/pangeo_full_201909/lib/python3.7/site-packages/tornado/ioloop.py", line 743, in _run_callback
    ret = callback()
  File "/softs/rh7/conda/4.5.4/envs/pangeo_full_201909/lib/python3.7/site-packages/tornado/ioloop.py", line 767, in _discard_future_result
    future.result()
  File "/softs/rh7/conda/4.5.4/envs/pangeo_full_201909/lib/python3.7/site-packages/distributed/worker.py", line 875, in heartbeat
    metrics=await self.get_metrics(),
  File "/softs/rh7/conda/4.5.4/envs/pangeo_full_201909/lib/python3.7/site-packages/distributed/core.py", line 747, in send_recv_from_rpc
    comm = await self.pool.connect(self.addr)
  File "/softs/rh7/conda/4.5.4/envs/pangeo_full_201909/lib/python3.7/site-packages/distributed/core.py", line 874, in connect
    connection_args=self.connection_args,
  File "/softs/rh7/conda/4.5.4/envs/pangeo_full_201909/lib/python3.7/site-packages/distributed/comm/core.py", line 227, in connect
    _raise(error)
  File "/softs/rh7/conda/4.5.4/envs/pangeo_full_201909/lib/python3.7/site-packages/distributed/comm/core.py", line 204, in _raise
    raise IOError(msg)
OSError: Timed out trying to connect to 'tcp://10.120.40.97:33653' after 10 s: in <distributed.comm.tcp.TCPConnector object at 0x2ba002efde48>: ConnectionRefusedError: [Errno 111] Connection refused
tornado.application - ERROR - Exception in callback functools.partial(<bound method IOLoop._discard_future_result of <tornado.platform.asyncio.AsyncIOLoop object at 0x2b9fed87bb38>>, <Task finished coro=<Worker.heartbeat() done, defined at /softs/rh7/conda/4.5.4/envs/pangeo_full_201909/lib/python3.7/site-packages/distributed/worker.py:866> exception=OSError("Timed out trying to connect to 'tcp://10.120.40.97:33653' after 10 s: in <distributed.comm.tcp.TCPConnector object at 0x2ba002e594a8>: ConnectionRefusedError: [Errno 111] Connection refused")>)
Traceback (most recent call last):
  File "/softs/rh7/conda/4.5.4/envs/pangeo_full_201909/lib/python3.7/site-packages/distributed/comm/core.py", line 215, in connect
    quiet_exceptions=EnvironmentError,
tornado.util.TimeoutError: Timeout

During handling of the above exception, another exception occurred:

Traceback (most recent call last):
  File "/softs/rh7/conda/4.5.4/envs/pangeo_full_201909/lib/python3.7/site-packages/tornado/ioloop.py", line 743, in _run_callback
    ret = callback()
  File "/softs/rh7/conda/4.5.4/envs/pangeo_full_201909/lib/python3.7/site-packages/tornado/ioloop.py", line 767, in _discard_future_result
    future.result()
  File "/softs/rh7/conda/4.5.4/envs/pangeo_full_201909/lib/python3.7/site-packages/distributed/worker.py", line 875, in heartbeat
    metrics=await self.get_metrics(),
  File "/softs/rh7/conda/4.5.4/envs/pangeo_full_201909/lib/python3.7/site-packages/distributed/core.py", line 747, in send_recv_from_rpc
    comm = await self.pool.connect(self.addr)
  File "/softs/rh7/conda/4.5.4/envs/pangeo_full_201909/lib/python3.7/site-packages/distributed/core.py", line 874, in connect
    connection_args=self.connection_args,
  File "/softs/rh7/conda/4.5.4/envs/pangeo_full_201909/lib/python3.7/site-packages/distributed/comm/core.py", line 227, in connect
    _raise(error)
  File "/softs/rh7/conda/4.5.4/envs/pangeo_full_201909/lib/python3.7/site-packages/distributed/comm/core.py", line 204, in _raise
    raise IOError(msg)
OSError: Timed out trying to connect to 'tcp://10.120.40.97:33653' after 10 s: in <distributed.comm.tcp.TCPConnector object at 0x2ba002e594a8>: ConnectionRefusedError: [Errno 111] Connection refused
tornado.application - ERROR - Exception in callback functools.partial(<bound method IOLoop._discard_future_result of <tornado.platform.asyncio.AsyncIOLoop object at 0x2b9fed87bb38>>, <Task finished coro=<Worker.heartbeat() done, defined at /softs/rh7/conda/4.5.4/envs/pangeo_full_201909/lib/python3.7/site-packages/distributed/worker.py:866> exception=OSError("Timed out trying to connect to 'tcp://10.120.40.97:33653' after 10 s: in <distributed.comm.tcp.TCPConnector object at 0x2ba0029ee9e8>: ConnectionRefusedError: [Errno 111] Connection refused")>)
Traceback (most recent call last):
  File "/softs/rh7/conda/4.5.4/envs/pangeo_full_201909/lib/python3.7/site-packages/distributed/comm/core.py", line 215, in connect
    quiet_exceptions=EnvironmentError,
tornado.util.TimeoutError: Timeout

During handling of the above exception, another exception occurred:

Traceback (most recent call last):
  File "/softs/rh7/conda/4.5.4/envs/pangeo_full_201909/lib/python3.7/site-packages/tornado/ioloop.py", line 743, in _run_callback
    ret = callback()
  File "/softs/rh7/conda/4.5.4/envs/pangeo_full_201909/lib/python3.7/site-packages/tornado/ioloop.py", line 767, in _discard_future_result
    future.result()
  File "/softs/rh7/conda/4.5.4/envs/pangeo_full_201909/lib/python3.7/site-packages/distributed/worker.py", line 875, in heartbeat
    metrics=await self.get_metrics(),
  File "/softs/rh7/conda/4.5.4/envs/pangeo_full_201909/lib/python3.7/site-packages/distributed/core.py", line 747, in send_recv_from_rpc
    comm = await self.pool.connect(self.addr)
  File "/softs/rh7/conda/4.5.4/envs/pangeo_full_201909/lib/python3.7/site-packages/distributed/core.py", line 874, in connect
    connection_args=self.connection_args,
  File "/softs/rh7/conda/4.5.4/envs/pangeo_full_201909/lib/python3.7/site-packages/distributed/comm/core.py", line 227, in connect
    _raise(error)
  File "/softs/rh7/conda/4.5.4/envs/pangeo_full_201909/lib/python3.7/site-packages/distributed/comm/core.py", line 204, in _raise
    raise IOError(msg)
OSError: Timed out trying to connect to 'tcp://10.120.40.97:33653' after 10 s: in <distributed.comm.tcp.TCPConnector object at 0x2ba0029ee9e8>: ConnectionRefusedError: [Errno 111] Connection refused
tornado.application - ERROR - Exception in callback functools.partial(<bound method IOLoop._discard_future_result of <tornado.platform.asyncio.AsyncIOLoop object at 0x2b9fed87bb38>>, <Task finished coro=<Worker.heartbeat() done, defined at /softs/rh7/conda/4.5.4/envs/pangeo_full_201909/lib/python3.7/site-packages/distributed/worker.py:866> exception=OSError("Timed out trying to connect to 'tcp://10.120.40.97:33653' after 10 s: in <distributed.comm.tcp.TCPConnector object at 0x2ba002806828>: ConnectionRefusedError: [Errno 111] Connection refused")>)
Traceback (most recent call last):
  File "/softs/rh7/conda/4.5.4/envs/pangeo_full_201909/lib/python3.7/site-packages/distributed/comm/core.py", line 215, in connect
    quiet_exceptions=EnvironmentError,
tornado.util.TimeoutError: Timeout

During handling of the above exception, another exception occurred:

Traceback (most recent call last):
  File "/softs/rh7/conda/4.5.4/envs/pangeo_full_201909/lib/python3.7/site-packages/tornado/ioloop.py", line 743, in _run_callback
    ret = callback()
  File "/softs/rh7/conda/4.5.4/envs/pangeo_full_201909/lib/python3.7/site-packages/tornado/ioloop.py", line 767, in _discard_future_result
    future.result()
  File "/softs/rh7/conda/4.5.4/envs/pangeo_full_201909/lib/python3.7/site-packages/distributed/worker.py", line 875, in heartbeat
    metrics=await self.get_metrics(),
  File "/softs/rh7/conda/4.5.4/envs/pangeo_full_201909/lib/python3.7/site-packages/distributed/core.py", line 747, in send_recv_from_rpc
    comm = await self.pool.connect(self.addr)
  File "/softs/rh7/conda/4.5.4/envs/pangeo_full_201909/lib/python3.7/site-packages/distributed/core.py", line 874, in connect
    connection_args=self.connection_args,
  File "/softs/rh7/conda/4.5.4/envs/pangeo_full_201909/lib/python3.7/site-packages/distributed/comm/core.py", line 227, in connect
    _raise(error)
  File "/softs/rh7/conda/4.5.4/envs/pangeo_full_201909/lib/python3.7/site-packages/distributed/comm/core.py", line 204, in _raise
    raise IOError(msg)
OSError: Timed out trying to connect to 'tcp://10.120.40.97:33653' after 10 s: in <distributed.comm.tcp.TCPConnector object at 0x2ba002806828>: ConnectionRefusedError: [Errno 111] Connection refused
tornado.application - ERROR - Exception in callback <function Worker._register_with_scheduler.<locals>.<lambda> at 0x2ba0005ead90>
Traceback (most recent call last):
  File "/softs/rh7/conda/4.5.4/envs/pangeo_full_201909/lib/python3.7/site-packages/tornado/ioloop.py", line 907, in _run
    return self.callback()
  File "/softs/rh7/conda/4.5.4/envs/pangeo_full_201909/lib/python3.7/site-packages/distributed/worker.py", line 857, in <lambda>
    lambda: self.batched_stream.send({"op": "keep-alive"}),
  File "/softs/rh7/conda/4.5.4/envs/pangeo_full_201909/lib/python3.7/site-packages/distributed/batched.py", line 117, in send
    raise CommClosedError
distributed.comm.core.CommClosedError
tornado.application - ERROR - Exception in callback functools.partial(<bound method IOLoop._discard_future_result of <tornado.platform.asyncio.AsyncIOLoop object at 0x2b9fed87bb38>>, <Task finished coro=<Worker.heartbeat() done, defined at /softs/rh7/conda/4.5.4/envs/pangeo_full_201909/lib/python3.7/site-packages/distributed/worker.py:866> exception=OSError("Timed out trying to connect to 'tcp://10.120.40.97:33653' after 10 s: in <distributed.comm.tcp.TCPConnector object at 0x2ba002e59e48>: ConnectionRefusedError: [Errno 111] Connection refused")>)
Traceback (most recent call last):
  File "/softs/rh7/conda/4.5.4/envs/pangeo_full_201909/lib/python3.7/site-packages/distributed/comm/core.py", line 215, in connect
    quiet_exceptions=EnvironmentError,
tornado.util.TimeoutError: Timeout

During handling of the above exception, another exception occurred:

Traceback (most recent call last):
  File "/softs/rh7/conda/4.5.4/envs/pangeo_full_201909/lib/python3.7/site-packages/tornado/ioloop.py", line 743, in _run_callback
    ret = callback()
  File "/softs/rh7/conda/4.5.4/envs/pangeo_full_201909/lib/python3.7/site-packages/tornado/ioloop.py", line 767, in _discard_future_result
    future.result()
  File "/softs/rh7/conda/4.5.4/envs/pangeo_full_201909/lib/python3.7/site-packages/distributed/worker.py", line 875, in heartbeat
    metrics=await self.get_metrics(),
  File "/softs/rh7/conda/4.5.4/envs/pangeo_full_201909/lib/python3.7/site-packages/distributed/core.py", line 747, in send_recv_from_rpc
    comm = await self.pool.connect(self.addr)
  File "/softs/rh7/conda/4.5.4/envs/pangeo_full_201909/lib/python3.7/site-packages/distributed/core.py", line 874, in connect
    connection_args=self.connection_args,
  File "/softs/rh7/conda/4.5.4/envs/pangeo_full_201909/lib/python3.7/site-packages/distributed/comm/core.py", line 227, in connect
    _raise(error)
  File "/softs/rh7/conda/4.5.4/envs/pangeo_full_201909/lib/python3.7/site-packages/distributed/comm/core.py", line 204, in _raise
    raise IOError(msg)
OSError: Timed out trying to connect to 'tcp://10.120.40.97:33653' after 10 s: in <distributed.comm.tcp.TCPConnector object at 0x2ba002e59e48>: ConnectionRefusedError: [Errno 111] Connection refused
tornado.application - ERROR - Exception in callback functools.partial(<bound method IOLoop._discard_future_result of <tornado.platform.asyncio.AsyncIOLoop object at 0x2b9fed87bb38>>, <Task finished coro=<Worker.heartbeat() done, defined at /softs/rh7/conda/4.5.4/envs/pangeo_full_201909/lib/python3.7/site-packages/distributed/worker.py:866> exception=OSError("Timed out trying to connect to 'tcp://10.120.40.97:33653' after 10 s: in <distributed.comm.tcp.TCPConnector object at 0x2ba00282ce48>: ConnectionRefusedError: [Errno 111] Connection refused")>)
Traceback (most recent call last):
  File "/softs/rh7/conda/4.5.4/envs/pangeo_full_201909/lib/python3.7/site-packages/distributed/comm/core.py", line 215, in connect
    quiet_exceptions=EnvironmentError,
tornado.util.TimeoutError: Timeout

During handling of the above exception, another exception occurred:

Traceback (most recent call last):
  File "/softs/rh7/conda/4.5.4/envs/pangeo_full_201909/lib/python3.7/site-packages/tornado/ioloop.py", line 743, in _run_callback
    ret = callback()
  File "/softs/rh7/conda/4.5.4/envs/pangeo_full_201909/lib/python3.7/site-packages/tornado/ioloop.py", line 767, in _discard_future_result
    future.result()
  File "/softs/rh7/conda/4.5.4/envs/pangeo_full_201909/lib/python3.7/site-packages/distributed/worker.py", line 875, in heartbeat
    metrics=await self.get_metrics(),
  File "/softs/rh7/conda/4.5.4/envs/pangeo_full_201909/lib/python3.7/site-packages/distributed/core.py", line 747, in send_recv_from_rpc
    comm = await self.pool.connect(self.addr)
  File "/softs/rh7/conda/4.5.4/envs/pangeo_full_201909/lib/python3.7/site-packages/distributed/core.py", line 874, in connect
    connection_args=self.connection_args,
  File "/softs/rh7/conda/4.5.4/envs/pangeo_full_201909/lib/python3.7/site-packages/distributed/comm/core.py", line 227, in connect
    _raise(error)
  File "/softs/rh7/conda/4.5.4/envs/pangeo_full_201909/lib/python3.7/site-packages/distributed/comm/core.py", line 204, in _raise
    raise IOError(msg)
OSError: Timed out trying to connect to 'tcp://10.120.40.97:33653' after 10 s: in <distributed.comm.tcp.TCPConnector object at 0x2ba00282ce48>: ConnectionRefusedError: [Errno 111] Connection refused
tornado.application - ERROR - Exception in callback functools.partial(<bound method IOLoop._discard_future_result of <tornado.platform.asyncio.AsyncIOLoop object at 0x2b9fed87bb38>>, <Task finished coro=<Worker.heartbeat() done, defined at /softs/rh7/conda/4.5.4/envs/pangeo_full_201909/lib/python3.7/site-packages/distributed/worker.py:866> exception=OSError("Timed out trying to connect to 'tcp://10.120.40.97:33653' after 10 s: in <distributed.comm.tcp.TCPConnector object at 0x2ba002bbf278>: ConnectionRefusedError: [Errno 111] Connection refused")>)
Traceback (most recent call last):
  File "/softs/rh7/conda/4.5.4/envs/pangeo_full_201909/lib/python3.7/site-packages/distributed/comm/core.py", line 215, in connect
    quiet_exceptions=EnvironmentError,
tornado.util.TimeoutError: Timeout

During handling of the above exception, another exception occurred:

Traceback (most recent call last):
  File "/softs/rh7/conda/4.5.4/envs/pangeo_full_201909/lib/python3.7/site-packages/tornado/ioloop.py", line 743, in _run_callback
    ret = callback()
  File "/softs/rh7/conda/4.5.4/envs/pangeo_full_201909/lib/python3.7/site-packages/tornado/ioloop.py", line 767, in _discard_future_result
    future.result()
  File "/softs/rh7/conda/4.5.4/envs/pangeo_full_201909/lib/python3.7/site-packages/distributed/worker.py", line 875, in heartbeat
    metrics=await self.get_metrics(),
  File "/softs/rh7/conda/4.5.4/envs/pangeo_full_201909/lib/python3.7/site-packages/distributed/core.py", line 747, in send_recv_from_rpc
    comm = await self.pool.connect(self.addr)
  File "/softs/rh7/conda/4.5.4/envs/pangeo_full_201909/lib/python3.7/site-packages/distributed/core.py", line 874, in connect
    connection_args=self.connection_args,
  File "/softs/rh7/conda/4.5.4/envs/pangeo_full_201909/lib/python3.7/site-packages/distributed/comm/core.py", line 227, in connect
    _raise(error)
  File "/softs/rh7/conda/4.5.4/envs/pangeo_full_201909/lib/python3.7/site-packages/distributed/comm/core.py", line 204, in _raise
    raise IOError(msg)
OSError: Timed out trying to connect to 'tcp://10.120.40.97:33653' after 10 s: in <distributed.comm.tcp.TCPConnector object at 0x2ba002bbf278>: ConnectionRefusedError: [Errno 111] Connection refused
tornado.application - ERROR - Exception in callback functools.partial(<bound method IOLoop._discard_future_result of <tornado.platform.asyncio.AsyncIOLoop object at 0x2b9fed87bb38>>, <Task finished coro=<Worker.heartbeat() done, defined at /softs/rh7/conda/4.5.4/envs/pangeo_full_201909/lib/python3.7/site-packages/distributed/worker.py:866> exception=OSError("Timed out trying to connect to 'tcp://10.120.40.97:33653' after 10 s: in <distributed.comm.tcp.TCPConnector object at 0x2ba002bbf240>: ConnectionRefusedError: [Errno 111] Connection refused")>)
Traceback (most recent call last):
  File "/softs/rh7/conda/4.5.4/envs/pangeo_full_201909/lib/python3.7/site-packages/distributed/comm/core.py", line 215, in connect
    quiet_exceptions=EnvironmentError,
tornado.util.TimeoutError: Timeout

During handling of the above exception, another exception occurred:

Traceback (most recent call last):
  File "/softs/rh7/conda/4.5.4/envs/pangeo_full_201909/lib/python3.7/site-packages/tornado/ioloop.py", line 743, in _run_callback
    ret = callback()
  File "/softs/rh7/conda/4.5.4/envs/pangeo_full_201909/lib/python3.7/site-packages/tornado/ioloop.py", line 767, in _discard_future_result
    future.result()
  File "/softs/rh7/conda/4.5.4/envs/pangeo_full_201909/lib/python3.7/site-packages/distributed/worker.py", line 875, in heartbeat
    metrics=await self.get_metrics(),
  File "/softs/rh7/conda/4.5.4/envs/pangeo_full_201909/lib/python3.7/site-packages/distributed/core.py", line 747, in send_recv_from_rpc
    comm = await self.pool.connect(self.addr)
  File "/softs/rh7/conda/4.5.4/envs/pangeo_full_201909/lib/python3.7/site-packages/distributed/core.py", line 874, in connect
    connection_args=self.connection_args,
  File "/softs/rh7/conda/4.5.4/envs/pangeo_full_201909/lib/python3.7/site-packages/distributed/comm/core.py", line 227, in connect
    _raise(error)
  File "/softs/rh7/conda/4.5.4/envs/pangeo_full_201909/lib/python3.7/site-packages/distributed/comm/core.py", line 204, in _raise
    raise IOError(msg)
OSError: Timed out trying to connect to 'tcp://10.120.40.97:33653' after 10 s: in <distributed.comm.tcp.TCPConnector object at 0x2ba002bbf240>: ConnectionRefusedError: [Errno 111] Connection refused
tornado.application - ERROR - Exception in callback functools.partial(<bound method IOLoop._discard_future_result of <tornado.platform.asyncio.AsyncIOLoop object at 0x2b9fed87bb38>>, <Task finished coro=<Worker.heartbeat() done, defined at /softs/rh7/conda/4.5.4/envs/pangeo_full_201909/lib/python3.7/site-packages/distributed/worker.py:866> exception=OSError("Timed out trying to connect to 'tcp://10.120.40.97:33653' after 10 s: in <distributed.comm.tcp.TCPConnector object at 0x2ba0027a6748>: ConnectionRefusedError: [Errno 111] Connection refused")>)
Traceback (most recent call last):
  File "/softs/rh7/conda/4.5.4/envs/pangeo_full_201909/lib/python3.7/site-packages/distributed/comm/core.py", line 215, in connect
    quiet_exceptions=EnvironmentError,
tornado.util.TimeoutError: Timeout

During handling of the above exception, another exception occurred:

Traceback (most recent call last):
  File "/softs/rh7/conda/4.5.4/envs/pangeo_full_201909/lib/python3.7/site-packages/tornado/ioloop.py", line 743, in _run_callback
    ret = callback()
  File "/softs/rh7/conda/4.5.4/envs/pangeo_full_201909/lib/python3.7/site-packages/tornado/ioloop.py", line 767, in _discard_future_result
    future.result()
  File "/softs/rh7/conda/4.5.4/envs/pangeo_full_201909/lib/python3.7/site-packages/distributed/worker.py", line 875, in heartbeat
    metrics=await self.get_metrics(),
  File "/softs/rh7/conda/4.5.4/envs/pangeo_full_201909/lib/python3.7/site-packages/distributed/core.py", line 747, in send_recv_from_rpc
    comm = await self.pool.connect(self.addr)
  File "/softs/rh7/conda/4.5.4/envs/pangeo_full_201909/lib/python3.7/site-packages/distributed/core.py", line 874, in connect
    connection_args=self.connection_args,
  File "/softs/rh7/conda/4.5.4/envs/pangeo_full_201909/lib/python3.7/site-packages/distributed/comm/core.py", line 227, in connect
    _raise(error)
  File "/softs/rh7/conda/4.5.4/envs/pangeo_full_201909/lib/python3.7/site-packages/distributed/comm/core.py", line 204, in _raise
    raise IOError(msg)
OSError: Timed out trying to connect to 'tcp://10.120.40.97:33653' after 10 s: in <distributed.comm.tcp.TCPConnector object at 0x2ba0027a6748>: ConnectionRefusedError: [Errno 111] Connection refused
tornado.application - ERROR - Exception in callback functools.partial(<bound method IOLoop._discard_future_result of <tornado.platform.asyncio.AsyncIOLoop object at 0x2b9fed87bb38>>, <Task finished coro=<Worker.heartbeat() done, defined at /softs/rh7/conda/4.5.4/envs/pangeo_full_201909/lib/python3.7/site-packages/distributed/worker.py:866> exception=OSError("Timed out trying to connect to 'tcp://10.120.40.97:33653' after 10 s: in <distributed.comm.tcp.TCPConnector object at 0x2ba001393358>: ConnectionRefusedError: [Errno 111] Connection refused")>)
Traceback (most recent call last):
  File "/softs/rh7/conda/4.5.4/envs/pangeo_full_201909/lib/python3.7/site-packages/distributed/comm/core.py", line 215, in connect
    quiet_exceptions=EnvironmentError,
tornado.util.TimeoutError: Timeout

During handling of the above exception, another exception occurred:

Traceback (most recent call last):
  File "/softs/rh7/conda/4.5.4/envs/pangeo_full_201909/lib/python3.7/site-packages/tornado/ioloop.py", line 743, in _run_callback
    ret = callback()
  File "/softs/rh7/conda/4.5.4/envs/pangeo_full_201909/lib/python3.7/site-packages/tornado/ioloop.py", line 767, in _discard_future_result
    future.result()
  File "/softs/rh7/conda/4.5.4/envs/pangeo_full_201909/lib/python3.7/site-packages/distributed/worker.py", line 875, in heartbeat
    metrics=await self.get_metrics(),
  File "/softs/rh7/conda/4.5.4/envs/pangeo_full_201909/lib/python3.7/site-packages/distributed/core.py", line 747, in send_recv_from_rpc
    comm = await self.pool.connect(self.addr)
  File "/softs/rh7/conda/4.5.4/envs/pangeo_full_201909/lib/python3.7/site-packages/distributed/core.py", line 874, in connect
    connection_args=self.connection_args,
  File "/softs/rh7/conda/4.5.4/envs/pangeo_full_201909/lib/python3.7/site-packages/distributed/comm/core.py", line 227, in connect
    _raise(error)
  File "/softs/rh7/conda/4.5.4/envs/pangeo_full_201909/lib/python3.7/site-packages/distributed/comm/core.py", line 204, in _raise
    raise IOError(msg)
OSError: Timed out trying to connect to 'tcp://10.120.40.97:33653' after 10 s: in <distributed.comm.tcp.TCPConnector object at 0x2ba001393358>: ConnectionRefusedError: [Errno 111] Connection refused
tornado.application - ERROR - Exception in callback <function Worker._register_with_scheduler.<locals>.<lambda> at 0x2ba0005ead90>
Traceback (most recent call last):
  File "/softs/rh7/conda/4.5.4/envs/pangeo_full_201909/lib/python3.7/site-packages/tornado/ioloop.py", line 907, in _run
    return self.callback()
  File "/softs/rh7/conda/4.5.4/envs/pangeo_full_201909/lib/python3.7/site-packages/distributed/worker.py", line 857, in <lambda>
    lambda: self.batched_stream.send({"op": "keep-alive"}),
  File "/softs/rh7/conda/4.5.4/envs/pangeo_full_201909/lib/python3.7/site-packages/distributed/batched.py", line 117, in send
    raise CommClosedError
distributed.comm.core.CommClosedError
tornado.application - ERROR - Exception in callback functools.partial(<bound method IOLoop._discard_future_result of <tornado.platform.asyncio.AsyncIOLoop object at 0x2b9fed87bb38>>, <Task finished coro=<Worker.heartbeat() done, defined at /softs/rh7/conda/4.5.4/envs/pangeo_full_201909/lib/python3.7/site-packages/distributed/worker.py:866> exception=OSError("Timed out trying to connect to 'tcp://10.120.40.97:33653' after 10 s: in <distributed.comm.tcp.TCPConnector object at 0x2ba002efda20>: ConnectionRefusedError: [Errno 111] Connection refused")>)
Traceback (most recent call last):
  File "/softs/rh7/conda/4.5.4/envs/pangeo_full_201909/lib/python3.7/site-packages/distributed/comm/core.py", line 215, in connect
    quiet_exceptions=EnvironmentError,
tornado.util.TimeoutError: Timeout

During handling of the above exception, another exception occurred:

Traceback (most recent call last):
  File "/softs/rh7/conda/4.5.4/envs/pangeo_full_201909/lib/python3.7/site-packages/tornado/ioloop.py", line 743, in _run_callback
    ret = callback()
  File "/softs/rh7/conda/4.5.4/envs/pangeo_full_201909/lib/python3.7/site-packages/tornado/ioloop.py", line 767, in _discard_future_result
    future.result()
  File "/softs/rh7/conda/4.5.4/envs/pangeo_full_201909/lib/python3.7/site-packages/distributed/worker.py", line 875, in heartbeat
    metrics=await self.get_metrics(),
  File "/softs/rh7/conda/4.5.4/envs/pangeo_full_201909/lib/python3.7/site-packages/distributed/core.py", line 747, in send_recv_from_rpc
    comm = await self.pool.connect(self.addr)
  File "/softs/rh7/conda/4.5.4/envs/pangeo_full_201909/lib/python3.7/site-packages/distributed/core.py", line 874, in connect
    connection_args=self.connection_args,
  File "/softs/rh7/conda/4.5.4/envs/pangeo_full_201909/lib/python3.7/site-packages/distributed/comm/core.py", line 227, in connect
    _raise(error)
  File "/softs/rh7/conda/4.5.4/envs/pangeo_full_201909/lib/python3.7/site-packages/distributed/comm/core.py", line 204, in _raise
    raise IOError(msg)
OSError: Timed out trying to connect to 'tcp://10.120.40.97:33653' after 10 s: in <distributed.comm.tcp.TCPConnector object at 0x2ba002efda20>: ConnectionRefusedError: [Errno 111] Connection refused
tornado.application - ERROR - Exception in callback functools.partial(<bound method IOLoop._discard_future_result of <tornado.platform.asyncio.AsyncIOLoop object at 0x2b9fed87bb38>>, <Task finished coro=<Worker.heartbeat() done, defined at /softs/rh7/conda/4.5.4/envs/pangeo_full_201909/lib/python3.7/site-packages/distributed/worker.py:866> exception=OSError("Timed out trying to connect to 'tcp://10.120.40.97:33653' after 10 s: in <distributed.comm.tcp.TCPConnector object at 0x2ba0029b00b8>: ConnectionRefusedError: [Errno 111] Connection refused")>)
Traceback (most recent call last):
  File "/softs/rh7/conda/4.5.4/envs/pangeo_full_201909/lib/python3.7/site-packages/distributed/comm/core.py", line 215, in connect
    quiet_exceptions=EnvironmentError,
tornado.util.TimeoutError: Timeout

During handling of the above exception, another exception occurred:

Traceback (most recent call last):
  File "/softs/rh7/conda/4.5.4/envs/pangeo_full_201909/lib/python3.7/site-packages/tornado/ioloop.py", line 743, in _run_callback
    ret = callback()
  File "/softs/rh7/conda/4.5.4/envs/pangeo_full_201909/lib/python3.7/site-packages/tornado/ioloop.py", line 767, in _discard_future_result
    future.result()
  File "/softs/rh7/conda/4.5.4/envs/pangeo_full_201909/lib/python3.7/site-packages/distributed/worker.py", line 875, in heartbeat
    metrics=await self.get_metrics(),
  File "/softs/rh7/conda/4.5.4/envs/pangeo_full_201909/lib/python3.7/site-packages/distributed/core.py", line 747, in send_recv_from_rpc
    comm = await self.pool.connect(self.addr)
  File "/softs/rh7/conda/4.5.4/envs/pangeo_full_201909/lib/python3.7/site-packages/distributed/core.py", line 874, in connect
    connection_args=self.connection_args,
  File "/softs/rh7/conda/4.5.4/envs/pangeo_full_201909/lib/python3.7/site-packages/distributed/comm/core.py", line 227, in connect
    _raise(error)
  File "/softs/rh7/conda/4.5.4/envs/pangeo_full_201909/lib/python3.7/site-packages/distributed/comm/core.py", line 204, in _raise
    raise IOError(msg)
OSError: Timed out trying to connect to 'tcp://10.120.40.97:33653' after 10 s: in <distributed.comm.tcp.TCPConnector object at 0x2ba0029b00b8>: ConnectionRefusedError: [Errno 111] Connection refused
tornado.application - ERROR - Exception in callback functools.partial(<bound method IOLoop._discard_future_result of <tornado.platform.asyncio.AsyncIOLoop object at 0x2b9fed87bb38>>, <Task finished coro=<Worker.heartbeat() done, defined at /softs/rh7/conda/4.5.4/envs/pangeo_full_201909/lib/python3.7/site-packages/distributed/worker.py:866> exception=OSError("Timed out trying to connect to 'tcp://10.120.40.97:33653' after 10 s: in <distributed.comm.tcp.TCPConnector object at 0x2ba002bbf400>: ConnectionRefusedError: [Errno 111] Connection refused")>)
Traceback (most recent call last):
  File "/softs/rh7/conda/4.5.4/envs/pangeo_full_201909/lib/python3.7/site-packages/distributed/comm/core.py", line 215, in connect
    quiet_exceptions=EnvironmentError,
tornado.util.TimeoutError: Timeout

During handling of the above exception, another exception occurred:

Traceback (most recent call last):
  File "/softs/rh7/conda/4.5.4/envs/pangeo_full_201909/lib/python3.7/site-packages/tornado/ioloop.py", line 743, in _run_callback
    ret = callback()
  File "/softs/rh7/conda/4.5.4/envs/pangeo_full_201909/lib/python3.7/site-packages/tornado/ioloop.py", line 767, in _discard_future_result
    future.result()
  File "/softs/rh7/conda/4.5.4/envs/pangeo_full_201909/lib/python3.7/site-packages/distributed/worker.py", line 875, in heartbeat
    metrics=await self.get_metrics(),
  File "/softs/rh7/conda/4.5.4/envs/pangeo_full_201909/lib/python3.7/site-packages/distributed/core.py", line 747, in send_recv_from_rpc
    comm = await self.pool.connect(self.addr)
  File "/softs/rh7/conda/4.5.4/envs/pangeo_full_201909/lib/python3.7/site-packages/distributed/core.py", line 874, in connect
    connection_args=self.connection_args,
  File "/softs/rh7/conda/4.5.4/envs/pangeo_full_201909/lib/python3.7/site-packages/distributed/comm/core.py", line 227, in connect
    _raise(error)
  File "/softs/rh7/conda/4.5.4/envs/pangeo_full_201909/lib/python3.7/site-packages/distributed/comm/core.py", line 204, in _raise
    raise IOError(msg)
OSError: Timed out trying to connect to 'tcp://10.120.40.97:33653' after 10 s: in <distributed.comm.tcp.TCPConnector object at 0x2ba002bbf400>: ConnectionRefusedError: [Errno 111] Connection refused
tornado.application - ERROR - Exception in callback functools.partial(<bound method IOLoop._discard_future_result of <tornado.platform.asyncio.AsyncIOLoop object at 0x2b9fed87bb38>>, <Task finished coro=<Worker.heartbeat() done, defined at /softs/rh7/conda/4.5.4/envs/pangeo_full_201909/lib/python3.7/site-packages/distributed/worker.py:866> exception=OSError("Timed out trying to connect to 'tcp://10.120.40.97:33653' after 10 s: in <distributed.comm.tcp.TCPConnector object at 0x2ba0021ffa20>: ConnectionRefusedError: [Errno 111] Connection refused")>)
Traceback (most recent call last):
  File "/softs/rh7/conda/4.5.4/envs/pangeo_full_201909/lib/python3.7/site-packages/distributed/comm/core.py", line 215, in connect
    quiet_exceptions=EnvironmentError,
tornado.util.TimeoutError: Timeout

During handling of the above exception, another exception occurred:

Traceback (most recent call last):
  File "/softs/rh7/conda/4.5.4/envs/pangeo_full_201909/lib/python3.7/site-packages/tornado/ioloop.py", line 743, in _run_callback
    ret = callback()
  File "/softs/rh7/conda/4.5.4/envs/pangeo_full_201909/lib/python3.7/site-packages/tornado/ioloop.py", line 767, in _discard_future_result
    future.result()
  File "/softs/rh7/conda/4.5.4/envs/pangeo_full_201909/lib/python3.7/site-packages/distributed/worker.py", line 875, in heartbeat
    metrics=await self.get_metrics(),
  File "/softs/rh7/conda/4.5.4/envs/pangeo_full_201909/lib/python3.7/site-packages/distributed/core.py", line 747, in send_recv_from_rpc
    comm = await self.pool.connect(self.addr)
  File "/softs/rh7/conda/4.5.4/envs/pangeo_full_201909/lib/python3.7/site-packages/distributed/core.py", line 874, in connect
    connection_args=self.connection_args,
  File "/softs/rh7/conda/4.5.4/envs/pangeo_full_201909/lib/python3.7/site-packages/distributed/comm/core.py", line 227, in connect
    _raise(error)
  File "/softs/rh7/conda/4.5.4/envs/pangeo_full_201909/lib/python3.7/site-packages/distributed/comm/core.py", line 204, in _raise
    raise IOError(msg)
OSError: Timed out trying to connect to 'tcp://10.120.40.97:33653' after 10 s: in <distributed.comm.tcp.TCPConnector object at 0x2ba0021ffa20>: ConnectionRefusedError: [Errno 111] Connection refused
tornado.application - ERROR - Exception in callback functools.partial(<bound method IOLoop._discard_future_result of <tornado.platform.asyncio.AsyncIOLoop object at 0x2b9fed87bb38>>, <Task finished coro=<Worker.heartbeat() done, defined at /softs/rh7/conda/4.5.4/envs/pangeo_full_201909/lib/python3.7/site-packages/distributed/worker.py:866> exception=OSError("Timed out trying to connect to 'tcp://10.120.40.97:33653' after 10 s: in <distributed.comm.tcp.TCPConnector object at 0x2ba0029b0e80>: ConnectionRefusedError: [Errno 111] Connection refused")>)
Traceback (most recent call last):
  File "/softs/rh7/conda/4.5.4/envs/pangeo_full_201909/lib/python3.7/site-packages/distributed/comm/core.py", line 215, in connect
    quiet_exceptions=EnvironmentError,
tornado.util.TimeoutError: Timeout

During handling of the above exception, another exception occurred:

Traceback (most recent call last):
  File "/softs/rh7/conda/4.5.4/envs/pangeo_full_201909/lib/python3.7/site-packages/tornado/ioloop.py", line 743, in _run_callback
    ret = callback()
  File "/softs/rh7/conda/4.5.4/envs/pangeo_full_201909/lib/python3.7/site-packages/tornado/ioloop.py", line 767, in _discard_future_result
    future.result()
  File "/softs/rh7/conda/4.5.4/envs/pangeo_full_201909/lib/python3.7/site-packages/distributed/worker.py", line 875, in heartbeat
    metrics=await self.get_metrics(),
  File "/softs/rh7/conda/4.5.4/envs/pangeo_full_201909/lib/python3.7/site-packages/distributed/core.py", line 747, in send_recv_from_rpc
    comm = await self.pool.connect(self.addr)
  File "/softs/rh7/conda/4.5.4/envs/pangeo_full_201909/lib/python3.7/site-packages/distributed/core.py", line 874, in connect
    connection_args=self.connection_args,
  File "/softs/rh7/conda/4.5.4/envs/pangeo_full_201909/lib/python3.7/site-packages/distributed/comm/core.py", line 227, in connect
    _raise(error)
  File "/softs/rh7/conda/4.5.4/envs/pangeo_full_201909/lib/python3.7/site-packages/distributed/comm/core.py", line 204, in _raise
    raise IOError(msg)
OSError: Timed out trying to connect to 'tcp://10.120.40.97:33653' after 10 s: in <distributed.comm.tcp.TCPConnector object at 0x2ba0029b0e80>: ConnectionRefusedError: [Errno 111] Connection refused
tornado.application - ERROR - Exception in callback <function Worker._register_with_scheduler.<locals>.<lambda> at 0x2ba0005ead90>
Traceback (most recent call last):
  File "/softs/rh7/conda/4.5.4/envs/pangeo_full_201909/lib/python3.7/site-packages/tornado/ioloop.py", line 907, in _run
    return self.callback()
  File "/softs/rh7/conda/4.5.4/envs/pangeo_full_201909/lib/python3.7/site-packages/distributed/worker.py", line 857, in <lambda>
    lambda: self.batched_stream.send({"op": "keep-alive"}),
  File "/softs/rh7/conda/4.5.4/envs/pangeo_full_201909/lib/python3.7/site-packages/distributed/batched.py", line 117, in send
    raise CommClosedError
distributed.comm.core.CommClosedError
tornado.application - ERROR - Exception in callback functools.partial(<bound method IOLoop._discard_future_result of <tornado.platform.asyncio.AsyncIOLoop object at 0x2b9fed87bb38>>, <Task finished coro=<Worker.heartbeat() done, defined at /softs/rh7/conda/4.5.4/envs/pangeo_full_201909/lib/python3.7/site-packages/distributed/worker.py:866> exception=OSError("Timed out trying to connect to 'tcp://10.120.40.97:33653' after 10 s: in <distributed.comm.tcp.TCPConnector object at 0x2ba0033ffb00>: ConnectionRefusedError: [Errno 111] Connection refused")>)
Traceback (most recent call last):
  File "/softs/rh7/conda/4.5.4/envs/pangeo_full_201909/lib/python3.7/site-packages/distributed/comm/core.py", line 215, in connect
    quiet_exceptions=EnvironmentError,
tornado.util.TimeoutError: Timeout

During handling of the above exception, another exception occurred:

Traceback (most recent call last):
  File "/softs/rh7/conda/4.5.4/envs/pangeo_full_201909/lib/python3.7/site-packages/tornado/ioloop.py", line 743, in _run_callback
    ret = callback()
  File "/softs/rh7/conda/4.5.4/envs/pangeo_full_201909/lib/python3.7/site-packages/tornado/ioloop.py", line 767, in _discard_future_result
    future.result()
  File "/softs/rh7/conda/4.5.4/envs/pangeo_full_201909/lib/python3.7/site-packages/distributed/worker.py", line 875, in heartbeat
    metrics=await self.get_metrics(),
  File "/softs/rh7/conda/4.5.4/envs/pangeo_full_201909/lib/python3.7/site-packages/distributed/core.py", line 747, in send_recv_from_rpc
    comm = await self.pool.connect(self.addr)
  File "/softs/rh7/conda/4.5.4/envs/pangeo_full_201909/lib/python3.7/site-packages/distributed/core.py", line 874, in connect
    connection_args=self.connection_args,
  File "/softs/rh7/conda/4.5.4/envs/pangeo_full_201909/lib/python3.7/site-packages/distributed/comm/core.py", line 227, in connect
    _raise(error)
  File "/softs/rh7/conda/4.5.4/envs/pangeo_full_201909/lib/python3.7/site-packages/distributed/comm/core.py", line 204, in _raise
    raise IOError(msg)
OSError: Timed out trying to connect to 'tcp://10.120.40.97:33653' after 10 s: in <distributed.comm.tcp.TCPConnector object at 0x2ba0033ffb00>: ConnectionRefusedError: [Errno 111] Connection refused
tornado.application - ERROR - Exception in callback functools.partial(<bound method IOLoop._discard_future_result of <tornado.platform.asyncio.AsyncIOLoop object at 0x2b9fed87bb38>>, <Task finished coro=<Worker.heartbeat() done, defined at /softs/rh7/conda/4.5.4/envs/pangeo_full_201909/lib/python3.7/site-packages/distributed/worker.py:866> exception=OSError("Timed out trying to connect to 'tcp://10.120.40.97:33653' after 10 s: in <distributed.comm.tcp.TCPConnector object at 0x2ba002f32f98>: ConnectionRefusedError: [Errno 111] Connection refused")>)
Traceback (most recent call last):
  File "/softs/rh7/conda/4.5.4/envs/pangeo_full_201909/lib/python3.7/site-packages/distributed/comm/tcp.py", line 356, in connect
    ip, port, max_buffer_size=MAX_BUFFER_SIZE, **kwargs
  File "/softs/rh7/conda/4.5.4/envs/pangeo_full_201909/lib/python3.7/site-packages/tornado/tcpclient.py", line 280, in connect
    af, addr, stream = await connector.start(connect_timeout=timeout)
  File "/softs/rh7/conda/4.5.4/envs/pangeo_full_201909/lib/python3.7/site-packages/tornado/tcpclient.py", line 143, in on_connect_done
    stream = future.result()
tornado.iostream.StreamClosedError: Stream is closed

During handling of the above exception, another exception occurred:

Traceback (most recent call last):
  File "/softs/rh7/conda/4.5.4/envs/pangeo_full_201909/lib/python3.7/site-packages/distributed/comm/core.py", line 215, in connect
    quiet_exceptions=EnvironmentError,
  File "/softs/rh7/conda/4.5.4/envs/pangeo_full_201909/lib/python3.7/site-packages/distributed/comm/tcp.py", line 368, in connect
    convert_stream_closed_error(self, e)
  File "/softs/rh7/conda/4.5.4/envs/pangeo_full_201909/lib/python3.7/site-packages/distributed/comm/tcp.py", line 138, in convert_stream_closed_error
    raise CommClosedError("in %s: %s: %s" % (obj, exc.__class__.__name__, exc))
distributed.comm.core.CommClosedError: in <distributed.comm.tcp.TCPConnector object at 0x2ba002f32f98>: ConnectionRefusedError: [Errno 111] Connection refused

During handling of the above exception, another exception occurred:

Traceback (most recent call last):
  File "/softs/rh7/conda/4.5.4/envs/pangeo_full_201909/lib/python3.7/site-packages/tornado/ioloop.py", line 743, in _run_callback
    ret = callback()
  File "/softs/rh7/conda/4.5.4/envs/pangeo_full_201909/lib/python3.7/site-packages/tornado/ioloop.py", line 767, in _discard_future_result
    future.result()
  File "/softs/rh7/conda/4.5.4/envs/pangeo_full_201909/lib/python3.7/site-packages/distributed/worker.py", line 875, in heartbeat
    metrics=await self.get_metrics(),
  File "/softs/rh7/conda/4.5.4/envs/pangeo_full_201909/lib/python3.7/site-packages/distributed/core.py", line 747, in send_recv_from_rpc
    comm = await self.pool.connect(self.addr)
  File "/softs/rh7/conda/4.5.4/envs/pangeo_full_201909/lib/python3.7/site-packages/distributed/core.py", line 874, in connect
    connection_args=self.connection_args,
  File "/softs/rh7/conda/4.5.4/envs/pangeo_full_201909/lib/python3.7/site-packages/distributed/comm/core.py", line 225, in connect
    _raise(error)
  File "/softs/rh7/conda/4.5.4/envs/pangeo_full_201909/lib/python3.7/site-packages/distributed/comm/core.py", line 204, in _raise
    raise IOError(msg)
OSError: Timed out trying to connect to 'tcp://10.120.40.97:33653' after 10 s: in <distributed.comm.tcp.TCPConnector object at 0x2ba002f32f98>: ConnectionRefusedError: [Errno 111] Connection refused
tornado.application - ERROR - Exception in callback functools.partial(<bound method IOLoop._discard_future_result of <tornado.platform.asyncio.AsyncIOLoop object at 0x2b9fed87bb38>>, <Task finished coro=<Worker.heartbeat() done, defined at /softs/rh7/conda/4.5.4/envs/pangeo_full_201909/lib/python3.7/site-packages/distributed/worker.py:866> exception=OSError("Timed out trying to connect to 'tcp://10.120.40.97:33653' after 10 s: in <distributed.comm.tcp.TCPConnector object at 0x2ba002f326d8>: ConnectionRefusedError: [Errno 111] Connection refused")>)
Traceback (most recent call last):
  File "/softs/rh7/conda/4.5.4/envs/pangeo_full_201909/lib/python3.7/site-packages/distributed/comm/core.py", line 215, in connect
    quiet_exceptions=EnvironmentError,
tornado.util.TimeoutError: Timeout

During handling of the above exception, another exception occurred:

Traceback (most recent call last):
  File "/softs/rh7/conda/4.5.4/envs/pangeo_full_201909/lib/python3.7/site-packages/tornado/ioloop.py", line 743, in _run_callback
    ret = callback()
  File "/softs/rh7/conda/4.5.4/envs/pangeo_full_201909/lib/python3.7/site-packages/tornado/ioloop.py", line 767, in _discard_future_result
    future.result()
  File "/softs/rh7/conda/4.5.4/envs/pangeo_full_201909/lib/python3.7/site-packages/distributed/worker.py", line 875, in heartbeat
    metrics=await self.get_metrics(),
  File "/softs/rh7/conda/4.5.4/envs/pangeo_full_201909/lib/python3.7/site-packages/distributed/core.py", line 747, in send_recv_from_rpc
    comm = await self.pool.connect(self.addr)
  File "/softs/rh7/conda/4.5.4/envs/pangeo_full_201909/lib/python3.7/site-packages/distributed/core.py", line 874, in connect
    connection_args=self.connection_args,
  File "/softs/rh7/conda/4.5.4/envs/pangeo_full_201909/lib/python3.7/site-packages/distributed/comm/core.py", line 227, in connect
    _raise(error)
  File "/softs/rh7/conda/4.5.4/envs/pangeo_full_201909/lib/python3.7/site-packages/distributed/comm/core.py", line 204, in _raise
    raise IOError(msg)
OSError: Timed out trying to connect to 'tcp://10.120.40.97:33653' after 10 s: in <distributed.comm.tcp.TCPConnector object at 0x2ba002f326d8>: ConnectionRefusedError: [Errno 111] Connection refused
tornado.application - ERROR - Exception in callback functools.partial(<bound method IOLoop._discard_future_result of <tornado.platform.asyncio.AsyncIOLoop object at 0x2b9fed87bb38>>, <Task finished coro=<Worker.heartbeat() done, defined at /softs/rh7/conda/4.5.4/envs/pangeo_full_201909/lib/python3.7/site-packages/distributed/worker.py:866> exception=OSError("Timed out trying to connect to 'tcp://10.120.40.97:33653' after 10 s: in <distributed.comm.tcp.TCPConnector object at 0x2ba002efd2e8>: ConnectionRefusedError: [Errno 111] Connection refused")>)
Traceback (most recent call last):
  File "/softs/rh7/conda/4.5.4/envs/pangeo_full_201909/lib/python3.7/site-packages/distributed/comm/core.py", line 215, in connect
    quiet_exceptions=EnvironmentError,
tornado.util.TimeoutError: Timeout

During handling of the above exception, another exception occurred:

Traceback (most recent call last):
  File "/softs/rh7/conda/4.5.4/envs/pangeo_full_201909/lib/python3.7/site-packages/tornado/ioloop.py", line 743, in _run_callback
    ret = callback()
  File "/softs/rh7/conda/4.5.4/envs/pangeo_full_201909/lib/python3.7/site-packages/tornado/ioloop.py", line 767, in _discard_future_result
    future.result()
  File "/softs/rh7/conda/4.5.4/envs/pangeo_full_201909/lib/python3.7/site-packages/distributed/worker.py", line 875, in heartbeat
    metrics=await self.get_metrics(),
  File "/softs/rh7/conda/4.5.4/envs/pangeo_full_201909/lib/python3.7/site-packages/distributed/core.py", line 747, in send_recv_from_rpc
    comm = await self.pool.connect(self.addr)
  File "/softs/rh7/conda/4.5.4/envs/pangeo_full_201909/lib/python3.7/site-packages/distributed/core.py", line 874, in connect
    connection_args=self.connection_args,
  File "/softs/rh7/conda/4.5.4/envs/pangeo_full_201909/lib/python3.7/site-packages/distributed/comm/core.py", line 227, in connect
    _raise(error)
  File "/softs/rh7/conda/4.5.4/envs/pangeo_full_201909/lib/python3.7/site-packages/distributed/comm/core.py", line 204, in _raise
    raise IOError(msg)
OSError: Timed out trying to connect to 'tcp://10.120.40.97:33653' after 10 s: in <distributed.comm.tcp.TCPConnector object at 0x2ba002efd2e8>: ConnectionRefusedError: [Errno 111] Connection refused
tornado.application - ERROR - Exception in callback functools.partial(<bound method IOLoop._discard_future_result of <tornado.platform.asyncio.AsyncIOLoop object at 0x2b9fed87bb38>>, <Task finished coro=<Worker.heartbeat() done, defined at /softs/rh7/conda/4.5.4/envs/pangeo_full_201909/lib/python3.7/site-packages/distributed/worker.py:866> exception=OSError("Timed out trying to connect to 'tcp://10.120.40.97:33653' after 10 s: in <distributed.comm.tcp.TCPConnector object at 0x2ba0027a6a58>: ConnectionRefusedError: [Errno 111] Connection refused")>)
Traceback (most recent call last):
  File "/softs/rh7/conda/4.5.4/envs/pangeo_full_201909/lib/python3.7/site-packages/distributed/comm/core.py", line 215, in connect
    quiet_exceptions=EnvironmentError,
tornado.util.TimeoutError: Timeout

During handling of the above exception, another exception occurred:

Traceback (most recent call last):
  File "/softs/rh7/conda/4.5.4/envs/pangeo_full_201909/lib/python3.7/site-packages/tornado/ioloop.py", line 743, in _run_callback
    ret = callback()
  File "/softs/rh7/conda/4.5.4/envs/pangeo_full_201909/lib/python3.7/site-packages/tornado/ioloop.py", line 767, in _discard_future_result
    future.result()
  File "/softs/rh7/conda/4.5.4/envs/pangeo_full_201909/lib/python3.7/site-packages/distributed/worker.py", line 875, in heartbeat
    metrics=await self.get_metrics(),
  File "/softs/rh7/conda/4.5.4/envs/pangeo_full_201909/lib/python3.7/site-packages/distributed/core.py", line 747, in send_recv_from_rpc
    comm = await self.pool.connect(self.addr)
  File "/softs/rh7/conda/4.5.4/envs/pangeo_full_201909/lib/python3.7/site-packages/distributed/core.py", line 874, in connect
    connection_args=self.connection_args,
  File "/softs/rh7/conda/4.5.4/envs/pangeo_full_201909/lib/python3.7/site-packages/distributed/comm/core.py", line 227, in connect
    _raise(error)
  File "/softs/rh7/conda/4.5.4/envs/pangeo_full_201909/lib/python3.7/site-packages/distributed/comm/core.py", line 204, in _raise
    raise IOError(msg)
OSError: Timed out trying to connect to 'tcp://10.120.40.97:33653' after 10 s: in <distributed.comm.tcp.TCPConnector object at 0x2ba0027a6a58>: ConnectionRefusedError: [Errno 111] Connection refused
tornado.application - ERROR - Exception in callback <function Worker._register_with_scheduler.<locals>.<lambda> at 0x2ba0005ead90>
Traceback (most recent call last):
  File "/softs/rh7/conda/4.5.4/envs/pangeo_full_201909/lib/python3.7/site-packages/tornado/ioloop.py", line 907, in _run
    return self.callback()
  File "/softs/rh7/conda/4.5.4/envs/pangeo_full_201909/lib/python3.7/site-packages/distributed/worker.py", line 857, in <lambda>
    lambda: self.batched_stream.send({"op": "keep-alive"}),
  File "/softs/rh7/conda/4.5.4/envs/pangeo_full_201909/lib/python3.7/site-packages/distributed/batched.py", line 117, in send
    raise CommClosedError
distributed.comm.core.CommClosedError
tornado.application - ERROR - Exception in callback functools.partial(<bound method IOLoop._discard_future_result of <tornado.platform.asyncio.AsyncIOLoop object at 0x2b9fed87bb38>>, <Task finished coro=<Worker.heartbeat() done, defined at /softs/rh7/conda/4.5.4/envs/pangeo_full_201909/lib/python3.7/site-packages/distributed/worker.py:866> exception=OSError("Timed out trying to connect to 'tcp://10.120.40.97:33653' after 10 s: in <distributed.comm.tcp.TCPConnector object at 0x2ba002efdeb8>: ConnectionRefusedError: [Errno 111] Connection refused")>)
Traceback (most recent call last):
  File "/softs/rh7/conda/4.5.4/envs/pangeo_full_201909/lib/python3.7/site-packages/distributed/comm/core.py", line 215, in connect
    quiet_exceptions=EnvironmentError,
tornado.util.TimeoutError: Timeout

During handling of the above exception, another exception occurred:

Traceback (most recent call last):
  File "/softs/rh7/conda/4.5.4/envs/pangeo_full_201909/lib/python3.7/site-packages/tornado/ioloop.py", line 743, in _run_callback
    ret = callback()
  File "/softs/rh7/conda/4.5.4/envs/pangeo_full_201909/lib/python3.7/site-packages/tornado/ioloop.py", line 767, in _discard_future_result
    future.result()
  File "/softs/rh7/conda/4.5.4/envs/pangeo_full_201909/lib/python3.7/site-packages/distributed/worker.py", line 875, in heartbeat
    metrics=await self.get_metrics(),
  File "/softs/rh7/conda/4.5.4/envs/pangeo_full_201909/lib/python3.7/site-packages/distributed/core.py", line 747, in send_recv_from_rpc
    comm = await self.pool.connect(self.addr)
  File "/softs/rh7/conda/4.5.4/envs/pangeo_full_201909/lib/python3.7/site-packages/distributed/core.py", line 874, in connect
    connection_args=self.connection_args,
  File "/softs/rh7/conda/4.5.4/envs/pangeo_full_201909/lib/python3.7/site-packages/distributed/comm/core.py", line 227, in connect
    _raise(error)
  File "/softs/rh7/conda/4.5.4/envs/pangeo_full_201909/lib/python3.7/site-packages/distributed/comm/core.py", line 204, in _raise
    raise IOError(msg)
OSError: Timed out trying to connect to 'tcp://10.120.40.97:33653' after 10 s: in <distributed.comm.tcp.TCPConnector object at 0x2ba002efdeb8>: ConnectionRefusedError: [Errno 111] Connection refused
tornado.application - ERROR - Exception in callback functools.partial(<bound method IOLoop._discard_future_result of <tornado.platform.asyncio.AsyncIOLoop object at 0x2b9fed87bb38>>, <Task finished coro=<Worker.heartbeat() done, defined at /softs/rh7/conda/4.5.4/envs/pangeo_full_201909/lib/python3.7/site-packages/distributed/worker.py:866> exception=OSError("Timed out trying to connect to 'tcp://10.120.40.97:33653' after 10 s: in <distributed.comm.tcp.TCPConnector object at 0x2ba0033ff048>: ConnectionRefusedError: [Errno 111] Connection refused")>)
Traceback (most recent call last):
  File "/softs/rh7/conda/4.5.4/envs/pangeo_full_201909/lib/python3.7/site-packages/distributed/comm/core.py", line 215, in connect
    quiet_exceptions=EnvironmentError,
tornado.util.TimeoutError: Timeout

During handling of the above exception, another exception occurred:

Traceback (most recent call last):
  File "/softs/rh7/conda/4.5.4/envs/pangeo_full_201909/lib/python3.7/site-packages/tornado/ioloop.py", line 743, in _run_callback
    ret = callback()
  File "/softs/rh7/conda/4.5.4/envs/pangeo_full_201909/lib/python3.7/site-packages/tornado/ioloop.py", line 767, in _discard_future_result
    future.result()
  File "/softs/rh7/conda/4.5.4/envs/pangeo_full_201909/lib/python3.7/site-packages/distributed/worker.py", line 875, in heartbeat
    metrics=await self.get_metrics(),
  File "/softs/rh7/conda/4.5.4/envs/pangeo_full_201909/lib/python3.7/site-packages/distributed/core.py", line 747, in send_recv_from_rpc
    comm = await self.pool.connect(self.addr)
  File "/softs/rh7/conda/4.5.4/envs/pangeo_full_201909/lib/python3.7/site-packages/distributed/core.py", line 874, in connect
    connection_args=self.connection_args,
  File "/softs/rh7/conda/4.5.4/envs/pangeo_full_201909/lib/python3.7/site-packages/distributed/comm/core.py", line 227, in connect
    _raise(error)
  File "/softs/rh7/conda/4.5.4/envs/pangeo_full_201909/lib/python3.7/site-packages/distributed/comm/core.py", line 204, in _raise
    raise IOError(msg)
OSError: Timed out trying to connect to 'tcp://10.120.40.97:33653' after 10 s: in <distributed.comm.tcp.TCPConnector object at 0x2ba0033ff048>: ConnectionRefusedError: [Errno 111] Connection refused
tornado.application - ERROR - Exception in callback functools.partial(<bound method IOLoop._discard_future_result of <tornado.platform.asyncio.AsyncIOLoop object at 0x2b9fed87bb38>>, <Task finished coro=<Worker.heartbeat() done, defined at /softs/rh7/conda/4.5.4/envs/pangeo_full_201909/lib/python3.7/site-packages/distributed/worker.py:866> exception=OSError("Timed out trying to connect to 'tcp://10.120.40.97:33653' after 10 s: in <distributed.comm.tcp.TCPConnector object at 0x2ba0005845c0>: ConnectionRefusedError: [Errno 111] Connection refused")>)
Traceback (most recent call last):
  File "/softs/rh7/conda/4.5.4/envs/pangeo_full_201909/lib/python3.7/site-packages/distributed/comm/core.py", line 215, in connect
    quiet_exceptions=EnvironmentError,
tornado.util.TimeoutError: Timeout

During handling of the above exception, another exception occurred:

Traceback (most recent call last):
  File "/softs/rh7/conda/4.5.4/envs/pangeo_full_201909/lib/python3.7/site-packages/tornado/ioloop.py", line 743, in _run_callback
    ret = callback()
  File "/softs/rh7/conda/4.5.4/envs/pangeo_full_201909/lib/python3.7/site-packages/tornado/ioloop.py", line 767, in _discard_future_result
    future.result()
  File "/softs/rh7/conda/4.5.4/envs/pangeo_full_201909/lib/python3.7/site-packages/distributed/worker.py", line 875, in heartbeat
    metrics=await self.get_metrics(),
  File "/softs/rh7/conda/4.5.4/envs/pangeo_full_201909/lib/python3.7/site-packages/distributed/core.py", line 747, in send_recv_from_rpc
    comm = await self.pool.connect(self.addr)
  File "/softs/rh7/conda/4.5.4/envs/pangeo_full_201909/lib/python3.7/site-packages/distributed/core.py", line 874, in connect
    connection_args=self.connection_args,
  File "/softs/rh7/conda/4.5.4/envs/pangeo_full_201909/lib/python3.7/site-packages/distributed/comm/core.py", line 227, in connect
    _raise(error)
  File "/softs/rh7/conda/4.5.4/envs/pangeo_full_201909/lib/python3.7/site-packages/distributed/comm/core.py", line 204, in _raise
    raise IOError(msg)
OSError: Timed out trying to connect to 'tcp://10.120.40.97:33653' after 10 s: in <distributed.comm.tcp.TCPConnector object at 0x2ba0005845c0>: ConnectionRefusedError: [Errno 111] Connection refused
tornado.application - ERROR - Exception in callback functools.partial(<bound method IOLoop._discard_future_result of <tornado.platform.asyncio.AsyncIOLoop object at 0x2b9fed87bb38>>, <Task finished coro=<Worker.heartbeat() done, defined at /softs/rh7/conda/4.5.4/envs/pangeo_full_201909/lib/python3.7/site-packages/distributed/worker.py:866> exception=OSError("Timed out trying to connect to 'tcp://10.120.40.97:33653' after 10 s: in <distributed.comm.tcp.TCPConnector object at 0x2ba00220a8d0>: ConnectionRefusedError: [Errno 111] Connection refused")>)
Traceback (most recent call last):
  File "/softs/rh7/conda/4.5.4/envs/pangeo_full_201909/lib/python3.7/site-packages/distributed/comm/core.py", line 215, in connect
    quiet_exceptions=EnvironmentError,
tornado.util.TimeoutError: Timeout

During handling of the above exception, another exception occurred:

Traceback (most recent call last):
  File "/softs/rh7/conda/4.5.4/envs/pangeo_full_201909/lib/python3.7/site-packages/tornado/ioloop.py", line 743, in _run_callback
    ret = callback()
  File "/softs/rh7/conda/4.5.4/envs/pangeo_full_201909/lib/python3.7/site-packages/tornado/ioloop.py", line 767, in _discard_future_result
    future.result()
  File "/softs/rh7/conda/4.5.4/envs/pangeo_full_201909/lib/python3.7/site-packages/distributed/worker.py", line 875, in heartbeat
    metrics=await self.get_metrics(),
  File "/softs/rh7/conda/4.5.4/envs/pangeo_full_201909/lib/python3.7/site-packages/distributed/core.py", line 747, in send_recv_from_rpc
    comm = await self.pool.connect(self.addr)
  File "/softs/rh7/conda/4.5.4/envs/pangeo_full_201909/lib/python3.7/site-packages/distributed/core.py", line 874, in connect
    connection_args=self.connection_args,
  File "/softs/rh7/conda/4.5.4/envs/pangeo_full_201909/lib/python3.7/site-packages/distributed/comm/core.py", line 227, in connect
    _raise(error)
  File "/softs/rh7/conda/4.5.4/envs/pangeo_full_201909/lib/python3.7/site-packages/distributed/comm/core.py", line 204, in _raise
    raise IOError(msg)
OSError: Timed out trying to connect to 'tcp://10.120.40.97:33653' after 10 s: in <distributed.comm.tcp.TCPConnector object at 0x2ba00220a8d0>: ConnectionRefusedError: [Errno 111] Connection refused
tornado.application - ERROR - Exception in callback functools.partial(<bound method IOLoop._discard_future_result of <tornado.platform.asyncio.AsyncIOLoop object at 0x2b9fed87bb38>>, <Task finished coro=<Worker.heartbeat() done, defined at /softs/rh7/conda/4.5.4/envs/pangeo_full_201909/lib/python3.7/site-packages/distributed/worker.py:866> exception=OSError("Timed out trying to connect to 'tcp://10.120.40.97:33653' after 10 s: in <distributed.comm.tcp.TCPConnector object at 0x2ba0033ff5c0>: ConnectionRefusedError: [Errno 111] Connection refused")>)
Traceback (most recent call last):
  File "/softs/rh7/conda/4.5.4/envs/pangeo_full_201909/lib/python3.7/site-packages/distributed/comm/core.py", line 215, in connect
    quiet_exceptions=EnvironmentError,
tornado.util.TimeoutError: Timeout

During handling of the above exception, another exception occurred:

Traceback (most recent call last):
  File "/softs/rh7/conda/4.5.4/envs/pangeo_full_201909/lib/python3.7/site-packages/tornado/ioloop.py", line 743, in _run_callback
    ret = callback()
  File "/softs/rh7/conda/4.5.4/envs/pangeo_full_201909/lib/python3.7/site-packages/tornado/ioloop.py", line 767, in _discard_future_result
    future.result()
  File "/softs/rh7/conda/4.5.4/envs/pangeo_full_201909/lib/python3.7/site-packages/distributed/worker.py", line 875, in heartbeat
    metrics=await self.get_metrics(),
  File "/softs/rh7/conda/4.5.4/envs/pangeo_full_201909/lib/python3.7/site-packages/distributed/core.py", line 747, in send_recv_from_rpc
    comm = await self.pool.connect(self.addr)
  File "/softs/rh7/conda/4.5.4/envs/pangeo_full_201909/lib/python3.7/site-packages/distributed/core.py", line 874, in connect
    connection_args=self.connection_args,
  File "/softs/rh7/conda/4.5.4/envs/pangeo_full_201909/lib/python3.7/site-packages/distributed/comm/core.py", line 227, in connect
    _raise(error)
  File "/softs/rh7/conda/4.5.4/envs/pangeo_full_201909/lib/python3.7/site-packages/distributed/comm/core.py", line 204, in _raise
    raise IOError(msg)
OSError: Timed out trying to connect to 'tcp://10.120.40.97:33653' after 10 s: in <distributed.comm.tcp.TCPConnector object at 0x2ba0033ff5c0>: ConnectionRefusedError: [Errno 111] Connection refused
tornado.application - ERROR - Exception in callback functools.partial(<bound method IOLoop._discard_future_result of <tornado.platform.asyncio.AsyncIOLoop object at 0x2b9fed87bb38>>, <Task finished coro=<Worker.heartbeat() done, defined at /softs/rh7/conda/4.5.4/envs/pangeo_full_201909/lib/python3.7/site-packages/distributed/worker.py:866> exception=OSError("Timed out trying to connect to 'tcp://10.120.40.97:33653' after 10 s: in <distributed.comm.tcp.TCPConnector object at 0x2ba00220aba8>: ConnectionRefusedError: [Errno 111] Connection refused")>)
Traceback (most recent call last):
  File "/softs/rh7/conda/4.5.4/envs/pangeo_full_201909/lib/python3.7/site-packages/distributed/comm/core.py", line 215, in connect
    quiet_exceptions=EnvironmentError,
tornado.util.TimeoutError: Timeout

During handling of the above exception, another exception occurred:

Traceback (most recent call last):
  File "/softs/rh7/conda/4.5.4/envs/pangeo_full_201909/lib/python3.7/site-packages/tornado/ioloop.py", line 743, in _run_callback
    ret = callback()
  File "/softs/rh7/conda/4.5.4/envs/pangeo_full_201909/lib/python3.7/site-packages/tornado/ioloop.py", line 767, in _discard_future_result
    future.result()
  File "/softs/rh7/conda/4.5.4/envs/pangeo_full_201909/lib/python3.7/site-packages/distributed/worker.py", line 875, in heartbeat
    metrics=await self.get_metrics(),
  File "/softs/rh7/conda/4.5.4/envs/pangeo_full_201909/lib/python3.7/site-packages/distributed/core.py", line 747, in send_recv_from_rpc
    comm = await self.pool.connect(self.addr)
  File "/softs/rh7/conda/4.5.4/envs/pangeo_full_201909/lib/python3.7/site-packages/distributed/core.py", line 874, in connect
    connection_args=self.connection_args,
  File "/softs/rh7/conda/4.5.4/envs/pangeo_full_201909/lib/python3.7/site-packages/distributed/comm/core.py", line 227, in connect
    _raise(error)
  File "/softs/rh7/conda/4.5.4/envs/pangeo_full_201909/lib/python3.7/site-packages/distributed/comm/core.py", line 204, in _raise
    raise IOError(msg)
OSError: Timed out trying to connect to 'tcp://10.120.40.97:33653' after 10 s: in <distributed.comm.tcp.TCPConnector object at 0x2ba00220aba8>: ConnectionRefusedError: [Errno 111] Connection refused
tornado.application - ERROR - Exception in callback <function Worker._register_with_scheduler.<locals>.<lambda> at 0x2ba0005ead90>
Traceback (most recent call last):
  File "/softs/rh7/conda/4.5.4/envs/pangeo_full_201909/lib/python3.7/site-packages/tornado/ioloop.py", line 907, in _run
    return self.callback()
  File "/softs/rh7/conda/4.5.4/envs/pangeo_full_201909/lib/python3.7/site-packages/distributed/worker.py", line 857, in <lambda>
    lambda: self.batched_stream.send({"op": "keep-alive"}),
  File "/softs/rh7/conda/4.5.4/envs/pangeo_full_201909/lib/python3.7/site-packages/distributed/batched.py", line 117, in send
    raise CommClosedError
distributed.comm.core.CommClosedError
tornado.application - ERROR - Exception in callback functools.partial(<bound method IOLoop._discard_future_result of <tornado.platform.asyncio.AsyncIOLoop object at 0x2b9fed87bb38>>, <Task finished coro=<Worker.heartbeat() done, defined at /softs/rh7/conda/4.5.4/envs/pangeo_full_201909/lib/python3.7/site-packages/distributed/worker.py:866> exception=OSError("Timed out trying to connect to 'tcp://10.120.40.97:33653' after 10 s: in <distributed.comm.tcp.TCPConnector object at 0x2ba0033ff400>: ConnectionRefusedError: [Errno 111] Connection refused")>)
Traceback (most recent call last):
  File "/softs/rh7/conda/4.5.4/envs/pangeo_full_201909/lib/python3.7/site-packages/distributed/comm/core.py", line 215, in connect
    quiet_exceptions=EnvironmentError,
tornado.util.TimeoutError: Timeout

During handling of the above exception, another exception occurred:

Traceback (most recent call last):
  File "/softs/rh7/conda/4.5.4/envs/pangeo_full_201909/lib/python3.7/site-packages/tornado/ioloop.py", line 743, in _run_callback
    ret = callback()
  File "/softs/rh7/conda/4.5.4/envs/pangeo_full_201909/lib/python3.7/site-packages/tornado/ioloop.py", line 767, in _discard_future_result
    future.result()
  File "/softs/rh7/conda/4.5.4/envs/pangeo_full_201909/lib/python3.7/site-packages/distributed/worker.py", line 875, in heartbeat
    metrics=await self.get_metrics(),
  File "/softs/rh7/conda/4.5.4/envs/pangeo_full_201909/lib/python3.7/site-packages/distributed/core.py", line 747, in send_recv_from_rpc
    comm = await self.pool.connect(self.addr)
  File "/softs/rh7/conda/4.5.4/envs/pangeo_full_201909/lib/python3.7/site-packages/distributed/core.py", line 874, in connect
    connection_args=self.connection_args,
  File "/softs/rh7/conda/4.5.4/envs/pangeo_full_201909/lib/python3.7/site-packages/distributed/comm/core.py", line 227, in connect
    _raise(error)
  File "/softs/rh7/conda/4.5.4/envs/pangeo_full_201909/lib/python3.7/site-packages/distributed/comm/core.py", line 204, in _raise
    raise IOError(msg)
OSError: Timed out trying to connect to 'tcp://10.120.40.97:33653' after 10 s: in <distributed.comm.tcp.TCPConnector object at 0x2ba0033ff400>: ConnectionRefusedError: [Errno 111] Connection refused
tornado.application - ERROR - Exception in callback functools.partial(<bound method IOLoop._discard_future_result of <tornado.platform.asyncio.AsyncIOLoop object at 0x2b9fed87bb38>>, <Task finished coro=<Worker.heartbeat() done, defined at /softs/rh7/conda/4.5.4/envs/pangeo_full_201909/lib/python3.7/site-packages/distributed/worker.py:866> exception=OSError("Timed out trying to connect to 'tcp://10.120.40.97:33653' after 10 s: in <distributed.comm.tcp.TCPConnector object at 0x2ba00348fcf8>: ConnectionRefusedError: [Errno 111] Connection refused")>)
Traceback (most recent call last):
  File "/softs/rh7/conda/4.5.4/envs/pangeo_full_201909/lib/python3.7/site-packages/distributed/comm/core.py", line 215, in connect
    quiet_exceptions=EnvironmentError,
tornado.util.TimeoutError: Timeout

During handling of the above exception, another exception occurred:

Traceback (most recent call last):
  File "/softs/rh7/conda/4.5.4/envs/pangeo_full_201909/lib/python3.7/site-packages/tornado/ioloop.py", line 743, in _run_callback
    ret = callback()
  File "/softs/rh7/conda/4.5.4/envs/pangeo_full_201909/lib/python3.7/site-packages/tornado/ioloop.py", line 767, in _discard_future_result
    future.result()
  File "/softs/rh7/conda/4.5.4/envs/pangeo_full_201909/lib/python3.7/site-packages/distributed/worker.py", line 875, in heartbeat
    metrics=await self.get_metrics(),
  File "/softs/rh7/conda/4.5.4/envs/pangeo_full_201909/lib/python3.7/site-packages/distributed/core.py", line 747, in send_recv_from_rpc
    comm = await self.pool.connect(self.addr)
  File "/softs/rh7/conda/4.5.4/envs/pangeo_full_201909/lib/python3.7/site-packages/distributed/core.py", line 874, in connect
    connection_args=self.connection_args,
  File "/softs/rh7/conda/4.5.4/envs/pangeo_full_201909/lib/python3.7/site-packages/distributed/comm/core.py", line 227, in connect
    _raise(error)
  File "/softs/rh7/conda/4.5.4/envs/pangeo_full_201909/lib/python3.7/site-packages/distributed/comm/core.py", line 204, in _raise
    raise IOError(msg)
OSError: Timed out trying to connect to 'tcp://10.120.40.97:33653' after 10 s: in <distributed.comm.tcp.TCPConnector object at 0x2ba00348fcf8>: ConnectionRefusedError: [Errno 111] Connection refused
tornado.application - ERROR - Exception in callback functools.partial(<bound method IOLoop._discard_future_result of <tornado.platform.asyncio.AsyncIOLoop object at 0x2b9fed87bb38>>, <Task finished coro=<Worker.heartbeat() done, defined at /softs/rh7/conda/4.5.4/envs/pangeo_full_201909/lib/python3.7/site-packages/distributed/worker.py:866> exception=OSError("Timed out trying to connect to 'tcp://10.120.40.97:33653' after 10 s: in <distributed.comm.tcp.TCPConnector object at 0x2ba00348fe80>: ConnectionRefusedError: [Errno 111] Connection refused")>)
Traceback (most recent call last):
  File "/softs/rh7/conda/4.5.4/envs/pangeo_full_201909/lib/python3.7/site-packages/distributed/comm/core.py", line 215, in connect
    quiet_exceptions=EnvironmentError,
tornado.util.TimeoutError: Timeout

During handling of the above exception, another exception occurred:

Traceback (most recent call last):
  File "/softs/rh7/conda/4.5.4/envs/pangeo_full_201909/lib/python3.7/site-packages/tornado/ioloop.py", line 743, in _run_callback
    ret = callback()
  File "/softs/rh7/conda/4.5.4/envs/pangeo_full_201909/lib/python3.7/site-packages/tornado/ioloop.py", line 767, in _discard_future_result
    future.result()
  File "/softs/rh7/conda/4.5.4/envs/pangeo_full_201909/lib/python3.7/site-packages/distributed/worker.py", line 875, in heartbeat
    metrics=await self.get_metrics(),
  File "/softs/rh7/conda/4.5.4/envs/pangeo_full_201909/lib/python3.7/site-packages/distributed/core.py", line 747, in send_recv_from_rpc
    comm = await self.pool.connect(self.addr)
  File "/softs/rh7/conda/4.5.4/envs/pangeo_full_201909/lib/python3.7/site-packages/distributed/core.py", line 874, in connect
    connection_args=self.connection_args,
  File "/softs/rh7/conda/4.5.4/envs/pangeo_full_201909/lib/python3.7/site-packages/distributed/comm/core.py", line 227, in connect
    _raise(error)
  File "/softs/rh7/conda/4.5.4/envs/pangeo_full_201909/lib/python3.7/site-packages/distributed/comm/core.py", line 204, in _raise
    raise IOError(msg)
OSError: Timed out trying to connect to 'tcp://10.120.40.97:33653' after 10 s: in <distributed.comm.tcp.TCPConnector object at 0x2ba00348fe80>: ConnectionRefusedError: [Errno 111] Connection refused
tornado.application - ERROR - Exception in callback functools.partial(<bound method IOLoop._discard_future_result of <tornado.platform.asyncio.AsyncIOLoop object at 0x2b9fed87bb38>>, <Task finished coro=<Worker.heartbeat() done, defined at /softs/rh7/conda/4.5.4/envs/pangeo_full_201909/lib/python3.7/site-packages/distributed/worker.py:866> exception=OSError("Timed out trying to connect to 'tcp://10.120.40.97:33653' after 10 s: in <distributed.comm.tcp.TCPConnector object at 0x2ba00348f9e8>: ConnectionRefusedError: [Errno 111] Connection refused")>)
Traceback (most recent call last):
  File "/softs/rh7/conda/4.5.4/envs/pangeo_full_201909/lib/python3.7/site-packages/distributed/comm/core.py", line 215, in connect
    quiet_exceptions=EnvironmentError,
tornado.util.TimeoutError: Timeout

During handling of the above exception, another exception occurred:

Traceback (most recent call last):
  File "/softs/rh7/conda/4.5.4/envs/pangeo_full_201909/lib/python3.7/site-packages/tornado/ioloop.py", line 743, in _run_callback
    ret = callback()
  File "/softs/rh7/conda/4.5.4/envs/pangeo_full_201909/lib/python3.7/site-packages/tornado/ioloop.py", line 767, in _discard_future_result
    future.result()
  File "/softs/rh7/conda/4.5.4/envs/pangeo_full_201909/lib/python3.7/site-packages/distributed/worker.py", line 875, in heartbeat
    metrics=await self.get_metrics(),
  File "/softs/rh7/conda/4.5.4/envs/pangeo_full_201909/lib/python3.7/site-packages/distributed/core.py", line 747, in send_recv_from_rpc
    comm = await self.pool.connect(self.addr)
  File "/softs/rh7/conda/4.5.4/envs/pangeo_full_201909/lib/python3.7/site-packages/distributed/core.py", line 874, in connect
    connection_args=self.connection_args,
  File "/softs/rh7/conda/4.5.4/envs/pangeo_full_201909/lib/python3.7/site-packages/distributed/comm/core.py", line 227, in connect
    _raise(error)
  File "/softs/rh7/conda/4.5.4/envs/pangeo_full_201909/lib/python3.7/site-packages/distributed/comm/core.py", line 204, in _raise
    raise IOError(msg)
OSError: Timed out trying to connect to 'tcp://10.120.40.97:33653' after 10 s: in <distributed.comm.tcp.TCPConnector object at 0x2ba00348f9e8>: ConnectionRefusedError: [Errno 111] Connection refused
tornado.application - ERROR - Exception in callback functools.partial(<bound method IOLoop._discard_future_result of <tornado.platform.asyncio.AsyncIOLoop object at 0x2b9fed87bb38>>, <Task finished coro=<Worker.heartbeat() done, defined at /softs/rh7/conda/4.5.4/envs/pangeo_full_201909/lib/python3.7/site-packages/distributed/worker.py:866> exception=OSError("Timed out trying to connect to 'tcp://10.120.40.97:33653' after 10 s: in <distributed.comm.tcp.TCPConnector object at 0x2ba0033ffeb8>: ConnectionRefusedError: [Errno 111] Connection refused")>)
Traceback (most recent call last):
  File "/softs/rh7/conda/4.5.4/envs/pangeo_full_201909/lib/python3.7/site-packages/distributed/comm/core.py", line 215, in connect
    quiet_exceptions=EnvironmentError,
tornado.util.TimeoutError: Timeout

During handling of the above exception, another exception occurred:

Traceback (most recent call last):
  File "/softs/rh7/conda/4.5.4/envs/pangeo_full_201909/lib/python3.7/site-packages/tornado/ioloop.py", line 743, in _run_callback
    ret = callback()
  File "/softs/rh7/conda/4.5.4/envs/pangeo_full_201909/lib/python3.7/site-packages/tornado/ioloop.py", line 767, in _discard_future_result
    future.result()
  File "/softs/rh7/conda/4.5.4/envs/pangeo_full_201909/lib/python3.7/site-packages/distributed/worker.py", line 875, in heartbeat
    metrics=await self.get_metrics(),
  File "/softs/rh7/conda/4.5.4/envs/pangeo_full_201909/lib/python3.7/site-packages/distributed/core.py", line 747, in send_recv_from_rpc
    comm = await self.pool.connect(self.addr)
  File "/softs/rh7/conda/4.5.4/envs/pangeo_full_201909/lib/python3.7/site-packages/distributed/core.py", line 874, in connect
    connection_args=self.connection_args,
  File "/softs/rh7/conda/4.5.4/envs/pangeo_full_201909/lib/python3.7/site-packages/distributed/comm/core.py", line 227, in connect
    _raise(error)
  File "/softs/rh7/conda/4.5.4/envs/pangeo_full_201909/lib/python3.7/site-packages/distributed/comm/core.py", line 204, in _raise
    raise IOError(msg)
OSError: Timed out trying to connect to 'tcp://10.120.40.97:33653' after 10 s: in <distributed.comm.tcp.TCPConnector object at 0x2ba0033ffeb8>: ConnectionRefusedError: [Errno 111] Connection refused
tornado.application - ERROR - Exception in callback <function Worker._register_with_scheduler.<locals>.<lambda> at 0x2ba0005ead90>
Traceback (most recent call last):
  File "/softs/rh7/conda/4.5.4/envs/pangeo_full_201909/lib/python3.7/site-packages/tornado/ioloop.py", line 907, in _run
    return self.callback()
  File "/softs/rh7/conda/4.5.4/envs/pangeo_full_201909/lib/python3.7/site-packages/distributed/worker.py", line 857, in <lambda>
    lambda: self.batched_stream.send({"op": "keep-alive"}),
  File "/softs/rh7/conda/4.5.4/envs/pangeo_full_201909/lib/python3.7/site-packages/distributed/batched.py", line 117, in send
    raise CommClosedError
distributed.comm.core.CommClosedError
tornado.application - ERROR - Exception in callback functools.partial(<bound method IOLoop._discard_future_result of <tornado.platform.asyncio.AsyncIOLoop object at 0x2b9fed87bb38>>, <Task finished coro=<Worker.heartbeat() done, defined at /softs/rh7/conda/4.5.4/envs/pangeo_full_201909/lib/python3.7/site-packages/distributed/worker.py:866> exception=OSError("Timed out trying to connect to 'tcp://10.120.40.97:33653' after 10 s: in <distributed.comm.tcp.TCPConnector object at 0x2ba0033ff4a8>: ConnectionRefusedError: [Errno 111] Connection refused")>)
Traceback (most recent call last):
  File "/softs/rh7/conda/4.5.4/envs/pangeo_full_201909/lib/python3.7/site-packages/distributed/comm/core.py", line 215, in connect
    quiet_exceptions=EnvironmentError,
tornado.util.TimeoutError: Timeout

During handling of the above exception, another exception occurred:

Traceback (most recent call last):
  File "/softs/rh7/conda/4.5.4/envs/pangeo_full_201909/lib/python3.7/site-packages/tornado/ioloop.py", line 743, in _run_callback
    ret = callback()
  File "/softs/rh7/conda/4.5.4/envs/pangeo_full_201909/lib/python3.7/site-packages/tornado/ioloop.py", line 767, in _discard_future_result
    future.result()
  File "/softs/rh7/conda/4.5.4/envs/pangeo_full_201909/lib/python3.7/site-packages/distributed/worker.py", line 875, in heartbeat
    metrics=await self.get_metrics(),
  File "/softs/rh7/conda/4.5.4/envs/pangeo_full_201909/lib/python3.7/site-packages/distributed/core.py", line 747, in send_recv_from_rpc
    comm = await self.pool.connect(self.addr)
  File "/softs/rh7/conda/4.5.4/envs/pangeo_full_201909/lib/python3.7/site-packages/distributed/core.py", line 874, in connect
    connection_args=self.connection_args,
  File "/softs/rh7/conda/4.5.4/envs/pangeo_full_201909/lib/python3.7/site-packages/distributed/comm/core.py", line 227, in connect
    _raise(error)
  File "/softs/rh7/conda/4.5.4/envs/pangeo_full_201909/lib/python3.7/site-packages/distributed/comm/core.py", line 204, in _raise
    raise IOError(msg)
OSError: Timed out trying to connect to 'tcp://10.120.40.97:33653' after 10 s: in <distributed.comm.tcp.TCPConnector object at 0x2ba0033ff4a8>: ConnectionRefusedError: [Errno 111] Connection refused
tornado.application - ERROR - Exception in callback functools.partial(<bound method IOLoop._discard_future_result of <tornado.platform.asyncio.AsyncIOLoop object at 0x2b9fed87bb38>>, <Task finished coro=<Worker.heartbeat() done, defined at /softs/rh7/conda/4.5.4/envs/pangeo_full_201909/lib/python3.7/site-packages/distributed/worker.py:866> exception=OSError("Timed out trying to connect to 'tcp://10.120.40.97:33653' after 10 s: in <distributed.comm.tcp.TCPConnector object at 0x2ba001393048>: ConnectionRefusedError: [Errno 111] Connection refused")>)
Traceback (most recent call last):
  File "/softs/rh7/conda/4.5.4/envs/pangeo_full_201909/lib/python3.7/site-packages/distributed/comm/core.py", line 215, in connect
    quiet_exceptions=EnvironmentError,
tornado.util.TimeoutError: Timeout

During handling of the above exception, another exception occurred:

Traceback (most recent call last):
  File "/softs/rh7/conda/4.5.4/envs/pangeo_full_201909/lib/python3.7/site-packages/tornado/ioloop.py", line 743, in _run_callback
    ret = callback()
  File "/softs/rh7/conda/4.5.4/envs/pangeo_full_201909/lib/python3.7/site-packages/tornado/ioloop.py", line 767, in _discard_future_result
    future.result()
  File "/softs/rh7/conda/4.5.4/envs/pangeo_full_201909/lib/python3.7/site-packages/distributed/worker.py", line 875, in heartbeat
    metrics=await self.get_metrics(),
  File "/softs/rh7/conda/4.5.4/envs/pangeo_full_201909/lib/python3.7/site-packages/distributed/core.py", line 747, in send_recv_from_rpc
    comm = await self.pool.connect(self.addr)
  File "/softs/rh7/conda/4.5.4/envs/pangeo_full_201909/lib/python3.7/site-packages/distributed/core.py", line 874, in connect
    connection_args=self.connection_args,
  File "/softs/rh7/conda/4.5.4/envs/pangeo_full_201909/lib/python3.7/site-packages/distributed/comm/core.py", line 227, in connect
    _raise(error)
  File "/softs/rh7/conda/4.5.4/envs/pangeo_full_201909/lib/python3.7/site-packages/distributed/comm/core.py", line 204, in _raise
    raise IOError(msg)
OSError: Timed out trying to connect to 'tcp://10.120.40.97:33653' after 10 s: in <distributed.comm.tcp.TCPConnector object at 0x2ba001393048>: ConnectionRefusedError: [Errno 111] Connection refused
tornado.application - ERROR - Exception in callback functools.partial(<bound method IOLoop._discard_future_result of <tornado.platform.asyncio.AsyncIOLoop object at 0x2b9fed87bb38>>, <Task finished coro=<Worker.heartbeat() done, defined at /softs/rh7/conda/4.5.4/envs/pangeo_full_201909/lib/python3.7/site-packages/distributed/worker.py:866> exception=OSError("Timed out trying to connect to 'tcp://10.120.40.97:33653' after 10 s: in <distributed.comm.tcp.TCPConnector object at 0x2ba0029ee0b8>: ConnectionRefusedError: [Errno 111] Connection refused")>)
Traceback (most recent call last):
  File "/softs/rh7/conda/4.5.4/envs/pangeo_full_201909/lib/python3.7/site-packages/distributed/comm/core.py", line 215, in connect
    quiet_exceptions=EnvironmentError,
tornado.util.TimeoutError: Timeout

During handling of the above exception, another exception occurred:

Traceback (most recent call last):
  File "/softs/rh7/conda/4.5.4/envs/pangeo_full_201909/lib/python3.7/site-packages/tornado/ioloop.py", line 743, in _run_callback
    ret = callback()
  File "/softs/rh7/conda/4.5.4/envs/pangeo_full_201909/lib/python3.7/site-packages/tornado/ioloop.py", line 767, in _discard_future_result
    future.result()
  File "/softs/rh7/conda/4.5.4/envs/pangeo_full_201909/lib/python3.7/site-packages/distributed/worker.py", line 875, in heartbeat
    metrics=await self.get_metrics(),
  File "/softs/rh7/conda/4.5.4/envs/pangeo_full_201909/lib/python3.7/site-packages/distributed/core.py", line 747, in send_recv_from_rpc
    comm = await self.pool.connect(self.addr)
  File "/softs/rh7/conda/4.5.4/envs/pangeo_full_201909/lib/python3.7/site-packages/distributed/core.py", line 874, in connect
    connection_args=self.connection_args,
  File "/softs/rh7/conda/4.5.4/envs/pangeo_full_201909/lib/python3.7/site-packages/distributed/comm/core.py", line 227, in connect
    _raise(error)
  File "/softs/rh7/conda/4.5.4/envs/pangeo_full_201909/lib/python3.7/site-packages/distributed/comm/core.py", line 204, in _raise
    raise IOError(msg)
OSError: Timed out trying to connect to 'tcp://10.120.40.97:33653' after 10 s: in <distributed.comm.tcp.TCPConnector object at 0x2ba0029ee0b8>: ConnectionRefusedError: [Errno 111] Connection refused
tornado.application - ERROR - Exception in callback functools.partial(<bound method IOLoop._discard_future_result of <tornado.platform.asyncio.AsyncIOLoop object at 0x2b9fed87bb38>>, <Task finished coro=<Worker.heartbeat() done, defined at /softs/rh7/conda/4.5.4/envs/pangeo_full_201909/lib/python3.7/site-packages/distributed/worker.py:866> exception=OSError("Timed out trying to connect to 'tcp://10.120.40.97:33653' after 10 s: in <distributed.comm.tcp.TCPConnector object at 0x2ba000ce64e0>: ConnectionRefusedError: [Errno 111] Connection refused")>)
Traceback (most recent call last):
  File "/softs/rh7/conda/4.5.4/envs/pangeo_full_201909/lib/python3.7/site-packages/distributed/comm/core.py", line 215, in connect
    quiet_exceptions=EnvironmentError,
tornado.util.TimeoutError: Timeout

During handling of the above exception, another exception occurred:

Traceback (most recent call last):
  File "/softs/rh7/conda/4.5.4/envs/pangeo_full_201909/lib/python3.7/site-packages/tornado/ioloop.py", line 743, in _run_callback
    ret = callback()
  File "/softs/rh7/conda/4.5.4/envs/pangeo_full_201909/lib/python3.7/site-packages/tornado/ioloop.py", line 767, in _discard_future_result
    future.result()
  File "/softs/rh7/conda/4.5.4/envs/pangeo_full_201909/lib/python3.7/site-packages/distributed/worker.py", line 875, in heartbeat
    metrics=await self.get_metrics(),
  File "/softs/rh7/conda/4.5.4/envs/pangeo_full_201909/lib/python3.7/site-packages/distributed/core.py", line 747, in send_recv_from_rpc
    comm = await self.pool.connect(self.addr)
  File "/softs/rh7/conda/4.5.4/envs/pangeo_full_201909/lib/python3.7/site-packages/distributed/core.py", line 874, in connect
    connection_args=self.connection_args,
  File "/softs/rh7/conda/4.5.4/envs/pangeo_full_201909/lib/python3.7/site-packages/distributed/comm/core.py", line 227, in connect
    _raise(error)
  File "/softs/rh7/conda/4.5.4/envs/pangeo_full_201909/lib/python3.7/site-packages/distributed/comm/core.py", line 204, in _raise
    raise IOError(msg)
OSError: Timed out trying to connect to 'tcp://10.120.40.97:33653' after 10 s: in <distributed.comm.tcp.TCPConnector object at 0x2ba000ce64e0>: ConnectionRefusedError: [Errno 111] Connection refused
tornado.application - ERROR - Exception in callback functools.partial(<bound method IOLoop._discard_future_result of <tornado.platform.asyncio.AsyncIOLoop object at 0x2b9fed87bb38>>, <Task finished coro=<Worker.heartbeat() done, defined at /softs/rh7/conda/4.5.4/envs/pangeo_full_201909/lib/python3.7/site-packages/distributed/worker.py:866> exception=OSError("Timed out trying to connect to 'tcp://10.120.40.97:33653' after 10 s: in <distributed.comm.tcp.TCPConnector object at 0x2ba00348f128>: ConnectionRefusedError: [Errno 111] Connection refused")>)
Traceback (most recent call last):
  File "/softs/rh7/conda/4.5.4/envs/pangeo_full_201909/lib/python3.7/site-packages/distributed/comm/core.py", line 215, in connect
    quiet_exceptions=EnvironmentError,
tornado.util.TimeoutError: Timeout

During handling of the above exception, another exception occurred:

Traceback (most recent call last):
  File "/softs/rh7/conda/4.5.4/envs/pangeo_full_201909/lib/python3.7/site-packages/tornado/ioloop.py", line 743, in _run_callback
    ret = callback()
  File "/softs/rh7/conda/4.5.4/envs/pangeo_full_201909/lib/python3.7/site-packages/tornado/ioloop.py", line 767, in _discard_future_result
    future.result()
  File "/softs/rh7/conda/4.5.4/envs/pangeo_full_201909/lib/python3.7/site-packages/distributed/worker.py", line 875, in heartbeat
    metrics=await self.get_metrics(),
  File "/softs/rh7/conda/4.5.4/envs/pangeo_full_201909/lib/python3.7/site-packages/distributed/core.py", line 747, in send_recv_from_rpc
    comm = await self.pool.connect(self.addr)
  File "/softs/rh7/conda/4.5.4/envs/pangeo_full_201909/lib/python3.7/site-packages/distributed/core.py", line 874, in connect
    connection_args=self.connection_args,
  File "/softs/rh7/conda/4.5.4/envs/pangeo_full_201909/lib/python3.7/site-packages/distributed/comm/core.py", line 227, in connect
    _raise(error)
  File "/softs/rh7/conda/4.5.4/envs/pangeo_full_201909/lib/python3.7/site-packages/distributed/comm/core.py", line 204, in _raise
    raise IOError(msg)
OSError: Timed out trying to connect to 'tcp://10.120.40.97:33653' after 10 s: in <distributed.comm.tcp.TCPConnector object at 0x2ba00348f128>: ConnectionRefusedError: [Errno 111] Connection refused
tornado.application - ERROR - Exception in callback functools.partial(<bound method IOLoop._discard_future_result of <tornado.platform.asyncio.AsyncIOLoop object at 0x2b9fed87bb38>>, <Task finished coro=<Worker.heartbeat() done, defined at /softs/rh7/conda/4.5.4/envs/pangeo_full_201909/lib/python3.7/site-packages/distributed/worker.py:866> exception=OSError("Timed out trying to connect to 'tcp://10.120.40.97:33653' after 10 s: in <distributed.comm.tcp.TCPConnector object at 0x2ba002bbf390>: ConnectionRefusedError: [Errno 111] Connection refused")>)
Traceback (most recent call last):
  File "/softs/rh7/conda/4.5.4/envs/pangeo_full_201909/lib/python3.7/site-packages/distributed/comm/core.py", line 215, in connect
    quiet_exceptions=EnvironmentError,
tornado.util.TimeoutError: Timeout

During handling of the above exception, another exception occurred:

Traceback (most recent call last):
  File "/softs/rh7/conda/4.5.4/envs/pangeo_full_201909/lib/python3.7/site-packages/tornado/ioloop.py", line 743, in _run_callback
    ret = callback()
  File "/softs/rh7/conda/4.5.4/envs/pangeo_full_201909/lib/python3.7/site-packages/tornado/ioloop.py", line 767, in _discard_future_result
    future.result()
  File "/softs/rh7/conda/4.5.4/envs/pangeo_full_201909/lib/python3.7/site-packages/distributed/worker.py", line 875, in heartbeat
    metrics=await self.get_metrics(),
  File "/softs/rh7/conda/4.5.4/envs/pangeo_full_201909/lib/python3.7/site-packages/distributed/core.py", line 747, in send_recv_from_rpc
    comm = await self.pool.connect(self.addr)
  File "/softs/rh7/conda/4.5.4/envs/pangeo_full_201909/lib/python3.7/site-packages/distributed/core.py", line 874, in connect
    connection_args=self.connection_args,
  File "/softs/rh7/conda/4.5.4/envs/pangeo_full_201909/lib/python3.7/site-packages/distributed/comm/core.py", line 227, in connect
    _raise(error)
  File "/softs/rh7/conda/4.5.4/envs/pangeo_full_201909/lib/python3.7/site-packages/distributed/comm/core.py", line 204, in _raise
    raise IOError(msg)
OSError: Timed out trying to connect to 'tcp://10.120.40.97:33653' after 10 s: in <distributed.comm.tcp.TCPConnector object at 0x2ba002bbf390>: ConnectionRefusedError: [Errno 111] Connection refused
tornado.application - ERROR - Exception in callback <function Worker._register_with_scheduler.<locals>.<lambda> at 0x2ba0005ead90>
Traceback (most recent call last):
  File "/softs/rh7/conda/4.5.4/envs/pangeo_full_201909/lib/python3.7/site-packages/tornado/ioloop.py", line 907, in _run
    return self.callback()
  File "/softs/rh7/conda/4.5.4/envs/pangeo_full_201909/lib/python3.7/site-packages/distributed/worker.py", line 857, in <lambda>
    lambda: self.batched_stream.send({"op": "keep-alive"}),
  File "/softs/rh7/conda/4.5.4/envs/pangeo_full_201909/lib/python3.7/site-packages/distributed/batched.py", line 117, in send
    raise CommClosedError
distributed.comm.core.CommClosedError
tornado.application - ERROR - Exception in callback functools.partial(<bound method IOLoop._discard_future_result of <tornado.platform.asyncio.AsyncIOLoop object at 0x2b9fed87bb38>>, <Task finished coro=<Worker.heartbeat() done, defined at /softs/rh7/conda/4.5.4/envs/pangeo_full_201909/lib/python3.7/site-packages/distributed/worker.py:866> exception=OSError("Timed out trying to connect to 'tcp://10.120.40.97:33653' after 10 s: in <distributed.comm.tcp.TCPConnector object at 0x2ba002bbf160>: ConnectionRefusedError: [Errno 111] Connection refused")>)
Traceback (most recent call last):
  File "/softs/rh7/conda/4.5.4/envs/pangeo_full_201909/lib/python3.7/site-packages/distributed/comm/core.py", line 215, in connect
    quiet_exceptions=EnvironmentError,
tornado.util.TimeoutError: Timeout

During handling of the above exception, another exception occurred:

Traceback (most recent call last):
  File "/softs/rh7/conda/4.5.4/envs/pangeo_full_201909/lib/python3.7/site-packages/tornado/ioloop.py", line 743, in _run_callback
    ret = callback()
  File "/softs/rh7/conda/4.5.4/envs/pangeo_full_201909/lib/python3.7/site-packages/tornado/ioloop.py", line 767, in _discard_future_result
    future.result()
  File "/softs/rh7/conda/4.5.4/envs/pangeo_full_201909/lib/python3.7/site-packages/distributed/worker.py", line 875, in heartbeat
    metrics=await self.get_metrics(),
  File "/softs/rh7/conda/4.5.4/envs/pangeo_full_201909/lib/python3.7/site-packages/distributed/core.py", line 747, in send_recv_from_rpc
    comm = await self.pool.connect(self.addr)
  File "/softs/rh7/conda/4.5.4/envs/pangeo_full_201909/lib/python3.7/site-packages/distributed/core.py", line 874, in connect
    connection_args=self.connection_args,
  File "/softs/rh7/conda/4.5.4/envs/pangeo_full_201909/lib/python3.7/site-packages/distributed/comm/core.py", line 227, in connect
    _raise(error)
  File "/softs/rh7/conda/4.5.4/envs/pangeo_full_201909/lib/python3.7/site-packages/distributed/comm/core.py", line 204, in _raise
    raise IOError(msg)
OSError: Timed out trying to connect to 'tcp://10.120.40.97:33653' after 10 s: in <distributed.comm.tcp.TCPConnector object at 0x2ba002bbf160>: ConnectionRefusedError: [Errno 111] Connection refused
tornado.application - ERROR - Exception in callback functools.partial(<bound method IOLoop._discard_future_result of <tornado.platform.asyncio.AsyncIOLoop object at 0x2b9fed87bb38>>, <Task finished coro=<Worker.heartbeat() done, defined at /softs/rh7/conda/4.5.4/envs/pangeo_full_201909/lib/python3.7/site-packages/distributed/worker.py:866> exception=OSError("Timed out trying to connect to 'tcp://10.120.40.97:33653' after 10 s: in <distributed.comm.tcp.TCPConnector object at 0x2ba0029b0358>: ConnectionRefusedError: [Errno 111] Connection refused")>)
Traceback (most recent call last):
  File "/softs/rh7/conda/4.5.4/envs/pangeo_full_201909/lib/python3.7/site-packages/distributed/comm/core.py", line 215, in connect
    quiet_exceptions=EnvironmentError,
tornado.util.TimeoutError: Timeout

During handling of the above exception, another exception occurred:

Traceback (most recent call last):
  File "/softs/rh7/conda/4.5.4/envs/pangeo_full_201909/lib/python3.7/site-packages/tornado/ioloop.py", line 743, in _run_callback
    ret = callback()
  File "/softs/rh7/conda/4.5.4/envs/pangeo_full_201909/lib/python3.7/site-packages/tornado/ioloop.py", line 767, in _discard_future_result
    future.result()
  File "/softs/rh7/conda/4.5.4/envs/pangeo_full_201909/lib/python3.7/site-packages/distributed/worker.py", line 875, in heartbeat
    metrics=await self.get_metrics(),
  File "/softs/rh7/conda/4.5.4/envs/pangeo_full_201909/lib/python3.7/site-packages/distributed/core.py", line 747, in send_recv_from_rpc
    comm = await self.pool.connect(self.addr)
  File "/softs/rh7/conda/4.5.4/envs/pangeo_full_201909/lib/python3.7/site-packages/distributed/core.py", line 874, in connect
    connection_args=self.connection_args,
  File "/softs/rh7/conda/4.5.4/envs/pangeo_full_201909/lib/python3.7/site-packages/distributed/comm/core.py", line 227, in connect
    _raise(error)
  File "/softs/rh7/conda/4.5.4/envs/pangeo_full_201909/lib/python3.7/site-packages/distributed/comm/core.py", line 204, in _raise
    raise IOError(msg)
OSError: Timed out trying to connect to 'tcp://10.120.40.97:33653' after 10 s: in <distributed.comm.tcp.TCPConnector object at 0x2ba0029b0358>: ConnectionRefusedError: [Errno 111] Connection refused
tornado.application - ERROR - Exception in callback functools.partial(<bound method IOLoop._discard_future_result of <tornado.platform.asyncio.AsyncIOLoop object at 0x2b9fed87bb38>>, <Task finished coro=<Worker.heartbeat() done, defined at /softs/rh7/conda/4.5.4/envs/pangeo_full_201909/lib/python3.7/site-packages/distributed/worker.py:866> exception=OSError("Timed out trying to connect to 'tcp://10.120.40.97:33653' after 10 s: in <distributed.comm.tcp.TCPConnector object at 0x2ba0029ee0f0>: ConnectionRefusedError: [Errno 111] Connection refused")>)
Traceback (most recent call last):
  File "/softs/rh7/conda/4.5.4/envs/pangeo_full_201909/lib/python3.7/site-packages/distributed/comm/core.py", line 215, in connect
    quiet_exceptions=EnvironmentError,
tornado.util.TimeoutError: Timeout

During handling of the above exception, another exception occurred:

Traceback (most recent call last):
  File "/softs/rh7/conda/4.5.4/envs/pangeo_full_201909/lib/python3.7/site-packages/tornado/ioloop.py", line 743, in _run_callback
    ret = callback()
  File "/softs/rh7/conda/4.5.4/envs/pangeo_full_201909/lib/python3.7/site-packages/tornado/ioloop.py", line 767, in _discard_future_result
    future.result()
  File "/softs/rh7/conda/4.5.4/envs/pangeo_full_201909/lib/python3.7/site-packages/distributed/worker.py", line 875, in heartbeat
    metrics=await self.get_metrics(),
  File "/softs/rh7/conda/4.5.4/envs/pangeo_full_201909/lib/python3.7/site-packages/distributed/core.py", line 747, in send_recv_from_rpc
    comm = await self.pool.connect(self.addr)
  File "/softs/rh7/conda/4.5.4/envs/pangeo_full_201909/lib/python3.7/site-packages/distributed/core.py", line 874, in connect
    connection_args=self.connection_args,
  File "/softs/rh7/conda/4.5.4/envs/pangeo_full_201909/lib/python3.7/site-packages/distributed/comm/core.py", line 227, in connect
    _raise(error)
  File "/softs/rh7/conda/4.5.4/envs/pangeo_full_201909/lib/python3.7/site-packages/distributed/comm/core.py", line 204, in _raise
    raise IOError(msg)
OSError: Timed out trying to connect to 'tcp://10.120.40.97:33653' after 10 s: in <distributed.comm.tcp.TCPConnector object at 0x2ba0029ee0f0>: ConnectionRefusedError: [Errno 111] Connection refused
tornado.application - ERROR - Exception in callback functools.partial(<bound method IOLoop._discard_future_result of <tornado.platform.asyncio.AsyncIOLoop object at 0x2b9fed87bb38>>, <Task finished coro=<Worker.heartbeat() done, defined at /softs/rh7/conda/4.5.4/envs/pangeo_full_201909/lib/python3.7/site-packages/distributed/worker.py:866> exception=OSError("Timed out trying to connect to 'tcp://10.120.40.97:33653' after 10 s: in <distributed.comm.tcp.TCPConnector object at 0x2ba002bbf320>: ConnectionRefusedError: [Errno 111] Connection refused")>)
Traceback (most recent call last):
  File "/softs/rh7/conda/4.5.4/envs/pangeo_full_201909/lib/python3.7/site-packages/distributed/comm/core.py", line 215, in connect
    quiet_exceptions=EnvironmentError,
tornado.util.TimeoutError: Timeout

During handling of the above exception, another exception occurred:

Traceback (most recent call last):
  File "/softs/rh7/conda/4.5.4/envs/pangeo_full_201909/lib/python3.7/site-packages/tornado/ioloop.py", line 743, in _run_callback
    ret = callback()
  File "/softs/rh7/conda/4.5.4/envs/pangeo_full_201909/lib/python3.7/site-packages/tornado/ioloop.py", line 767, in _discard_future_result
    future.result()
  File "/softs/rh7/conda/4.5.4/envs/pangeo_full_201909/lib/python3.7/site-packages/distributed/worker.py", line 875, in heartbeat
    metrics=await self.get_metrics(),
  File "/softs/rh7/conda/4.5.4/envs/pangeo_full_201909/lib/python3.7/site-packages/distributed/core.py", line 747, in send_recv_from_rpc
    comm = await self.pool.connect(self.addr)
  File "/softs/rh7/conda/4.5.4/envs/pangeo_full_201909/lib/python3.7/site-packages/distributed/core.py", line 874, in connect
    connection_args=self.connection_args,
  File "/softs/rh7/conda/4.5.4/envs/pangeo_full_201909/lib/python3.7/site-packages/distributed/comm/core.py", line 227, in connect
    _raise(error)
  File "/softs/rh7/conda/4.5.4/envs/pangeo_full_201909/lib/python3.7/site-packages/distributed/comm/core.py", line 204, in _raise
    raise IOError(msg)
OSError: Timed out trying to connect to 'tcp://10.120.40.97:33653' after 10 s: in <distributed.comm.tcp.TCPConnector object at 0x2ba002bbf320>: ConnectionRefusedError: [Errno 111] Connection refused
tornado.application - ERROR - Exception in callback functools.partial(<bound method IOLoop._discard_future_result of <tornado.platform.asyncio.AsyncIOLoop object at 0x2b9fed87bb38>>, <Task finished coro=<Worker.heartbeat() done, defined at /softs/rh7/conda/4.5.4/envs/pangeo_full_201909/lib/python3.7/site-packages/distributed/worker.py:866> exception=OSError("Timed out trying to connect to 'tcp://10.120.40.97:33653' after 10 s: in <distributed.comm.tcp.TCPConnector object at 0x2ba00348fdd8>: ConnectionRefusedError: [Errno 111] Connection refused")>)
Traceback (most recent call last):
  File "/softs/rh7/conda/4.5.4/envs/pangeo_full_201909/lib/python3.7/site-packages/distributed/comm/core.py", line 215, in connect
    quiet_exceptions=EnvironmentError,
tornado.util.TimeoutError: Timeout

During handling of the above exception, another exception occurred:

Traceback (most recent call last):
  File "/softs/rh7/conda/4.5.4/envs/pangeo_full_201909/lib/python3.7/site-packages/tornado/ioloop.py", line 743, in _run_callback
    ret = callback()
  File "/softs/rh7/conda/4.5.4/envs/pangeo_full_201909/lib/python3.7/site-packages/tornado/ioloop.py", line 767, in _discard_future_result
    future.result()
  File "/softs/rh7/conda/4.5.4/envs/pangeo_full_201909/lib/python3.7/site-packages/distributed/worker.py", line 875, in heartbeat
    metrics=await self.get_metrics(),
  File "/softs/rh7/conda/4.5.4/envs/pangeo_full_201909/lib/python3.7/site-packages/distributed/core.py", line 747, in send_recv_from_rpc
    comm = await self.pool.connect(self.addr)
  File "/softs/rh7/conda/4.5.4/envs/pangeo_full_201909/lib/python3.7/site-packages/distributed/core.py", line 874, in connect
    connection_args=self.connection_args,
  File "/softs/rh7/conda/4.5.4/envs/pangeo_full_201909/lib/python3.7/site-packages/distributed/comm/core.py", line 227, in connect
    _raise(error)
  File "/softs/rh7/conda/4.5.4/envs/pangeo_full_201909/lib/python3.7/site-packages/distributed/comm/core.py", line 204, in _raise
    raise IOError(msg)
OSError: Timed out trying to connect to 'tcp://10.120.40.97:33653' after 10 s: in <distributed.comm.tcp.TCPConnector object at 0x2ba00348fdd8>: ConnectionRefusedError: [Errno 111] Connection refused
tornado.application - ERROR - Exception in callback <function Worker._register_with_scheduler.<locals>.<lambda> at 0x2ba0005ead90>
Traceback (most recent call last):
  File "/softs/rh7/conda/4.5.4/envs/pangeo_full_201909/lib/python3.7/site-packages/tornado/ioloop.py", line 907, in _run
    return self.callback()
  File "/softs/rh7/conda/4.5.4/envs/pangeo_full_201909/lib/python3.7/site-packages/distributed/worker.py", line 857, in <lambda>
    lambda: self.batched_stream.send({"op": "keep-alive"}),
  File "/softs/rh7/conda/4.5.4/envs/pangeo_full_201909/lib/python3.7/site-packages/distributed/batched.py", line 117, in send
    raise CommClosedError
distributed.comm.core.CommClosedError
tornado.application - ERROR - Exception in callback functools.partial(<bound method IOLoop._discard_future_result of <tornado.platform.asyncio.AsyncIOLoop object at 0x2b9fed87bb38>>, <Task finished coro=<Worker.heartbeat() done, defined at /softs/rh7/conda/4.5.4/envs/pangeo_full_201909/lib/python3.7/site-packages/distributed/worker.py:866> exception=OSError("Timed out trying to connect to 'tcp://10.120.40.97:33653' after 10 s: in <distributed.comm.tcp.TCPConnector object at 0x2ba0021ff390>: ConnectionRefusedError: [Errno 111] Connection refused")>)
Traceback (most recent call last):
  File "/softs/rh7/conda/4.5.4/envs/pangeo_full_201909/lib/python3.7/site-packages/distributed/comm/core.py", line 215, in connect
    quiet_exceptions=EnvironmentError,
tornado.util.TimeoutError: Timeout

During handling of the above exception, another exception occurred:

Traceback (most recent call last):
  File "/softs/rh7/conda/4.5.4/envs/pangeo_full_201909/lib/python3.7/site-packages/tornado/ioloop.py", line 743, in _run_callback
    ret = callback()
  File "/softs/rh7/conda/4.5.4/envs/pangeo_full_201909/lib/python3.7/site-packages/tornado/ioloop.py", line 767, in _discard_future_result
    future.result()
  File "/softs/rh7/conda/4.5.4/envs/pangeo_full_201909/lib/python3.7/site-packages/distributed/worker.py", line 875, in heartbeat
    metrics=await self.get_metrics(),
  File "/softs/rh7/conda/4.5.4/envs/pangeo_full_201909/lib/python3.7/site-packages/distributed/core.py", line 747, in send_recv_from_rpc
    comm = await self.pool.connect(self.addr)
  File "/softs/rh7/conda/4.5.4/envs/pangeo_full_201909/lib/python3.7/site-packages/distributed/core.py", line 874, in connect
    connection_args=self.connection_args,
  File "/softs/rh7/conda/4.5.4/envs/pangeo_full_201909/lib/python3.7/site-packages/distributed/comm/core.py", line 227, in connect
    _raise(error)
  File "/softs/rh7/conda/4.5.4/envs/pangeo_full_201909/lib/python3.7/site-packages/distributed/comm/core.py", line 204, in _raise
    raise IOError(msg)
OSError: Timed out trying to connect to 'tcp://10.120.40.97:33653' after 10 s: in <distributed.comm.tcp.TCPConnector object at 0x2ba0021ff390>: ConnectionRefusedError: [Errno 111] Connection refused
tornado.application - ERROR - Exception in callback functools.partial(<bound method IOLoop._discard_future_result of <tornado.platform.asyncio.AsyncIOLoop object at 0x2b9fed87bb38>>, <Task finished coro=<Worker.heartbeat() done, defined at /softs/rh7/conda/4.5.4/envs/pangeo_full_201909/lib/python3.7/site-packages/distributed/worker.py:866> exception=OSError("Timed out trying to connect to 'tcp://10.120.40.97:33653' after 10 s: in <distributed.comm.tcp.TCPConnector object at 0x2ba0021ffd30>: ConnectionRefusedError: [Errno 111] Connection refused")>)
Traceback (most recent call last):
  File "/softs/rh7/conda/4.5.4/envs/pangeo_full_201909/lib/python3.7/site-packages/distributed/comm/core.py", line 215, in connect
    quiet_exceptions=EnvironmentError,
tornado.util.TimeoutError: Timeout

During handling of the above exception, another exception occurred:

Traceback (most recent call last):
  File "/softs/rh7/conda/4.5.4/envs/pangeo_full_201909/lib/python3.7/site-packages/tornado/ioloop.py", line 743, in _run_callback
    ret = callback()
  File "/softs/rh7/conda/4.5.4/envs/pangeo_full_201909/lib/python3.7/site-packages/tornado/ioloop.py", line 767, in _discard_future_result
    future.result()
  File "/softs/rh7/conda/4.5.4/envs/pangeo_full_201909/lib/python3.7/site-packages/distributed/worker.py", line 875, in heartbeat
    metrics=await self.get_metrics(),
  File "/softs/rh7/conda/4.5.4/envs/pangeo_full_201909/lib/python3.7/site-packages/distributed/core.py", line 747, in send_recv_from_rpc
    comm = await self.pool.connect(self.addr)
  File "/softs/rh7/conda/4.5.4/envs/pangeo_full_201909/lib/python3.7/site-packages/distributed/core.py", line 874, in connect
    connection_args=self.connection_args,
  File "/softs/rh7/conda/4.5.4/envs/pangeo_full_201909/lib/python3.7/site-packages/distributed/comm/core.py", line 227, in connect
    _raise(error)
  File "/softs/rh7/conda/4.5.4/envs/pangeo_full_201909/lib/python3.7/site-packages/distributed/comm/core.py", line 204, in _raise
    raise IOError(msg)
OSError: Timed out trying to connect to 'tcp://10.120.40.97:33653' after 10 s: in <distributed.comm.tcp.TCPConnector object at 0x2ba0021ffd30>: ConnectionRefusedError: [Errno 111] Connection refused
tornado.application - ERROR - Exception in callback functools.partial(<bound method IOLoop._discard_future_result of <tornado.platform.asyncio.AsyncIOLoop object at 0x2b9fed87bb38>>, <Task finished coro=<Worker.heartbeat() done, defined at /softs/rh7/conda/4.5.4/envs/pangeo_full_201909/lib/python3.7/site-packages/distributed/worker.py:866> exception=OSError("Timed out trying to connect to 'tcp://10.120.40.97:33653' after 10 s: in <distributed.comm.tcp.TCPConnector object at 0x2ba002f329b0>: ConnectionRefusedError: [Errno 111] Connection refused")>)
Traceback (most recent call last):
  File "/softs/rh7/conda/4.5.4/envs/pangeo_full_201909/lib/python3.7/site-packages/distributed/comm/core.py", line 215, in connect
    quiet_exceptions=EnvironmentError,
tornado.util.TimeoutError: Timeout

During handling of the above exception, another exception occurred:

Traceback (most recent call last):
  File "/softs/rh7/conda/4.5.4/envs/pangeo_full_201909/lib/python3.7/site-packages/tornado/ioloop.py", line 743, in _run_callback
    ret = callback()
  File "/softs/rh7/conda/4.5.4/envs/pangeo_full_201909/lib/python3.7/site-packages/tornado/ioloop.py", line 767, in _discard_future_result
    future.result()
  File "/softs/rh7/conda/4.5.4/envs/pangeo_full_201909/lib/python3.7/site-packages/distributed/worker.py", line 875, in heartbeat
    metrics=await self.get_metrics(),
  File "/softs/rh7/conda/4.5.4/envs/pangeo_full_201909/lib/python3.7/site-packages/distributed/core.py", line 747, in send_recv_from_rpc
    comm = await self.pool.connect(self.addr)
  File "/softs/rh7/conda/4.5.4/envs/pangeo_full_201909/lib/python3.7/site-packages/distributed/core.py", line 874, in connect
    connection_args=self.connection_args,
  File "/softs/rh7/conda/4.5.4/envs/pangeo_full_201909/lib/python3.7/site-packages/distributed/comm/core.py", line 227, in connect
    _raise(error)
  File "/softs/rh7/conda/4.5.4/envs/pangeo_full_201909/lib/python3.7/site-packages/distributed/comm/core.py", line 204, in _raise
    raise IOError(msg)
OSError: Timed out trying to connect to 'tcp://10.120.40.97:33653' after 10 s: in <distributed.comm.tcp.TCPConnector object at 0x2ba002f329b0>: ConnectionRefusedError: [Errno 111] Connection refused
tornado.application - ERROR - Exception in callback functools.partial(<bound method IOLoop._discard_future_result of <tornado.platform.asyncio.AsyncIOLoop object at 0x2b9fed87bb38>>, <Task finished coro=<Worker.heartbeat() done, defined at /softs/rh7/conda/4.5.4/envs/pangeo_full_201909/lib/python3.7/site-packages/distributed/worker.py:866> exception=OSError("Timed out trying to connect to 'tcp://10.120.40.97:33653' after 10 s: in <distributed.comm.tcp.TCPConnector object at 0x2ba00348f7f0>: ConnectionRefusedError: [Errno 111] Connection refused")>)
Traceback (most recent call last):
  File "/softs/rh7/conda/4.5.4/envs/pangeo_full_201909/lib/python3.7/site-packages/distributed/comm/core.py", line 215, in connect
    quiet_exceptions=EnvironmentError,
tornado.util.TimeoutError: Timeout

During handling of the above exception, another exception occurred:

Traceback (most recent call last):
  File "/softs/rh7/conda/4.5.4/envs/pangeo_full_201909/lib/python3.7/site-packages/tornado/ioloop.py", line 743, in _run_callback
    ret = callback()
  File "/softs/rh7/conda/4.5.4/envs/pangeo_full_201909/lib/python3.7/site-packages/tornado/ioloop.py", line 767, in _discard_future_result
    future.result()
  File "/softs/rh7/conda/4.5.4/envs/pangeo_full_201909/lib/python3.7/site-packages/distributed/worker.py", line 875, in heartbeat
    metrics=await self.get_metrics(),
  File "/softs/rh7/conda/4.5.4/envs/pangeo_full_201909/lib/python3.7/site-packages/distributed/core.py", line 747, in send_recv_from_rpc
    comm = await self.pool.connect(self.addr)
  File "/softs/rh7/conda/4.5.4/envs/pangeo_full_201909/lib/python3.7/site-packages/distributed/core.py", line 874, in connect
    connection_args=self.connection_args,
  File "/softs/rh7/conda/4.5.4/envs/pangeo_full_201909/lib/python3.7/site-packages/distributed/comm/core.py", line 227, in connect
    _raise(error)
  File "/softs/rh7/conda/4.5.4/envs/pangeo_full_201909/lib/python3.7/site-packages/distributed/comm/core.py", line 204, in _raise
    raise IOError(msg)
OSError: Timed out trying to connect to 'tcp://10.120.40.97:33653' after 10 s: in <distributed.comm.tcp.TCPConnector object at 0x2ba00348f7f0>: ConnectionRefusedError: [Errno 111] Connection refused
tornado.application - ERROR - Exception in callback functools.partial(<bound method IOLoop._discard_future_result of <tornado.platform.asyncio.AsyncIOLoop object at 0x2b9fed87bb38>>, <Task finished coro=<Worker.heartbeat() done, defined at /softs/rh7/conda/4.5.4/envs/pangeo_full_201909/lib/python3.7/site-packages/distributed/worker.py:866> exception=OSError("Timed out trying to connect to 'tcp://10.120.40.97:33653' after 10 s: in <distributed.comm.tcp.TCPConnector object at 0x2ba0029b06d8>: ConnectionRefusedError: [Errno 111] Connection refused")>)
Traceback (most recent call last):
  File "/softs/rh7/conda/4.5.4/envs/pangeo_full_201909/lib/python3.7/site-packages/distributed/comm/core.py", line 215, in connect
    quiet_exceptions=EnvironmentError,
tornado.util.TimeoutError: Timeout

During handling of the above exception, another exception occurred:

Traceback (most recent call last):
  File "/softs/rh7/conda/4.5.4/envs/pangeo_full_201909/lib/python3.7/site-packages/tornado/ioloop.py", line 743, in _run_callback
    ret = callback()
  File "/softs/rh7/conda/4.5.4/envs/pangeo_full_201909/lib/python3.7/site-packages/tornado/ioloop.py", line 767, in _discard_future_result
    future.result()
  File "/softs/rh7/conda/4.5.4/envs/pangeo_full_201909/lib/python3.7/site-packages/distributed/worker.py", line 875, in heartbeat
    metrics=await self.get_metrics(),
  File "/softs/rh7/conda/4.5.4/envs/pangeo_full_201909/lib/python3.7/site-packages/distributed/core.py", line 747, in send_recv_from_rpc
    comm = await self.pool.connect(self.addr)
  File "/softs/rh7/conda/4.5.4/envs/pangeo_full_201909/lib/python3.7/site-packages/distributed/core.py", line 874, in connect
    connection_args=self.connection_args,
  File "/softs/rh7/conda/4.5.4/envs/pangeo_full_201909/lib/python3.7/site-packages/distributed/comm/core.py", line 227, in connect
    _raise(error)
  File "/softs/rh7/conda/4.5.4/envs/pangeo_full_201909/lib/python3.7/site-packages/distributed/comm/core.py", line 204, in _raise
    raise IOError(msg)
OSError: Timed out trying to connect to 'tcp://10.120.40.97:33653' after 10 s: in <distributed.comm.tcp.TCPConnector object at 0x2ba0029b06d8>: ConnectionRefusedError: [Errno 111] Connection refused
tornado.application - ERROR - Exception in callback functools.partial(<bound method IOLoop._discard_future_result of <tornado.platform.asyncio.AsyncIOLoop object at 0x2b9fed87bb38>>, <Task finished coro=<Worker.heartbeat() done, defined at /softs/rh7/conda/4.5.4/envs/pangeo_full_201909/lib/python3.7/site-packages/distributed/worker.py:866> exception=OSError("Timed out trying to connect to 'tcp://10.120.40.97:33653' after 10 s: in <distributed.comm.tcp.TCPConnector object at 0x2ba00348f898>: ConnectionRefusedError: [Errno 111] Connection refused")>)
Traceback (most recent call last):
  File "/softs/rh7/conda/4.5.4/envs/pangeo_full_201909/lib/python3.7/site-packages/distributed/comm/core.py", line 215, in connect
    quiet_exceptions=EnvironmentError,
tornado.util.TimeoutError: Timeout

During handling of the above exception, another exception occurred:

Traceback (most recent call last):
  File "/softs/rh7/conda/4.5.4/envs/pangeo_full_201909/lib/python3.7/site-packages/tornado/ioloop.py", line 743, in _run_callback
    ret = callback()
  File "/softs/rh7/conda/4.5.4/envs/pangeo_full_201909/lib/python3.7/site-packages/tornado/ioloop.py", line 767, in _discard_future_result
    future.result()
  File "/softs/rh7/conda/4.5.4/envs/pangeo_full_201909/lib/python3.7/site-packages/distributed/worker.py", line 875, in heartbeat
    metrics=await self.get_metrics(),
  File "/softs/rh7/conda/4.5.4/envs/pangeo_full_201909/lib/python3.7/site-packages/distributed/core.py", line 747, in send_recv_from_rpc
    comm = await self.pool.connect(self.addr)
  File "/softs/rh7/conda/4.5.4/envs/pangeo_full_201909/lib/python3.7/site-packages/distributed/core.py", line 874, in connect
    connection_args=self.connection_args,
  File "/softs/rh7/conda/4.5.4/envs/pangeo_full_201909/lib/python3.7/site-packages/distributed/comm/core.py", line 227, in connect
    _raise(error)
  File "/softs/rh7/conda/4.5.4/envs/pangeo_full_201909/lib/python3.7/site-packages/distributed/comm/core.py", line 204, in _raise
    raise IOError(msg)
OSError: Timed out trying to connect to 'tcp://10.120.40.97:33653' after 10 s: in <distributed.comm.tcp.TCPConnector object at 0x2ba00348f898>: ConnectionRefusedError: [Errno 111] Connection refused
tornado.application - ERROR - Exception in callback <function Worker._register_with_scheduler.<locals>.<lambda> at 0x2ba0005ead90>
Traceback (most recent call last):
  File "/softs/rh7/conda/4.5.4/envs/pangeo_full_201909/lib/python3.7/site-packages/tornado/ioloop.py", line 907, in _run
    return self.callback()
  File "/softs/rh7/conda/4.5.4/envs/pangeo_full_201909/lib/python3.7/site-packages/distributed/worker.py", line 857, in <lambda>
    lambda: self.batched_stream.send({"op": "keep-alive"}),
  File "/softs/rh7/conda/4.5.4/envs/pangeo_full_201909/lib/python3.7/site-packages/distributed/batched.py", line 117, in send
    raise CommClosedError
distributed.comm.core.CommClosedError
tornado.application - ERROR - Exception in callback functools.partial(<bound method IOLoop._discard_future_result of <tornado.platform.asyncio.AsyncIOLoop object at 0x2b9fed87bb38>>, <Task finished coro=<Worker.heartbeat() done, defined at /softs/rh7/conda/4.5.4/envs/pangeo_full_201909/lib/python3.7/site-packages/distributed/worker.py:866> exception=OSError("Timed out trying to connect to 'tcp://10.120.40.97:33653' after 10 s: in <distributed.comm.tcp.TCPConnector object at 0x2ba0022515f8>: ConnectionRefusedError: [Errno 111] Connection refused")>)
Traceback (most recent call last):
  File "/softs/rh7/conda/4.5.4/envs/pangeo_full_201909/lib/python3.7/site-packages/distributed/comm/core.py", line 215, in connect
    quiet_exceptions=EnvironmentError,
tornado.util.TimeoutError: Timeout

During handling of the above exception, another exception occurred:

Traceback (most recent call last):
  File "/softs/rh7/conda/4.5.4/envs/pangeo_full_201909/lib/python3.7/site-packages/tornado/ioloop.py", line 743, in _run_callback
    ret = callback()
  File "/softs/rh7/conda/4.5.4/envs/pangeo_full_201909/lib/python3.7/site-packages/tornado/ioloop.py", line 767, in _discard_future_result
    future.result()
  File "/softs/rh7/conda/4.5.4/envs/pangeo_full_201909/lib/python3.7/site-packages/distributed/worker.py", line 875, in heartbeat
    metrics=await self.get_metrics(),
  File "/softs/rh7/conda/4.5.4/envs/pangeo_full_201909/lib/python3.7/site-packages/distributed/core.py", line 747, in send_recv_from_rpc
    comm = await self.pool.connect(self.addr)
  File "/softs/rh7/conda/4.5.4/envs/pangeo_full_201909/lib/python3.7/site-packages/distributed/core.py", line 874, in connect
    connection_args=self.connection_args,
  File "/softs/rh7/conda/4.5.4/envs/pangeo_full_201909/lib/python3.7/site-packages/distributed/comm/core.py", line 227, in connect
    _raise(error)
  File "/softs/rh7/conda/4.5.4/envs/pangeo_full_201909/lib/python3.7/site-packages/distributed/comm/core.py", line 204, in _raise
    raise IOError(msg)
OSError: Timed out trying to connect to 'tcp://10.120.40.97:33653' after 10 s: in <distributed.comm.tcp.TCPConnector object at 0x2ba0022515f8>: ConnectionRefusedError: [Errno 111] Connection refused
tornado.application - ERROR - Exception in callback functools.partial(<bound method IOLoop._discard_future_result of <tornado.platform.asyncio.AsyncIOLoop object at 0x2b9fed87bb38>>, <Task finished coro=<Worker.heartbeat() done, defined at /softs/rh7/conda/4.5.4/envs/pangeo_full_201909/lib/python3.7/site-packages/distributed/worker.py:866> exception=OSError("Timed out trying to connect to 'tcp://10.120.40.97:33653' after 10 s: in <distributed.comm.tcp.TCPConnector object at 0x2ba002b59320>: ConnectionRefusedError: [Errno 111] Connection refused")>)
Traceback (most recent call last):
  File "/softs/rh7/conda/4.5.4/envs/pangeo_full_201909/lib/python3.7/site-packages/distributed/comm/core.py", line 215, in connect
    quiet_exceptions=EnvironmentError,
tornado.util.TimeoutError: Timeout

During handling of the above exception, another exception occurred:

Traceback (most recent call last):
  File "/softs/rh7/conda/4.5.4/envs/pangeo_full_201909/lib/python3.7/site-packages/tornado/ioloop.py", line 743, in _run_callback
    ret = callback()
  File "/softs/rh7/conda/4.5.4/envs/pangeo_full_201909/lib/python3.7/site-packages/tornado/ioloop.py", line 767, in _discard_future_result
    future.result()
  File "/softs/rh7/conda/4.5.4/envs/pangeo_full_201909/lib/python3.7/site-packages/distributed/worker.py", line 875, in heartbeat
    metrics=await self.get_metrics(),
  File "/softs/rh7/conda/4.5.4/envs/pangeo_full_201909/lib/python3.7/site-packages/distributed/core.py", line 747, in send_recv_from_rpc
    comm = await self.pool.connect(self.addr)
  File "/softs/rh7/conda/4.5.4/envs/pangeo_full_201909/lib/python3.7/site-packages/distributed/core.py", line 874, in connect
    connection_args=self.connection_args,
  File "/softs/rh7/conda/4.5.4/envs/pangeo_full_201909/lib/python3.7/site-packages/distributed/comm/core.py", line 227, in connect
    _raise(error)
  File "/softs/rh7/conda/4.5.4/envs/pangeo_full_201909/lib/python3.7/site-packages/distributed/comm/core.py", line 204, in _raise
    raise IOError(msg)
OSError: Timed out trying to connect to 'tcp://10.120.40.97:33653' after 10 s: in <distributed.comm.tcp.TCPConnector object at 0x2ba002b59320>: ConnectionRefusedError: [Errno 111] Connection refused
tornado.application - ERROR - Exception in callback functools.partial(<bound method IOLoop._discard_future_result of <tornado.platform.asyncio.AsyncIOLoop object at 0x2b9fed87bb38>>, <Task finished coro=<Worker.heartbeat() done, defined at /softs/rh7/conda/4.5.4/envs/pangeo_full_201909/lib/python3.7/site-packages/distributed/worker.py:866> exception=OSError("Timed out trying to connect to 'tcp://10.120.40.97:33653' after 10 s: in <distributed.comm.tcp.TCPConnector object at 0x2ba0034b9b38>: ConnectionRefusedError: [Errno 111] Connection refused")>)
Traceback (most recent call last):
  File "/softs/rh7/conda/4.5.4/envs/pangeo_full_201909/lib/python3.7/site-packages/distributed/comm/core.py", line 215, in connect
    quiet_exceptions=EnvironmentError,
tornado.util.TimeoutError: Timeout

During handling of the above exception, another exception occurred:

Traceback (most recent call last):
  File "/softs/rh7/conda/4.5.4/envs/pangeo_full_201909/lib/python3.7/site-packages/tornado/ioloop.py", line 743, in _run_callback
    ret = callback()
  File "/softs/rh7/conda/4.5.4/envs/pangeo_full_201909/lib/python3.7/site-packages/tornado/ioloop.py", line 767, in _discard_future_result
    future.result()
  File "/softs/rh7/conda/4.5.4/envs/pangeo_full_201909/lib/python3.7/site-packages/distributed/worker.py", line 875, in heartbeat
    metrics=await self.get_metrics(),
  File "/softs/rh7/conda/4.5.4/envs/pangeo_full_201909/lib/python3.7/site-packages/distributed/core.py", line 747, in send_recv_from_rpc
    comm = await self.pool.connect(self.addr)
  File "/softs/rh7/conda/4.5.4/envs/pangeo_full_201909/lib/python3.7/site-packages/distributed/core.py", line 874, in connect
    connection_args=self.connection_args,
  File "/softs/rh7/conda/4.5.4/envs/pangeo_full_201909/lib/python3.7/site-packages/distributed/comm/core.py", line 227, in connect
    _raise(error)
  File "/softs/rh7/conda/4.5.4/envs/pangeo_full_201909/lib/python3.7/site-packages/distributed/comm/core.py", line 204, in _raise
    raise IOError(msg)
OSError: Timed out trying to connect to 'tcp://10.120.40.97:33653' after 10 s: in <distributed.comm.tcp.TCPConnector object at 0x2ba0034b9b38>: ConnectionRefusedError: [Errno 111] Connection refused
tornado.application - ERROR - Exception in callback functools.partial(<bound method IOLoop._discard_future_result of <tornado.platform.asyncio.AsyncIOLoop object at 0x2b9fed87bb38>>, <Task finished coro=<Worker.heartbeat() done, defined at /softs/rh7/conda/4.5.4/envs/pangeo_full_201909/lib/python3.7/site-packages/distributed/worker.py:866> exception=OSError("Timed out trying to connect to 'tcp://10.120.40.97:33653' after 10 s: in <distributed.comm.tcp.TCPConnector object at 0x2ba0029b0d30>: ConnectionRefusedError: [Errno 111] Connection refused")>)
Traceback (most recent call last):
  File "/softs/rh7/conda/4.5.4/envs/pangeo_full_201909/lib/python3.7/site-packages/distributed/comm/core.py", line 215, in connect
    quiet_exceptions=EnvironmentError,
tornado.util.TimeoutError: Timeout

During handling of the above exception, another exception occurred:

Traceback (most recent call last):
  File "/softs/rh7/conda/4.5.4/envs/pangeo_full_201909/lib/python3.7/site-packages/tornado/ioloop.py", line 743, in _run_callback
    ret = callback()
  File "/softs/rh7/conda/4.5.4/envs/pangeo_full_201909/lib/python3.7/site-packages/tornado/ioloop.py", line 767, in _discard_future_result
    future.result()
  File "/softs/rh7/conda/4.5.4/envs/pangeo_full_201909/lib/python3.7/site-packages/distributed/worker.py", line 875, in heartbeat
    metrics=await self.get_metrics(),
  File "/softs/rh7/conda/4.5.4/envs/pangeo_full_201909/lib/python3.7/site-packages/distributed/core.py", line 747, in send_recv_from_rpc
    comm = await self.pool.connect(self.addr)
  File "/softs/rh7/conda/4.5.4/envs/pangeo_full_201909/lib/python3.7/site-packages/distributed/core.py", line 874, in connect
    connection_args=self.connection_args,
  File "/softs/rh7/conda/4.5.4/envs/pangeo_full_201909/lib/python3.7/site-packages/distributed/comm/core.py", line 227, in connect
    _raise(error)
  File "/softs/rh7/conda/4.5.4/envs/pangeo_full_201909/lib/python3.7/site-packages/distributed/comm/core.py", line 204, in _raise
    raise IOError(msg)
OSError: Timed out trying to connect to 'tcp://10.120.40.97:33653' after 10 s: in <distributed.comm.tcp.TCPConnector object at 0x2ba0029b0d30>: ConnectionRefusedError: [Errno 111] Connection refused
tornado.application - ERROR - Exception in callback functools.partial(<bound method IOLoop._discard_future_result of <tornado.platform.asyncio.AsyncIOLoop object at 0x2b9fed87bb38>>, <Task finished coro=<Worker.heartbeat() done, defined at /softs/rh7/conda/4.5.4/envs/pangeo_full_201909/lib/python3.7/site-packages/distributed/worker.py:866> exception=OSError("Timed out trying to connect to 'tcp://10.120.40.97:33653' after 10 s: in <distributed.comm.tcp.TCPConnector object at 0x2ba002f32a90>: ConnectionRefusedError: [Errno 111] Connection refused")>)
Traceback (most recent call last):
  File "/softs/rh7/conda/4.5.4/envs/pangeo_full_201909/lib/python3.7/site-packages/distributed/comm/core.py", line 215, in connect
    quiet_exceptions=EnvironmentError,
tornado.util.TimeoutError: Timeout

During handling of the above exception, another exception occurred:

Traceback (most recent call last):
  File "/softs/rh7/conda/4.5.4/envs/pangeo_full_201909/lib/python3.7/site-packages/tornado/ioloop.py", line 743, in _run_callback
    ret = callback()
  File "/softs/rh7/conda/4.5.4/envs/pangeo_full_201909/lib/python3.7/site-packages/tornado/ioloop.py", line 767, in _discard_future_result
    future.result()
  File "/softs/rh7/conda/4.5.4/envs/pangeo_full_201909/lib/python3.7/site-packages/distributed/worker.py", line 875, in heartbeat
    metrics=await self.get_metrics(),
  File "/softs/rh7/conda/4.5.4/envs/pangeo_full_201909/lib/python3.7/site-packages/distributed/core.py", line 747, in send_recv_from_rpc
    comm = await self.pool.connect(self.addr)
  File "/softs/rh7/conda/4.5.4/envs/pangeo_full_201909/lib/python3.7/site-packages/distributed/core.py", line 874, in connect
    connection_args=self.connection_args,
  File "/softs/rh7/conda/4.5.4/envs/pangeo_full_201909/lib/python3.7/site-packages/distributed/comm/core.py", line 227, in connect
    _raise(error)
  File "/softs/rh7/conda/4.5.4/envs/pangeo_full_201909/lib/python3.7/site-packages/distributed/comm/core.py", line 204, in _raise
    raise IOError(msg)
OSError: Timed out trying to connect to 'tcp://10.120.40.97:33653' after 10 s: in <distributed.comm.tcp.TCPConnector object at 0x2ba002f32a90>: ConnectionRefusedError: [Errno 111] Connection refused
tornado.application - ERROR - Exception in callback <function Worker._register_with_scheduler.<locals>.<lambda> at 0x2ba0005ead90>
Traceback (most recent call last):
  File "/softs/rh7/conda/4.5.4/envs/pangeo_full_201909/lib/python3.7/site-packages/tornado/ioloop.py", line 907, in _run
    return self.callback()
  File "/softs/rh7/conda/4.5.4/envs/pangeo_full_201909/lib/python3.7/site-packages/distributed/worker.py", line 857, in <lambda>
    lambda: self.batched_stream.send({"op": "keep-alive"}),
  File "/softs/rh7/conda/4.5.4/envs/pangeo_full_201909/lib/python3.7/site-packages/distributed/batched.py", line 117, in send
    raise CommClosedError
distributed.comm.core.CommClosedError
tornado.application - ERROR - Exception in callback functools.partial(<bound method IOLoop._discard_future_result of <tornado.platform.asyncio.AsyncIOLoop object at 0x2b9fed87bb38>>, <Task finished coro=<Worker.heartbeat() done, defined at /softs/rh7/conda/4.5.4/envs/pangeo_full_201909/lib/python3.7/site-packages/distributed/worker.py:866> exception=OSError("Timed out trying to connect to 'tcp://10.120.40.97:33653' after 10 s: in <distributed.comm.tcp.TCPConnector object at 0x2ba002e59400>: ConnectionRefusedError: [Errno 111] Connection refused")>)
Traceback (most recent call last):
  File "/softs/rh7/conda/4.5.4/envs/pangeo_full_201909/lib/python3.7/site-packages/distributed/comm/core.py", line 215, in connect
    quiet_exceptions=EnvironmentError,
tornado.util.TimeoutError: Timeout

During handling of the above exception, another exception occurred:

Traceback (most recent call last):
  File "/softs/rh7/conda/4.5.4/envs/pangeo_full_201909/lib/python3.7/site-packages/tornado/ioloop.py", line 743, in _run_callback
    ret = callback()
  File "/softs/rh7/conda/4.5.4/envs/pangeo_full_201909/lib/python3.7/site-packages/tornado/ioloop.py", line 767, in _discard_future_result
    future.result()
  File "/softs/rh7/conda/4.5.4/envs/pangeo_full_201909/lib/python3.7/site-packages/distributed/worker.py", line 875, in heartbeat
    metrics=await self.get_metrics(),
  File "/softs/rh7/conda/4.5.4/envs/pangeo_full_201909/lib/python3.7/site-packages/distributed/core.py", line 747, in send_recv_from_rpc
    comm = await self.pool.connect(self.addr)
  File "/softs/rh7/conda/4.5.4/envs/pangeo_full_201909/lib/python3.7/site-packages/distributed/core.py", line 874, in connect
    connection_args=self.connection_args,
  File "/softs/rh7/conda/4.5.4/envs/pangeo_full_201909/lib/python3.7/site-packages/distributed/comm/core.py", line 227, in connect
    _raise(error)
  File "/softs/rh7/conda/4.5.4/envs/pangeo_full_201909/lib/python3.7/site-packages/distributed/comm/core.py", line 204, in _raise
    raise IOError(msg)
OSError: Timed out trying to connect to 'tcp://10.120.40.97:33653' after 10 s: in <distributed.comm.tcp.TCPConnector object at 0x2ba002e59400>: ConnectionRefusedError: [Errno 111] Connection refused
tornado.application - ERROR - Exception in callback functools.partial(<bound method IOLoop._discard_future_result of <tornado.platform.asyncio.AsyncIOLoop object at 0x2b9fed87bb38>>, <Task finished coro=<Worker.heartbeat() done, defined at /softs/rh7/conda/4.5.4/envs/pangeo_full_201909/lib/python3.7/site-packages/distributed/worker.py:866> exception=OSError("Timed out trying to connect to 'tcp://10.120.40.97:33653' after 10 s: in <distributed.comm.tcp.TCPConnector object at 0x2ba002e593c8>: ConnectionRefusedError: [Errno 111] Connection refused")>)
Traceback (most recent call last):
  File "/softs/rh7/conda/4.5.4/envs/pangeo_full_201909/lib/python3.7/site-packages/distributed/comm/core.py", line 215, in connect
    quiet_exceptions=EnvironmentError,
tornado.util.TimeoutError: Timeout

During handling of the above exception, another exception occurred:

Traceback (most recent call last):
  File "/softs/rh7/conda/4.5.4/envs/pangeo_full_201909/lib/python3.7/site-packages/tornado/ioloop.py", line 743, in _run_callback
    ret = callback()
  File "/softs/rh7/conda/4.5.4/envs/pangeo_full_201909/lib/python3.7/site-packages/tornado/ioloop.py", line 767, in _discard_future_result
    future.result()
  File "/softs/rh7/conda/4.5.4/envs/pangeo_full_201909/lib/python3.7/site-packages/distributed/worker.py", line 875, in heartbeat
    metrics=await self.get_metrics(),
  File "/softs/rh7/conda/4.5.4/envs/pangeo_full_201909/lib/python3.7/site-packages/distributed/core.py", line 747, in send_recv_from_rpc
    comm = await self.pool.connect(self.addr)
  File "/softs/rh7/conda/4.5.4/envs/pangeo_full_201909/lib/python3.7/site-packages/distributed/core.py", line 874, in connect
    connection_args=self.connection_args,
  File "/softs/rh7/conda/4.5.4/envs/pangeo_full_201909/lib/python3.7/site-packages/distributed/comm/core.py", line 227, in connect
    _raise(error)
  File "/softs/rh7/conda/4.5.4/envs/pangeo_full_201909/lib/python3.7/site-packages/distributed/comm/core.py", line 204, in _raise
    raise IOError(msg)
OSError: Timed out trying to connect to 'tcp://10.120.40.97:33653' after 10 s: in <distributed.comm.tcp.TCPConnector object at 0x2ba002e593c8>: ConnectionRefusedError: [Errno 111] Connection refused
tornado.application - ERROR - Exception in callback functools.partial(<bound method IOLoop._discard_future_result of <tornado.platform.asyncio.AsyncIOLoop object at 0x2b9fed87bb38>>, <Task finished coro=<Worker.heartbeat() done, defined at /softs/rh7/conda/4.5.4/envs/pangeo_full_201909/lib/python3.7/site-packages/distributed/worker.py:866> exception=OSError("Timed out trying to connect to 'tcp://10.120.40.97:33653' after 10 s: in <distributed.comm.tcp.TCPConnector object at 0x2ba002f32e80>: ConnectionRefusedError: [Errno 111] Connection refused")>)
Traceback (most recent call last):
  File "/softs/rh7/conda/4.5.4/envs/pangeo_full_201909/lib/python3.7/site-packages/distributed/comm/core.py", line 215, in connect
    quiet_exceptions=EnvironmentError,
tornado.util.TimeoutError: Timeout

During handling of the above exception, another exception occurred:

Traceback (most recent call last):
  File "/softs/rh7/conda/4.5.4/envs/pangeo_full_201909/lib/python3.7/site-packages/tornado/ioloop.py", line 743, in _run_callback
    ret = callback()
  File "/softs/rh7/conda/4.5.4/envs/pangeo_full_201909/lib/python3.7/site-packages/tornado/ioloop.py", line 767, in _discard_future_result
    future.result()
  File "/softs/rh7/conda/4.5.4/envs/pangeo_full_201909/lib/python3.7/site-packages/distributed/worker.py", line 875, in heartbeat
    metrics=await self.get_metrics(),
  File "/softs/rh7/conda/4.5.4/envs/pangeo_full_201909/lib/python3.7/site-packages/distributed/core.py", line 747, in send_recv_from_rpc
    comm = await self.pool.connect(self.addr)
  File "/softs/rh7/conda/4.5.4/envs/pangeo_full_201909/lib/python3.7/site-packages/distributed/core.py", line 874, in connect
    connection_args=self.connection_args,
  File "/softs/rh7/conda/4.5.4/envs/pangeo_full_201909/lib/python3.7/site-packages/distributed/comm/core.py", line 227, in connect
    _raise(error)
  File "/softs/rh7/conda/4.5.4/envs/pangeo_full_201909/lib/python3.7/site-packages/distributed/comm/core.py", line 204, in _raise
    raise IOError(msg)
OSError: Timed out trying to connect to 'tcp://10.120.40.97:33653' after 10 s: in <distributed.comm.tcp.TCPConnector object at 0x2ba002f32e80>: ConnectionRefusedError: [Errno 111] Connection refused
tornado.application - ERROR - Exception in callback functools.partial(<bound method IOLoop._discard_future_result of <tornado.platform.asyncio.AsyncIOLoop object at 0x2b9fed87bb38>>, <Task finished coro=<Worker.heartbeat() done, defined at /softs/rh7/conda/4.5.4/envs/pangeo_full_201909/lib/python3.7/site-packages/distributed/worker.py:866> exception=OSError("Timed out trying to connect to 'tcp://10.120.40.97:33653' after 10 s: in <distributed.comm.tcp.TCPConnector object at 0x2ba002b59da0>: ConnectionRefusedError: [Errno 111] Connection refused")>)
Traceback (most recent call last):
  File "/softs/rh7/conda/4.5.4/envs/pangeo_full_201909/lib/python3.7/site-packages/distributed/comm/core.py", line 215, in connect
    quiet_exceptions=EnvironmentError,
tornado.util.TimeoutError: Timeout

During handling of the above exception, another exception occurred:

Traceback (most recent call last):
  File "/softs/rh7/conda/4.5.4/envs/pangeo_full_201909/lib/python3.7/site-packages/tornado/ioloop.py", line 743, in _run_callback
    ret = callback()
  File "/softs/rh7/conda/4.5.4/envs/pangeo_full_201909/lib/python3.7/site-packages/tornado/ioloop.py", line 767, in _discard_future_result
    future.result()
  File "/softs/rh7/conda/4.5.4/envs/pangeo_full_201909/lib/python3.7/site-packages/distributed/worker.py", line 875, in heartbeat
    metrics=await self.get_metrics(),
  File "/softs/rh7/conda/4.5.4/envs/pangeo_full_201909/lib/python3.7/site-packages/distributed/core.py", line 747, in send_recv_from_rpc
    comm = await self.pool.connect(self.addr)
  File "/softs/rh7/conda/4.5.4/envs/pangeo_full_201909/lib/python3.7/site-packages/distributed/core.py", line 874, in connect
    connection_args=self.connection_args,
  File "/softs/rh7/conda/4.5.4/envs/pangeo_full_201909/lib/python3.7/site-packages/distributed/comm/core.py", line 227, in connect
    _raise(error)
  File "/softs/rh7/conda/4.5.4/envs/pangeo_full_201909/lib/python3.7/site-packages/distributed/comm/core.py", line 204, in _raise
    raise IOError(msg)
OSError: Timed out trying to connect to 'tcp://10.120.40.97:33653' after 10 s: in <distributed.comm.tcp.TCPConnector object at 0x2ba002b59da0>: ConnectionRefusedError: [Errno 111] Connection refused
tornado.application - ERROR - Exception in callback functools.partial(<bound method IOLoop._discard_future_result of <tornado.platform.asyncio.AsyncIOLoop object at 0x2b9fed87bb38>>, <Task finished coro=<Worker.heartbeat() done, defined at /softs/rh7/conda/4.5.4/envs/pangeo_full_201909/lib/python3.7/site-packages/distributed/worker.py:866> exception=OSError("Timed out trying to connect to 'tcp://10.120.40.97:33653' after 10 s: in <distributed.comm.tcp.TCPConnector object at 0x2ba002b59a20>: ConnectionRefusedError: [Errno 111] Connection refused")>)
Traceback (most recent call last):
  File "/softs/rh7/conda/4.5.4/envs/pangeo_full_201909/lib/python3.7/site-packages/distributed/comm/core.py", line 215, in connect
    quiet_exceptions=EnvironmentError,
tornado.util.TimeoutError: Timeout

During handling of the above exception, another exception occurred:

Traceback (most recent call last):
  File "/softs/rh7/conda/4.5.4/envs/pangeo_full_201909/lib/python3.7/site-packages/tornado/ioloop.py", line 743, in _run_callback
    ret = callback()
  File "/softs/rh7/conda/4.5.4/envs/pangeo_full_201909/lib/python3.7/site-packages/tornado/ioloop.py", line 767, in _discard_future_result
    future.result()
  File "/softs/rh7/conda/4.5.4/envs/pangeo_full_201909/lib/python3.7/site-packages/distributed/worker.py", line 875, in heartbeat
    metrics=await self.get_metrics(),
  File "/softs/rh7/conda/4.5.4/envs/pangeo_full_201909/lib/python3.7/site-packages/distributed/core.py", line 747, in send_recv_from_rpc
    comm = await self.pool.connect(self.addr)
  File "/softs/rh7/conda/4.5.4/envs/pangeo_full_201909/lib/python3.7/site-packages/distributed/core.py", line 874, in connect
    connection_args=self.connection_args,
  File "/softs/rh7/conda/4.5.4/envs/pangeo_full_201909/lib/python3.7/site-packages/distributed/comm/core.py", line 227, in connect
    _raise(error)
  File "/softs/rh7/conda/4.5.4/envs/pangeo_full_201909/lib/python3.7/site-packages/distributed/comm/core.py", line 204, in _raise
    raise IOError(msg)
OSError: Timed out trying to connect to 'tcp://10.120.40.97:33653' after 10 s: in <distributed.comm.tcp.TCPConnector object at 0x2ba002b59a20>: ConnectionRefusedError: [Errno 111] Connection refused
tornado.application - ERROR - Exception in callback functools.partial(<bound method IOLoop._discard_future_result of <tornado.platform.asyncio.AsyncIOLoop object at 0x2b9fed87bb38>>, <Task finished coro=<Worker.heartbeat() done, defined at /softs/rh7/conda/4.5.4/envs/pangeo_full_201909/lib/python3.7/site-packages/distributed/worker.py:866> exception=OSError("Timed out trying to connect to 'tcp://10.120.40.97:33653' after 10 s: in <distributed.comm.tcp.TCPConnector object at 0x2ba002e59128>: ConnectionRefusedError: [Errno 111] Connection refused")>)
Traceback (most recent call last):
  File "/softs/rh7/conda/4.5.4/envs/pangeo_full_201909/lib/python3.7/site-packages/distributed/comm/core.py", line 215, in connect
    quiet_exceptions=EnvironmentError,
tornado.util.TimeoutError: Timeout

During handling of the above exception, another exception occurred:

Traceback (most recent call last):
  File "/softs/rh7/conda/4.5.4/envs/pangeo_full_201909/lib/python3.7/site-packages/tornado/ioloop.py", line 743, in _run_callback
    ret = callback()
  File "/softs/rh7/conda/4.5.4/envs/pangeo_full_201909/lib/python3.7/site-packages/tornado/ioloop.py", line 767, in _discard_future_result
    future.result()
  File "/softs/rh7/conda/4.5.4/envs/pangeo_full_201909/lib/python3.7/site-packages/distributed/worker.py", line 875, in heartbeat
    metrics=await self.get_metrics(),
  File "/softs/rh7/conda/4.5.4/envs/pangeo_full_201909/lib/python3.7/site-packages/distributed/core.py", line 747, in send_recv_from_rpc
    comm = await self.pool.connect(self.addr)
  File "/softs/rh7/conda/4.5.4/envs/pangeo_full_201909/lib/python3.7/site-packages/distributed/core.py", line 874, in connect
    connection_args=self.connection_args,
  File "/softs/rh7/conda/4.5.4/envs/pangeo_full_201909/lib/python3.7/site-packages/distributed/comm/core.py", line 227, in connect
    _raise(error)
  File "/softs/rh7/conda/4.5.4/envs/pangeo_full_201909/lib/python3.7/site-packages/distributed/comm/core.py", line 204, in _raise
    raise IOError(msg)
OSError: Timed out trying to connect to 'tcp://10.120.40.97:33653' after 10 s: in <distributed.comm.tcp.TCPConnector object at 0x2ba002e59128>: ConnectionRefusedError: [Errno 111] Connection refused
tornado.application - ERROR - Exception in callback <function Worker._register_with_scheduler.<locals>.<lambda> at 0x2ba0005ead90>
Traceback (most recent call last):
  File "/softs/rh7/conda/4.5.4/envs/pangeo_full_201909/lib/python3.7/site-packages/tornado/ioloop.py", line 907, in _run
    return self.callback()
  File "/softs/rh7/conda/4.5.4/envs/pangeo_full_201909/lib/python3.7/site-packages/distributed/worker.py", line 857, in <lambda>
    lambda: self.batched_stream.send({"op": "keep-alive"}),
  File "/softs/rh7/conda/4.5.4/envs/pangeo_full_201909/lib/python3.7/site-packages/distributed/batched.py", line 117, in send
    raise CommClosedError
distributed.comm.core.CommClosedError
tornado.application - ERROR - Exception in callback functools.partial(<bound method IOLoop._discard_future_result of <tornado.platform.asyncio.AsyncIOLoop object at 0x2b9fed87bb38>>, <Task finished coro=<Worker.heartbeat() done, defined at /softs/rh7/conda/4.5.4/envs/pangeo_full_201909/lib/python3.7/site-packages/distributed/worker.py:866> exception=OSError("Timed out trying to connect to 'tcp://10.120.40.97:33653' after 10 s: in <distributed.comm.tcp.TCPConnector object at 0x2ba00350f128>: ConnectionRefusedError: [Errno 111] Connection refused")>)
Traceback (most recent call last):
  File "/softs/rh7/conda/4.5.4/envs/pangeo_full_201909/lib/python3.7/site-packages/distributed/comm/core.py", line 215, in connect
    quiet_exceptions=EnvironmentError,
tornado.util.TimeoutError: Timeout

During handling of the above exception, another exception occurred:

Traceback (most recent call last):
  File "/softs/rh7/conda/4.5.4/envs/pangeo_full_201909/lib/python3.7/site-packages/tornado/ioloop.py", line 743, in _run_callback
    ret = callback()
  File "/softs/rh7/conda/4.5.4/envs/pangeo_full_201909/lib/python3.7/site-packages/tornado/ioloop.py", line 767, in _discard_future_result
    future.result()
  File "/softs/rh7/conda/4.5.4/envs/pangeo_full_201909/lib/python3.7/site-packages/distributed/worker.py", line 875, in heartbeat
    metrics=await self.get_metrics(),
  File "/softs/rh7/conda/4.5.4/envs/pangeo_full_201909/lib/python3.7/site-packages/distributed/core.py", line 747, in send_recv_from_rpc
    comm = await self.pool.connect(self.addr)
  File "/softs/rh7/conda/4.5.4/envs/pangeo_full_201909/lib/python3.7/site-packages/distributed/core.py", line 874, in connect
    connection_args=self.connection_args,
  File "/softs/rh7/conda/4.5.4/envs/pangeo_full_201909/lib/python3.7/site-packages/distributed/comm/core.py", line 227, in connect
    _raise(error)
  File "/softs/rh7/conda/4.5.4/envs/pangeo_full_201909/lib/python3.7/site-packages/distributed/comm/core.py", line 204, in _raise
    raise IOError(msg)
OSError: Timed out trying to connect to 'tcp://10.120.40.97:33653' after 10 s: in <distributed.comm.tcp.TCPConnector object at 0x2ba00350f128>: ConnectionRefusedError: [Errno 111] Connection refused
=>> PBS: job killed: walltime 1819 exceeded limit 1800
distributed.nanny - INFO - Worker process 15618 was killed by unknown signal
distributed.dask_worker - INFO - Exiting on signal 15
distributed.nanny - INFO - Closing Nanny at 'tcp://10.120.40.58:43553'
distributed.dask_worker - INFO - End worker
Traceback (most recent call last):
  File "/softs/rh7/conda/4.5.4/envs/pangeo_full_201909/lib/python3.7/runpy.py", line 193, in _run_module_as_main
    "__main__", mod_spec)
  File "/softs/rh7/conda/4.5.4/envs/pangeo_full_201909/lib/python3.7/runpy.py", line 85, in _run_code
    exec(code, run_globals)
  File "/softs/rh7/conda/4.5.4/envs/pangeo_full_201909/lib/python3.7/site-packages/distributed/cli/dask_worker.py", line 410, in <module>
    go()
  File "/softs/rh7/conda/4.5.4/envs/pangeo_full_201909/lib/python3.7/site-packages/distributed/cli/dask_worker.py", line 406, in go
    main()
  File "/softs/rh7/conda/4.5.4/envs/pangeo_full_201909/lib/python3.7/site-packages/click/core.py", line 764, in __call__
    return self.main(*args, **kwargs)
  File "/softs/rh7/conda/4.5.4/envs/pangeo_full_201909/lib/python3.7/site-packages/click/core.py", line 717, in main
    rv = self.invoke(ctx)
  File "/softs/rh7/conda/4.5.4/envs/pangeo_full_201909/lib/python3.7/site-packages/click/core.py", line 956, in invoke
    return ctx.invoke(self.callback, **ctx.params)
  File "/softs/rh7/conda/4.5.4/envs/pangeo_full_201909/lib/python3.7/site-packages/click/core.py", line 555, in invoke
    return callback(*args, **kwargs)
  File "/softs/rh7/conda/4.5.4/envs/pangeo_full_201909/lib/python3.7/site-packages/distributed/cli/dask_worker.py", line 397, in main
    raise TimeoutError("Timed out starting worker.") from None
tornado.util.TimeoutError: Timed out starting worker.
