distributed.nanny - INFO -         Start Nanny at: 'tcp://10.120.40.64:38823'
distributed.worker - INFO -       Start worker at:   tcp://10.120.40.64:46667
distributed.worker - INFO -          Listening to:   tcp://10.120.40.64:46667
distributed.worker - INFO -          dashboard at:         10.120.40.64:33409
distributed.worker - INFO - Waiting to connect to:   tcp://10.120.40.97:33653
distributed.worker - INFO - -------------------------------------------------
distributed.worker - INFO -               Threads:                          1
distributed.worker - INFO -                Memory:                  120.00 GB
distributed.worker - INFO -       Local Directory: /tmp/pbs.6182537.admin01/worker-bvl7kk4d
distributed.worker - INFO - -------------------------------------------------
distributed.worker - INFO -         Registered to:   tcp://10.120.40.97:33653
distributed.worker - INFO - -------------------------------------------------
distributed.core - INFO - Starting established connection
/softs/rh7/conda/4.5.4/envs/pangeo_full_201909/lib/python3.7/site-packages/dask/core.py:119: RuntimeWarning: invalid value encountered in less
  return func(*args2)
distributed.worker - INFO - Connection to scheduler broken.  Reconnecting...
distributed.worker - WARNING - Heartbeat to scheduler failed
distributed.worker - WARNING - Heartbeat to scheduler failed
tornado.application - ERROR - Exception in callback functools.partial(<bound method IOLoop._discard_future_result of <tornado.platform.asyncio.AsyncIOLoop object at 0x2b37e7ab2b38>>, <Task finished coro=<Worker.heartbeat() done, defined at /softs/rh7/conda/4.5.4/envs/pangeo_full_201909/lib/python3.7/site-packages/distributed/worker.py:866> exception=OSError("Timed out trying to connect to 'tcp://10.120.40.97:33653' after 10 s: in <distributed.comm.tcp.TCPConnector object at 0x2b37fac23630>: ConnectionRefusedError: [Errno 111] Connection refused")>)
Traceback (most recent call last):
  File "/softs/rh7/conda/4.5.4/envs/pangeo_full_201909/lib/python3.7/site-packages/distributed/comm/core.py", line 215, in connect
    quiet_exceptions=EnvironmentError,
tornado.util.TimeoutError: Timeout

During handling of the above exception, another exception occurred:

Traceback (most recent call last):
  File "/softs/rh7/conda/4.5.4/envs/pangeo_full_201909/lib/python3.7/site-packages/tornado/ioloop.py", line 743, in _run_callback
    ret = callback()
  File "/softs/rh7/conda/4.5.4/envs/pangeo_full_201909/lib/python3.7/site-packages/tornado/ioloop.py", line 767, in _discard_future_result
    future.result()
  File "/softs/rh7/conda/4.5.4/envs/pangeo_full_201909/lib/python3.7/site-packages/distributed/worker.py", line 875, in heartbeat
    metrics=await self.get_metrics(),
  File "/softs/rh7/conda/4.5.4/envs/pangeo_full_201909/lib/python3.7/site-packages/distributed/core.py", line 747, in send_recv_from_rpc
    comm = await self.pool.connect(self.addr)
  File "/softs/rh7/conda/4.5.4/envs/pangeo_full_201909/lib/python3.7/site-packages/distributed/core.py", line 874, in connect
    connection_args=self.connection_args,
  File "/softs/rh7/conda/4.5.4/envs/pangeo_full_201909/lib/python3.7/site-packages/distributed/comm/core.py", line 227, in connect
    _raise(error)
  File "/softs/rh7/conda/4.5.4/envs/pangeo_full_201909/lib/python3.7/site-packages/distributed/comm/core.py", line 204, in _raise
    raise IOError(msg)
OSError: Timed out trying to connect to 'tcp://10.120.40.97:33653' after 10 s: in <distributed.comm.tcp.TCPConnector object at 0x2b37fac23630>: ConnectionRefusedError: [Errno 111] Connection refused
tornado.application - ERROR - Exception in callback functools.partial(<bound method IOLoop._discard_future_result of <tornado.platform.asyncio.AsyncIOLoop object at 0x2b37e7ab2b38>>, <Task finished coro=<Worker.heartbeat() done, defined at /softs/rh7/conda/4.5.4/envs/pangeo_full_201909/lib/python3.7/site-packages/distributed/worker.py:866> exception=OSError("Timed out trying to connect to 'tcp://10.120.40.97:33653' after 10 s: in <distributed.comm.tcp.TCPConnector object at 0x2b38109323c8>: ConnectionRefusedError: [Errno 111] Connection refused")>)
Traceback (most recent call last):
  File "/softs/rh7/conda/4.5.4/envs/pangeo_full_201909/lib/python3.7/site-packages/distributed/comm/core.py", line 215, in connect
    quiet_exceptions=EnvironmentError,
tornado.util.TimeoutError: Timeout

During handling of the above exception, another exception occurred:

Traceback (most recent call last):
  File "/softs/rh7/conda/4.5.4/envs/pangeo_full_201909/lib/python3.7/site-packages/tornado/ioloop.py", line 743, in _run_callback
    ret = callback()
  File "/softs/rh7/conda/4.5.4/envs/pangeo_full_201909/lib/python3.7/site-packages/tornado/ioloop.py", line 767, in _discard_future_result
    future.result()
  File "/softs/rh7/conda/4.5.4/envs/pangeo_full_201909/lib/python3.7/site-packages/distributed/worker.py", line 875, in heartbeat
    metrics=await self.get_metrics(),
  File "/softs/rh7/conda/4.5.4/envs/pangeo_full_201909/lib/python3.7/site-packages/distributed/core.py", line 747, in send_recv_from_rpc
    comm = await self.pool.connect(self.addr)
  File "/softs/rh7/conda/4.5.4/envs/pangeo_full_201909/lib/python3.7/site-packages/distributed/core.py", line 874, in connect
    connection_args=self.connection_args,
  File "/softs/rh7/conda/4.5.4/envs/pangeo_full_201909/lib/python3.7/site-packages/distributed/comm/core.py", line 227, in connect
    _raise(error)
  File "/softs/rh7/conda/4.5.4/envs/pangeo_full_201909/lib/python3.7/site-packages/distributed/comm/core.py", line 204, in _raise
    raise IOError(msg)
OSError: Timed out trying to connect to 'tcp://10.120.40.97:33653' after 10 s: in <distributed.comm.tcp.TCPConnector object at 0x2b38109323c8>: ConnectionRefusedError: [Errno 111] Connection refused
tornado.application - ERROR - Exception in callback functools.partial(<bound method IOLoop._discard_future_result of <tornado.platform.asyncio.AsyncIOLoop object at 0x2b37e7ab2b38>>, <Task finished coro=<Worker.heartbeat() done, defined at /softs/rh7/conda/4.5.4/envs/pangeo_full_201909/lib/python3.7/site-packages/distributed/worker.py:866> exception=OSError("Timed out trying to connect to 'tcp://10.120.40.97:33653' after 10 s: in <distributed.comm.tcp.TCPConnector object at 0x2b3810e9a1d0>: ConnectionRefusedError: [Errno 111] Connection refused")>)
Traceback (most recent call last):
  File "/softs/rh7/conda/4.5.4/envs/pangeo_full_201909/lib/python3.7/site-packages/distributed/comm/core.py", line 215, in connect
    quiet_exceptions=EnvironmentError,
tornado.util.TimeoutError: Timeout

During handling of the above exception, another exception occurred:

Traceback (most recent call last):
  File "/softs/rh7/conda/4.5.4/envs/pangeo_full_201909/lib/python3.7/site-packages/tornado/ioloop.py", line 743, in _run_callback
    ret = callback()
  File "/softs/rh7/conda/4.5.4/envs/pangeo_full_201909/lib/python3.7/site-packages/tornado/ioloop.py", line 767, in _discard_future_result
    future.result()
  File "/softs/rh7/conda/4.5.4/envs/pangeo_full_201909/lib/python3.7/site-packages/distributed/worker.py", line 875, in heartbeat
    metrics=await self.get_metrics(),
  File "/softs/rh7/conda/4.5.4/envs/pangeo_full_201909/lib/python3.7/site-packages/distributed/core.py", line 747, in send_recv_from_rpc
    comm = await self.pool.connect(self.addr)
  File "/softs/rh7/conda/4.5.4/envs/pangeo_full_201909/lib/python3.7/site-packages/distributed/core.py", line 874, in connect
    connection_args=self.connection_args,
  File "/softs/rh7/conda/4.5.4/envs/pangeo_full_201909/lib/python3.7/site-packages/distributed/comm/core.py", line 227, in connect
    _raise(error)
  File "/softs/rh7/conda/4.5.4/envs/pangeo_full_201909/lib/python3.7/site-packages/distributed/comm/core.py", line 204, in _raise
    raise IOError(msg)
OSError: Timed out trying to connect to 'tcp://10.120.40.97:33653' after 10 s: in <distributed.comm.tcp.TCPConnector object at 0x2b3810e9a1d0>: ConnectionRefusedError: [Errno 111] Connection refused
tornado.application - ERROR - Exception in callback functools.partial(<bound method IOLoop._discard_future_result of <tornado.platform.asyncio.AsyncIOLoop object at 0x2b37e7ab2b38>>, <Task finished coro=<Worker.heartbeat() done, defined at /softs/rh7/conda/4.5.4/envs/pangeo_full_201909/lib/python3.7/site-packages/distributed/worker.py:866> exception=OSError("Timed out trying to connect to 'tcp://10.120.40.97:33653' after 10 s: in <distributed.comm.tcp.TCPConnector object at 0x2b3811101d30>: ConnectionRefusedError: [Errno 111] Connection refused")>)
Traceback (most recent call last):
  File "/softs/rh7/conda/4.5.4/envs/pangeo_full_201909/lib/python3.7/site-packages/distributed/comm/core.py", line 215, in connect
    quiet_exceptions=EnvironmentError,
tornado.util.TimeoutError: Timeout

During handling of the above exception, another exception occurred:

Traceback (most recent call last):
  File "/softs/rh7/conda/4.5.4/envs/pangeo_full_201909/lib/python3.7/site-packages/tornado/ioloop.py", line 743, in _run_callback
    ret = callback()
  File "/softs/rh7/conda/4.5.4/envs/pangeo_full_201909/lib/python3.7/site-packages/tornado/ioloop.py", line 767, in _discard_future_result
    future.result()
  File "/softs/rh7/conda/4.5.4/envs/pangeo_full_201909/lib/python3.7/site-packages/distributed/worker.py", line 875, in heartbeat
    metrics=await self.get_metrics(),
  File "/softs/rh7/conda/4.5.4/envs/pangeo_full_201909/lib/python3.7/site-packages/distributed/core.py", line 747, in send_recv_from_rpc
    comm = await self.pool.connect(self.addr)
  File "/softs/rh7/conda/4.5.4/envs/pangeo_full_201909/lib/python3.7/site-packages/distributed/core.py", line 874, in connect
    connection_args=self.connection_args,
  File "/softs/rh7/conda/4.5.4/envs/pangeo_full_201909/lib/python3.7/site-packages/distributed/comm/core.py", line 227, in connect
    _raise(error)
  File "/softs/rh7/conda/4.5.4/envs/pangeo_full_201909/lib/python3.7/site-packages/distributed/comm/core.py", line 204, in _raise
    raise IOError(msg)
OSError: Timed out trying to connect to 'tcp://10.120.40.97:33653' after 10 s: in <distributed.comm.tcp.TCPConnector object at 0x2b3811101d30>: ConnectionRefusedError: [Errno 111] Connection refused
tornado.application - ERROR - Exception in callback <function Worker._register_with_scheduler.<locals>.<lambda> at 0x2b37fa7fee18>
Traceback (most recent call last):
  File "/softs/rh7/conda/4.5.4/envs/pangeo_full_201909/lib/python3.7/site-packages/tornado/ioloop.py", line 907, in _run
    return self.callback()
  File "/softs/rh7/conda/4.5.4/envs/pangeo_full_201909/lib/python3.7/site-packages/distributed/worker.py", line 857, in <lambda>
    lambda: self.batched_stream.send({"op": "keep-alive"}),
  File "/softs/rh7/conda/4.5.4/envs/pangeo_full_201909/lib/python3.7/site-packages/distributed/batched.py", line 117, in send
    raise CommClosedError
distributed.comm.core.CommClosedError
tornado.application - ERROR - Exception in callback functools.partial(<bound method IOLoop._discard_future_result of <tornado.platform.asyncio.AsyncIOLoop object at 0x2b37e7ab2b38>>, <Task finished coro=<Worker.heartbeat() done, defined at /softs/rh7/conda/4.5.4/envs/pangeo_full_201909/lib/python3.7/site-packages/distributed/worker.py:866> exception=OSError("Timed out trying to connect to 'tcp://10.120.40.97:33653' after 10 s: in <distributed.comm.tcp.TCPConnector object at 0x2b3810d412e8>: ConnectionRefusedError: [Errno 111] Connection refused")>)
Traceback (most recent call last):
  File "/softs/rh7/conda/4.5.4/envs/pangeo_full_201909/lib/python3.7/site-packages/distributed/comm/core.py", line 215, in connect
    quiet_exceptions=EnvironmentError,
tornado.util.TimeoutError: Timeout

During handling of the above exception, another exception occurred:

Traceback (most recent call last):
  File "/softs/rh7/conda/4.5.4/envs/pangeo_full_201909/lib/python3.7/site-packages/tornado/ioloop.py", line 743, in _run_callback
    ret = callback()
  File "/softs/rh7/conda/4.5.4/envs/pangeo_full_201909/lib/python3.7/site-packages/tornado/ioloop.py", line 767, in _discard_future_result
    future.result()
  File "/softs/rh7/conda/4.5.4/envs/pangeo_full_201909/lib/python3.7/site-packages/distributed/worker.py", line 875, in heartbeat
    metrics=await self.get_metrics(),
  File "/softs/rh7/conda/4.5.4/envs/pangeo_full_201909/lib/python3.7/site-packages/distributed/core.py", line 747, in send_recv_from_rpc
    comm = await self.pool.connect(self.addr)
  File "/softs/rh7/conda/4.5.4/envs/pangeo_full_201909/lib/python3.7/site-packages/distributed/core.py", line 874, in connect
    connection_args=self.connection_args,
  File "/softs/rh7/conda/4.5.4/envs/pangeo_full_201909/lib/python3.7/site-packages/distributed/comm/core.py", line 227, in connect
    _raise(error)
  File "/softs/rh7/conda/4.5.4/envs/pangeo_full_201909/lib/python3.7/site-packages/distributed/comm/core.py", line 204, in _raise
    raise IOError(msg)
OSError: Timed out trying to connect to 'tcp://10.120.40.97:33653' after 10 s: in <distributed.comm.tcp.TCPConnector object at 0x2b3810d412e8>: ConnectionRefusedError: [Errno 111] Connection refused
tornado.application - ERROR - Exception in callback functools.partial(<bound method IOLoop._discard_future_result of <tornado.platform.asyncio.AsyncIOLoop object at 0x2b37e7ab2b38>>, <Task finished coro=<Worker.heartbeat() done, defined at /softs/rh7/conda/4.5.4/envs/pangeo_full_201909/lib/python3.7/site-packages/distributed/worker.py:866> exception=OSError("Timed out trying to connect to 'tcp://10.120.40.97:33653' after 10 s: in <distributed.comm.tcp.TCPConnector object at 0x2b37fbf9fb00>: ConnectionRefusedError: [Errno 111] Connection refused")>)
Traceback (most recent call last):
  File "/softs/rh7/conda/4.5.4/envs/pangeo_full_201909/lib/python3.7/site-packages/distributed/comm/core.py", line 215, in connect
    quiet_exceptions=EnvironmentError,
tornado.util.TimeoutError: Timeout

During handling of the above exception, another exception occurred:

Traceback (most recent call last):
  File "/softs/rh7/conda/4.5.4/envs/pangeo_full_201909/lib/python3.7/site-packages/tornado/ioloop.py", line 743, in _run_callback
    ret = callback()
  File "/softs/rh7/conda/4.5.4/envs/pangeo_full_201909/lib/python3.7/site-packages/tornado/ioloop.py", line 767, in _discard_future_result
    future.result()
  File "/softs/rh7/conda/4.5.4/envs/pangeo_full_201909/lib/python3.7/site-packages/distributed/worker.py", line 875, in heartbeat
    metrics=await self.get_metrics(),
  File "/softs/rh7/conda/4.5.4/envs/pangeo_full_201909/lib/python3.7/site-packages/distributed/core.py", line 747, in send_recv_from_rpc
    comm = await self.pool.connect(self.addr)
  File "/softs/rh7/conda/4.5.4/envs/pangeo_full_201909/lib/python3.7/site-packages/distributed/core.py", line 874, in connect
    connection_args=self.connection_args,
  File "/softs/rh7/conda/4.5.4/envs/pangeo_full_201909/lib/python3.7/site-packages/distributed/comm/core.py", line 227, in connect
    _raise(error)
  File "/softs/rh7/conda/4.5.4/envs/pangeo_full_201909/lib/python3.7/site-packages/distributed/comm/core.py", line 204, in _raise
    raise IOError(msg)
OSError: Timed out trying to connect to 'tcp://10.120.40.97:33653' after 10 s: in <distributed.comm.tcp.TCPConnector object at 0x2b37fbf9fb00>: ConnectionRefusedError: [Errno 111] Connection refused
tornado.application - ERROR - Exception in callback functools.partial(<bound method IOLoop._discard_future_result of <tornado.platform.asyncio.AsyncIOLoop object at 0x2b37e7ab2b38>>, <Task finished coro=<Worker.heartbeat() done, defined at /softs/rh7/conda/4.5.4/envs/pangeo_full_201909/lib/python3.7/site-packages/distributed/worker.py:866> exception=OSError("Timed out trying to connect to 'tcp://10.120.40.97:33653' after 10 s: in <distributed.comm.tcp.TCPConnector object at 0x2b3810d41b00>: ConnectionRefusedError: [Errno 111] Connection refused")>)
Traceback (most recent call last):
  File "/softs/rh7/conda/4.5.4/envs/pangeo_full_201909/lib/python3.7/site-packages/distributed/comm/core.py", line 215, in connect
    quiet_exceptions=EnvironmentError,
tornado.util.TimeoutError: Timeout

During handling of the above exception, another exception occurred:

Traceback (most recent call last):
  File "/softs/rh7/conda/4.5.4/envs/pangeo_full_201909/lib/python3.7/site-packages/tornado/ioloop.py", line 743, in _run_callback
    ret = callback()
  File "/softs/rh7/conda/4.5.4/envs/pangeo_full_201909/lib/python3.7/site-packages/tornado/ioloop.py", line 767, in _discard_future_result
    future.result()
  File "/softs/rh7/conda/4.5.4/envs/pangeo_full_201909/lib/python3.7/site-packages/distributed/worker.py", line 875, in heartbeat
    metrics=await self.get_metrics(),
  File "/softs/rh7/conda/4.5.4/envs/pangeo_full_201909/lib/python3.7/site-packages/distributed/core.py", line 747, in send_recv_from_rpc
    comm = await self.pool.connect(self.addr)
  File "/softs/rh7/conda/4.5.4/envs/pangeo_full_201909/lib/python3.7/site-packages/distributed/core.py", line 874, in connect
    connection_args=self.connection_args,
  File "/softs/rh7/conda/4.5.4/envs/pangeo_full_201909/lib/python3.7/site-packages/distributed/comm/core.py", line 227, in connect
    _raise(error)
  File "/softs/rh7/conda/4.5.4/envs/pangeo_full_201909/lib/python3.7/site-packages/distributed/comm/core.py", line 204, in _raise
    raise IOError(msg)
OSError: Timed out trying to connect to 'tcp://10.120.40.97:33653' after 10 s: in <distributed.comm.tcp.TCPConnector object at 0x2b3810d41b00>: ConnectionRefusedError: [Errno 111] Connection refused
tornado.application - ERROR - Exception in callback functools.partial(<bound method IOLoop._discard_future_result of <tornado.platform.asyncio.AsyncIOLoop object at 0x2b37e7ab2b38>>, <Task finished coro=<Worker.heartbeat() done, defined at /softs/rh7/conda/4.5.4/envs/pangeo_full_201909/lib/python3.7/site-packages/distributed/worker.py:866> exception=OSError("Timed out trying to connect to 'tcp://10.120.40.97:33653' after 10 s: in <distributed.comm.tcp.TCPConnector object at 0x2b3811101898>: ConnectionRefusedError: [Errno 111] Connection refused")>)
Traceback (most recent call last):
  File "/softs/rh7/conda/4.5.4/envs/pangeo_full_201909/lib/python3.7/site-packages/distributed/comm/core.py", line 215, in connect
    quiet_exceptions=EnvironmentError,
tornado.util.TimeoutError: Timeout

During handling of the above exception, another exception occurred:

Traceback (most recent call last):
  File "/softs/rh7/conda/4.5.4/envs/pangeo_full_201909/lib/python3.7/site-packages/tornado/ioloop.py", line 743, in _run_callback
    ret = callback()
  File "/softs/rh7/conda/4.5.4/envs/pangeo_full_201909/lib/python3.7/site-packages/tornado/ioloop.py", line 767, in _discard_future_result
    future.result()
  File "/softs/rh7/conda/4.5.4/envs/pangeo_full_201909/lib/python3.7/site-packages/distributed/worker.py", line 875, in heartbeat
    metrics=await self.get_metrics(),
  File "/softs/rh7/conda/4.5.4/envs/pangeo_full_201909/lib/python3.7/site-packages/distributed/core.py", line 747, in send_recv_from_rpc
    comm = await self.pool.connect(self.addr)
  File "/softs/rh7/conda/4.5.4/envs/pangeo_full_201909/lib/python3.7/site-packages/distributed/core.py", line 874, in connect
    connection_args=self.connection_args,
  File "/softs/rh7/conda/4.5.4/envs/pangeo_full_201909/lib/python3.7/site-packages/distributed/comm/core.py", line 227, in connect
    _raise(error)
  File "/softs/rh7/conda/4.5.4/envs/pangeo_full_201909/lib/python3.7/site-packages/distributed/comm/core.py", line 204, in _raise
    raise IOError(msg)
OSError: Timed out trying to connect to 'tcp://10.120.40.97:33653' after 10 s: in <distributed.comm.tcp.TCPConnector object at 0x2b3811101898>: ConnectionRefusedError: [Errno 111] Connection refused
tornado.application - ERROR - Exception in callback functools.partial(<bound method IOLoop._discard_future_result of <tornado.platform.asyncio.AsyncIOLoop object at 0x2b37e7ab2b38>>, <Task finished coro=<Worker.heartbeat() done, defined at /softs/rh7/conda/4.5.4/envs/pangeo_full_201909/lib/python3.7/site-packages/distributed/worker.py:866> exception=OSError("Timed out trying to connect to 'tcp://10.120.40.97:33653' after 10 s: in <distributed.comm.tcp.TCPConnector object at 0x2b38109e1f28>: ConnectionRefusedError: [Errno 111] Connection refused")>)
Traceback (most recent call last):
  File "/softs/rh7/conda/4.5.4/envs/pangeo_full_201909/lib/python3.7/site-packages/distributed/comm/tcp.py", line 356, in connect
    ip, port, max_buffer_size=MAX_BUFFER_SIZE, **kwargs
  File "/softs/rh7/conda/4.5.4/envs/pangeo_full_201909/lib/python3.7/site-packages/tornado/tcpclient.py", line 280, in connect
    af, addr, stream = await connector.start(connect_timeout=timeout)
  File "/softs/rh7/conda/4.5.4/envs/pangeo_full_201909/lib/python3.7/site-packages/tornado/tcpclient.py", line 143, in on_connect_done
    stream = future.result()
tornado.iostream.StreamClosedError: Stream is closed

During handling of the above exception, another exception occurred:

Traceback (most recent call last):
  File "/softs/rh7/conda/4.5.4/envs/pangeo_full_201909/lib/python3.7/site-packages/distributed/comm/core.py", line 215, in connect
    quiet_exceptions=EnvironmentError,
  File "/softs/rh7/conda/4.5.4/envs/pangeo_full_201909/lib/python3.7/site-packages/distributed/comm/tcp.py", line 368, in connect
    convert_stream_closed_error(self, e)
  File "/softs/rh7/conda/4.5.4/envs/pangeo_full_201909/lib/python3.7/site-packages/distributed/comm/tcp.py", line 138, in convert_stream_closed_error
    raise CommClosedError("in %s: %s: %s" % (obj, exc.__class__.__name__, exc))
distributed.comm.core.CommClosedError: in <distributed.comm.tcp.TCPConnector object at 0x2b38109e1f28>: ConnectionRefusedError: [Errno 111] Connection refused

During handling of the above exception, another exception occurred:

Traceback (most recent call last):
  File "/softs/rh7/conda/4.5.4/envs/pangeo_full_201909/lib/python3.7/site-packages/tornado/ioloop.py", line 743, in _run_callback
    ret = callback()
  File "/softs/rh7/conda/4.5.4/envs/pangeo_full_201909/lib/python3.7/site-packages/tornado/ioloop.py", line 767, in _discard_future_result
    future.result()
  File "/softs/rh7/conda/4.5.4/envs/pangeo_full_201909/lib/python3.7/site-packages/distributed/worker.py", line 875, in heartbeat
    metrics=await self.get_metrics(),
  File "/softs/rh7/conda/4.5.4/envs/pangeo_full_201909/lib/python3.7/site-packages/distributed/core.py", line 747, in send_recv_from_rpc
    comm = await self.pool.connect(self.addr)
  File "/softs/rh7/conda/4.5.4/envs/pangeo_full_201909/lib/python3.7/site-packages/distributed/core.py", line 874, in connect
    connection_args=self.connection_args,
  File "/softs/rh7/conda/4.5.4/envs/pangeo_full_201909/lib/python3.7/site-packages/distributed/comm/core.py", line 225, in connect
    _raise(error)
  File "/softs/rh7/conda/4.5.4/envs/pangeo_full_201909/lib/python3.7/site-packages/distributed/comm/core.py", line 204, in _raise
    raise IOError(msg)
OSError: Timed out trying to connect to 'tcp://10.120.40.97:33653' after 10 s: in <distributed.comm.tcp.TCPConnector object at 0x2b38109e1f28>: ConnectionRefusedError: [Errno 111] Connection refused
tornado.application - ERROR - Exception in callback functools.partial(<bound method IOLoop._discard_future_result of <tornado.platform.asyncio.AsyncIOLoop object at 0x2b37e7ab2b38>>, <Task finished coro=<Worker.heartbeat() done, defined at /softs/rh7/conda/4.5.4/envs/pangeo_full_201909/lib/python3.7/site-packages/distributed/worker.py:866> exception=OSError("Timed out trying to connect to 'tcp://10.120.40.97:33653' after 10 s: in <distributed.comm.tcp.TCPConnector object at 0x2b38111f46d8>: ConnectionRefusedError: [Errno 111] Connection refused")>)
Traceback (most recent call last):
  File "/softs/rh7/conda/4.5.4/envs/pangeo_full_201909/lib/python3.7/site-packages/distributed/comm/core.py", line 215, in connect
    quiet_exceptions=EnvironmentError,
tornado.util.TimeoutError: Timeout

During handling of the above exception, another exception occurred:

Traceback (most recent call last):
  File "/softs/rh7/conda/4.5.4/envs/pangeo_full_201909/lib/python3.7/site-packages/tornado/ioloop.py", line 743, in _run_callback
    ret = callback()
  File "/softs/rh7/conda/4.5.4/envs/pangeo_full_201909/lib/python3.7/site-packages/tornado/ioloop.py", line 767, in _discard_future_result
    future.result()
  File "/softs/rh7/conda/4.5.4/envs/pangeo_full_201909/lib/python3.7/site-packages/distributed/worker.py", line 875, in heartbeat
    metrics=await self.get_metrics(),
  File "/softs/rh7/conda/4.5.4/envs/pangeo_full_201909/lib/python3.7/site-packages/distributed/core.py", line 747, in send_recv_from_rpc
    comm = await self.pool.connect(self.addr)
  File "/softs/rh7/conda/4.5.4/envs/pangeo_full_201909/lib/python3.7/site-packages/distributed/core.py", line 874, in connect
    connection_args=self.connection_args,
  File "/softs/rh7/conda/4.5.4/envs/pangeo_full_201909/lib/python3.7/site-packages/distributed/comm/core.py", line 227, in connect
    _raise(error)
  File "/softs/rh7/conda/4.5.4/envs/pangeo_full_201909/lib/python3.7/site-packages/distributed/comm/core.py", line 204, in _raise
    raise IOError(msg)
OSError: Timed out trying to connect to 'tcp://10.120.40.97:33653' after 10 s: in <distributed.comm.tcp.TCPConnector object at 0x2b38111f46d8>: ConnectionRefusedError: [Errno 111] Connection refused
tornado.application - ERROR - Exception in callback <function Worker._register_with_scheduler.<locals>.<lambda> at 0x2b37fa7fee18>
Traceback (most recent call last):
  File "/softs/rh7/conda/4.5.4/envs/pangeo_full_201909/lib/python3.7/site-packages/tornado/ioloop.py", line 907, in _run
    return self.callback()
  File "/softs/rh7/conda/4.5.4/envs/pangeo_full_201909/lib/python3.7/site-packages/distributed/worker.py", line 857, in <lambda>
    lambda: self.batched_stream.send({"op": "keep-alive"}),
  File "/softs/rh7/conda/4.5.4/envs/pangeo_full_201909/lib/python3.7/site-packages/distributed/batched.py", line 117, in send
    raise CommClosedError
distributed.comm.core.CommClosedError
tornado.application - ERROR - Exception in callback functools.partial(<bound method IOLoop._discard_future_result of <tornado.platform.asyncio.AsyncIOLoop object at 0x2b37e7ab2b38>>, <Task finished coro=<Worker.heartbeat() done, defined at /softs/rh7/conda/4.5.4/envs/pangeo_full_201909/lib/python3.7/site-packages/distributed/worker.py:866> exception=OSError("Timed out trying to connect to 'tcp://10.120.40.97:33653' after 10 s: in <distributed.comm.tcp.TCPConnector object at 0x2b38111f41d0>: ConnectionRefusedError: [Errno 111] Connection refused")>)
Traceback (most recent call last):
  File "/softs/rh7/conda/4.5.4/envs/pangeo_full_201909/lib/python3.7/site-packages/distributed/comm/core.py", line 215, in connect
    quiet_exceptions=EnvironmentError,
tornado.util.TimeoutError: Timeout

During handling of the above exception, another exception occurred:

Traceback (most recent call last):
  File "/softs/rh7/conda/4.5.4/envs/pangeo_full_201909/lib/python3.7/site-packages/tornado/ioloop.py", line 743, in _run_callback
    ret = callback()
  File "/softs/rh7/conda/4.5.4/envs/pangeo_full_201909/lib/python3.7/site-packages/tornado/ioloop.py", line 767, in _discard_future_result
    future.result()
  File "/softs/rh7/conda/4.5.4/envs/pangeo_full_201909/lib/python3.7/site-packages/distributed/worker.py", line 875, in heartbeat
    metrics=await self.get_metrics(),
  File "/softs/rh7/conda/4.5.4/envs/pangeo_full_201909/lib/python3.7/site-packages/distributed/core.py", line 747, in send_recv_from_rpc
    comm = await self.pool.connect(self.addr)
  File "/softs/rh7/conda/4.5.4/envs/pangeo_full_201909/lib/python3.7/site-packages/distributed/core.py", line 874, in connect
    connection_args=self.connection_args,
  File "/softs/rh7/conda/4.5.4/envs/pangeo_full_201909/lib/python3.7/site-packages/distributed/comm/core.py", line 227, in connect
    _raise(error)
  File "/softs/rh7/conda/4.5.4/envs/pangeo_full_201909/lib/python3.7/site-packages/distributed/comm/core.py", line 204, in _raise
    raise IOError(msg)
OSError: Timed out trying to connect to 'tcp://10.120.40.97:33653' after 10 s: in <distributed.comm.tcp.TCPConnector object at 0x2b38111f41d0>: ConnectionRefusedError: [Errno 111] Connection refused
distributed.utils_perf - INFO - full garbage collection released 15.94 MB from 3373 reference cycles (threshold: 10.00 MB)
tornado.application - ERROR - Exception in callback functools.partial(<bound method IOLoop._discard_future_result of <tornado.platform.asyncio.AsyncIOLoop object at 0x2b37e7ab2b38>>, <Task finished coro=<Worker.heartbeat() done, defined at /softs/rh7/conda/4.5.4/envs/pangeo_full_201909/lib/python3.7/site-packages/distributed/worker.py:866> exception=OSError("Timed out trying to connect to 'tcp://10.120.40.97:33653' after 10 s: in <distributed.comm.tcp.TCPConnector object at 0x2b3810c8fe48>: ConnectionRefusedError: [Errno 111] Connection refused")>)
Traceback (most recent call last):
  File "/softs/rh7/conda/4.5.4/envs/pangeo_full_201909/lib/python3.7/site-packages/distributed/comm/core.py", line 215, in connect
    quiet_exceptions=EnvironmentError,
tornado.util.TimeoutError: Timeout

During handling of the above exception, another exception occurred:

Traceback (most recent call last):
  File "/softs/rh7/conda/4.5.4/envs/pangeo_full_201909/lib/python3.7/site-packages/tornado/ioloop.py", line 743, in _run_callback
    ret = callback()
  File "/softs/rh7/conda/4.5.4/envs/pangeo_full_201909/lib/python3.7/site-packages/tornado/ioloop.py", line 767, in _discard_future_result
    future.result()
  File "/softs/rh7/conda/4.5.4/envs/pangeo_full_201909/lib/python3.7/site-packages/distributed/worker.py", line 875, in heartbeat
    metrics=await self.get_metrics(),
  File "/softs/rh7/conda/4.5.4/envs/pangeo_full_201909/lib/python3.7/site-packages/distributed/core.py", line 747, in send_recv_from_rpc
    comm = await self.pool.connect(self.addr)
  File "/softs/rh7/conda/4.5.4/envs/pangeo_full_201909/lib/python3.7/site-packages/distributed/core.py", line 874, in connect
    connection_args=self.connection_args,
  File "/softs/rh7/conda/4.5.4/envs/pangeo_full_201909/lib/python3.7/site-packages/distributed/comm/core.py", line 227, in connect
    _raise(error)
  File "/softs/rh7/conda/4.5.4/envs/pangeo_full_201909/lib/python3.7/site-packages/distributed/comm/core.py", line 204, in _raise
    raise IOError(msg)
OSError: Timed out trying to connect to 'tcp://10.120.40.97:33653' after 10 s: in <distributed.comm.tcp.TCPConnector object at 0x2b3810c8fe48>: ConnectionRefusedError: [Errno 111] Connection refused
tornado.application - ERROR - Exception in callback functools.partial(<bound method IOLoop._discard_future_result of <tornado.platform.asyncio.AsyncIOLoop object at 0x2b37e7ab2b38>>, <Task finished coro=<Worker.heartbeat() done, defined at /softs/rh7/conda/4.5.4/envs/pangeo_full_201909/lib/python3.7/site-packages/distributed/worker.py:866> exception=OSError("Timed out trying to connect to 'tcp://10.120.40.97:33653' after 10 s: in <distributed.comm.tcp.TCPConnector object at 0x2b381096a978>: ConnectionRefusedError: [Errno 111] Connection refused")>)
Traceback (most recent call last):
  File "/softs/rh7/conda/4.5.4/envs/pangeo_full_201909/lib/python3.7/site-packages/distributed/comm/core.py", line 215, in connect
    quiet_exceptions=EnvironmentError,
tornado.util.TimeoutError: Timeout

During handling of the above exception, another exception occurred:

Traceback (most recent call last):
  File "/softs/rh7/conda/4.5.4/envs/pangeo_full_201909/lib/python3.7/site-packages/tornado/ioloop.py", line 743, in _run_callback
    ret = callback()
  File "/softs/rh7/conda/4.5.4/envs/pangeo_full_201909/lib/python3.7/site-packages/tornado/ioloop.py", line 767, in _discard_future_result
    future.result()
  File "/softs/rh7/conda/4.5.4/envs/pangeo_full_201909/lib/python3.7/site-packages/distributed/worker.py", line 875, in heartbeat
    metrics=await self.get_metrics(),
  File "/softs/rh7/conda/4.5.4/envs/pangeo_full_201909/lib/python3.7/site-packages/distributed/core.py", line 747, in send_recv_from_rpc
    comm = await self.pool.connect(self.addr)
  File "/softs/rh7/conda/4.5.4/envs/pangeo_full_201909/lib/python3.7/site-packages/distributed/core.py", line 874, in connect
    connection_args=self.connection_args,
  File "/softs/rh7/conda/4.5.4/envs/pangeo_full_201909/lib/python3.7/site-packages/distributed/comm/core.py", line 227, in connect
    _raise(error)
  File "/softs/rh7/conda/4.5.4/envs/pangeo_full_201909/lib/python3.7/site-packages/distributed/comm/core.py", line 204, in _raise
    raise IOError(msg)
OSError: Timed out trying to connect to 'tcp://10.120.40.97:33653' after 10 s: in <distributed.comm.tcp.TCPConnector object at 0x2b381096a978>: ConnectionRefusedError: [Errno 111] Connection refused
tornado.application - ERROR - Exception in callback functools.partial(<bound method IOLoop._discard_future_result of <tornado.platform.asyncio.AsyncIOLoop object at 0x2b37e7ab2b38>>, <Task finished coro=<Worker.heartbeat() done, defined at /softs/rh7/conda/4.5.4/envs/pangeo_full_201909/lib/python3.7/site-packages/distributed/worker.py:866> exception=OSError("Timed out trying to connect to 'tcp://10.120.40.97:33653' after 10 s: in <distributed.comm.tcp.TCPConnector object at 0x2b381096a9e8>: ConnectionRefusedError: [Errno 111] Connection refused")>)
Traceback (most recent call last):
  File "/softs/rh7/conda/4.5.4/envs/pangeo_full_201909/lib/python3.7/site-packages/distributed/comm/core.py", line 215, in connect
    quiet_exceptions=EnvironmentError,
tornado.util.TimeoutError: Timeout

During handling of the above exception, another exception occurred:

Traceback (most recent call last):
  File "/softs/rh7/conda/4.5.4/envs/pangeo_full_201909/lib/python3.7/site-packages/tornado/ioloop.py", line 743, in _run_callback
    ret = callback()
  File "/softs/rh7/conda/4.5.4/envs/pangeo_full_201909/lib/python3.7/site-packages/tornado/ioloop.py", line 767, in _discard_future_result
    future.result()
  File "/softs/rh7/conda/4.5.4/envs/pangeo_full_201909/lib/python3.7/site-packages/distributed/worker.py", line 875, in heartbeat
    metrics=await self.get_metrics(),
  File "/softs/rh7/conda/4.5.4/envs/pangeo_full_201909/lib/python3.7/site-packages/distributed/core.py", line 747, in send_recv_from_rpc
    comm = await self.pool.connect(self.addr)
  File "/softs/rh7/conda/4.5.4/envs/pangeo_full_201909/lib/python3.7/site-packages/distributed/core.py", line 874, in connect
    connection_args=self.connection_args,
  File "/softs/rh7/conda/4.5.4/envs/pangeo_full_201909/lib/python3.7/site-packages/distributed/comm/core.py", line 227, in connect
    _raise(error)
  File "/softs/rh7/conda/4.5.4/envs/pangeo_full_201909/lib/python3.7/site-packages/distributed/comm/core.py", line 204, in _raise
    raise IOError(msg)
OSError: Timed out trying to connect to 'tcp://10.120.40.97:33653' after 10 s: in <distributed.comm.tcp.TCPConnector object at 0x2b381096a9e8>: ConnectionRefusedError: [Errno 111] Connection refused
tornado.application - ERROR - Exception in callback functools.partial(<bound method IOLoop._discard_future_result of <tornado.platform.asyncio.AsyncIOLoop object at 0x2b37e7ab2b38>>, <Task finished coro=<Worker.heartbeat() done, defined at /softs/rh7/conda/4.5.4/envs/pangeo_full_201909/lib/python3.7/site-packages/distributed/worker.py:866> exception=OSError("Timed out trying to connect to 'tcp://10.120.40.97:33653' after 10 s: in <distributed.comm.tcp.TCPConnector object at 0x2b3810be12e8>: ConnectionRefusedError: [Errno 111] Connection refused")>)
Traceback (most recent call last):
  File "/softs/rh7/conda/4.5.4/envs/pangeo_full_201909/lib/python3.7/site-packages/distributed/comm/core.py", line 215, in connect
    quiet_exceptions=EnvironmentError,
tornado.util.TimeoutError: Timeout

During handling of the above exception, another exception occurred:

Traceback (most recent call last):
  File "/softs/rh7/conda/4.5.4/envs/pangeo_full_201909/lib/python3.7/site-packages/tornado/ioloop.py", line 743, in _run_callback
    ret = callback()
  File "/softs/rh7/conda/4.5.4/envs/pangeo_full_201909/lib/python3.7/site-packages/tornado/ioloop.py", line 767, in _discard_future_result
    future.result()
  File "/softs/rh7/conda/4.5.4/envs/pangeo_full_201909/lib/python3.7/site-packages/distributed/worker.py", line 875, in heartbeat
    metrics=await self.get_metrics(),
  File "/softs/rh7/conda/4.5.4/envs/pangeo_full_201909/lib/python3.7/site-packages/distributed/core.py", line 747, in send_recv_from_rpc
    comm = await self.pool.connect(self.addr)
  File "/softs/rh7/conda/4.5.4/envs/pangeo_full_201909/lib/python3.7/site-packages/distributed/core.py", line 874, in connect
    connection_args=self.connection_args,
  File "/softs/rh7/conda/4.5.4/envs/pangeo_full_201909/lib/python3.7/site-packages/distributed/comm/core.py", line 227, in connect
    _raise(error)
  File "/softs/rh7/conda/4.5.4/envs/pangeo_full_201909/lib/python3.7/site-packages/distributed/comm/core.py", line 204, in _raise
    raise IOError(msg)
OSError: Timed out trying to connect to 'tcp://10.120.40.97:33653' after 10 s: in <distributed.comm.tcp.TCPConnector object at 0x2b3810be12e8>: ConnectionRefusedError: [Errno 111] Connection refused
tornado.application - ERROR - Exception in callback <function Worker._register_with_scheduler.<locals>.<lambda> at 0x2b37fa7fee18>
Traceback (most recent call last):
  File "/softs/rh7/conda/4.5.4/envs/pangeo_full_201909/lib/python3.7/site-packages/tornado/ioloop.py", line 907, in _run
    return self.callback()
  File "/softs/rh7/conda/4.5.4/envs/pangeo_full_201909/lib/python3.7/site-packages/distributed/worker.py", line 857, in <lambda>
    lambda: self.batched_stream.send({"op": "keep-alive"}),
  File "/softs/rh7/conda/4.5.4/envs/pangeo_full_201909/lib/python3.7/site-packages/distributed/batched.py", line 117, in send
    raise CommClosedError
distributed.comm.core.CommClosedError
tornado.application - ERROR - Exception in callback functools.partial(<bound method IOLoop._discard_future_result of <tornado.platform.asyncio.AsyncIOLoop object at 0x2b37e7ab2b38>>, <Task finished coro=<Worker.heartbeat() done, defined at /softs/rh7/conda/4.5.4/envs/pangeo_full_201909/lib/python3.7/site-packages/distributed/worker.py:866> exception=OSError("Timed out trying to connect to 'tcp://10.120.40.97:33653' after 10 s: in <distributed.comm.tcp.TCPConnector object at 0x2b3810ede470>: ConnectionRefusedError: [Errno 111] Connection refused")>)
Traceback (most recent call last):
  File "/softs/rh7/conda/4.5.4/envs/pangeo_full_201909/lib/python3.7/site-packages/distributed/comm/core.py", line 215, in connect
    quiet_exceptions=EnvironmentError,
tornado.util.TimeoutError: Timeout

During handling of the above exception, another exception occurred:

Traceback (most recent call last):
  File "/softs/rh7/conda/4.5.4/envs/pangeo_full_201909/lib/python3.7/site-packages/tornado/ioloop.py", line 743, in _run_callback
    ret = callback()
  File "/softs/rh7/conda/4.5.4/envs/pangeo_full_201909/lib/python3.7/site-packages/tornado/ioloop.py", line 767, in _discard_future_result
    future.result()
  File "/softs/rh7/conda/4.5.4/envs/pangeo_full_201909/lib/python3.7/site-packages/distributed/worker.py", line 875, in heartbeat
    metrics=await self.get_metrics(),
  File "/softs/rh7/conda/4.5.4/envs/pangeo_full_201909/lib/python3.7/site-packages/distributed/core.py", line 747, in send_recv_from_rpc
    comm = await self.pool.connect(self.addr)
  File "/softs/rh7/conda/4.5.4/envs/pangeo_full_201909/lib/python3.7/site-packages/distributed/core.py", line 874, in connect
    connection_args=self.connection_args,
  File "/softs/rh7/conda/4.5.4/envs/pangeo_full_201909/lib/python3.7/site-packages/distributed/comm/core.py", line 227, in connect
    _raise(error)
  File "/softs/rh7/conda/4.5.4/envs/pangeo_full_201909/lib/python3.7/site-packages/distributed/comm/core.py", line 204, in _raise
    raise IOError(msg)
OSError: Timed out trying to connect to 'tcp://10.120.40.97:33653' after 10 s: in <distributed.comm.tcp.TCPConnector object at 0x2b3810ede470>: ConnectionRefusedError: [Errno 111] Connection refused
tornado.application - ERROR - Exception in callback functools.partial(<bound method IOLoop._discard_future_result of <tornado.platform.asyncio.AsyncIOLoop object at 0x2b37e7ab2b38>>, <Task finished coro=<Worker.heartbeat() done, defined at /softs/rh7/conda/4.5.4/envs/pangeo_full_201909/lib/python3.7/site-packages/distributed/worker.py:866> exception=OSError("Timed out trying to connect to 'tcp://10.120.40.97:33653' after 10 s: in <distributed.comm.tcp.TCPConnector object at 0x2b3810a34320>: ConnectionRefusedError: [Errno 111] Connection refused")>)
Traceback (most recent call last):
  File "/softs/rh7/conda/4.5.4/envs/pangeo_full_201909/lib/python3.7/site-packages/distributed/comm/core.py", line 215, in connect
    quiet_exceptions=EnvironmentError,
tornado.util.TimeoutError: Timeout

During handling of the above exception, another exception occurred:

Traceback (most recent call last):
  File "/softs/rh7/conda/4.5.4/envs/pangeo_full_201909/lib/python3.7/site-packages/tornado/ioloop.py", line 743, in _run_callback
    ret = callback()
  File "/softs/rh7/conda/4.5.4/envs/pangeo_full_201909/lib/python3.7/site-packages/tornado/ioloop.py", line 767, in _discard_future_result
    future.result()
  File "/softs/rh7/conda/4.5.4/envs/pangeo_full_201909/lib/python3.7/site-packages/distributed/worker.py", line 875, in heartbeat
    metrics=await self.get_metrics(),
  File "/softs/rh7/conda/4.5.4/envs/pangeo_full_201909/lib/python3.7/site-packages/distributed/core.py", line 747, in send_recv_from_rpc
    comm = await self.pool.connect(self.addr)
  File "/softs/rh7/conda/4.5.4/envs/pangeo_full_201909/lib/python3.7/site-packages/distributed/core.py", line 874, in connect
    connection_args=self.connection_args,
  File "/softs/rh7/conda/4.5.4/envs/pangeo_full_201909/lib/python3.7/site-packages/distributed/comm/core.py", line 227, in connect
    _raise(error)
  File "/softs/rh7/conda/4.5.4/envs/pangeo_full_201909/lib/python3.7/site-packages/distributed/comm/core.py", line 204, in _raise
    raise IOError(msg)
OSError: Timed out trying to connect to 'tcp://10.120.40.97:33653' after 10 s: in <distributed.comm.tcp.TCPConnector object at 0x2b3810a34320>: ConnectionRefusedError: [Errno 111] Connection refused
tornado.application - ERROR - Exception in callback functools.partial(<bound method IOLoop._discard_future_result of <tornado.platform.asyncio.AsyncIOLoop object at 0x2b37e7ab2b38>>, <Task finished coro=<Worker.heartbeat() done, defined at /softs/rh7/conda/4.5.4/envs/pangeo_full_201909/lib/python3.7/site-packages/distributed/worker.py:866> exception=OSError("Timed out trying to connect to 'tcp://10.120.40.97:33653' after 10 s: in <distributed.comm.tcp.TCPConnector object at 0x2b3810be1710>: ConnectionRefusedError: [Errno 111] Connection refused")>)
Traceback (most recent call last):
  File "/softs/rh7/conda/4.5.4/envs/pangeo_full_201909/lib/python3.7/site-packages/distributed/comm/core.py", line 215, in connect
    quiet_exceptions=EnvironmentError,
tornado.util.TimeoutError: Timeout

During handling of the above exception, another exception occurred:

Traceback (most recent call last):
  File "/softs/rh7/conda/4.5.4/envs/pangeo_full_201909/lib/python3.7/site-packages/tornado/ioloop.py", line 743, in _run_callback
    ret = callback()
  File "/softs/rh7/conda/4.5.4/envs/pangeo_full_201909/lib/python3.7/site-packages/tornado/ioloop.py", line 767, in _discard_future_result
    future.result()
  File "/softs/rh7/conda/4.5.4/envs/pangeo_full_201909/lib/python3.7/site-packages/distributed/worker.py", line 875, in heartbeat
    metrics=await self.get_metrics(),
  File "/softs/rh7/conda/4.5.4/envs/pangeo_full_201909/lib/python3.7/site-packages/distributed/core.py", line 747, in send_recv_from_rpc
    comm = await self.pool.connect(self.addr)
  File "/softs/rh7/conda/4.5.4/envs/pangeo_full_201909/lib/python3.7/site-packages/distributed/core.py", line 874, in connect
    connection_args=self.connection_args,
  File "/softs/rh7/conda/4.5.4/envs/pangeo_full_201909/lib/python3.7/site-packages/distributed/comm/core.py", line 227, in connect
    _raise(error)
  File "/softs/rh7/conda/4.5.4/envs/pangeo_full_201909/lib/python3.7/site-packages/distributed/comm/core.py", line 204, in _raise
    raise IOError(msg)
OSError: Timed out trying to connect to 'tcp://10.120.40.97:33653' after 10 s: in <distributed.comm.tcp.TCPConnector object at 0x2b3810be1710>: ConnectionRefusedError: [Errno 111] Connection refused
tornado.application - ERROR - Exception in callback functools.partial(<bound method IOLoop._discard_future_result of <tornado.platform.asyncio.AsyncIOLoop object at 0x2b37e7ab2b38>>, <Task finished coro=<Worker.heartbeat() done, defined at /softs/rh7/conda/4.5.4/envs/pangeo_full_201909/lib/python3.7/site-packages/distributed/worker.py:866> exception=OSError("Timed out trying to connect to 'tcp://10.120.40.97:33653' after 10 s: in <distributed.comm.tcp.TCPConnector object at 0x2b3810e9abe0>: ConnectionRefusedError: [Errno 111] Connection refused")>)
Traceback (most recent call last):
  File "/softs/rh7/conda/4.5.4/envs/pangeo_full_201909/lib/python3.7/site-packages/distributed/comm/core.py", line 215, in connect
    quiet_exceptions=EnvironmentError,
tornado.util.TimeoutError: Timeout

During handling of the above exception, another exception occurred:

Traceback (most recent call last):
  File "/softs/rh7/conda/4.5.4/envs/pangeo_full_201909/lib/python3.7/site-packages/tornado/ioloop.py", line 743, in _run_callback
    ret = callback()
  File "/softs/rh7/conda/4.5.4/envs/pangeo_full_201909/lib/python3.7/site-packages/tornado/ioloop.py", line 767, in _discard_future_result
    future.result()
  File "/softs/rh7/conda/4.5.4/envs/pangeo_full_201909/lib/python3.7/site-packages/distributed/worker.py", line 875, in heartbeat
    metrics=await self.get_metrics(),
  File "/softs/rh7/conda/4.5.4/envs/pangeo_full_201909/lib/python3.7/site-packages/distributed/core.py", line 747, in send_recv_from_rpc
    comm = await self.pool.connect(self.addr)
  File "/softs/rh7/conda/4.5.4/envs/pangeo_full_201909/lib/python3.7/site-packages/distributed/core.py", line 874, in connect
    connection_args=self.connection_args,
  File "/softs/rh7/conda/4.5.4/envs/pangeo_full_201909/lib/python3.7/site-packages/distributed/comm/core.py", line 227, in connect
    _raise(error)
  File "/softs/rh7/conda/4.5.4/envs/pangeo_full_201909/lib/python3.7/site-packages/distributed/comm/core.py", line 204, in _raise
    raise IOError(msg)
OSError: Timed out trying to connect to 'tcp://10.120.40.97:33653' after 10 s: in <distributed.comm.tcp.TCPConnector object at 0x2b3810e9abe0>: ConnectionRefusedError: [Errno 111] Connection refused
tornado.application - ERROR - Exception in callback functools.partial(<bound method IOLoop._discard_future_result of <tornado.platform.asyncio.AsyncIOLoop object at 0x2b37e7ab2b38>>, <Task finished coro=<Worker.heartbeat() done, defined at /softs/rh7/conda/4.5.4/envs/pangeo_full_201909/lib/python3.7/site-packages/distributed/worker.py:866> exception=OSError("Timed out trying to connect to 'tcp://10.120.40.97:33653' after 10 s: in <distributed.comm.tcp.TCPConnector object at 0x2b381096a278>: ConnectionRefusedError: [Errno 111] Connection refused")>)
Traceback (most recent call last):
  File "/softs/rh7/conda/4.5.4/envs/pangeo_full_201909/lib/python3.7/site-packages/distributed/comm/core.py", line 215, in connect
    quiet_exceptions=EnvironmentError,
tornado.util.TimeoutError: Timeout

During handling of the above exception, another exception occurred:

Traceback (most recent call last):
  File "/softs/rh7/conda/4.5.4/envs/pangeo_full_201909/lib/python3.7/site-packages/tornado/ioloop.py", line 743, in _run_callback
    ret = callback()
  File "/softs/rh7/conda/4.5.4/envs/pangeo_full_201909/lib/python3.7/site-packages/tornado/ioloop.py", line 767, in _discard_future_result
    future.result()
  File "/softs/rh7/conda/4.5.4/envs/pangeo_full_201909/lib/python3.7/site-packages/distributed/worker.py", line 875, in heartbeat
    metrics=await self.get_metrics(),
  File "/softs/rh7/conda/4.5.4/envs/pangeo_full_201909/lib/python3.7/site-packages/distributed/core.py", line 747, in send_recv_from_rpc
    comm = await self.pool.connect(self.addr)
  File "/softs/rh7/conda/4.5.4/envs/pangeo_full_201909/lib/python3.7/site-packages/distributed/core.py", line 874, in connect
    connection_args=self.connection_args,
  File "/softs/rh7/conda/4.5.4/envs/pangeo_full_201909/lib/python3.7/site-packages/distributed/comm/core.py", line 227, in connect
    _raise(error)
  File "/softs/rh7/conda/4.5.4/envs/pangeo_full_201909/lib/python3.7/site-packages/distributed/comm/core.py", line 204, in _raise
    raise IOError(msg)
OSError: Timed out trying to connect to 'tcp://10.120.40.97:33653' after 10 s: in <distributed.comm.tcp.TCPConnector object at 0x2b381096a278>: ConnectionRefusedError: [Errno 111] Connection refused
tornado.application - ERROR - Exception in callback <function Worker._register_with_scheduler.<locals>.<lambda> at 0x2b37fa7fee18>
Traceback (most recent call last):
  File "/softs/rh7/conda/4.5.4/envs/pangeo_full_201909/lib/python3.7/site-packages/tornado/ioloop.py", line 907, in _run
    return self.callback()
  File "/softs/rh7/conda/4.5.4/envs/pangeo_full_201909/lib/python3.7/site-packages/distributed/worker.py", line 857, in <lambda>
    lambda: self.batched_stream.send({"op": "keep-alive"}),
  File "/softs/rh7/conda/4.5.4/envs/pangeo_full_201909/lib/python3.7/site-packages/distributed/batched.py", line 117, in send
    raise CommClosedError
distributed.comm.core.CommClosedError
tornado.application - ERROR - Exception in callback functools.partial(<bound method IOLoop._discard_future_result of <tornado.platform.asyncio.AsyncIOLoop object at 0x2b37e7ab2b38>>, <Task finished coro=<Worker.heartbeat() done, defined at /softs/rh7/conda/4.5.4/envs/pangeo_full_201909/lib/python3.7/site-packages/distributed/worker.py:866> exception=OSError("Timed out trying to connect to 'tcp://10.120.40.97:33653' after 10 s: in <distributed.comm.tcp.TCPConnector object at 0x2b3810ede3c8>: ConnectionRefusedError: [Errno 111] Connection refused")>)
Traceback (most recent call last):
  File "/softs/rh7/conda/4.5.4/envs/pangeo_full_201909/lib/python3.7/site-packages/distributed/comm/core.py", line 215, in connect
    quiet_exceptions=EnvironmentError,
tornado.util.TimeoutError: Timeout

During handling of the above exception, another exception occurred:

Traceback (most recent call last):
  File "/softs/rh7/conda/4.5.4/envs/pangeo_full_201909/lib/python3.7/site-packages/tornado/ioloop.py", line 743, in _run_callback
    ret = callback()
  File "/softs/rh7/conda/4.5.4/envs/pangeo_full_201909/lib/python3.7/site-packages/tornado/ioloop.py", line 767, in _discard_future_result
    future.result()
  File "/softs/rh7/conda/4.5.4/envs/pangeo_full_201909/lib/python3.7/site-packages/distributed/worker.py", line 875, in heartbeat
    metrics=await self.get_metrics(),
  File "/softs/rh7/conda/4.5.4/envs/pangeo_full_201909/lib/python3.7/site-packages/distributed/core.py", line 747, in send_recv_from_rpc
    comm = await self.pool.connect(self.addr)
  File "/softs/rh7/conda/4.5.4/envs/pangeo_full_201909/lib/python3.7/site-packages/distributed/core.py", line 874, in connect
    connection_args=self.connection_args,
  File "/softs/rh7/conda/4.5.4/envs/pangeo_full_201909/lib/python3.7/site-packages/distributed/comm/core.py", line 227, in connect
    _raise(error)
  File "/softs/rh7/conda/4.5.4/envs/pangeo_full_201909/lib/python3.7/site-packages/distributed/comm/core.py", line 204, in _raise
    raise IOError(msg)
OSError: Timed out trying to connect to 'tcp://10.120.40.97:33653' after 10 s: in <distributed.comm.tcp.TCPConnector object at 0x2b3810ede3c8>: ConnectionRefusedError: [Errno 111] Connection refused
tornado.application - ERROR - Exception in callback functools.partial(<bound method IOLoop._discard_future_result of <tornado.platform.asyncio.AsyncIOLoop object at 0x2b37e7ab2b38>>, <Task finished coro=<Worker.heartbeat() done, defined at /softs/rh7/conda/4.5.4/envs/pangeo_full_201909/lib/python3.7/site-packages/distributed/worker.py:866> exception=OSError("Timed out trying to connect to 'tcp://10.120.40.97:33653' after 10 s: in <distributed.comm.tcp.TCPConnector object at 0x2b3810a34828>: ConnectionRefusedError: [Errno 111] Connection refused")>)
Traceback (most recent call last):
  File "/softs/rh7/conda/4.5.4/envs/pangeo_full_201909/lib/python3.7/site-packages/distributed/comm/core.py", line 215, in connect
    quiet_exceptions=EnvironmentError,
tornado.util.TimeoutError: Timeout

During handling of the above exception, another exception occurred:

Traceback (most recent call last):
  File "/softs/rh7/conda/4.5.4/envs/pangeo_full_201909/lib/python3.7/site-packages/tornado/ioloop.py", line 743, in _run_callback
    ret = callback()
  File "/softs/rh7/conda/4.5.4/envs/pangeo_full_201909/lib/python3.7/site-packages/tornado/ioloop.py", line 767, in _discard_future_result
    future.result()
  File "/softs/rh7/conda/4.5.4/envs/pangeo_full_201909/lib/python3.7/site-packages/distributed/worker.py", line 875, in heartbeat
    metrics=await self.get_metrics(),
  File "/softs/rh7/conda/4.5.4/envs/pangeo_full_201909/lib/python3.7/site-packages/distributed/core.py", line 747, in send_recv_from_rpc
    comm = await self.pool.connect(self.addr)
  File "/softs/rh7/conda/4.5.4/envs/pangeo_full_201909/lib/python3.7/site-packages/distributed/core.py", line 874, in connect
    connection_args=self.connection_args,
  File "/softs/rh7/conda/4.5.4/envs/pangeo_full_201909/lib/python3.7/site-packages/distributed/comm/core.py", line 227, in connect
    _raise(error)
  File "/softs/rh7/conda/4.5.4/envs/pangeo_full_201909/lib/python3.7/site-packages/distributed/comm/core.py", line 204, in _raise
    raise IOError(msg)
OSError: Timed out trying to connect to 'tcp://10.120.40.97:33653' after 10 s: in <distributed.comm.tcp.TCPConnector object at 0x2b3810a34828>: ConnectionRefusedError: [Errno 111] Connection refused
tornado.application - ERROR - Exception in callback functools.partial(<bound method IOLoop._discard_future_result of <tornado.platform.asyncio.AsyncIOLoop object at 0x2b37e7ab2b38>>, <Task finished coro=<Worker.heartbeat() done, defined at /softs/rh7/conda/4.5.4/envs/pangeo_full_201909/lib/python3.7/site-packages/distributed/worker.py:866> exception=OSError("Timed out trying to connect to 'tcp://10.120.40.97:33653' after 10 s: in <distributed.comm.tcp.TCPConnector object at 0x2b37fbf9f0f0>: ConnectionRefusedError: [Errno 111] Connection refused")>)
Traceback (most recent call last):
  File "/softs/rh7/conda/4.5.4/envs/pangeo_full_201909/lib/python3.7/site-packages/distributed/comm/core.py", line 215, in connect
    quiet_exceptions=EnvironmentError,
tornado.util.TimeoutError: Timeout

During handling of the above exception, another exception occurred:

Traceback (most recent call last):
  File "/softs/rh7/conda/4.5.4/envs/pangeo_full_201909/lib/python3.7/site-packages/tornado/ioloop.py", line 743, in _run_callback
    ret = callback()
  File "/softs/rh7/conda/4.5.4/envs/pangeo_full_201909/lib/python3.7/site-packages/tornado/ioloop.py", line 767, in _discard_future_result
    future.result()
  File "/softs/rh7/conda/4.5.4/envs/pangeo_full_201909/lib/python3.7/site-packages/distributed/worker.py", line 875, in heartbeat
    metrics=await self.get_metrics(),
  File "/softs/rh7/conda/4.5.4/envs/pangeo_full_201909/lib/python3.7/site-packages/distributed/core.py", line 747, in send_recv_from_rpc
    comm = await self.pool.connect(self.addr)
  File "/softs/rh7/conda/4.5.4/envs/pangeo_full_201909/lib/python3.7/site-packages/distributed/core.py", line 874, in connect
    connection_args=self.connection_args,
  File "/softs/rh7/conda/4.5.4/envs/pangeo_full_201909/lib/python3.7/site-packages/distributed/comm/core.py", line 227, in connect
    _raise(error)
  File "/softs/rh7/conda/4.5.4/envs/pangeo_full_201909/lib/python3.7/site-packages/distributed/comm/core.py", line 204, in _raise
    raise IOError(msg)
OSError: Timed out trying to connect to 'tcp://10.120.40.97:33653' after 10 s: in <distributed.comm.tcp.TCPConnector object at 0x2b37fbf9f0f0>: ConnectionRefusedError: [Errno 111] Connection refused
tornado.application - ERROR - Exception in callback functools.partial(<bound method IOLoop._discard_future_result of <tornado.platform.asyncio.AsyncIOLoop object at 0x2b37e7ab2b38>>, <Task finished coro=<Worker.heartbeat() done, defined at /softs/rh7/conda/4.5.4/envs/pangeo_full_201909/lib/python3.7/site-packages/distributed/worker.py:866> exception=OSError("Timed out trying to connect to 'tcp://10.120.40.97:33653' after 10 s: in <distributed.comm.tcp.TCPConnector object at 0x2b38109e1748>: ConnectionRefusedError: [Errno 111] Connection refused")>)
Traceback (most recent call last):
  File "/softs/rh7/conda/4.5.4/envs/pangeo_full_201909/lib/python3.7/site-packages/distributed/comm/core.py", line 215, in connect
    quiet_exceptions=EnvironmentError,
tornado.util.TimeoutError: Timeout

During handling of the above exception, another exception occurred:

Traceback (most recent call last):
  File "/softs/rh7/conda/4.5.4/envs/pangeo_full_201909/lib/python3.7/site-packages/tornado/ioloop.py", line 743, in _run_callback
    ret = callback()
  File "/softs/rh7/conda/4.5.4/envs/pangeo_full_201909/lib/python3.7/site-packages/tornado/ioloop.py", line 767, in _discard_future_result
    future.result()
  File "/softs/rh7/conda/4.5.4/envs/pangeo_full_201909/lib/python3.7/site-packages/distributed/worker.py", line 875, in heartbeat
    metrics=await self.get_metrics(),
  File "/softs/rh7/conda/4.5.4/envs/pangeo_full_201909/lib/python3.7/site-packages/distributed/core.py", line 747, in send_recv_from_rpc
    comm = await self.pool.connect(self.addr)
  File "/softs/rh7/conda/4.5.4/envs/pangeo_full_201909/lib/python3.7/site-packages/distributed/core.py", line 874, in connect
    connection_args=self.connection_args,
  File "/softs/rh7/conda/4.5.4/envs/pangeo_full_201909/lib/python3.7/site-packages/distributed/comm/core.py", line 227, in connect
    _raise(error)
  File "/softs/rh7/conda/4.5.4/envs/pangeo_full_201909/lib/python3.7/site-packages/distributed/comm/core.py", line 204, in _raise
    raise IOError(msg)
OSError: Timed out trying to connect to 'tcp://10.120.40.97:33653' after 10 s: in <distributed.comm.tcp.TCPConnector object at 0x2b38109e1748>: ConnectionRefusedError: [Errno 111] Connection refused
tornado.application - ERROR - Exception in callback functools.partial(<bound method IOLoop._discard_future_result of <tornado.platform.asyncio.AsyncIOLoop object at 0x2b37e7ab2b38>>, <Task finished coro=<Worker.heartbeat() done, defined at /softs/rh7/conda/4.5.4/envs/pangeo_full_201909/lib/python3.7/site-packages/distributed/worker.py:866> exception=OSError("Timed out trying to connect to 'tcp://10.120.40.97:33653' after 10 s: in <distributed.comm.tcp.TCPConnector object at 0x2b3811101ac8>: ConnectionRefusedError: [Errno 111] Connection refused")>)
Traceback (most recent call last):
  File "/softs/rh7/conda/4.5.4/envs/pangeo_full_201909/lib/python3.7/site-packages/distributed/comm/core.py", line 215, in connect
    quiet_exceptions=EnvironmentError,
tornado.util.TimeoutError: Timeout

During handling of the above exception, another exception occurred:

Traceback (most recent call last):
  File "/softs/rh7/conda/4.5.4/envs/pangeo_full_201909/lib/python3.7/site-packages/tornado/ioloop.py", line 743, in _run_callback
    ret = callback()
  File "/softs/rh7/conda/4.5.4/envs/pangeo_full_201909/lib/python3.7/site-packages/tornado/ioloop.py", line 767, in _discard_future_result
    future.result()
  File "/softs/rh7/conda/4.5.4/envs/pangeo_full_201909/lib/python3.7/site-packages/distributed/worker.py", line 875, in heartbeat
    metrics=await self.get_metrics(),
  File "/softs/rh7/conda/4.5.4/envs/pangeo_full_201909/lib/python3.7/site-packages/distributed/core.py", line 747, in send_recv_from_rpc
    comm = await self.pool.connect(self.addr)
  File "/softs/rh7/conda/4.5.4/envs/pangeo_full_201909/lib/python3.7/site-packages/distributed/core.py", line 874, in connect
    connection_args=self.connection_args,
  File "/softs/rh7/conda/4.5.4/envs/pangeo_full_201909/lib/python3.7/site-packages/distributed/comm/core.py", line 227, in connect
    _raise(error)
  File "/softs/rh7/conda/4.5.4/envs/pangeo_full_201909/lib/python3.7/site-packages/distributed/comm/core.py", line 204, in _raise
    raise IOError(msg)
OSError: Timed out trying to connect to 'tcp://10.120.40.97:33653' after 10 s: in <distributed.comm.tcp.TCPConnector object at 0x2b3811101ac8>: ConnectionRefusedError: [Errno 111] Connection refused
tornado.application - ERROR - Exception in callback functools.partial(<bound method IOLoop._discard_future_result of <tornado.platform.asyncio.AsyncIOLoop object at 0x2b37e7ab2b38>>, <Task finished coro=<Worker.heartbeat() done, defined at /softs/rh7/conda/4.5.4/envs/pangeo_full_201909/lib/python3.7/site-packages/distributed/worker.py:866> exception=OSError("Timed out trying to connect to 'tcp://10.120.40.97:33653' after 10 s: in <distributed.comm.tcp.TCPConnector object at 0x2b37fbf9fcc0>: ConnectionRefusedError: [Errno 111] Connection refused")>)
Traceback (most recent call last):
  File "/softs/rh7/conda/4.5.4/envs/pangeo_full_201909/lib/python3.7/site-packages/distributed/comm/core.py", line 215, in connect
    quiet_exceptions=EnvironmentError,
tornado.util.TimeoutError: Timeout

During handling of the above exception, another exception occurred:

Traceback (most recent call last):
  File "/softs/rh7/conda/4.5.4/envs/pangeo_full_201909/lib/python3.7/site-packages/tornado/ioloop.py", line 743, in _run_callback
    ret = callback()
  File "/softs/rh7/conda/4.5.4/envs/pangeo_full_201909/lib/python3.7/site-packages/tornado/ioloop.py", line 767, in _discard_future_result
    future.result()
  File "/softs/rh7/conda/4.5.4/envs/pangeo_full_201909/lib/python3.7/site-packages/distributed/worker.py", line 875, in heartbeat
    metrics=await self.get_metrics(),
  File "/softs/rh7/conda/4.5.4/envs/pangeo_full_201909/lib/python3.7/site-packages/distributed/core.py", line 747, in send_recv_from_rpc
    comm = await self.pool.connect(self.addr)
  File "/softs/rh7/conda/4.5.4/envs/pangeo_full_201909/lib/python3.7/site-packages/distributed/core.py", line 874, in connect
    connection_args=self.connection_args,
  File "/softs/rh7/conda/4.5.4/envs/pangeo_full_201909/lib/python3.7/site-packages/distributed/comm/core.py", line 227, in connect
    _raise(error)
  File "/softs/rh7/conda/4.5.4/envs/pangeo_full_201909/lib/python3.7/site-packages/distributed/comm/core.py", line 204, in _raise
    raise IOError(msg)
OSError: Timed out trying to connect to 'tcp://10.120.40.97:33653' after 10 s: in <distributed.comm.tcp.TCPConnector object at 0x2b37fbf9fcc0>: ConnectionRefusedError: [Errno 111] Connection refused
tornado.application - ERROR - Exception in callback <function Worker._register_with_scheduler.<locals>.<lambda> at 0x2b37fa7fee18>
Traceback (most recent call last):
  File "/softs/rh7/conda/4.5.4/envs/pangeo_full_201909/lib/python3.7/site-packages/tornado/ioloop.py", line 907, in _run
    return self.callback()
  File "/softs/rh7/conda/4.5.4/envs/pangeo_full_201909/lib/python3.7/site-packages/distributed/worker.py", line 857, in <lambda>
    lambda: self.batched_stream.send({"op": "keep-alive"}),
  File "/softs/rh7/conda/4.5.4/envs/pangeo_full_201909/lib/python3.7/site-packages/distributed/batched.py", line 117, in send
    raise CommClosedError
distributed.comm.core.CommClosedError
tornado.application - ERROR - Exception in callback functools.partial(<bound method IOLoop._discard_future_result of <tornado.platform.asyncio.AsyncIOLoop object at 0x2b37e7ab2b38>>, <Task finished coro=<Worker.heartbeat() done, defined at /softs/rh7/conda/4.5.4/envs/pangeo_full_201909/lib/python3.7/site-packages/distributed/worker.py:866> exception=OSError("Timed out trying to connect to 'tcp://10.120.40.97:33653' after 10 s: in <distributed.comm.tcp.TCPConnector object at 0x2b3810e9a630>: ConnectionRefusedError: [Errno 111] Connection refused")>)
Traceback (most recent call last):
  File "/softs/rh7/conda/4.5.4/envs/pangeo_full_201909/lib/python3.7/site-packages/distributed/comm/core.py", line 215, in connect
    quiet_exceptions=EnvironmentError,
tornado.util.TimeoutError: Timeout

During handling of the above exception, another exception occurred:

Traceback (most recent call last):
  File "/softs/rh7/conda/4.5.4/envs/pangeo_full_201909/lib/python3.7/site-packages/tornado/ioloop.py", line 743, in _run_callback
    ret = callback()
  File "/softs/rh7/conda/4.5.4/envs/pangeo_full_201909/lib/python3.7/site-packages/tornado/ioloop.py", line 767, in _discard_future_result
    future.result()
  File "/softs/rh7/conda/4.5.4/envs/pangeo_full_201909/lib/python3.7/site-packages/distributed/worker.py", line 875, in heartbeat
    metrics=await self.get_metrics(),
  File "/softs/rh7/conda/4.5.4/envs/pangeo_full_201909/lib/python3.7/site-packages/distributed/core.py", line 747, in send_recv_from_rpc
    comm = await self.pool.connect(self.addr)
  File "/softs/rh7/conda/4.5.4/envs/pangeo_full_201909/lib/python3.7/site-packages/distributed/core.py", line 874, in connect
    connection_args=self.connection_args,
  File "/softs/rh7/conda/4.5.4/envs/pangeo_full_201909/lib/python3.7/site-packages/distributed/comm/core.py", line 227, in connect
    _raise(error)
  File "/softs/rh7/conda/4.5.4/envs/pangeo_full_201909/lib/python3.7/site-packages/distributed/comm/core.py", line 204, in _raise
    raise IOError(msg)
OSError: Timed out trying to connect to 'tcp://10.120.40.97:33653' after 10 s: in <distributed.comm.tcp.TCPConnector object at 0x2b3810e9a630>: ConnectionRefusedError: [Errno 111] Connection refused
tornado.application - ERROR - Exception in callback functools.partial(<bound method IOLoop._discard_future_result of <tornado.platform.asyncio.AsyncIOLoop object at 0x2b37e7ab2b38>>, <Task finished coro=<Worker.heartbeat() done, defined at /softs/rh7/conda/4.5.4/envs/pangeo_full_201909/lib/python3.7/site-packages/distributed/worker.py:866> exception=OSError("Timed out trying to connect to 'tcp://10.120.40.97:33653' after 10 s: in <distributed.comm.tcp.TCPConnector object at 0x2b38111011d0>: ConnectionRefusedError: [Errno 111] Connection refused")>)
Traceback (most recent call last):
  File "/softs/rh7/conda/4.5.4/envs/pangeo_full_201909/lib/python3.7/site-packages/distributed/comm/core.py", line 215, in connect
    quiet_exceptions=EnvironmentError,
tornado.util.TimeoutError: Timeout

During handling of the above exception, another exception occurred:

Traceback (most recent call last):
  File "/softs/rh7/conda/4.5.4/envs/pangeo_full_201909/lib/python3.7/site-packages/tornado/ioloop.py", line 743, in _run_callback
    ret = callback()
  File "/softs/rh7/conda/4.5.4/envs/pangeo_full_201909/lib/python3.7/site-packages/tornado/ioloop.py", line 767, in _discard_future_result
    future.result()
  File "/softs/rh7/conda/4.5.4/envs/pangeo_full_201909/lib/python3.7/site-packages/distributed/worker.py", line 875, in heartbeat
    metrics=await self.get_metrics(),
  File "/softs/rh7/conda/4.5.4/envs/pangeo_full_201909/lib/python3.7/site-packages/distributed/core.py", line 747, in send_recv_from_rpc
    comm = await self.pool.connect(self.addr)
  File "/softs/rh7/conda/4.5.4/envs/pangeo_full_201909/lib/python3.7/site-packages/distributed/core.py", line 874, in connect
    connection_args=self.connection_args,
  File "/softs/rh7/conda/4.5.4/envs/pangeo_full_201909/lib/python3.7/site-packages/distributed/comm/core.py", line 227, in connect
    _raise(error)
  File "/softs/rh7/conda/4.5.4/envs/pangeo_full_201909/lib/python3.7/site-packages/distributed/comm/core.py", line 204, in _raise
    raise IOError(msg)
OSError: Timed out trying to connect to 'tcp://10.120.40.97:33653' after 10 s: in <distributed.comm.tcp.TCPConnector object at 0x2b38111011d0>: ConnectionRefusedError: [Errno 111] Connection refused
tornado.application - ERROR - Exception in callback functools.partial(<bound method IOLoop._discard_future_result of <tornado.platform.asyncio.AsyncIOLoop object at 0x2b37e7ab2b38>>, <Task finished coro=<Worker.heartbeat() done, defined at /softs/rh7/conda/4.5.4/envs/pangeo_full_201909/lib/python3.7/site-packages/distributed/worker.py:866> exception=OSError("Timed out trying to connect to 'tcp://10.120.40.97:33653' after 10 s: in <distributed.comm.tcp.TCPConnector object at 0x2b3810a340f0>: ConnectionRefusedError: [Errno 111] Connection refused")>)
Traceback (most recent call last):
  File "/softs/rh7/conda/4.5.4/envs/pangeo_full_201909/lib/python3.7/site-packages/distributed/comm/core.py", line 215, in connect
    quiet_exceptions=EnvironmentError,
tornado.util.TimeoutError: Timeout

During handling of the above exception, another exception occurred:

Traceback (most recent call last):
  File "/softs/rh7/conda/4.5.4/envs/pangeo_full_201909/lib/python3.7/site-packages/tornado/ioloop.py", line 743, in _run_callback
    ret = callback()
  File "/softs/rh7/conda/4.5.4/envs/pangeo_full_201909/lib/python3.7/site-packages/tornado/ioloop.py", line 767, in _discard_future_result
    future.result()
  File "/softs/rh7/conda/4.5.4/envs/pangeo_full_201909/lib/python3.7/site-packages/distributed/worker.py", line 875, in heartbeat
    metrics=await self.get_metrics(),
  File "/softs/rh7/conda/4.5.4/envs/pangeo_full_201909/lib/python3.7/site-packages/distributed/core.py", line 747, in send_recv_from_rpc
    comm = await self.pool.connect(self.addr)
  File "/softs/rh7/conda/4.5.4/envs/pangeo_full_201909/lib/python3.7/site-packages/distributed/core.py", line 874, in connect
    connection_args=self.connection_args,
  File "/softs/rh7/conda/4.5.4/envs/pangeo_full_201909/lib/python3.7/site-packages/distributed/comm/core.py", line 227, in connect
    _raise(error)
  File "/softs/rh7/conda/4.5.4/envs/pangeo_full_201909/lib/python3.7/site-packages/distributed/comm/core.py", line 204, in _raise
    raise IOError(msg)
OSError: Timed out trying to connect to 'tcp://10.120.40.97:33653' after 10 s: in <distributed.comm.tcp.TCPConnector object at 0x2b3810a340f0>: ConnectionRefusedError: [Errno 111] Connection refused
tornado.application - ERROR - Exception in callback functools.partial(<bound method IOLoop._discard_future_result of <tornado.platform.asyncio.AsyncIOLoop object at 0x2b37e7ab2b38>>, <Task finished coro=<Worker.heartbeat() done, defined at /softs/rh7/conda/4.5.4/envs/pangeo_full_201909/lib/python3.7/site-packages/distributed/worker.py:866> exception=OSError("Timed out trying to connect to 'tcp://10.120.40.97:33653' after 10 s: in <distributed.comm.tcp.TCPConnector object at 0x2b3810d41828>: ConnectionRefusedError: [Errno 111] Connection refused")>)
Traceback (most recent call last):
  File "/softs/rh7/conda/4.5.4/envs/pangeo_full_201909/lib/python3.7/site-packages/distributed/comm/core.py", line 215, in connect
    quiet_exceptions=EnvironmentError,
tornado.util.TimeoutError: Timeout

During handling of the above exception, another exception occurred:

Traceback (most recent call last):
  File "/softs/rh7/conda/4.5.4/envs/pangeo_full_201909/lib/python3.7/site-packages/tornado/ioloop.py", line 743, in _run_callback
    ret = callback()
  File "/softs/rh7/conda/4.5.4/envs/pangeo_full_201909/lib/python3.7/site-packages/tornado/ioloop.py", line 767, in _discard_future_result
    future.result()
  File "/softs/rh7/conda/4.5.4/envs/pangeo_full_201909/lib/python3.7/site-packages/distributed/worker.py", line 875, in heartbeat
    metrics=await self.get_metrics(),
  File "/softs/rh7/conda/4.5.4/envs/pangeo_full_201909/lib/python3.7/site-packages/distributed/core.py", line 747, in send_recv_from_rpc
    comm = await self.pool.connect(self.addr)
  File "/softs/rh7/conda/4.5.4/envs/pangeo_full_201909/lib/python3.7/site-packages/distributed/core.py", line 874, in connect
    connection_args=self.connection_args,
  File "/softs/rh7/conda/4.5.4/envs/pangeo_full_201909/lib/python3.7/site-packages/distributed/comm/core.py", line 227, in connect
    _raise(error)
  File "/softs/rh7/conda/4.5.4/envs/pangeo_full_201909/lib/python3.7/site-packages/distributed/comm/core.py", line 204, in _raise
    raise IOError(msg)
OSError: Timed out trying to connect to 'tcp://10.120.40.97:33653' after 10 s: in <distributed.comm.tcp.TCPConnector object at 0x2b3810d41828>: ConnectionRefusedError: [Errno 111] Connection refused
tornado.application - ERROR - Exception in callback functools.partial(<bound method IOLoop._discard_future_result of <tornado.platform.asyncio.AsyncIOLoop object at 0x2b37e7ab2b38>>, <Task finished coro=<Worker.heartbeat() done, defined at /softs/rh7/conda/4.5.4/envs/pangeo_full_201909/lib/python3.7/site-packages/distributed/worker.py:866> exception=OSError("Timed out trying to connect to 'tcp://10.120.40.97:33653' after 10 s: in <distributed.comm.tcp.TCPConnector object at 0x2b3810e9a7b8>: ConnectionRefusedError: [Errno 111] Connection refused")>)
Traceback (most recent call last):
  File "/softs/rh7/conda/4.5.4/envs/pangeo_full_201909/lib/python3.7/site-packages/distributed/comm/core.py", line 215, in connect
    quiet_exceptions=EnvironmentError,
tornado.util.TimeoutError: Timeout

During handling of the above exception, another exception occurred:

Traceback (most recent call last):
  File "/softs/rh7/conda/4.5.4/envs/pangeo_full_201909/lib/python3.7/site-packages/tornado/ioloop.py", line 743, in _run_callback
    ret = callback()
  File "/softs/rh7/conda/4.5.4/envs/pangeo_full_201909/lib/python3.7/site-packages/tornado/ioloop.py", line 767, in _discard_future_result
    future.result()
  File "/softs/rh7/conda/4.5.4/envs/pangeo_full_201909/lib/python3.7/site-packages/distributed/worker.py", line 875, in heartbeat
    metrics=await self.get_metrics(),
  File "/softs/rh7/conda/4.5.4/envs/pangeo_full_201909/lib/python3.7/site-packages/distributed/core.py", line 747, in send_recv_from_rpc
    comm = await self.pool.connect(self.addr)
  File "/softs/rh7/conda/4.5.4/envs/pangeo_full_201909/lib/python3.7/site-packages/distributed/core.py", line 874, in connect
    connection_args=self.connection_args,
  File "/softs/rh7/conda/4.5.4/envs/pangeo_full_201909/lib/python3.7/site-packages/distributed/comm/core.py", line 227, in connect
    _raise(error)
  File "/softs/rh7/conda/4.5.4/envs/pangeo_full_201909/lib/python3.7/site-packages/distributed/comm/core.py", line 204, in _raise
    raise IOError(msg)
OSError: Timed out trying to connect to 'tcp://10.120.40.97:33653' after 10 s: in <distributed.comm.tcp.TCPConnector object at 0x2b3810e9a7b8>: ConnectionRefusedError: [Errno 111] Connection refused
tornado.application - ERROR - Exception in callback <function Worker._register_with_scheduler.<locals>.<lambda> at 0x2b37fa7fee18>
Traceback (most recent call last):
  File "/softs/rh7/conda/4.5.4/envs/pangeo_full_201909/lib/python3.7/site-packages/tornado/ioloop.py", line 907, in _run
    return self.callback()
  File "/softs/rh7/conda/4.5.4/envs/pangeo_full_201909/lib/python3.7/site-packages/distributed/worker.py", line 857, in <lambda>
    lambda: self.batched_stream.send({"op": "keep-alive"}),
  File "/softs/rh7/conda/4.5.4/envs/pangeo_full_201909/lib/python3.7/site-packages/distributed/batched.py", line 117, in send
    raise CommClosedError
distributed.comm.core.CommClosedError
tornado.application - ERROR - Exception in callback functools.partial(<bound method IOLoop._discard_future_result of <tornado.platform.asyncio.AsyncIOLoop object at 0x2b37e7ab2b38>>, <Task finished coro=<Worker.heartbeat() done, defined at /softs/rh7/conda/4.5.4/envs/pangeo_full_201909/lib/python3.7/site-packages/distributed/worker.py:866> exception=OSError("Timed out trying to connect to 'tcp://10.120.40.97:33653' after 10 s: in <distributed.comm.tcp.TCPConnector object at 0x2b38109e1400>: ConnectionRefusedError: [Errno 111] Connection refused")>)
Traceback (most recent call last):
  File "/softs/rh7/conda/4.5.4/envs/pangeo_full_201909/lib/python3.7/site-packages/distributed/comm/core.py", line 215, in connect
    quiet_exceptions=EnvironmentError,
tornado.util.TimeoutError: Timeout

During handling of the above exception, another exception occurred:

Traceback (most recent call last):
  File "/softs/rh7/conda/4.5.4/envs/pangeo_full_201909/lib/python3.7/site-packages/tornado/ioloop.py", line 743, in _run_callback
    ret = callback()
  File "/softs/rh7/conda/4.5.4/envs/pangeo_full_201909/lib/python3.7/site-packages/tornado/ioloop.py", line 767, in _discard_future_result
    future.result()
  File "/softs/rh7/conda/4.5.4/envs/pangeo_full_201909/lib/python3.7/site-packages/distributed/worker.py", line 875, in heartbeat
    metrics=await self.get_metrics(),
  File "/softs/rh7/conda/4.5.4/envs/pangeo_full_201909/lib/python3.7/site-packages/distributed/core.py", line 747, in send_recv_from_rpc
    comm = await self.pool.connect(self.addr)
  File "/softs/rh7/conda/4.5.4/envs/pangeo_full_201909/lib/python3.7/site-packages/distributed/core.py", line 874, in connect
    connection_args=self.connection_args,
  File "/softs/rh7/conda/4.5.4/envs/pangeo_full_201909/lib/python3.7/site-packages/distributed/comm/core.py", line 227, in connect
    _raise(error)
  File "/softs/rh7/conda/4.5.4/envs/pangeo_full_201909/lib/python3.7/site-packages/distributed/comm/core.py", line 204, in _raise
    raise IOError(msg)
OSError: Timed out trying to connect to 'tcp://10.120.40.97:33653' after 10 s: in <distributed.comm.tcp.TCPConnector object at 0x2b38109e1400>: ConnectionRefusedError: [Errno 111] Connection refused
tornado.application - ERROR - Exception in callback functools.partial(<bound method IOLoop._discard_future_result of <tornado.platform.asyncio.AsyncIOLoop object at 0x2b37e7ab2b38>>, <Task finished coro=<Worker.heartbeat() done, defined at /softs/rh7/conda/4.5.4/envs/pangeo_full_201909/lib/python3.7/site-packages/distributed/worker.py:866> exception=OSError("Timed out trying to connect to 'tcp://10.120.40.97:33653' after 10 s: in <distributed.comm.tcp.TCPConnector object at 0x2b381096aba8>: ConnectionRefusedError: [Errno 111] Connection refused")>)
Traceback (most recent call last):
  File "/softs/rh7/conda/4.5.4/envs/pangeo_full_201909/lib/python3.7/site-packages/distributed/comm/core.py", line 215, in connect
    quiet_exceptions=EnvironmentError,
tornado.util.TimeoutError: Timeout

During handling of the above exception, another exception occurred:

Traceback (most recent call last):
  File "/softs/rh7/conda/4.5.4/envs/pangeo_full_201909/lib/python3.7/site-packages/tornado/ioloop.py", line 743, in _run_callback
    ret = callback()
  File "/softs/rh7/conda/4.5.4/envs/pangeo_full_201909/lib/python3.7/site-packages/tornado/ioloop.py", line 767, in _discard_future_result
    future.result()
  File "/softs/rh7/conda/4.5.4/envs/pangeo_full_201909/lib/python3.7/site-packages/distributed/worker.py", line 875, in heartbeat
    metrics=await self.get_metrics(),
  File "/softs/rh7/conda/4.5.4/envs/pangeo_full_201909/lib/python3.7/site-packages/distributed/core.py", line 747, in send_recv_from_rpc
    comm = await self.pool.connect(self.addr)
  File "/softs/rh7/conda/4.5.4/envs/pangeo_full_201909/lib/python3.7/site-packages/distributed/core.py", line 874, in connect
    connection_args=self.connection_args,
  File "/softs/rh7/conda/4.5.4/envs/pangeo_full_201909/lib/python3.7/site-packages/distributed/comm/core.py", line 227, in connect
    _raise(error)
  File "/softs/rh7/conda/4.5.4/envs/pangeo_full_201909/lib/python3.7/site-packages/distributed/comm/core.py", line 204, in _raise
    raise IOError(msg)
OSError: Timed out trying to connect to 'tcp://10.120.40.97:33653' after 10 s: in <distributed.comm.tcp.TCPConnector object at 0x2b381096aba8>: ConnectionRefusedError: [Errno 111] Connection refused
tornado.application - ERROR - Exception in callback functools.partial(<bound method IOLoop._discard_future_result of <tornado.platform.asyncio.AsyncIOLoop object at 0x2b37e7ab2b38>>, <Task finished coro=<Worker.heartbeat() done, defined at /softs/rh7/conda/4.5.4/envs/pangeo_full_201909/lib/python3.7/site-packages/distributed/worker.py:866> exception=OSError("Timed out trying to connect to 'tcp://10.120.40.97:33653' after 10 s: in <distributed.comm.tcp.TCPConnector object at 0x2b38109e15c0>: ConnectionRefusedError: [Errno 111] Connection refused")>)
Traceback (most recent call last):
  File "/softs/rh7/conda/4.5.4/envs/pangeo_full_201909/lib/python3.7/site-packages/distributed/comm/core.py", line 215, in connect
    quiet_exceptions=EnvironmentError,
tornado.util.TimeoutError: Timeout

During handling of the above exception, another exception occurred:

Traceback (most recent call last):
  File "/softs/rh7/conda/4.5.4/envs/pangeo_full_201909/lib/python3.7/site-packages/tornado/ioloop.py", line 743, in _run_callback
    ret = callback()
  File "/softs/rh7/conda/4.5.4/envs/pangeo_full_201909/lib/python3.7/site-packages/tornado/ioloop.py", line 767, in _discard_future_result
    future.result()
  File "/softs/rh7/conda/4.5.4/envs/pangeo_full_201909/lib/python3.7/site-packages/distributed/worker.py", line 875, in heartbeat
    metrics=await self.get_metrics(),
  File "/softs/rh7/conda/4.5.4/envs/pangeo_full_201909/lib/python3.7/site-packages/distributed/core.py", line 747, in send_recv_from_rpc
    comm = await self.pool.connect(self.addr)
  File "/softs/rh7/conda/4.5.4/envs/pangeo_full_201909/lib/python3.7/site-packages/distributed/core.py", line 874, in connect
    connection_args=self.connection_args,
  File "/softs/rh7/conda/4.5.4/envs/pangeo_full_201909/lib/python3.7/site-packages/distributed/comm/core.py", line 227, in connect
    _raise(error)
  File "/softs/rh7/conda/4.5.4/envs/pangeo_full_201909/lib/python3.7/site-packages/distributed/comm/core.py", line 204, in _raise
    raise IOError(msg)
OSError: Timed out trying to connect to 'tcp://10.120.40.97:33653' after 10 s: in <distributed.comm.tcp.TCPConnector object at 0x2b38109e15c0>: ConnectionRefusedError: [Errno 111] Connection refused
tornado.application - ERROR - Exception in callback functools.partial(<bound method IOLoop._discard_future_result of <tornado.platform.asyncio.AsyncIOLoop object at 0x2b37e7ab2b38>>, <Task finished coro=<Worker.heartbeat() done, defined at /softs/rh7/conda/4.5.4/envs/pangeo_full_201909/lib/python3.7/site-packages/distributed/worker.py:866> exception=OSError("Timed out trying to connect to 'tcp://10.120.40.97:33653' after 10 s: in <distributed.comm.tcp.TCPConnector object at 0x2b381153bef0>: ConnectionRefusedError: [Errno 111] Connection refused")>)
Traceback (most recent call last):
  File "/softs/rh7/conda/4.5.4/envs/pangeo_full_201909/lib/python3.7/site-packages/distributed/comm/core.py", line 215, in connect
    quiet_exceptions=EnvironmentError,
tornado.util.TimeoutError: Timeout

During handling of the above exception, another exception occurred:

Traceback (most recent call last):
  File "/softs/rh7/conda/4.5.4/envs/pangeo_full_201909/lib/python3.7/site-packages/tornado/ioloop.py", line 743, in _run_callback
    ret = callback()
  File "/softs/rh7/conda/4.5.4/envs/pangeo_full_201909/lib/python3.7/site-packages/tornado/ioloop.py", line 767, in _discard_future_result
    future.result()
  File "/softs/rh7/conda/4.5.4/envs/pangeo_full_201909/lib/python3.7/site-packages/distributed/worker.py", line 875, in heartbeat
    metrics=await self.get_metrics(),
  File "/softs/rh7/conda/4.5.4/envs/pangeo_full_201909/lib/python3.7/site-packages/distributed/core.py", line 747, in send_recv_from_rpc
    comm = await self.pool.connect(self.addr)
  File "/softs/rh7/conda/4.5.4/envs/pangeo_full_201909/lib/python3.7/site-packages/distributed/core.py", line 874, in connect
    connection_args=self.connection_args,
  File "/softs/rh7/conda/4.5.4/envs/pangeo_full_201909/lib/python3.7/site-packages/distributed/comm/core.py", line 227, in connect
    _raise(error)
  File "/softs/rh7/conda/4.5.4/envs/pangeo_full_201909/lib/python3.7/site-packages/distributed/comm/core.py", line 204, in _raise
    raise IOError(msg)
OSError: Timed out trying to connect to 'tcp://10.120.40.97:33653' after 10 s: in <distributed.comm.tcp.TCPConnector object at 0x2b381153bef0>: ConnectionRefusedError: [Errno 111] Connection refused
tornado.application - ERROR - Exception in callback functools.partial(<bound method IOLoop._discard_future_result of <tornado.platform.asyncio.AsyncIOLoop object at 0x2b37e7ab2b38>>, <Task finished coro=<Worker.heartbeat() done, defined at /softs/rh7/conda/4.5.4/envs/pangeo_full_201909/lib/python3.7/site-packages/distributed/worker.py:866> exception=OSError("Timed out trying to connect to 'tcp://10.120.40.97:33653' after 10 s: in <distributed.comm.tcp.TCPConnector object at 0x2b38114a8e10>: ConnectionRefusedError: [Errno 111] Connection refused")>)
Traceback (most recent call last):
  File "/softs/rh7/conda/4.5.4/envs/pangeo_full_201909/lib/python3.7/site-packages/distributed/comm/core.py", line 215, in connect
    quiet_exceptions=EnvironmentError,
tornado.util.TimeoutError: Timeout

During handling of the above exception, another exception occurred:

Traceback (most recent call last):
  File "/softs/rh7/conda/4.5.4/envs/pangeo_full_201909/lib/python3.7/site-packages/tornado/ioloop.py", line 743, in _run_callback
    ret = callback()
  File "/softs/rh7/conda/4.5.4/envs/pangeo_full_201909/lib/python3.7/site-packages/tornado/ioloop.py", line 767, in _discard_future_result
    future.result()
  File "/softs/rh7/conda/4.5.4/envs/pangeo_full_201909/lib/python3.7/site-packages/distributed/worker.py", line 875, in heartbeat
    metrics=await self.get_metrics(),
  File "/softs/rh7/conda/4.5.4/envs/pangeo_full_201909/lib/python3.7/site-packages/distributed/core.py", line 747, in send_recv_from_rpc
    comm = await self.pool.connect(self.addr)
  File "/softs/rh7/conda/4.5.4/envs/pangeo_full_201909/lib/python3.7/site-packages/distributed/core.py", line 874, in connect
    connection_args=self.connection_args,
  File "/softs/rh7/conda/4.5.4/envs/pangeo_full_201909/lib/python3.7/site-packages/distributed/comm/core.py", line 227, in connect
    _raise(error)
  File "/softs/rh7/conda/4.5.4/envs/pangeo_full_201909/lib/python3.7/site-packages/distributed/comm/core.py", line 204, in _raise
    raise IOError(msg)
OSError: Timed out trying to connect to 'tcp://10.120.40.97:33653' after 10 s: in <distributed.comm.tcp.TCPConnector object at 0x2b38114a8e10>: ConnectionRefusedError: [Errno 111] Connection refused
tornado.application - ERROR - Exception in callback functools.partial(<bound method IOLoop._discard_future_result of <tornado.platform.asyncio.AsyncIOLoop object at 0x2b37e7ab2b38>>, <Task finished coro=<Worker.heartbeat() done, defined at /softs/rh7/conda/4.5.4/envs/pangeo_full_201909/lib/python3.7/site-packages/distributed/worker.py:866> exception=OSError("Timed out trying to connect to 'tcp://10.120.40.97:33653' after 10 s: in <distributed.comm.tcp.TCPConnector object at 0x2b381153b7f0>: ConnectionRefusedError: [Errno 111] Connection refused")>)
Traceback (most recent call last):
  File "/softs/rh7/conda/4.5.4/envs/pangeo_full_201909/lib/python3.7/site-packages/distributed/comm/core.py", line 215, in connect
    quiet_exceptions=EnvironmentError,
tornado.util.TimeoutError: Timeout

During handling of the above exception, another exception occurred:

Traceback (most recent call last):
  File "/softs/rh7/conda/4.5.4/envs/pangeo_full_201909/lib/python3.7/site-packages/tornado/ioloop.py", line 743, in _run_callback
    ret = callback()
  File "/softs/rh7/conda/4.5.4/envs/pangeo_full_201909/lib/python3.7/site-packages/tornado/ioloop.py", line 767, in _discard_future_result
    future.result()
  File "/softs/rh7/conda/4.5.4/envs/pangeo_full_201909/lib/python3.7/site-packages/distributed/worker.py", line 875, in heartbeat
    metrics=await self.get_metrics(),
  File "/softs/rh7/conda/4.5.4/envs/pangeo_full_201909/lib/python3.7/site-packages/distributed/core.py", line 747, in send_recv_from_rpc
    comm = await self.pool.connect(self.addr)
  File "/softs/rh7/conda/4.5.4/envs/pangeo_full_201909/lib/python3.7/site-packages/distributed/core.py", line 874, in connect
    connection_args=self.connection_args,
  File "/softs/rh7/conda/4.5.4/envs/pangeo_full_201909/lib/python3.7/site-packages/distributed/comm/core.py", line 227, in connect
    _raise(error)
  File "/softs/rh7/conda/4.5.4/envs/pangeo_full_201909/lib/python3.7/site-packages/distributed/comm/core.py", line 204, in _raise
    raise IOError(msg)
OSError: Timed out trying to connect to 'tcp://10.120.40.97:33653' after 10 s: in <distributed.comm.tcp.TCPConnector object at 0x2b381153b7f0>: ConnectionRefusedError: [Errno 111] Connection refused
tornado.application - ERROR - Exception in callback <function Worker._register_with_scheduler.<locals>.<lambda> at 0x2b37fa7fee18>
Traceback (most recent call last):
  File "/softs/rh7/conda/4.5.4/envs/pangeo_full_201909/lib/python3.7/site-packages/tornado/ioloop.py", line 907, in _run
    return self.callback()
  File "/softs/rh7/conda/4.5.4/envs/pangeo_full_201909/lib/python3.7/site-packages/distributed/worker.py", line 857, in <lambda>
    lambda: self.batched_stream.send({"op": "keep-alive"}),
  File "/softs/rh7/conda/4.5.4/envs/pangeo_full_201909/lib/python3.7/site-packages/distributed/batched.py", line 117, in send
    raise CommClosedError
distributed.comm.core.CommClosedError
tornado.application - ERROR - Exception in callback functools.partial(<bound method IOLoop._discard_future_result of <tornado.platform.asyncio.AsyncIOLoop object at 0x2b37e7ab2b38>>, <Task finished coro=<Worker.heartbeat() done, defined at /softs/rh7/conda/4.5.4/envs/pangeo_full_201909/lib/python3.7/site-packages/distributed/worker.py:866> exception=OSError("Timed out trying to connect to 'tcp://10.120.40.97:33653' after 10 s: in <distributed.comm.tcp.TCPConnector object at 0x2b381145df98>: ConnectionRefusedError: [Errno 111] Connection refused")>)
Traceback (most recent call last):
  File "/softs/rh7/conda/4.5.4/envs/pangeo_full_201909/lib/python3.7/site-packages/distributed/comm/core.py", line 215, in connect
    quiet_exceptions=EnvironmentError,
tornado.util.TimeoutError: Timeout

During handling of the above exception, another exception occurred:

Traceback (most recent call last):
  File "/softs/rh7/conda/4.5.4/envs/pangeo_full_201909/lib/python3.7/site-packages/tornado/ioloop.py", line 743, in _run_callback
    ret = callback()
  File "/softs/rh7/conda/4.5.4/envs/pangeo_full_201909/lib/python3.7/site-packages/tornado/ioloop.py", line 767, in _discard_future_result
    future.result()
  File "/softs/rh7/conda/4.5.4/envs/pangeo_full_201909/lib/python3.7/site-packages/distributed/worker.py", line 875, in heartbeat
    metrics=await self.get_metrics(),
  File "/softs/rh7/conda/4.5.4/envs/pangeo_full_201909/lib/python3.7/site-packages/distributed/core.py", line 747, in send_recv_from_rpc
    comm = await self.pool.connect(self.addr)
  File "/softs/rh7/conda/4.5.4/envs/pangeo_full_201909/lib/python3.7/site-packages/distributed/core.py", line 874, in connect
    connection_args=self.connection_args,
  File "/softs/rh7/conda/4.5.4/envs/pangeo_full_201909/lib/python3.7/site-packages/distributed/comm/core.py", line 227, in connect
    _raise(error)
  File "/softs/rh7/conda/4.5.4/envs/pangeo_full_201909/lib/python3.7/site-packages/distributed/comm/core.py", line 204, in _raise
    raise IOError(msg)
OSError: Timed out trying to connect to 'tcp://10.120.40.97:33653' after 10 s: in <distributed.comm.tcp.TCPConnector object at 0x2b381145df98>: ConnectionRefusedError: [Errno 111] Connection refused
tornado.application - ERROR - Exception in callback functools.partial(<bound method IOLoop._discard_future_result of <tornado.platform.asyncio.AsyncIOLoop object at 0x2b37e7ab2b38>>, <Task finished coro=<Worker.heartbeat() done, defined at /softs/rh7/conda/4.5.4/envs/pangeo_full_201909/lib/python3.7/site-packages/distributed/worker.py:866> exception=OSError("Timed out trying to connect to 'tcp://10.120.40.97:33653' after 10 s: in <distributed.comm.tcp.TCPConnector object at 0x2b3811502e48>: ConnectionRefusedError: [Errno 111] Connection refused")>)
Traceback (most recent call last):
  File "/softs/rh7/conda/4.5.4/envs/pangeo_full_201909/lib/python3.7/site-packages/distributed/comm/core.py", line 215, in connect
    quiet_exceptions=EnvironmentError,
tornado.util.TimeoutError: Timeout

During handling of the above exception, another exception occurred:

Traceback (most recent call last):
  File "/softs/rh7/conda/4.5.4/envs/pangeo_full_201909/lib/python3.7/site-packages/tornado/ioloop.py", line 743, in _run_callback
    ret = callback()
  File "/softs/rh7/conda/4.5.4/envs/pangeo_full_201909/lib/python3.7/site-packages/tornado/ioloop.py", line 767, in _discard_future_result
    future.result()
  File "/softs/rh7/conda/4.5.4/envs/pangeo_full_201909/lib/python3.7/site-packages/distributed/worker.py", line 875, in heartbeat
    metrics=await self.get_metrics(),
  File "/softs/rh7/conda/4.5.4/envs/pangeo_full_201909/lib/python3.7/site-packages/distributed/core.py", line 747, in send_recv_from_rpc
    comm = await self.pool.connect(self.addr)
  File "/softs/rh7/conda/4.5.4/envs/pangeo_full_201909/lib/python3.7/site-packages/distributed/core.py", line 874, in connect
    connection_args=self.connection_args,
  File "/softs/rh7/conda/4.5.4/envs/pangeo_full_201909/lib/python3.7/site-packages/distributed/comm/core.py", line 227, in connect
    _raise(error)
  File "/softs/rh7/conda/4.5.4/envs/pangeo_full_201909/lib/python3.7/site-packages/distributed/comm/core.py", line 204, in _raise
    raise IOError(msg)
OSError: Timed out trying to connect to 'tcp://10.120.40.97:33653' after 10 s: in <distributed.comm.tcp.TCPConnector object at 0x2b3811502e48>: ConnectionRefusedError: [Errno 111] Connection refused
tornado.application - ERROR - Exception in callback functools.partial(<bound method IOLoop._discard_future_result of <tornado.platform.asyncio.AsyncIOLoop object at 0x2b37e7ab2b38>>, <Task finished coro=<Worker.heartbeat() done, defined at /softs/rh7/conda/4.5.4/envs/pangeo_full_201909/lib/python3.7/site-packages/distributed/worker.py:866> exception=OSError("Timed out trying to connect to 'tcp://10.120.40.97:33653' after 10 s: in <distributed.comm.tcp.TCPConnector object at 0x2b3810e9a160>: ConnectionRefusedError: [Errno 111] Connection refused")>)
Traceback (most recent call last):
  File "/softs/rh7/conda/4.5.4/envs/pangeo_full_201909/lib/python3.7/site-packages/distributed/comm/core.py", line 215, in connect
    quiet_exceptions=EnvironmentError,
tornado.util.TimeoutError: Timeout

During handling of the above exception, another exception occurred:

Traceback (most recent call last):
  File "/softs/rh7/conda/4.5.4/envs/pangeo_full_201909/lib/python3.7/site-packages/tornado/ioloop.py", line 743, in _run_callback
    ret = callback()
  File "/softs/rh7/conda/4.5.4/envs/pangeo_full_201909/lib/python3.7/site-packages/tornado/ioloop.py", line 767, in _discard_future_result
    future.result()
  File "/softs/rh7/conda/4.5.4/envs/pangeo_full_201909/lib/python3.7/site-packages/distributed/worker.py", line 875, in heartbeat
    metrics=await self.get_metrics(),
  File "/softs/rh7/conda/4.5.4/envs/pangeo_full_201909/lib/python3.7/site-packages/distributed/core.py", line 747, in send_recv_from_rpc
    comm = await self.pool.connect(self.addr)
  File "/softs/rh7/conda/4.5.4/envs/pangeo_full_201909/lib/python3.7/site-packages/distributed/core.py", line 874, in connect
    connection_args=self.connection_args,
  File "/softs/rh7/conda/4.5.4/envs/pangeo_full_201909/lib/python3.7/site-packages/distributed/comm/core.py", line 227, in connect
    _raise(error)
  File "/softs/rh7/conda/4.5.4/envs/pangeo_full_201909/lib/python3.7/site-packages/distributed/comm/core.py", line 204, in _raise
    raise IOError(msg)
OSError: Timed out trying to connect to 'tcp://10.120.40.97:33653' after 10 s: in <distributed.comm.tcp.TCPConnector object at 0x2b3810e9a160>: ConnectionRefusedError: [Errno 111] Connection refused
tornado.application - ERROR - Exception in callback functools.partial(<bound method IOLoop._discard_future_result of <tornado.platform.asyncio.AsyncIOLoop object at 0x2b37e7ab2b38>>, <Task finished coro=<Worker.heartbeat() done, defined at /softs/rh7/conda/4.5.4/envs/pangeo_full_201909/lib/python3.7/site-packages/distributed/worker.py:866> exception=OSError("Timed out trying to connect to 'tcp://10.120.40.97:33653' after 10 s: in <distributed.comm.tcp.TCPConnector object at 0x2b3811574898>: ConnectionRefusedError: [Errno 111] Connection refused")>)
Traceback (most recent call last):
  File "/softs/rh7/conda/4.5.4/envs/pangeo_full_201909/lib/python3.7/site-packages/distributed/comm/core.py", line 215, in connect
    quiet_exceptions=EnvironmentError,
tornado.util.TimeoutError: Timeout

During handling of the above exception, another exception occurred:

Traceback (most recent call last):
  File "/softs/rh7/conda/4.5.4/envs/pangeo_full_201909/lib/python3.7/site-packages/tornado/ioloop.py", line 743, in _run_callback
    ret = callback()
  File "/softs/rh7/conda/4.5.4/envs/pangeo_full_201909/lib/python3.7/site-packages/tornado/ioloop.py", line 767, in _discard_future_result
    future.result()
  File "/softs/rh7/conda/4.5.4/envs/pangeo_full_201909/lib/python3.7/site-packages/distributed/worker.py", line 875, in heartbeat
    metrics=await self.get_metrics(),
  File "/softs/rh7/conda/4.5.4/envs/pangeo_full_201909/lib/python3.7/site-packages/distributed/core.py", line 747, in send_recv_from_rpc
    comm = await self.pool.connect(self.addr)
  File "/softs/rh7/conda/4.5.4/envs/pangeo_full_201909/lib/python3.7/site-packages/distributed/core.py", line 874, in connect
    connection_args=self.connection_args,
  File "/softs/rh7/conda/4.5.4/envs/pangeo_full_201909/lib/python3.7/site-packages/distributed/comm/core.py", line 227, in connect
    _raise(error)
  File "/softs/rh7/conda/4.5.4/envs/pangeo_full_201909/lib/python3.7/site-packages/distributed/comm/core.py", line 204, in _raise
    raise IOError(msg)
OSError: Timed out trying to connect to 'tcp://10.120.40.97:33653' after 10 s: in <distributed.comm.tcp.TCPConnector object at 0x2b3811574898>: ConnectionRefusedError: [Errno 111] Connection refused
tornado.application - ERROR - Exception in callback functools.partial(<bound method IOLoop._discard_future_result of <tornado.platform.asyncio.AsyncIOLoop object at 0x2b37e7ab2b38>>, <Task finished coro=<Worker.heartbeat() done, defined at /softs/rh7/conda/4.5.4/envs/pangeo_full_201909/lib/python3.7/site-packages/distributed/worker.py:866> exception=OSError("Timed out trying to connect to 'tcp://10.120.40.97:33653' after 10 s: in <distributed.comm.tcp.TCPConnector object at 0x2b3811502c18>: ConnectionRefusedError: [Errno 111] Connection refused")>)
Traceback (most recent call last):
  File "/softs/rh7/conda/4.5.4/envs/pangeo_full_201909/lib/python3.7/site-packages/distributed/comm/tcp.py", line 356, in connect
    ip, port, max_buffer_size=MAX_BUFFER_SIZE, **kwargs
  File "/softs/rh7/conda/4.5.4/envs/pangeo_full_201909/lib/python3.7/site-packages/tornado/tcpclient.py", line 280, in connect
    af, addr, stream = await connector.start(connect_timeout=timeout)
  File "/softs/rh7/conda/4.5.4/envs/pangeo_full_201909/lib/python3.7/site-packages/tornado/tcpclient.py", line 143, in on_connect_done
    stream = future.result()
tornado.iostream.StreamClosedError: Stream is closed

During handling of the above exception, another exception occurred:

Traceback (most recent call last):
  File "/softs/rh7/conda/4.5.4/envs/pangeo_full_201909/lib/python3.7/site-packages/distributed/comm/core.py", line 215, in connect
    quiet_exceptions=EnvironmentError,
  File "/softs/rh7/conda/4.5.4/envs/pangeo_full_201909/lib/python3.7/site-packages/distributed/comm/tcp.py", line 368, in connect
    convert_stream_closed_error(self, e)
  File "/softs/rh7/conda/4.5.4/envs/pangeo_full_201909/lib/python3.7/site-packages/distributed/comm/tcp.py", line 138, in convert_stream_closed_error
    raise CommClosedError("in %s: %s: %s" % (obj, exc.__class__.__name__, exc))
distributed.comm.core.CommClosedError: in <distributed.comm.tcp.TCPConnector object at 0x2b3811502c18>: ConnectionRefusedError: [Errno 111] Connection refused

During handling of the above exception, another exception occurred:

Traceback (most recent call last):
  File "/softs/rh7/conda/4.5.4/envs/pangeo_full_201909/lib/python3.7/site-packages/tornado/ioloop.py", line 743, in _run_callback
    ret = callback()
  File "/softs/rh7/conda/4.5.4/envs/pangeo_full_201909/lib/python3.7/site-packages/tornado/ioloop.py", line 767, in _discard_future_result
    future.result()
  File "/softs/rh7/conda/4.5.4/envs/pangeo_full_201909/lib/python3.7/site-packages/distributed/worker.py", line 875, in heartbeat
    metrics=await self.get_metrics(),
  File "/softs/rh7/conda/4.5.4/envs/pangeo_full_201909/lib/python3.7/site-packages/distributed/core.py", line 747, in send_recv_from_rpc
    comm = await self.pool.connect(self.addr)
  File "/softs/rh7/conda/4.5.4/envs/pangeo_full_201909/lib/python3.7/site-packages/distributed/core.py", line 874, in connect
    connection_args=self.connection_args,
  File "/softs/rh7/conda/4.5.4/envs/pangeo_full_201909/lib/python3.7/site-packages/distributed/comm/core.py", line 225, in connect
    _raise(error)
  File "/softs/rh7/conda/4.5.4/envs/pangeo_full_201909/lib/python3.7/site-packages/distributed/comm/core.py", line 204, in _raise
    raise IOError(msg)
OSError: Timed out trying to connect to 'tcp://10.120.40.97:33653' after 10 s: in <distributed.comm.tcp.TCPConnector object at 0x2b3811502c18>: ConnectionRefusedError: [Errno 111] Connection refused
tornado.application - ERROR - Exception in callback <function Worker._register_with_scheduler.<locals>.<lambda> at 0x2b37fa7fee18>
Traceback (most recent call last):
  File "/softs/rh7/conda/4.5.4/envs/pangeo_full_201909/lib/python3.7/site-packages/tornado/ioloop.py", line 907, in _run
    return self.callback()
  File "/softs/rh7/conda/4.5.4/envs/pangeo_full_201909/lib/python3.7/site-packages/distributed/worker.py", line 857, in <lambda>
    lambda: self.batched_stream.send({"op": "keep-alive"}),
  File "/softs/rh7/conda/4.5.4/envs/pangeo_full_201909/lib/python3.7/site-packages/distributed/batched.py", line 117, in send
    raise CommClosedError
distributed.comm.core.CommClosedError
tornado.application - ERROR - Exception in callback functools.partial(<bound method IOLoop._discard_future_result of <tornado.platform.asyncio.AsyncIOLoop object at 0x2b37e7ab2b38>>, <Task finished coro=<Worker.heartbeat() done, defined at /softs/rh7/conda/4.5.4/envs/pangeo_full_201909/lib/python3.7/site-packages/distributed/worker.py:866> exception=OSError("Timed out trying to connect to 'tcp://10.120.40.97:33653' after 10 s: in <distributed.comm.tcp.TCPConnector object at 0x2b38115a3668>: ConnectionRefusedError: [Errno 111] Connection refused")>)
Traceback (most recent call last):
  File "/softs/rh7/conda/4.5.4/envs/pangeo_full_201909/lib/python3.7/site-packages/distributed/comm/core.py", line 215, in connect
    quiet_exceptions=EnvironmentError,
tornado.util.TimeoutError: Timeout

During handling of the above exception, another exception occurred:

Traceback (most recent call last):
  File "/softs/rh7/conda/4.5.4/envs/pangeo_full_201909/lib/python3.7/site-packages/tornado/ioloop.py", line 743, in _run_callback
    ret = callback()
  File "/softs/rh7/conda/4.5.4/envs/pangeo_full_201909/lib/python3.7/site-packages/tornado/ioloop.py", line 767, in _discard_future_result
    future.result()
  File "/softs/rh7/conda/4.5.4/envs/pangeo_full_201909/lib/python3.7/site-packages/distributed/worker.py", line 875, in heartbeat
    metrics=await self.get_metrics(),
  File "/softs/rh7/conda/4.5.4/envs/pangeo_full_201909/lib/python3.7/site-packages/distributed/core.py", line 747, in send_recv_from_rpc
    comm = await self.pool.connect(self.addr)
  File "/softs/rh7/conda/4.5.4/envs/pangeo_full_201909/lib/python3.7/site-packages/distributed/core.py", line 874, in connect
    connection_args=self.connection_args,
  File "/softs/rh7/conda/4.5.4/envs/pangeo_full_201909/lib/python3.7/site-packages/distributed/comm/core.py", line 227, in connect
    _raise(error)
  File "/softs/rh7/conda/4.5.4/envs/pangeo_full_201909/lib/python3.7/site-packages/distributed/comm/core.py", line 204, in _raise
    raise IOError(msg)
OSError: Timed out trying to connect to 'tcp://10.120.40.97:33653' after 10 s: in <distributed.comm.tcp.TCPConnector object at 0x2b38115a3668>: ConnectionRefusedError: [Errno 111] Connection refused
tornado.application - ERROR - Exception in callback functools.partial(<bound method IOLoop._discard_future_result of <tornado.platform.asyncio.AsyncIOLoop object at 0x2b37e7ab2b38>>, <Task finished coro=<Worker.heartbeat() done, defined at /softs/rh7/conda/4.5.4/envs/pangeo_full_201909/lib/python3.7/site-packages/distributed/worker.py:866> exception=OSError("Timed out trying to connect to 'tcp://10.120.40.97:33653' after 10 s: in <distributed.comm.tcp.TCPConnector object at 0x2b3810d418d0>: ConnectionRefusedError: [Errno 111] Connection refused")>)
Traceback (most recent call last):
  File "/softs/rh7/conda/4.5.4/envs/pangeo_full_201909/lib/python3.7/site-packages/distributed/comm/core.py", line 215, in connect
    quiet_exceptions=EnvironmentError,
tornado.util.TimeoutError: Timeout

During handling of the above exception, another exception occurred:

Traceback (most recent call last):
  File "/softs/rh7/conda/4.5.4/envs/pangeo_full_201909/lib/python3.7/site-packages/tornado/ioloop.py", line 743, in _run_callback
    ret = callback()
  File "/softs/rh7/conda/4.5.4/envs/pangeo_full_201909/lib/python3.7/site-packages/tornado/ioloop.py", line 767, in _discard_future_result
    future.result()
  File "/softs/rh7/conda/4.5.4/envs/pangeo_full_201909/lib/python3.7/site-packages/distributed/worker.py", line 875, in heartbeat
    metrics=await self.get_metrics(),
  File "/softs/rh7/conda/4.5.4/envs/pangeo_full_201909/lib/python3.7/site-packages/distributed/core.py", line 747, in send_recv_from_rpc
    comm = await self.pool.connect(self.addr)
  File "/softs/rh7/conda/4.5.4/envs/pangeo_full_201909/lib/python3.7/site-packages/distributed/core.py", line 874, in connect
    connection_args=self.connection_args,
  File "/softs/rh7/conda/4.5.4/envs/pangeo_full_201909/lib/python3.7/site-packages/distributed/comm/core.py", line 227, in connect
    _raise(error)
  File "/softs/rh7/conda/4.5.4/envs/pangeo_full_201909/lib/python3.7/site-packages/distributed/comm/core.py", line 204, in _raise
    raise IOError(msg)
OSError: Timed out trying to connect to 'tcp://10.120.40.97:33653' after 10 s: in <distributed.comm.tcp.TCPConnector object at 0x2b3810d418d0>: ConnectionRefusedError: [Errno 111] Connection refused
tornado.application - ERROR - Exception in callback functools.partial(<bound method IOLoop._discard_future_result of <tornado.platform.asyncio.AsyncIOLoop object at 0x2b37e7ab2b38>>, <Task finished coro=<Worker.heartbeat() done, defined at /softs/rh7/conda/4.5.4/envs/pangeo_full_201909/lib/python3.7/site-packages/distributed/worker.py:866> exception=OSError("Timed out trying to connect to 'tcp://10.120.40.97:33653' after 10 s: in <distributed.comm.tcp.TCPConnector object at 0x2b3810d41b00>: ConnectionRefusedError: [Errno 111] Connection refused")>)
Traceback (most recent call last):
  File "/softs/rh7/conda/4.5.4/envs/pangeo_full_201909/lib/python3.7/site-packages/distributed/comm/core.py", line 215, in connect
    quiet_exceptions=EnvironmentError,
tornado.util.TimeoutError: Timeout

During handling of the above exception, another exception occurred:

Traceback (most recent call last):
  File "/softs/rh7/conda/4.5.4/envs/pangeo_full_201909/lib/python3.7/site-packages/tornado/ioloop.py", line 743, in _run_callback
    ret = callback()
  File "/softs/rh7/conda/4.5.4/envs/pangeo_full_201909/lib/python3.7/site-packages/tornado/ioloop.py", line 767, in _discard_future_result
    future.result()
  File "/softs/rh7/conda/4.5.4/envs/pangeo_full_201909/lib/python3.7/site-packages/distributed/worker.py", line 875, in heartbeat
    metrics=await self.get_metrics(),
  File "/softs/rh7/conda/4.5.4/envs/pangeo_full_201909/lib/python3.7/site-packages/distributed/core.py", line 747, in send_recv_from_rpc
    comm = await self.pool.connect(self.addr)
  File "/softs/rh7/conda/4.5.4/envs/pangeo_full_201909/lib/python3.7/site-packages/distributed/core.py", line 874, in connect
    connection_args=self.connection_args,
  File "/softs/rh7/conda/4.5.4/envs/pangeo_full_201909/lib/python3.7/site-packages/distributed/comm/core.py", line 227, in connect
    _raise(error)
  File "/softs/rh7/conda/4.5.4/envs/pangeo_full_201909/lib/python3.7/site-packages/distributed/comm/core.py", line 204, in _raise
    raise IOError(msg)
OSError: Timed out trying to connect to 'tcp://10.120.40.97:33653' after 10 s: in <distributed.comm.tcp.TCPConnector object at 0x2b3810d41b00>: ConnectionRefusedError: [Errno 111] Connection refused
tornado.application - ERROR - Exception in callback functools.partial(<bound method IOLoop._discard_future_result of <tornado.platform.asyncio.AsyncIOLoop object at 0x2b37e7ab2b38>>, <Task finished coro=<Worker.heartbeat() done, defined at /softs/rh7/conda/4.5.4/envs/pangeo_full_201909/lib/python3.7/site-packages/distributed/worker.py:866> exception=OSError("Timed out trying to connect to 'tcp://10.120.40.97:33653' after 10 s: in <distributed.comm.tcp.TCPConnector object at 0x2b38115a3358>: ConnectionRefusedError: [Errno 111] Connection refused")>)
Traceback (most recent call last):
  File "/softs/rh7/conda/4.5.4/envs/pangeo_full_201909/lib/python3.7/site-packages/distributed/comm/core.py", line 215, in connect
    quiet_exceptions=EnvironmentError,
tornado.util.TimeoutError: Timeout

During handling of the above exception, another exception occurred:

Traceback (most recent call last):
  File "/softs/rh7/conda/4.5.4/envs/pangeo_full_201909/lib/python3.7/site-packages/tornado/ioloop.py", line 743, in _run_callback
    ret = callback()
  File "/softs/rh7/conda/4.5.4/envs/pangeo_full_201909/lib/python3.7/site-packages/tornado/ioloop.py", line 767, in _discard_future_result
    future.result()
  File "/softs/rh7/conda/4.5.4/envs/pangeo_full_201909/lib/python3.7/site-packages/distributed/worker.py", line 875, in heartbeat
    metrics=await self.get_metrics(),
  File "/softs/rh7/conda/4.5.4/envs/pangeo_full_201909/lib/python3.7/site-packages/distributed/core.py", line 747, in send_recv_from_rpc
    comm = await self.pool.connect(self.addr)
  File "/softs/rh7/conda/4.5.4/envs/pangeo_full_201909/lib/python3.7/site-packages/distributed/core.py", line 874, in connect
    connection_args=self.connection_args,
  File "/softs/rh7/conda/4.5.4/envs/pangeo_full_201909/lib/python3.7/site-packages/distributed/comm/core.py", line 227, in connect
    _raise(error)
  File "/softs/rh7/conda/4.5.4/envs/pangeo_full_201909/lib/python3.7/site-packages/distributed/comm/core.py", line 204, in _raise
    raise IOError(msg)
OSError: Timed out trying to connect to 'tcp://10.120.40.97:33653' after 10 s: in <distributed.comm.tcp.TCPConnector object at 0x2b38115a3358>: ConnectionRefusedError: [Errno 111] Connection refused
tornado.application - ERROR - Exception in callback functools.partial(<bound method IOLoop._discard_future_result of <tornado.platform.asyncio.AsyncIOLoop object at 0x2b37e7ab2b38>>, <Task finished coro=<Worker.heartbeat() done, defined at /softs/rh7/conda/4.5.4/envs/pangeo_full_201909/lib/python3.7/site-packages/distributed/worker.py:866> exception=OSError("Timed out trying to connect to 'tcp://10.120.40.97:33653' after 10 s: in <distributed.comm.tcp.TCPConnector object at 0x2b38115027f0>: ConnectionRefusedError: [Errno 111] Connection refused")>)
Traceback (most recent call last):
  File "/softs/rh7/conda/4.5.4/envs/pangeo_full_201909/lib/python3.7/site-packages/distributed/comm/core.py", line 215, in connect
    quiet_exceptions=EnvironmentError,
tornado.util.TimeoutError: Timeout

During handling of the above exception, another exception occurred:

Traceback (most recent call last):
  File "/softs/rh7/conda/4.5.4/envs/pangeo_full_201909/lib/python3.7/site-packages/tornado/ioloop.py", line 743, in _run_callback
    ret = callback()
  File "/softs/rh7/conda/4.5.4/envs/pangeo_full_201909/lib/python3.7/site-packages/tornado/ioloop.py", line 767, in _discard_future_result
    future.result()
  File "/softs/rh7/conda/4.5.4/envs/pangeo_full_201909/lib/python3.7/site-packages/distributed/worker.py", line 875, in heartbeat
    metrics=await self.get_metrics(),
  File "/softs/rh7/conda/4.5.4/envs/pangeo_full_201909/lib/python3.7/site-packages/distributed/core.py", line 747, in send_recv_from_rpc
    comm = await self.pool.connect(self.addr)
  File "/softs/rh7/conda/4.5.4/envs/pangeo_full_201909/lib/python3.7/site-packages/distributed/core.py", line 874, in connect
    connection_args=self.connection_args,
  File "/softs/rh7/conda/4.5.4/envs/pangeo_full_201909/lib/python3.7/site-packages/distributed/comm/core.py", line 227, in connect
    _raise(error)
  File "/softs/rh7/conda/4.5.4/envs/pangeo_full_201909/lib/python3.7/site-packages/distributed/comm/core.py", line 204, in _raise
    raise IOError(msg)
OSError: Timed out trying to connect to 'tcp://10.120.40.97:33653' after 10 s: in <distributed.comm.tcp.TCPConnector object at 0x2b38115027f0>: ConnectionRefusedError: [Errno 111] Connection refused
tornado.application - ERROR - Exception in callback functools.partial(<bound method IOLoop._discard_future_result of <tornado.platform.asyncio.AsyncIOLoop object at 0x2b37e7ab2b38>>, <Task finished coro=<Worker.heartbeat() done, defined at /softs/rh7/conda/4.5.4/envs/pangeo_full_201909/lib/python3.7/site-packages/distributed/worker.py:866> exception=OSError("Timed out trying to connect to 'tcp://10.120.40.97:33653' after 10 s: in <distributed.comm.tcp.TCPConnector object at 0x2b3811574ba8>: ConnectionRefusedError: [Errno 111] Connection refused")>)
Traceback (most recent call last):
  File "/softs/rh7/conda/4.5.4/envs/pangeo_full_201909/lib/python3.7/site-packages/distributed/comm/core.py", line 215, in connect
    quiet_exceptions=EnvironmentError,
tornado.util.TimeoutError: Timeout

During handling of the above exception, another exception occurred:

Traceback (most recent call last):
  File "/softs/rh7/conda/4.5.4/envs/pangeo_full_201909/lib/python3.7/site-packages/tornado/ioloop.py", line 743, in _run_callback
    ret = callback()
  File "/softs/rh7/conda/4.5.4/envs/pangeo_full_201909/lib/python3.7/site-packages/tornado/ioloop.py", line 767, in _discard_future_result
    future.result()
  File "/softs/rh7/conda/4.5.4/envs/pangeo_full_201909/lib/python3.7/site-packages/distributed/worker.py", line 875, in heartbeat
    metrics=await self.get_metrics(),
  File "/softs/rh7/conda/4.5.4/envs/pangeo_full_201909/lib/python3.7/site-packages/distributed/core.py", line 747, in send_recv_from_rpc
    comm = await self.pool.connect(self.addr)
  File "/softs/rh7/conda/4.5.4/envs/pangeo_full_201909/lib/python3.7/site-packages/distributed/core.py", line 874, in connect
    connection_args=self.connection_args,
  File "/softs/rh7/conda/4.5.4/envs/pangeo_full_201909/lib/python3.7/site-packages/distributed/comm/core.py", line 227, in connect
    _raise(error)
  File "/softs/rh7/conda/4.5.4/envs/pangeo_full_201909/lib/python3.7/site-packages/distributed/comm/core.py", line 204, in _raise
    raise IOError(msg)
OSError: Timed out trying to connect to 'tcp://10.120.40.97:33653' after 10 s: in <distributed.comm.tcp.TCPConnector object at 0x2b3811574ba8>: ConnectionRefusedError: [Errno 111] Connection refused
tornado.application - ERROR - Exception in callback <function Worker._register_with_scheduler.<locals>.<lambda> at 0x2b37fa7fee18>
Traceback (most recent call last):
  File "/softs/rh7/conda/4.5.4/envs/pangeo_full_201909/lib/python3.7/site-packages/tornado/ioloop.py", line 907, in _run
    return self.callback()
  File "/softs/rh7/conda/4.5.4/envs/pangeo_full_201909/lib/python3.7/site-packages/distributed/worker.py", line 857, in <lambda>
    lambda: self.batched_stream.send({"op": "keep-alive"}),
  File "/softs/rh7/conda/4.5.4/envs/pangeo_full_201909/lib/python3.7/site-packages/distributed/batched.py", line 117, in send
    raise CommClosedError
distributed.comm.core.CommClosedError
tornado.application - ERROR - Exception in callback functools.partial(<bound method IOLoop._discard_future_result of <tornado.platform.asyncio.AsyncIOLoop object at 0x2b37e7ab2b38>>, <Task finished coro=<Worker.heartbeat() done, defined at /softs/rh7/conda/4.5.4/envs/pangeo_full_201909/lib/python3.7/site-packages/distributed/worker.py:866> exception=OSError("Timed out trying to connect to 'tcp://10.120.40.97:33653' after 10 s: in <distributed.comm.tcp.TCPConnector object at 0x2b3811502f60>: ConnectionRefusedError: [Errno 111] Connection refused")>)
Traceback (most recent call last):
  File "/softs/rh7/conda/4.5.4/envs/pangeo_full_201909/lib/python3.7/site-packages/distributed/comm/core.py", line 215, in connect
    quiet_exceptions=EnvironmentError,
tornado.util.TimeoutError: Timeout

During handling of the above exception, another exception occurred:

Traceback (most recent call last):
  File "/softs/rh7/conda/4.5.4/envs/pangeo_full_201909/lib/python3.7/site-packages/tornado/ioloop.py", line 743, in _run_callback
    ret = callback()
  File "/softs/rh7/conda/4.5.4/envs/pangeo_full_201909/lib/python3.7/site-packages/tornado/ioloop.py", line 767, in _discard_future_result
    future.result()
  File "/softs/rh7/conda/4.5.4/envs/pangeo_full_201909/lib/python3.7/site-packages/distributed/worker.py", line 875, in heartbeat
    metrics=await self.get_metrics(),
  File "/softs/rh7/conda/4.5.4/envs/pangeo_full_201909/lib/python3.7/site-packages/distributed/core.py", line 747, in send_recv_from_rpc
    comm = await self.pool.connect(self.addr)
  File "/softs/rh7/conda/4.5.4/envs/pangeo_full_201909/lib/python3.7/site-packages/distributed/core.py", line 874, in connect
    connection_args=self.connection_args,
  File "/softs/rh7/conda/4.5.4/envs/pangeo_full_201909/lib/python3.7/site-packages/distributed/comm/core.py", line 227, in connect
    _raise(error)
  File "/softs/rh7/conda/4.5.4/envs/pangeo_full_201909/lib/python3.7/site-packages/distributed/comm/core.py", line 204, in _raise
    raise IOError(msg)
OSError: Timed out trying to connect to 'tcp://10.120.40.97:33653' after 10 s: in <distributed.comm.tcp.TCPConnector object at 0x2b3811502f60>: ConnectionRefusedError: [Errno 111] Connection refused
tornado.application - ERROR - Exception in callback functools.partial(<bound method IOLoop._discard_future_result of <tornado.platform.asyncio.AsyncIOLoop object at 0x2b37e7ab2b38>>, <Task finished coro=<Worker.heartbeat() done, defined at /softs/rh7/conda/4.5.4/envs/pangeo_full_201909/lib/python3.7/site-packages/distributed/worker.py:866> exception=OSError("Timed out trying to connect to 'tcp://10.120.40.97:33653' after 10 s: in <distributed.comm.tcp.TCPConnector object at 0x2b3810ede470>: ConnectionRefusedError: [Errno 111] Connection refused")>)
Traceback (most recent call last):
  File "/softs/rh7/conda/4.5.4/envs/pangeo_full_201909/lib/python3.7/site-packages/distributed/comm/core.py", line 215, in connect
    quiet_exceptions=EnvironmentError,
tornado.util.TimeoutError: Timeout

During handling of the above exception, another exception occurred:

Traceback (most recent call last):
  File "/softs/rh7/conda/4.5.4/envs/pangeo_full_201909/lib/python3.7/site-packages/tornado/ioloop.py", line 743, in _run_callback
    ret = callback()
  File "/softs/rh7/conda/4.5.4/envs/pangeo_full_201909/lib/python3.7/site-packages/tornado/ioloop.py", line 767, in _discard_future_result
    future.result()
  File "/softs/rh7/conda/4.5.4/envs/pangeo_full_201909/lib/python3.7/site-packages/distributed/worker.py", line 875, in heartbeat
    metrics=await self.get_metrics(),
  File "/softs/rh7/conda/4.5.4/envs/pangeo_full_201909/lib/python3.7/site-packages/distributed/core.py", line 747, in send_recv_from_rpc
    comm = await self.pool.connect(self.addr)
  File "/softs/rh7/conda/4.5.4/envs/pangeo_full_201909/lib/python3.7/site-packages/distributed/core.py", line 874, in connect
    connection_args=self.connection_args,
  File "/softs/rh7/conda/4.5.4/envs/pangeo_full_201909/lib/python3.7/site-packages/distributed/comm/core.py", line 227, in connect
    _raise(error)
  File "/softs/rh7/conda/4.5.4/envs/pangeo_full_201909/lib/python3.7/site-packages/distributed/comm/core.py", line 204, in _raise
    raise IOError(msg)
OSError: Timed out trying to connect to 'tcp://10.120.40.97:33653' after 10 s: in <distributed.comm.tcp.TCPConnector object at 0x2b3810ede470>: ConnectionRefusedError: [Errno 111] Connection refused
tornado.application - ERROR - Exception in callback functools.partial(<bound method IOLoop._discard_future_result of <tornado.platform.asyncio.AsyncIOLoop object at 0x2b37e7ab2b38>>, <Task finished coro=<Worker.heartbeat() done, defined at /softs/rh7/conda/4.5.4/envs/pangeo_full_201909/lib/python3.7/site-packages/distributed/worker.py:866> exception=OSError("Timed out trying to connect to 'tcp://10.120.40.97:33653' after 10 s: in <distributed.comm.tcp.TCPConnector object at 0x2b37fbf9f8d0>: ConnectionRefusedError: [Errno 111] Connection refused")>)
Traceback (most recent call last):
  File "/softs/rh7/conda/4.5.4/envs/pangeo_full_201909/lib/python3.7/site-packages/distributed/comm/core.py", line 215, in connect
    quiet_exceptions=EnvironmentError,
tornado.util.TimeoutError: Timeout

During handling of the above exception, another exception occurred:

Traceback (most recent call last):
  File "/softs/rh7/conda/4.5.4/envs/pangeo_full_201909/lib/python3.7/site-packages/tornado/ioloop.py", line 743, in _run_callback
    ret = callback()
  File "/softs/rh7/conda/4.5.4/envs/pangeo_full_201909/lib/python3.7/site-packages/tornado/ioloop.py", line 767, in _discard_future_result
    future.result()
  File "/softs/rh7/conda/4.5.4/envs/pangeo_full_201909/lib/python3.7/site-packages/distributed/worker.py", line 875, in heartbeat
    metrics=await self.get_metrics(),
  File "/softs/rh7/conda/4.5.4/envs/pangeo_full_201909/lib/python3.7/site-packages/distributed/core.py", line 747, in send_recv_from_rpc
    comm = await self.pool.connect(self.addr)
  File "/softs/rh7/conda/4.5.4/envs/pangeo_full_201909/lib/python3.7/site-packages/distributed/core.py", line 874, in connect
    connection_args=self.connection_args,
  File "/softs/rh7/conda/4.5.4/envs/pangeo_full_201909/lib/python3.7/site-packages/distributed/comm/core.py", line 227, in connect
    _raise(error)
  File "/softs/rh7/conda/4.5.4/envs/pangeo_full_201909/lib/python3.7/site-packages/distributed/comm/core.py", line 204, in _raise
    raise IOError(msg)
OSError: Timed out trying to connect to 'tcp://10.120.40.97:33653' after 10 s: in <distributed.comm.tcp.TCPConnector object at 0x2b37fbf9f8d0>: ConnectionRefusedError: [Errno 111] Connection refused
tornado.application - ERROR - Exception in callback functools.partial(<bound method IOLoop._discard_future_result of <tornado.platform.asyncio.AsyncIOLoop object at 0x2b37e7ab2b38>>, <Task finished coro=<Worker.heartbeat() done, defined at /softs/rh7/conda/4.5.4/envs/pangeo_full_201909/lib/python3.7/site-packages/distributed/worker.py:866> exception=OSError("Timed out trying to connect to 'tcp://10.120.40.97:33653' after 10 s: in <distributed.comm.tcp.TCPConnector object at 0x2b37fb56b1d0>: ConnectionRefusedError: [Errno 111] Connection refused")>)
Traceback (most recent call last):
  File "/softs/rh7/conda/4.5.4/envs/pangeo_full_201909/lib/python3.7/site-packages/distributed/comm/core.py", line 215, in connect
    quiet_exceptions=EnvironmentError,
tornado.util.TimeoutError: Timeout

During handling of the above exception, another exception occurred:

Traceback (most recent call last):
  File "/softs/rh7/conda/4.5.4/envs/pangeo_full_201909/lib/python3.7/site-packages/tornado/ioloop.py", line 743, in _run_callback
    ret = callback()
  File "/softs/rh7/conda/4.5.4/envs/pangeo_full_201909/lib/python3.7/site-packages/tornado/ioloop.py", line 767, in _discard_future_result
    future.result()
  File "/softs/rh7/conda/4.5.4/envs/pangeo_full_201909/lib/python3.7/site-packages/distributed/worker.py", line 875, in heartbeat
    metrics=await self.get_metrics(),
  File "/softs/rh7/conda/4.5.4/envs/pangeo_full_201909/lib/python3.7/site-packages/distributed/core.py", line 747, in send_recv_from_rpc
    comm = await self.pool.connect(self.addr)
  File "/softs/rh7/conda/4.5.4/envs/pangeo_full_201909/lib/python3.7/site-packages/distributed/core.py", line 874, in connect
    connection_args=self.connection_args,
  File "/softs/rh7/conda/4.5.4/envs/pangeo_full_201909/lib/python3.7/site-packages/distributed/comm/core.py", line 227, in connect
    _raise(error)
  File "/softs/rh7/conda/4.5.4/envs/pangeo_full_201909/lib/python3.7/site-packages/distributed/comm/core.py", line 204, in _raise
    raise IOError(msg)
OSError: Timed out trying to connect to 'tcp://10.120.40.97:33653' after 10 s: in <distributed.comm.tcp.TCPConnector object at 0x2b37fb56b1d0>: ConnectionRefusedError: [Errno 111] Connection refused
tornado.application - ERROR - Exception in callback functools.partial(<bound method IOLoop._discard_future_result of <tornado.platform.asyncio.AsyncIOLoop object at 0x2b37e7ab2b38>>, <Task finished coro=<Worker.heartbeat() done, defined at /softs/rh7/conda/4.5.4/envs/pangeo_full_201909/lib/python3.7/site-packages/distributed/worker.py:866> exception=OSError("Timed out trying to connect to 'tcp://10.120.40.97:33653' after 10 s: in <distributed.comm.tcp.TCPConnector object at 0x2b3810be1278>: ConnectionRefusedError: [Errno 111] Connection refused")>)
Traceback (most recent call last):
  File "/softs/rh7/conda/4.5.4/envs/pangeo_full_201909/lib/python3.7/site-packages/distributed/comm/core.py", line 215, in connect
    quiet_exceptions=EnvironmentError,
tornado.util.TimeoutError: Timeout

During handling of the above exception, another exception occurred:

Traceback (most recent call last):
  File "/softs/rh7/conda/4.5.4/envs/pangeo_full_201909/lib/python3.7/site-packages/tornado/ioloop.py", line 743, in _run_callback
    ret = callback()
  File "/softs/rh7/conda/4.5.4/envs/pangeo_full_201909/lib/python3.7/site-packages/tornado/ioloop.py", line 767, in _discard_future_result
    future.result()
  File "/softs/rh7/conda/4.5.4/envs/pangeo_full_201909/lib/python3.7/site-packages/distributed/worker.py", line 875, in heartbeat
    metrics=await self.get_metrics(),
  File "/softs/rh7/conda/4.5.4/envs/pangeo_full_201909/lib/python3.7/site-packages/distributed/core.py", line 747, in send_recv_from_rpc
    comm = await self.pool.connect(self.addr)
  File "/softs/rh7/conda/4.5.4/envs/pangeo_full_201909/lib/python3.7/site-packages/distributed/core.py", line 874, in connect
    connection_args=self.connection_args,
  File "/softs/rh7/conda/4.5.4/envs/pangeo_full_201909/lib/python3.7/site-packages/distributed/comm/core.py", line 227, in connect
    _raise(error)
  File "/softs/rh7/conda/4.5.4/envs/pangeo_full_201909/lib/python3.7/site-packages/distributed/comm/core.py", line 204, in _raise
    raise IOError(msg)
OSError: Timed out trying to connect to 'tcp://10.120.40.97:33653' after 10 s: in <distributed.comm.tcp.TCPConnector object at 0x2b3810be1278>: ConnectionRefusedError: [Errno 111] Connection refused
tornado.application - ERROR - Exception in callback <function Worker._register_with_scheduler.<locals>.<lambda> at 0x2b37fa7fee18>
Traceback (most recent call last):
  File "/softs/rh7/conda/4.5.4/envs/pangeo_full_201909/lib/python3.7/site-packages/tornado/ioloop.py", line 907, in _run
    return self.callback()
  File "/softs/rh7/conda/4.5.4/envs/pangeo_full_201909/lib/python3.7/site-packages/distributed/worker.py", line 857, in <lambda>
    lambda: self.batched_stream.send({"op": "keep-alive"}),
  File "/softs/rh7/conda/4.5.4/envs/pangeo_full_201909/lib/python3.7/site-packages/distributed/batched.py", line 117, in send
    raise CommClosedError
distributed.comm.core.CommClosedError
tornado.application - ERROR - Exception in callback functools.partial(<bound method IOLoop._discard_future_result of <tornado.platform.asyncio.AsyncIOLoop object at 0x2b37e7ab2b38>>, <Task finished coro=<Worker.heartbeat() done, defined at /softs/rh7/conda/4.5.4/envs/pangeo_full_201909/lib/python3.7/site-packages/distributed/worker.py:866> exception=OSError("Timed out trying to connect to 'tcp://10.120.40.97:33653' after 10 s: in <distributed.comm.tcp.TCPConnector object at 0x2b381145dd68>: ConnectionRefusedError: [Errno 111] Connection refused")>)
Traceback (most recent call last):
  File "/softs/rh7/conda/4.5.4/envs/pangeo_full_201909/lib/python3.7/site-packages/distributed/comm/core.py", line 215, in connect
    quiet_exceptions=EnvironmentError,
tornado.util.TimeoutError: Timeout

During handling of the above exception, another exception occurred:

Traceback (most recent call last):
  File "/softs/rh7/conda/4.5.4/envs/pangeo_full_201909/lib/python3.7/site-packages/tornado/ioloop.py", line 743, in _run_callback
    ret = callback()
  File "/softs/rh7/conda/4.5.4/envs/pangeo_full_201909/lib/python3.7/site-packages/tornado/ioloop.py", line 767, in _discard_future_result
    future.result()
  File "/softs/rh7/conda/4.5.4/envs/pangeo_full_201909/lib/python3.7/site-packages/distributed/worker.py", line 875, in heartbeat
    metrics=await self.get_metrics(),
  File "/softs/rh7/conda/4.5.4/envs/pangeo_full_201909/lib/python3.7/site-packages/distributed/core.py", line 747, in send_recv_from_rpc
    comm = await self.pool.connect(self.addr)
  File "/softs/rh7/conda/4.5.4/envs/pangeo_full_201909/lib/python3.7/site-packages/distributed/core.py", line 874, in connect
    connection_args=self.connection_args,
  File "/softs/rh7/conda/4.5.4/envs/pangeo_full_201909/lib/python3.7/site-packages/distributed/comm/core.py", line 227, in connect
    _raise(error)
  File "/softs/rh7/conda/4.5.4/envs/pangeo_full_201909/lib/python3.7/site-packages/distributed/comm/core.py", line 204, in _raise
    raise IOError(msg)
OSError: Timed out trying to connect to 'tcp://10.120.40.97:33653' after 10 s: in <distributed.comm.tcp.TCPConnector object at 0x2b381145dd68>: ConnectionRefusedError: [Errno 111] Connection refused
tornado.application - ERROR - Exception in callback functools.partial(<bound method IOLoop._discard_future_result of <tornado.platform.asyncio.AsyncIOLoop object at 0x2b37e7ab2b38>>, <Task finished coro=<Worker.heartbeat() done, defined at /softs/rh7/conda/4.5.4/envs/pangeo_full_201909/lib/python3.7/site-packages/distributed/worker.py:866> exception=OSError("Timed out trying to connect to 'tcp://10.120.40.97:33653' after 10 s: in <distributed.comm.tcp.TCPConnector object at 0x2b3811574dd8>: ConnectionRefusedError: [Errno 111] Connection refused")>)
Traceback (most recent call last):
  File "/softs/rh7/conda/4.5.4/envs/pangeo_full_201909/lib/python3.7/site-packages/distributed/comm/core.py", line 215, in connect
    quiet_exceptions=EnvironmentError,
tornado.util.TimeoutError: Timeout

During handling of the above exception, another exception occurred:

Traceback (most recent call last):
  File "/softs/rh7/conda/4.5.4/envs/pangeo_full_201909/lib/python3.7/site-packages/tornado/ioloop.py", line 743, in _run_callback
    ret = callback()
  File "/softs/rh7/conda/4.5.4/envs/pangeo_full_201909/lib/python3.7/site-packages/tornado/ioloop.py", line 767, in _discard_future_result
    future.result()
  File "/softs/rh7/conda/4.5.4/envs/pangeo_full_201909/lib/python3.7/site-packages/distributed/worker.py", line 875, in heartbeat
    metrics=await self.get_metrics(),
  File "/softs/rh7/conda/4.5.4/envs/pangeo_full_201909/lib/python3.7/site-packages/distributed/core.py", line 747, in send_recv_from_rpc
    comm = await self.pool.connect(self.addr)
  File "/softs/rh7/conda/4.5.4/envs/pangeo_full_201909/lib/python3.7/site-packages/distributed/core.py", line 874, in connect
    connection_args=self.connection_args,
  File "/softs/rh7/conda/4.5.4/envs/pangeo_full_201909/lib/python3.7/site-packages/distributed/comm/core.py", line 227, in connect
    _raise(error)
  File "/softs/rh7/conda/4.5.4/envs/pangeo_full_201909/lib/python3.7/site-packages/distributed/comm/core.py", line 204, in _raise
    raise IOError(msg)
OSError: Timed out trying to connect to 'tcp://10.120.40.97:33653' after 10 s: in <distributed.comm.tcp.TCPConnector object at 0x2b3811574dd8>: ConnectionRefusedError: [Errno 111] Connection refused
tornado.application - ERROR - Exception in callback functools.partial(<bound method IOLoop._discard_future_result of <tornado.platform.asyncio.AsyncIOLoop object at 0x2b37e7ab2b38>>, <Task finished coro=<Worker.heartbeat() done, defined at /softs/rh7/conda/4.5.4/envs/pangeo_full_201909/lib/python3.7/site-packages/distributed/worker.py:866> exception=OSError("Timed out trying to connect to 'tcp://10.120.40.97:33653' after 10 s: in <distributed.comm.tcp.TCPConnector object at 0x2b3811502080>: ConnectionRefusedError: [Errno 111] Connection refused")>)
Traceback (most recent call last):
  File "/softs/rh7/conda/4.5.4/envs/pangeo_full_201909/lib/python3.7/site-packages/distributed/comm/core.py", line 215, in connect
    quiet_exceptions=EnvironmentError,
tornado.util.TimeoutError: Timeout

During handling of the above exception, another exception occurred:

Traceback (most recent call last):
  File "/softs/rh7/conda/4.5.4/envs/pangeo_full_201909/lib/python3.7/site-packages/tornado/ioloop.py", line 743, in _run_callback
    ret = callback()
  File "/softs/rh7/conda/4.5.4/envs/pangeo_full_201909/lib/python3.7/site-packages/tornado/ioloop.py", line 767, in _discard_future_result
    future.result()
  File "/softs/rh7/conda/4.5.4/envs/pangeo_full_201909/lib/python3.7/site-packages/distributed/worker.py", line 875, in heartbeat
    metrics=await self.get_metrics(),
  File "/softs/rh7/conda/4.5.4/envs/pangeo_full_201909/lib/python3.7/site-packages/distributed/core.py", line 747, in send_recv_from_rpc
    comm = await self.pool.connect(self.addr)
  File "/softs/rh7/conda/4.5.4/envs/pangeo_full_201909/lib/python3.7/site-packages/distributed/core.py", line 874, in connect
    connection_args=self.connection_args,
  File "/softs/rh7/conda/4.5.4/envs/pangeo_full_201909/lib/python3.7/site-packages/distributed/comm/core.py", line 227, in connect
    _raise(error)
  File "/softs/rh7/conda/4.5.4/envs/pangeo_full_201909/lib/python3.7/site-packages/distributed/comm/core.py", line 204, in _raise
    raise IOError(msg)
OSError: Timed out trying to connect to 'tcp://10.120.40.97:33653' after 10 s: in <distributed.comm.tcp.TCPConnector object at 0x2b3811502080>: ConnectionRefusedError: [Errno 111] Connection refused
tornado.application - ERROR - Exception in callback functools.partial(<bound method IOLoop._discard_future_result of <tornado.platform.asyncio.AsyncIOLoop object at 0x2b37e7ab2b38>>, <Task finished coro=<Worker.heartbeat() done, defined at /softs/rh7/conda/4.5.4/envs/pangeo_full_201909/lib/python3.7/site-packages/distributed/worker.py:866> exception=OSError("Timed out trying to connect to 'tcp://10.120.40.97:33653' after 10 s: in <distributed.comm.tcp.TCPConnector object at 0x2b3810e9a2e8>: ConnectionRefusedError: [Errno 111] Connection refused")>)
Traceback (most recent call last):
  File "/softs/rh7/conda/4.5.4/envs/pangeo_full_201909/lib/python3.7/site-packages/distributed/comm/core.py", line 215, in connect
    quiet_exceptions=EnvironmentError,
tornado.util.TimeoutError: Timeout

During handling of the above exception, another exception occurred:

Traceback (most recent call last):
  File "/softs/rh7/conda/4.5.4/envs/pangeo_full_201909/lib/python3.7/site-packages/tornado/ioloop.py", line 743, in _run_callback
    ret = callback()
  File "/softs/rh7/conda/4.5.4/envs/pangeo_full_201909/lib/python3.7/site-packages/tornado/ioloop.py", line 767, in _discard_future_result
    future.result()
  File "/softs/rh7/conda/4.5.4/envs/pangeo_full_201909/lib/python3.7/site-packages/distributed/worker.py", line 875, in heartbeat
    metrics=await self.get_metrics(),
  File "/softs/rh7/conda/4.5.4/envs/pangeo_full_201909/lib/python3.7/site-packages/distributed/core.py", line 747, in send_recv_from_rpc
    comm = await self.pool.connect(self.addr)
  File "/softs/rh7/conda/4.5.4/envs/pangeo_full_201909/lib/python3.7/site-packages/distributed/core.py", line 874, in connect
    connection_args=self.connection_args,
  File "/softs/rh7/conda/4.5.4/envs/pangeo_full_201909/lib/python3.7/site-packages/distributed/comm/core.py", line 227, in connect
    _raise(error)
  File "/softs/rh7/conda/4.5.4/envs/pangeo_full_201909/lib/python3.7/site-packages/distributed/comm/core.py", line 204, in _raise
    raise IOError(msg)
OSError: Timed out trying to connect to 'tcp://10.120.40.97:33653' after 10 s: in <distributed.comm.tcp.TCPConnector object at 0x2b3810e9a2e8>: ConnectionRefusedError: [Errno 111] Connection refused
tornado.application - ERROR - Exception in callback functools.partial(<bound method IOLoop._discard_future_result of <tornado.platform.asyncio.AsyncIOLoop object at 0x2b37e7ab2b38>>, <Task finished coro=<Worker.heartbeat() done, defined at /softs/rh7/conda/4.5.4/envs/pangeo_full_201909/lib/python3.7/site-packages/distributed/worker.py:866> exception=OSError("Timed out trying to connect to 'tcp://10.120.40.97:33653' after 10 s: in <distributed.comm.tcp.TCPConnector object at 0x2b3810932208>: ConnectionRefusedError: [Errno 111] Connection refused")>)
Traceback (most recent call last):
  File "/softs/rh7/conda/4.5.4/envs/pangeo_full_201909/lib/python3.7/site-packages/distributed/comm/core.py", line 215, in connect
    quiet_exceptions=EnvironmentError,
tornado.util.TimeoutError: Timeout

During handling of the above exception, another exception occurred:

Traceback (most recent call last):
  File "/softs/rh7/conda/4.5.4/envs/pangeo_full_201909/lib/python3.7/site-packages/tornado/ioloop.py", line 743, in _run_callback
    ret = callback()
  File "/softs/rh7/conda/4.5.4/envs/pangeo_full_201909/lib/python3.7/site-packages/tornado/ioloop.py", line 767, in _discard_future_result
    future.result()
  File "/softs/rh7/conda/4.5.4/envs/pangeo_full_201909/lib/python3.7/site-packages/distributed/worker.py", line 875, in heartbeat
    metrics=await self.get_metrics(),
  File "/softs/rh7/conda/4.5.4/envs/pangeo_full_201909/lib/python3.7/site-packages/distributed/core.py", line 747, in send_recv_from_rpc
    comm = await self.pool.connect(self.addr)
  File "/softs/rh7/conda/4.5.4/envs/pangeo_full_201909/lib/python3.7/site-packages/distributed/core.py", line 874, in connect
    connection_args=self.connection_args,
  File "/softs/rh7/conda/4.5.4/envs/pangeo_full_201909/lib/python3.7/site-packages/distributed/comm/core.py", line 227, in connect
    _raise(error)
  File "/softs/rh7/conda/4.5.4/envs/pangeo_full_201909/lib/python3.7/site-packages/distributed/comm/core.py", line 204, in _raise
    raise IOError(msg)
OSError: Timed out trying to connect to 'tcp://10.120.40.97:33653' after 10 s: in <distributed.comm.tcp.TCPConnector object at 0x2b3810932208>: ConnectionRefusedError: [Errno 111] Connection refused
tornado.application - ERROR - Exception in callback functools.partial(<bound method IOLoop._discard_future_result of <tornado.platform.asyncio.AsyncIOLoop object at 0x2b37e7ab2b38>>, <Task finished coro=<Worker.heartbeat() done, defined at /softs/rh7/conda/4.5.4/envs/pangeo_full_201909/lib/python3.7/site-packages/distributed/worker.py:866> exception=OSError("Timed out trying to connect to 'tcp://10.120.40.97:33653' after 10 s: in <distributed.comm.tcp.TCPConnector object at 0x2b3811776588>: ConnectionRefusedError: [Errno 111] Connection refused")>)
Traceback (most recent call last):
  File "/softs/rh7/conda/4.5.4/envs/pangeo_full_201909/lib/python3.7/site-packages/distributed/comm/core.py", line 215, in connect
    quiet_exceptions=EnvironmentError,
tornado.util.TimeoutError: Timeout

During handling of the above exception, another exception occurred:

Traceback (most recent call last):
  File "/softs/rh7/conda/4.5.4/envs/pangeo_full_201909/lib/python3.7/site-packages/tornado/ioloop.py", line 743, in _run_callback
    ret = callback()
  File "/softs/rh7/conda/4.5.4/envs/pangeo_full_201909/lib/python3.7/site-packages/tornado/ioloop.py", line 767, in _discard_future_result
    future.result()
  File "/softs/rh7/conda/4.5.4/envs/pangeo_full_201909/lib/python3.7/site-packages/distributed/worker.py", line 875, in heartbeat
    metrics=await self.get_metrics(),
  File "/softs/rh7/conda/4.5.4/envs/pangeo_full_201909/lib/python3.7/site-packages/distributed/core.py", line 747, in send_recv_from_rpc
    comm = await self.pool.connect(self.addr)
  File "/softs/rh7/conda/4.5.4/envs/pangeo_full_201909/lib/python3.7/site-packages/distributed/core.py", line 874, in connect
    connection_args=self.connection_args,
  File "/softs/rh7/conda/4.5.4/envs/pangeo_full_201909/lib/python3.7/site-packages/distributed/comm/core.py", line 227, in connect
    _raise(error)
  File "/softs/rh7/conda/4.5.4/envs/pangeo_full_201909/lib/python3.7/site-packages/distributed/comm/core.py", line 204, in _raise
    raise IOError(msg)
OSError: Timed out trying to connect to 'tcp://10.120.40.97:33653' after 10 s: in <distributed.comm.tcp.TCPConnector object at 0x2b3811776588>: ConnectionRefusedError: [Errno 111] Connection refused
tornado.application - ERROR - Exception in callback <function Worker._register_with_scheduler.<locals>.<lambda> at 0x2b37fa7fee18>
Traceback (most recent call last):
  File "/softs/rh7/conda/4.5.4/envs/pangeo_full_201909/lib/python3.7/site-packages/tornado/ioloop.py", line 907, in _run
    return self.callback()
  File "/softs/rh7/conda/4.5.4/envs/pangeo_full_201909/lib/python3.7/site-packages/distributed/worker.py", line 857, in <lambda>
    lambda: self.batched_stream.send({"op": "keep-alive"}),
  File "/softs/rh7/conda/4.5.4/envs/pangeo_full_201909/lib/python3.7/site-packages/distributed/batched.py", line 117, in send
    raise CommClosedError
distributed.comm.core.CommClosedError
tornado.application - ERROR - Exception in callback functools.partial(<bound method IOLoop._discard_future_result of <tornado.platform.asyncio.AsyncIOLoop object at 0x2b37e7ab2b38>>, <Task finished coro=<Worker.heartbeat() done, defined at /softs/rh7/conda/4.5.4/envs/pangeo_full_201909/lib/python3.7/site-packages/distributed/worker.py:866> exception=OSError("Timed out trying to connect to 'tcp://10.120.40.97:33653' after 10 s: in <distributed.comm.tcp.TCPConnector object at 0x2b3810e9a4e0>: ConnectionRefusedError: [Errno 111] Connection refused")>)
Traceback (most recent call last):
  File "/softs/rh7/conda/4.5.4/envs/pangeo_full_201909/lib/python3.7/site-packages/distributed/comm/core.py", line 215, in connect
    quiet_exceptions=EnvironmentError,
tornado.util.TimeoutError: Timeout

During handling of the above exception, another exception occurred:

Traceback (most recent call last):
  File "/softs/rh7/conda/4.5.4/envs/pangeo_full_201909/lib/python3.7/site-packages/tornado/ioloop.py", line 743, in _run_callback
    ret = callback()
  File "/softs/rh7/conda/4.5.4/envs/pangeo_full_201909/lib/python3.7/site-packages/tornado/ioloop.py", line 767, in _discard_future_result
    future.result()
  File "/softs/rh7/conda/4.5.4/envs/pangeo_full_201909/lib/python3.7/site-packages/distributed/worker.py", line 875, in heartbeat
    metrics=await self.get_metrics(),
  File "/softs/rh7/conda/4.5.4/envs/pangeo_full_201909/lib/python3.7/site-packages/distributed/core.py", line 747, in send_recv_from_rpc
    comm = await self.pool.connect(self.addr)
  File "/softs/rh7/conda/4.5.4/envs/pangeo_full_201909/lib/python3.7/site-packages/distributed/core.py", line 874, in connect
    connection_args=self.connection_args,
  File "/softs/rh7/conda/4.5.4/envs/pangeo_full_201909/lib/python3.7/site-packages/distributed/comm/core.py", line 227, in connect
    _raise(error)
  File "/softs/rh7/conda/4.5.4/envs/pangeo_full_201909/lib/python3.7/site-packages/distributed/comm/core.py", line 204, in _raise
    raise IOError(msg)
OSError: Timed out trying to connect to 'tcp://10.120.40.97:33653' after 10 s: in <distributed.comm.tcp.TCPConnector object at 0x2b3810e9a4e0>: ConnectionRefusedError: [Errno 111] Connection refused
tornado.application - ERROR - Exception in callback functools.partial(<bound method IOLoop._discard_future_result of <tornado.platform.asyncio.AsyncIOLoop object at 0x2b37e7ab2b38>>, <Task finished coro=<Worker.heartbeat() done, defined at /softs/rh7/conda/4.5.4/envs/pangeo_full_201909/lib/python3.7/site-packages/distributed/worker.py:866> exception=OSError("Timed out trying to connect to 'tcp://10.120.40.97:33653' after 10 s: in <distributed.comm.tcp.TCPConnector object at 0x2b3810932240>: ConnectionRefusedError: [Errno 111] Connection refused")>)
Traceback (most recent call last):
  File "/softs/rh7/conda/4.5.4/envs/pangeo_full_201909/lib/python3.7/site-packages/distributed/comm/core.py", line 215, in connect
    quiet_exceptions=EnvironmentError,
tornado.util.TimeoutError: Timeout

During handling of the above exception, another exception occurred:

Traceback (most recent call last):
  File "/softs/rh7/conda/4.5.4/envs/pangeo_full_201909/lib/python3.7/site-packages/tornado/ioloop.py", line 743, in _run_callback
    ret = callback()
  File "/softs/rh7/conda/4.5.4/envs/pangeo_full_201909/lib/python3.7/site-packages/tornado/ioloop.py", line 767, in _discard_future_result
    future.result()
  File "/softs/rh7/conda/4.5.4/envs/pangeo_full_201909/lib/python3.7/site-packages/distributed/worker.py", line 875, in heartbeat
    metrics=await self.get_metrics(),
  File "/softs/rh7/conda/4.5.4/envs/pangeo_full_201909/lib/python3.7/site-packages/distributed/core.py", line 747, in send_recv_from_rpc
    comm = await self.pool.connect(self.addr)
  File "/softs/rh7/conda/4.5.4/envs/pangeo_full_201909/lib/python3.7/site-packages/distributed/core.py", line 874, in connect
    connection_args=self.connection_args,
  File "/softs/rh7/conda/4.5.4/envs/pangeo_full_201909/lib/python3.7/site-packages/distributed/comm/core.py", line 227, in connect
    _raise(error)
  File "/softs/rh7/conda/4.5.4/envs/pangeo_full_201909/lib/python3.7/site-packages/distributed/comm/core.py", line 204, in _raise
    raise IOError(msg)
OSError: Timed out trying to connect to 'tcp://10.120.40.97:33653' after 10 s: in <distributed.comm.tcp.TCPConnector object at 0x2b3810932240>: ConnectionRefusedError: [Errno 111] Connection refused
tornado.application - ERROR - Exception in callback functools.partial(<bound method IOLoop._discard_future_result of <tornado.platform.asyncio.AsyncIOLoop object at 0x2b37e7ab2b38>>, <Task finished coro=<Worker.heartbeat() done, defined at /softs/rh7/conda/4.5.4/envs/pangeo_full_201909/lib/python3.7/site-packages/distributed/worker.py:866> exception=OSError("Timed out trying to connect to 'tcp://10.120.40.97:33653' after 10 s: in <distributed.comm.tcp.TCPConnector object at 0x2b3810c8fe48>: ConnectionRefusedError: [Errno 111] Connection refused")>)
Traceback (most recent call last):
  File "/softs/rh7/conda/4.5.4/envs/pangeo_full_201909/lib/python3.7/site-packages/distributed/comm/core.py", line 215, in connect
    quiet_exceptions=EnvironmentError,
tornado.util.TimeoutError: Timeout

During handling of the above exception, another exception occurred:

Traceback (most recent call last):
  File "/softs/rh7/conda/4.5.4/envs/pangeo_full_201909/lib/python3.7/site-packages/tornado/ioloop.py", line 743, in _run_callback
    ret = callback()
  File "/softs/rh7/conda/4.5.4/envs/pangeo_full_201909/lib/python3.7/site-packages/tornado/ioloop.py", line 767, in _discard_future_result
    future.result()
  File "/softs/rh7/conda/4.5.4/envs/pangeo_full_201909/lib/python3.7/site-packages/distributed/worker.py", line 875, in heartbeat
    metrics=await self.get_metrics(),
  File "/softs/rh7/conda/4.5.4/envs/pangeo_full_201909/lib/python3.7/site-packages/distributed/core.py", line 747, in send_recv_from_rpc
    comm = await self.pool.connect(self.addr)
  File "/softs/rh7/conda/4.5.4/envs/pangeo_full_201909/lib/python3.7/site-packages/distributed/core.py", line 874, in connect
    connection_args=self.connection_args,
  File "/softs/rh7/conda/4.5.4/envs/pangeo_full_201909/lib/python3.7/site-packages/distributed/comm/core.py", line 227, in connect
    _raise(error)
  File "/softs/rh7/conda/4.5.4/envs/pangeo_full_201909/lib/python3.7/site-packages/distributed/comm/core.py", line 204, in _raise
    raise IOError(msg)
OSError: Timed out trying to connect to 'tcp://10.120.40.97:33653' after 10 s: in <distributed.comm.tcp.TCPConnector object at 0x2b3810c8fe48>: ConnectionRefusedError: [Errno 111] Connection refused
tornado.application - ERROR - Exception in callback functools.partial(<bound method IOLoop._discard_future_result of <tornado.platform.asyncio.AsyncIOLoop object at 0x2b37e7ab2b38>>, <Task finished coro=<Worker.heartbeat() done, defined at /softs/rh7/conda/4.5.4/envs/pangeo_full_201909/lib/python3.7/site-packages/distributed/worker.py:866> exception=OSError("Timed out trying to connect to 'tcp://10.120.40.97:33653' after 10 s: in <distributed.comm.tcp.TCPConnector object at 0x2b3810c8f9e8>: ConnectionRefusedError: [Errno 111] Connection refused")>)
Traceback (most recent call last):
  File "/softs/rh7/conda/4.5.4/envs/pangeo_full_201909/lib/python3.7/site-packages/distributed/comm/core.py", line 215, in connect
    quiet_exceptions=EnvironmentError,
tornado.util.TimeoutError: Timeout

During handling of the above exception, another exception occurred:

Traceback (most recent call last):
  File "/softs/rh7/conda/4.5.4/envs/pangeo_full_201909/lib/python3.7/site-packages/tornado/ioloop.py", line 743, in _run_callback
    ret = callback()
  File "/softs/rh7/conda/4.5.4/envs/pangeo_full_201909/lib/python3.7/site-packages/tornado/ioloop.py", line 767, in _discard_future_result
    future.result()
  File "/softs/rh7/conda/4.5.4/envs/pangeo_full_201909/lib/python3.7/site-packages/distributed/worker.py", line 875, in heartbeat
    metrics=await self.get_metrics(),
  File "/softs/rh7/conda/4.5.4/envs/pangeo_full_201909/lib/python3.7/site-packages/distributed/core.py", line 747, in send_recv_from_rpc
    comm = await self.pool.connect(self.addr)
  File "/softs/rh7/conda/4.5.4/envs/pangeo_full_201909/lib/python3.7/site-packages/distributed/core.py", line 874, in connect
    connection_args=self.connection_args,
  File "/softs/rh7/conda/4.5.4/envs/pangeo_full_201909/lib/python3.7/site-packages/distributed/comm/core.py", line 227, in connect
    _raise(error)
  File "/softs/rh7/conda/4.5.4/envs/pangeo_full_201909/lib/python3.7/site-packages/distributed/comm/core.py", line 204, in _raise
    raise IOError(msg)
OSError: Timed out trying to connect to 'tcp://10.120.40.97:33653' after 10 s: in <distributed.comm.tcp.TCPConnector object at 0x2b3810c8f9e8>: ConnectionRefusedError: [Errno 111] Connection refused
tornado.application - ERROR - Exception in callback functools.partial(<bound method IOLoop._discard_future_result of <tornado.platform.asyncio.AsyncIOLoop object at 0x2b37e7ab2b38>>, <Task finished coro=<Worker.heartbeat() done, defined at /softs/rh7/conda/4.5.4/envs/pangeo_full_201909/lib/python3.7/site-packages/distributed/worker.py:866> exception=OSError("Timed out trying to connect to 'tcp://10.120.40.97:33653' after 10 s: in <distributed.comm.tcp.TCPConnector object at 0x2b3810e9a048>: ConnectionRefusedError: [Errno 111] Connection refused")>)
Traceback (most recent call last):
  File "/softs/rh7/conda/4.5.4/envs/pangeo_full_201909/lib/python3.7/site-packages/distributed/comm/core.py", line 215, in connect
    quiet_exceptions=EnvironmentError,
tornado.util.TimeoutError: Timeout

During handling of the above exception, another exception occurred:

Traceback (most recent call last):
  File "/softs/rh7/conda/4.5.4/envs/pangeo_full_201909/lib/python3.7/site-packages/tornado/ioloop.py", line 743, in _run_callback
    ret = callback()
  File "/softs/rh7/conda/4.5.4/envs/pangeo_full_201909/lib/python3.7/site-packages/tornado/ioloop.py", line 767, in _discard_future_result
    future.result()
  File "/softs/rh7/conda/4.5.4/envs/pangeo_full_201909/lib/python3.7/site-packages/distributed/worker.py", line 875, in heartbeat
    metrics=await self.get_metrics(),
  File "/softs/rh7/conda/4.5.4/envs/pangeo_full_201909/lib/python3.7/site-packages/distributed/core.py", line 747, in send_recv_from_rpc
    comm = await self.pool.connect(self.addr)
  File "/softs/rh7/conda/4.5.4/envs/pangeo_full_201909/lib/python3.7/site-packages/distributed/core.py", line 874, in connect
    connection_args=self.connection_args,
  File "/softs/rh7/conda/4.5.4/envs/pangeo_full_201909/lib/python3.7/site-packages/distributed/comm/core.py", line 227, in connect
    _raise(error)
  File "/softs/rh7/conda/4.5.4/envs/pangeo_full_201909/lib/python3.7/site-packages/distributed/comm/core.py", line 204, in _raise
    raise IOError(msg)
OSError: Timed out trying to connect to 'tcp://10.120.40.97:33653' after 10 s: in <distributed.comm.tcp.TCPConnector object at 0x2b3810e9a048>: ConnectionRefusedError: [Errno 111] Connection refused
tornado.application - ERROR - Exception in callback <function Worker._register_with_scheduler.<locals>.<lambda> at 0x2b37fa7fee18>
Traceback (most recent call last):
  File "/softs/rh7/conda/4.5.4/envs/pangeo_full_201909/lib/python3.7/site-packages/tornado/ioloop.py", line 907, in _run
    return self.callback()
  File "/softs/rh7/conda/4.5.4/envs/pangeo_full_201909/lib/python3.7/site-packages/distributed/worker.py", line 857, in <lambda>
    lambda: self.batched_stream.send({"op": "keep-alive"}),
  File "/softs/rh7/conda/4.5.4/envs/pangeo_full_201909/lib/python3.7/site-packages/distributed/batched.py", line 117, in send
    raise CommClosedError
distributed.comm.core.CommClosedError
tornado.application - ERROR - Exception in callback functools.partial(<bound method IOLoop._discard_future_result of <tornado.platform.asyncio.AsyncIOLoop object at 0x2b37e7ab2b38>>, <Task finished coro=<Worker.heartbeat() done, defined at /softs/rh7/conda/4.5.4/envs/pangeo_full_201909/lib/python3.7/site-packages/distributed/worker.py:866> exception=OSError("Timed out trying to connect to 'tcp://10.120.40.97:33653' after 10 s: in <distributed.comm.tcp.TCPConnector object at 0x2b381096a358>: ConnectionRefusedError: [Errno 111] Connection refused")>)
Traceback (most recent call last):
  File "/softs/rh7/conda/4.5.4/envs/pangeo_full_201909/lib/python3.7/site-packages/distributed/comm/core.py", line 215, in connect
    quiet_exceptions=EnvironmentError,
tornado.util.TimeoutError: Timeout

During handling of the above exception, another exception occurred:

Traceback (most recent call last):
  File "/softs/rh7/conda/4.5.4/envs/pangeo_full_201909/lib/python3.7/site-packages/tornado/ioloop.py", line 743, in _run_callback
    ret = callback()
  File "/softs/rh7/conda/4.5.4/envs/pangeo_full_201909/lib/python3.7/site-packages/tornado/ioloop.py", line 767, in _discard_future_result
    future.result()
  File "/softs/rh7/conda/4.5.4/envs/pangeo_full_201909/lib/python3.7/site-packages/distributed/worker.py", line 875, in heartbeat
    metrics=await self.get_metrics(),
  File "/softs/rh7/conda/4.5.4/envs/pangeo_full_201909/lib/python3.7/site-packages/distributed/core.py", line 747, in send_recv_from_rpc
    comm = await self.pool.connect(self.addr)
  File "/softs/rh7/conda/4.5.4/envs/pangeo_full_201909/lib/python3.7/site-packages/distributed/core.py", line 874, in connect
    connection_args=self.connection_args,
  File "/softs/rh7/conda/4.5.4/envs/pangeo_full_201909/lib/python3.7/site-packages/distributed/comm/core.py", line 227, in connect
    _raise(error)
  File "/softs/rh7/conda/4.5.4/envs/pangeo_full_201909/lib/python3.7/site-packages/distributed/comm/core.py", line 204, in _raise
    raise IOError(msg)
OSError: Timed out trying to connect to 'tcp://10.120.40.97:33653' after 10 s: in <distributed.comm.tcp.TCPConnector object at 0x2b381096a358>: ConnectionRefusedError: [Errno 111] Connection refused
tornado.application - ERROR - Exception in callback functools.partial(<bound method IOLoop._discard_future_result of <tornado.platform.asyncio.AsyncIOLoop object at 0x2b37e7ab2b38>>, <Task finished coro=<Worker.heartbeat() done, defined at /softs/rh7/conda/4.5.4/envs/pangeo_full_201909/lib/python3.7/site-packages/distributed/worker.py:866> exception=OSError("Timed out trying to connect to 'tcp://10.120.40.97:33653' after 10 s: in <distributed.comm.tcp.TCPConnector object at 0x2b3810d41940>: ConnectionRefusedError: [Errno 111] Connection refused")>)
Traceback (most recent call last):
  File "/softs/rh7/conda/4.5.4/envs/pangeo_full_201909/lib/python3.7/site-packages/distributed/comm/core.py", line 215, in connect
    quiet_exceptions=EnvironmentError,
tornado.util.TimeoutError: Timeout

During handling of the above exception, another exception occurred:

Traceback (most recent call last):
  File "/softs/rh7/conda/4.5.4/envs/pangeo_full_201909/lib/python3.7/site-packages/tornado/ioloop.py", line 743, in _run_callback
    ret = callback()
  File "/softs/rh7/conda/4.5.4/envs/pangeo_full_201909/lib/python3.7/site-packages/tornado/ioloop.py", line 767, in _discard_future_result
    future.result()
  File "/softs/rh7/conda/4.5.4/envs/pangeo_full_201909/lib/python3.7/site-packages/distributed/worker.py", line 875, in heartbeat
    metrics=await self.get_metrics(),
  File "/softs/rh7/conda/4.5.4/envs/pangeo_full_201909/lib/python3.7/site-packages/distributed/core.py", line 747, in send_recv_from_rpc
    comm = await self.pool.connect(self.addr)
  File "/softs/rh7/conda/4.5.4/envs/pangeo_full_201909/lib/python3.7/site-packages/distributed/core.py", line 874, in connect
    connection_args=self.connection_args,
  File "/softs/rh7/conda/4.5.4/envs/pangeo_full_201909/lib/python3.7/site-packages/distributed/comm/core.py", line 227, in connect
    _raise(error)
  File "/softs/rh7/conda/4.5.4/envs/pangeo_full_201909/lib/python3.7/site-packages/distributed/comm/core.py", line 204, in _raise
    raise IOError(msg)
OSError: Timed out trying to connect to 'tcp://10.120.40.97:33653' after 10 s: in <distributed.comm.tcp.TCPConnector object at 0x2b3810d41940>: ConnectionRefusedError: [Errno 111] Connection refused
tornado.application - ERROR - Exception in callback functools.partial(<bound method IOLoop._discard_future_result of <tornado.platform.asyncio.AsyncIOLoop object at 0x2b37e7ab2b38>>, <Task finished coro=<Worker.heartbeat() done, defined at /softs/rh7/conda/4.5.4/envs/pangeo_full_201909/lib/python3.7/site-packages/distributed/worker.py:866> exception=OSError("Timed out trying to connect to 'tcp://10.120.40.97:33653' after 10 s: in <distributed.comm.tcp.TCPConnector object at 0x2b38115025f8>: ConnectionRefusedError: [Errno 111] Connection refused")>)
Traceback (most recent call last):
  File "/softs/rh7/conda/4.5.4/envs/pangeo_full_201909/lib/python3.7/site-packages/distributed/comm/core.py", line 215, in connect
    quiet_exceptions=EnvironmentError,
tornado.util.TimeoutError: Timeout

During handling of the above exception, another exception occurred:

Traceback (most recent call last):
  File "/softs/rh7/conda/4.5.4/envs/pangeo_full_201909/lib/python3.7/site-packages/tornado/ioloop.py", line 743, in _run_callback
    ret = callback()
  File "/softs/rh7/conda/4.5.4/envs/pangeo_full_201909/lib/python3.7/site-packages/tornado/ioloop.py", line 767, in _discard_future_result
    future.result()
  File "/softs/rh7/conda/4.5.4/envs/pangeo_full_201909/lib/python3.7/site-packages/distributed/worker.py", line 875, in heartbeat
    metrics=await self.get_metrics(),
  File "/softs/rh7/conda/4.5.4/envs/pangeo_full_201909/lib/python3.7/site-packages/distributed/core.py", line 747, in send_recv_from_rpc
    comm = await self.pool.connect(self.addr)
  File "/softs/rh7/conda/4.5.4/envs/pangeo_full_201909/lib/python3.7/site-packages/distributed/core.py", line 874, in connect
    connection_args=self.connection_args,
  File "/softs/rh7/conda/4.5.4/envs/pangeo_full_201909/lib/python3.7/site-packages/distributed/comm/core.py", line 227, in connect
    _raise(error)
  File "/softs/rh7/conda/4.5.4/envs/pangeo_full_201909/lib/python3.7/site-packages/distributed/comm/core.py", line 204, in _raise
    raise IOError(msg)
OSError: Timed out trying to connect to 'tcp://10.120.40.97:33653' after 10 s: in <distributed.comm.tcp.TCPConnector object at 0x2b38115025f8>: ConnectionRefusedError: [Errno 111] Connection refused
tornado.application - ERROR - Exception in callback functools.partial(<bound method IOLoop._discard_future_result of <tornado.platform.asyncio.AsyncIOLoop object at 0x2b37e7ab2b38>>, <Task finished coro=<Worker.heartbeat() done, defined at /softs/rh7/conda/4.5.4/envs/pangeo_full_201909/lib/python3.7/site-packages/distributed/worker.py:866> exception=OSError("Timed out trying to connect to 'tcp://10.120.40.97:33653' after 10 s: in <distributed.comm.tcp.TCPConnector object at 0x2b38114a80f0>: ConnectionRefusedError: [Errno 111] Connection refused")>)
Traceback (most recent call last):
  File "/softs/rh7/conda/4.5.4/envs/pangeo_full_201909/lib/python3.7/site-packages/distributed/comm/core.py", line 215, in connect
    quiet_exceptions=EnvironmentError,
tornado.util.TimeoutError: Timeout

During handling of the above exception, another exception occurred:

Traceback (most recent call last):
  File "/softs/rh7/conda/4.5.4/envs/pangeo_full_201909/lib/python3.7/site-packages/tornado/ioloop.py", line 743, in _run_callback
    ret = callback()
  File "/softs/rh7/conda/4.5.4/envs/pangeo_full_201909/lib/python3.7/site-packages/tornado/ioloop.py", line 767, in _discard_future_result
    future.result()
  File "/softs/rh7/conda/4.5.4/envs/pangeo_full_201909/lib/python3.7/site-packages/distributed/worker.py", line 875, in heartbeat
    metrics=await self.get_metrics(),
  File "/softs/rh7/conda/4.5.4/envs/pangeo_full_201909/lib/python3.7/site-packages/distributed/core.py", line 747, in send_recv_from_rpc
    comm = await self.pool.connect(self.addr)
  File "/softs/rh7/conda/4.5.4/envs/pangeo_full_201909/lib/python3.7/site-packages/distributed/core.py", line 874, in connect
    connection_args=self.connection_args,
  File "/softs/rh7/conda/4.5.4/envs/pangeo_full_201909/lib/python3.7/site-packages/distributed/comm/core.py", line 227, in connect
    _raise(error)
  File "/softs/rh7/conda/4.5.4/envs/pangeo_full_201909/lib/python3.7/site-packages/distributed/comm/core.py", line 204, in _raise
    raise IOError(msg)
OSError: Timed out trying to connect to 'tcp://10.120.40.97:33653' after 10 s: in <distributed.comm.tcp.TCPConnector object at 0x2b38114a80f0>: ConnectionRefusedError: [Errno 111] Connection refused
tornado.application - ERROR - Exception in callback functools.partial(<bound method IOLoop._discard_future_result of <tornado.platform.asyncio.AsyncIOLoop object at 0x2b37e7ab2b38>>, <Task finished coro=<Worker.heartbeat() done, defined at /softs/rh7/conda/4.5.4/envs/pangeo_full_201909/lib/python3.7/site-packages/distributed/worker.py:866> exception=OSError("Timed out trying to connect to 'tcp://10.120.40.97:33653' after 10 s: in <distributed.comm.tcp.TCPConnector object at 0x2b381096a860>: ConnectionRefusedError: [Errno 111] Connection refused")>)
Traceback (most recent call last):
  File "/softs/rh7/conda/4.5.4/envs/pangeo_full_201909/lib/python3.7/site-packages/distributed/comm/core.py", line 215, in connect
    quiet_exceptions=EnvironmentError,
tornado.util.TimeoutError: Timeout

During handling of the above exception, another exception occurred:

Traceback (most recent call last):
  File "/softs/rh7/conda/4.5.4/envs/pangeo_full_201909/lib/python3.7/site-packages/tornado/ioloop.py", line 743, in _run_callback
    ret = callback()
  File "/softs/rh7/conda/4.5.4/envs/pangeo_full_201909/lib/python3.7/site-packages/tornado/ioloop.py", line 767, in _discard_future_result
    future.result()
  File "/softs/rh7/conda/4.5.4/envs/pangeo_full_201909/lib/python3.7/site-packages/distributed/worker.py", line 875, in heartbeat
    metrics=await self.get_metrics(),
  File "/softs/rh7/conda/4.5.4/envs/pangeo_full_201909/lib/python3.7/site-packages/distributed/core.py", line 747, in send_recv_from_rpc
    comm = await self.pool.connect(self.addr)
  File "/softs/rh7/conda/4.5.4/envs/pangeo_full_201909/lib/python3.7/site-packages/distributed/core.py", line 874, in connect
    connection_args=self.connection_args,
  File "/softs/rh7/conda/4.5.4/envs/pangeo_full_201909/lib/python3.7/site-packages/distributed/comm/core.py", line 227, in connect
    _raise(error)
  File "/softs/rh7/conda/4.5.4/envs/pangeo_full_201909/lib/python3.7/site-packages/distributed/comm/core.py", line 204, in _raise
    raise IOError(msg)
OSError: Timed out trying to connect to 'tcp://10.120.40.97:33653' after 10 s: in <distributed.comm.tcp.TCPConnector object at 0x2b381096a860>: ConnectionRefusedError: [Errno 111] Connection refused
tornado.application - ERROR - Exception in callback functools.partial(<bound method IOLoop._discard_future_result of <tornado.platform.asyncio.AsyncIOLoop object at 0x2b37e7ab2b38>>, <Task finished coro=<Worker.heartbeat() done, defined at /softs/rh7/conda/4.5.4/envs/pangeo_full_201909/lib/python3.7/site-packages/distributed/worker.py:866> exception=OSError("Timed out trying to connect to 'tcp://10.120.40.97:33653' after 10 s: in <distributed.comm.tcp.TCPConnector object at 0x2b3811574630>: ConnectionRefusedError: [Errno 111] Connection refused")>)
Traceback (most recent call last):
  File "/softs/rh7/conda/4.5.4/envs/pangeo_full_201909/lib/python3.7/site-packages/distributed/comm/core.py", line 215, in connect
    quiet_exceptions=EnvironmentError,
tornado.util.TimeoutError: Timeout

During handling of the above exception, another exception occurred:

Traceback (most recent call last):
  File "/softs/rh7/conda/4.5.4/envs/pangeo_full_201909/lib/python3.7/site-packages/tornado/ioloop.py", line 743, in _run_callback
    ret = callback()
  File "/softs/rh7/conda/4.5.4/envs/pangeo_full_201909/lib/python3.7/site-packages/tornado/ioloop.py", line 767, in _discard_future_result
    future.result()
  File "/softs/rh7/conda/4.5.4/envs/pangeo_full_201909/lib/python3.7/site-packages/distributed/worker.py", line 875, in heartbeat
    metrics=await self.get_metrics(),
  File "/softs/rh7/conda/4.5.4/envs/pangeo_full_201909/lib/python3.7/site-packages/distributed/core.py", line 747, in send_recv_from_rpc
    comm = await self.pool.connect(self.addr)
  File "/softs/rh7/conda/4.5.4/envs/pangeo_full_201909/lib/python3.7/site-packages/distributed/core.py", line 874, in connect
    connection_args=self.connection_args,
  File "/softs/rh7/conda/4.5.4/envs/pangeo_full_201909/lib/python3.7/site-packages/distributed/comm/core.py", line 227, in connect
    _raise(error)
  File "/softs/rh7/conda/4.5.4/envs/pangeo_full_201909/lib/python3.7/site-packages/distributed/comm/core.py", line 204, in _raise
    raise IOError(msg)
OSError: Timed out trying to connect to 'tcp://10.120.40.97:33653' after 10 s: in <distributed.comm.tcp.TCPConnector object at 0x2b3811574630>: ConnectionRefusedError: [Errno 111] Connection refused
tornado.application - ERROR - Exception in callback <function Worker._register_with_scheduler.<locals>.<lambda> at 0x2b37fa7fee18>
Traceback (most recent call last):
  File "/softs/rh7/conda/4.5.4/envs/pangeo_full_201909/lib/python3.7/site-packages/tornado/ioloop.py", line 907, in _run
    return self.callback()
  File "/softs/rh7/conda/4.5.4/envs/pangeo_full_201909/lib/python3.7/site-packages/distributed/worker.py", line 857, in <lambda>
    lambda: self.batched_stream.send({"op": "keep-alive"}),
  File "/softs/rh7/conda/4.5.4/envs/pangeo_full_201909/lib/python3.7/site-packages/distributed/batched.py", line 117, in send
    raise CommClosedError
distributed.comm.core.CommClosedError
tornado.application - ERROR - Exception in callback functools.partial(<bound method IOLoop._discard_future_result of <tornado.platform.asyncio.AsyncIOLoop object at 0x2b37e7ab2b38>>, <Task finished coro=<Worker.heartbeat() done, defined at /softs/rh7/conda/4.5.4/envs/pangeo_full_201909/lib/python3.7/site-packages/distributed/worker.py:866> exception=OSError("Timed out trying to connect to 'tcp://10.120.40.97:33653' after 10 s: in <distributed.comm.tcp.TCPConnector object at 0x2b38114a8908>: ConnectionRefusedError: [Errno 111] Connection refused")>)
Traceback (most recent call last):
  File "/softs/rh7/conda/4.5.4/envs/pangeo_full_201909/lib/python3.7/site-packages/distributed/comm/core.py", line 215, in connect
    quiet_exceptions=EnvironmentError,
tornado.util.TimeoutError: Timeout

During handling of the above exception, another exception occurred:

Traceback (most recent call last):
  File "/softs/rh7/conda/4.5.4/envs/pangeo_full_201909/lib/python3.7/site-packages/tornado/ioloop.py", line 743, in _run_callback
    ret = callback()
  File "/softs/rh7/conda/4.5.4/envs/pangeo_full_201909/lib/python3.7/site-packages/tornado/ioloop.py", line 767, in _discard_future_result
    future.result()
  File "/softs/rh7/conda/4.5.4/envs/pangeo_full_201909/lib/python3.7/site-packages/distributed/worker.py", line 875, in heartbeat
    metrics=await self.get_metrics(),
  File "/softs/rh7/conda/4.5.4/envs/pangeo_full_201909/lib/python3.7/site-packages/distributed/core.py", line 747, in send_recv_from_rpc
    comm = await self.pool.connect(self.addr)
  File "/softs/rh7/conda/4.5.4/envs/pangeo_full_201909/lib/python3.7/site-packages/distributed/core.py", line 874, in connect
    connection_args=self.connection_args,
  File "/softs/rh7/conda/4.5.4/envs/pangeo_full_201909/lib/python3.7/site-packages/distributed/comm/core.py", line 227, in connect
    _raise(error)
  File "/softs/rh7/conda/4.5.4/envs/pangeo_full_201909/lib/python3.7/site-packages/distributed/comm/core.py", line 204, in _raise
    raise IOError(msg)
OSError: Timed out trying to connect to 'tcp://10.120.40.97:33653' after 10 s: in <distributed.comm.tcp.TCPConnector object at 0x2b38114a8908>: ConnectionRefusedError: [Errno 111] Connection refused
tornado.application - ERROR - Exception in callback functools.partial(<bound method IOLoop._discard_future_result of <tornado.platform.asyncio.AsyncIOLoop object at 0x2b37e7ab2b38>>, <Task finished coro=<Worker.heartbeat() done, defined at /softs/rh7/conda/4.5.4/envs/pangeo_full_201909/lib/python3.7/site-packages/distributed/worker.py:866> exception=OSError("Timed out trying to connect to 'tcp://10.120.40.97:33653' after 10 s: in <distributed.comm.tcp.TCPConnector object at 0x2b38116039e8>: ConnectionRefusedError: [Errno 111] Connection refused")>)
Traceback (most recent call last):
  File "/softs/rh7/conda/4.5.4/envs/pangeo_full_201909/lib/python3.7/site-packages/distributed/comm/core.py", line 215, in connect
    quiet_exceptions=EnvironmentError,
tornado.util.TimeoutError: Timeout

During handling of the above exception, another exception occurred:

Traceback (most recent call last):
  File "/softs/rh7/conda/4.5.4/envs/pangeo_full_201909/lib/python3.7/site-packages/tornado/ioloop.py", line 743, in _run_callback
    ret = callback()
  File "/softs/rh7/conda/4.5.4/envs/pangeo_full_201909/lib/python3.7/site-packages/tornado/ioloop.py", line 767, in _discard_future_result
    future.result()
  File "/softs/rh7/conda/4.5.4/envs/pangeo_full_201909/lib/python3.7/site-packages/distributed/worker.py", line 875, in heartbeat
    metrics=await self.get_metrics(),
  File "/softs/rh7/conda/4.5.4/envs/pangeo_full_201909/lib/python3.7/site-packages/distributed/core.py", line 747, in send_recv_from_rpc
    comm = await self.pool.connect(self.addr)
  File "/softs/rh7/conda/4.5.4/envs/pangeo_full_201909/lib/python3.7/site-packages/distributed/core.py", line 874, in connect
    connection_args=self.connection_args,
  File "/softs/rh7/conda/4.5.4/envs/pangeo_full_201909/lib/python3.7/site-packages/distributed/comm/core.py", line 227, in connect
    _raise(error)
  File "/softs/rh7/conda/4.5.4/envs/pangeo_full_201909/lib/python3.7/site-packages/distributed/comm/core.py", line 204, in _raise
    raise IOError(msg)
OSError: Timed out trying to connect to 'tcp://10.120.40.97:33653' after 10 s: in <distributed.comm.tcp.TCPConnector object at 0x2b38116039e8>: ConnectionRefusedError: [Errno 111] Connection refused
tornado.application - ERROR - Exception in callback functools.partial(<bound method IOLoop._discard_future_result of <tornado.platform.asyncio.AsyncIOLoop object at 0x2b37e7ab2b38>>, <Task finished coro=<Worker.heartbeat() done, defined at /softs/rh7/conda/4.5.4/envs/pangeo_full_201909/lib/python3.7/site-packages/distributed/worker.py:866> exception=OSError("Timed out trying to connect to 'tcp://10.120.40.97:33653' after 10 s: in <distributed.comm.tcp.TCPConnector object at 0x2b3811603748>: ConnectionRefusedError: [Errno 111] Connection refused")>)
Traceback (most recent call last):
  File "/softs/rh7/conda/4.5.4/envs/pangeo_full_201909/lib/python3.7/site-packages/distributed/comm/core.py", line 215, in connect
    quiet_exceptions=EnvironmentError,
tornado.util.TimeoutError: Timeout

During handling of the above exception, another exception occurred:

Traceback (most recent call last):
  File "/softs/rh7/conda/4.5.4/envs/pangeo_full_201909/lib/python3.7/site-packages/tornado/ioloop.py", line 743, in _run_callback
    ret = callback()
  File "/softs/rh7/conda/4.5.4/envs/pangeo_full_201909/lib/python3.7/site-packages/tornado/ioloop.py", line 767, in _discard_future_result
    future.result()
  File "/softs/rh7/conda/4.5.4/envs/pangeo_full_201909/lib/python3.7/site-packages/distributed/worker.py", line 875, in heartbeat
    metrics=await self.get_metrics(),
  File "/softs/rh7/conda/4.5.4/envs/pangeo_full_201909/lib/python3.7/site-packages/distributed/core.py", line 747, in send_recv_from_rpc
    comm = await self.pool.connect(self.addr)
  File "/softs/rh7/conda/4.5.4/envs/pangeo_full_201909/lib/python3.7/site-packages/distributed/core.py", line 874, in connect
    connection_args=self.connection_args,
  File "/softs/rh7/conda/4.5.4/envs/pangeo_full_201909/lib/python3.7/site-packages/distributed/comm/core.py", line 227, in connect
    _raise(error)
  File "/softs/rh7/conda/4.5.4/envs/pangeo_full_201909/lib/python3.7/site-packages/distributed/comm/core.py", line 204, in _raise
    raise IOError(msg)
OSError: Timed out trying to connect to 'tcp://10.120.40.97:33653' after 10 s: in <distributed.comm.tcp.TCPConnector object at 0x2b3811603748>: ConnectionRefusedError: [Errno 111] Connection refused
tornado.application - ERROR - Exception in callback functools.partial(<bound method IOLoop._discard_future_result of <tornado.platform.asyncio.AsyncIOLoop object at 0x2b37e7ab2b38>>, <Task finished coro=<Worker.heartbeat() done, defined at /softs/rh7/conda/4.5.4/envs/pangeo_full_201909/lib/python3.7/site-packages/distributed/worker.py:866> exception=OSError("Timed out trying to connect to 'tcp://10.120.40.97:33653' after 10 s: in <distributed.comm.tcp.TCPConnector object at 0x2b3810e9a358>: ConnectionRefusedError: [Errno 111] Connection refused")>)
Traceback (most recent call last):
  File "/softs/rh7/conda/4.5.4/envs/pangeo_full_201909/lib/python3.7/site-packages/distributed/comm/core.py", line 215, in connect
    quiet_exceptions=EnvironmentError,
tornado.util.TimeoutError: Timeout

During handling of the above exception, another exception occurred:

Traceback (most recent call last):
  File "/softs/rh7/conda/4.5.4/envs/pangeo_full_201909/lib/python3.7/site-packages/tornado/ioloop.py", line 743, in _run_callback
    ret = callback()
  File "/softs/rh7/conda/4.5.4/envs/pangeo_full_201909/lib/python3.7/site-packages/tornado/ioloop.py", line 767, in _discard_future_result
    future.result()
  File "/softs/rh7/conda/4.5.4/envs/pangeo_full_201909/lib/python3.7/site-packages/distributed/worker.py", line 875, in heartbeat
    metrics=await self.get_metrics(),
  File "/softs/rh7/conda/4.5.4/envs/pangeo_full_201909/lib/python3.7/site-packages/distributed/core.py", line 747, in send_recv_from_rpc
    comm = await self.pool.connect(self.addr)
  File "/softs/rh7/conda/4.5.4/envs/pangeo_full_201909/lib/python3.7/site-packages/distributed/core.py", line 874, in connect
    connection_args=self.connection_args,
  File "/softs/rh7/conda/4.5.4/envs/pangeo_full_201909/lib/python3.7/site-packages/distributed/comm/core.py", line 227, in connect
    _raise(error)
  File "/softs/rh7/conda/4.5.4/envs/pangeo_full_201909/lib/python3.7/site-packages/distributed/comm/core.py", line 204, in _raise
    raise IOError(msg)
OSError: Timed out trying to connect to 'tcp://10.120.40.97:33653' after 10 s: in <distributed.comm.tcp.TCPConnector object at 0x2b3810e9a358>: ConnectionRefusedError: [Errno 111] Connection refused
tornado.application - ERROR - Exception in callback functools.partial(<bound method IOLoop._discard_future_result of <tornado.platform.asyncio.AsyncIOLoop object at 0x2b37e7ab2b38>>, <Task finished coro=<Worker.heartbeat() done, defined at /softs/rh7/conda/4.5.4/envs/pangeo_full_201909/lib/python3.7/site-packages/distributed/worker.py:866> exception=OSError("Timed out trying to connect to 'tcp://10.120.40.97:33653' after 10 s: in <distributed.comm.tcp.TCPConnector object at 0x2b3810932b38>: ConnectionRefusedError: [Errno 111] Connection refused")>)
Traceback (most recent call last):
  File "/softs/rh7/conda/4.5.4/envs/pangeo_full_201909/lib/python3.7/site-packages/distributed/comm/core.py", line 215, in connect
    quiet_exceptions=EnvironmentError,
tornado.util.TimeoutError: Timeout

During handling of the above exception, another exception occurred:

Traceback (most recent call last):
  File "/softs/rh7/conda/4.5.4/envs/pangeo_full_201909/lib/python3.7/site-packages/tornado/ioloop.py", line 743, in _run_callback
    ret = callback()
  File "/softs/rh7/conda/4.5.4/envs/pangeo_full_201909/lib/python3.7/site-packages/tornado/ioloop.py", line 767, in _discard_future_result
    future.result()
  File "/softs/rh7/conda/4.5.4/envs/pangeo_full_201909/lib/python3.7/site-packages/distributed/worker.py", line 875, in heartbeat
    metrics=await self.get_metrics(),
  File "/softs/rh7/conda/4.5.4/envs/pangeo_full_201909/lib/python3.7/site-packages/distributed/core.py", line 747, in send_recv_from_rpc
    comm = await self.pool.connect(self.addr)
  File "/softs/rh7/conda/4.5.4/envs/pangeo_full_201909/lib/python3.7/site-packages/distributed/core.py", line 874, in connect
    connection_args=self.connection_args,
  File "/softs/rh7/conda/4.5.4/envs/pangeo_full_201909/lib/python3.7/site-packages/distributed/comm/core.py", line 227, in connect
    _raise(error)
  File "/softs/rh7/conda/4.5.4/envs/pangeo_full_201909/lib/python3.7/site-packages/distributed/comm/core.py", line 204, in _raise
    raise IOError(msg)
OSError: Timed out trying to connect to 'tcp://10.120.40.97:33653' after 10 s: in <distributed.comm.tcp.TCPConnector object at 0x2b3810932b38>: ConnectionRefusedError: [Errno 111] Connection refused
tornado.application - ERROR - Exception in callback <function Worker._register_with_scheduler.<locals>.<lambda> at 0x2b37fa7fee18>
Traceback (most recent call last):
  File "/softs/rh7/conda/4.5.4/envs/pangeo_full_201909/lib/python3.7/site-packages/tornado/ioloop.py", line 907, in _run
    return self.callback()
  File "/softs/rh7/conda/4.5.4/envs/pangeo_full_201909/lib/python3.7/site-packages/distributed/worker.py", line 857, in <lambda>
    lambda: self.batched_stream.send({"op": "keep-alive"}),
  File "/softs/rh7/conda/4.5.4/envs/pangeo_full_201909/lib/python3.7/site-packages/distributed/batched.py", line 117, in send
    raise CommClosedError
distributed.comm.core.CommClosedError
tornado.application - ERROR - Exception in callback functools.partial(<bound method IOLoop._discard_future_result of <tornado.platform.asyncio.AsyncIOLoop object at 0x2b37e7ab2b38>>, <Task finished coro=<Worker.heartbeat() done, defined at /softs/rh7/conda/4.5.4/envs/pangeo_full_201909/lib/python3.7/site-packages/distributed/worker.py:866> exception=OSError("Timed out trying to connect to 'tcp://10.120.40.97:33653' after 10 s: in <distributed.comm.tcp.TCPConnector object at 0x2b3810a34668>: ConnectionRefusedError: [Errno 111] Connection refused")>)
Traceback (most recent call last):
  File "/softs/rh7/conda/4.5.4/envs/pangeo_full_201909/lib/python3.7/site-packages/distributed/comm/core.py", line 215, in connect
    quiet_exceptions=EnvironmentError,
tornado.util.TimeoutError: Timeout

During handling of the above exception, another exception occurred:

Traceback (most recent call last):
  File "/softs/rh7/conda/4.5.4/envs/pangeo_full_201909/lib/python3.7/site-packages/tornado/ioloop.py", line 743, in _run_callback
    ret = callback()
  File "/softs/rh7/conda/4.5.4/envs/pangeo_full_201909/lib/python3.7/site-packages/tornado/ioloop.py", line 767, in _discard_future_result
    future.result()
  File "/softs/rh7/conda/4.5.4/envs/pangeo_full_201909/lib/python3.7/site-packages/distributed/worker.py", line 875, in heartbeat
    metrics=await self.get_metrics(),
  File "/softs/rh7/conda/4.5.4/envs/pangeo_full_201909/lib/python3.7/site-packages/distributed/core.py", line 747, in send_recv_from_rpc
    comm = await self.pool.connect(self.addr)
  File "/softs/rh7/conda/4.5.4/envs/pangeo_full_201909/lib/python3.7/site-packages/distributed/core.py", line 874, in connect
    connection_args=self.connection_args,
  File "/softs/rh7/conda/4.5.4/envs/pangeo_full_201909/lib/python3.7/site-packages/distributed/comm/core.py", line 227, in connect
    _raise(error)
  File "/softs/rh7/conda/4.5.4/envs/pangeo_full_201909/lib/python3.7/site-packages/distributed/comm/core.py", line 204, in _raise
    raise IOError(msg)
OSError: Timed out trying to connect to 'tcp://10.120.40.97:33653' after 10 s: in <distributed.comm.tcp.TCPConnector object at 0x2b3810a34668>: ConnectionRefusedError: [Errno 111] Connection refused
=>> PBS: job killed: walltime 1820 exceeded limit 1800
distributed.nanny - INFO - Worker process 14078 was killed by unknown signal
distributed.dask_worker - INFO - Exiting on signal 15
distributed.nanny - INFO - Closing Nanny at 'tcp://10.120.40.64:38823'
distributed.dask_worker - INFO - End worker
Traceback (most recent call last):
  File "/softs/rh7/conda/4.5.4/envs/pangeo_full_201909/lib/python3.7/runpy.py", line 193, in _run_module_as_main
    "__main__", mod_spec)
  File "/softs/rh7/conda/4.5.4/envs/pangeo_full_201909/lib/python3.7/runpy.py", line 85, in _run_code
    exec(code, run_globals)
  File "/softs/rh7/conda/4.5.4/envs/pangeo_full_201909/lib/python3.7/site-packages/distributed/cli/dask_worker.py", line 410, in <module>
    go()
  File "/softs/rh7/conda/4.5.4/envs/pangeo_full_201909/lib/python3.7/site-packages/distributed/cli/dask_worker.py", line 406, in go
    main()
  File "/softs/rh7/conda/4.5.4/envs/pangeo_full_201909/lib/python3.7/site-packages/click/core.py", line 764, in __call__
    return self.main(*args, **kwargs)
  File "/softs/rh7/conda/4.5.4/envs/pangeo_full_201909/lib/python3.7/site-packages/click/core.py", line 717, in main
    rv = self.invoke(ctx)
  File "/softs/rh7/conda/4.5.4/envs/pangeo_full_201909/lib/python3.7/site-packages/click/core.py", line 956, in invoke
    return ctx.invoke(self.callback, **ctx.params)
  File "/softs/rh7/conda/4.5.4/envs/pangeo_full_201909/lib/python3.7/site-packages/click/core.py", line 555, in invoke
    return callback(*args, **kwargs)
  File "/softs/rh7/conda/4.5.4/envs/pangeo_full_201909/lib/python3.7/site-packages/distributed/cli/dask_worker.py", line 397, in main
    raise TimeoutError("Timed out starting worker.") from None
tornado.util.TimeoutError: Timed out starting worker.
